Workbook

Sheet Sep 2021
A1: DATE | B1: STATION 48 | C1: ANDERSON-ROSE | D1: J CANAL | E1: TULE LAKE PRECIP | F1: TULE LAKE SNOW | G1: D PLANT | H1: TULE LAKE ELEV. | I1: CHANGES @ STATION 48
B2: (in CFS) | C2: (in CFS) | D2: (in CFS) | G2: (in AF)
A3: 44440 | B3: 150 | C3: 0 | D3: 158 | E3: 0 | F3: 0 | G3: 0 | H3: -
A4: =A3+1 -> 44441 | B4: 150 | C4: 0 | D4: 158 | E4: 0 | F4: 0 | G4: 0 | H4: -
A5: =A4+1 -> 44442 | B5: 150 | C5: 0 | D5: 158 | E5: 0 | F5: 0 | G5: 0 | H5: -
A6: =A5+1 -> 44443 | B6: 150 | C6: 0 | D6: 158 | E6: 0 | F6: 0 | G6: 0 | H6: -
A7: =A6+1 -> 44444 | B7: 150 | C7: 0 | D7: 158 | E7: 0 | F7: 0 | G7: 0 | H7: -
A8: =A7+1 -> 44445 | B8: 150 | C8: 0 | D8: 163 | E8: 0 | F8: 0 | G8: 0 | H8: -
A9: =A8+1 -> 44446 | B9: 150 | C9: 0 | D9: 163 | E9: 0 | F9: 0 | G9: 0 | H9: -
A10: =A9+1 -> 44447 | B10: 58 | C10: 0 | D10: 160 | E10: 0 | F10: 0 | G10: 0 | H10: - | I10: * 09:20 150/0
A11: =A10+1 -> 44448 | B11: 0 | C11: 0 | D11: 107 | E11: 0 | F11: 0 | G11: 0 | H11: -
A12: =A11+1 -> 44449 | B12: 0 | C12: 0 | D12: 45 | E12: 1.08 | F12: 0 | G12: 0 | H12: -
A13: =A12+1 -> 44450 | B13: 0 | C13: 0 | D13: 20 | E13: 0 | F13: 0 | G13: 0 | H13: -
A14: =A13+1 -> 44451 | B14: 0 | C14: 0 | D14: 12 | E14: 0 | F14: 0 | G14: 0 | H14: -
A15: =A14+1 -> 44452 | B15: 0 | C15: 0 | D15: 8 | E15: 0 | F15: 0 | G15: 0 | H15: -
A16: =A15+1 -> 44453 | B16: 0 | C16: 0 | D16: 4 | E16: 0 | F16: 0 | G16: 0 | H16: -
A17: =A16+1 -> 44454 | B17: 0 | C17: 0 | D17: 5 | E17: 0 | F17: 0 | G17: 0 | H17: -
A18: =A17+1 -> 44455 | B18: 0 | C18: 0 | D18: 6 | E18: 0 | F18: 0 | G18: 0 | H18: -
A19: =A18+1 -> 44456 | B19: 0 | C19: 0 | D19: 6 | E19: 0 | F19: 0 | G19: 0 | H19: -
A20: =A19+1 -> 44457 | B20: 0 | C20: 0 | D20: 6 | E20: 0.14 | F20: 0 | G20: 0 | H20: -
A21: =A20+1 -> 44458 | B21: 0 | C21: 0 | D21: 6 | E21: 0.01 | F21: 0 | G21: 0 | H21: -
A22: =A21+1 -> 44459 | B22: 0 | C22: 0 | D22: 5 | E22: 0 | F22: 0 | G22: 0 | H22: -
... A32: =A31+1 -> 44469 | B32: 0 | C32: 0 | D32: 5 | E32: 0 | F32: 0 | G32: 0 | H32: -
A33: Monthly Total | B33: =SUM(B3:B32) -> 1108 | C33: =SUM(C3:C32) -> 0 | D33: =SUM(D3:D32) -> 1556 | E33: =SUM(E3:E32) -> 1.4 | F33: =SUM(F3:F32) -> 0 | G33: =SUM(G3:G32) -> 0
A34: WY Total | B34: =SUM(B33+'Aug 2021'!B35) -> 11633 | C34: =SUM(C33+'Aug 2021'!C35) -> 3290 | D34: =SUM(D33+'Aug 2021'!D35) -> 12019 | E34: =SUM(E33+'Aug 2021'!E35) -> 5.56 | F34: =SUM(F33+'Aug 2021'!F35) -> 10.9 | G34: =SUM(G33+'Aug 2021'!G35) -> 0
A36: Acre Feet | B36: =SUM(B3:B32)*1.9835 -> 2197.718 | C36: =SUM(C3:C32)*1.9835 -> 0 | D36: =SUM(D3:D32)*1.9835 -> 3086.326
A38: WY AF Total | B38: =SUM(B36+'Aug 2021'!B39) -> 23966.63 | C38: =SUM(C36+'Aug 2021'!C39) -> 6555.4675 | D38: =SUM(D36+'Aug 2021'!D39) -> 25025.82
G40: * COMPUTATIONAL PURPOSES ONLY! Do Not Enter Data in the Red Columns
A42: *This is computation purposes only for Station 48
A43: Sta 48
F44: =SUM(24-D44) -> 24 | G44: =SUM(C44+E44) -> 0 | H44: =SUM(C44/24*D44+G44/24*F44) -> 0
F45: =SUM(24-D45) -> 24 | G45: =SUM(C45+E45) -> 0 | H45: =SUM(C45/24*D45+G45/24*F45) -> 0
F46: =SUM(24-D46) -> 24 | G46: =SUM(C46+E46) -> 0 | H46: =SUM(C46/24*D46+G46/24*F46) -> 0
F47: =SUM(24-D47) -> 24 | G47: =SUM(C47+E47) -> 0 | H47: =SUM(C47/24*D47+G47/24*F47) -> 0
F48: =SUM(24-D48) -> 24 | G48: =SUM(C48+E48) -> 0 | H48: =SUM(C48/24*D48+G48/24*F48) -> 0
A50: Use for more than 1 change in a day.
A51: **Station 48: | B51: Time | C51: Current CFS | D51: Hours Run | E51: +/- cfs | F51: Sub-total cfs
F52: =SUM(C52/24*D52) -> 0
F53: =SUM(C53/24*D53) -> 0
F54: =SUM(C54/24*D54) -> 0
...

Sheet Aug 2021
A1: DATE | B1: STATION 48 | C1: ANDERSON-ROSE | D1: J CANAL | E1: TULE LAKE PRECIP | F1: TULE LAKE SNOW | G1: D PLANT | H1: TULE LAKE ELEV. | I1: CHANGES @ STATION 48
B2: (in CFS) | C2: (in CFS) | D2: (in CFS) | G2: (in AF)
A3: 44409 | B3: 0 | C3: 0 | D3: 0 | E3: 0 | F3: 0 | G3: 0 | H3: -
A4: =A3+1 -> 44410 | B4: 0 | C4: 0 | D4: 0 | E4: 0 | F4: 0 | G4: 0 | H4: -
A5: =A4+1 -> 44411 | B5: 0 | C5: 0 | D5: 0 | E5: 0 | F5: 0 | G5: 0 | H5: -
A6: =A5+1 -> 44412 | B6: 0 | C6: 0 | D6: 0 | E6: 0 | F6: 0 | G6: 0 | H6: -
A7: =A6+1 -> 44413 | B7: 53 | C7: 0 | D7: 0 | E7: 0 | F7: 0 | G7: 0 | H7: - | I7: * 15:30 0/150
A8: =A7+1 -> 44414 | B8: 150 | C8: 0 | D8: 0 | E8: 0 | F8: 0 | G8: 0 | H8: -
A9: =A8+1 -> 44415 | B9: 150 | C9: 0 | D9: 58 | E9: 0 | F9: 0 | G9: 0 | H9: -
A10: =A9+1 -> 44416 | B10: 150 | C10: 0 | D10: 115 | E10: 0 | F10: 0 | G10: 0 | H10: -
A11: =A10+1 -> 44417 | B11: 150 | C11: 0 | D11: 115 | E11: 0 | F11: 0 | G11: 0 | H11: -
A12: =A11+1 -> 44418 | B12: 150 | C12: 0 | D12: 125 | E12: 0 | F12: 0 | G12: 0 | H12: -
A13: =A12+1 -> 44419 | B13: 150 | C13: 0 | D13: 135 | E13: 0 | F13: 0 | G13: 0 | H13: -
A14: =A13+1 -> 44420 | B14: 130 | C14: 0 | D14: 130 | E14: 0 | F14: 0 | G14: 0 | H14: -
A15: =A14+1 -> 44421 | B15: 150 | C15: 0 | D15: 130 | E15: 0 | F15: 0 | G15: 0 | H15: -
A16: =A15+1 -> 44422 | B16: 150 | C16: 0 | D16: 142 | E16: 0 | F16: 0 | G16: 0 | H16: -
A17: =A16+1 -> 44423 | B17: 150 | C17: 0 | D17: 149 | E17: 0 | F17: 0 | G17: 0 | H17: -
A18: =A17+1 -> 44424 | B18: 150 | C18: 0 | D18: 155 | E18: 0 | F18: 0 | G18: 0 | H18: -
A19: =A18+1 -> 44425 | B19: 150 | C19: 0 | D19: 158 | E19: 0 | F19: 0 | G19: 0 | H19: -
... A33: =A32+1 -> 44439 | B33: 150 | C33: 0 | D33: 158 | E33: 0 | F33: 0 | G33: 0 | H33: -
A34: Monthly Total | B34: =SUM(B3:B33) -> 3933 | C34: =SUM(C3:C33) -> 0 | D34: =SUM(D3:D33) -> 3643 | E34: =SUM(E3:E33) -> 0 | F34: =SUM(F3:F33) -> 0 | G34: =SUM(G3:G33) -> 0
A35: WY Total | B35: =SUM(B34+'Jul 2021'!B35) -> 10525 | C35: =SUM(C34+'Jul 2021'!C35) -> 3290 | D35: =SUM(D34+'Jul 2021'!D35) -> 10463 | E35: =SUM(E34+'Jul 2021'!E35) -> 4.16 | F35: =SUM(F34+'Jul 2021'!F35) -> 10.9 | G35: =SUM(G34+'Jul 2021'!G35) -> 0
A37: Acre Feet | B37: =SUM(B3:B33)*1.9835 -> 7801.1055 | C37: =SUM(C3:C33)*1.9835 -> 0 | D37: =SUM(D3:D33)*1.9835 -> 7225.8905
A39: WY AF Total | B39: =SUM(B37+'Jul 2021'!B39) -> 21768.912 | C39: =SUM(C37+'Jul 2021'!C39) -> 6555.4675 | D39: =SUM(D37+'Jul 2021'!D39) -> 21939.494
G41: * COMPUTATIONAL PURPOSES ONLY! Do Not Enter Data in the Red Columns
A43: *This is computation purposes only for Station 48
A44: Sta 48
F45: =SUM(24-D45) -> 24 | G45: =SUM(C45+E45) -> 0 | H45: =SUM(C45/24*D45+G45/24*F45) -> 0
F46: =SUM(24-D46) -> 24 | G46: =SUM(C46+E46) -> 0 | H46: =SUM(C46/24*D46+G46/24*F46) -> 0
F47: =SUM(24-D47) -> 24 | G47: =SUM(C47+E47) -> 0 | H47: =SUM(C47/24*D47+G47/24*F47) -> 0
F48: =SUM(24-D48) -> 24 | G48: =SUM(C48+E48) -> 0 | H48: =SUM(C48/24*D48+G48/24*F48) -> 0
F49: =SUM(24-D49) -> 24 | G49: =SUM(C49+E49) -> 0 | H49: =SUM(C49/24*D49+G49/24*F49) -> 0
A51: Use for more than 1 change in a day.
A52: **Station 48: | B52: Time | C52: Current CFS | D52: Hours Run | E52: +/- cfs | F52: Sub-total cfs
F53: =SUM(C53/24*D53) -> 0
F54: =SUM(C54/24*D54) -> 0
F55: =SUM(C55/24*D55) -> 0
F56: =SUM(C56/24*D56) -> 0
F57: =SUM(C57/24*D57) -> 0
A58: Total Hours Run | D58: =SUM(D53:D57) -> 0 | E58: Total/Day cfs | F58: =SUM(F53:F57) -> 0

Sheet Jul 2021
A1: DATE | B1: STATION 48 | C1: ANDERSON-ROSE | D1: J CANAL | E1: TULE LAKE PRECIP | F1: TULE LAKE SNOW | G1: D PLANT | H1: TULE LAKE ELEV. | I1: CHANGES @ STATION 48
B2: (in CFS) | C2: (in CFS) | D2: (in CFS) | G2: (in AF)
A3: 44378 | B3: 0 | C3: 0 | D3: 0 | E3: 0 | F3: 0 | G3: 0 | H3: 4030
A4: =A3+1 -> 44379 | B4: 0 | C4: 0 | D4: 0 | E4: 0 | F4: 0 | G4: 0 | H4: 4030
A5: =A4+1 -> 44380 | B5: 0 | C5: 0 | D5: 0 | E5: 0 | F5: 0 | G5: 0 | H5: 4030
A6: =A5+1 -> 44381 | B6: 0 | C6: 0 | D6: 0 | E6: 0 | F6: 0 | G6: 0 | H6: 4030
A7: =A6+1 -> 44382 | B7: 0 | C7: 0 | D7: 0 | E7: 0 | F7: 0 | G7: 0 | H7: 4030
A8: =A7+1 -> 44383 | B8: 0 | C8: 0 | D8: 0 | E8: 0 | F8: 0 | G8: 0 | H8: -
A9: =A8+1 -> 44384 | B9: 0 | C9: 0 | D9: 0 | E9: 0 | F9: 0 | G9: 0 | H9: -
A10: =A9+1 -> 44385 | B10: 0 | C10: 0 | D10: 0 | E10: 0 | F10: 0 | G10: 0 | H10: -
A11: =A10+1 -> 44386 | B11: 0 | C11: 0 | D11: 0 | E11: 0 | F11: 0 | G11: 0 | H11: -
A12: =A11+1 -> 44387 | B12: 0 | C12: 0 | D12: 0 | E12: 0 | F12: 0 | G12: 0 | H12: -
A13: =A12+1 -> 44388 | B13: 0 | C13: 0 | D13: 0 | E13: 0 | F13: 0 | G13: 0 | H13: -
A14: =A13+1 -> 44389 | B14: 0 | C14: 0 | D14: 0 | E14: 0 | F14: 0 | G14: 0 | H14: -
A15: =A14+1 -> 44390 | B15: 0 | C15: 0 | D15: 0 | E15: 0 | F15: 0 | G15: 0 | H15: -
A16: =A15+1 -> 44391 | B16: 0 | C16: 0 | D16: 0 | E16: 0 | F16: 0 | G16: 0 | H16: -
A17: =A16+1 -> 44392 | B17: 0 | C17: 0 | D17: 0 | E17: 0 | F17: 0 | G17: 0 | H17: -
A18: =A17+1 -> 44393 | B18: 0 | C18: 0 | D18: 0 | E18: 0 | F18: 0 | G18: 0 | H18: -
A19: =A18+1 -> 44394 | B19: 0 | C19: 0 | D19: 0 | E19: 0 | F19: 0 | G19: 0 | H19: -
... A33: =A32+1 -> 44408 | B33: 0 | C33: 0 | D33: 0 | E33: 0 | F33: 0 | G33: 0 | H33: -
A34: Monthly Total | B34: =SUM(B3:B33) -> 0 | C34: =SUM(C3:C33) -> 0 | D34: =SUM(D3:D33) -> 0 | E34: =SUM(E3:E33) -> 0 | F34: =SUM(F3:F33) -> 0 | G34: =SUM(G3:G33) -> 0
A35: WY Total | B35: =SUM(B34+'Jun 2021'!B34) -> 6592 | C35: =SUM(C34+'Jun 2021'!C34) -> 3290 | D35: =SUM(D34+'Jun 2021'!D34) -> 6820 | E35: =SUM(E34+'Jun 2021'!E34) -> 4.16 | F35: =SUM(F34+'Jun 2021'!F34) -> 10.9 | G35: =SUM(G34+'Jun 2021'!G34) -> 0
A37: Acre Feet | B37: =SUM(B3:B33)*1.9835 -> 0 | C37: =SUM(C3:C33)*1.9835 -> 0 | D37: =SUM(D3:D33)*1.9835 -> 0
A39: WY AF Total | B39: =SUM(B37+'Jun 2021'!B38) -> 13967.807 | C39: =SUM(C37+'Jun 2021'!C38) -> 6555.4675 | D39: =SUM(D37+'Jun 2021'!D38) -> 14713.603
G41: * COMPUTATIONAL PURPOSES ONLY! Do Not Enter Data in the Red Columns
A43: *This is computation purposes only for Station 48
A44: Sta 48
F45: =SUM(24-D45) -> 24 | G45: =SUM(C45+E45) -> 0 | H45: =SUM(C45/24*D45+G45/24*F45) -> 0
F46: =SUM(24-D46) -> 24 | G46: =SUM(C46+E46) -> 0 | H46: =SUM(C46/24*D46+G46/24*F46) -> 0
F47: =SUM(24-D47) -> 24 | G47: =SUM(C47+E47) -> 0 | H47: =SUM(C47/24*D47+G47/24*F47) -> 0
F48: =SUM(24-D48) -> 24 | G48: =SUM(C48+E48) -> 0 | H48: =SUM(C48/24*D48+G48/24*F48) -> 0
F49: =SUM(24-D49) -> 24 | G49: =SUM(C49+E49) -> 0 | H49: =SUM(C49/24*D49+G49/24*F49) -> 0
A51: Use for more than 1 change in a day.
A52: **Station 48: | B52: Time | C52: Current CFS | D52: Hours Run | E52: +/- cfs | F52: Sub-total cfs
F53: =SUM(C53/24*D53) -> 0
F54: =SUM(C54/24*D54) -> 0
F55: =SUM(C55/24*D55) -> 0
F56: =SUM(C56/24*D56) -> 0
F57: =SUM(C57/24*D57) -> 0
A58: Total Hours Run | D58: =SUM(D53:D57) -> 0 | E58: Total/Day cfs | F58: =SUM(F53:F57) -> 0

Sheet Jun 2021
A1: DATE | B1: STATION 48 | C1: ANDERSON-ROSE | D1: J CANAL | E1: TULE LAKE PRECIP | F1: TULE LAKE SNOW | G1: D PLANT | H1: TULE LAKE ELEV. | I1: CHANGES @ STATION 48
B2: (in CFS) | C2: (in CFS) | D2: (in CFS) | G2: (in AF)
A3: 44348 | B3: 10 | C3: 0 | D3: 0 | E3: 0 | F3: 0 | G3: 0 | H3: 4032.42
A4: =A3+1 -> 44349 | B4: 10 | C4: 0 | D4: 0 | E4: 0 | F4: 0 | G4: 0 | H4: 4032.39
A5: =A4+1 -> 44350 | B5: 4 | C5: 0 | D5: 0 | E5: 0 | F5: 0 | G5: 0 | H5: 4032.36 | I5: *0600 10/0
A6: =A5+1 -> 44351 | B6: 0 | C6: 0 | D6: 0 | E6: 0 | F6: 0 | G6: 0 | H6: 4032.33
A7: =A6+1 -> 44352 | B7: 0 | C7: 0 | D7: 0 | E7: 0 | F7: 0 | G7: 0 | H7: 4032.31
A8: =A7+1 -> 44353 | B8: 0 | C8: 0 | D8: 0 | E8: 0 | F8: 0 | G8: 0 | H8: 4032.28
A9: =A8+1 -> 44354 | B9: 0 | C9: 0 | D9: 0 | E9: 0 | F9: 0 | G9: 0 | H9: 4032.2
A10: =A9+1 -> 44355 | B10: 0 | C10: 0 | D10: 0 | E10: 0 | F10: 0 | G10: 0 | H10: 4032.1
A11: =A10+1 -> 44356 | B11: 0 | C11: 0 | D11: 0 | E11: 0.01 | F11: 0 | G11: 0 | H11: 4032
A12: =A11+1 -> 44357 | B12: 0 | C12: 0 | D12: 0 | E12: 0.03 | F12: 0 | G12: 0 | H12: 4031.8
A13: =A12+1 -> 44358 | B13: 0 | C13: 0 | D13: 0 | E13: 0 | F13: 0 | G13: 0 | H13: 4031.6
A14: =A13+1 -> 44359 | B14: 0 | C14: 0 | D14: 0 | E14: 0.01 | F14: 0 | G14: 0 | H14: 4031.4
A15: =A14+1 -> 44360 | B15: 0 | C15: 0 | D15: 0 | E15: 0 | F15: 0 | G15: 0 | H15: 4031.2
A16: =A15+1 -> 44361 | B16: 0 | C16: 0 | D16: 0 | E16: 0 | F16: 0 | G16: 0 | H16: 4031
A17: =A16+1 -> 44362 | B17: 0 | C17: 0 | D17: 0 | E17: 0 | F17: 0 | G17: 0 | H17: 4030.8
... A32: =A31+1 -> 44377 | B32: 0 | C32: 0 | D32: 0 | E32: 0 | F32: 0 | G32: 0 | H32: 4030
A33: Monthly Total | B33: =SUM(B3:B32) -> 24 | C33: =SUM(C3:C32) -> 0 | D33: =SUM(D3:D32) -> 0 | E33: =SUM(E3:E32) -> 0.05 | F33: =SUM(F3:F32) -> 0 | G33: =SUM(G3:G32) -> 0
A34: WY Total | B34: =SUM(B33+'May 2021'!B35) -> 6592 | C34: =SUM(C33+'May 2021'!C35) -> 3290 | D34: =SUM(D33+'May 2021'!D35) -> 6820 | E34: =SUM(E33+'May 2021'!E35) -> 4.16 | F34: =SUM(F33+'May 2021'!F35) -> 10.9 | G34: =SUM(G33+'May 2021'!G35) -> 0
A36: Acre Feet | B36: =SUM(B3:B32)*1.9835 -> 47.604 | C36: =SUM(C3:C32)*1.9835 -> 0 | D36: =SUM(D3:D32)*1.9835 -> 0
A38: WY AF Total | B38: =SUM(B36+'May 2021'!B39) -> 13967.807 | C38: =SUM(C36+'May 2021'!C39) -> 6555.4675 | D38: =SUM(D36+'May 2021'!D39) -> 14713.603
G40: * COMPUTATIONAL PURPOSES ONLY! Do Not Enter Data in the Red Columns
A42: *This is computation purposes only for Station 48
A43: Sta 48
F44: =SUM(24-D44) -> 24 | G44: =SUM(C44+E44) -> 0 | H44: =SUM(C44/24*D44+G44/24*F44) -> 0
F45: =SUM(24-D45) -> 24 | G45: =SUM(C45+E45) -> 0 | H45: =SUM(C45/24*D45+G45/24*F45) -> 0
F46: =SUM(24-D46) -> 24 | G46: =SUM(C46+E46) -> 0 | H46: =SUM(C46/24*D46+G46/24*F46) -> 0
F47: =SUM(24-D47) -> 24 | G47: =SUM(C47+E47) -> 0 | H47: =SUM(C47/24*D47+G47/24*F47) -> 0
F48: =SUM(24-D48) -> 24 | G48: =SUM(C48+E48) -> 0 | H48: =SUM(C48/24*D48+G48/24*F48) -> 0
A50: Use for more than 1 change in a day.
A51: **Station 48: | B51: Time | C51: Current CFS | D51: Hours Run | E51: +/- cfs | F51: Sub-total cfs
F52: =SUM(C52/24*D52) -> 0
F53: =SUM(C53/24*D53) -> 0
F54: =SUM(C54/24*D54) -> 0
F55: =SUM(C55/24*D55) -> 0
F56: =SUM(C56/24*D56) -> 0
A57: Total Hours Run | D57: =SUM(D52:D56) -> 0 | E57: Total/Day cfs | F57: =SUM(F52:F56) -> 0

Sheet May 2021
A1: DATE | B1: STATION 48 | C1: ANDERSON-ROSE | D1: J CANAL | E1: TULE LAKE PRECIP | F1: TULE LAKE SNOW | G1: D PLANT | H1: TULE LAKE ELEV. | I1: CHANGES @ STATION 48
B2: (in CFS) | C2: (in CFS) | D2: (in CFS) | G2: (in AF)
A3: 44317 | B3: 5 | C3: 0 | D3: 5 | E3: 0 | F3: 0 | G3: 0 | H3: 4033.5
A4: =A3+1 -> 44318 | B4: 5 | C4: 0 | D4: 20 | E4: 0 | F4: 0 | G4: 0 | H4: 4033.5
A5: =A4+1 -> 44319 | B5: 5 | C5: 0 | D5: 20 | E5: 0 | F5: 0 | G5: 0 | H5: 4033.48
A6: =A5+1 -> 44320 | B6: 5 | C6: 0 | D6: 20 | E6: 0 | F6: 0 | G6: 0 | H6: 4033.44
A7: =A6+1 -> 44321 | B7: 8 | C7: 0 | D7: 20 | E7: 0 | F7: 0 | G7: 0 | H7: 4033.4 | I7: * 11:00 5/10
A8: =A7+1 -> 44322 | B8: 10 | C8: 0 | D8: 20 | E8: 0 | F8: 0 | G8: 0 | H8: 4033.38
A9: =A8+1 -> 44323 | B9: 10 | C9: 0 | D9: 20 | E9: 0 | F9: 0 | G9: 0 | H9: 4033.36
A10: =A9+1 -> 44324 | B10: 10 | C10: 0 | D10: 2 | E10: 0 | F10: 0 | G10: 0 | H10: 4033.35
A11: =A10+1 -> 44325 | B11: 10 | C11: 0 | D11: 2 | E11: 0 | F11: 0 | G11: 0 | H11: 4033.32
A12: =A11+1 -> 44326 | B12: 10 | C12: 0 | D12: 0 | E12: 0 | F12: 0 | G12: 0 | H12: 4033.3
A13: =A12+1 -> 44327 | B13: 10 | C13: 0 | D13: 0 | E13: 0 | F13: 0 | G13: 0 | H13: 4033.28
A14: =A13+1 -> 44328 | B14: 10 | C14: 0 | D14: 0 | E14: 0 | F14: 0 | G14: 0 | H14: 4033.26
A15: =A14+1 -> 44329 | B15: 10 | C15: 0 | D15: 0 | E15: 0 | F15: 0 | G15: 0 | H15: 4033.24
A16: =A15+1 -> 44330 | B16: 10 | C16: 0 | D16: 0 | E16: 0 | F16: 0 | G16: 0 | H16: 4033.2
A17: =A16+1 -> 44331 | B17: 10 | C17: 0 | D17: 0 | E17: 0.03 | F17: 0 | G17: 0 | H17: 4033.18
A18: =A17+1 -> 44332 | B18: 10 | C18: 0 | D18: 0 | E18: 0 | F18: 0 | G18: 0 | H18: 4033.16
A19: =A18+1 -> 44333 | B19: 10 | C19: 0 | D19: 0 | E19: 0 | F19: 0 | G19: 0 | H19: 4033.09
... A33: =A32+1 -> 44347 | B33: 10 | C33: 0 | D33: 0 | E33: 0 | F33: 0 | G33: 0 | H33: 4032.45
A34: Monthly Total | B34: =SUM(B3:B33) -> 288 | C34: =SUM(C3:C33) -> 0 | D34: =SUM(D3:D33) -> 129 | E34: =SUM(E3:E33) -> 0.26 | F34: =SUM(F3:F33) -> 0 | G34: =SUM(G3:G33) -> 0
A35: WY Total | B35: =SUM(B34+'Apr 2021'!B34) -> 6568 | C35: =SUM(C34+'Apr 2021'!C34) -> 3290 | D35: =SUM(D34+'Apr 2021'!D34) -> 6820 | E35: =SUM(E34+'Apr 2021'!E34) -> 4.11 | F35: =SUM(F34+'Apr 2021'!F34) -> 10.9 | G35: =SUM(G34+'Apr 2021'!G34) -> 0
A37: Acre Feet | B37: =SUM(B3:B33)*1.9835 -> 571.248 | C37: =SUM(C3:C33)*1.9835 -> 0 | D37: =SUM(D3:D33)*1.9835 -> 255.8715
A39: WY AF Total | B39: =SUM(B37+'Apr 2021'!B38) -> 13920.203 | C39: =SUM(C37+'Apr 2021'!C38) -> 6555.4675 | D39: =SUM(D37+'Apr 2021'!D38) -> 14713.603
G41: * COMPUTATIONAL PURPOSES ONLY! Do Not Enter Data in the Red Columns
A43: *This is computation purposes only for Station 48
A44: Sta 48
F45: =SUM(24-D45) -> 24 | G45: =SUM(C45+E45) -> 0 | H45: =SUM(C45/24*D45+G45/24*F45) -> 0
F46: =SUM(24-D46) -> 24 | G46: =SUM(C46+E46) -> 0 | H46: =SUM(C46/24*D46+G46/24*F46) -> 0
F47: =SUM(24-D47) -> 24 | G47: =SUM(C47+E47) -> 0 | H47: =SUM(C47/24*D47+G47/24*F47) -> 0
F48: =SUM(24-D48) -> 24 | G48: =SUM(C48+E48) -> 0 | H48: =SUM(C48/24*D48+G48/24*F48) -> 0
F49: =SUM(24-D49) -> 24 | G49: =SUM(C49+E49) -> 0 | H49: =SUM(C49/24*D49+G49/24*F49) -> 0
A51: Use for more than 1 change in a day.
A52: **Station 48: | B52: Time | C52: Current CFS | D52: Hours Run | E52: +/- cfs | F52: Sub-total cfs
F53: =SUM(C53/24*D53) -> 0
F54: =SUM(C54/24*D54) -> 0
F55: =SUM(C55/24*D55) -> 0
F56: =SUM(C56/24*D56) -> 0
F57: =SUM(C57/24*D57) -> 0
A58: Total Hours Run | D58: =SUM(D53:D57) -> 0 | E58: Total/Day cfs | F58: =SUM(F53:F57) -> 0

Sheet Apr 2021
A1: DATE | B1: STATION 48 | C1: ANDERSON-ROSE | D1: J CANAL | E1: TULE LAKE PRECIP | F1: TULE LAKE SNOW | G1: D PLANT | H1: TULE LAKE ELEV. | I1: CHANGES @ STATION 48
B2: (in CFS) | C2: (in CFS) | D2: (in CFS) | G2: (in AF)
A3: 44287 | B3: 40 | C3: 15 | D3: 21 | E3: 0 | F3: 0 | G3: 0 | H3: 4034.1
A4: =A3+1 -> 44288 | B4: 40 | C4: 0 | D4: 38 | E4: 0 | F4: 0 | G4: 0 | H4: 4034.1
A5: =A4+1 -> 44289 | B5: 40 | C5: 0 | D5: 40 | E5: 0 | F5: 0 | G5: 0 | H5: 4034.1
A6: =A5+1 -> 44290 | B6: 40 | C6: 0 | D6: 40 | E6: 0 | F6: 0 | G6: 0 | H6: 4034.1
A7: =A6+1 -> 44291 | B7: 37 | C7: 0 | D7: 30 | E7: 0 | F7: 0 | G7: 0 | H7: 4034.08 | I7: * 9:00 40/35
A8: =A7+1 -> 44292 | B8: 35 | C8: 0 | D8: 35 | E8: 0 | F8: 0 | G8: 0 | H8: 4034.08
A9: =A8+1 -> 44293 | B9: 35 | C9: 0 | D9: 48 | E9: 0 | F9: 0 | G9: 0 | H9: 4034.06
A10: =A9+1 -> 44294 | B10: 35 | C10: 0 | D10: 45 | E10: 0 | F10: 0 | G10: 0 | H10: 4034.06
A11: =A10+1 -> 44295 | B11: 35 | C11: 0 | D11: 39 | E11: 0 | F11: 0 | G11: 0 | H11: 4034.04
A12: =A11+1 -> 44296 | B12: 19 | C12: 0 | D12: 38 | E12: 0 | F12: 0 | G12: 0 | H12: 4034.04 | I12: * 8:30 35/10
A13: =A12+1 -> 44297 | B13: 7 | C13: 0 | D13: 36 | E13: 0 | F13: 0 | G13: 0 | H13: 4034.02 | I13: * 16:00 10/0
A14: =A13+1 -> 44298 | B14: 0 | C14: 0 | D14: 24 | E14: 0 | F14: 0 | G14: 0 | H14: 4033.99
A15: =A14+1 -> 44299 | B15: 0 | C15: 0 | D15: 17 | E15: 0 | F15: 0 | G15: 0 | H15: 4033.96
A16: =A15+1 -> 44300 | B16: 0 | C16: 0 | D16: 16 | E16: 0 | F16: 0 | G16: 0 | H16: 4033.93
A17: =A16+1 -> 44301 | B17: 3 | C17: 0 | D17: 15 | E17: 0 | F17: 0 | G17: 0 | H17: 4033.9 | I17: * 16:30 0/10
A18: =A17+1 -> 44302 | B18: 8 | C18: 0 | D18: 15 | E18: 0 | F18: 0 | G18: 0 | H18: 4033.87 | I18: * 12:00 10/5
A19: =A18+1 -> 44303 | B19: 5 | C19: 0 | D19: 15 | E19: 0 | F19: 0 | G19: 0 | H19: 4033.84
A20: =A19+1 -> 44304 | B20: 5 | C20: 0 | D20: 10 | E20: 0 | F20: 0 | G20: 0 | H20: 4033.81
A21: =A20+1 -> 44305 | B21: 5 | C21: 0 | D21: 10 | E21: 0 | F21: 0 | G21: 0 | H21: 4033.78
A22: =A21+1 -> 44306 | B22: 5 | C22: 0 | D22: 8 | E22: 0.04 | F22: 0 | G22: 0 | H22: 4033.76
A23: =A22+1 -> 44307 | B23: 5 | C23: 0 | D23: 8 | E23: 0 | F23: 0 | G23: 0 | H23: 4033.74
A24: =A23+1 -> 44308 | B24: 5 | C24: 0 | D24: 7 | E24: 0 | F24: 0 | G24: 0 | H24: 4033.7
A25: =A24+1 -> 44309 | B25: 5 | C25: 0 | D25: 6 | E25: 0 | F25: 0 | G25: 0 | H25: 4033.66
A26: =A25+1 -> 44310 | B26: 5 | C26: 0 | D26: 6 | E26: 0.32 | F26: 0 | G26: 0 | H26: 4033.64
A27: =A26+1 -> 44311 | B27: 5 | C27: 0 | D27: 6 | E27: 0.19 | F27: 0 | G27: 0 | H27: 4033.6
A28: =A27+1 -> 44312 | B28: 5 | C28: 0 | D28: 5 | E28: 0.14 | F28: 0.5 | G28: 0 | H28: 4033.6
A29: =A28+1 -> 44313 | B29: 5 | C29: 0 | D29: 5 | E29: 0.02 | F29: 0 | G29: 0 | H29: 4033.58
A30: =A29+1 -> 44314 | B30: 8 | C30: 0 | D30: 5 | E30: 0 | F30: 0 | G30: 0 | H30: 4033.56 | I30: * 16:00 5/15
A31: =A30+1 -> 44315 | B31: 8 | C31: 0 | D31: 5 | E31: 0 | F31: 0 | G31: 0 | H31: 4033.54 | I31: * 08:00 15/5
A32: =A31+1 -> 44316 | B32: 5 | C32: 0 | D32: 5 | E32: 0 | F32: 0 | G32: 0 | H32: 4033.52
A33: Monthly Total | B33: =SUM(B3:B32) -> 450 | C33: =SUM(C3:C32) -> 15 | D33: =SUM(D3:D32) -> 598 | E33: =SUM(E3:E32) -> 0.71 | F33: =SUM(F3:F32) -> 0.5 | G33: =SUM(G3:G32) -> 0
A34: WY Total | B34: =SUM(B33+'Mar 2021'!B35) -> 6280 | C34: =SUM(C33+'Mar 2021'!C35) -> 3290 | D34: =SUM(D33+'Mar 2021'!D35) -> 6691 | E34: =SUM(E33+'Mar 2021'!E35) -> 3.85 | F34: =SUM(F33+'Mar 2021'!F35) -> 10.9 | G34: =SUM(G33+'Mar 2021'!G35) -> 0
A36: Acre Feet | B36: =SUM(B3:B33)*1.9835 -> 1785.15 | C36: =SUM(C3:C33)*1.9835 -> 59.505 | D36: =SUM(D3:D33)*1.9835 -> 2372.266
A38: WY AF Total | B38: =SUM(B36+'Mar 2021'!B39) -> 13348.955 | C38: =SUM(C36+'Mar 2021'!C39) -> 6555.4675 | D38: =SUM(D36+'Mar 2021'!D39) -> 14457.731
G40: * COMPUTATIONAL PURPOSES ONLY! Do Not Enter Data in the Red Columns
A42: *This is computation purposes only for Station 48
A43: Sta 48
F44: =SUM(24-D44) -> 24 | G44: =SUM(C44+E44) -> 0 | H44: =SUM(C44/24*D44+G44/24*F44) -> 0
...

Sheet Mar 2021
A1: DATE | B1: STATION 48 | C1: ANDERSON-ROSE | D1: J CANAL | E1: TULE LAKE PRECIP | F1: TULE LAKE SNOW | G1: D PLANT | H1: TULE LAKE ELEV. | I1: CHANGES @ STATION 48
B2: (in CFS) | C2: (in CFS) | D2: (in CFS) | G2: (in AF)
A3: 44256 | B3: 0 | C3: 15 | D3: 0 | E3: 0 | F3: 0 | G3: 0 | H3: 4033.95
A4: =A3+1 -> 44257 | B4: 0 | C4: 15 | D4: 0 | E4: 0 | F4: 0 | G4: 0 | H4: 4033.95
A5: =A4+1 -> 44258 | B5: 0 | C5: 15 | D5: 0 | E5: 0 | F5: 0 | G5: 0 | H5: 4033.95
A6: =A5+1 -> 44259 | B6: 0 | C6: 15 | D6: 0 | E6: 0 | F6: 0 | G6: 0 | H6: 4033.95
A7: =A6+1 -> 44260 | B7: 31 | C7: 15 | D7: 0 | E7: 0 | F7: 0 | G7: 0 | H7: 4033.95 | I7: * 09:00 0/50
A8: =A7+1 -> 44261 | B8: 43 | C8: 55 | D8: 0 | E8: 0.05 | F8: 0.1 | G8: 0 | H8: 4033.95 | I8: * 16:00 50/30
A9: 44262 | B9: 30 | C9: 55 | D9: 0 | E9: 0 | F9: 0 | G9: 0 | H9: 4033.95
A10: 44263 | B10: 30 | C10: 42 | D10: 0 | E10: 0 | F10: 0 | G10: 0 | H10: 4033.96
A11: 44264 | B11: 30 | C11: 40 | D11: 0 | E11: 0 | F11: 0 | G11: 0 | H11: 4033.96
A12: 44265 | B12: 30 | C12: 45 | D12: 0 | E12: 0.05 | F12: 0 | G12: 0 | H12: 4033.99
A13: 44266 | B13: 30 | C13: 50 | D13: 0 | E13: T | F13: 0 | G13: 0 | H13: 4034.02
A14: 44267 | B14: 30 | C14: 48 | D14: 0 | E14: 0 | F14: 0 | G14: 0 | H14: 4034.04
A15: 44268 | B15: 30 | C15: 45 | D15: 0 | E15: 0 | F15: 0 | G15: 0 | H15: 4034.06
A16: 44269 | B16: 30 | C16: 45 | D16: 0 | E16: 0 | F16: 0 | G16: 0 | H16: 4034.08
A17: =A16+1 -> 44270 | B17: 30 | C17: 45 | D17: 0 | E17: 0.22 | F17: 3 | G17: 0 | H17: 4034.08
A18: =A17+1 -> 44271 | B18: 30 | C18: 45 | D18: 0 | E18: 0 | F18: 0 | G18: 0 | H18: 4034.08
A19: =A18+1 -> 44272 | B19: 35 | C19: 45 | D19: 0 | E19: 0 | F19: 0 | G19: 0 | H19: 4034.08 | I19: * 12:00 30/40
A20: =A19+1 -> 44273 | B20: 40 | C20: 45 | D20: 0 | E20: 0 | F20: 0 | G20: 0 | H20: 4034.08
A21: =A20+1 -> 44274 | B21: 40 | C21: 48 | D21: 0 | E21: 0.02 | F21: 0 | G21: 0 | H21: 4034.08
A22: =A21+1 -> 44275 | B22: 40 | C22: 55 | D22: 0 | E22: 0 | F22: 0 | G22: 0 | H22: 4034.08
A23: =A22+1 -> 44276 | B23: 40 | C23: 55 | D23: 0 | E23: 0 | F23: 0 | G23: 0 | H23: 4034.08
A24: =A23+1 -> 44277 | B24: 40 | C24: 55 | D24: 0 | E24: 0.03 | F24: 0 | G24: 0 | H24: 4034.08
A25: =A24+1 -> 44278 | B25: 40 | C25: 55 | D25: 0 | E25: T | F25: 0 | G25: 0 | H25: 4034.09
A26: =A25+1 -> 44279 | B26: 40 | C26: 53 | D26: 0 | E26: 0 | F26: 0 | G26: 0 | H26: 4034.1
A27: =A26+1 -> 44280 | B27: 40 | C27: 50 | D27: 0 | E27: T | F27: 0 | G27: 0 | H27: 4034.1
A28: =A27+1 -> 44281 | B28: 40 | C28: 50 | D28: 0 | E28: 0 | F28: 0 | G28: 0 | H28: 4034.11
A29: =A28+1 -> 44282 | B29: 40 | C29: 50 | D29: 0 | E29: T | F29: 0 | G29: 0 | H29: 4034.12
A30: =A29+1 -> 44283 | B30: 40 | C30: 45 | D30: 0 | E30: 0 | F30: 0 | G30: 0 | H30: 4034.12
A31: =A30+1 -> 44284 | B31: 40 | C31: 40 | D31: 0 | E31: 0 | F31: 0 | G31: 0 | H31: 4034.1
A32: =A31+1 -> 44285 | B32: 40 | C32: 40 | D32: 0 | E32: 0 | F32: 0 | G32: 0 | H32: 4034.1
A33: =A32+1 -> 44286 | B33: 40 | C33: 40 | D33: 0 | E33: 0 | F33: 0 | G33: 0 | H33: 4034.1
A34: Monthly Total | B34: =SUM(B3:B33) -> 969 | C34: =SUM(C3:C33) -> 1316 | D34: =SUM(D3:D33) -> 0 | E34: =SUM(E3:E33) -> 0.37 | F34: =SUM(F3:F33) -> 3.1 | G34: =SUM(G3:G33) -> 0
A35: WY Total | B35: =SUM(B34+'Feb 2021'!B33) -> 5830 | C35: =SUM(C34+'Feb 2021'!C33) -> 3275 | D35: =SUM(D34+'Feb 2021'!D33) -> 6093 | E35: =SUM(E34+'Feb 2021'!E33) -> 3.14 | F35: =SUM(F34+'Feb 2021'!F33) -> 10.4 | G35: =SUM(G34+'Feb 2021'!G33) -> 0
A37: Acre Feet | B37: =SUM(B3:B33)*1.9835 -> 1922.0115 | C37: =SUM(C3:C33)*1.9835 -> 2610.286 | D37: =SUM(D3:D33)*1.9835 -> 0
A39: WY AF Total | B39: =SUM(B37+'Feb 2021'!B37) -> 11563.805 | C39: =SUM(C37+'Feb 2021'!C37) -> 6495.9625 | D39: =SUM(D37+'Feb 2021'!D37) -> 12085.466
G41: * COMPUTATIONAL PURPOSES ONLY! Do Not Enter Data in the Red Columns
A43: *This is computation purposes only for Station 48
A44: Sta 48
...

Sheet Feb 2021
A1: DATE | B1: STATION 48 | C1: ANDERSON-ROSE | D1: J CANAL | E1: TULE LAKE PRECIP | F1: TULE LAKE SNOW | G1: D PLANT | H1: TULE LAKE ELEV. | I1: CHANGES @ STATION 48
B2: (in CFS) | C2: (in CFS) | D2: (in CFS) | G2: (in AF)
A3: 44228 | B3: 0 | C3: 15 | D3: 0 | E3: 0 | F3: 0 | G3: 0 | H3: 4033.78
A4: =A3+1 -> 44229 | B4: 0 | C4: 15 | D4: 0 | E4: 0.01 | F4: 0 | G4: 0 | H4: 4033.78
A5: =A4+1 -> 44230 | B5: 0 | C5: 15 | D5: 0 | E5: 0.03 | F5: 0 | G5: 0 | H5: 4033.78
A6: =A5+1 -> 44231 | B6: 0 | C6: 15 | D6: 0 | E6: 0.01 | F6: 0 | G6: 0 | H6: 4033.78
A7: =A6+1 -> 44232 | B7: 0 | C7: 15 | D7: 0 | E7: 0 | F7: 0 | G7: 0 | H7: 4033.78
A8: =A7+1 -> 44233 | B8: 0 | C8: 15 | D8: 0 | E8: 0 | F8: 0 | G8: 0 | H8: 4033.78
A9: =A8+1 -> 44234 | B9: 0 | C9: 15 | D9: 0 | E9: 0 | F9: 0 | G9: 0 | H9: 4033.78
A10: =A9+1 -> 44235 | B10: 0 | C10: 15 | D10: 0 | E10: T | F10: 0 | G10: 0 | H10: 4033.78
A11: =A10+1 -> 44236 | B11: 0 | C11: 15 | D11: 0 | E11: 0 | F11: 0 | G11: 0 | H11: 4033.78
A12: =A11+1 -> 44237 | B12: 0 | C12: 15 | D12: 0 | E12: 0 | F12: 0 | G12: 0 | H12: 4033.78
A13: =A12+1 -> 44238 | B13: 0 | C13: 15 | D13: 0 | E13: 0.05 | F13: 0 | G13: 0 | H13: 4033.78
A14: =A13+1 -> 44239 | B14: 0 | C14: 15 | D14: 0 | E14: 0.01 | F14: 0 | G14: 0 | H14: 4033.78
A15: =A14+1 -> 44240 | B15: 0 | C15: 15 | D15: 0 | E15: 0.17 | F15: 0 | G15: 0 | H15: 4033.8
A16: =A15+1 -> 44241 | B16: 0 | C16: 15 | D16: 0 | E16: 0.03 | F16: 0.1 | G16: 0 | H16: 4033.8
A17: =A16+1 -> 44242 | B17: 0 | C17: 15 | D17: 0 | E17: 0.25 | F17: 0.5 | G17: 0 | H17: 4033.8
A18: =A17+1 -> 44243 | B18: 0 | C18: 15 | D18: 0 | E18: T | F18: 0 | G18: 0 | H18: 4033.82
A19: =A18+1 -> 44244 | B19: 0 | C19: 15 | D19: 0 | E19: 0 | F19: 0 | G19: 0 | H19: 4033.82
A20: =A19+1 -> 44245 | B20: 0 | C20: 15 | D20: 0 | E20: 0.05 | F20: 2 | G20: 0 | H20: 4033.84
A21: =A20+1 -> 44246 | B21: 0 | C21: 19 | D21: 0 | E21: 0.14 | F21: 0 | G21: 0 | H21: 4033.84
A22: =A21+1 -> 44247 | B22: 0 | C22: 25 | D22: 0 | E22: 0.01 | F22: 0 | G22: 0 | H22: 4033.86
A23: =A22+1 -> 44248 | B23: 0 | C23: 19 | D23: 0 | E23: 0.01 | F23: 0 | G23: 0 | H23: 4033.88
A24: =A23+1 -> 44249 | B24: 0 | C24: 15 | D24: 0 | E24: T | F24: 0 | G24: 0 | H24: 4033.9
A25: =A24+1 -> 44250 | B25: 0 | C25: 15 | D25: 0 | E25: 0 | F25: 0 | G25: 0 | H25: 4033.9
A26: =A25+1 -> 44251 | B26: 0 | C26: 15 | D26: 0 | E26: 0 | F26: 0 | G26: 0 | H26: 4033.94
A27: =A26+1 -> 44252 | B27: 0 | C27: 15 | D27: 0 | E27: 0 | F27: 0 | G27: 0 | H27: 4033.94
A28: =A27+1 -> 44253 | B28: 0 | C28: 15 | D28: 0 | E28: 0 | F28: 0 | G28: 0 | H28: 4033.94
A29: =A28+1 -> 44254 | B29: 0 | C29: 15 | D29: 0 | E29: 0 | F29: 0 | G29: 0 | H29: 4033.95
A30: =A29+1 -> 44255 | B30: 0 | C30: 15 | D30: 0 | E30: 0 | F30: 0 | G30: 0 | H30: 4033.95
A32: Monthly Total | B32: =SUM(B3:B31) -> 0 | C32: =SUM(C3:C31) -> 438 | D32: =SUM(D3:D31) -> 0 | E32: =SUM(E3:E31) -> 0.77 | F32: =SUM(F3:F31) -> 2.6 | G32: =SUM(G3:G31) -> 0
A33: WY Total | B33: =SUM(B32+'Jan 2021'!B35) -> 4861 | C33: =SUM(C32+'Jan 2021'!C35) -> 1959 | D33: =SUM(D32+'Jan 2021'!D35) -> 6093 | E33: =SUM(E32+'Jan 2021'!E35) -> 2.77 | F33: =SUM(F32+'Jan 2021'!F35) -> 7.3 | G33: =SUM(G32+'Jan 2021'!G35) -> 0
A35: Acre Feet | B35: =SUM(B3:B31)*1.9835 -> 0 | C35: =SUM(C3:C31)*1.9835 -> 868.773 | D35: =SUM(D3:D31)*1.9835 -> 0
A37: WY AF Total | B37: =SUM(B35+'Jan 2021'!B39) -> 9641.7935 | C37: =SUM(C35+'Jan 2021'!C39) -> 3885.6765 | D37: =SUM(D35+'Jan 2021'!D39) -> 12085.466
G39: * COMPUTATIONAL PURPOSES ONLY! Do Not Enter Data in the Red Columns
A41: *This is computation purposes only for Station 48
A42: Sta 48
F43: =SUM(24-D43) -> 24 | G43: =SUM(C43+E43) -> 0 | H43: =SUM(C43/24*D43+G43/24*F43) -> 0
F44: =SUM(24-D44) -> 24 | G44: =SUM(C44+E44) -> 0 | H44: =SUM(C44/24*D44+G44/24*F44) -> 0
F45: =SUM(24-D45) -> 24 | G45: =SUM(C45+E45) -> 0 | H45: =SUM(C45/24*D45+G45/24*F45) -> 0
...

Sheet Jan 2021
A1: DATE | B1: STATION 48 | C1: ANDERSON-ROSE | D1: J CANAL | E1: TULE LAKE PRECIP | F1: TULE LAKE SNOW | G1: D PLANT | H1: TULE LAKE ELEV. | I1: CHANGES @ STATION 48
B2: (in CFS) | C2: (in CFS) | D2: (in CFS) | G2: (in AF)
A3: 44197 | B3: 0 | C3: 15 | D3: 0 | E3: 0.02 | F3: 0 | G3: 0 | H3: 4033.7
A4: =A3+1 -> 44198 | B4: 0 | C4: 15 | D4: 0 | E4: 0.03 | F4: 0 | G4: 0 | H4: 4033.7
A5: =A4+1 -> 44199 | B5: 0 | C5: 15 | D5: 0 | E5: 0 | F5: 0 | G5: 0 | H5: 4033.7
A6: =A5+1 -> 44200 | B6: 0 | C6: 15 | D6: 0 | E6: 0.04 | F6: 0 | G6: 0 | H6: 4033.7
A7: =A6+1 -> 44201 | B7: 0 | C7: 15 | D7: 0 | E7: T | F7: 0 | G7: 0 | H7: 4033.72
A8: =A7+1 -> 44202 | B8: 0 | C8: 15 | D8: 0 | E8: T | F8: 0 | G8: 0 | H8: 4033.72
A9: =A8+1 -> 44203 | B9: 0 | C9: 24 | D9: 0 | E9: 0.01 | F9: 0 | G9: 0 | H9: 4033.72
A10: =A9+1 -> 44204 | B10: 0 | C10: 30 | D10: 0 | E10: 0.12 | F10: 0 | G10: 0 | H10: 4033.74
A11: =A10+1 -> 44205 | B11: 0 | C11: 30 | D11: 0 | E11: T | F11: 0 | G11: 0 | H11: 4033.74
A12: =A11+1 -> 44206 | B12: 0 | C12: 27 | D12: 0 | E12: 0 | F12: 0 | G12: 0 | H12: 4033.76
A13: =A12+1 -> 44207 | B13: 0 | C13: 12 | D13: 0 | E13: T | F13: 0 | G13: 0 | H13: 4033.76
A14: =A13+1 -> 44208 | B14: 0 | C14: 12 | D14: 0 | E14: 0 | F14: 0 | G14: 0 | H14: 4033.76
A15: =A14+1 -> 44209 | B15: 0 | C15: 12 | D15: 0 | E15: 0.05 | F15: 0 | G15: 0 | H15: 4033.76
A16: =A15+1 -> 44210 | B16: 0 | C16: 12 | D16: 0 | E16: T | F16: 0 | G16: 0 | H16: 4033.78
A17: =A16+1 -> 44211 | B17: 0 | C17: 12 | D17: 0 | E17: 0.01 | F17: 0 | G17: 0 | H17: 4033.78
A18: =A17+1 -> 44212 | B18: 0 | C18: 12 | D18: 0 | E18: 0.02 | F18: 0 | G18: 0 | H18: 4033.78
A19: =A18+1 -> 44213 | B19: 0 | C19: 12 | D19: 0 | E19: 0.01 | F19: 0 | G19: 0 | H19: 4033.8
A20: =A19+1 -> 44214 | B20: 0 | C20: 12 | D20: 0 | E20: 0 | F20: 0 | G20: 0 | H20: 4033.8
A21: =A20+1 -> 44215 | B21: 0 | C21: 12 | D21: 0 | E21: 0.02 | F21: T | G21: 0 | H21: 4033.8
A22: =A21+1 -> 44216 | B22: 0 | C22: 12 | D22: 0 | E22: 0 | F22: 0 | G22: 0 | H22: 4033.8
A23: =A22+1 -> 44217 | B23: 0 | C23: 12 | D23: 0 | E23: 0 | F23: 0 | G23: 0 | H23: 4033.8
A24: =A23+1 -> 44218 | B24: 0 | C24: 14 | D24: 0 | E24: 0 | F24: 0 | G24: 0 | H24: 4033.8
A25: =A24+1 -> 44219 | B25: 0 | C25: 15 | D25: 0 | E25: 0 | F25: 0 | G25: 0 | H25: 4033.8
A26: =A25+1 -> 44220 | B26: 0 | C26: 15 | D26: 0 | E26: 0 | F26: 0 | G26: 0 | H26: 4033.8
A27: =A26+1 -> 44221 | B27: 0 | C27: 15 | D27: 0 | E27: 0 | F27: 0 | G27: 0 | H27: 4033.8
A28: =A27+1 -> 44222 | B28: 0 | C28: 15 | D28: 0 | E28: 0 | F28: 0 | G28: 0 | H28: 4033.78
A29: =A28+1 -> 44223 | B29: 0 | C29: 15 | D29: 0 | E29: 0 | F29: 0 | G29: 0 | H29: 4033.78
A30: =A29+1 -> 44224 | B30: 0 | C30: 15 | D30: 0 | E30: 0.04 | F30: 0 | G30: 0 | H30: 4033.78
A31: =A30+1 -> 44225 | B31: 0 | C31: 15 | D31: 0 | E31: 0.01 | F31: 0 | G31: 0 | H31: 4033.78
A32: =A31+1 -> 44226 | B32: 0 | C32: 15 | D32: 0 | E32: 0 | F32: 0 | G32: 0 | H32: 4033.78
A33: =A32+1 -> 44227 | B33: 0 | C33: 15 | D33: 0 | E33: 0 | F33: 0 | G33: 0 | H33: 4033.78
A34: Monthly Total | B34: =SUM(B3:B33) -> 0 | C34: =SUM(C3:C33) -> 482 | D34: =SUM(D3:D33) -> 0 | E34: =SUM(E3:E33) -> 0.38 | F34: =SUM(F3:F33) -> 0 | G34: =SUM(G3:G33) -> 0
A35: WY Total | B35: =SUM(B34+'Dec 2020'!B35) -> 4861 | C35: =SUM(C34+'Dec 2020'!C35) -> 1521 | D35: =SUM(D34+'Dec 2020'!D35) -> 6093 | E35: =SUM(E34+'Dec 2020'!E35) -> 2 | F35: =SUM(F34+'Dec 2020'!F35) -> 4.7 | G35: =SUM(G34+'Dec 2020'!G35) -> 0
A37: Acre Feet | B37: =SUM(B3:B33)*1.9835 -> 0 | C37: =SUM(C3:C33)*1.9835 -> 956.047 | D37: =SUM(D3:D33)*1.9835 -> 0
A39: WY AF Total | B39: =SUM(B37+'Dec 2020'!B39) -> 9641.7935 | C39: =SUM(C37+'Dec 2020'!C39) -> 3016.9035 | D39: =SUM(D37+'Dec 2020'!D39) -> 12085.466
G41: * COMPUTATIONAL PURPOSES ONLY! Do Not Enter Data in the Red Columns
A43: *This is computation purposes only for Station 48
A44: Sta 48
...

Sheet Dec 2020
A1: DATE | B1: STATION 48 | C1: ANDERSON-ROSE | D1: J CANAL | E1: TULE LAKE PRECIP | F1: TULE LAKE SNOW | G1: D PLANT | H1: TULE LAKE ELEV. | I1: CHANGES @ STATION 48
B2: (in CFS) | C2: (in CFS) | D2: (in CFS) | G2: (in AF)
A3: 44166 | B3: 0 | C3: 0 | D3: 8 | E3: 0 | F3: 0 | G3: 0 | H3: 4033.6
A4: =A3+1 -> 44167 | B4: 0 | C4: 0 | D4: 0 | E4: 0 | F4: 0 | G4: 0 | H4: 4033.58
A5: =A4+1 -> 44168 | B5: 0 | C5: 0 | D5: 0 | E5: 0 | F5: 0 | G5: 0 | H5: 4033.58
A6: =A5+1 -> 44169 | B6: 0 | C6: 0 | D6: 0 | E6: 0 | F6: 0 | G6: 0 | H6: 4033.54
A7: =A6+1 -> 44170 | B7: 0 | C7: 0 | D7: 0 | E7: 0 | F7: 0 | G7: 0 | H7: 4033.54
A8: =A7+1 -> 44171 | B8: 0 | C8: 0 | D8: 0 | E8: 0.06 | F8: 0 | G8: 0 | H8: 4033.52
A9: =A8+1 -> 44172 | B9: 0 | C9: 0 | D9: 0 | E9: 0.01 | F9: 0 | G9: 0 | H9: 4033.52
A10: =A9+1 -> 44173 | B10: 0 | C10: 0 | D10: 0 | E10: 0 | F10: 0 | G10: 0 | H10: 4033.5
A11: =A10+1 -> 44174 | B11: 0 | C11: 0 | D11: 0 | E11: 0 | F11: 0 | G11: 0 | H11: 4033.5
A12: =A11+1 -> 44175 | B12: 0 | C12: 0 | D12: 0 | E12: 0 | F12: 0 | G12: 0 | H12: 4033.5
A13: =A12+1 -> 44176 | B13: 0 | C13: 5 | D13: 0 | E13: 0 | F13: 0 | G13: 0 | H13: 4033.54
A14: =A13+1 -> 44177 | B14: 0 | C14: 10 | D14: 0 | E14: 0.11 | F14: 1.5 | G14: 0 | H14: 4033.56
A15: =A14+1 -> 44178 | B15: 0 | C15: 10 | D15: 0 | E15: 0.01 | F15: 0 | G15: 0 | H15: 4033.58
A16: =A15+1 -> 44179 | B16: 0 | C16: 10 | D16: 0 | E16: 0.1 | F16: 0 | G16: 0 | H16: 4033.6
A17: =A16+1 -> 44180 | B17: 0 | C17: 16 | D17: 0 | E17: 0.09 | F17: 0 | G17: 0 | H17: 4033.6 | I17: correction to Anderson Rose
A18: =A17+1 -> 44181 | B18: 0 | C18: 20 | D18: 0 | E18: 0 | F18: 0 | G18: 0 | H18: 4033.62 | I18: "
A19: =A18+1 -> 44182 | B19: 0 | C19: 20 | D19: 0 | E19: 0.11 | F19: 0 | G19: 0 | H19: 4033.64 | I19: "
A20: =A19+1 -> 44183 | B20: 0 | C20: 17 | D20: 0 | E20: 0 | F20: 0 | G20: 0 | H20: 4033.65 | I20: "
A21: =A20+1 -> 44184 | B21: 0 | C21: 15 | D21: 0 | E21: 0 | F21: 0 | G21: 0 | H21: 4033.66 | I21: "
A22: =A21+1 -> 44185 | B22: 0 | C22: 15 | D22: 0 | E22: 0 | F22: 0 | G22: 0 | H22: 4033.66 | I22: "
A23: =A22+1 -> 44186 | B23: 0 | C23: 15 | D23: 0 | E23: 0 | F23: 0 | G23: 0 | H23: 4033.66
A24: =A23+1 -> 44187 | B24: 0 | C24: 15 | D24: 0 | E24: T | F24: 0 | G24: 0 | H24: 4033.67
A25: =A24+1 -> 44188 | B25: 0 | C25: 15 | D25: 0 | E25: T | F25: 0 | G25: 0 | H25: 4033.67
A26: =A25+1 -> 44189 | B26: 0 | C26: 15 | D26: 0 | E26: 0 | F26: 0 | G26: 0 | H26: 4033.68
A27: =A26+1 -> 44190 | B27: 0 | C27: 14 | D27: 0 | E27: 0 | F27: 0 | G27: 0 | H27: 4033.68
A28: =A27+1 -> 44191 | B28: 0 | C28: 10 | D28: 0 | E28: 0 | F28: 0 | G28: 0 | H28: 4033.68
A29: =A28+1 -> 44192 | B29: 0 | C29: 10 | D29: 0 | E29: T | F29: 0 | G29: 0 | H29: 4033.7
A30: =A29+1 -> 44193 | B30: 0 | C30: 10 | D30: 0 | E30: 0 | F30: 0 | G30: 0 | H30: 4033.7
A31: =A30+1 -> 44194 | B31: 0 | C31: 10 | D31: 0 | E31: 0 | F31: 0 | G31: 0 | H31: 4033.7
A32: =A31+1 -> 44195 | B32: 0 | C32: 10 | D32: 0 | E32: 0 | F32: 0 | G32: 0 | H32: 4033.7
A33: =A32+1 -> 44196 | B33: 0 | C33: 10 | D33: 0 | E33: 0.2 | F33: 3 | G33: 0 | H33: 4033.7
A34: Monthly Total | B34: =SUM(B3:B33) -> 0 | C34: =SUM(C3:C33) -> 272 | D34: =SUM(D3:D33) -> 8 | E34: =SUM(E3:E33) -> 0.69 | F34: =SUM(F3:F33) -> 4.5 | G34: =SUM(G3:G33) -> 0
A35: WY Total | B35: =SUM(B34+'Nov 2020'!B34) -> 4861 | C35: =SUM(C34+'Nov 2020'!C34) -> 1039 | D35: =SUM(D34+'Nov 2020'!D34) -> 6093 | E35: =SUM(E34+'Nov 2020'!E34) -> 1.62 | F35: =SUM(F34+'Nov 2020'!F34) -> 4.7 | G35: =SUM(G34+'Nov 2020'!G34) -> 0
A37: Acre Feet | B37: =SUM(B3:B33)*1.9835 -> 0 | C37: =SUM(C3:C33)*1.9835 -> 539.512 | D37: =SUM(D3:D33)*1.9835 -> 15.868
A39: WY AF Total | B39: =SUM('Nov 2020'!B38+B37) -> 9641.7935 | C39: =SUM('Nov 2020'!C38+C37) -> 2060.8565 | D39: =SUM('Nov 2020'!D38+D37) -> 12085.466
G41: * COMPUTATIONAL PURPOSES ONLY! Do Not Enter Data in the Red Columns
A43: *This is computation purposes only for Station 48
A44: Sta 48
...

Sheet Nov 2020
A1: DATE | B1: STATION 48 | C1: ANDERSON-ROSE | D1: J CANAL | E1: TULE LAKE PRECIP | F1: TULE LAKE SNOW | G1: D PLANT | H1: TULE LAKE ELEV. | I1: CHANGES @ STATION 48
B2: (in CFS) | C2: (in CFS) | D2: (in CFS) | G2: (in AF)
A3: 44136 | B3: 125 | C3: 0 | D3: 130 | E3: 0 | F3: 0 | G3: 0 | H3: 4033.88
A4: =A3+1 -> 44137 | B4: 125 | C4: 0 | D4: 139 | E4: 0 | F4: 0 | G4: 0 | H4: 4033.84
A5: =A4+1 -> 44138 | B5: 125 | C5: 0 | D5: 145 | E5: 0 | F5: 0 | G5: 0 | H5: 4033.8
A6: =A5+1 -> 44139 | B6: 168 | C6: 0 | D6: 141 | E6: 0 | F6: 0 | G6: 0 | H6: 4033.75 | I6: * 00:00 125/175 * 17:00 175/150
A7: =A6+1 -> 44140 | B7: 127 | C7: 0 | D7: 109 | E7: 0 | F7: 0 | G7: 0 | H7: 4033.73 | I7: * 13:00 150/100
A8: =A7+1 -> 44141 | B8: 92 | C8: 0 | D8: 84 | E8: 0.06 | F8: 0 | G8: 0 | H8: 4033.7 | I8: * 16:00 100/75
A9: =A8+1 -> 44142 | B9: 75 | C9: 0 | D9: 80 | E9: T | F9: 0 | G9: 0 | H9: 4033.68
A10: =A9+1 -> 44143 | B10: 67 | C10: 0 | D10: 69 | E10: 0.02 | F10: 0.2 | G10: 0 | H10: 4033.68 | I10: * 16:00 75/50
A11: =A10+1 -> 44144 | B11: 50 | C11: 0 | D11: 56 | E11: 0 | F11: 0 | G11: 0 | H11: 4034.68
A12: =A11+1 -> 44145 | B12: 39 | C12: 0 | D12: 52 | E12: 0 | F12: 0 | G12: 0 | H12: 4034.67 | I12: * 13:00 50/25
A13: =A12+1 -> 44146 | B13: 19 | C13: 0 | D13: 46 | E13: 0 | F13: 0 | G13: 0 | H13: 4034.67 | I13: * 18:00 25/0
A14: =A13+1 -> 44147 | B14: 0 | C14: 0 | D14: 41 | E14: 0 | F14: 0 | G14: 0 | H14: 4034.66
A15: =A14+1 -> 44148 | B15: 0 | C15: 0 | D15: 42 | E15: 0.13 | F15: 0 | G15: 0 | H15: 4034.66
A16: =A15+1 -> 44149 | B16: 0 | C16: 0 | D16: 51 | E16: 0.03 | F16: 0 | G16: 0 | H16: 4034.65
A17: =A16+1 -> 44150 | B17: 0 | C17: 0 | D17: 54 | E17: 0.31 | F17: 0 | G17: 0 | H17: 4034.65
A18: =A17+1 -> 44151 | B18: 0 | C18: 0 | D18: 54 | E18: 0.02 | F18: 0 | G18: 0 | H18: 4034.66
A19: =A18+1 -> 44152 | B19: 0 | C19: 0 | D19: 48 | E19: 0.01 | F19: 0 | G19: 0 | H19: 4034.66
A20: =A19+1 -> 44153 | B20: 0 | C20: 0 | D20: 52 | E20: 0.21 | F20: 0 | G20: 0 | H20: 4034.66
A21: =A20+1 -> 44154 | B21: 0 | C21: 0 | D21: 53 | E21: 0.01 | F21: 0 | G21: 0 | H21: 4034.66
A22: =A21+1 -> 44155 | B22: 0 | C22: 0 | D22: 53 | E22: 0 | F22: 0 | G22: 0 | H22: 4034.65
A23: =A22+1 -> 44156 | B23: 0 | C23: 0 | D23: 38 | E23: 0.01 | F23: 0 | G23: 0 | H23: 4034.65
A24: =A23+1 -> 44157 | B24: 0 | C24: 0 | D24: 30 | E24: 0 | F24: 0 | G24: 0 | H24: 4034.65
A25: =A24+1 -> 44158 | B25: 0 | C25: 0 | D25: 30 | E25: 0 | F25: 0 | G25: 0 | H25: 4034.64
... A32: =A31+1 -> 44165 | B32: 0 | C32: 0 | D32: 20 | E32: 0 | F32: 0 | G32: 0 | H32: 4033.6
A33: Monthly Total | B33: =SUM(B3:B32) -> 1012 | C33: =SUM(C3:C32) -> 0 | D33: =SUM(D3:D32) -> 1775 | E33: =SUM(E3:E32) -> 0.88 | F33: =SUM(F3:F32) -> 0.2 | G33: =SUM(G3:G32) -> 0
A34: WY Total | B34: =SUM(B33+'Oct 2020'!B35) -> 4861 | C34: =SUM(C33+'Oct 2020'!C35) -> 767 | D34: =SUM(D33+'Oct 2020'!D35) -> 6085 | E34: =SUM(E33+'Oct 2020'!E35) -> 0.93 | F34: =SUM(F33+'Oct 2020'!F35) -> 0.2 | G34: =SUM(G33+'Oct 2020'!G35) -> 0
A36: Acre Feet | B36: =SUM(B3:B32)*1.9835 -> 2007.302 | C36: =SUM(C3:C32)*1.9835 -> 0 | D36: =SUM(D3:D32)*1.9835 -> 3520.7125
A38: WY AF Total | B38: =SUM('Oct 2020'!B39+B36) -> 9641.7935 | C38: =SUM('Oct 2020'!C39+C36) -> 1521.3445 | D38: =SUM('Oct 2020'!D39+D36) -> 12069.597
G40: * COMPUTATIONAL PURPOSES ONLY! Do Not Enter Data in the Red Columns
A42: *This is computation purposes only for Station 48
A43: Sta 48
F44: =SUM(24-D44) -> 24 | G44: =SUM(C44+E44) -> 0 | H44: =SUM(C44/24*D44+G44/24*F44) -> 0
F45: =SUM(24-D45) -> 24 | G45: =SUM(C45+E45) -> 0 | H45: =SUM(C45/24*D45+G45/24*F45) -> 0
F46: =SUM(24-D46) -> 24 | G46: =SUM(C46+E46) -> 0 | H46: =SUM(C46/24*D46+G46/24*F46) -> 0
F47: =SUM(24-D47) -> 24 | G47: =SUM(C47+E47) -> 0 | H47: =SUM(C47/24*D47+G47/24*F47) -> 0
F48: =SUM(24-D48) -> 24 | G48: =SUM(C48+E48) -> 0 | H48: =SUM(C48/24*D48+G48/24*F48) -> 0
A50: Use for more than 1 change in a day.
A51: **Station 48: | B51: Time | C51: Current CFS | D51: Hours Run | E51: +/- cfs | F51: Sub-total cfs
...

Sheet Oct 2020
A1: DATE | B1: STATION 48 | C1: ANDERSON-ROSE | D1: J CANAL | E1: TULE LAKE PRECIP | F1: TULE LAKE SNOW | G1: D PLANT | H1: TULE LAKE ELEV. | I1: CHANGES @ STATION 48
B2: (in CFS) | C2: (in CFS) | D2: (in CFS)
A3: 44105 | B3: 135 | C3: 0 | D3: 124 | E3: 0 | F3: 0 | G3: 0 | H3: 4034.45 | I3: * 14:00 125/150 | J3: Sump 1A - 50
A4: 44106 | B4: 138 | C4: 25 | D4: 115 | E4: 0 | F4: 0 | G4: 0 | H4: 4034.43 | I4: * 12:00 150/125 | J4: Sump 1A - 50
A5: 44107 | B5: 125 | C5: 56 | D5: 115 | E5: 0 | F5: 0 | G5: 0 | H5: 4034.42 | J5: Sump 1A - 50
A6: 44108 | B6: 125 | C6: 53 | D6: 117 | E6: 0 | F6: 0 | G6: 0 | H6: 4034.41 | J6: Sump 1A - 50
A7: 44109 | B7: 125 | C7: 70 | D7: 134 | E7: 0 | F7: 0 | G7: 0 | H7: 4034.4 | J7: Sump 1A - 50
A8: 44110 | B8: 135 | C8: 50 | D8: 141 | E8: 0 | F8: 0 | G8: 0 | H8: 4034.38 | I8: * 14:00 125/150 | J8: Sump 1A - 50
A9: 44111 | B9: 163 | C9: 50 | D9: 143 | E9: 0 | F9: 0 | G9: 0 | H9: 4034.36 | I9: * 12:00 150/175 | J9: Sump 1A - 50
A10: 44112 | B10: 166 | C10: 50 | D10: 146 | E10: 0 | F10: 0 | G10: 0 | H10: 4034.35 | I10: * 15:00 175/150 | J10: Sump 1A - 50
A11: 44113 | B11: 150 | C11: 50 | D11: 150 | E11: 0 | F11: 0 | G11: 0 | H11: 4034.33 | J11: Sump 1A - 50
A12: 44114 | B12: 136 | C12: 50 | D12: 150 | E12: 0.05 | F12: 0 | G12: 0 | H12: 4034.32 | I12: * 11:00 150/125 | J12: Sump 1A - 50 | L12: correction to St 48 and J-canal
A13: 44115 | B13: 125 | C13: 50 | D13: 157 | E13: T | F13: 0 | G13: 0 | H13: 4034.31 | J13: Sump 1A - 50
A14: 44116 | B14: 134 | C14: 50 | D14: 176 | E14: 0 | F14: 0 | G14: 0 | H14: 4034.3 | I14: * 15:00 125/150 | J14: Sump 1A - 50
A15: 44117 | B15: 164 | C15: 50 | D15: 173 | E15: 0 | F15: 0 | G15: 0 | H15: 4034.29 | I15: * 10:30 150/175 | J15: Sump 1A - 50
A16: 44118 | B16: 175 | C16: 50 | D16: 167 | E16: 0 | F16: 0 | G16: 0 | H16: 4034.28 | J16: Sump 1A - 50
A17: 44119 | B17: 150 | C17: 50 | D17: 150 | E17: 0 | F17: 0 | G17: 0 | H17: 4034.26 | I17: * 12:00 175/125 | J17: Sump 1A - * 12:00 50/0
A18: 44120 | B18: 125 | C18: 38 | D18: 148 | E18: 0 | F18: 0 | G18: 0 | H18: 4034.24
A19: 44121 | B19: 125 | C19: 0 | D19: 160 | E19: 0 | F19: 0 | G19: 0 | H19: 4034.22
A20: 44122 | B20: 125 | C20: 0 | D20: 145 | E20: 0 | F20: 0 | G20: 0 | H20: 4034.2
A21: 44123 | B21: 114 | C21: 0 | D21: 130 | E21: 0 | F21: 0 | G21: 0 | H21: 4034.18 | I21: * 1300 125/100
A22: 44124 | B22: 100 | C22: 0 | D22: 131 | E22: 0 | F22: 0 | G22: 0 | H22: 4034.17
A23: 44125 | B23: 91 | C23: 10 | D23: 144 | E23: 0 | F23: 0 | G23: 0 | H23: 4034.16 | I23: * 1500 100/75
A24: 44126 | B24: 75 | C24: 10 | D24: 129 | E24: 0 | F24: 0 | G24: 0 | H24: 4034.15
A25: 44127 | B25: 75 | C25: 5 | D25: 127 | E25: 0 | F25: 0 | G25: 0 | H25: 4034.14
A26: 44128 | B26: 75 | C26: 0 | D26: 123 | E26: 0 | F26: 0 | G26: 0 | H26: 4034.12
A27: 44129 | B27: 87 | C27: 0 | D27: 114 | E27: 0 | F27: 0 | G27: 0 | H27: 4034.12 | I27: * 12:30 75/100
A28: 44130 | B28: 100 | C28: 0 | D28: 126 | E28: 0 | F28: 0 | G28: 0 | H28: 4034.1
A29: 44131 | B29: 111 | C29: 0 | D29: 147 | E29: 0 | F29: 0 | G29: 0 | H29: 4034.07 | I29: * 13:30 100/125
A30: 44132 | B30: 125 | C30: 0 | D30: 139 | E30: 0 | F30: 0 | G30: 0 | H30: 4034.04
A31: 44133 | B31: 125 | C31: 0 | D31: 132 | E31: 0 | F31: 0 | G31: 0 | H31: 4034
A32: 44134 | B32: 125 | C32: 0 | D32: 127 | E32: 0 | F32: 0 | G32: 0 | H32: 4033.96
A33: 44135 | B33: 125 | C33: 0 | D33: 130 | E33: 0 | F33: 0 | G33: 0 | H33: 4033.92
A34: Monthly Total | B34: =SUM(B3:B33) -> 3849 | C34: =SUM(C3:C33) -> 767 | D34: =SUM(D3:D33) -> 4310 | E34: =SUM(E3:E33) -> 0.05 | F34: =SUM(F3:F33) -> 0 | G34: =SUM(G3:G33) -> 0
A35: WY Total | B35: =SUM(B34+'Oct 2020'!B36) -> 3849 | C35: =SUM(C34+'Oct 2020'!C36) -> 767 | D35: =SUM(D34+'Oct 2020'!D36) -> 4310 | E35: =SUM(E34+'Oct 2020'!E36) -> 0.05 | F35: =SUM(F34+'Oct 2020'!F36) -> 0 | G35: =SUM(G34+'Oct 2020'!G36) -> 0
A37: Acre Feet | B37: =SUM(B3:B33)*1.9835 -> 7634.4915 | C37: =SUM(C3:C33)*1.9835 -> 1521.3445 | D37: =SUM(D3:D33)*1.9835 -> 8548.885
A39: WY AF Total | B39: =SUM('Oct 2020'!B40+B37) -> 7634.4915 | C39: =SUM('Oct 2020'!C40+C37) -> 1521.3445 | D39: =SUM('Oct 2020'!D40+D37) -> 8548.885
G41: * COMPUTATIONAL PURPOSES ONLY! Do Not Enter Data in the Red Columns
A43: *This is computation purposes only for Station 48
A44: Sta 48
...
