Workbook

Sheet Sep 2024
A1: DATE | B1: LRDC | C1: STATION 48 | D1: ANDERSON-ROSE | E1: J CANAL | F1: TULE LAKE PRECIP | G1: TULE LAKE SNOW | H1: D PLANT | I1: TULE LAKE ELEV. | J1: CHANGES @ STATION 48
B2: (in CFS) | C2: (in CFS) | D2: (in CFS) | E2: (in CFS) | H2: (in AF)
A3: 45536 | B3: 0 | C3: 275 | D3: 100 | E3: 322 | F3: 0 | G3: 0 | H3: 0 | J3: * 14:00 300/250
A4: =A3+1 -> 45537 | B4: 0 | C4: 250 | D4: 100 | E4: 294 | F4: 0 | G4: 0 | H4: 0
A5: =A4+1 -> 45538 | B5: 0 | C5: 229 | D5: 100 | E5: 265 | F5: 0 | G5: 0 | H5: 0 | J5: * 14:00 250/200
A6: =A5+1 -> 45539 | B6: 0 | C6: 222 | D6: 100 | E6: 300 | F6: 0 | G6: 0 | H6: 0 | J6: * 13:30 200/250
A7: =A6+1 -> 45540 | B7: 0 | C7: 272 | D7: 100 | E7: 298 | F7: 0 | G7: 0 | H7: 0 | J7: * 15:30 250/300
A8: =A7+1 -> 45541 | B8: 0 | C8: 321 | D8: 100 | E8: 277 | F8: 0 | G8: 0 | H8: 0 | J8: * 07:00 300/350 * 350/300
A9: =A8+1 -> 45542 | B9: 0 | C9: 300 | D9: 100 | E9: 284 | F9: 0 | G9: 0 | H9: 0
A10: =A9+1 -> 45543 | B10: 0 | C10: 271 | D10: 100 | E10: 283 | F10: 0 | G10: 0 | H10: 0 | J10: * 10:00 300/250
A11: =A10+1 -> 45544 | B11: 0 | C11: 250 | D11: 116 | E11: 287 | F11: 0 | G11: 0 | H11: 0
A12: =A11+1 -> 45545 | B12: 0 | C12: 160 | D12: 115 | E12: 284 | F12: 0 | G12: 0 | H12: 0 | J12: * 08:00 250/100 14:00 100/125
A13: =A12+1 -> 45546 | B13: 0 | C13: 115 | D13: 29 | E13: 271 | F13: 0.01 | G13: 0 | H13: 0 | J13: * 14:00 125/100
A14: =A13+1 -> 45547 | B14: 0 | C14: 97 | D14: 0 | E14: 274 | F14: 0 | G14: 0 | H14: 0 | J14: * 10:00 100/75 13:00 75/100
A15: =A14+1 -> 45548 | B15: 0 | C15: 100 | D15: 0 | E15: 258 | F15: 0 | G15: 0 | H15: 0
A16: =A15+1 -> 45549 | B16: 0 | C16: 116 | D16: 0 | E16: 242 | F16: 0 | G16: 0 | H16: 0 | J16: * 09:00 100/125
A17: =A16+1 -> 45550 | B17: 0 | C17: 99 | D17: 0 | E17: 222 | F17: 0.01 | G17: 0 | H17: 0 | J17: * 10:00 125/100 * 13:00 100/75
A18: =A17+1 -> 45551 | B18: 0 | C18: 59 | D18: 39 | E18: 190 | F18: 0.07 | G18: 0 | H18: 0 | J18: * 13:00 75/50
A19: =A18+1 -> 45552 | B19: 0 | C19: 18 | D19: 61 | E19: 177 | F19: 0.03 | G19: 0 | H19: 0 | J19: * 08:00 50/25 09:00 25/0
A20: =A19+1 -> 45553 | B20: 0 | C20: 0 | D20: 72 | E20: 151 | F20: 0.04 | G20: 0 | H20: 0
A21: =A20+1 -> 45554 | B21: 0 | C21: 0 | D21: 83 | E21: 133 | F21: 0 | G21: 0 | H21: 0
A22: =A21+1 -> 45555 | B22: 0 | C22: 0 | D22: 86 | E22: 169 | F22: 0 | G22: 0 | H22: 0
A23: =A22+1 -> 45556 | B23: 0 | C23: 0 | D23: 35 | E23: 149 | F23: 0 | G23: 0 | H23: 0
A24: =A23+1 -> 45557 | B24: 0 | C24: 0 | D24: 29 | E24: 151 | F24: 0 | G24: 0 | H24: 0
A25: =A24+1 -> 45558 | B25: 0 | C25: 56 | D25: 2 | E25: 250 | F25: 0 | G25: 0 | H25: 0 | J25: * 08:00 0/50 * 50/100
A26: =A25+1 -> 45559 | B26: 0 | C26: 77 | D26: 0 | E26: 281 | F26: 0 | G26: 0 | H26: 0 | J26: * 13:00 100/50
A27: =A26+1 -> 45560 | B27: 0 | C27: 44 | D27: 0 | E27: 258 | F27: 0 | G27: 0 | H27: 0 | J27: * 21:00 50/0
A28: =A27+1 -> 45561 | B28: 0 | C28: 0 | D28: 5 | E28: 229 | F28: 0 | G28: 0 | H28: 0
A29: =A28+1 -> 45562 | B29: 0 | C29: 0 | D29: 1 | E29: 206 | F29: 0 | G29: 0 | H29: 0
A30: =A29+1 -> 45563 | B30: 0 | C30: 0 | D30: 0 | E30: 181 | F30: 0 | G30: 0 | H30: 0
A31: =A30+1 -> 45564 | B31: 0 | C31: 0 | D31: 0 | E31: 174 | F31: 0 | G31: 0 | H31: 0
A32: =A31+1 -> 45565 | B32: 0 | C32: 0 | D32: 0 | E32: 176
A33: Monthly Total | B33: =SUM(B3:B32) -> 0 | C33: =SUM(C3:C32) -> 3331 | D33: =SUM(D3:D32) -> 1473 | E33: =SUM(E3:E32) -> 7036 | F33: =SUM(F3:F32) -> 0.16 | G33: =SUM(G3:G32) -> 0 | H33: =SUM(H3:H32) -> 0
A34: WY Total | B34: =SUM(B33+'Aug 2024'!B35) -> 0 | C34: =SUM(C33+'Aug 2024'!C35) -> 61072 | D34: =SUM(D33+'Aug 2024'!D35) -> 25789 | E34: =SUM(E33+'Aug 2024'!E35) -> 88351 | F34: =SUM(F33+'Aug 2024'!F35) -> 8.93 | G34: =SUM(G33+'Aug 2024'!G35) -> 10.65 | H34: =SUM(H33+'Aug 2024'!H35) -> 6707
A36: Acre Feet | B36: =SUM(B3:B32)*1.9835 -> 0 | C36: =SUM(C3:C32)*1.9835 -> 6607.0385 | D36: =SUM(D3:D32)*1.9835 -> 2921.6955 | E36: =SUM(E3:E32)*1.9835 -> 13955.906
A38: WY AF Total | B38: =SUM(B36+'Aug 2024'!B39) -> 0 | C38: =SUM(C36+'Aug 2024'!C39) -> 128893.78 | D38: =SUM(D36+'Aug 2024'!D39) -> 58816.726 | E38: =SUM(E36+'Aug 2024'!E39) -> 183455.9
H40: * COMPUTATIONAL PURPOSES ONLY! Do Not Enter Data in the Red Columns
A42: *This is computation purposes only for Station 48
A43: Sta 48
G44: =SUM(24-E44) -> 24 | H44: =SUM(D44+F44) -> 0 | I44: =SUM(D44/24*E44+H44/24*G44) -> 0
...

Sheet Aug 2024
A1: DATE | B1: LRDC | C1: STATION 48 | D1: ANDERSON-ROSE | E1: J CANAL | F1: TULE LAKE PRECIP | G1: TULE LAKE SNOW | H1: D PLANT | I1: TULE LAKE ELEV. | J1: CHANGES @ STATION 48
B2: (in CFS) | C2: (in CFS) | D2: (in CFS) | E2: (in CFS) | H2: (in AF)
A3: 45505 | B3: 0 | C3: 400 | D3: 0 | E3: 517 | F3: 0 | G3: 0 | H3: 0 | I3: -
A4: =A3+1 -> 45506 | B4: 0 | C4: 400 | D4: 0 | E4: 507 | F4: 0 | G4: 0 | H4: 0 | I4: -
A5: =A4+1 -> 45507 | B5: 0 | C5: 400 | D5: 0 | E5: 504 | F5: 0 | G5: 0 | H5: 0 | I5: -
A6: =A5+1 -> 45508 | B6: 0 | C6: 378 | D6: 0 | E6: 491 | F6: 0 | G6: 0 | H6: 0 | I6: - | J6: * 13:30 400/350
A7: =A6+1 -> 45509 | B7: 0 | C7: 328 | D7: 2 | E7: 439 | F7: 0 | G7: 0 | H7: 0 | I7: - | J7: * 13:30 350/300
A8: =A7+1 -> 45510 | B8: 0 | C8: 300 | D8: 0 | E8: 437 | F8: 0 | G8: 0 | H8: 0 | I8: -
A9: =A8+1 -> 45511 | B9: 0 | C9: 300 | D9: 0 | E9: 460 | F9: 0 | G9: 0 | H9: 0 | I9: -
A10: =A9+1 -> 45512 | B10: 0 | C10: 300 | D10: 0 | E10: 426 | F10: 0 | G10: 0 | H10: 0 | I10: -
A11: =A10+1 -> 45513 | B11: 0 | C11: 300 | D11: 0 | E11: 414 | F11: 0 | G11: 0 | H11: 0 | I11: -
A12: =A11+1 -> 45514 | B12: 0 | C12: 283 | D12: 0 | E12: 405 | F12: 0 | G12: 0 | H12: 0 | I12: - | J12: * 16:00 300/250
A13: =A12+1 -> 45515 | B13: 0 | C13: 250 | D13: 0 | E13: 409 | F13: 0 | G13: 0 | H13: 0 | I13: -
A14: =A13+1 -> 45516 | B14: 0 | C14: 292 | D14: 0 | E14: 401 | F14: 0 | G14: 0 | H14: 0 | J14: * 07:00 250/300 * 10:30 300/350 * 13:30 350/300
A15: =A14+1 -> 45517 | B15: 0 | C15: 321 | D15: 0 | E15: 422 | F15: 0 | G15: 0 | H15: 0 | J15: * 13:45 300/350
A16: =A15+1 -> 45518 | B16: 0 | C16: 385 | D16: 0 | E16: 466 | F16: 0 | G16: 0 | H16: 0 | J16: * 07:00 350/400
A17: =A16+1 -> 45519 | B17: 0 | C17: 400 | D17: 0 | E17: 486 | F17: 0.17 | G17: 0 | H17: 0 | J17: * 08:00 400/350 *09:30 350/300
A18: =A17+1 -> 45520 | B18: 0 | C18: 332 | D18: 16 | E18: 522 | F18: 0 | G18: 0 | H18: 0 | J18: * 10:00 300/400
A19: =A18+1 -> 45521 | B19: 0 | C19: 400 | D19: 74 | E19: 489 | F19: 0 | G19: 0 | H19: 0
A20: =A19+1 -> 45522 | B20: 0 | C20: 400 | D20: 100 | E20: 503 | F20: 0 | G20: 0 | H20: 0 | J20: * 14:00 400/450
A21: =A20+1 -> 45523 | B21: 0 | C21: 421 | D21: 100 | E21: 535 | F21: 0 | G21: 0 | H21: 0
A22: =A21+1 -> 45524 | B22: 0 | C22: 450 | D22: 100 | E22: 539 | F22: 0 | G22: 0 | H22: 0
A23: =A22+1 -> 45525 | B23: 0 | C23: 450 | D23: 100 | E23: 539 | F23: 0 | G23: 0 | H23: 0
A24: =A23+1 -> 45526 | B24: 0 | C24: 450 | D24: 100 | E24: 549 | F24: 0 | G24: 0 | H24: 0
A25: =A24+1 -> 45527 | B25: 0 | C25: 398 | D25: 110 | E25: 542 | F25: 0.21 | G25: 0 | H25: 0 | J25: * 07:00 450/400 * 16:00 400/350
A26: =A25+1 -> 45528 | B26: 0 | C26: 350 | D26: 116 | E26: 497 | F26: 0.25 | G26: 0 | H26: 0
A27: =A26+1 -> 45529 | B27: 0 | C27: 282 | D27: 125 | E27: 430 | F27: 0 | G27: 0 | H27: 0 | J27: * 07:00 350/300 09:30 300/250
A28: =A27+1 -> 45530 | C28: 217 | D28: 102 | E28: 379 | J28: * 08:00 250/200
A29: =A28+1 -> 45531 | C29: 200 | D29: 100 | E29: 361
A30: =A29+1 -> 45532 | C30: 252 | D30: 100 | E30: 346 | J30: * 00:00 200/250 * 23:00 250/300
A31: =A30+1 -> 45533 | C31: 336 | D31: 100 | E31: 315 | J31: * 06:30 300/350
A32: =A31+1 -> 45534 | C32: 350 | D32: 100 | E32: 353 | J32: * 14:00 350/300
A33: =A32+1 -> 45535 | C33: 329 | D33: 100 | E33: 347
A34: Monthly Total | B34: =SUM(B3:B33) -> 0 | C34: =SUM(C3:C33) -> 10654 | D34: =SUM(D3:D33) -> 1545 | E34: =SUM(E3:E33) -> 14030 | F34: =SUM(F3:F33) -> 0.63 | G34: =SUM(G3:G33) -> 0 | H34: =SUM(H3:H33) -> 0
A35: WY Total | B35: =SUM(B34+'Jul 2024'!B35) -> 0 | C35: =SUM(C34+'Jul 2024'!C35) -> 57741 | D35: =SUM(D34+'Jul 2024'!D35) -> 24316 | E35: =SUM(E34+'Jul 2024'!E35) -> 81315 | F35: =SUM(F34+'Jul 2024'!F35) -> 8.77 | G35: =SUM(G34+'Jul 2024'!G35) -> 10.65 | H35: =SUM(H34+'Jul 2024'!H35) -> 6707
A37: Acre Feet | B37: =SUM(B3:B33)*1.9835 -> 0 | C37: =SUM(C3:C33)*1.9835 -> 21132.209 | D37: =SUM(D3:D33)*1.9835 -> 3064.5075 | E37: =SUM(E3:E33)*1.9835 -> 27828.505
A39: WY AF Total | B39: =SUM(B37+'Jul 2024'!B39) -> 0 | C39: =SUM(C37+'Jul 2024'!C39) -> 122286.74 | D39: =SUM(D37+'Jul 2024'!D39) -> 55895.03 | E39: =SUM(E37+'Jul 2024'!E39) -> 169499.99
H41: * COMPUTATIONAL PURPOSES ONLY! Do Not Enter Data in the Red Columns
A43: *This is computation purposes only for Station 48
A44: Sta 48
...

Sheet Jul 2024
A1: DATE | B1: LRDC | C1: STATION 48 | D1: ANDERSON-ROSE | E1: J CANAL | F1: TULE LAKE PRECIP | G1: TULE LAKE SNOW | H1: D PLANT | I1: TULE LAKE ELEV. | J1: CHANGES @ STATION 48
B2: (in CFS) | C2: (in CFS) | D2: (in CFS) | E2: (in CFS) | H2: (in AF)
A3: 45474 | B3: 0 | C3: 319 | D3: 3 | E3: 466 | F3: 0 | G3: 0 | H3: 0 | I3: - | J3: * 09:00 350/300
A4: =A3+1 -> 45475 | B4: 0 | C4: 335 | D4: 0 | E4: 439 | F4: 0 | G4: 0 | H4: 0 | I4: - | J4: * 07:00 300/350
A5: =A4+1 -> 45476 | B5: 0 | C5: 399 | D5: 0 | E5: 443 | F5: 0 | G5: 0 | H5: 0 | I5: - | J5: * 07:30 350/400 * 09:00 400/450 *16:00 450/400
A6: =A5+1 -> 45477 | B6: 0 | C6: 330 | D6: 0 | E6: 419 | F6: 0 | G6: 0 | H6: 0 | I6: - | J6: * 08:00 400/350 * 14:30 350/300
A7: =A6+1 -> 45478 | B7: 0 | C7: 300 | D7: 0 | E7: 405 | F7: 0 | G7: 0 | H7: 0 | I7: -
A8: =A7+1 -> 45479 | B8: 0 | C8: 300 | D8: 0 | E8: 403 | F8: 0 | G8: 0 | H8: 0 | I8: -
A9: =A8+1 -> 45480 | B9: 0 | C9: 300 | D9: 0 | E9: 390 | F9: 0 | G9: 0 | H9: 0 | I9: -
A10: =A9+1 -> 45481 | B10: 0 | C10: 331 | D10: 0 | E10: 427 | F10: 0 | G10: 0 | H10: 0 | I10: - | J10: * 09:00 300/350
A11: =A10+1 -> 45482 | B11: 0 | C11: 350 | D11: 0 | E11: 383 | F11: 0 | G11: 0 | H11: 0 | I11: -
A12: =A11+1 -> 45483 | B12: 0 | C12: 350 | D12: 0 | E12: 414 | F12: 0 | G12: 0 | H12: 0 | I12: -
A13: =A12+1 -> 45484 | B13: 0 | C13: 381 | D13: 0 | E13: 410 | F13: 0 | G13: 0 | H13: 0 | I13: - | J13: * 09:00 350/400
A14: =A13+1 -> 45485 | B14: 0 | C14: 421 | D14: 0 | E14: 458 | F14: 0 | G14: 0 | H14: 0 | I14: - | J14: * 14:00 400/450
A15: =A14+1 -> 45486 | B15: 0 | C15: 460 | D15: 0 | E15: 488 | F15: 0 | G15: 0 | H15: 0 | I15: - | J15: * 10:00 450/500 * 15:00 500/450
A16: =A15+1 -> 45487 | B16: 0 | C16: 416 | D16: 15 | E16: 485 | F16: 0 | G16: 0 | H16: 0 | I16: - | J16: * 07:30 450/400
A17: =A16+1 -> 45488 | B17: 0 | C17: 419 | D17: 11 | E17: 509 | F17: 0 | G17: 0 | H17: 0 | I17: - | J17: * 15:00 400/450
A18: =A17+1 -> 45489 | B18: 0 | C18: 450 | D18: 10 | E18: 557 | F18: 0 | G18: 0 | H18: 0 | I18: -
A19: =A18+1 -> 45490 | B19: 0 | C19: 386 | D19: 25 | E19: 555 | F19: 0 | G19: 0 | H19: 0 | I19: - | J19: * 08:00 450/400 * 09:30 400/350
A20: =A19+1 -> 45491 | B20: 0 | C20: 419 | D20: 19 | E20: 572 | F20: 0 | G20: 0 | H20: 0 | I20: - | J20: * 07:00 350/400 * 08:00 400/450
A21: =A20+1 -> 45492 | B21: 0 | C21: 481 | D21: 0 | E21: 561 | F21: 0 | G21: 0 | H21: 0 | I21: - | J21: * 09:00 450/500
A22: =A21+1 -> 45493 | B22: 0 | C22: 479 | D22: 0 | E22: 574 | F22: 0 | G22: 0 | H22: 0 | I22: - | J22: * 14:00 500/450
A23: =A22+1 -> 45494 | B23: 0 | C23: 429 | D23: 0 | E23: 579 | F23: 0 | G23: 0 | H23: 0 | I23: - | J23: *14:00 450/400
A24: =A23+1 -> 45495 | B24: 0 | C24: 385 | D24: 0 | E24: 561 | F24: 0 | G24: 0 | H24: 0 | I24: - | J24: *07:30 400/350 *14:30 350/400
A25: =A24+1 -> 45496 | B25: 0 | C25: 441 | D25: 0 | E25: 545 | F25: 0 | G25: 0 | H25: 0 | I25: - | J25: * 12:30 400/450 * 16:00 450/500
A26: =A25+1 -> 45497 | B26: 0 | C26: 466 | D26: 0 | E26: 552 | F26: 0 | G26: 0 | H26: 0 | I26: - | J26: * 07:30 500/450
A27: =A26+1 -> 45498 | B27: 0 | C27: 431 | D27: 0 | E27: 537 | F27: 0 | G27: 0 | H27: 0 | I27: - | J27: * 15:00 450/400
A28: =A27+1 -> 45499 | B28: 0 | C28: 400 | D28: 3 | E28: 515 | F28: 0 | G28: 0 | H28: 0 | I28: -
A29: =A28+1 -> 45500 | B29: 0 | C29: 365 | D29: 26 | E29: 544 | F29: 0 | G29: 0 | H29: 0 | I29: - | J29: * 07:00 400/350
A30: =A29+1 -> 45501 | B30: 0 | C30: 350 | D30: 4 | E30: 557 | F30: 0 | G30: 0 | H30: 0 | I30: -
A31: =A30+1 -> 45502 | B31: 0 | C31: 350 | D31: 0 | E31: 573 | F31: 0 | G31: 0 | H31: 0
A32: =A31+1 -> 45503 | B32: 0 | C32: 372 | D32: 0 | E32: 548 | F32: 0 | G32: 0 | H32: 0 | J32: * 13:30 350/400
A33: =A32+1 -> 45504 | B33: 0 | C33: 414 | D33: 0 | E33: 535 | F33: 0 | G33: 0 | H33: 0 | J33: * 07:00 400/450 * 13:30 450/400
A34: Monthly Total | B34: =SUM(B3:B33) -> 0 | C34: =SUM(C3:C33) -> 12029 | D34: =SUM(D3:D33) -> 116 | E34: =SUM(E3:E33) -> 15404 | F34: =SUM(F3:F33) -> 0 | G34: =SUM(G3:G33) -> 0 | H34: =SUM(H3:H33) -> 0
A35: WY Total | B35: =SUM(B34+'Jun 2024'!B34) -> 0 | C35: =SUM(C34+'Jun 2024'!C34) -> 47087 | D35: =SUM(D34+'Jun 2024'!D34) -> 22771 | E35: =SUM(E34+'Jun 2024'!E34) -> 67285 | F35: =SUM(F34+'Jun 2024'!F34) -> 8.14 | G35: =SUM(G34+'Jun 2024'!G34) -> 10.65 | H35: =SUM(H34+'Jun 2024'!H34) -> 6707
A37: Acre Feet | B37: =SUM(B3:B33)*1.9835 -> 0 | C37: =SUM(C3:C33)*1.9835 -> 23859.521 | D37: =SUM(D3:D33)*1.9835 -> 230.086 | E37: =SUM(E3:E33)*1.9835 -> 30553.834
A39: WY AF Total | B39: =SUM(B37+'Jun 2024'!B38) -> 0 | C39: =SUM(C37+'Jun 2024'!C38) -> 101154.53 | D39: =SUM(D37+'Jun 2024'!D38) -> 52830.523 | E39: =SUM(E37+'Jun 2024'!E38) -> 141671.49
H41: * COMPUTATIONAL PURPOSES ONLY! Do Not Enter Data in the Red Columns
A43: *This is computation purposes only for Station 48
A44: Sta 48
...

Sheet Jun 2024
A1: DATE | B1: LRDC | C1: STATION 48 | D1: ANDERSON-ROSE | E1: J CANAL | F1: TULE LAKE PRECIP | G1: TULE LAKE SNOW | H1: D PLANT | I1: TULE LAKE ELEV. | J1: CHANGES @ STATION 48
B2: (in CFS) | C2: (in CFS) | D2: (in CFS) | E2: (in CFS) | H2: (in AF)
A3: 45444 | B3: 0 | C3: 244 | D3: 52 | E3: 347 | F3: 0 | G3: 0 | H3: 0 | I3: - | J3: * 07:00 300/250 14:00 250/200
A4: =A3+1 -> 45445 | B4: 0 | C4: 180 | D4: 31 | E4: 315 | F4: 0 | G4: 0 | H4: 0 | I4: - | J4: * 14:30 200/150
A5: =A4+1 -> 45446 | B5: 0 | C5: 150 | D5: 21 | E5: 326 | F5: 0.01 | G5: 0 | H5: 0 | I5: -
A6: =A5+1 -> 45447 | B6: 0 | C6: 150 | D6: 0 | E6: 348 | F6: 0 | G6: 0 | H6: 0 | I6: -
A7: =A6+1 -> 45448 | B7: 0 | C7: 171 | D7: 0 | E7: 365 | F7: 0 | G7: 0 | H7: 0 | I7: - | J7: * 14:00 150/200
A8: =A7+1 -> 45449 | B8: 0 | C8: 246 | D8: 0 | E8: 360 | F8: 0 | G8: 0 | H8: 0 | I8: - | J8: * 08:30 200/300 * 14:00 300/250 * 23:00 250/300
A9: =A8+1 -> 45450 | B9: 0 | C9: 308 | D9: 0 | E9: 386 | F9: 0 | G9: 0 | H9: 0 | I9: - | J9: * 20:00 300/350
A10: =A9+1 -> 45451 | B10: 0 | C10: 336 | D10: 0 | E10: 411 | F10: 0.15 | G10: 0 | H10: 0 | I10: - | J10: * 17:30 350/300
A11: =A10+1 -> 45452 | B11: 0 | C11: 300 | D11: 0 | E11: 438 | F11: 0.08 | G11: 0 | H11: 0 | I11: -
A12: =A11+1 -> 45453 | B12: 0 | C12: 300 | D12: 2 | E12: 449 | F12: 0 | G12: 0 | H12: 0 | I12: -
A13: =A12+1 -> 45454 | B13: 0 | C13: 300 | D13: 1 | E13: 456 | F13: 0 | G13: 0 | H13: 0 | I13: -
A14: =A13+1 -> 45455 | B14: 0 | C14: 324 | D14: 0 | E14: 454 | F14: 0 | G14: 0 | H14: 0 | I14: - | J14: * 12:30 300/350
A15: =A14+1 -> 45456 | B15: 0 | C15: 410 | D15: 0 | E15: 494 | F15: 0 | G15: 0 | H15: 0 | I15: - | J15: * 10:30 350/400 * 13:45 400/450 19:00450/500
A16: =A15+1 -> 45457 | B16: 0 | C16: 465 | D16: 0 | E16: 544 | F16: 0 | G16: 0 | H16: 0 | I16: - | J16: * 07:00 500/450
A17: =A16+1 -> 45458 | B17: 0 | C17: 454 | D17: 0 | E17: 564 | F17: 0 | G17: 0 | H17: 0 | I17: - | J17: * 2200 450/500
A18: =A17+1 -> 45459 | B18: 0 | C18: 470 | D18: 0 | E18: 569 | F18: 0 | G18: 0 | H18: 0 | I18: - | J18: *0930 500/450
A19: =A18+1 -> 45460 | B19: 0 | C19: 435 | D19: 15 | E19: 581 | F19: 0 | G19: 0 | H19: 0 | I19: - | J19: * 07:00 450/400 * 14:00 400/450
A20: =A19+1 -> 45461 | B20: 0 | C20: 472 | D20: 0 | E20: 599 | F20: 0 | G20: 0 | H20: 0 | I20: - | J20: * 16:00 450/400
A21: =A20+1 -> 45462 | B21: 0 | C21: 413 | D21: 0 | E21: 554 | F21: 0 | G21: 0 | H21: 0 | I21: - | J21: * 18:00 400/450
A22: =A21+1 -> 45463 | B22: 0 | C22: 473 | D22: 0 | E22: 554 | F22: 0 | G22: 0 | H22: 0 | I22: - | J22: * 13:00 450/500
A23: =A22+1 -> 45464 | B23: 0 | C23: 504 | D23: 0 | E23: 568 | F23: 0 | G23: 0 | H23: 0 | I23: - | J23: * 22:00 500/550
A24: =A23+1 -> 45465 | B24: 0 | C24: 550 | D24: 0 | E24: 556 | F24: 0 | G24: 0 | H24: 0 | I24: - | J24: * 07:30 550/500 * 11:00 500/450
A25: =A24+1 -> 45466 | B25: 0 | C25: 450 | D25: 0 | E25: 566 | F25: 0 | G25: 0 | H25: 0 | I25: - | J25: * 08:00 450/400 * 1500 400/450
A26: =A25+1 -> 45467 | B26: 0 | C26: 435 | D26: 0 | E26: 583 | F26: 0 | G26: 0 | H26: 0 | I26: -
A27: =A26+1 -> 45468 | B27: 0 | C27: 501 | D27: 0 | E27: 572 | F27: 0 | G27: 0 | H27: 0 | I27: - | J27: * 06:30 450/500 * 17:00 500/550
A28: =A27+1 -> 45469 | B28: 0 | C28: 515 | D28: 0 | E28: 573 | F28: 0 | G28: 0 | H28: 0 | I28: - | J28: * 07:00 550/500
A29: =A28+1 -> 45470 | B29: 0 | C29: 500 | D29: 0 | E29: 530 | F29: 0 | G29: 0 | H29: 0 | I29: -
A30: =A29+1 -> 45471 | B30: 0 | C30: 500 | D30: 16 | E30: 538 | F30: 0 | G30: 0 | H30: 0 | I30: -
A31: =A30+1 -> 45472 | B31: 0 | C31: 467 | D31: 19 | E31: 540 | F31: 0 | G31: 0 | H31: 0 | I31: - | J31: * 08:00 500/450
A32: =A31+1 -> 45473 | B32: 0 | C32: 400 | D32: 18 | E32: 496 | F32: 0 | G32: 0 | H32: 0 | I32: - | J32: * 10:00 450/400 14:00 400/350
A33: Monthly Total | B33: =SUM(B3:B32) -> 0 | C33: =SUM(C3:C32) -> 11423 | D33: =SUM(D3:D32) -> 175 | E33: =SUM(E3:E32) -> 14636 | F33: =SUM(F3:F32) -> 0.24 | G33: =SUM(G3:G32) -> 0 | H33: =SUM(H3:H32) -> 0
A34: WY Total | B34: =SUM(B33+'May 2024'!B35) -> 0 | C34: =SUM(C33+'May 2024'!C35) -> 35058 | D34: =SUM(D33+'May 2024'!D35) -> 22655 | E34: =SUM(E33+'May 2024'!E35) -> 51881 | F34: =SUM(F33+'May 2024'!F35) -> 8.14 | G34: =SUM(G33+'May 2024'!G35) -> 10.65 | H34: =SUM(H33+'May 2024'!H35) -> 6707
A36: Acre Feet | B36: =SUM(B3:B32)*1.9835 -> 0 | C36: =SUM(C3:C32)*1.9835 -> 22657.52 | D36: =SUM(D3:D32)*1.9835 -> 347.1125 | E36: =SUM(E3:E32)*1.9835 -> 29030.506
A38: WY AF Total | B38: =SUM(B36+'May 2024'!B39) -> 0 | C38: =SUM(C36+'May 2024'!C39) -> 77295.011 | D38: =SUM(D36+'May 2024'!D39) -> 52600.437 | E38: =SUM(E36+'May 2024'!E39) -> 111117.65
H40: * COMPUTATIONAL PURPOSES ONLY! Do Not Enter Data in the Red Columns
A42: *This is computation purposes only for Station 48
A43: Sta 48
G44: =SUM(24-E44) -> 24 | H44: =SUM(D44+F44) -> 0 | I44: =SUM(D44/24*E44+H44/24*G44) -> 0
...

Sheet May 2024
A1: DATE | B1: LRDC | C1: STATION 48 | D1: ANDERSON-ROSE | E1: J CANAL | F1: TULE LAKE PRECIP | G1: TULE LAKE SNOW | H1: D PLANT | I1: TULE LAKE ELEV. | J1: CHANGES @ STATION 48
B2: (in CFS) | C2: (in CFS) | D2: (in CFS) | E2: (in CFS) | H2: (in AF)
A3: 45413 | B3: 0 | C3: 217 | D3: 50 | E3: 245 | F3: 0 | G3: 0 | H3: 0 | I3: - | J3: * 16:00 200/250
A4: =A3+1 -> 45414 | B4: 0 | C4: 250 | D4: 50 | E4: 250 | F4: 0.08 | G4: 0 | H4: 0 | I4: -
A5: =A4+1 -> 45415 | B5: 0 | C5: 250 | D5: 57 | E5: 236 | F5: 0 | G5: 0 | H5: 0 | I5: -
A6: =A5+1 -> 45416 | B6: 0 | C6: 204 | D6: 75 | E6: 222 | F6: 0.22 | G6: 0 | H6: 0 | I6: - | J6: * 12:00 250/200 *14:00 200/150
A7: =A6+1 -> 45417 | B7: 0 | C7: 150 | D7: 75 | E7: 223 | F7: 0.02 | G7: 0 | H7: 0 | I7: -
A8: =A7+1 -> 45418 | B8: 0 | C8: 150 | D8: 86 | E8: 258 | F8: 0 | G8: 0 | H8: 0 | I8: -
A9: =A8+1 -> 45419 | B9: 0 | C9: 185 | D9: 57 | E9: 316 | F9: T | G9: 0 | H9: 0 | I9: - | J9: * 14:00 150/200 17:00 200/250
A10: =A9+1 -> 45420 | B10: 0 | C10: 272 | D10: 22 | E10: 388 | F10: 0 | G10: 0 | H10: 0 | I10: - | J10: * 13:30 250/300
A11: =A10+1 -> 45421 | B11: 0 | C11: 321 | D11: 0 | E11: 403 | F11: 0 | G11: 0 | H11: 0 | I11: - | J11: * 14:00 300/350
A12: =A11+1 -> 45422 | B12: 0 | C12: 350 | D12: 0 | E12: 417 | F12: 0 | G12: 0 | H12: 0 | I12: -
A13: =A12+1 -> 45423 | B13: 0 | C13: 376 | D13: 0 | E13: 439 | F13: 0 | G13: 0 | H13: 0 | I13: - | J13: * 11:30 350/400
A14: =A13+1 -> 45424 | B14: 0 | C14: 433 | D14: 0 | E14: 447 | F14: 0 | G14: 0 | H14: 0 | I14: - | J14: * 08:00 400/450
A15: =A14+1 -> 45425 | B15: 0 | C15: 450 | D15: 54 | E15: 472 | F15: T | G15: 0 | H15: 0 | I15: -
A16: =A15+1 -> 45426 | B16: 0 | C16: 450 | D16: 81 | E16: 466 | F16: 0 | G16: 0 | H16: 0 | I16: -
A17: =A16+1 -> 45427 | B17: 0 | C17: 473 | D17: 39 | E17: 470 | F17: 0 | G17: 0 | H17: 0 | I17: - | J17: * 13:00 450/500
A18: =A17+1 -> 45428 | B18: 0 | C18: 500 | D18: 63 | E18: 486 | F18: 0 | G18: 0 | H18: 0 | I18: -
A19: =A18+1 -> 45429 | B19: 0 | C19: 500 | D19: 100 | E19: 492 | F19: 0 | G19: 0 | H19: 0 | I19: -
A20: =A19+1 -> 45430 | B20: 0 | C20: 500 | D20: 100 | E20: 489 | F20: 0 | G20: 0 | H20: 0 | I20: -
A21: =A20+1 -> 45431 | B21: 0 | C21: 500 | D21: 108 | E21: 474 | F21: 0 | G21: 0 | H21: 0 | I21: -
A22: =A21+1 -> 45432 | B22: 0 | C22: 449 | D22: 156 | E22: 478 | F22: 0 | G22: 0 | H22: 0 | I22: - | J22: *10:00 500/450 * 13:30 450/400
A23: =A22+1 -> 45433 | B23: 0 | C23: 379 | D23: 128 | E23: 436 | F23: 0 | G23: 0 | H23: 0 | I23: - | J23: * 14:00 400/350
A24: =A23+1 -> 45434 | B24: 0 | C24: 317 | D24: 82 | E24: 413 | F24: 0 | G24: 0 | H24: 0 | I24: - | J24: * 08:00 350/300
A25: =A24+1 -> 45435 | B25: 0 | C25: 266 | D25: 89 | E25: 409 | F25: 0 | G25: 0 | H25: 0 | I25: - | J25: * 07:30 300/250
A26: =A25+1 -> 45436 | B26: 0 | C26: 215 | D26: 83 | E26: 408 | F26: 0 | G26: 0 | H26: 0 | I26: - | J26: * 07:00 250/200
A27: =A26+1 -> 45437 | B27: 0 | C27: 200 | D27: 41 | E27: 399 | F27: 0 | G27: 0 | H27: 0 | I27: -
A28: =A27+1 -> 45438 | B28: 0 | C28: 179 | D28: 35 | E28: 363 | F28: 0 | G28: 0 | H28: 0 | I28: - | J28: * 14:00 200/150
A29: =A28+1 -> 45439 | B29: 0 | C29: 150 | D29: 50 | E29: 357 | F29: 0 | G29: 0 | H29: 0 | I29: -
A30: =A29+1 -> 45440 | B30: 0 | C30: 194 | D30: 18 | E30: 412 | F30: 0 | G30: 0 | H30: 0 | I30: - | J30: * 13:30 150/250
A31: =A30+1 -> 45441 | B31: 0 | C31: 296 | D31: 0 | E31: 407 | F31: 0 | G31: 0 | H31: 0 | I31: - | J31: * 12:00 250/300 * 300/350
A32: =A31+1 -> 45442 | B32: 0 | C32: 340 | D32: 0 | E32: 343 | F32: 0 | G32: 0 | H32: 0 | I32: - | J32: * 07:00 350/300
A33: =A32+1 -> 45443 | B33: 0 | C33: 300 | D33: 26 | E33: 338 | F33: 0 | G33: 0 | H33: 0 | I33: -
A34: Monthly Total | B34: =SUM(B3:B33) -> 0 | C34: =SUM(C3:C33) -> 9816 | D34: =SUM(D3:D33) -> 1725 | E34: =SUM(E3:E33) -> 11956 | F34: =SUM(F3:F33) -> 0.32 | G34: =SUM(G3:G33) -> 0 | H34: =SUM(H3:H33) -> 0
A35: WY Total | B35: =SUM(B34+'Apr 2024'!B34) -> 0 | C35: =SUM(C34+'Apr 2024'!C34) -> 23635 | D35: =SUM(D34+'Apr 2024'!D34) -> 22480 | E35: =SUM(E34+'Apr 2024'!E34) -> 37245 | F35: =SUM(F34+'Apr 2024'!F34) -> 7.9 | G35: =SUM(G34+'Apr 2024'!G34) -> 10.65 | H35: =SUM(H34+'Apr 2024'!H34) -> 6707
A37: Acre Feet | B37: =SUM(B3:B33)*1.9835 -> 0 | C37: =SUM(C3:C33)*1.9835 -> 19470.036 | D37: =SUM(D3:D33)*1.9835 -> 3421.5375 | E37: =SUM(E3:E33)*1.9835 -> 23714.726
A39: WY AF Total | B39: =SUM(B37+'Apr 2024'!B38) -> 0 | C39: =SUM(C37+'Apr 2024'!C38) -> 54637.491 | D39: =SUM(D37+'Apr 2024'!D38) -> 52253.324 | E39: =SUM(E37+'Apr 2024'!E38) -> 82087.148
H41: * COMPUTATIONAL PURPOSES ONLY! Do Not Enter Data in the Red Columns
A43: *This is computation purposes only for Station 48
A44: Sta 48
...

Sheet Apr 2024
A1: DATE | B1: LRDC | C1: STATION 48 | D1: ANDERSON-ROSE | E1: J CANAL | F1: TULE LAKE PRECIP | G1: TULE LAKE SNOW | H1: D PLANT | I1: TULE LAKE ELEV. | J1: CHANGES @ STATION 48
B2: (in CFS) | C2: (in CFS) | D2: (in CFS) | E2: (in CFS) | H2: (in AF)
A3: 45383 | B3: 0 | C3: 275 | D3: 250 | E3: 229 | F3: 0 | G3: 0 | H3: 317 | I3: -
A4: =A3+1 -> 45384 | B4: 0 | C4: 273 | D4: 235 | E4: 207 | F4: 0 | G4: 0 | H4: 317 | I4: - | J4: * 09:30 275/300 * 16:00 300/250
A5: =A4+1 -> 45385 | B5: 0 | C5: 234 | D5: 220 | E5: 179 | F5: 0.06 | G5: 0 | H5: 317 | I5: - | J5: * 16:30 250/200
A6: =A5+1 -> 45386 | B6: 0 | C6: 200 | D6: 220 | E6: 140 | F6: 0.19 | G6: 0 | H6: 317 | I6: -
A7: =A6+1 -> 45387 | B7: 0 | C7: 181 | D7: 220 | E7: 117 | F7: T | G7: 0 | H7: 317 | I7: - | J7: * 15:00 200/150
A8: =A7+1 -> 45388 | B8: 0 | C8: 150 | D8: 230 | E8: 101 | F8: 0 | G8: 0 | H8: 317 | I8: -
A9: =A8+1 -> 45389 | B9: 0 | C9: 150 | D9: 256 | E9: 94 | F9: 0.03 | G9: 0 | H9: 317 | I9: -
A10: =A9+1 -> 45390 | B10: 0 | C10: 150 | D10: 250 | E10: 87 | F10: 0 | G10: 0 | H10: 317 | I10: -
A11: =A10+1 -> 45391 | B11: 0 | C11: 150 | D11: 250 | E11: 87 | F11: T | G11: 0 | H11: 317 | I11: -
A12: =A11+1 -> 45392 | B12: 0 | C12: 150 | D12: 215 | E12: 90 | F12: 0 | G12: 0 | H12: 317 | I12: -
A13: =A12+1 -> 45393 | B13: 0 | C13: 150 | D13: 199 | E13: 96 | F13: 0 | G13: 0 | H13: 317 | I13: -
A14: =A13+1 -> 45394 | B14: 0 | C14: 38 | D14: 83 | E14: 84 | F14: T | G14: 0 | H14: 112 | I14: - | J14: * 06:30 150/0 (D-Plant 2 units off 08:30)
A15: =A14+1 -> 45395 | B15: 0 | C15: 33 | D15: 0 | E15: 87 | F15: 0.01 | G15: 0 | H15: 0 | I15: - | J15: * 08:00 0/50
A16: =A15+1 -> 45396 | B16: 0 | C16: 35 | D16: 23 | E16: 88 | F16: 0.62 | G16: 0 | H16: 0 | I16: - | J16: * 12:00 50/20
A17: =A16+1 -> 45397 | B17: 0 | C17: 20 | D17: 56 | E17: 90 | F17: 0.05 | G17: 0 | H17: 0 | I17: -
A18: =A17+1 -> 45398 | B18: 0 | C18: 14 | D18: 70 | E18: 90 | F18: 0 | G18: 0 | H18: 0 | I18: - | J18: * 17:00 20/0
A19: =A18+1 -> 45399 | B19: 0 | C19: 0 | D19: 70 | E19: 90 | F19: 0 | G19: 0 | H19: 0 | I19: -
A20: =A19+1 -> 45400 | B20: 0 | C20: 8 | D20: 70 | E20: 94 | F20: 0 | G20: 0 | H20: 0 | I20: - | J20: * 14:00 0/25
A21: =A20+1 -> 45401 | B21: 0 | C21: 25 | D21: 70 | E21: 98 | F21: 0 | G21: 0 | H21: 0 | I21: -
A22: =A21+1 -> 45402 | B22: 0 | C22: 33 | D22: 70 | E22: 95 | F22: 0 | G22: 0 | H22: 0 | I22: - | J22: * 16:30 25/50
A23: =A22+1 -> 45403 | B23: 0 | C23: 50 | D23: 70 | E23: 99 | F23: 0 | G23: 0 | H23: 0 | I23: -
A24: =A23+1 -> 45404 | B24: 0 | C24: 76 | D24: 70 | E24: 129 | F24: 0 | G24: 0 | H24: 0 | I24: - | J24: * 09:00 50/75 * 14:00 75/100
A25: =A24+1 -> 45405 | B25: 0 | C25: 131 | D25: 70 | E25: 172 | F25: 0 | G25: 0 | H25: 0 | I25: - | J25: * 09:00 100/150
A26: =A25+1 -> 45406 | B26: 0 | C26: 185 | D26: 44 | E26: 187 | F26: 0 | G26: 0 | H26: 0 | I26: - | J26: * 07:00 150/200
A27: =A26+1 -> 45407 | B27: 0 | C27: 200 | D27: 60 | E27: 203 | F27: 0.04 | G27: 0 | H27: 0 | I27: -
A28: =A27+1 -> 45408 | B28: 0 | C28: 200 | D28: 58 | E28: 212 | F28: 0.01 | G28: 0 | H28: 0 | I28: -
A29: =A28+1 -> 45409 | B29: 0 | C29: 200 | D29: 82 | E29: 219 | F29: T | G29: 0 | H29: 0 | I29: -
A30: =A29+1 -> 45410 | B30: 0 | C30: 200 | D30: 129 | E30: 212 | F30: 0 | G30: 0 | H30: 0 | I30: -
A31: =A30+1 -> 45411 | B31: 0 | C31: 200 | D31: 141 | E31: 227 | F31: 0 | G31: 0 | H31: 0 | I31: -
A32: =A31+1 -> 45412 | B32: 0 | C32: 200 | D32: 83 | E32: 237 | F32: 0 | G32: 0 | H32: 0 | I32: -
A33: Monthly Total | B33: =SUM(B3:B32) -> 0 | C33: =SUM(C3:C32) -> 3911 | D33: =SUM(D3:D32) -> 3864 | E33: =SUM(E3:E32) -> 4140 | F33: =SUM(F3:F32) -> 1.01 | G33: =SUM(G3:G32) -> 0 | H33: =SUM(H3:H32) -> 3599
A34: WY Total | B34: =SUM(B33+'Mar 2024'!B35) -> 0 | C34: =SUM(C33+'Mar 2024'!C35) -> 13819 | D34: =SUM(D33+'Mar 2024'!D35) -> 20755 | E34: =SUM(E33+'Mar 2024'!E35) -> 25289 | F34: =SUM(F33+'Mar 2024'!F35) -> 7.58 | G34: =SUM(G33+'Mar 2024'!G35) -> 10.65 | H34: =SUM(H33+'Mar 2024'!H35) -> 6707
A36: Acre Feet | B36: =SUM(B3:B33)*1.9835 -> 0 | C36: =SUM(C3:C33)*1.9835 -> 15514.937 | D36: =SUM(D3:D33)*1.9835 -> 15328.488 | E36: =SUM(E3:E33)*1.9835 -> 16423.38
A38: WY AF Total | B38: =SUM(B36+'Mar 2024'!B39) -> 0 | C38: =SUM(C36+'Mar 2024'!C39) -> 35167.455 | D38: =SUM(D36+'Mar 2024'!D39) -> 48831.787 | E38: =SUM(E36+'Mar 2024'!E39) -> 58372.422
H40: * COMPUTATIONAL PURPOSES ONLY! Do Not Enter Data in the Red Columns
A42: *This is computation purposes only for Station 48
A43: Sta 48
G44: =SUM(24-E44) -> 24 | H44: =SUM(D44+F44) -> 0 | I44: =SUM(D44/24*E44+H44/24*G44) -> 0
...

Sheet Mar 2024
A1: DATE | B1: LRDC | C1: STATION 48 | D1: ANDERSON-ROSE | E1: J CANAL | F1: TULE LAKE PRECIP | G1: TULE LAKE SNOW | H1: D PLANT | I1: TULE LAKE ELEV. | J1: CHANGES @ STATION 48
B2: (in CFS) | C2: (in CFS) | D2: (in CFS) | E2: (in CFS) | H2: (in AF)
A3: 44986 | B3: 0 | C3: 0 | D3: 171 | E3: 0 | F3: 0.02 | G3: 0 | H3: 0 | I3: -
A4: =A3+1 -> 44987 | B4: 0 | C4: 0 | D4: 160 | E4: 0 | F4: 0.05 | G4: 1 | H4: 0 | I4: -
A5: =A4+1 -> 44988 | B5: 0 | C5: 0 | D5: 160 | E5: 0 | F5: 0.05 | G5: 1 | H5: 0 | I5: -
A6: =A5+1 -> 44989 | B6: 0 | C6: 50 | D6: 160 | E6: 0 | F6: 0.02 | G6: 0 | H6: 0 | I6: - | J6: * 12:00 0/100
A7: =A6+1 -> 44990 | B7: 0 | C7: 100 | D7: 231 | E7: 0 | F7: 0.08 | G7: 0 | H7: 0 | I7: -
A8: =A7+1 -> 44991 | B8: 0 | C8: 100 | D8: 322 | E8: 0 | F8: 0 | G8: 0 | H8: 0 | I8: -
A9: =A8+1 -> 44992 | B9: 0 | C9: 100 | D9: 463 | E9: 0 | F9: 0 | G9: 0 | H9: 0 | I9: -
A10: =A9+1 -> 44993 | B10: 0 | C10: 100 | D10: 742 | E10: 0 | F10: T | G10: 0 | H10: 0 | I10: -
A11: =A10+1 -> 44994 | B11: 0 | C11: 100 | D11: 631 | E11: 0 | F11: 0 | G11: 0 | H11: 0 | I11: -
A12: =A11+1 -> 44995 | B12: 0 | C12: 100 | D12: 500 | E12: 0 | F12: 0 | G12: 0 | H12: 0 | I12: -
A13: =A12+1 -> 44996 | B13: 0 | C13: 100 | D13: 500 | E13: 0 | F13: 0 | G13: 0 | H13: 0 | I13: -
A14: =A13+1 -> 44997 | B14: 0 | C14: 100 | D14: 500 | E14: 0 | F14: 0 | G14: 0 | H14: 0 | I14: -
A15: =A14+1 -> 44998 | B15: 0 | C15: 100 | D15: 403 | E15: 0 | F15: 0 | G15: 0 | H15: 0 | I15: -
A16: =A15+1 -> 44999 | B16: 0 | C16: 100 | D16: 350 | E16: 0 | F16: 0 | G16: 0 | H16: 0 | I16: -
A17: =A16+1 -> 45000 | B17: 0 | C17: 100 | D17: 350 | E17: 18 | F17: 0 | G17: 0 | H17: 0 | I17: -
A18: =A17+1 -> 45001 | B18: 0 | C18: 100 | D18: 304 | E18: 28 | F18: 0 | G18: 0 | H18: 0 | I18: -
A19: =A18+1 -> 45002 | B19: 0 | C19: 100 | D19: 250 | E19: 28 | F19: 0 | G19: 0 | H19: 0 | I19: -
A20: =A19+1 -> 45003 | B20: 0 | C20: 67 | D20: 234 | E20: 42 | F20: 0 | G20: 0 | H20: 0 | I20: - | J20: *13:30 100/25
A21: =A20+1 -> 45004 | B21: 0 | C21: 25 | D21: 100 | E21: 50 | F21: 0 | G21: 0 | H21: 0 | I21: -
A22: =A21+1 -> 45005 | B22: 0 | C22: 25 | D22: 100 | E22: 50 | F22: 0 | G22: 0 | H22: 0 | I22: -
A23: =A22+1 -> 45006 | B23: 0 | C23: 35 | D23: 100 | E23: 70 | F23: 0 | G23: 0 | H23: 85 | I23: - | J23: * 19:00 25/75 - (D Plant 1 Unit ON)
A24: =A23+1 -> 45007 | B24: 0 | C24: 75 | D24: 100 | E24: 80 | F24: 0 | G24: 0 | H24: 215 | I24: - | J24: * (D Plant 2 Units ON)
A25: =A24+1 -> 45008 | B25: 0 | C25: 75 | D25: 100 | E25: 119 | F25: 0.18 | G25: 0 | H25: 317 | I25: -
A26: =A25+1 -> 45009 | B26: 0 | C26: 113 | D26: 100 | E26: 150 | F26: 0.11 | G26: 0.4 | H26: 317 | I26: - | J26: * 12:00 75/150
A27: =A26+1 -> 45010 | B27: 0 | C27: 202 | D27: 115 | E27: 175 | F27: T | G27: 0 | H27: 284 | I27: - | J27: * 09:00 150/200 * 14:00 200/250
A28: =A27+1 -> 45011 | B28: 0 | C28: 250 | D28: 150 | E28: 221 | F28: 0 | G28: 0 | H28: 316 | I28: -
A29: =A28+1 -> 45012 | B29: 0 | C29: 250 | D29: 150 | E29: 234 | F29: 0.03 | G29: 0 | H29: 309 | I29: -
A30: =A29+1 -> 45013 | B30: 0 | C30: 250 | D30: 150 | E30: 245 | F30: T | G30: 0 | H30: 316 | I30: -
A31: =A30+1 -> 45014 | B31: 0 | C31: 281 | D31: 172 | E31: 225 | F31: T | G31: 0 | H31: 316 | I31: - | J31: * 09:00 250/300
A32: =A31+1 -> 45015 | B32: 0 | C32: 293 | D32: 241 | E32: 225 | F32: 0 | G32: 0 | H32: 316 | I32: - | J32: * 17:30 300/275
A33: =A32+1 -> 45016 | B33: 0 | C33: 275 | D33: 250 | E33: 222 | F33: 0 | G33: 0 | H33: 317 | I33: -
A34: Monthly Total | B34: =SUM(B3:B33) -> 0 | C34: =SUM(C3:C33) -> 3566 | D34: =SUM(D3:D33) -> 8259 | E34: =SUM(E3:E33) -> 2182 | F34: =SUM(F3:F33) -> 0.54 | G34: =SUM(G3:G33) -> 2.4 | H34: =SUM(H3:H33) -> 3108
A35: WY Total | B35: =SUM(B34+'Feb 2024'!B33) -> 0 | C35: =SUM(C34+'Feb 2024'!C33) -> 9908 | D35: =SUM(D34+'Feb 2024'!D33) -> 16891 | E35: =SUM(E34+'Feb 2024'!E33) -> 21149 | F35: =SUM(F34+'Feb 2024'!F33) -> 6.57 | G35: =SUM(G34+'Feb 2024'!G33) -> 10.65 | H35: =SUM(H34+'Feb 2024'!H33) -> 3108
A37: Acre Feet | B37: =SUM(B3:B33)*1.9835 -> 0 | C37: =SUM(C3:C33)*1.9835 -> 7073.161 | D37: =SUM(D3:D33)*1.9835 -> 16381.727 | E37: =SUM(E3:E33)*1.9835 -> 4327.997
A39: WY AF Total | B39: =SUM(B37+'Feb 2024'!B37) -> 0 | C39: =SUM(C37+'Feb 2024'!C37) -> 19652.518 | D39: =SUM(D37+'Feb 2024'!D37) -> 33503.299 | E39: =SUM(E37+'Feb 2024'!E37) -> 41949.042
H41: * COMPUTATIONAL PURPOSES ONLY! Do Not Enter Data in the Red Columns
A43: *This is computation purposes only for Station 48
A44: Sta 48
...

Sheet Feb 2024
A1: DATE | B1: LRDC | C1: STATION 48 | D1: ANDERSON-ROSE | E1: J CANAL | F1: TULE LAKE PRECIP | G1: TULE LAKE SNOW | H1: D PLANT | I1: TULE LAKE ELEV. | J1: CHANGES @ STATION 48
B2: (in CFS) | C2: (in CFS) | D2: (in CFS) | E2: (in CFS) | H2: (in AF)
A3: 45323 | B3: 0 | C3: 0 | D3: 150 | E3: 89 | F3: T | G3: 0 | H3: 0 | I3: -
A4: =A3+1 -> 45324 | B4: 0 | C4: 0 | D4: 177 | E4: 57 | F4: 0.06 | G4: 0 | H4: 0 | I4: -
A5: =A4+1 -> 45325 | B5: 0 | C5: 0 | D5: 202 | E5: 0 | F5: 0.15 | G5: 0 | H5: 0 | I5: -
A6: =A5+1 -> 45326 | B6: 0 | C6: 0 | D6: 170 | E6: 0 | F6: 0.15 | G6: 1 | H6: 0 | I6: -
A7: =A6+1 -> 45327 | B7: 0 | C7: 0 | D7: 151 | E7: 0 | F7: 0 | G7: 0 | H7: 0 | I7: -
A8: =A7+1 -> 45328 | B8: 0 | C8: 0 | D8: 140 | E8: 0 | F8: 0 | G8: 0 | H8: 0 | I8: -
A9: =A8+1 -> 45329 | B9: 0 | C9: 0 | D9: 140 | E9: 0 | F9: 0 | G9: 0 | H9: 0 | I9: -
A10: =A9+1 -> 45330 | B10: 0 | C10: 0 | D10: 158 | E10: 0 | F10: 0 | G10: 0 | H10: 0 | I10: -
A11: =A10+1 -> 45331 | B11: 0 | C11: 0 | D11: 170 | E11: 0 | F11: 0.02 | G11: 0 | H11: 0 | I11: -
A12: =A11+1 -> 45332 | B12: 0 | C12: 0 | D12: 164 | E12: 0 | F12: 0 | G12: 0 | H12: 0 | I12: -
A13: =A12+1 -> 45333 | B13: 0 | C13: 0 | D13: 140 | E13: 0 | F13: 0 | G13: 0 | H13: 0 | I13: -
A14: =A13+1 -> 45334 | B14: 0 | C14: 0 | D14: 129 | E14: 0 | F14: T | G14: 0 | H14: 0 | I14: -
A15: =A14+1 -> 45335 | B15: 0 | C15: 0 | D15: 120 | E15: 0 | F15: 0 | G15: 0 | H15: 0 | I15: -
A16: =A15+1 -> 45336 | B16: 0 | C16: 0 | D16: 120 | E16: 0 | F16: 0.13 | G16: 0 | H16: 0 | I16: -
A17: =A16+1 -> 45337 | B17: 0 | C17: 0 | D17: 120 | E17: 0 | F17: 0.13 | G17: 0 | H17: 0 | I17: -
A18: =A17+1 -> 45338 | B18: 0 | C18: 0 | D18: 120 | E18: 0 | F18: 0.03 | G18: 0 | H18: 0 | I18: -
A19: =A18+1 -> 45339 | B19: 0 | C19: 0 | D19: 122 | E19: 0 | F19: 0 | G19: 0 | H19: 0 | I19: -
A20: =A19+1 -> 45340 | B20: 0 | C20: 0 | D20: 150 | E20: 0 | F20: 0.2 | G20: 0 | H20: 0 | I20: -
A21: =A20+1 -> 45341 | B21: 0 | C21: 0 | D21: 160 | E21: 0 | F21: 0.4 | G21: 0 | H21: 0 | I21: -
A22: =A21+1 -> 45342 | B22: 0 | C22: 0 | D22: 189 | E22: 0 | F22: 0.09 | G22: 0 | H22: 0 | I22: -
A23: =A22+1 -> 45343 | B23: 0 | C23: 0 | D23: 299 | E23: 0 | F23: 0.02 | G23: 0 | H23: 0 | I23: -
A24: =A23+1 -> 45344 | B24: 0 | C24: 0 | D24: 350 | E24: 0 | F24: 0 | G24: 0 | H24: 0 | I24: -
A25: =A24+1 -> 45345 | B25: 0 | C25: 0 | D25: 321 | E25: 0 | F25: 0 | G25: 0 | H25: 0 | I25: -
A26: =A25+1 -> 45346 | B26: 0 | C26: 0 | D26: 269 | E26: 0 | F26: 0 | G26: 0 | H26: 0 | I26: -
... A31: =A30+1 -> 45351 | B31: 0 | C31: 0 | D31: 190 | E31: 0 | F31: 0.13 | G31: 0 | H31: 0 | I31: -
A32: Monthly Total | B32: =SUM(B3:B31) -> 0 | C32: =SUM(C3:C31) -> 0 | D32: =SUM(D3:D31) -> 5198 | E32: =SUM(E3:E31) -> 146 | F32: =SUM(F3:F31) -> 1.6 | G32: =SUM(G3:G31) -> 1 | H32: =SUM(H3:H31) -> 0
A33: WY Total | B33: =SUM(B32+'Jan 2024'!B35) -> 0 | C33: =SUM(C32+'Jan 2024'!C35) -> 6342 | D33: =SUM(D32+'Jan 2024'!D35) -> 8632 | E33: =SUM(E32+'Jan 2024'!E35) -> 18967 | F33: =SUM(F32+'Jan 2024'!F35) -> 6.03 | G33: =SUM(G32+'Jan 2024'!G35) -> 8.25 | H33: =SUM(H32+'Jan 2024'!H35) -> 0
A35: Acre Feet | B35: =SUM(B3:B31)*1.9835 -> 0 | C35: =SUM(C3:C31)*1.9835 -> 0 | D35: =SUM(D3:D31)*1.9835 -> 10310.233 | E35: =SUM(E3:E31)*1.9835 -> 289.591
A37: WY AF Total | B37: =SUM(B35+'Jan 2024'!B39) -> 0 | C37: =SUM(C35+'Jan 2024'!C39) -> 12579.357 | D37: =SUM(D35+'Jan 2024'!D39) -> 17121.572 | E37: =SUM(E35+'Jan 2024'!E39) -> 37621.045
H39: * COMPUTATIONAL PURPOSES ONLY! Do Not Enter Data in the Red Columns
A41: *This is computation purposes only for Station 48
A42: Sta 48
G43: =SUM(24-E43) -> 24 | H43: =SUM(D43+F43) -> 0 | I43: =SUM(D43/24*E43+H43/24*G43) -> 0
G44: =SUM(24-E44) -> 24 | H44: =SUM(D44+F44) -> 0 | I44: =SUM(D44/24*E44+H44/24*G44) -> 0
G45: =SUM(24-E45) -> 24 | H45: =SUM(D45+F45) -> 0 | I45: =SUM(D45/24*E45+H45/24*G45) -> 0
G46: =SUM(24-E46) -> 24 | H46: =SUM(D46+F46) -> 0 | I46: =SUM(D46/24*E46+H46/24*G46) -> 0
G47: =SUM(24-E47) -> 24 | H47: =SUM(D47+F47) -> 0 | I47: =SUM(D47/24*E47+H47/24*G47) -> 0
A49: Use for more than 1 change in a day.
...

Sheet Jan 2024
A1: DATE | B1: LRDC | C1: STATION 48 | D1: ANDERSON-ROSE | E1: J CANAL | F1: TULE LAKE PRECIP | G1: TULE LAKE SNOW | H1: D PLANT | I1: TULE LAKE ELEV. | J1: CHANGES @ STATION 48
B2: (in CFS) | C2: (in CFS) | D2: (in CFS) | E2: (in CFS) | H2: (in AF)
A3: 45292 | B3: 0 | C3: 0 | D3: 0 | E3: 88 | F3: 0 | G3: 0 | H3: 0 | I3: -
A4: =A3+1 -> 45293 | B4: 0 | C4: 0 | D4: 0 | E4: 88 | F4: 0.01 | G4: 0 | H4: 0 | I4: -
A5: =A4+1 -> 45294 | B5: 0 | C5: 0 | D5: 0 | E5: 88 | F5: 0.02 | G5: 0 | H5: 0 | I5: -
A6: =A5+1 -> 45295 | B6: 0 | C6: 0 | D6: 0 | E6: 86 | F6: T | G6: 0 | H6: 0 | I6: -
A7: =A6+1 -> 45296 | B7: 0 | C7: 0 | D7: 0 | E7: 86 | F7: 0.13 | G7: 0 | H7: 0 | I7: -
A8: =A7+1 -> 45297 | B8: 0 | C8: 0 | D8: 0 | E8: 87 | F8: 0.1 | G8: 0 | H8: 0 | I8: -
A9: =A8+1 -> 45298 | B9: 0 | C9: 0 | D9: 0 | E9: 88 | F9: 0.1 | G9: 0 | H9: 0 | I9: -
A10: =A9+1 -> 45299 | B10: 0 | C10: 0 | D10: 0 | E10: 88 | F10: 0.06 | G10: 1.75 | H10: 0 | I10: -
A11: =A10+1 -> 45300 | B11: 0 | C11: 0 | D11: 0 | E11: 88 | F11: 0.04 | G11: 0 | H11: 0 | I11: -
A12: =A11+1 -> 45301 | B12: 0 | C12: 0 | D12: 0 | E12: 87 | F12: 0.18 | G12: 3.5 | H12: 0 | I12: -
A13: =A12+1 -> 45302 | B13: 0 | C13: 0 | D13: 0 | E13: 83 | F13: 0.02 | G13: 0 | H13: 0 | I13: -
A14: =A13+1 -> 45303 | B14: 0 | C14: 0 | D14: 0 | E14: 85 | F14: T | G14: 0 | H14: 0 | I14: -
A15: =A14+1 -> 45304 | B15: 0 | C15: 0 | D15: 0 | E15: 87 | F15: 0.3 | G15: 1.5 | H15: 0 | I15: -
A16: =A15+1 -> 45305 | B16: 0 | C16: 0 | D16: 0 | E16: 89 | F16: 0.1 | G16: 0 | H16: 0 | I16: -
A17: =A16+1 -> 45306 | B17: 0 | C17: 0 | D17: 0 | E17: 91 | F17: T | G17: 0 | H17: 0 | I17: -
A18: =A17+1 -> 45307 | B18: 0 | C18: 0 | D18: 45 | E18: 93 | F18: 0.1 | G18: 0 | H18: 0 | I18: -
A19: =A18+1 -> 45308 | B19: 0 | C19: 20 | D19: 84 | E19: 86 | F19: 0.02 | G19: 0 | H19: 0 | I19: - | J19: 1430 *0/50
A20: =A19+1 -> 45309 | B20: 0 | C20: 81 | D20: 104 | E20: 83 | F20: 0.02 | G20: 0 | H20: 0 | I20: - | J20: * 15:00 50/100
A21: =A20+1 -> 45310 | B21: 0 | C21: 100 | D21: 173 | E21: 90 | F21: 0 | G21: 0 | H21: 0 | I21: -
A22: =A21+1 -> 45311 | B22: 0 | C22: 100 | D22: 200 | E22: 91 | F22: 0 | G22: 0 | H22: 0 | I22: -
A23: =A22+1 -> 45312 | B23: 0 | C23: 100 | D23: 223 | E23: 93 | F23: 0.02 | G23: 0 | H23: 0 | I23: -
A24: =A23+1 -> 45313 | B24: 0 | C24: 69 | D24: 288 | E24: 94 | F24: 0.01 | G24: 0 | H24: 0 | I24: - | J24: * 16:30 100/0
A25: =A24+1 -> 45314 | B25: 0 | C25: 0 | D25: 332 | E25: 97 | F25: 0.24 | G25: 0 | H25: 0 | I25: -
A26: =A25+1 -> 45315 | B26: 0 | C26: 0 | D26: 385 | E26: 99 | F26: 0.12 | G26: 0 | H26: 0 | I26: -
A27: =A26+1 -> 45316 | B27: 0 | C27: 0 | D27: 387 | E27: 95 | F27: 0 | G27: 0 | H27: 0 | I27: -
A28: =A27+1 -> 45317 | B28: 0 | C28: 0 | D28: 323 | E28: 90 | F28: 0.06 | G28: 0 | H28: 0 | I28: -
A29: =A28+1 -> 45318 | B29: 0 | C29: 0 | D29: 247 | E29: 90 | F29: 0.12 | G29: 0 | H29: 0 | I29: -
A30: =A29+1 -> 45319 | B30: 0 | C30: 0 | D30: 177 | E30: 85 | F30: 0 | G30: 0 | H30: 0 | I30: -
A31: =A30+1 -> 45320 | B31: 0 | C31: 0 | D31: 150 | E31: 90 | F31: 0 | G31: 0 | H31: 0 | I31: -
A32: =A31+1 -> 45321 | B32: 0 | C32: 0 | D32: 150 | E32: 91 | F32: 0 | G32: 0 | H32: 0 | I32: -
A33: =A32+1 -> 45322 | B33: 0 | C33: 0 | D33: 150 | E33: 91 | F33: 0 | G33: 0 | H33: 0 | I33: -
A34: Monthly Total | B34: =SUM(B3:B33) -> 0 | C34: =SUM(C3:C33) -> 470 | D34: =SUM(D3:D33) -> 3418 | E34: =SUM(E3:E33) -> 2767 | F34: =SUM(F3:F33) -> 1.77 | G34: =SUM(G3:G33) -> 6.75 | H34: =SUM(H3:H33) -> 0
A35: WY Total | B35: =SUM(B34+'Dec 2023'!B35) -> 0 | C35: =SUM(C34+'Dec 2023'!C35) -> 6342 | D35: =SUM(D34+'Dec 2023'!D35) -> 3434 | E35: =SUM(E34+'Dec 2023'!E35) -> 18821 | F35: =SUM(F34+'Dec 2023'!F35) -> 4.43 | G35: =SUM(G34+'Dec 2023'!G35) -> 7.25 | H35: =SUM(H34+'Dec 2023'!H35) -> 0
A37: Acre Feet | B37: =SUM(B3:B33)*1.9835 -> 0 | C37: =SUM(C3:C33)*1.9835 -> 932.245 | D37: =SUM(D3:D33)*1.9835 -> 6779.603 | E37: =SUM(E3:E33)*1.9835 -> 5488.3445
A39: WY AF Total | B39: =SUM(B37+'Dec 2023'!B39) -> 0 | C39: =SUM(C37+'Dec 2023'!C39) -> 12579.357 | D39: =SUM(D37+'Dec 2023'!D39) -> 6811.339 | E39: =SUM(E37+'Dec 2023'!E39) -> 37331.454
H41: * COMPUTATIONAL PURPOSES ONLY! Do Not Enter Data in the Red Columns
A43: *This is computation purposes only for Station 48
A44: Sta 48
...

Sheet Dec 2023
A1: DATE | B1: LRDC | C1: STATION 48 | D1: ANDERSON-ROSE | E1: J CANAL | F1: TULE LAKE PRECIP | G1: TULE LAKE SNOW | H1: D PLANT | I1: TULE LAKE ELEV. | J1: CHANGES @ STATION 48
B2: (in CFS) | C2: (in CFS) | D2: (in CFS) | E2: (in CFS) | H2: (in AF)
A3: 45261 | B3: 0 | C3: 0 | D3: 0 | E3: 76 | F3: 0.13 | G3: 0 | H3: 0 | I3: -
A4: =A3+1 -> 45262 | B4: 0 | C4: 0 | D4: 0 | E4: 79 | F4: 0.2 | G4: 0 | H4: 0 | I4: -
A5: =A4+1 -> 45263 | B5: 0 | C5: 0 | D5: 0 | E5: 82 | F5: 0.18 | G5: 0 | H5: 0 | I5: -
A6: =A5+1 -> 45264 | B6: 0 | C6: 0 | D6: 0 | E6: 84 | F6: T | G6: 0 | H6: 0 | I6: -
A7: =A6+1 -> 45265 | B7: 0 | C7: 0 | D7: 0 | E7: 86 | F7: 0 | G7: 0 | H7: 0 | I7: -
A8: =A7+1 -> 45266 | B8: 0 | C8: 0 | D8: 0 | E8: 83 | F8: T | G8: 0 | H8: 0 | I8: -
A9: =A8+1 -> 45267 | B9: 0 | C9: 0 | D9: 0 | E9: 82 | F9: 0.07 | G9: 0 | H9: 0 | I9: -
A10: =A9+1 -> 45268 | B10: 0 | C10: 0 | D10: 0 | E10: 82 | F10: 0 | G10: 0 | H10: 0 | I10: -
A11: =A10+1 -> 45269 | B11: 0 | C11: 0 | D11: 0 | E11: 81 | F11: 0 | G11: 0 | H11: 0 | I11: -
A12: =A11+1 -> 45270 | B12: 0 | C12: 0 | D12: 0 | E12: 81 | F12: 0 | G12: 0 | H12: 0 | I12: -
A13: =A12+1 -> 45271 | B13: 0 | C13: 0 | D13: 0 | E13: 80 | F13: 0.02 | G13: 0 | H13: 0 | I13: -
A14: =A13+1 -> 45272 | B14: 0 | C14: 0 | D14: 0 | E14: 78 | F14: 0 | G14: 0 | H14: 0 | I14: -
A15: =A14+1 -> 45273 | B15: 0 | C15: 0 | D15: 0 | E15: 76 | F15: 0 | G15: 0 | H15: 0 | I15: -
A16: =A15+1 -> 45274 | B16: 0 | C16: 0 | D16: 0 | E16: 77 | F16: 0 | G16: 0 | H16: 0 | I16: -
A17: =A16+1 -> 45275 | B17: 0 | C17: 0 | D17: 0 | E17: 76 | F17: T | G17: 0 | H17: 0 | I17: -
A18: =A17+1 -> 45276 | B18: 0 | C18: 0 | D18: 0 | E18: 78 | F18: 0 | G18: 0 | H18: 0 | I18: -
A19: =A18+1 -> 45277 | B19: 0 | C19: 0 | D19: 0 | E19: 80 | F19: 0 | G19: 0 | H19: 0 | I19: -
A20: =A19+1 -> 45278 | B20: 0 | C20: 0 | D20: 0 | E20: 82 | F20: 0.38 | G20: 0 | H20: 0 | I20: -
A21: =A20+1 -> 45279 | B21: 0 | C21: 0 | D21: 0 | E21: 83 | F21: 0.29 | G21: 0 | H21: 0 | I21: -
A22: =A21+1 -> 45280 | B22: 0 | C22: 0 | D22: 0 | E22: 77 | F22: 0.08 | G22: 0 | H22: 0 | I22: -
A23: =A22+1 -> 45281 | B23: 0 | C23: 0 | D23: 0 | E23: 99 | F23: 0.01 | G23: 0 | H23: 0 | I23: -
A24: =A23+1 -> 45282 | B24: 0 | C24: 0 | D24: 0 | E24: 116 | F24: T | G24: 0 | H24: 0 | I24: -
A25: =A24+1 -> 45283 | B25: 0 | C25: 0 | D25: 0 | E25: 114 | F25: T | G25: 0 | H25: 0 | I25: -
A26: =A25+1 -> 45284 | B26: 0 | C26: 0 | D26: 0 | E26: 112 | F26: T | G26: 0 | H26: 0 | I26: -
A27: =A26+1 -> 45285 | B27: 0 | C27: 0 | D27: 0 | E27: 112 | F27: T | G27: 0 | H27: 0 | I27: -
A28: =A27+1 -> 45286 | B28: 0 | C28: 0 | D28: 0 | E28: 98 | F28: 0 | G28: 0 | H28: 0 | I28: -
A29: =A28+1 -> 45287 | B29: 0 | C29: 0 | D29: 0 | E29: 78 | F29: T | G29: 0 | H29: 0 | I29: -
A30: =A29+1 -> 45288 | B30: 0 | C30: 0 | D30: 0 | E30: 86 | F30: T | G30: 0 | H30: 0 | I30: -
A31: =A30+1 -> 45289 | B31: 0 | C31: 0 | D31: 0 | E31: 90 | F31: T | G31: 0 | H31: 0 | I31: -
A32: =A31+1 -> 45290 | B32: 0 | C32: 0 | D32: 0 | E32: 90 | F32: 0 | G32: 0 | H32: 0 | I32: -
A33: =A32+1 -> 45291 | B33: 0 | C33: 0 | D33: 0 | E33: 88 | F33: 0.03 | G33: 0 | H33: 0 | I33: -
A34: Monthly Total | B34: =SUM(B3:B33) -> 0 | C34: =SUM(C3:C33) -> 0 | D34: =SUM(D3:D33) -> 0 | E34: =SUM(E3:E33) -> 2686 | F34: =SUM(F3:F33) -> 1.39 | G34: =SUM(G3:G33) -> 0 | H34: =SUM(H3:H33) -> 0
A35: WY Total | B35: =SUM(B34+'Nov 2023'!B34) -> 0 | C35: =SUM(C34+'Nov 2023'!C34) -> 5872 | D35: =SUM(D34+'Nov 2023'!D34) -> 16 | E35: =SUM(E34+'Nov 2023'!E34) -> 16054 | F35: =SUM(F34+'Nov 2023'!F34) -> 2.66 | G35: =SUM(G34+'Nov 2023'!G34) -> 0.5 | H35: =SUM(H34+'Nov 2023'!H34) -> 0
A37: Acre Feet | B37: =SUM(B3:B33)*1.9835 -> 0 | C37: =SUM(C3:C33)*1.9835 -> 0 | D37: =SUM(D3:D33)*1.9835 -> 0 | E37: =SUM(E3:E33)*1.9835 -> 5327.681
A39: WY AF Total | B39: =SUM('Nov 2023'!B38+B37) -> 0 | C39: =SUM('Nov 2023'!C38+C37) -> 11647.112 | D39: =SUM('Nov 2023'!D38+D37) -> 31.736 | E39: =SUM('Nov 2023'!E38+E37) -> 31843.109
H41: * COMPUTATIONAL PURPOSES ONLY! Do Not Enter Data in the Red Columns
A43: *This is computation purposes only for Station 48
A44: Sta 48
...

Sheet Nov 2023
A1: DATE | B1: LRDC | C1: STATION 48 | D1: ANDERSON-ROSE | E1: J CANAL | F1: TULE LAKE PRECIP | G1: TULE LAKE SNOW | H1: D PLANT | I1: TULE LAKE ELEV. | J1: CHANGES @ STATION 48
B2: (in CFS) | C2: (in CFS) | D2: (in CFS) | E2: (in CFS) | H2: (in AF)
A3: 45231 | B3: 0 | C3: 100 | D3: 0 | E3: 230 | F3: 0 | G3: 0 | H3: 0 | I3: -
A4: =A3+1 -> 45232 | B4: 0 | C4: 100 | D4: 0 | E4: 228 | F4: 0.05 | G4: 0 | H4: 0 | I4: -
A5: =A4+1 -> 45233 | B5: 0 | C5: 114 | D5: 0 | E5: 223 | F5: 0.01 | G5: 0 | H5: 0 | I5: - | J5: * 11:00 100/125
A6: =A5+1 -> 45234 | B6: 0 | C6: 125 | D6: 0 | E6: 220 | F6: 0 | G6: 0 | H6: 0 | I6: -
A7: =A6+1 -> 45235 | B7: 0 | C7: 125 | D7: 0 | E7: 220 | F7: 0 | G7: 0 | H7: 0 | I7: -
A8: =A7+1 -> 45236 | B8: 0 | C8: 125 | D8: 0 | E8: 216 | F8: 0.3 | G8: 0 | H8: 0 | I8: -
A9: =A8+1 -> 45237 | B9: 0 | C9: 140 | D9: 0 | E9: 210 | F9: 0 | G9: 0 | H9: 0 | I9: - | J9: * 10:00 125/150
A10: =A9+1 -> 45238 | B10: 0 | C10: 150 | D10: 0 | E10: 209 | F10: T | G10: 0 | H10: 0 | I10: -
A11: =A10+1 -> 45239 | B11: 0 | C11: 135 | D11: 0 | E11: 180 | F11: T | G11: 0 | H11: 0 | I11: - | J11: * 10:00 150/125
A12: =A11+1 -> 45240 | B12: 0 | C12: 110 | D12: 0 | E12: 175 | F12: 0 | G12: 0 | H12: 0 | I12: - | J12: * 10:00 125/100
A13: =A12+1 -> 45241 | B13: 0 | C13: 100 | D13: 0 | E13: 175 | F13: 0 | G13: 0 | H13: 0 | I13: -
A14: =A13+1 -> 45242 | B14: 0 | C14: 100 | D14: 0 | E14: 175 | F14: 0 | G14: 0 | H14: 0 | I14: -
A15: =A14+1 -> 45243 | B15: 0 | C15: 100 | D15: 0 | E15: 175 | F15: 0 | G15: 0 | H15: 0 | I15: -
A16: =A15+1 -> 45244 | B16: 0 | C16: 85 | D16: 0 | E16: 171 | F16: 0 | G16: 0 | H16: 0 | I16: - | J16: * 10:00 100/75
A17: =A16+1 -> 45245 | B17: 0 | C17: 38 | D17: 0 | E17: 162 | F17: T | G17: 0 | H17: 0 | I17: - | J17: *12:00 75/0
A18: =A17+1 -> 45246 | B18: 0 | C18: 0 | D18: 0 | E18: 119 | F18: 0.04 | G18: 0 | H18: 0 | I18: -
A19: =A18+1 -> 45247 | B19: 0 | C19: 0 | D19: 0 | E19: 67 | F19: 0 | G19: 0 | H19: 0 | I19: -
A20: =A19+1 -> 45248 | B20: 0 | C20: 0 | D20: 0 | E20: 65 | F20: 0.16 | G20: 0 | H20: 0 | I20: -
A21: =A20+1 -> 45249 | B21: 0 | C21: 0 | D21: 0 | E21: 60 | F21: 0.05 | G21: 0 | H21: 0 | I21: -
A22: =A21+1 -> 45250 | B22: 0 | C22: 0 | D22: 0 | E22: 60 | F22: 0.21 | G22: 0 | H22: 0 | I22: -
A23: =A22+1 -> 45251 | B23: 0 | C23: 0 | D23: 0 | E23: 45 | F23: 0 | G23: 0 | H23: 0 | I23: -
A24: =A23+1 -> 45252 | B24: 0 | C24: 0 | D24: 0 | E24: 40 | F24: 0 | G24: 0 | H24: 0 | I24: -
A25: =A24+1 -> 45253 | B25: 0 | C25: 0 | D25: 0 | E25: 42 | F25: 0 | G25: 0 | H25: 0 | I25: -
A26: =A25+1 -> 45254 | B26: 0 | C26: 0 | D26: 0 | E26: 44 | F26: 0.01 | G26: 0 | H26: 0 | I26: -
A27: =A26+1 -> 45255 | B27: 0 | C27: 0 | D27: 0 | E27: 46 | F27: 0 | G27: 0 | H27: 0 | I27: -
A28: =A27+1 -> 45256 | B28: 0 | C28: 0 | D28: 0 | E28: 48 | F28: 0 | G28: 0 | H28: 0 | I28: -
A29: =A28+1 -> 45257 | B29: 0 | C29: 0 | D29: 0 | E29: 50 | F29: 0 | G29: 0 | H29: 0 | I29: -
A30: =A29+1 -> 45258 | B30: 0 | C30: 0 | D30: 0 | E30: 57 | F30: 0 | G30: 0 | H30: 0 | I30: -
A31: =A30+1 -> 45259 | B31: 0 | C31: 0 | D31: 0 | E31: 70 | F31: T | G31: 0 | H31: 0 | I31: -
A32: =A31+1 -> 45260 | B32: 0 | C32: 0 | D32: 0 | E32: 76 | F32: 0.05 | G32: 0.5 | H32: 0 | I32: -
A33: Monthly Total | B33: =SUM(B3:B32) -> 0 | C33: =SUM(C3:C32) -> 1647 | D33: =SUM(D3:D32) -> 0 | E33: =SUM(E3:E32) -> 3858 | F33: =SUM(F3:F32) -> 0.88 | G33: =SUM(G3:G32) -> 0.5 | H33: =SUM(H3:H32) -> 0
A34: WY Total | B34: =SUM(B33+'Oct 2023'!B35) -> 0 | C34: =SUM(C33+'Oct 2023'!C35) -> 5872 | D34: =SUM(D33+'Oct 2023'!D35) -> 16 | E34: =SUM(E33+'Oct 2023'!E35) -> 13368 | F34: =SUM(F33+'Oct 2023'!F35) -> 1.27 | G34: =SUM(G33+'Oct 2023'!G35) -> 0.5 | H34: =SUM(H33+'Oct 2023'!H35) -> 0
A36: Acre Feet | B36: =SUM(B3:B32)*1.9835 -> 0 | C36: =SUM(C3:C32)*1.9835 -> 3266.8245 | D36: =SUM(D3:D32)*1.9835 -> 0 | E36: =SUM(E3:E32)*1.9835 -> 7652.343
A38: WY AF Total | B38: =SUM('Oct 2023'!B39+B36) -> 0 | C38: =SUM('Oct 2023'!C39+C36) -> 11647.112 | D38: =SUM('Oct 2023'!D39+D36) -> 31.736 | E38: =SUM('Oct 2023'!E39+E36) -> 26515.428
H40: * COMPUTATIONAL PURPOSES ONLY! Do Not Enter Data in the Red Columns
A42: *This is computation purposes only for Station 48
A43: Sta 48
G44: =SUM(24-E44) -> 24 | H44: =SUM(D44+F44) -> 0 | I44: =SUM(D44/24*E44+H44/24*G44) -> 0
...

Sheet Oct 2023
A1: DATE | B1: LRDC | C1: STATION 48 | D1: ANDERSON-ROSE | E1: J CANAL | F1: TULE LAKE PRECIP | G1: TULE LAKE SNOW | H1: D PLANT | I1: TULE LAKE ELEV. | J1: CHANGES @ STATION 48
B2: (in CFS) | C2: (in CFS) | D2: (in CFS) | E2: (in CFS)
A3: 45200 | B3: 0 | C3: 150 | D3: 0 | E3: 378 | F3: 0 | G3: 0 | H3: 0 | I3: -
A4: =A3+1 -> 45201 | B4: 0 | C4: 150 | D4: 0 | E4: 403 | F4: 0 | G4: 0 | H4: 0 | I4: -
A5: =A4+1 -> 45202 | B5: 0 | C5: 150 | D5: 0 | E5: 418 | F5: 0.02 | G5: 0 | H5: 0 | I5: -
A6: =A5+1 -> 45203 | B6: 0 | C6: 150 | D6: 0 | E6: 403 | F6: 0 | G6: 0 | H6: 0 | I6: -
A7: =A6+1 -> 45204 | B7: 0 | C7: 150 | D7: 0 | E7: 399 | F7: 0 | G7: 0 | H7: 0 | I7: -
A8: =A7+1 -> 45205 | B8: 0 | C8: 150 | D8: 0 | E8: 363 | F8: 0 | G8: 0 | H8: 0 | I8: -
A9: =A8+1 -> 45206 | B9: 0 | C9: 150 | D9: 0 | E9: 345 | F9: 0 | G9: 0 | H9: 0 | I9: -
A10: =A9+1 -> 45207 | B10: 0 | C10: 150 | D10: 4 | E10: 345 | F10: 0 | G10: 0 | H10: 0 | I10: -
A11: =A10+1 -> 45208 | B11: 0 | C11: 150 | D11: 9 | E11: 356 | F11: 0 | G11: 0 | H11: 0 | I11: -
A12: =A11+1 -> 45209 | B12: 0 | C12: 150 | D12: 3 | E12: 385 | F12: 0.11 | G12: 0 | H12: 0 | I12: -
A13: =A12+1 -> 45210 | B13: 0 | C13: 150 | D13: 0 | E13: 420 | F13: 0.12 | G13: 0 | H13: 0 | I13: -
A14: =A13+1 -> 45211 | B14: 0 | C14: 150 | D14: 0 | E14: 382 | F14: 0.01 | G14: 0 | H14: 0 | I14: -
A15: =A14+1 -> 45212 | B15: 0 | C15: 150 | D15: 0 | E15: 362 | F15: 0 | G15: 0 | H15: 0 | I15: -
... A23: =A22+1 -> 45220 | B23: 0 | C23: 150 | D23: 0 | E23: 223 | F23: 0 | G23: 0 | H23: 0 | I23: -
A24: =A23+1 -> 45221 | B24: 0 | C24: 150 | D24: 0 | E24: 202 | F24: T | G24: 0 | H24: 0 | I24: -
A25: =A24+1 -> 45222 | B25: 0 | C25: 125 | D25: 0 | E25: 206 | F25: 0 | G25: 0 | H25: 0 | I25: - | J25: * 12:00 150/100
A26: =A25+1 -> 45223 | B26: 0 | C26: 100 | D26: 0 | E26: 221 | F26: T | G26: 0 | H26: 0 | I26: -
A27: =A26+1 -> 45224 | B27: 0 | C27: 100 | D27: 0 | E27: 235 | F27: 0.04 | G27: 0 | H27: 0 | I27: -
A28: =A27+1 -> 45225 | B28: 0 | C28: 100 | D28: 0 | E28: 241 | F28: 0.03 | G28: 0 | H28: 0 | I28: -
A29: =A28+1 -> 45226 | B29: 0 | C29: 100 | D29: 0 | E29: 231 | F29: 0 | G29: 0 | H29: 0 | I29: -
A30: =A29+1 -> 45227 | B30: 0 | C30: 100 | D30: 0 | E30: 214 | F30: 0 | G30: 0 | H30: 0 | I30: -
A31: =A30+1 -> 45228 | B31: 0 | C31: 100 | D31: 0 | E31: 196 | F31: 0 | G31: 0 | H31: 0 | I31: -
A32: =A31+1 -> 45229 | B32: 0 | C32: 100 | D32: 0 | E32: 203 | F32: 0 | G32: 0 | H32: 0 | I32: -
A33: =A32+1 -> 45230 | B33: 0 | C33: 100 | D33: 0 | E33: 224 | F33: 0 | G33: 0 | H33: 0 | I33: -
A34: Monthly Total | B34: =SUM(B3:B33) -> 0 | C34: =SUM(C3:C33) -> 4225 | D34: =SUM(D3:D33) -> 16 | E34: =SUM(E3:E33) -> 9510 | F34: =SUM(F3:F33) -> 0.39 | G34: =SUM(G3:G33) -> 0 | H34: =SUM(H3:H33) -> 0 | I34: -
A35: WY Total | B35: =SUM(B34+'Oct 2023'!B36) -> 0 | C35: =SUM(C34+'Oct 2023'!C36) -> 4225 | D35: =SUM(D34+'Oct 2023'!D36) -> 16 | E35: =SUM(E34+'Oct 2023'!E36) -> 9510 | F35: =SUM(F34+'Oct 2023'!F36) -> 0.39 | G35: =SUM(G34+'Oct 2023'!G36) -> 0 | H35: =SUM(H34+'Oct 2023'!H36) -> 0
A37: Acre Feet | B37: =SUM(B3:B33)*1.9835 -> 0 | C37: =SUM(C3:C33)*1.9835 -> 8380.2875 | D37: =SUM(D3:D33)*1.9835 -> 31.736 | E37: =SUM(E3:E33)*1.9835 -> 18863.085
A39: WY AF Total | B39: =SUM('Oct 2023'!B40+B37) -> 0 | C39: =SUM('Oct 2023'!C40+C37) -> 8380.2875 | D39: =SUM('Oct 2023'!D40+D37) -> 31.736 | E39: =SUM('Oct 2023'!E40+E37) -> 18863.085
H41: * COMPUTATIONAL PURPOSES ONLY! Do Not Enter Data in the Red Columns
A43: *This is computation purposes only for Station 48
A44: Sta 48
G45: =SUM(24-E45) -> 24 | H45: =SUM(D45+F45) -> 0 | I45: =SUM(D45/24*E45+H45/24*G45) -> 0
G46: =SUM(24-E46) -> 24 | H46: =SUM(D46+F46) -> 0 | I46: =SUM(D46/24*E46+H46/24*G46) -> 0
G47: =SUM(24-E47) -> 24 | H47: =SUM(D47+F47) -> 0 | I47: =SUM(D47/24*E47+H47/24*G47) -> 0
G48: =SUM(24-E48) -> 24 | H48: =SUM(D48+F48) -> 0 | I48: =SUM(D48/24*E48+H48/24*G48) -> 0
G49: =SUM(24-E49) -> 24 | H49: =SUM(D49+F49) -> 0 | I49: =SUM(D49/24*E49+H49/24*G49) -> 0
A51: Use for more than 1 change in a day.
A52: **Station 48: | C52: Time | D52: Current CFS | E52: Hours Run | F52: +/- cfs | G52: Sub-total cfs
...
