Workbook

Sheet Sep 2017
A1: DATE | B1: STATION 48 | C1: ANDERSON-ROSE | D1: J CANAL | E1: TULE LAKE PRECIP | F1: TULE LAKE SNOW | G1: D PLANT | H1: TULE LAKE ELEV. | I1: CHANGES @ STATION 48
B2: (in CFS) | C2: (in CFS) | D2: (in CFS) | G2: (in AF)
A3: 42979 | B3: 215 | C3: 75 | D3: 391 | E3: 0 | F3: 0 | G3: 0 | H3: 4034.9 | I3: * 07:00 250/200
A4: 42980 | B4: 179 | C4: 30 | D4: 373 | E4: 0 | F4: 0 | G4: 0 | H4: 4034.95 | I4: * 14:00 200/150
A5: 42981 | B5: 150 | C5: 27 | D5: 358 | E5: 0 | F5: 0 | G5: 0 | H5: 4034.95
A6: 42982 | B6: 133 | C6: 5 | D6: 370 | E6: 0 | F6: 0 | G6: 0 | H6: 4034.95 | I6: * 10:00 150/100 * 16:00 100/150
A7: 42983 | B7: 163 | C7: 0 | D7: 376 | E7: 0 | F7: 0 | G7: 0 | H7: 4034.96 | I7: * 18:00 150/200
A8: 42984 | B8: 200 | C8: 0 | D8: 376 | E8: 0 | F8: 0 | G8: 0 | H8: 4034.96
A9: 42985 | B9: 185 | C9: 0 | D9: 353 | E9: 0.07 | F9: 0 | G9: 0 | H9: 4034.96 | I9: * 1700 200/150
A10: 42986 | B10: 119 | C10: 0 | D10: 331 | E10: 0 | F10: 0 | G10: 0 | H10: 4034.97 | I10: * 0900 150/100
A11: 42987 | B11: 117 | C11: 0 | D11: 315 | E11: 0 | F11: 0 | G11: 0 | H11: 4034.98 | I11: * 0800 100/150 * 1600 150/100
A12: 42988 | B12: 73 | C12: 0 | D12: 265 | E12: 0 | F12: 0 | G12: 0 | H12: 4034.98 | I12: * 1100 100/50
A13: 42989 | B13: 95 | C13: 0 | D13: 286 | E13: 0 | F13: 0 | G13: 0 | H13: 4035 | I13: * 0830 50/150 * 1600 150/100 * 22:30 100/50
A14: 42990 | B14: 50 | C14: 0 | D14: 293 | E14: T | F14: 0 | G14: 0 | H14: 4035
A15: 42991 | B15: 36 | C15: 0 | D15: 262 | E15: 0 | F15: 0 | G15: 103 | H15: 4035 | I15: * 13:00 50/20
A16: 42992 | B16: 20 | C16: 0 | D16: 235 | E16: 0 | F16: 0 | G16: 261 | H16: 4035
A17: 42993 | B17: 38 | C17: 0 | D17: 212 | E17: 0 | F17: 0 | G17: 297 | H17: 4035 | I17: * 10:00 20/50
A18: 42994 | B18: 31 | C18: 0 | D18: 187 | E18: 0 | F18: 0 | G18: 318 | H18: 4035 | I18: * 09:00 50/20
A19: 42995 | B19: 12 | C19: 20 | D19: 166 | E19: 0 | F19: 0 | G19: 318 | H19: 4034.96 | I19: * 14:00 20/0
A20: 42996 | B20: 0 | C20: 17 | D20: 157 | E20: 0.05 | F20: 0 | G20: 318 | H20: 4034.94
A21: 42997 | B21: 0 | C21: 18 | D21: 147 | E21: 0.01 | F21: 0 | G21: 318 | H21: 4034.92
A22: 42998 | B22: 0 | C22: 15 | D22: 141 | E22: 0.04 | F22: 0 | G22: 318 | H22: 4034.9
A23: 42999 | B23: 0 | C23: 5 | D23: 151 | E23: 0.01 | F23: 0 | G23: 318 | H23: 4034.88
A24: 43000 | B24: 0 | C24: 0 | D24: 147 | E24: 0 | F24: 0 | G24: 318 | H24: 4034.86
A25: 43001 | B25: 0 | C25: 0 | D25: 148 | E25: 0 | F25: 0 | G25: 318 | H25: 4034.84
A26: 43002 | B26: 8 | C26: 0 | D26: 166 | E26: 0 | F26: 0 | G26: 318 | H26: 4034.82 | I26: * 1600 0/25
A27: 43003 | B27: 25 | C27: 0 | D27: 180 | E27: 0 | F27: 0 | G27: 318 | H27: 4034.82
A28: 43004 | B28: 9 | C28: 9 | D28: 166 | E28: 0 | F28: 0 | G28: 318 | H28: 4034.82 | I28: * 09:00 25/0
A29: 43005 | B29: 0 | C29: 0 | D29: 160 | E29: 0 | F29: 0 | G29: 318 | H29: 4034.82
A30: 43006 | B30: 0 | C30: 0 | D30: 152 | E30: 0 | F30: 0 | G30: 318 | H30: 4034.82
A31: 43007 | B31: 0 | C31: 0 | D31: 131 | E31: 0 | F31: 0 | G31: 318 | H31: 4034.8
A32: 43008 | B32: 0 | C32: 51 | D32: 99 | E32: 0 | F32: 0 | G32: 318 | H32: 4034.8
A33: Monthly Total | B33: =SUM(B3:B32) -> 1858 | C33: =SUM(C3:C32) -> 272 | D33: =SUM(D3:D32) -> 7094 | E33: =SUM(E3:E32) -> 0.18 | F33: =SUM(F3:F32) -> 0 | G33: =SUM(G3:G32) -> 5431
A34: WY Total | B34: =SUM(B33+'Aug 2017'!B35) -> 35926 | C34: =SUM(C33+'Aug 2017'!C35) -> 10576 | D34: =SUM(D33+'Aug 2017'!D35) -> 60532 | E34: =SUM(E33+'Aug 2017'!E35) -> 11.849 | F34: =SUM(F33+'Aug 2017'!F35) -> 27.6 | G34: =SUM(G33+'Aug 2017'!G35) -> 32511
A36: Acre Feet | B36: =SUM(B3:B32)*1.9835 -> 3685.343 | C36: =SUM(C3:C32)*1.9835 -> 539.512 | D36: =SUM(D3:D32)*1.9835 -> 14070.949
A38: WY AF Total | B38: =SUM(B36+'Aug 2017'!B39) -> 71259.221 | C38: =SUM(C36+'Aug 2017'!C39) -> 23439.019 | D38: =SUM(D36+'Aug 2017'!D39) -> 122715.18
G40: * COMPUTATIONAL PURPOSES ONLY! Do Not Enter Data in the Red Columns
A42: *This is computation purposes only for Station 48
A43: Sta 48
F44: =SUM(24-D44) -> 24 | G44: =SUM(C44+E44) -> 0 | H44: =SUM(C44/24*D44+G44/24*F44) -> 0
...

Sheet Aug 2017
A1: DATE | B1: STATION 48 | C1: ANDERSON-ROSE | D1: J CANAL | E1: TULE LAKE PRECIP | F1: TULE LAKE SNOW | G1: D PLANT | H1: TULE LAKE ELEV. | I1: CHANGES @ STATION 48
B2: (in CFS) | C2: (in CFS) | D2: (in CFS) | G2: (in AF)
A3: 42948 | B3: 327 | C3: 0 | D3: 465 | E3: 0 | F3: 0 | G3: 0 | H3: 4034.78 | I3: *15:00 350/250 * 17:00 250/300
A4: 42949 | B4: 300 | C4: 0 | D4: 422 | E4: 0 | F4: 0 | G4: 0 | H4: 4034.76
A5: 42950 | B5: 338 | C5: 0 | D5: 419 | E5: 0 | F5: 0 | G5: 0 | H5: 4034.78 | I5: * noon 300/400 * 1800 400/350
A6: 42951 | B6: 350 | C6: 0 | D6: 458 | E6: 0 | F6: 0 | G6: 0 | H6: 4034.78
A7: 42952 | B7: 342 | C7: 0 | D7: 460 | E7: 0 | F7: 0 | G7: 0 | H7: 4034.8 | I7: * 1130 350/300 * 1530 300/350
A8: 42953 | B8: 308 | C8: 19 | D8: 428 | E8: 0 | F8: 0 | G8: 0 | H8: 4034.8 | I8: * 14:00 350/250
A9: 42954 | B9: 243 | C9: 43 | D9: 376 | E9: 0.02 | F9: 0 | G9: 0 | H9: 4034.8 | I9: * 20:30 250/200
A10: 42955 | B10: 218 | C10: 0 | D10: 362 | E10: 0 | F10: 0 | G10: 0 | H10: 4034.8 | I10: * 15:30 200/250
A11: 42956 | B11: 233 | C11: 8 | D11: 378 | E11: 0 | F11: 0 | G11: 0 | H11: 4034.8 | I11: * 1600 250/200
A12: 42957 | B12: 211 | C12: 10 | D12: 387 | E12: 0 | F12: 0 | G12: 0 | H12: 4034.81 | I12: * 1800 200/250 * 23:30 250/200
A13: 42958 | B13: 167 | C13: 11 | D13: 340 | E13: 0.17 | F13: 0 | G13: 0 | H13: 4034.82 | I13: * 08:00 200/150
A14: 42959 | B14: 121 | C14: 38 | D14: 292 | E14: 0 | F14: 0 | G14: 0 | H14: 4034.84 | I14: * 14:00 150/50 * 18:00 50/100
A15: 42960 | B15: 100 | C15: 14 | D15: 275 | E15: 0 | F15: 0 | G15: 0 | H15: 4034.86
A16: 42961 | B16: 100 | C16: 10 | D16: 275 | E16: 0 | F16: 0 | G16: 0 | H16: 4034.86
A17: 42962 | B17: 119 | C17: 0 | D17: 323 | E17: 0 | F17: 0 | G17: 0 | H17: 4034.86 | I17: * 1500 100/150
A18: 42963 | B18: 150 | C18: 0 | D18: 330 | E18: 0 | F18: 0 | G18: 0 | H18: 4034.85
A19: 42964 | B19: 221 | C19: 0 | D19: 348 | E19: 0 | F19: 0 | G19: 0 | H19: 4034.85 | I19: * 7:00 150/250
A20: 42965 | B20: 223 | C20: 5 | D20: 348 | E20: 0 | F20: 0 | G20: 0 | H20: 4034.86 | I20: * 16:00 250/150
A21: 42966 | B21: 150 | C21: 33 | D21: 355 | E21: 0 | F21: 0 | G21: 0 | H21: 4034.86
A22: 42967 | B22: 150 | C22: 0 | D22: 376 | E22: 0 | F22: 0 | G22: 0 | H22: 4034.85
A23: 42968 | B23: 217 | C23: 0 | D23: 383 | E23: 0 | F23: 0 | G23: 0 | H23: 4034.85 | I23: * 8:00 150/250
A24: 42969 | B24: 271 | C24: 0 | D24: 404 | E24: 0 | F24: 0 | G24: 0 | H24: 4034.85 | I24: * 14:00 250/300
A25: 42970 | B25: 300 | C25: 0 | D25: 388 | E25: 0.05 | F25: 0 | G25: 0 | H25: 4034.85
A26: 42971 | B26: 300 | C26: 0 | D26: 384 | E26: 0 | F26: 0 | G26: 0 | H26: 4034.86
A27: 42972 | B27: 265 | C27: 0 | D27: 408 | E27: 0 | F27: 0 | G27: 0 | H27: 4034.87 | I27: * 7:00 300/250
A28: 42973 | B28: 217 | C28: 8 | D28: 376 | E28: 0 | F28: 0 | G28: 0 | H28: 4034.88 | I28: * 0800 250/200
A29: 42974 | B29: 165 | C29: 24 | D29: 352 | E29: 0 | F29: 0 | G29: 0 | H29: 4034.9 | I29: * 0700 200/150
A30: 42975 | B30: 163 | C30: 0 | D30: 363 | E30: 0 | F30: 0 | G30: 0 | H30: 4034.9 | I30: * 1800 150/200
A31: 42976 | B31: 213 | C31: 0 | D31: 387 | E31: 0 | F31: 0 | G31: 0 | H31: 4034.9 | I31: * 1800 200/250
A32: 42977 | B32: 283 | C32: 0 | D32: 403 | E32: 0 | F32: 0 | G32: 0 | H32: 4034.9 | I32: * 1300 250/350 * 18:00 350/300
A33: 42978 | B33: 279 | C33: 10 | D33: 373 | E33: 0 | F33: 0 | G33: 0 | H33: 4034.95 | I33: * 14:00 300/250
A34: Monthly Total | B34: =SUM(B3:B33) -> 7044 | C34: =SUM(C3:C33) -> 233 | D34: =SUM(D3:D33) -> 11638 | E34: =SUM(E3:E33) -> 0.24 | F34: =SUM(F3:F33) -> 0 | G34: =SUM(G3:G33) -> 0
A35: WY Total | B35: =SUM(B34+'Jul 2017'!B35) -> 34068 | C35: =SUM(C34+'Jul 2017'!C35) -> 10304 | D35: =SUM(D34+'Jul 2017'!D35) -> 53438 | E35: =SUM(E34+'Jul 2017'!E35) -> 11.669 | F35: =SUM(F34+'Jul 2017'!F35) -> 27.6 | G35: =SUM(G34+'Jul 2017'!G35) -> 27080
A37: Acre Feet | B37: =SUM(B3:B33)*1.9835 -> 13971.774 | C37: =SUM(C3:C33)*1.9835 -> 462.1555 | D37: =SUM(D3:D33)*1.9835 -> 23083.973
A39: WY AF Total | B39: =SUM(B37+'Jul 2017'!B39) -> 67573.878 | C39: =SUM(C37+'Jul 2017'!C39) -> 22899.507 | D39: =SUM(D37+'Jul 2017'!D39) -> 108644.23
G41: * COMPUTATIONAL PURPOSES ONLY! Do Not Enter Data in the Red Columns
A43: *This is computation purposes only for Station 48
A44: Sta 48
...

Sheet Jul 2017
A1: DATE | B1: STATION 48 | C1: ANDERSON-ROSE | D1: J CANAL | E1: TULE LAKE PRECIP | F1: TULE LAKE SNOW | G1: D PLANT | H1: TULE LAKE ELEV. | I1: CHANGES @ STATION 48
B2: (in CFS) | C2: (in CFS) | D2: (in CFS) | G2: (in AF)
A3: 42917 | B3: 500 | C3: 0 | D3: 610 | E3: 0 | F3: 0 | G3: 0 | H3: 4035.05
A4: 42918 | B4: 535 | C4: 0 | D4: 623 | E4: 0 | F4: 0 | G4: 0 | H4: 4035.04 | I4: * 07:00 500/550
A5: 42919 | B5: 466 | C5: 45 | D5: 591 | E5: 0 | F5: 0 | G5: 0 | H5: 4035.02 | I5: * 07:00 550/500 *09:00 500/450 * 15:30 450/400
A6: 42920 | B6: 434 | C6: 7 | D6: 579 | E6: 0 | F6: 0 | G6: 0 | H6: 4034.02 | I6: * 15:00 400/450 * 16:30 450/500
A7: 42921 | B7: 467 | C7: 19 | D7: 577 | E7: 0 | F7: 0 | G7: 0 | H7: 4035 | I7: * 08:00 500/450
A8: 42922 | B8: 450 | C8: 11 | D8: 578 | E8: 0 | F8: 0 | G8: 0 | H8: 4035
A9: 42923 | B9: 450 | C9: 0 | D9: 558 | E9: 0 | F9: 0 | G9: 0 | H9: 4034.98
A10: 42924 | B10: 450 | C10: 0 | D10: 494 | E10: 0 | F10: 0 | G10: 0 | H10: 4034.96
A11: 42925 | B11: 379 | C11: 0 | D11: 426 | E11: 0 | F11: 0 | G11: 0 | H11: 4034.95 | I11: * 0700 450/350
A12: 42926 | B12: 328 | C12: 0 | D12: 442 | E12: 0 | F12: 0 | G12: 0 | H12: 4034.94 | I12: * 1200 350/300 * 22:30 300/350
A13: 42927 | B13: 350 | C13: 0 | D13: 461 | E13: 0 | F13: 0 | G13: 0 | H13: 4034.94
A14: 42928 | B14: 355 | C14: 0 | D14: 464 | E14: 0 | F14: 0 | G14: 0 | H14: 4034.92 | I14: * 21:30 350/400
A15: 42929 | B15: 388 | C15: 0 | D15: 466 | E15: 0 | F15: 0 | G15: 0 | H15: 4034.92 | I15: * 18:00 400/350
A16: 42930 | B16: 350 | C16: 0 | D16: 463 | E16: 0 | F16: 0 | G16: 0 | H16: 4034.9
A17: 42931 | B17: 421 | C17: 0 | D17: 468 | E17: 0 | F17: 0 | G17: 0 | H17: 4034.88 | I17: * 07:00 350/450
A18: 42932 | B18: 360 | C18: 5 | D18: 430 | E18: 0 | F18: 0 | G18: 0 | H18: 4034.88 | I18: * 07:00 450/350 * 15:00 350/300
A19: 42933 | B19: 306 | C19: 33 | D19: 430 | E19: 0 | F19: 0 | G19: 0 | H19: 4034.86 | I19: * 15:00 300/350 * 18:00 350/300
A20: 42934 | B20: 315 | C20: 0 | D20: 470 | E20: 0 | F20: 0 | G20: 0 | H20: 4034.86 | I20: * 17:00 300/350
A21: 42935 | B21: 385 | C21: 0 | D21: 471 | E21: 0 | F21: 0 | G21: 0 | H21: 4034.86 | I21: *07:00 350/400
A22: 42936 | B22: 400 | C22: 0 | D22: 455 | E22: 0 | F22: 0 | G22: 0 | H22: 4034.84
A23: 42937 | B23: 433 | C23: 0 | D23: 454 | E23: 0 | F23: 0 | G23: 0 | H23: 4034.84 | I23: * 0800 400/500 * 1600 500/400
A24: 42938 | B24: 385 | C24: 0 | D24: 466 | E24: 0 | F24: 0 | G24: 0 | H24: 4034.84 | I24: * 1700 400/350
A25: 42939 | B25: 331 | C25: 54 | D25: 454 | E25: 0 | F25: 0 | G25: 0 | H25: 4034.84 | I25: * 1500 350/300
A26: 42940 | B26: 325 | C26: 11 | D26: 479 | E26: 0 | F26: 0 | G26: 0 | H26: 4034.84 | I26: * 1800 300/400
A27: 42941 | B27: 340 | C27: 33 | D27: 528 | E27: 0 | F27: 0 | G27: 0 | H27: 4034.84 | I27: * 0630 400/300 * 2100 300/400
A28: 42942 | B28: 329 | C28: 0 | D28: 514 | E28: 0.02 | F28: 0 | G28: 0 | H28: 4034.84 | I28: * 07:00 400/300
A29: 42943 | B29: 246 | C29: 5 | D29: 456 | E29: 0 | F29: 0 | G29: 0 | H29: 4034.84 | I29: * 11:00 300/200
A30: 42944 | B30: 267 | C30: 0 | D30: 461 | E30: 0 | F30: 0 | G30: 0 | H30: 4034.83 | I30: * 08:00 200/300
A31: 42945 | B31: 385 | C31: 0 | D31: 479 | E31: 0 | F31: 0 | G31: 0 | H31: 4034.82 | I31: *10:00 300/400 *17:30 400/500
A32: 42946 | B32: 392 | C32: 43 | D32: 471 | E32: 0 | F32: 0 | G32: 0 | H32: 4034.8 | I32: *7:00 500/400 *15:00 400/300
A33: 42947 | B33: 325 | C33: 40 | D33: 463 | E33: 0 | F33: 0 | G33: 0 | H33: 4034.8 | I33: * 15:00 300/400 * 18:00 400/350
A34: Monthly Total | B34: =SUM(B3:B33) -> 11847 | C34: =SUM(C3:C33) -> 306 | D34: =SUM(D3:D33) -> 15281 | E34: =SUM(E3:E33) -> 0.02 | F34: =SUM(F3:F33) -> 0 | G34: =SUM(G3:G33) -> 0
A35: WY Total | B35: =SUM(B34+'Jun 2017'!B34) -> 27024 | C35: =SUM(C34+'Jun 2017'!C34) -> 10071 | D35: =SUM(D34+'Jun 2017'!D34) -> 41800 | E35: =SUM(E34+'Jun 2017'!E34) -> 11.429 | F35: =SUM(F34+'Jun 2017'!F34) -> 27.6 | G35: =SUM(G34+'Jun 2017'!G34) -> 27080
A37: Acre Feet | B37: =SUM(B3:B33)*1.9835 -> 23498.524 | C37: =SUM(C3:C33)*1.9835 -> 606.951 | D37: =SUM(D3:D33)*1.9835 -> 30309.863
A39: WY AF Total | B39: =SUM(B37+'Jun 2017'!B38) -> 53602.104 | C39: =SUM(C37+'Jun 2017'!C38) -> 22437.352 | D39: =SUM(D37+'Jun 2017'!D38) -> 85560.256
G41: * COMPUTATIONAL PURPOSES ONLY! Do Not Enter Data in the Red Columns
A43: *This is computation purposes only for Station 48
A44: Sta 48
...

Sheet Jun 2017
A1: DATE | B1: STATION 48 | C1: ANDERSON-ROSE | D1: J CANAL | E1: TULE LAKE PRECIP | F1: TULE LAKE SNOW | G1: D PLANT | H1: TULE LAKE ELEV. | I1: CHANGES @ STATION 48
B2: (in CFS) | C2: (in CFS) | D2: (in CFS) | G2: (in AF)
A3: 42887 | B3: 283 | C3: 0 | D3: 375 | E3: 0.12 | F3: 0 | G3: 0 | H3: 4035 | I3: * 16:00 250/350
A4: 42888 | B4: 429 | C4: 0 | D4: 345 | E4: 0 | F4: 0 | G4: 0 | H4: 4035 | I4: * 07:00 350/400 *13:30 400/500
A5: 42889 | B5: 376 | C5: 63 | D5: 303 | E5: 0 | F5: 0 | G5: 0 | H5: 4035 | I5: * 08:30 500/350 * 11:00 350/300
A6: 42890 | B6: 300 | C6: 49 | D6: 307 | E6: 0 | F6: 0 | G6: 0 | H6: 4035
A7: 42891 | B7: 235 | C7: 0 | D7: 349 | E7: 0 | F7: 0 | G7: 0 | H7: 4035.01 | I7: * 08:30 300/200
A8: 42892 | B8: 205 | C8: 0 | D8: 349 | E8: 0 | F8: 0 | G8: 0 | H8: 4035.02 | I8: * 21:30 200/250
A9: 42893 | B9: 250 | C9: 0 | D9: 362 | E9: 0 | F9: 0 | G9: 0 | H9: 4035.03
A10: 42894 | B10: 250 | C10: 0 | D10: 369 | E10: 0 | F10: 0 | G10: 0 | H10: 4035.04
A11: 42895 | B11: 250 | C11: 0 | D11: 349 | E11: 0.01 | F11: 0 | G11: 0 | H11: 4035.05
A12: 42896 | B12: 267 | C12: 6 | D12: 357 | E12: 0.02 | F12: 0 | G12: 0 | H12: 4035.06 | I12: * 02:30 AM 250/350 * 0700 350/300 * 1500 300/250 * 1700 250/200
A13: 42897 | B13: 154 | C13: 70 | D13: 334 | E13: 0.43 | F13: 0 | G13: 0 | H13: 4035.07 | I13: * 1300 200/100
A14: 42898 | B14: 125 | C14: 0 | D14: 312 | E14: 0.29 | F14: 0 | G14: 0 | H14: 4035.12 | I14: * 0800 100/200 * 1400 200/100
A15: 42899 | B15: 151 | C15: 0 | D15: 270 | E15: 0 | F15: 0 | G15: 0 | H15: 4035.16 | I15: * 0800 100/200 * 1630 200/150
A16: 42900 | B16: 150 | C16: 0 | D16: 271 | E16: 0 | F16: 0 | G16: 0 | H16: 4035.2
A17: 42901 | B17: 122 | C17: 0 | D17: 272 | E17: 0 | F17: 0 | G17: 0 | H17: 4035.2 | I17: * 10:30 150/100
A18: 42902 | B18: 100 | C18: 0 | D18: 266 | E18: 0 | F18: 0 | G18: 0 | H18: 4035.24
A19: 42903 | B19: 135 | C19: 0 | D19: 269 | E19: 0 | F19: 0 | G19: 0 | H19: 4035.25 | I19: *07:00 100/150
A20: 42904 | B20: 200 | C20: 0 | D20: 285 | E20: 0 | F20: 0 | G20: 0 | H20: 4035.25 | I20: * 09:00 150/200 * 11:00 200/235
A21: 42905 | B21: 281 | C21: 0 | D21: 363 | E21: 0 | F21: 0 | G21: 0 | H21: 4035.25 | I21: * 11:00 235/250 * 15:00 250/350
A22: 42906 | B22: 331 | C22: 0 | D22: 446 | E22: 0.2 | F22: 0 | G22: 0 | H22: 4035.25 | I22: * 15:00 350/300
A23: 42907 | B23: 300 | C23: 0 | D23: 416 | E23: 0 | F23: 0 | G23: 0 | H23: 4035.22
A24: 42908 | B24: 319 | C24: 0 | D24: 456 | E24: 0 | F24: 0 | G24: 0 | H24: 4035.2 | I24: * 0700 300/350 * 1600 350/300
A25: 42909 | B25: 300 | C25: 23 | D25: 441 | E25: 0 | F25: 0 | G25: 0 | H25: 4035.18
A26: 42910 | B26: 285 | C26: 0 | D26: 426 | E26: 0 | F26: 0 | G26: 0 | H26: 4035.16 | I26: * 1700 300/250
A27: 42911 | B27: 283 | C27: 5 | D27: 417 | E27: 0 | F27: 0 | G27: 0 | H27: 4035.15 | I27: * 0800 250/300
A28: 42912 | B28: 300 | C28: 2 | D28: 428 | E28: 0.51 | F28: 0 | G28: 0 | H28: 4035.15
A29: 42913 | B29: 319 | C29: 0 | D29: 481 | E29: 0 | F29: 0 | G29: 0 | H29: 4035.12 | I29: * 1500 300/350
A30: 42914 | B30: 388 | C30: 0 | D30: 545 | E30: 0 | F30: 0 | G30: 0 | H30: 4035.12 | I30: * 15:00 350/450
A31: 42915 | B31: 488 | C31: 0 | D31: 600 | E31: 0 | F31: 0 | G31: 0 | H31: 4035.1 | I31: * 15:00 450/550
A32: 42916 | B32: 534 | C32: 0 | D32: 626 | E32: 0 | F32: 0 | G32: 0 | H32: 4035.07 | I32: * 16:30 550/500
A33: Monthly Total | B33: =SUM(B3:B32) -> 8110 | C33: =SUM(C3:C32) -> 218 | D33: =SUM(D3:D32) -> 11389 | E33: =SUM(E3:E32) -> 1.58 | F33: =SUM(F3:F32) -> 0 | G33: =SUM(G3:G32) -> 0
A34: WY Total | B34: =SUM(B33+'May 2017'!B35) -> 15177 | C34: =SUM(C33+'May 2017'!C35) -> 9765 | D34: =SUM(D33+'May 2017'!D35) -> 26519 | E34: =SUM(E33+'May 2017'!E35) -> 11.409 | F34: =SUM(F33+'May 2017'!F35) -> 27.6 | G34: =SUM(G33+'May 2017'!G35) -> 27080
A36: Acre Feet | B36: =SUM(B3:B32)*1.9835 -> 16086.185 | C36: =SUM(C3:C32)*1.9835 -> 432.403 | D36: =SUM(D3:D32)*1.9835 -> 22590.082
A38: WY AF Total | B38: =SUM(B36+'May 2017'!B39) -> 30103.579 | C38: =SUM(C36+'May 2017'!C39) -> 21830.401 | D38: =SUM(D36+'May 2017'!D39) -> 55250.393
G40: * COMPUTATIONAL PURPOSES ONLY! Do Not Enter Data in the Red Columns
A42: *This is computation purposes only for Station 48
A43: Sta 48
F44: =SUM(24-D44) -> 24 | G44: =SUM(C44+E44) -> 0 | H44: =SUM(C44/24*D44+G44/24*F44) -> 0
...

Sheet May 2017
A1: DATE | B1: STATION 48 | C1: ANDERSON-ROSE | D1: J CANAL | E1: TULE LAKE PRECIP | F1: TULE LAKE SNOW | G1: D PLANT | H1: TULE LAKE ELEV. | I1: CHANGES @ STATION 48
B2: (in CFS) | C2: (in CFS) | D2: (in CFS) | G2: (in AF)
A3: 42856 | B3: 0 | C3: 16 | D3: 125 | E3: 0 | F3: 0 | G3: 0 | H3: 4035
A4: 42857 | B4: 21 | C4: 0 | D4: 138 | E4: 0 | F4: 0 | G4: 0 | H4: 4034.98 | I4: * 2PM 0/50
A5: 42858 | B5: 77 | C5: 0 | D5: 159 | E5: 0 | F5: 0 | G5: 0 | H5: 4034.98 | I5: * 11AM 50/100
A6: 42859 | B6: 89 | C6: 0 | D6: 183 | E6: 0 | F6: 0 | G6: 0 | H6: 4035 | I6: * 08:30 100/50 * 01:30 50/100 *16:00 100/150
A7: 42860 | B7: 166 | C7: 0 | D7: 208 | E7: 0 | F7: 0 | G7: 0 | H7: 4035 | I7: * 16:30 150/200
A8: 42861 | B8: 200 | C8: 0 | D8: 226 | E8: 0 | F8: 0 | G8: 0 | H8: 4034.98
A9: 42862 | B9: 134 | C9: 35 | D9: 221 | E9: 0 | F9: 0 | G9: 0 | H9: 4034.98 | I9: * 08:00 200/100 *23:30 100/150
A10: 42863 | B10: 135 | C10: 0 | D10: 272 | E10: 0 | F10: 0 | G10: 0 | H10: 4034.98 | I10: * 08:00 150/98 * 14:00 98/146
A11: 42864 | B11: 210 | C11: 0 | D11: 336 | E11: 0 | F11: 0 | G11: 0 | H11: 4034.97 | I11: * 08:00 145/191 * 1400 191/238 * 1600 238/285
A12: 42865 | B12: 298 | C12: 0 | D12: 381 | E12: 0 | F12: 0 | G12: 0 | H12: 4034.96 | I12: * 15:00 281/327
A13: 42866 | B13: 348 | C13: 0 | D13: 409 | E13: 0 | F13: 0 | G13: 0 | H13: 4034.95 | I13: * 14:00 327/377
A14: 42867 | B14: 308 | C14: 0 | D14: 445 | E14: 0.1 | F14: T | G14: 0 | H14: 4034.95 | I14: * 12:00 370/276 *16:00 276/231
A15: 42868 | B15: 276 | C15: 0 | D15: 428 | E15: 0.14 | F15: T | G15: 0 | H15: 4034.94 | I15: * 09:00 222/309
A16: 42869 | B16: 291 | C16: 0 | D16: 406 | E16: 0 | F16: 0 | G16: 0 | H16: 4034.94 | I16: * 07:00 324/278
A17: 42870 | B17: 240 | C17: 0 | D17: 414 | E17: 0 | F17: 0 | G17: 0 | H17: 4034.94 | I17: * 12:00 283/237 *14:00 237/189
A18: 42871 | B18: 248 | C18: 0 | D18: 403 | E18: 0.1 | F18: 0 | G18: 0 | H18: 4034.94 | I18: * 0700 184/275
A19: 42872 | B19: 278 | C19: 0 | D19: 397 | E19: 0.02 | F19: 0 | G19: 0 | H19: 4034.96
A20: 42873 | B20: 307 | C20: 0 | D20: 388 | E20: 0 | F20: 0 | G20: 0 | H20: 4034.96 | I20: * 08:00 277/322
A21: 42874 | B21: 306 | C21: 0 | D21: 397 | E21: 0 | F21: 0 | G21: 0 | H21: 4034.98 | I21: * 13:30 319/273
A22: 42875 | B22: 296 | C22: 0 | D22: 392 | E22: 0 | F22: 0 | G22: 0 | H22: 4034.99
A23: 42876 | B23: 264 | C23: 5 | D23: 339 | E23: 0 | F23: 0 | G23: 0 | H23: 4035 | I23: * 13:30 300/250 *17:00 250/200
A24: 42877 | B24: 218 | C24: 13 | D24: 363 | E24: 0 | F24: 0 | G24: 0 | H24: 4035 | I24: * 15:30 200/250
A25: 42878 | B25: 270 | C25: 7 | D25: 375 | E25: 0 | F25: 0 | G25: 0 | H25: 4035 | I25: * 13:30 248/297
A26: 42879 | B26: 291 | C26: 0 | D26: 404 | E26: 0 | F26: 0 | G26: 0 | H26: 4035
A27: 42880 | B27: 278 | C27: 0 | D27: 411 | E27: 0 | F27: 0 | G27: 0 | H27: 4034.99 | I27: * 1600 294/246
A28: 42881 | B28: 226 | C28: 21 | D28: 404 | E28: 0 | F28: 0 | G28: 0 | H28: 4035 | I28: * 1400 246/197
A29: 42882 | B29: 177 | C29: 7 | D29: 360 | E29: 0 | F29: 0 | G29: 0 | H29: 4034.98 | I29: * 1300 200/150
A30: 42883 | B30: 150 | C30: 0 | D30: 327 | E30: 0 | F30: 0 | G30: 0 | H30: 4035
A31: 42884 | B31: 165 | C31: 0 | D31: 326 | E31: 0 | F31: 0 | G31: 0 | H31: 4035 | I31: * 0900 150/200 * 1600 200/150
A32: 42885 | B32: 171 | C32: 0 | D32: 270 | E32: 0 | F32: 0 | G32: 0 | H32: 4035 | I32: * 1400 150/200
A33: 42886 | B33: 220 | C33: 0 | D33: 349 | E33: 0.21 | F33: 0 | G33: 0 | H33: 4035 | I33: * 14:30 200/250
A34: Monthly Total | B34: =SUM(B3:B33) -> 6658 | C34: =SUM(C3:C33) -> 104 | D34: =SUM(D3:D33) -> 10256 | E34: =SUM(E3:E33) -> 0.57 | F34: =SUM(F3:F33) -> 0 | G34: =SUM(G3:G33) -> 0
A35: WY Total | B35: =SUM(B34+'Apr 2017'!B34) -> 7067 | C35: =SUM(C34+'Apr 2017'!C34) -> 9547 | D35: =SUM(D34+'Apr 2017'!D34) -> 15130 | E35: =SUM(E34+'Apr 2017'!E34) -> 9.829 | F35: =SUM(F34+'Apr 2017'!F34) -> 27.6 | G35: =SUM(G34+'Apr 2017'!G34) -> 27080
A37: Acre Feet | B37: =SUM(B3:B33)*1.9835 -> 13206.143 | C37: =SUM(C3:C33)*1.9835 -> 206.284 | D37: =SUM(D3:D33)*1.9835 -> 20342.776
A39: WY AF Total | B39: =SUM(B37+'Apr 2017'!B38) -> 14017.395 | C39: =SUM(C37+'Apr 2017'!C38) -> 21397.998 | D39: =SUM(D37+'Apr 2017'!D38) -> 32660.311
G41: * COMPUTATIONAL PURPOSES ONLY! Do Not Enter Data in the Red Columns
A43: *This is computation purposes only for Station 48
A44: Sta 48
...

Sheet Apr 2017
A1: DATE | B1: STATION 48 | C1: ANDERSON-ROSE | D1: J CANAL | E1: TULE LAKE PRECIP | F1: TULE LAKE SNOW | G1: D PLANT | H1: TULE LAKE ELEV. | I1: CHANGES @ STATION 48
B2: (in CFS) | C2: (in CFS) | D2: (in CFS) | G2: (in AF)
A3: 42826 | B3: 0 | C3: 0 | D3: 58 | E3: 0 | F3: 0 | G3: 0 | H3: 4034.68
A4: 42827 | B4: 0 | C4: 0 | D4: 58 | E4: 0 | F4: 0 | G4: 0 | H4: 4034.68
A5: 42828 | B5: 0 | C5: 0 | D5: 58 | E5: 0 | F5: 0 | G5: 0 | H5: 4034.68
A6: 42829 | B6: 0 | C6: 0 | D6: 54 | E6: 0 | F6: 0 | G6: 0 | H6: 4034.68
A7: 42830 | B7: 0 | C7: 0 | D7: 40 | E7: 0 | F7: 0 | G7: 0 | H7: 4034.68
A8: 42831 | B8: 0 | C8: 0 | D8: 42 | E8: 0 | F8: 0 | G8: 0 | H8: 4034.69
A9: 42832 | B9: 0 | C9: 0 | D9: 42 | E9: 0.24 | F9: 0 | G9: 0 | H9: 4034.69
A10: 42833 | B10: 0 | C10: 0 | D10: 58 | E10: 0.33 | F10: 0 | G10: 0 | H10: 4034.7
A11: 42834 | B11: 0 | C11: 8 | D11: 40 | E11: 0.02 | F11: 0 | G11: 0 | H11: 4034.7
A12: 42835 | B12: 0 | C12: 20 | D12: 41 | E12: 0.05 | F12: 0 | G12: 0 | H12: 4034.74
A13: 42836 | B13: 0 | C13: 45 | D13: 43 | E13: 0 | F13: 0 | G13: 0 | H13: 4034.76
A14: 42837 | B14: 0 | C14: 60 | D14: 41 | E14: 0.06 | F14: 0 | G14: 0 | H14: 4034.78
... A18: 42841 | B18: 0 | C18: 59 | D18: 39 | E18: 0 | F18: 0 | G18: 0 | H18: 4034.86
A19: 42842 | B19: 0 | C19: 50 | D19: 39 | E19: T | F19: 0 | G19: 0 | H19: 4034.86
A20: 42843 | B20: 0 | C20: 50 | D20: 46 | E20: 0.03 | F20: 0 | G20: 0 | H20: 4034.88
A21: 42844 | B21: 0 | C21: 50 | D21: 46 | E21: 0.07 | F21: 0 | G21: 0 | H21: 4034.88
A22: 42845 | B22: 0 | C22: 66 | D22: 46 | E22: 0.25 | F22: 0 | G22: 0 | H22: 4034.9
A23: 42846 | B23: 0 | C23: 67 | D23: 44 | E23: 0 | F23: 0 | G23: 0 | H23: 4034.92
A24: 42847 | B24: 0 | C24: 54 | D24: 45 | E24: 0 | F24: 0 | G24: 0 | H24: 4034.94
A25: 42848 | B25: 0 | C25: 50 | D25: 46 | E25: 0 | F25: 0 | G25: 0 | H25: 4034.96
A26: 42849 | B26: 0 | C26: 59 | D26: 38 | E26: 0.08 | F26: 0 | G26: 0 | H26: 4034.98
A27: 42850 | B27: 0 | C27: 70 | D27: 32 | E27: 0.02 | F27: 0 | G27: 0 | H27: 4034.99
A28: 42851 | B28: 0 | C28: 70 | D28: 31 | E28: 0.13 | F28: 0 | G28: 0 | H28: 4034.99
A29: 42852 | B29: 0 | C29: 70 | D29: 37 | E29: 0.01 | F29: 0 | G29: 0 | H29: 4034.99
A30: 42853 | B30: 0 | C30: 70 | D30: 37 | E30: 0 | F30: 0 | G30: 0 | H30: 4035
A31: 42854 | B31: 0 | C31: 51 | D31: 53 | E31: 0 | F31: 0 | G31: 0 | H31: 4035
A32: 42855 | B32: 0 | C32: 40 | D32: 65 | E32: 0 | F32: 0 | G32: 0 | H32: 4035
A33: Monthly Total | B33: =SUM(B3:B32) -> 0 | C33: =SUM(C3:C32) -> 1241 | D33: =SUM(D3:D32) -> 1336 | E33: =SUM(E3:E32) -> 1.44 | F33: =SUM(F3:F32) -> 1 | G33: =SUM(G3:G32) -> 0
A34: WY Total | B34: =SUM(B33+'Mar 2017'!B35) -> 409 | C34: =SUM(C33+'Mar 2017'!C35) -> 9443 | D34: =SUM(D33+'Mar 2017'!D35) -> 4874 | E34: =SUM(E33+'Mar 2017'!E35) -> 9.259 | F34: =SUM(F33+'Mar 2017'!F35) -> 27.6 | G34: =SUM(G33+'Mar 2017'!G35) -> 27080
A36: Acre Feet | B36: =SUM(B3:B33)*1.9835 -> 0 | C36: =SUM(C3:C33)*1.9835 -> 4923.047 | D36: =SUM(D3:D33)*1.9835 -> 5299.912
A38: WY AF Total | B38: =SUM(B36+'Mar 2017'!B39) -> 811.2515 | C38: =SUM(C36+'Mar 2017'!C39) -> 21191.714 | D38: =SUM(D36+'Mar 2017'!D39) -> 12317.535
G40: * COMPUTATIONAL PURPOSES ONLY! Do Not Enter Data in the Red Columns
A42: *This is computation purposes only for Station 48
A43: Sta 48
F44: =SUM(24-D44) -> 24 | G44: =SUM(C44+E44) -> 0 | H44: =SUM(C44/24*D44+G44/24*F44) -> 0
F45: =SUM(24-D45) -> 24 | G45: =SUM(C45+E45) -> 0 | H45: =SUM(C45/24*D45+G45/24*F45) -> 0
F46: =SUM(24-D46) -> 24 | G46: =SUM(C46+E46) -> 0 | H46: =SUM(C46/24*D46+G46/24*F46) -> 0
F47: =SUM(24-D47) -> 24 | G47: =SUM(C47+E47) -> 0 | H47: =SUM(C47/24*D47+G47/24*F47) -> 0
...

Sheet Mar 2017
A1: DATE | B1: STATION 48 | C1: ANDERSON-ROSE | D1: J CANAL | E1: TULE LAKE PRECIP | F1: TULE LAKE SNOW | G1: D PLANT | H1: TULE LAKE ELEV. | I1: CHANGES @ STATION 48
B2: (in CFS) | C2: (in CFS) | D2: (in CFS) | G2: (in AF)
A3: 42795 | B3: 0 | C3: 45 | D3: 0 | E3: 0 | F3: 0 | G3: 300 | H3: 4034.64
A4: 42796 | B4: 0 | C4: 40 | D4: 0 | E4: 0 | F4: 0 | G4: 300 | H4: 4034.63
A5: 42797 | B5: 0 | C5: 40 | D5: 0 | E5: 0 | F5: 0 | G5: 300 | H5: 4034.63
A6: 42798 | B6: 0 | C6: 40 | D6: 0 | E6: 0.03 | F6: 0 | G6: 300 | H6: 4034.62
A7: 42799 | B7: 0 | C7: 40 | D7: 0 | E7: 0.02 | F7: 0 | G7: 300 | H7: 4034.62
A8: 42800 | B8: 0 | C8: 40 | D8: 0 | E8: 0.01 | F8: 0 | G8: 300 | H8: 4034.61
A9: 42801 | B9: 0 | C9: 40 | D9: 0 | E9: 0.02 | F9: 0 | G9: 210 | H9: 4034.6 | I9: * Shut one unit D-Plant off @ apprx. 8:30 AM
A10: 42802 | B10: 0 | C10: 40 | D10: 0 | E10: 0.02 | F10: 0 | G10: 160 | H10: 4034.6
A11: 42803 | B11: 0 | C11: 40 | D11: 0 | E11: 0.03 | F11: 0 | G11: 160 | H11: 4034.59
A12: 42804 | B12: 0 | C12: 40 | D12: 0 | E12: 0.01 | F12: 0 | G12: 160 | H12: 4034.59
A13: 42805 | B13: 0 | C13: 40 | D13: 0 | E13: 0 | F13: 0 | G13: 54 | H13: 4034.58 | I13: * shut D-Plant off @ 8:05 AM
A14: 42806 | B14: 0 | C14: 40 | D14: 0 | E14: 0 | F14: 0 | G14: 0 | H14: 4034.58
A15: 42807 | B15: 0 | C15: 40 | D15: 0 | E15: T | F15: 0 | G15: 0 | H15: 4034.58
A16: 42808 | B16: 0 | C16: 16 | D16: 0 | E16: 0 | F16: 0 | G16: 0 | H16: 4034.6
A17: 42809 | B17: 0 | C17: 0 | D17: 0 | E17: 0.02 | F17: 0 | G17: 0 | H17: 4034.6
A18: 42810 | B18: 0 | C18: 0 | D18: 0 | E18: 0.03 | F18: 0 | G18: 0 | H18: 4034.6
A19: 42811 | B19: 0 | C19: 0 | D19: 41 | E19: 0 | F19: 0 | G19: 0 | H19: 4034.6
A20: 42812 | B20: 0 | C20: 0 | D20: 40 | E20: 0.03 | F20: 0 | G20: 0 | H20: 4034.6
A21: 42813 | B21: 0 | C21: 0 | D21: 35 | E21: 0.03 | F21: 0 | G21: 0 | H21: 4034.6
A22: 42814 | B22: 0 | C22: 0 | D22: 36 | E22: 0 | F22: 0 | G22: 0 | H22: 4034.6
A23: 42815 | B23: 0 | C23: 12 | D23: 37 | E23: 0.17 | F23: 0 | G23: 0 | H23: 4034.6
A24: 42816 | B24: 0 | C24: 28 | D24: 37 | E24: 0.46 | F24: 0 | G24: 0 | H24: 4034.62
A25: 42817 | B25: 0 | C25: 40 | D25: 37 | E25: 0.03 | F25: 0 | G25: 0 | H25: 4034.62
A26: 42818 | B26: 0 | C26: 33 | D26: 38 | E26: T | F26: 0 | G26: 0 | H26: 4034.64
A27: 42819 | B27: 0 | C27: 23 | D27: 37 | E27: T | F27: 0 | G27: 0 | H27: 4034.66
A28: 42820 | B28: 0 | C28: 20 | D28: 34 | E28: 0.15 | F28: 0 | G28: 0 | H28: 4034.66
A29: 42821 | B29: 0 | C29: 0 | D29: 42 | E29: 0.02 | F29: 0 | G29: 0 | H29: 4034.66
A30: 42822 | B30: 0 | C30: 0 | D30: 44 | E30: T | F30: 0 | G30: 0 | H30: 4034.66
A31: 42823 | B31: 0 | C31: 8 | D31: 43 | E31: 0.07 | F31: 0 | G31: 0 | H31: 4034.67
A32: 42824 | B32: 0 | C32: 20 | D32: 70 | E32: 0.29 | F32: 0 | G32: 0 | H32: 4034.67
A33: 42825 | B33: 0 | C33: 8 | D33: 58 | E33: 0.01 | F33: 0 | G33: 0 | H33: 4034.68
A34: Monthly Total | B34: =SUM(B3:B33) -> 0 | C34: =SUM(C3:C33) -> 733 | D34: =SUM(D3:D33) -> 629 | E34: =SUM(E3:E33) -> 1.45 | F34: =SUM(F3:F33) -> 0 | G34: =SUM(G3:G33) -> 2544
A35: WY Total | B35: =SUM(B34+'Feb 2017'!B32) -> 409 | C35: =SUM(C34+'Feb 2017'!C32) -> 8202 | D35: =SUM(D34+'Feb 2017'!D32) -> 3538 | E35: =SUM(E34+'Feb 2017'!E32) -> 7.819 | F35: =SUM(F34+'Feb 2017'!F32) -> 26.6 | G35: =SUM(G34+'Feb 2017'!G32) -> 27080
A37: Acre Feet | B37: =SUM(B3:B33)*1.9835 -> 0 | C37: =SUM(C3:C33)*1.9835 -> 1453.9055 | D37: =SUM(D3:D33)*1.9835 -> 1247.6215
A39: WY AF Total | B39: =SUM(B37+'Feb 2017'!B36) -> 811.2515 | C39: =SUM(C37+'Feb 2017'!C36) -> 16268.667 | D39: =SUM(D37+'Feb 2017'!D36) -> 7017.623
G41: * COMPUTATIONAL PURPOSES ONLY! Do Not Enter Data in the Red Columns
A43: *This is computation purposes only for Station 48
A44: Sta 48
...

Sheet Feb 2017
A1: DATE | B1: STATION 48 | C1: ANDERSON-ROSE | D1: J CANAL | E1: TULE LAKE PRECIP | F1: TULE LAKE SNOW | G1: D PLANT | H1: TULE LAKE ELEV. | I1: CHANGES @ STATION 48
B2: (in CFS) | C2: (in CFS) | D2: (in CFS) | G2: (in AF)
A3: 42767 | B3: 0 | C3: 60 | D3: 0 | E3: 0 | F3: 0 | G3: 160 | H3: 4034.55
A4: 42768 | B4: 0 | C4: 60 | D4: 0 | E4: 0.01 | F4: 0 | G4: 160 | H4: 4034.54
A5: 42769 | B5: 0 | C5: 83 | D5: 0 | E5: 0.38 | F5: 0 | G5: 160 | H5: 4034.57
A6: 42770 | B6: 0 | C6: 177 | D6: 0 | E6: T | F6: 0 | G6: 160 | H6: 4034.6
A7: 42771 | B7: 0 | C7: 200 | D7: 0 | E7: 0 | F7: 0 | G7: 160 | H7: 4034.63
A8: 42772 | B8: 0 | C8: 169 | D8: 0 | E8: 0.03 | F8: 0 | G8: 160 | H8: 4034.66
A9: 42773 | B9: 0 | C9: 150 | D9: 0 | E9: 0.42 | F9: 0.25 | G9: 253 | H9: 4034.69 | I9: * Started 2nd unit at D- Plant 8:43 AM
A10: 42774 | B10: 0 | C10: 170 | D10: 0 | E10: 0.03 | F10: 0 | G10: 395 | H10: 4034.72 | I10: * Starting 3rd unit at D-Plant apprx. 10:30 AM
A11: 42775 | B11: 0 | C11: 190 | D11: 0 | E11: 0.07 | F11: 0 | G11: 453 | H11: 4034.75
A12: 42776 | B12: 0 | C12: 203 | D12: 0 | E12: 0.02 | F12: 0 | G12: 452 | H12: 4034.78
A13: 42777 | B13: 0 | C13: 194 | D13: 0 | E13: 0 | F13: 0 | G13: 452 | H13: 4034.81
A14: 42778 | B14: 0 | C14: 123 | D14: 0 | E14: 0 | F14: 0 | G14: 452 | H14: 4034.83
A15: 42779 | B15: 0 | C15: 100 | D15: 0 | E15: 0.01 | F15: 0 | G15: 451 | H15: 4034.8
A16: 42780 | B16: 0 | C16: 84 | D16: 0 | E16: 0 | F16: 0 | G16: 451 | H16: 4034.78
A17: 42781 | B17: 0 | C17: 70 | D17: 0 | E17: 0.06 | F17: 0 | G17: 451 | H17: 4034.76
A18: 42782 | B18: 0 | C18: 70 | D18: 0 | E18: 0.16 | F18: 0 | G18: 451 | H18: 4034.74
A19: 42783 | B19: 0 | C19: 70 | D19: 0 | E19: 0.03 | F19: 0 | G19: 395 | H19: 4034.72 | I19: * Apprx 3:00 PM Shutting one unit OFF at D-Plant
A20: 42784 | B20: 0 | C20: 70 | D20: 0 | E20: 0.24 | F20: 0 | G20: 300 | H20: 4034.71
A21: 42785 | B21: 0 | C21: 70 | D21: 0 | E21: 0.03 | F21: 0 | G21: 300 | H21: 4034.7
A22: 42786 | B22: 0 | C22: 70 | D22: 0 | E22: 0.06 | F22: 0 | G22: 300 | H22: 4034.7
A23: 42787 | B23: 0 | C23: 70 | D23: 0 | E23: 0.12 | F23: 0 | G23: 300 | H23: 4034.69
A24: 42788 | B24: 0 | C24: 70 | D24: 0 | E24: 0.1 | F24: 2 | G24: 300 | H24: 4034.68
A25: 42789 | B25: 0 | C25: 70 | D25: 0 | E25: 0.05 | F25: 0.5 | G25: 300 | H25: 4034.67
A26: 42790 | B26: 0 | C26: 70 | D26: 0 | E26: 0 | F26: T | G26: 300 | H26: 4034.66
A27: 42791 | B27: 0 | C27: 70 | D27: 0 | E27: 0 | F27: T | G27: 300 | H27: 4034.65
A28: 42792 | B28: 0 | C28: 70 | D28: 0 | E28: 0 | F28: T | G28: 300 | H28: 4034.63
A29: 42793 | B29: 0 | C29: 58 | D29: 0 | E29: 0.03 | F29: 0.5 | G29: 300 | H29: 4034.64
A30: 42794 | B30: 0 | C30: 50 | D30: 0 | E30: 0.02 | F30: 0.25 | G30: 300 | H30: 4034.64
A31: Monthly Total | B31: =SUM(B3:B30) -> 0 | C31: =SUM(C3:C30) -> 2911 | D31: =SUM(D3:D30) -> 0 | E31: =SUM(E3:E30) -> 1.87 | F31: =SUM(F3:F30) -> 3.5 | G31: =SUM(G3:G30) -> 8916
A32: WY Total | B32: =SUM(B31+'Jan 2017'!B35) -> 409 | C32: =SUM(C31+'Jan 2017'!C35) -> 7469 | D32: =SUM(D31+'Jan 2017'!D35) -> 2909 | E32: =SUM(E31+'Jan 2017'!E35) -> 6.369 | F32: =SUM(F31+'Jan 2017'!F35) -> 26.6 | G32: =SUM(G31+'Jan 2017'!G35) -> 24536
A34: Acre Feet | B34: =SUM(B3:B30)*1.9835 -> 0 | C34: =SUM(C3:C30)*1.9835 -> 5773.9685 | D34: =SUM(D3:D30)*1.9835 -> 0
A36: WY AF Total | B36: =SUM(B34+'Jan 2017'!B39) -> 811.2515 | C36: =SUM(C34+'Jan 2017'!C39) -> 14814.762 | D36: =SUM(D34+'Jan 2017'!D39) -> 5770.0015
G38: * COMPUTATIONAL PURPOSES ONLY! Do Not Enter Data in the Red Columns
A40: *This is computation purposes only for Station 48
A41: Sta 48
F42: =SUM(24-D42) -> 24 | G42: =SUM(C42+E42) -> 0 | H42: =SUM(C42/24*D42+G42/24*F42) -> 0
F43: =SUM(24-D43) -> 24 | G43: =SUM(C43+E43) -> 0 | H43: =SUM(C43/24*D43+G43/24*F43) -> 0
F44: =SUM(24-D44) -> 24 | G44: =SUM(C44+E44) -> 0 | H44: =SUM(C44/24*D44+G44/24*F44) -> 0
...

Sheet Jan 2017
A1: DATE | B1: STATION 48 | C1: ANDERSON-ROSE | D1: J CANAL | E1: TULE LAKE PRECIP | F1: TULE LAKE SNOW | G1: D PLANT | H1: TULE LAKE ELEV. | I1: CHANGES @ STATION 48
B2: (in CFS) | C2: (in CFS) | D2: (in CFS) | G2: (in AF)
A3: 42736 | B3: 0 | C3: 16 | D3: 0 | E3: 0.02 | F3: 2 | G3: 0 | H3: 4034.58
A4: 42737 | B4: 0 | C4: 10 | D4: 0 | E4: 0 | F4: 0 | G4: 0 | H4: 4034.58
A5: 42738 | B5: 0 | C5: 10 | D5: 0 | E5: 0.18 | F5: 5 | G5: 0 | H5: 4034.58
A6: 42739 | B6: 0 | C6: 10 | D6: 0 | E6: 0.33 | F6: 12 | G6: 0 | H6: 4034.58
A7: 42740 | B7: 0 | C7: 10 | D7: 0 | E7: 0 | F7: 0 | G7: 0 | H7: 4034.6
A8: 42741 | B8: 0 | C8: 10 | D8: 0 | E8: 0 | F8: 0 | G8: 0 | H8: 4034.61
A9: 42742 | B9: 0 | C9: 10 | D9: 0 | E9: 0.05 | F9: 1 | G9: 0 | H9: 4034.62
A10: 42743 | B10: 0 | C10: 10 | D10: 0 | E10: 0.06 | F10: 0 | G10: 0 | H10: 4034.63
A11: 42744 | B11: 0 | C11: 10 | D11: 0 | E11: 0.03 | F11: 1 | G11: 58 | H11: 4034.65 | I11: Approx. 10:00 AM started 1 unit at D Plant
A12: 42745 | B12: 0 | C12: 28 | D12: 0 | E12: 0.16 | F12: 0 | G12: 260 | H12: 4034.67 | I12: Approx. 10:00 AM started 2nd unit at D Plant
A13: 42746 | B13: 0 | C13: 50 | D13: 0 | E13: 0.18 | F13: 0 | G13: 318 | H13: 4034.68
A14: 42747 | B14: 0 | C14: 50 | D14: 0 | E14: 0 | F14: 0 | G14: 318 | H14: 4034.66
A15: 42748 | B15: 0 | C15: 50 | D15: 0 | E15: 0 | F15: 0 | G15: *260 | H15: 4034.65 | I15: *Shut 1 D-Plant unit off at 3:19 PM
A16: 42749 | B16: 0 | C16: 50 | D16: 0 | E16: 0 | F16: 0 | G16: 160 | H16: 4034.64
A17: 42750 | B17: 0 | C17: 50 | D17: 0 | E17: 0 | F17: 0 | G17: 160 | H17: 4034.63
A18: 42751 | B18: 0 | C18: 50 | D18: 0 | E18: 0 | F18: 0 | G18: 160 | H18: 4034.62
A19: 42752 | B19: 0 | C19: 27 | D19: 0 | E19: 0 | F19: 0 | G19: 160 | H19: 4034.62
A20: 42753 | B20: 0 | C20: 10 | D20: 0 | E20: 0.05 | F20: 0 | G20: 160 | H20: 4034.62
A21: 42754 | B21: 0 | C21: 10 | D21: 0 | E21: 0.03 | F21: T | G21: 160 | H21: 4034.62
A22: 42755 | B22: 0 | C22: 10 | D22: 0 | E22: 0.01 | F22: 0 | G22: 160 | H22: 4034.61
A23: 42756 | B23: 0 | C23: 10 | D23: 0 | E23: 0 | F23: 0 | G23: 160 | H23: 4034.61
A24: 42757 | B24: 0 | C24: 10 | D24: 0 | E24: 0.05 | F24: 2 | G24: 160 | H24: 4034.6
A25: 42758 | B25: 0 | C25: 28 | D25: 0 | E25: 0.01 | F25: T | G25: 160 | H25: 4034.6
A26: 42759 | B26: 0 | C26: 50 | D26: 0 | E26: T | F26: 0 | G26: 160 | H26: 4034.6
A27: 42760 | B27: 0 | C27: 50 | D27: 0 | E27: 0 | F27: 0 | G27: 160 | H27: 4034.6
A28: 42761 | B28: 0 | C28: 31 | D28: 0 | E28: 0.01 | F28: 0 | G28: 160 | H28: 4034.59
A29: 42762 | B29: 0 | C29: 20 | D29: 0 | E29: 0.01 | F29: 0 | G29: 160 | H29: 4034.59
A30: 42763 | B30: 0 | C30: 20 | D30: 0 | E30: 0 | F30: 0 | G30: 160 | H30: 4034.58
A31: 42764 | B31: 0 | C31: 20 | D31: 0 | E31: 0 | F31: 0 | G31: 160 | H31: 4034.57
A32: 42765 | B32: 0 | C32: 20 | D32: 0 | E32: 0 | F32: 0 | G32: 160 | H32: 4034.56
A33: 42766 | B33: 0 | C33: 38 | D33: 0 | E33: 0 | F33: 0 | G33: 160 | H33: 4034.55
A34: Monthly Total | B34: =SUM(B3:B33) -> 0 | C34: =SUM(C3:C33) -> 778 | D34: =SUM(D3:D33) -> 0 | E34: =SUM(E3:E33) -> 1.18 | F34: =SUM(F3:F33) -> 23 | G34: =SUM(G3:G33) -> 3834
A35: WY Total | B35: =SUM(B34+'Dec 2016'!B35) -> 409 | C35: =SUM(C34+'Dec 2016'!C35) -> 4558 | D35: =SUM(D34+'Dec 2016'!D35) -> 2909 | E35: =SUM(E34+'Dec 2016'!E35) -> 4.499 | F35: =SUM(F34+'Dec 2016'!F35) -> 23.1 | G35: =SUM(G34+'Dec 2016'!G35) -> 15620
A37: Acre Feet | B37: =SUM(B3:B33)*1.9835 -> 0 | C37: =SUM(C3:C33)*1.9835 -> 1543.163 | D37: =SUM(D3:D33)*1.9835 -> 0
A39: WY AF Total | B39: =SUM(B37+'Dec 2016'!B39) -> 811.2515 | C39: =SUM(C37+'Dec 2016'!C39) -> 9040.793 | D39: =SUM(D37+'Dec 2016'!D39) -> 5770.0015
G41: * COMPUTATIONAL PURPOSES ONLY! Do Not Enter Data in the Red Columns
A43: *This is computation purposes only for Station 48
A44: Sta 48
...

Sheet Dec 2016
A1: DATE | B1: STATION 48 | C1: ANDERSON-ROSE | D1: J CANAL | E1: TULE LAKE PRECIP | F1: TULE LAKE SNOW | G1: D PLANT | H1: TULE LAKE ELEV. | I1: CHANGES @ STATION 48
B2: (in CFS) | C2: (in CFS) | D2: (in CFS) | G2: (in AF)
A3: 42705 | B3: 0 | C3: 40 | D3: 0 | E3: 0 | F3: 0 | G3: 0 | H3: 4034.34
A4: 42706 | B4: 0 | C4: 40 | D4: 0 | E4: 0 | F4: 0 | G4: 0 | H4: 4034.34
A5: 42707 | B5: 0 | C5: 40 | D5: 0 | E5: 0 | F5: 0 | G5: 0 | H5: 4034.34
A6: 42708 | B6: 0 | C6: 40 | D6: 0 | E6: 0.01 | F6: 0 | G6: 0 | H6: 4034.34
A7: 42709 | B7: 0 | C7: 40 | D7: 0 | E7: 0.02 | F7: 0 | G7: 0 | H7: 4034.34
A8: 42710 | B8: 0 | C8: 40 | D8: 0 | E8: 0.12 | F8: 0 | G8: 0 | H8: 4034.35
A9: 42711 | B9: 0 | C9: 40 | D9: 0 | E9: 0 | F9: 0 | G9: 0 | H9: 4034.35
A10: 42712 | B10: 0 | C10: 40 | D10: 0 | E10: 0.11 | F10: 0 | G10: 0 | H10: 4034.4
A11: 42713 | B11: 0 | C11: 40 | D11: 0 | E11: 0 | F11: 0 | G11: 0 | H11: 4034.4
A12: 42714 | B12: 0 | C12: 40 | D12: 0 | E12: 0.269 | F12: 0 | G12: 0 | H12: 4034.4
A13: 42715 | B13: 0 | C13: 40 | D13: 0 | E13: T | F13: 0 | G13: 0 | H13: 4034.4
A14: 42716 | B14: 0 | C14: 40 | D14: 0 | E14: T | F14: 0 | G14: 0 | H14: 4034.42
A15: 42717 | B15: 0 | C15: 40 | D15: 0 | E15: T | F15: 0 | G15: 0 | H15: 4034.44
A16: 42718 | B16: 0 | C16: 40 | D16: 0 | E16: 0.31 | F16: 0 | G16: 0 | H16: 4034.45
A17: 42719 | B17: 0 | C17: 40 | D17: 0 | E17: 0.47 | F17: 0 | G17: 0 | H17: 4034.48
A18: 42720 | B18: 0 | C18: 43 | D18: 0 | E18: 0.02 | F18: 0 | G18: 0 | H18: 4034.5
A19: 42721 | B19: 0 | C19: 50 | D19: 0 | E19: 0 | F19: 0 | G19: 0 | H19: 4034.52
A20: 42722 | B20: 0 | C20: 50 | D20: 0 | E20: 0 | F20: 0 | G20: 0 | H20: 4034.55
A21: 42723 | B21: 0 | C21: 50 | D21: 0 | E21: 0 | F21: 0 | G21: 0 | H21: 4034.58
A22: 42724 | B22: 0 | C22: 50 | D22: 0 | E22: 0 | F22: 0 | G22: 0 | H22: 4034.58
A23: 42725 | B23: 0 | C23: 30 | D23: 0 | E23: 0 | F23: 0 | G23: 0 | H23: 4034.6
A24: 42726 | B24: 0 | C24: 20 | D24: 0 | E24: 0 | F24: 0 | G24: 0 | H24: 4034.58
A25: 42727 | B25: 0 | C25: 20 | D25: 0 | E25: 0.01 | F25: 0 | G25: 0 | H25: 4034.58
A26: 42728 | B26: 0 | C26: 20 | D26: 0 | E26: 0.02 | F26: 0.1 | G26: 0 | H26: 4034.58
A27: 42729 | B27: 0 | C27: 20 | D27: 0 | E27: 0 | F27: 0 | G27: 0 | H27: 4034.58
... A30: 42732 | B30: 0 | C30: 20 | D30: 0 | E30: 0.01 | F30: 0 | G30: 0 | H30: 4034.58
A31: 42733 | B31: 0 | C31: 20 | D31: 0 | E31: T | F31: 0 | G31: 0 | H31: 4034.58
A32: 42734 | B32: 0 | C32: 20 | D32: 0 | E32: 0 | F32: 0 | G32: 0 | H32: 4034.58
A33: 42735 | B33: 0 | C33: 20 | D33: 0 | E33: T | F33: T | G33: 0 | H33: 4034.58
A34: Monthly Total | B34: =SUM(B3:B33) -> 0 | C34: =SUM(C3:C33) -> 1073 | D34: =SUM(D3:D33) -> 0 | E34: =SUM(E3:E33) -> 1.379 | F34: =SUM(F3:F33) -> 0.1 | G34: =SUM(G3:G33) -> 0
A35: WY Total | B35: =SUM(B34+'Nov 2016'!B34) -> 409 | C35: =SUM(C34+'Nov 2016'!C34) -> 3780 | D35: =SUM(D34+'Nov 2016'!D34) -> 2909 | E35: =SUM(E34+'Nov 2016'!E34) -> 3.319 | F35: =SUM(F34+'Nov 2016'!F34) -> 0.1 | G35: =SUM(G34+'Nov 2016'!G34) -> 11786
A37: Acre Feet | B37: =SUM(B3:B33)*1.9835 -> 0 | C37: =SUM(C3:C33)*1.9835 -> 2128.2955 | D37: =SUM(D3:D33)*1.9835 -> 0
A39: WY AF Total | B39: =SUM('Nov 2016'!B38+B37) -> 811.2515 | C39: =SUM('Nov 2016'!C38+C37) -> 7497.63 | D39: =SUM('Nov 2016'!D38+D37) -> 5770.0015
G41: * COMPUTATIONAL PURPOSES ONLY! Do Not Enter Data in the Red Columns
A43: *This is computation purposes only for Station 48
A44: Sta 48
F45: =SUM(24-D45) -> 24 | G45: =SUM(C45+E45) -> 0 | H45: =SUM(C45/24*D45+G45/24*F45) -> 0
F46: =SUM(24-D46) -> 24 | G46: =SUM(C46+E46) -> 0 | H46: =SUM(C46/24*D46+G46/24*F46) -> 0
...

Sheet Nov 2016
A1: DATE | B1: STATION 48 | C1: ANDERSON-ROSE | D1: J CANAL | E1: TULE LAKE PRECIP | F1: TULE LAKE SNOW | G1: D PLANT | H1: TULE LAKE ELEV. | I1: CHANGES @ STATION 48
B2: (in CFS) | C2: (in CFS) | D2: (in CFS) | G2: (in AF)
A3: 42675 | B3: 45 | C3: 106 | D3: 36 | E3: 0.01 | F3: 0 | G3: 318 | H3: 4034.72
A4: 42676 | B4: 18 | C4: 100 | D4: 39 | E4: 0 | F4: 0 | G4: 318 | H4: 4034.72
A5: 42677 | B5: 0 | C5: 100 | D5: 38 | E5: 0 | F5: 0 | G5: 318 | H5: 4034.71
A6: 42678 | B6: 0 | C6: 71 | D6: 36 | E6: 0 | F6: 0 | G6: 318 | H6: 4034.7
A7: 42679 | B7: 0 | C7: 50 | D7: 37 | E7: 0 | F7: 0 | G7: 160 | H7: 4034.68
A8: 42680 | B8: 0 | C8: 50 | D8: 40 | E8: 0.01 | F8: 0 | G8: 160 | H8: 4034.67
A9: 42681 | B9: 0 | C9: 23 | D9: 64 | E9: 0 | F9: 0 | G9: 259 | H9: 4034.65
A10: 42682 | B10: 0 | C10: 0 | D10: 77 | E10: 0 | F10: 0 | G10: 318 | H10: 4034.63
A11: 42683 | B11: 0 | C11: 0 | D11: 68 | E11: 0 | F11: 0 | G11: 318 | H11: 4034.61
A12: 42684 | B12: 0 | C12: 0 | D12: 64 | E12: 0 | F12: 0 | G12: 263 | H12: 4034.59
A13: 42685 | B13: 0 | C13: 0 | D13: 60 | E13: 0 | F13: 0 | G13: 160 | H13: 4034.57
A14: 42686 | B14: 0 | C14: 0 | D14: 59 | E14: 0 | F14: 0 | G14: 160 | H14: 4034.55
... A17: 42689 | B17: 0 | C17: 16 | D17: 41 | E17: 0.14 | F17: 0 | G17: 318 | H17: 4034.48
A18: 42690 | B18: 0 | C18: 0 | D18: 40 | E18: T | F18: 0 | G18: 318 | H18: 4034.44
A19: 42691 | B19: 0 | C19: 0 | D19: 39 | E19: 0 | F19: 0 | G19: 318 | H19: 4034.42
A20: 42692 | B20: 0 | C20: 0 | D20: 38 | E20: 0 | F20: 0 | G20: 260 | H20: 4034.4
A21: 42693 | B21: 0 | C21: 0 | D21: 36 | E21: 0 | F21: 0 | G21: 160 | H21: 4034.38
A22: 42694 | B22: 0 | C22: 0 | D22: 35 | E22: 0.13 | F22: 0 | G22: 159 | H22: 4034.35
A23: 42695 | B23: 0 | C23: 0 | D23: 16 | E23: T | F23: 0 | G23: 258 | H23: 4034.32
A24: 42696 | B24: 0 | C24: 11 | D24: 0 | E24: 0.01 | F24: 0 | G24: 318 | H24: 4034.3
A25: 42697 | B25: 0 | C25: 28 | D25: 0 | E25: 0.09 | F25: 0 | G25: 198 | H25: 4034.28
A26: 42698 | B26: 0 | C26: 40 | D26: 0 | E26: 0 | F26: 0 | G26: 0 | H26: 4034.28
A27: 42699 | B27: 0 | C27: 40 | D27: 0 | E27: T | F27: 0 | G27: 0 | H27: 4034.3
A28: 42700 | B28: 0 | C28: 40 | D28: 0 | E28: 0.01 | F28: 0 | G28: 0 | H28: 4034.31
A29: 42701 | B29: 0 | C29: 40 | D29: 0 | E29: T | F29: 0 | G29: 0 | H29: 4034.32
A30: 42702 | B30: 0 | C30: 40 | D30: 0 | E30: 0 | F30: 0 | G30: 0 | H30: 4034.32
A31: 42703 | B31: 0 | C31: 40 | D31: 0 | E31: 0.01 | F31: 0 | G31: 0 | H31: 4034.33
A32: 42704 | B32: 0 | C32: 40 | D32: 0 | E32: 0.07 | F32: 0 | G32: 0 | H32: 4034.34
A33: Monthly Total | B33: =SUM(B3:B32) -> 63 | C33: =SUM(C3:C32) -> 835 | D33: =SUM(D3:D32) -> 940 | E33: =SUM(E3:E32) -> 0.48 | F33: =SUM(F3:F32) -> 0 | G33: =SUM(G3:G32) -> 5794
A34: WY Total | B34: =SUM(B33+'Oct 2016'!B35) -> 409 | C34: =SUM(C33+'Oct 2016'!C35) -> 2707 | D34: =SUM(D33+'Oct 2016'!D35) -> 2909 | E34: =SUM(E33+'Oct 2016'!E35) -> 1.94 | F34: =SUM(F33+'Oct 2016'!F35) -> 0 | G34: =SUM(G33+'Oct 2016'!G35) -> 11786
A36: Acre Feet | B36: =SUM(B3:B32)*1.9835 -> 124.9605 | C36: =SUM(C3:C32)*1.9835 -> 1656.2225 | D36: =SUM(D3:D32)*1.9835 -> 1864.49
A38: WY AF Total | B38: =SUM('Oct 2016'!B39+B36) -> 811.2515 | C38: =SUM('Oct 2016'!C39+C36) -> 5369.3345 | D38: =SUM('Oct 2016'!D39+D36) -> 5770.0015
G40: * COMPUTATIONAL PURPOSES ONLY! Do Not Enter Data in the Red Columns
A42: *This is computation purposes only for Station 48
A43: Sta 48
F44: =SUM(24-D44) -> 24 | G44: =SUM(C44+E44) -> 0 | H44: =SUM(C44/24*D44+G44/24*F44) -> 0
F45: =SUM(24-D45) -> 24 | G45: =SUM(C45+E45) -> 0 | H45: =SUM(C45/24*D45+G45/24*F45) -> 0
F46: =SUM(24-D46) -> 24 | G46: =SUM(C46+E46) -> 0 | H46: =SUM(C46/24*D46+G46/24*F46) -> 0
...

Sheet Oct 2016
A1: DATE | B1: STATION 48 | C1: ANDERSON-ROSE | D1: J CANAL | E1: TULE LAKE PRECIP | F1: TULE LAKE SNOW | G1: D PLANT | H1: TULE LAKE ELEV. | I1: CHANGES @ STATION 48
B2: (in CFS) | C2: (in CFS) | D2: (in CFS)
A3: 42644 | B3: 0 | C3: 0 | D3: 149 | E3: 0 | F3: 0 | G3: 160 | H3: 4034.68
A4: 42645 | B4: 0 | C4: 18 | D4: 145 | E4: 0.05 | F4: 0 | G4: 160 | H4: 4034.68
A5: 42646 | B5: 0 | C5: 44 | D5: 138 | E5: 0.1 | F5: 0 | G5: 160 | H5: 4034.72
A6: 42647 | B6: 0 | C6: 41 | D6: 126 | E6: 0.11 | F6: 0 | G6: 160 | H6: 4034.74
A7: 42648 | B7: 0 | C7: 31 | D7: 118 | E7: 0 | F7: 0 | G7: 160 | H7: 4034.76
A8: 42649 | B8: 0 | C8: 100 | D8: 114 | E8: 0.03 | F8: 0 | G8: 160 | H8: 4034.78
A9: 42650 | B9: 0 | C9: 0 | D9: 121 | E9: 0 | F9: 0 | G9: 160 | H9: 4034.79
A10: 42651 | B10: 0 | C10: 0 | D10: 108 | E10: 0 | F10: 0 | G10: 160 | H10: 4034.79
A11: 42652 | B11: 0 | C11: 19 | D11: 86 | E11: 0 | F11: 0 | G11: 160 | H11: 4034.79
A12: 42653 | B12: 0 | C12: 40 | D12: 88 | E12: 0 | F12: 0 | G12: 160 | H12: 4034.79
A13: 42654 | B13: 0 | C13: 38 | D13: 65 | E13: 0 | F13: 0 | G13: 160 | H13: 4034.79
A14: 42655 | B14: 0 | C14: 50 | D14: 61 | E14: 0 | F14: 0 | G14: 160 | H14: 4034.79
... A18: 42659 | B18: 0 | C18: 108 | D18: 32 | E18: 0.14 | F18: 0 | G18: 0 | H18: 4034.86
A19: 42660 | B19: 0 | C19: 106 | D19: 32 | E19: 0.13 | F19: 0 | G19: 200 | H19: 4034.86 | I19: * Start 2 Units D-Plant apprx. 9:00 AM
A20: 42661 | B20: 0 | C20: 82 | D20: 32 | E20: 0 | F20: 0 | G20: 320 | H20: 4034.88
A21: 42662 | B21: 0 | C21: 51 | D21: 30 | E21: 0.01 | F21: 0 | G21: 320 | H21: 4034.9
A22: 42663 | B22: 0 | C22: 41 | D22: 32 | E22: 0.01 | F22: 0 | G22: 320 | H22: 4034.88
A23: 42664 | B23: 0 | C23: 31 | D23: 32 | E23: 0.01 | F23: 0 | G23: 320 | H23: 4034.86
A24: 42665 | B24: 0 | C24: 9 | D24: 31 | E24: 0 | F24: 0 | G24: 320 | H24: 4034.84
A25: 42666 | B25: 0 | C25: 2 | D25: 30 | E25: 0 | F25: 0 | G25: 320 | H25: 4034.8
A26: 42667 | B26: 23 | C26: 5 | D26: 35 | E26: 0 | F26: 0 | G26: 182 | H26: 4034.79 | I26: * 13:00 0/50
A27: 42668 | B27: 48 | C27: 126 | D27: 36 | E27: 0.12 | F27: 0 | G27: 259 | H27: 4034.78
A28: 42669 | B28: 46 | C28: 101 | D28: 35 | E28: 0.02 | F28: 0 | G28: 317 | H28: 4034.77
A29: 42670 | B29: 43 | C29: 102 | D29: 35 | E29: 0.03 | F29: 0 | G29: 261 | H29: 4034.76
A30: 42671 | B30: 47 | C30: 100 | D30: 35 | E30: 0 | F30: 0 | G30: 261 | H30: 4034.76
A31: 42672 | B31: 43 | C31: 101 | D31: 33 | E31: 0.03 | F31: 0 | G31: 160 | H31: 4034.76
A32: 42673 | B32: 49 | C32: 111 | D32: 32 | E32: 0.07 | F32: 0 | G32: 160 | H32: 4034.75
A33: 42674 | B33: 47 | C33: 116 | D33: 32 | E33: 0.02 | F33: 0 | G33: 259 | H33: 4034.73 | I33: Started 2nd unit at D Plant 8:45 AM
A34: Monthly Total | B34: =SUM(B3:B33) -> 346 | C34: =SUM(C3:C33) -> 1872 | D34: =SUM(D3:D33) -> 1969 | E34: =SUM(E3:E33) -> 1.46 | F34: =SUM(F3:F33) -> 0 | G34: =SUM(G3:G33) -> 5992
A35: WY Total | B35: =SUM(B34+'Oct 2016'!B36) -> 346 | C35: =SUM(C34+'Oct 2016'!C36) -> 1872 | D35: =SUM(D34+'Oct 2016'!D36) -> 1969 | E35: =SUM(E34+'Oct 2016'!E36) -> 1.46 | F35: =SUM(F34+'Oct 2016'!F36) -> 0 | G35: =SUM(G34+'Oct 2016'!G36) -> 5992
A37: Acre Feet | B37: =SUM(B3:B33)*1.9835 -> 686.291 | C37: =SUM(C3:C33)*1.9835 -> 3713.112 | D37: =SUM(D3:D33)*1.9835 -> 3905.5115
A39: WY AF Total | B39: =SUM('Oct 2016'!B40+B37) -> 686.291 | C39: =SUM('Oct 2016'!C40+C37) -> 3713.112 | D39: =SUM('Oct 2016'!D40+D37) -> 3905.5115
G41: * COMPUTATIONAL PURPOSES ONLY! Do Not Enter Data in the Red Columns
A43: *This is computation purposes only for Station 48
A44: Sta 48
F45: =SUM(24-D45) -> 24 | G45: =SUM(C45+E45) -> 0 | H45: =SUM(C45/24*D45+G45/24*F45) -> 0
F46: =SUM(24-D46) -> 24 | G46: =SUM(C46+E46) -> 0 | H46: =SUM(C46/24*D46+G46/24*F46) -> 0
F47: =SUM(24-D47) -> 24 | G47: =SUM(C47+E47) -> 0 | H47: =SUM(C47/24*D47+G47/24*F47) -> 0
...

Sheet Sheet1
