Workbook

Sheet Sep 2019
A1: DATE | B1: STATION 48 | C1: ANDERSON-ROSE | D1: J CANAL | E1: TULE LAKE PRECIP | F1: TULE LAKE SNOW | G1: D PLANT | H1: TULE LAKE ELEV. | I1: CHANGES @ STATION 48
B2: (in CFS) | C2: (in CFS) | D2: (in CFS) | G2: (in AF)
A3: 43709 | B3: 235 | C3: 5 | D3: 414 | E3: 0 | F3: 0 | G3: 0 | H3: 4034.6 | I3: * 08:30 300/200
A4: 43710 | B4: 169 | C4: 18 | D4: 373 | E4: 0 | F4: 0 | G4: 0 | H4: 4034.6 | I4: * 0900 200/150
A5: 43711 | B5: 133 | C5: 0 | D5: 334 | E5: 0 | F5: 0 | G5: 0 | H5: 4034.6 | I5: * 1600 150/100
A6: 43712 | B6: 83 | C6: 0 | D6: 297 | E6: 0 | F6: 0 | G6: 0 | H6: 4034.62 | I6: * 1600 100/50
A7: 43713 | B7: 50 | C7: 0 | D7: 277 | E7: 0.1 | F7: 0 | G7: 0 | H7: 4034.62
A8: 43714 | B8: 81 | C8: 0 | D8: 267 | E8: 0 | F8: 0 | G8: 0 | H8: 4034.62 | I8: * 0900 50/100 | J8: * Station 48 corrected from 50 to 81
A9: 43715 | B9: 65 | C9: 0 | D9: 252 | E9: 0 | F9: 0 | G9: 0 | H9: 4034.64 | I9: * 0700 100/50
A10: 43716 | B10: 42 | C10: 0 | D10: 213 | E10: 0 | F10: 0 | G10: 0 | H10: 4034.64 | I10: * 1600 50/25
A11: 43717 | B11: 25 | C11: 0 | D11: 230 | E11: 0 | F11: 0 | G11: 0 | H11: 4034.64
A12: 43718 | B12: 53 | C12: 0 | D12: 234 | E12: 0 | F12: 0 | G12: 0 | H12: 4034.64 | I12: * 1030 25/75
A13: 43719 | B13: 75 | C13: 0 | D13: 233 | E13: 0 | F13: 0 | G13: 0 | H13: 4034.64
A14: 43720 | B14: 97 | C14: 0 | D14: 229 | E14: 0 | F14: 0 | G14: 0 | H14: 4034.64 | I14: * 1000 75/125 * 1700 125/100
A15: 43721 | B15: 100 | C15: 0 | D15: 237 | E15: 0 | F15: 0 | G15: 0 | H15: 4034.64
A16: 43722 | B16: 52 | C16: 22 | D16: 238 | E16: 0 | F16: 0 | G16: 0 | H16: 4034.64 | I16: * 07:00 100/50 * 14:30 50/18
A17: 43723 | B17: 18 | C17: 14 | D17: 190 | E17: 0 | F17: 0 | G17: 0 | H17: 4034.64
A18: 43724 | B18: 7 | C18: 52 | D18: 174 | E18: 0.53 | F18: 0 | G18: 0 | H18: 4034.75 | I18: * 09:00 18/0
A19: 43725 | B19: 0 | C19: 74 | D19: 141 | E19: 0.02 | F19: 0 | G19: 0 | H19: 4034.8
A20: 43726 | B20: 0 | C20: 140 | D20: 98 | E20: 0.32 | F20: 0 | G20: 0 | H20: 4034.83
A21: 43727 | B21: 0 | C21: 120 | D21: 81 | E21: 0.19 | F21: 0 | G21: 97 | H21: 4034.86
A22: 43728 | B22: 0 | C22: 119 | D22: 79 | E22: 0 | F22: 0 | G22: 160 | H22: 4034.88
A23: 43729 | B23: 0 | C23: 146 | D23: 88 | E23: 0 | F23: 0 | G23: 160 | H23: 4034.9
A24: 43730 | B24: 0 | C24: 117 | D24: 80 | E24: T | F24: 0 | G24: 160 | H24: 4034.9
A25: 43731 | B25: 0 | C25: 140 | D25: 77 | E25: 0 | F25: 0 | G25: 160 | H25: 4034.9
A26: 43732 | B26: 0 | C26: 99 | D26: 79 | E26: 0 | F26: 0 | G26: 160 | H26: 4034.92
A27: 43733 | B27: 0 | C27: 91 | D27: 75 | E27: 0 | F27: 0 | G27: 160 | H27: 4034.92
A28: 43734 | B28: 0 | C28: 77 | D28: 80 | E28: 0 | F28: 0 | G28: 160 | H28: 4034.92
A29: 43735 | B29: 0 | C29: 71 | D29: 77 | E29: 0 | F29: 0 | G29: 160 | H29: 4034.9
A30: 43736 | B30: 0 | C30: 62 | D30: 69 | E30: 0.01 | F30: 0 | G30: 160 | H30: 4034.9
A31: 43737 | B31: 0 | C31: 68 | D31: 56 | E31: 0.01 | F31: 0 | G31: 160 | H31: 4034.9
A32: 43738 | B32: 0 | C32: 74 | D32: 51 | E32: 0.11 | F32: 0 | G32: 160 | H32: 4034.9
A33: Monthly Total | B33: =SUM(B3:B32) -> 1285 | C33: =SUM(C3:C32) -> 1509 | D33: =SUM(D3:D32) -> 5323 | E33: =SUM(E3:E32) -> 1.29 | F33: =SUM(F3:F32) -> 0 | G33: =SUM(G4:G32) -> 1857
A34: WY Total | B34: =SUM(B33+'Aug 2019'!B35) -> 30925 | C34: =SUM(C33+'Aug 2019'!C35) -> 7662 | D34: =SUM(D33+'Aug 2019'!D35) -> 55339 | E34: =SUM(E33+'Aug 2019'!E35) -> 13.476 | F34: =SUM(F33+'Aug 2019'!F35) -> 23.87 | G34: =SUM(G33+'Aug 2019'!G35) -> 30109
A36: Acre Feet | B36: =SUM(B3:B32)*1.9835 -> 2548.7975 | C36: =SUM(C3:C32)*1.9835 -> 2993.1015 | D36: =SUM(D3:D32)*1.9835 -> 10558.171
A38: WY AF Total | B38: =SUM(B36+'Aug 2019'!B39) -> 61532.137 | C38: =SUM(C36+'Aug 2019'!C39) -> 16552.307 | D38: =SUM(D36+'Aug 2019'!D39) -> 118002.38
G40: * COMPUTATIONAL PURPOSES ONLY! Do Not Enter Data in the Red Columns
A42: *This is computation purposes only for Station 48
A43: Sta 48
F44: =SUM(24-D44) -> 24 | G44: =SUM(C44+E44) -> 0 | H44: =SUM(C44/24*D44+G44/24*F44) -> 0
...

Sheet Aug 2019
A1: DATE | B1: STATION 48 | C1: ANDERSON-ROSE | D1: J CANAL | E1: TULE LAKE PRECIP | F1: TULE LAKE SNOW | G1: D PLANT | H1: TULE LAKE ELEV. | I1: CHANGES @ STATION 48
B2: (in CFS) | C2: (in CFS) | D2: (in CFS) | G2: (in AF)
A3: 43678 | B3: 415 | C3: 0 | D3: 453 | E3: 0 | F3: 0 | G3: 0 | H3: 4034.56 | I3: * 15:30 450/350
A4: 43679 | B4: 390 | C4: 0 | D4: 456 | E4: 0 | F4: 0 | G4: 0 | H4: 4034.56 | I4: * 08:30 350/450 * 18:00 450/350
A5: 43680 | B5: 333 | C5: 0 | D5: 456 | E5: 0 | F5: 0 | G5: 0 | H5: 4034.55 | I5: * 16:00 350/300 | J5: * correction 48 should be 333
A6: 43681 | B6: 280 | C6: 0 | D6: 391 | E6: 0 | F6: 0 | G6: 0 | H6: 4034.55 | I6: * 14:30 300/250 corrected
A7: 43682 | B7: 235 | C7: 0 | D7: 409 | E7: 0 | F7: 0 | G7: 0 | H7: 4034.53 | I7: * 1700 250/200
A8: 43683 | B8: 290 | C8: 0 | D8: 386 | E8: 0 | F8: 0 | G8: 0 | H8: 4034.52 | I8: * 0830 200/300 * 1100 300/400 * 1700 400/300
A9: 43684 | B9: 282 | C9: 0 | D9: 405 | E9: 0 | F9: 0 | G9: 0 | H9: 4034.52 | I9: * 0700 300/250 * 1530 250/300
A10: 43685 | B10: 265 | C10: 0 | D10: 406 | E10: 0 | F10: 0 | G10: 0 | H10: 4034.5 | I10: * 0700 300/250
A11: 43686 | B11: 250 | C11: 0 | D11: 418 | E11: 0 | F11: 0 | G11: 0 | H11: 4034.5
A12: 43687 | B12: 169 | C12: 44 | D12: 373 | E12: 0.49 | F12: 0 | G12: 0 | H12: 4034.52 | I12: * 0700 250/200 * 1000 200/150 * 1600 150/100 * corrected from 185
A13: 43688 | B13: 100 | C13: 37 | D13: 312 | E13: 0.04 | F13: 0 | G13: 0 | H13: 4034.54 | I13: * 0700 100/150 *1500 150/100 *1600 100/50
A14: 43689 | B14: 50 | C14: 8 | D14: 244 | E14: 0 | F14: 0 | G14: 0 | H14: 4034.54
A15: 43690 | B15: 50 | C15: 0 | D15: 194 | E15: 0 | F15: 0 | G15: 0 | H15: 4034.55
A16: 43691 | B16: 99 | C16: 0 | D16: 220 | E16: 0 | F16: 0 | G16: 0 | H16: 4034.56 | I16: * 0930 50/100 *1500 100/150
A17: 43692 | B17: 205 | C17: 0 | D17: 254 | E17: 0 | F17: 0 | G17: 0 | H17: 4034.56 | I17: * 09:00 150/200 * 16:00 200/250 * 20:30 250/300
A18: 43693 | B18: 233 | C18: 0 | D18: 328 | E18: 0 | F18: 0 | G18: 0 | H18: 4034.58 | I18: * 11:00 300/200 * 18:00 200/150
A19: 43694 | B19: 181 | C19: 0 | D19: 342 | E19: 0 | F19: 0 | G19: 0 | H19: 4034.58 | I19: * 12:00 150/250 * 15:00 250/200
A20: 43695 | B20: 160 | C20: 18 | D20: 336 | E20: 0 | F20: 0 | G20: 0 | H20: 4034.6 | I20: * 14:30 200/100
A21: 43696 | B21: 146 | C21: 0 | D21: 322 | E21: 0 | F21: 0 | G21: 0 | H21: 4034.6 | I21: * 0930 100/200 * 1700 200/150
A22: 43697 | B22: 213 | C22: 0 | D22: 337 | E22: 0 | F22: 0 | G22: 0 | H22: 4034.6 | I22: * 1030 150/250 * 2100 250/300
A23: 43698 | B23: 286 | C23: 0 | D23: 350 | E23: 0 | F23: 0 | G23: 0 | H23: 4034.6 | I23: * 1730 300/250
A24: 43699 | B24: 215 | C24: 7 | D24: 371 | E24: 0 | F24: 0 | G24: 0 | H24: 4034.6 | I24: * 0700 250/200
A25: 43700 | B25: 200 | C25: 1 | D25: 382 | E25: 0 | F25: 0 | G25: 0 | H25: 4034.6
A26: 43701 | B26: 206 | C26: 0 | D26: 401 | E26: 0 | F26: 0 | G26: 0 | H26: 4034.6 | I26: * 21:00 200/250
A27: 43702 | B27: 250 | C27: 0 | D27: 377 | E27: 0 | F27: 0 | G27: 0 | H27: 4034.6
A28: 43703 | B28: 250 | C28: 9 | D28: 408 | E28: 0 | F28: 0 | G28: 0 | H28: 4034.6
A29: 43704 | B29: 250 | C29: 22 | D29: 445 | E29: 0 | F29: 0 | G29: 0 | H29: 4034.6
A30: 43705 | B30: 236 | C30: 0 | D30: 467 | E30: 0 | F30: 0 | G30: 0 | H30: 4034.6 | I30: * 1730 250/200
A31: 43706 | B31: 210 | C31: 0 | D31: 459 | E31: 0 | F31: 0 | G31: 0 | H31: 4034.6 | I31: * 19:00 200/250
A32: 43707 | B32: 258 | C32: 0 | D32: 474 | E32: 0 | F32: 0 | G32: 0 | H32: 4034.6 | I32: * 20:00 250/300
A33: 43708 | B33: 300 | C33: 0 | D33: 465 | E33: 0 | F33: 0 | G33: 0 | H33: 4034.6
A34: Monthly Total | B34: =SUM(B3:B33) -> 7007 | C34: =SUM(C3:C33) -> 146 | D34: =SUM(D3:D33) -> 11641 | E34: =SUM(E3:E33) -> 0.53 | F34: =SUM(F3:F33) -> 0 | G34: =SUM(G3:G33) -> 0
A35: WY Total | B35: =SUM(B34+'Jul 2019'!B35) -> 29640 | C35: =SUM(C34+'Jul 2019'!C35) -> 6153 | D35: =SUM(D34+'Jul 2019'!D35) -> 50016 | E35: =SUM(E34+'Jul 2019'!E35) -> 12.186 | F35: =SUM(F34+'Jul 2019'!F35) -> 23.87 | G35: =SUM(G34+'Jul 2019'!G35) -> 28252
A37: Acre Feet | B37: =SUM(B3:B33)*1.9835 -> 13898.385 | C37: =SUM(C3:C33)*1.9835 -> 289.591 | D37: =SUM(D3:D33)*1.9835 -> 23089.924
A39: WY AF Total | B39: =SUM(B37+'Jul 2019'!B39) -> 58983.34 | C39: =SUM(C37+'Jul 2019'!C39) -> 13559.206 | D39: =SUM(D37+'Jul 2019'!D39) -> 107444.21
G41: * COMPUTATIONAL PURPOSES ONLY! Do Not Enter Data in the Red Columns
A43: *This is computation purposes only for Station 48
A44: Sta 48
...

Sheet Jul 2019
A1: DATE | B1: STATION 48 | C1: ANDERSON-ROSE | D1: J CANAL | E1: TULE LAKE PRECIP | F1: TULE LAKE SNOW | G1: D PLANT | H1: TULE LAKE ELEV. | I1: CHANGES @ STATION 48
B2: (in CFS) | C2: (in CFS) | D2: (in CFS) | G2: (in AF)
A3: 43647 | B3: 340 | C3: 0 | D3: 459 | E3: 0 | F3: 0 | G3: 0 | H3: 4034.8 | I3: * 2130 350/250
A4: 43648 | B4: 296 | C4: 0 | D4: 455 | E4: 0 | F4: 0 | G4: 0 | H4: 4034.75 | I4: * 0830 250/350 * 1500 350/300
A5: 43649 | B5: 313 | C5: 0 | D5: 447 | E5: 0 | F5: 0 | G5: 0 | H5: 4034.75 | I5: * 0930 300/400 * 1530 400/300 * 1800 300/250
A6: 43650 | B6: 291 | C6: 0 | D6: 413 | E6: 0 | F6: 0 | G6: 0 | H6: 4034.75 | I6: * 10:00 250/350 * 15:30 350/300
A7: 43651 | B7: 229 | C7: 46 | D7: 365 | E7: 0 | F7: 0 | G7: 0 | H7: 4034.7 | I7: * 10:00 300/250 * 14:00 250/150
A8: 43652 | B8: 150 | C8: 3 | D8: 317 | E8: 0 | F8: 0 | G8: 0 | H8: 4034.68
A9: 43653 | B9: 185 | C9: 0 | D9: 302 | E9: 0 | F9: 0 | G9: 0 | H9: 4034.67 | I9: * 07:00 150/200
A10: 43654 | B10: 242 | C10: 0 | D10: 392 | E10: 0 | F10: 0 | G10: 0 | H10: 4034.68 | I10: * 1100 200/250 * 1700 250/300
A11: 43655 | B11: 287 | C11: 0 | D11: 463 | E11: 0 | F11: 0 | G11: 0 | H11: 4034.68 | I11: * 1730 300/250
A12: 43656 | B12: 250 | C12: 0 | D12: 385 | E12: 0 | F12: 0 | G12: 0 | H12: 4034.7
A13: 43657 | B13: 231 | C13: 0 | D13: 363 | E13: 0 | F13: 0 | G13: 0 | H13: 3034.7 | I13: * 1500 250/200
A14: 43658 | B14: 190 | C14: 14 | D14: 308 | E14: 0 | F14: 0 | G14: 0 | H14: 4034.68 | I14: * 19:00 200/150
A15: 43659 | B15: 150 | C15: 2 | D15: 300 | E15: 0 | F15: 0 | G15: 0 | H15: 4034.68
A16: 43660 | B16: 150 | C16: 0 | D16: 340 | E16: 0 | F16: 0 | G16: 0 | H16: 4034.68
A17: 43661 | B17: 150 | C17: 0 | D17: 339 | E17: 0.03 | F17: 0 | G17: 0 | H17: 4034.67
A18: 43662 | B18: 181 | C18: 0 | D18: 358 | E18: 0 | F18: 0 | G18: 0 | H18: 4034.66 | I18: * 0900 150/200
A19: 43663 | B19: 238 | C19: 0 | D19: 393 | E19: 0 | F19: 0 | G19: 0 | H19: 4034.65 | I19: * 1500 200/300
A20: 43664 | B20: 324 | C20: 0 | D20: 459 | E20: 0 | F20: 0 | G20: 0 | H20: 4034.65 | I20: * 11:00 300/350
A21: 43665 | B21: 363 | C21: 0 | D21: 500 | E21: 0 | F21: 0 | G21: 0 | H21: 4034.64 | I21: * 10:00 350/400 * 16:30 400/350
A22: 43666 | B22: 315 | C22: 7 | D22: 485 | E22: 0 | F22: 0 | G22: 0 | H22: 4034.64 | I22: * 07:00 350/300
A23: 43667 | B23: 281 | C23: 0 | D23: 468 | E23: 0 | F23: 0 | G23: 0 | H23: 4034.63 | I23: * 15:00 300/250
A24: 43668 | B24: 306 | C24: 0 | D24: 492 | E24: 0 | F24: 0 | G24: 0 | H24: 4034.63 | I24: * 1500 250/400
A25: 43669 | B25: 400 | C25: 0 | D25: 563 | E25: 0 | F25: 0 | G25: 0 | H25: 4034.63
A26: 43670 | B26: 430 | C26: 0 | D26: 570 | E26: 0 | F26: 0 | G26: 0 | H26: 4034.63 | I26: * 0000 400/450 * 1730 450/375
A27: 43671 | B27: 425 | C27: 0 | D27: 529 | E27: 0 | F27: 0 | G27: 0 | H27: 4034.63 | I27: * 0800 375/450
A28: 43672 | B28: 404 | C28: 0 | D28: 542 | E28: 0 | F28: 0 | G28: 0 | H28: 4034.63 | I28: * 0900 450/400 * 1700 400/350
A29: 43673 | B29: 342 | C29: 0 | D29: 519 | E29: 0 | F29: 0 | G29: 0 | H29: 4034.63 | I29: * 22:00 350/250
A30: 43674 | B30: 284 | C30: 29 | D30: 494 | E30: 0 | F30: 0 | G30: 0 | H30: 4034.63 | I30: * 0730 250/300
A31: 43675 | B31: 263 | C31: 26 | D31: 482 | E31: 0 | F31: 0 | G31: 0 | H31: 4034.61 | I31: * 1030 300/200 * 1500 200/250
A32: 43676 | B32: 308 | C32: 0 | D32: 477 | E32: 0 | F32: 0 | G32: 0 | H32: 4034.58 | I32: * 1330 250/350 * 1700 350/400
A33: 43677 | B33: 388 | C33: 0 | D33: 469 | E33: 0 | F33: 0 | G33: 0 | H33: 4034.58 | I33: * 0900 400/350 * 19:30 350/450
A34: Monthly Total | B34: =SUM(B3:B33) -> 8706 | C34: =SUM(C3:C33) -> 127 | D34: =SUM(D3:D33) -> 13448 | E34: =SUM(E3:E33) -> 0.03 | F34: =SUM(F3:F33) -> 0 | G34: =SUM(G3:G33) -> 0
A35: WY Total | B35: =SUM(B34+'Jun 2019'!B34) -> 22633 | C35: =SUM(C34+'Jun 2019'!C34) -> 6007 | D35: =SUM(D34+'Jun 2019'!D34) -> 38375 | E35: =SUM(E34+'Jun 2019'!E34) -> 11.656 | F35: =SUM(F34+'Jun 2019'!F34) -> 23.87 | G35: =SUM(G34+'Jun 2019'!G34) -> 28252
A37: Acre Feet | B37: =SUM(B3:B33)*1.9835 -> 17268.351 | C37: =SUM(C3:C33)*1.9835 -> 251.9045 | D37: =SUM(D3:D33)*1.9835 -> 26674.108
A39: WY AF Total | B39: =SUM(B37+'Jun 2019'!B38) -> 45084.955 | C39: =SUM(C37+'Jun 2019'!C38) -> 13269.615 | D39: =SUM(D37+'Jun 2019'!D38) -> 84354.288
G41: * COMPUTATIONAL PURPOSES ONLY! Do Not Enter Data in the Red Columns
A43: *This is computation purposes only for Station 48
A44: Sta 48
...

Sheet Jun 2019
A1: DATE | B1: STATION 48 | C1: ANDERSON-ROSE | D1: J CANAL | E1: TULE LAKE PRECIP | F1: TULE LAKE SNOW | G1: D PLANT | H1: TULE LAKE ELEV. | I1: CHANGES @ STATION 48
B2: (in CFS) | C2: (in CFS) | D2: (in CFS) | G2: (in AF)
A3: 43617 | B3: 0 | C3: 21 | D3: 137 | E3: 0.04 | F3: 0 | G3: 320 | H3: 4035.28
A4: 43618 | B4: 0 | C4: 8 | D4: 149 | E4: 0 | F4: 0 | G4: 320 | H4: 4035.28
A5: 43619 | B5: 25 | C5: 0 | D5: 168 | E5: 0 | F5: 0 | G5: 319 | H5: 4035.27 | I5: * 1200 0/50
A6: 43620 | B6: 71 | C6: 0 | D6: 184 | E6: 0 | F6: 0 | G6: 319 | H6: 4035.2 | I6: * 1400 50/100 | J6: * correction 48; should be 71 instead of 56
A7: 43621 | B7: 100 | C7: 0 | D7: 219 | E7: 0 | F7: 0 | G7: 319 | H7: 4035.2
A8: 43622 | B8: 100 | C8: 0 | D8: 255 | E8: 0 | F8: 0 | G8: 318 | H8: 4035.14
A9: 43623 | B9: 80 | C9: 25 | D9: 262 | E9: 0 | F9: 0 | G9: 318 | H9: 4035.1 | I9: * 1430 100/50
A10: 43624 | B10: 50 | C10: 0 | D10: 244 | E10: 0 | F10: 0 | G10: 318 | H10: 4035.07
A11: 43625 | B11: 69 | C11: 0 | D11: 241 | E11: 0 | F11: 0 | G11: 318 | H11: 4035.04 | I11: * 15:00 50/100
A12: 43626 | B12: 148 | C12: 0 | D12: 293 | E12: 0 | F12: 0 | G12: 318 | H12: 4035.04 | I12: * 0830 100/150 * 1630 150/200
A13: 43627 | B13: 260 | C13: 0 | D13: 361 | E13: 0 | F13: 0 | G13: 192 | H13: 4035.02 | I13: * 0930 200/300
A14: 43628 | B14: 313 | C14: 0 | D14: 394 | E14: 0 | F14: 0 | G14: 47 | H14: 4035.02 | I14: * 1800 300/350
A15: 43629 | B15: 336 | C15: 0 | D15: 457 | E15: 0 | F15: 0 | G15: 0 | H15: 4035.02 | I15: * 1730 350/300
A16: 43630 | B16: 329 | C16: 11 | D16: 510 | E16: 0 | F16: 0 | G16: 0 | H16: 4035.02 | I16: * 1000 300/350
A17: 43631 | B17: 350 | C17: 0 | D17: 526 | E17: 0 | F17: 0 | G17: 0 | H17: 4035
A18: 43632 | B18: 350 | C18: 0 | D18: 507 | E18: 0 | F18: 0 | G18: 0 | H18: 4035
A19: 43633 | B19: 381 | C19: 0 | D19: 509 | E19: 0 | F19: 0 | G19: 0 | H19: 4035.95 | I19: * 0900 350/400
A20: 43634 | B20: 463 | C20: 0 | D20: 540 | E20: 0 | F20: 0 | G20: 0 | H20: 4035.9 | I20: * 0900 400/500
A21: 43635 | B21: 594 | C21: 0 | D21: 621 | E21: 0 | F21: 0 | G21: 0 | H21: 4035.9 | I21: * 0700 500/650 * 2000 650/600 * 2200 600/550
A22: 43636 | B22: 492 | C22: 35 | D22: 655 | E22: 0 | F22: 0 | G22: 0 | H22: 4035.856 | I22: * 0600 550/450 * 1600 450/500
A23: 43637 | B23: 519 | C23: 0 | D23: 674 | E23: 0 | F23: 0 | G23: 0 | H23: 4035.86 | I23: * 15:00 500/550
A24: 43638 | B24: 599 | C24: 0 | D24: 707 | E24: 0 | F24: 0 | G24: 0 | H24: 4035.86 | I24: * 09:00 550/650 * 17:30 650/600
A25: 43639 | B25: 547 | C25: 116 | D25: 694 | E25: 0 | F25: 0 | G25: 0 | H25: 4035.85 | I25: * 07:30 600/550 * 15:00 550/500
A26: 43640 | B26: 429 | C26: 64 | D26: 635 | E26: 0 | F26: 0 | G26: 0 | H26: 4034.84 | I26: * 07:00 500/400
A27: 43641 | B27: 485 | C27: 0 | D27: 667 | E27: 0 | F27: 0 | G27: 0 | H27: 4034.83 | I27: * 08:00 400/500 * 15:00 500/550
A28: 43642 | B28: 542 | C28: 17 | D28: 678 | E28: 0 | F28: 0 | G28: 0 | H28: 4034.82 | I28: * 2200 550/450
A29: 43643 | B29: 450 | C29: 44 | D29: 652 | E29: 0.3 | F29: 0 | G29: 0 | H29: 4034.81
A30: 43644 | B30: 475 | C30: 0 | D30: 579 | E30: 0 | F30: 0 | G30: 0 | H30: 4034.8 | I30: * 1000 450/550 * 1600 550/450
A31: 43645 | B31: 413 | C31: 0 | D31: 528 | E31: 0 | F31: 0 | G31: 0 | H31: 4034.79 | I31: * 1500 450/350
A32: 43646 | B32: 350 | C32: 0 | D32: 476 | E32: 0 | F32: 0 | G32: 0 | H32: 4034.78
A33: Monthly Total | B33: =SUM(B3:B32) -> 9320 | C33: =SUM(C3:C32) -> 341 | D33: =SUM(D3:D32) -> 13522 | E33: =SUM(E3:E32) -> 0.34 | F33: =SUM(F3:F32) -> 0 | G33: =SUM(G3:G32) -> 3426
A34: WY Total | B34: =SUM(B33+'May 2019'!B35) -> 13927 | C34: =SUM(C33+'May 2019'!C35) -> 5880 | D34: =SUM(D33+'May 2019'!D35) -> 24927 | E34: =SUM(E33+'May 2019'!E35) -> 11.626 | F34: =SUM(F33+'May 2019'!F35) -> 23.87 | G34: =SUM(G33+'May 2019'!G35) -> 28252
A36: Acre Feet | B36: =SUM(B3:B32)*1.9835 -> 18486.22 | C36: =SUM(C3:C32)*1.9835 -> 676.3735 | D36: =SUM(D3:D32)*1.9835 -> 26820.887
A38: WY AF Total | B38: =SUM(B36+'May 2019'!B39) -> 27816.604 | C38: =SUM(C36+'May 2019'!C39) -> 13017.71 | D38: =SUM(D36+'May 2019'!D39) -> 57680.18
G40: * COMPUTATIONAL PURPOSES ONLY! Do Not Enter Data in the Red Columns
A42: *This is computation purposes only for Station 48
A43: Sta 48
F44: =SUM(24-D44) -> 24 | G44: =SUM(C44+E44) -> 0 | H44: =SUM(C44/24*D44+G44/24*F44) -> 0
...

Sheet May 2019
A1: DATE | B1: STATION 48 | C1: ANDERSON-ROSE | D1: J CANAL | E1: TULE LAKE PRECIP | F1: TULE LAKE SNOW | G1: D PLANT | H1: TULE LAKE ELEV. | I1: CHANGES @ STATION 48
B2: (in CFS) | C2: (in CFS) | D2: (in CFS) | G2: (in AF)
A3: 43586 | B3: 0 | C3: 5 | D3: 114 | E3: 0 | F3: 0 | G3: 0 | H3: 4035.16
A4: 43587 | B4: 0 | C4: 0 | D4: 145 | E4: 0 | F4: 0 | G4: 0 | H4: 4035.16
A5: 43588 | B5: 22 | C5: 0 | D5: 153 | E5: 0 | F5: 0 | G5: 0 | H5: 4035.16 | I5: * 1330 0/50
A6: 43589 | B6: 88 | C6: 0 | D6: 180 | E6: 0 | F6: 0 | G6: 0 | H6: 4035.16 | I6: *1500 50/150
A7: 43590 | B7: 133 | C7: 0 | D7: 267 | E7: 0 | F7: 0 | G7: 0 | H7: 4035.16 | I7: *0700 150/100 1500 100/150
A8: 43591 | B8: 169 | C8: 0 | D8: 318 | E8: 0 | F8: 0 | G8: 0 | H8: 4035.15 | I8: * 15:00 150/200
A9: 43592 | B9: 200 | C9: 0 | D9: 337 | E9: 0 | F9: 0 | G9: 0 | H9: 4035.14
A10: 43593 | B10: 200 | C10: 0 | D10: 437 | E10: 0 | F10: 0 | G10: 0 | H10: 4035.12
A11: 43594 | B11: 271 | C11: 0 | D11: 482 | E11: 0 | F11: 0 | G11: 0 | H11: 4035.12 | I11: * 1030 200/300 * 1700 300/350
A12: 43595 | B12: 371 | C12: 0 | D12: 472 | E12: 0 | F12: 0 | G12: 0 | H12: 4035.12 | I12: *1400 350/400
A13: 43596 | B13: 400 | C13: 0 | D13: 512 | E13: 0 | F13: 0 | G13: 0 | H13: 4035.13
A14: 43597 | B14: 347 | C14: 23 | D14: 491 | E14: 0 | F14: 0 | G14: 0 | H14: 4035.13 | I14: ** 07:30 400/350 15:00 350/300
A15: 43598 | B15: 263 | C15: 6 | D15: 477 | E15: 0 | F15: 0 | G15: 0 | H15: 4035.15 | I15: * 15:00 300/200
A16: 43599 | B16: 200 | C16: 0 | D16: 473 | E16: 0 | F16: 0 | G16: 0 | H16: 4035.15
A17: 43600 | B17: 169 | C17: 0 | D17: 420 | E17: 0.07 | F17: 0 | G17: 0 | H17: 4035.15 | I17: * 0900 200/150
A18: 43601 | B18: 150 | C18: 0 | D18: 370 | E18: 0 | F18: 0 | G18: 0 | H18: 4035.15
A19: 43602 | B19: 120 | C19: 0 | D19: 350 | E19: 0.03 | F19: 0 | G19: 0 | H19: 4035.15 | I19: * 0930 150/100
A20: 43603 | B20: 52 | C20: 0 | D20: 317 | E20: 0 | F20: 0 | G20: 0 | H20: 4035.15 | I20: *0700 100/50 *1430 50/18
A21: 43604 | B21: 18 | C21: 0 | D21: 270 | E21: 0.09 | F21: 0 | G21: 0 | H21: 4035.15
A22: 43605 | B22: 41 | C22: 0 | D22: 241 | E22: 0.01 | F22: 0 | G22: 0 | H22: 4035.15 | I22: * 0700 18/50
A23: 43606 | B23: 108 | C23: 0 | D23: 244 | E23: 0.13 | F23: 0 | G23: 0 | H23: 4035.16 | I23: * 0500 50/150 * 1400 150/100
A24: 43607 | B24: 67 | C24: 10 | D24: 218 | E24: 0.06 | F24: 0 | G24: 165 | H24: 4035.17 | I24: * 0800 100/50 * 0000 50/18
A25: 43608 | B25: 13 | C25: 14 | D25: 229 | E25: T | F25: 0 | G25: 262 | H25: 4035.18 | I25: * 17:00 18/0
A26: 43609 | B26: 19 | C26: 0 | D26: 242 | E26: 0 | F26: 0 | G26: 320 | H26: 4035.19 | I26: * 15:00 0/50
A27: 43610 | B27: 37 | C27: 0 | D27: 225 | E27: 0 | F27: 0 | G27: 320 | H27: 4035.22 | I27: * 14:30 50/18
A28: 43611 | B28: 5 | C28: 54 | D28: 194 | E28: 0.7 | F28: T | G28: 320 | H28: 4035.24 | I28: * 07:15 18/0
A29: 43612 | B29: 0 | C29: 62 | D29: 165 | E29: 0.43 | F29: 0 | G29: 320 | H29: 4035.26
A30: 43613 | B30: 0 | C30: 48 | D30: 143 | E30: 0.05 | F30: 0 | G30: 320 | H30: 4035.28
A31: 43614 | B31: 0 | C31: 21 | D31: 128 | E31: 0.06 | F31: 0 | G31: 320 | H31: 4035.3
A32: 43615 | B32: 0 | C32: 28 | D32: 129 | E32: 0 | F32: 0 | G32: 320 | H32: 4035.3
A33: 43616 | B33: 0 | C33: 58 | D33: 135 | E33: 0.02 | F33: 0 | G33: 320 | H33: 4035.28
A34: Monthly Total | B34: =SUM(B3:B33) -> 3463 | C34: =SUM(C3:C33) -> 329 | D34: =SUM(D3:D33) -> 8878 | E34: =SUM(E3:E33) -> 1.65 | F34: =SUM(F3:F33) -> 0 | G34: =SUM(G3:G33) -> 2987
A35: WY Total | B35: =SUM(B34+'Apr 2019'!B34) -> 4607 | C35: =SUM(C34+'Apr 2019'!C34) -> 5539 | D35: =SUM(D34+'Apr 2019'!D34) -> 11405 | E35: =SUM(E34+'Apr 2019'!E34) -> 11.286 | F35: =SUM(F34+'Apr 2019'!F34) -> 23.87 | G35: =SUM(G34+'Apr 2019'!G34) -> 24826
A37: Acre Feet | B37: =SUM(B3:B33)*1.9835 -> 6868.8605 | C37: =SUM(C3:C33)*1.9835 -> 652.5715 | D37: =SUM(D3:D33)*1.9835 -> 17609.513
A39: WY AF Total | B39: =SUM(B37+'Apr 2019'!B38) -> 9330.384 | C39: =SUM(C37+'Apr 2019'!C38) -> 12341.337 | D39: =SUM(D37+'Apr 2019'!D38) -> 30859.293
G41: * COMPUTATIONAL PURPOSES ONLY! Do Not Enter Data in the Red Columns
A43: *This is computation purposes only for Station 48
A44: Sta 48
...

Sheet Apr 2019
A1: DATE | B1: STATION 48 | C1: ANDERSON-ROSE | D1: J CANAL | E1: TULE LAKE PRECIP | F1: TULE LAKE SNOW | G1: D PLANT | H1: TULE LAKE ELEV. | I1: CHANGES @ STATION 48
B2: (in CFS) | C2: (in CFS) | D2: (in CFS) | G2: (in AF)
A3: 43556 | B3: 0 | C3: 0 | D3: 25 | E3: 0.05 | F3: 0 | G3: 160 | H3: 4034.82
A4: 43557 | B4: 12 | C4: 0 | D4: 38 | E4: 0.4 | F4: 0 | G4: 160 | H4: 4034.82 | I4: * 1300 0/25
A5: 43558 | B5: 25 | C5: 0 | D5: 49 | E5: 0.08 | F5: 0 | G5: 57 | H5: 4034.83
A6: 43559 | B6: 25 | C6: 0 | D6: 49 | E6: 0 | F6: 0 | G6: 0 | H6: 4034.83
A7: 43560 | B7: 25 | C7: 0 | D7: 49 | E7: 0.01 | F7: 0 | G7: 0 | H7: 4034.84
A8: 43561 | B8: 10 | C8: 0 | D8: 39 | E8: 0.05 | F8: 0 | G8: 0 | H8: 4034.84 | I8: * 1000 25/0
A9: 43562 | B9: 0 | C9: 0 | D9: 25 | E9: 0 | F9: 0 | G9: 0 | H9: 4034.84
A10: 43563 | B10: 0 | C10: 0 | D10: 44 | E10: 0.1 | F10: 0 | G10: 0 | H10: 4034.83
A11: 43564 | B11: 0 | C11: 0 | D11: 76 | E11: 0.49 | F11: 0 | G11: 0 | H11: 4034.86
A12: 43565 | B12: 0 | C12: 4 | D12: 93 | E12: T | F12: 0 | G12: 0 | H12: 4034.9
A13: 43566 | B13: 0 | C13: 0 | D13: 100 | E13: 0 | F13: 0 | G13: 0 | H13: 4034.91
A14: 43567 | B14: 0 | C14: 0 | D14: 90 | E14: T | F14: 0 | G14: 0 | H14: 4034.92
A15: 43568 | B15: 0 | C15: 0 | D15: 65 | E15: 0 | F15: 0 | G15: 0 | H15: 4034.93
A16: 43569 | B16: 0 | C16: 0 | D16: 68 | E16: 0.15 | F16: 0 | G16: 0 | H16: 4034.94
A17: 43570 | B17: 0 | C17: 18 | D17: 58 | E17: T | F17: 0 | G17: 0 | H17: 4034.95
A18: 43571 | B18: 0 | C18: 50 | D18: 40 | E18: 0.03 | F18: 0 | G18: 0 | H18: 4034.96
A19: 43572 | B19: 0 | C19: 50 | D19: 30 | E19: 0 | F19: 0 | G19: 0 | H19: 4034.98
A20: 43573 | B20: 0 | C20: 40 | D20: 30 | E20: 0 | F20: 0 | G20: 0 | H20: 4035
A21: 43574 | B21: 0 | C21: 45 | D21: 32 | E21: 0 | F21: 0 | G21: 0 | H21: 4035.02
A22: 43575 | B22: 0 | C22: 40 | D22: 32 | E22: 0.22 | F22: 0 | G22: 0 | H22: 4035.05
A23: 43576 | B23: 0 | C23: 35 | D23: 32 | E23: 0.08 | F23: 0 | G23: 0 | H23: 4035.07
A24: 43577 | B24: 0 | C24: 33 | D24: 32 | E24: 0 | F24: 0 | G24: 0 | H24: 4035.09
A25: 43578 | B25: 0 | C25: 43 | D25: 32 | E25: 0 | F25: 0 | G25: 0 | H25: 4035.12
A26: 43579 | B26: 0 | C26: 36 | D26: 32 | E26: 0 | F26: 0 | G26: 0 | H26: 4035.14
A27: 43580 | B27: 0 | C27: 41 | D27: 32 | E27: 0 | F27: 0 | G27: 0 | H27: 4035.14
A28: 43581 | B28: 0 | C28: 54 | D28: 57 | E28: 0 | F28: 0 | G28: 0 | H28: 4035.15
A29: 43582 | B29: 0 | C29: 58 | D29: 50 | E29: 0 | F29: 0 | G29: 0 | H29: 4035.15
... A32: 43585 | B32: 0 | C32: 31 | D32: 100 | E32: 0 | F32: 0 | G32: 0 | H32: 4035.16
A33: Monthly Total | B33: =SUM(B3:B32) -> 97 | C33: =SUM(C3:C32) -> 683 | D33: =SUM(D3:D32) -> 1543 | E33: =SUM(E3:E32) -> 1.66 | F33: =SUM(F3:F32) -> 0 | G33: =SUM(G3:G32) -> 377
A34: WY Total | B34: =SUM(B33+'Mar 2019'!B35) -> 1144 | C34: =SUM(C33+'Mar 2019'!C35) -> 5210 | D34: =SUM(D33+'Mar 2019'!D35) -> 2527 | E34: =SUM(E33+'Mar 2019'!E35) -> 9.636 | F34: =SUM(F33+'Mar 2019'!F35) -> 23.87 | G34: =SUM(G33+'Mar 2019'!G35) -> 21839
A36: Acre Feet | B36: =SUM(B3:B33)*1.9835 -> 384.799 | C36: =SUM(C3:C33)*1.9835 -> 2709.461 | D36: =SUM(D3:D33)*1.9835 -> 6121.081
A38: WY AF Total | B38: =SUM(B36+'Mar 2019'!B39) -> 2461.5235 | C38: =SUM(C36+'Mar 2019'!C39) -> 11688.765 | D38: =SUM(D36+'Mar 2019'!D39) -> 13249.78
G40: * COMPUTATIONAL PURPOSES ONLY! Do Not Enter Data in the Red Columns
A42: *This is computation purposes only for Station 48
A43: Sta 48
F44: =SUM(24-D44) -> 24 | G44: =SUM(C44+E44) -> 0 | H44: =SUM(C44/24*D44+G44/24*F44) -> 0
F45: =SUM(24-D45) -> 24 | G45: =SUM(C45+E45) -> 0 | H45: =SUM(C45/24*D45+G45/24*F45) -> 0
F46: =SUM(24-D46) -> 24 | G46: =SUM(C46+E46) -> 0 | H46: =SUM(C46/24*D46+G46/24*F46) -> 0
...

Sheet Mar 2019
A1: DATE | B1: STATION 48 | C1: ANDERSON-ROSE | D1: J CANAL | E1: TULE LAKE PRECIP | F1: TULE LAKE SNOW | G1: D PLANT | H1: TULE LAKE ELEV. | I1: CHANGES @ STATION 48
B2: (in CFS) | C2: (in CFS) | D2: (in CFS) | G2: (in AF)
A3: 43525 | B3: 0 | C3: 100 | D3: 0 | E3: T | F3: 0 | G3: 452 | H3: 4035.06
A4: 43526 | B4: 0 | C4: 106 | D4: 0 | E4: 0.02 | F4: 0 | G4: 452 | H4: 4035.06
A5: 43527 | B5: 0 | C5: 92 | D5: 0 | E5: T | F5: 0 | G5: 452 | H5: 4035.06
A6: 43528 | B6: 0 | C6: 75 | D6: 0 | E6: 0.01 | F6: 0 | G6: 452 | H6: 4035.05
A7: 43529 | B7: 0 | C7: 65 | D7: 0 | E7: 0.02 | F7: 0 | G7: 452 | H7: 4035.04
A8: 43530 | B8: 0 | C8: 85 | D8: 0 | E8: 0.22 | F8: 0 | G8: 452 | H8: 4035.03
A9: 43531 | B9: 0 | C9: 80 | D9: 0 | E9: 0.13 | F9: 0 | G9: 452 | H9: 4035.02
A10: 43532 | B10: 0 | C10: 61 | D10: 0 | E10: T | F10: 0 | G10: 452 | H10: 4035.01
A11: 43533 | B11: 0 | C11: 34 | D11: 0 | E11: 0.02 | F11: 1 | G11: 452 | H11: 4035
A12: 43534 | B12: 0 | C12: 60 | D12: 0 | E12: 0.14 | F12: 3 | G12: 452 | H12: 4034.99
A13: 43535 | B13: 0 | C13: 41 | D13: 0 | E13: 0.01 | F13: 0 | G13: 452 | H13: 4034.98
A14: 43536 | B14: 0 | C14: 42 | D14: 0 | E14: 0.06 | F14: 0.5 | G14: 451 | H14: 4034.97
A15: 43537 | B15: 0 | C15: 40 | D15: 0 | E15: T | F15: 0 | G15: 451 | H15: 4034.96
A16: 43538 | B16: 0 | C16: 35 | D16: 0 | E16: 0.02 | F16: 0 | G16: 452 | H16: 4034.95
A17: 43539 | B17: 0 | C17: 31 | D17: 0 | E17: 0 | F17: 0 | G17: 369 | H17: 4034.94
A18: 43540 | B18: 0 | C18: 31 | D18: 0 | E18: 0 | F18: 0 | G18: 318 | H18: 4034.93
A19: 43541 | B19: 0 | C19: 31 | D19: 0 | E19: 0 | F19: 0 | G19: 318 | H19: 4034.92
A20: 43542 | B20: 0 | C20: 31 | D20: 0 | E20: 0 | F20: 0 | G20: 318 | H20: 4034.9
A21: 43543 | B21: 0 | C21: 31 | D21: 0 | E21: 0 | F21: 0 | G21: 318 | H21: 4034.89
A22: 43544 | B22: 0 | C22: 29 | D22: 0 | E22: 0 | F22: 0 | G22: 318 | H22: 4034.87
A23: 43545 | B23: 0 | C23: 27 | D23: 0 | E23: 0 | F23: 0 | G23: 318 | H23: 4034.86
A24: 43546 | B24: 0 | C24: 26 | D24: 0 | E24: 0 | F24: 0 | G24: 218 | H24: 4034.85
A25: 43547 | B25: 0 | C25: 25 | D25: 0 | E25: 0.05 | F25: 0 | G25: 160 | H25: 4034.84
A26: 43548 | B26: 0 | C26: 25 | D26: 0 | E26: 0.07 | F26: 0 | G26: 160 | H26: 4034.83
A27: 43549 | B27: 0 | C27: 11 | D27: 29 | E27: 0.03 | F27: 0 | G27: 160 | H27: 4034.82
... A33: 43555 | B33: 0 | C33: 0 | D33: 24 | E33: 0 | F33: 0 | G33: 160 | H33: 4034.83
A34: Monthly Total | B34: =SUM(B3:B33) -> 0 | C34: =SUM(C3:C33) -> 1214 | D34: =SUM(D3:D33) -> 204 | E34: =SUM(E3:E33) -> 1.306 | F34: =SUM(F3:F33) -> 4.5 | G34: =SUM(G3:G33) -> 10261
A35: WY Total | B35: =SUM(B34+'Feb 2019'!B33) -> 1047 | C35: =SUM(C34+'Feb 2019'!C33) -> 4527 | D35: =SUM(D34+'Feb 2019'!D33) -> 984 | E35: =SUM(E34+'Feb 2019'!E33) -> 7.976 | F35: =SUM(F34+'Feb 2019'!F33) -> 23.87 | G35: =SUM(G34+'Feb 2019'!G33) -> 21462
A37: Acre Feet | B37: =SUM(B3:B33)*1.9835 -> 0 | C37: =SUM(C3:C33)*1.9835 -> 2407.969 | D37: =SUM(D3:D33)*1.9835 -> 404.634
A39: WY AF Total | B39: =SUM(B37+'Feb 2019'!B37) -> 2076.7245 | C39: =SUM(C37+'Feb 2019'!C37) -> 8979.3045 | D39: =SUM(D37+'Feb 2019'!D37) -> 7128.699
G41: * COMPUTATIONAL PURPOSES ONLY! Do Not Enter Data in the Red Columns
A43: *This is computation purposes only for Station 48
A44: Sta 48
F45: =SUM(24-D45) -> 24 | G45: =SUM(C45+E45) -> 0 | H45: =SUM(C45/24*D45+G45/24*F45) -> 0
F46: =SUM(24-D46) -> 24 | G46: =SUM(C46+E46) -> 0 | H46: =SUM(C46/24*D46+G46/24*F46) -> 0
F47: =SUM(24-D47) -> 24 | G47: =SUM(C47+E47) -> 0 | H47: =SUM(C47/24*D47+G47/24*F47) -> 0
F48: =SUM(24-D48) -> 24 | G48: =SUM(C48+E48) -> 0 | H48: =SUM(C48/24*D48+G48/24*F48) -> 0
F49: =SUM(24-D49) -> 24 | G49: =SUM(C49+E49) -> 0 | H49: =SUM(C49/24*D49+G49/24*F49) -> 0
...

Sheet Feb 2019
A1: DATE | B1: STATION 48 | C1: ANDERSON-ROSE | D1: J CANAL | E1: TULE LAKE PRECIP | F1: TULE LAKE SNOW | G1: D PLANT | H1: TULE LAKE ELEV. | I1: CHANGES @ STATION 48
B2: (in CFS) | C2: (in CFS) | D2: (in CFS) | G2: (in AF)
A3: 43497 | B3: 0 | C3: 30 | D3: 0 | E3: T | F3: 0 | G3: 0 | H3: 4035.01
A4: 43498 | B4: 0 | C4: 30 | D4: 0 | E4: 0.03 | F4: 0 | G4: 0 | H4: 4035.02
A5: 43499 | B5: 0 | C5: 30 | D5: 0 | E5: T | F5: 0 | G5: 0 | H5: 4035.03
A6: 43500 | B6: 0 | C6: 30 | D6: 0 | E6: 0.25 | F6: 3 | G6: 0 | H6: 4035.04
A7: 43501 | B7: 0 | C7: 30 | D7: 0 | E7: 0.08 | F7: 1 | G7: 99 | H7: 4035.05 | I7: *Start 1 unit D PLANT 9:00 AM
A8: 43502 | B8: 0 | C8: 30 | D8: 0 | E8: 0.02 | F8: 0 | G8: 160 | H8: 4035.05
A9: 43503 | B9: 0 | C9: 30 | D9: 0 | E9: T | F9: 0 | G9: 160 | H9: 4035.05
A10: 43504 | B10: 0 | C10: 30 | D10: 0 | E10: T | F10: 0 | G10: 160 | H10: 4035.05
A11: 43505 | B11: 0 | C11: 30 | D11: 0 | E11: 0.08 | F11: 0.5 | G11: 160 | H11: 4035.04
A12: 43506 | B12: 0 | C12: 30 | D12: 0 | E12: 0.03 | F12: 0 | G12: 160 | H12: 4035.04
A13: 43507 | B13: 0 | C13: 30 | D13: 0 | E13: 0 | F13: 0 | G13: 160 | H13: 4035.04
A14: 43508 | B14: 0 | C14: 30 | D14: 0 | E14: 0 | F14: 0 | G14: 160 | H14: 4035.04
A15: 43509 | B15: 0 | C15: 30 | D15: 0 | E15: 0.19 | F15: 2.5 | G15: 108 | H15: 4035.05
A16: 43510 | B16: 0 | C16: 73 | D16: 0 | E16: 0.61 | F16: 0 | G16: 244 | H16: 4035.1
A17: 43511 | B17: 0 | C17: 150 | D17: 0 | E17: 0.03 | F17: 0.5 | G17: 300 | H17: 4035.07
A18: 43512 | B18: 0 | C18: 94 | D18: 0 | E18: 0.06 | F18: 1 | G18: 300 | H18: 4035.06
A19: 43513 | B19: 0 | C19: 55 | D19: 0 | E19: 0.07 | F19: 0 | G19: 300 | H19: 4035.06
A20: 43514 | B20: 0 | C20: 45 | D20: 0 | E20: 0 | F20: 0 | G20: 300 | H20: 4035.04
A21: 43515 | B21: 0 | C21: 40 | D21: 0 | E21: 0 | F21: 0 | G21: 300 | H21: 4035.03
A22: 43516 | B22: 0 | C22: 33 | D22: 0 | E22: 0.05 | F22: 0.5 | G22: 300 | H22: 4035.02
A23: 43517 | B23: 0 | C23: 28 | D23: 0 | E23: T | F23: T | G23: 300 | H23: 4035.01
A24: 43518 | B24: 0 | C24: 33 | D24: 0 | E24: 0 | F24: T | G24: 300 | H24: 4035
A25: 43519 | B25: 0 | C25: 34 | D25: 0 | E25: T | F25: 0 | G25: 300 | H25: 4034.99
A26: 43520 | B26: 0 | C26: 34 | D26: 0 | E26: 0 | F26: 0 | G26: 300 | H26: 4034.97
A27: 43521 | B27: 0 | C27: 33 | D27: 0 | E27: 0 | F27: 0 | G27: 301 | H27: 4034.99
A28: 43522 | B28: 0 | C28: 53 | D28: 0 | E28: 0.74 | F28: 7 | G28: 301 | H28: 4035.05
A29: 43523 | B29: 0 | C29: 56 | D29: 0 | E29: T | F29: T | G29: 396 | H29: 4035.06
A30: 43524 | B30: 0 | C30: 91 | D30: 0 | E30: 0.07 | F30: T | G30: 452 | H30: 4035.06
A32: Monthly Total | B32: =SUM(B3:B31) -> 0 | C32: =SUM(C3:C31) -> 1242 | D32: =SUM(D3:D31) -> 0 | E32: =SUM(E3:E31) -> 2.31 | F32: =SUM(F3:F31) -> 16 | G32: =SUM(G3:G31) -> 6021
A33: WY Total | B33: =SUM(B32+'Jan 2019'!B35) -> 1047 | C33: =SUM(C32+'Jan 2019'!C35) -> 3313 | D33: =SUM(D32+'Jan 2019'!D35) -> 780 | E33: =SUM(E32+'Jan 2019'!E35) -> 6.67 | F33: =SUM(F32+'Jan 2019'!F35) -> 19.37 | G33: =SUM(G32+'Jan 2019'!G35) -> 11201
A35: Acre Feet | B35: =SUM(B3:B31)*1.9835 -> 0 | C35: =SUM(C3:C31)*1.9835 -> 2463.507 | D35: =SUM(D3:D31)*1.9835 -> 0
A37: WY AF Total | B37: =SUM(B35+'Jan 2019'!B39) -> 2076.7245 | C37: =SUM(C35+'Jan 2019'!C39) -> 6571.3355 | D37: =SUM(D35+'Jan 2019'!D39) -> 6724.065
G39: * COMPUTATIONAL PURPOSES ONLY! Do Not Enter Data in the Red Columns
A41: *This is computation purposes only for Station 48
A42: Sta 48
F43: =SUM(24-D43) -> 24 | G43: =SUM(C43+E43) -> 0 | H43: =SUM(C43/24*D43+G43/24*F43) -> 0
F44: =SUM(24-D44) -> 24 | G44: =SUM(C44+E44) -> 0 | H44: =SUM(C44/24*D44+G44/24*F44) -> 0
F45: =SUM(24-D45) -> 24 | G45: =SUM(C45+E45) -> 0 | H45: =SUM(C45/24*D45+G45/24*F45) -> 0
...

Sheet Jan 2019
A1: DATE | B1: STATION 48 | C1: ANDERSON-ROSE | D1: J CANAL | E1: TULE LAKE PRECIP | F1: TULE LAKE SNOW | G1: D PLANT | H1: TULE LAKE ELEV. | I1: CHANGES @ STATION 48
B2: (in CFS) | C2: (in CFS) | D2: (in CFS) | G2: (in AF)
A3: 43466 | B3: 0 | C3: 20 | D3: 0 | E3: 0 | F3: 0 | G3: 0 | H3: 4034.65
A4: 43467 | B4: 0 | C4: 20 | D4: 0 | E4: 0 | F4: 0 | G4: 0 | H4: 4034.65
A5: 43468 | B5: 0 | C5: 20 | D5: 0 | E5: 0 | F5: 0 | G5: 0 | H5: 4034.65
A6: 43469 | B6: 0 | C6: 20 | D6: 0 | E6: 0 | F6: 0 | G6: 0 | H6: 4034.66
A7: 43470 | B7: 0 | C7: 20 | D7: 0 | E7: 0 | F7: 0 | G7: 0 | H7: 4034.66
A8: 43471 | B8: 0 | C8: 20 | D8: 0 | E8: T | F8: 0 | G8: 0 | H8: 4034.66
A9: 43472 | B9: 0 | C9: 20 | D9: 0 | E9: 0.08 | F9: 2 | G9: 0 | H9: 4034.67
A10: 43473 | B10: 0 | C10: 20 | D10: 0 | E10: 0 | F10: 0 | G10: 0 | H10: 4034.68
A11: 43474 | B11: 0 | C11: 20 | D11: 0 | E11: 0.28 | F11: 0 | G11: 0 | H11: 4034.68
A12: 43475 | B12: 0 | C12: 20 | D12: 0 | E12: 0.02 | F12: 0 | G12: 0 | H12: 4034.7
A13: 43476 | B13: 0 | C13: 20 | D13: 0 | E13: t | F13: 0 | G13: 0 | H13: 4034.7
A14: 43477 | B14: 0 | C14: 20 | D14: 0 | E14: 0 | F14: 0 | G14: 0 | H14: 4034.72
A15: 43478 | B15: 0 | C15: 20 | D15: 0 | E15: 0 | F15: 0 | G15: 0 | H15: 4034.72
A16: 43479 | B16: 0 | C16: 20 | D16: 0 | E16: 0 | F16: 0 | G16: 0 | H16: 4034.73
A17: 43480 | B17: 0 | C17: 20 | D17: 0 | E17: T | F17: 0 | G17: 0 | H17: 4034.74
A18: 43481 | B18: 0 | C18: 20 | D18: 0 | E18: 0 | F18: 0 | G18: 0 | H18: 4034.76
A19: 43482 | B19: 0 | C19: 20 | D19: 0 | E19: 0.36 | F19: 0 | G19: 0 | H19: 4034.78
A20: 43483 | B20: 0 | C20: 20 | D20: 0 | E20: 0.3 | F20: 1 | G20: 0 | H20: 4034.79
A21: 43484 | B21: 0 | C21: 20 | D21: 0 | E21: 0.04 | F21: 0 | G21: 0 | H21: 4034.81
A22: 43485 | B22: 0 | C22: 20 | D22: 0 | E22: 0.17 | F22: 0 | G22: 0 | H22: 4034.83
A23: 43486 | B23: 0 | C23: 20 | D23: 0 | E23: 0.01 | F23: 0 | G23: 0 | H23: 4034.84
A24: 43487 | B24: 0 | C24: 45 | D24: 0 | E24: T | F24: 0 | G24: 0 | H24: 4034.85
A25: 43488 | B25: 0 | C25: 68 | D25: 0 | E25: 0 | F25: 0 | G25: 0 | H25: 4034.86
A26: 43489 | B26: 0 | C26: 80 | D26: 0 | E26: 0.01 | F26: 0 | G26: 0 | H26: 4034.88
A27: 43490 | B27: 0 | C27: 80 | D27: 0 | E27: 0.02 | F27: 0 | G27: 0 | H27: 4034.9
A28: 43491 | B28: 0 | C28: 80 | D28: 0 | E28: 0.01 | F28: 0 | G28: 0 | H28: 4034.92
A29: 43492 | B29: 0 | C29: 80 | D29: 0 | E29: T | F29: 0 | G29: 0 | H29: 4034.94
A30: 43493 | B30: 0 | C30: 80 | D30: 0 | E30: 0.01 | F30: 0 | G30: 0 | H30: 4034.95
A31: 43494 | B31: 0 | C31: 63 | D31: 0 | E31: 0 | F31: 0 | G31: 0 | H31: 4034.96
A32: 43495 | B32: 0 | C32: 38 | D32: 0 | E32: 0 | F32: 0 | G32: 0 | H32: 4034.98
A33: 43496 | B33: 0 | C33: 30 | D33: 0 | E33: 0.01 | F33: 0 | G33: 0 | H33: 4035
A34: Monthly Total | B34: =SUM(B3:B33) -> 0 | C34: =SUM(C3:C33) -> 1064 | D34: =SUM(D3:D33) -> 0 | E34: =SUM(E3:E33) -> 1.32 | F34: =SUM(F3:F33) -> 3 | G34: =SUM(G3:G33) -> 0
A35: WY Total | B35: =SUM(B34+'Dec 2018'!B35) -> 1047 | C35: =SUM(C34+'Dec 2018'!C35) -> 2071 | D35: =SUM(D34+'Dec 2018'!D35) -> 780 | E35: =SUM(E34+'Dec 2018'!E35) -> 4.36 | F35: =SUM(F34+'Dec 2018'!F35) -> 3.37 | G35: =SUM(G34+'Dec 2018'!G35) -> 5180
A37: Acre Feet | B37: =SUM(B3:B33)*1.9835 -> 0 | C37: =SUM(C3:C33)*1.9835 -> 2110.444 | D37: =SUM(D3:D33)*1.9835 -> 0
A39: WY AF Total | B39: =SUM(B37+'Dec 2018'!B39) -> 2076.7245 | C39: =SUM(C37+'Dec 2018'!C39) -> 4107.8285 | D39: =SUM(D37+'Dec 2018'!D39) -> 6724.065
G41: * COMPUTATIONAL PURPOSES ONLY! Do Not Enter Data in the Red Columns
A43: *This is computation purposes only for Station 48
A44: Sta 48
...

Sheet Dec 2018
A1: DATE | B1: STATION 48 | C1: ANDERSON-ROSE | D1: J CANAL | E1: TULE LAKE PRECIP | F1: TULE LAKE SNOW | G1: D PLANT | H1: TULE LAKE ELEV. | I1: CHANGES @ STATION 48
B2: (in CFS) | C2: (in CFS) | D2: (in CFS) | G2: (in AF)
A3: 43435 | B3: 0 | C3: 20 | D3: 0 | E3: 0 | F3: 0.15 | G3: 0 | H3: 4034.52
A4: 43436 | B4: 0 | C4: 20 | D4: 0 | E4: 0 | F4: 0.02 | G4: 0 | H4: 4034.52
A5: 43437 | B5: 0 | C5: 20 | D5: 0 | E5: 0 | F5: 0 | G5: 0 | H5: 4034.54
A6: 43438 | B6: 0 | C6: 9 | D6: 0 | E6: 0 | F6: 0 | G6: 0 | H6: 4034.54
A7: 43439 | B7: 0 | C7: 0 | D7: 0 | E7: 0 | F7: 0 | G7: 0 | H7: 4034.54
A8: 43440 | B8: 0 | C8: 0 | D8: 0 | E8: 0 | F8: 0 | G8: 0 | H8: 4034.54
A9: 43441 | B9: 0 | C9: 0 | D9: 0 | E9: 0 | F9: 0 | G9: 0 | H9: 4034.54
A10: 43442 | B10: 0 | C10: 0 | D10: 0 | E10: 0 | F10: 0 | G10: 0 | H10: 4034.54
A11: 43443 | B11: 0 | C11: 0 | D11: 0 | E11: 0 | F11: 0 | G11: 0 | H11: 4034.54
A12: 43444 | B12: 0 | C12: 0 | D12: 0 | E12: 0.13 | F12: 0 | G12: 0 | H12: 4034.54
A13: 43445 | B13: 0 | C13: 12 | D13: 0 | E13: 0 | F13: 0 | G13: 0 | H13: 4034.54
A14: 43446 | B14: 0 | C14: 20 | D14: 0 | E14: 0.05 | F14: 0 | G14: 0 | H14: 4034.54
... A23: 43455 | B23: 0 | C23: 30 | D23: 0 | E23: 0.11 | F23: 0 | G23: 0 | H23: 4034.58
A24: 43456 | B24: 0 | C24: 30 | D24: 0 | E24: T | F24: 0 | G24: 0 | H24: 4034.58
A25: 43457 | B25: 0 | C25: 30 | D25: 0 | E25: 0.17 | F25: 0 | G25: 0 | H25: 4034.59
A26: 43458 | B26: 0 | C26: 30 | D26: 0 | E26: 0.58 | F26: 0 | G26: 0 | H26: 4034.6
A27: 43459 | B27: 0 | C27: 30 | D27: 0 | E27: 0.17 | F27: 0.2 | G27: 0 | H27: 4034.61
A28: 43460 | B28: 0 | C28: 30 | D28: 0 | E28: T | F28: 0 | G28: 0 | H28: 4034.62
A29: 43461 | B29: 0 | C29: 24 | D29: 0 | E29: T | F29: 0 | G29: 0 | H29: 4034.62
A30: 43462 | B30: 0 | C30: 20 | D30: 0 | E30: 0 | F30: 0 | G30: 0 | H30: 4034.62
A31: 43463 | B31: 0 | C31: 20 | D31: 0 | E31: 0 | F31: 0 | G31: 0 | H31: 4034.62
A32: 43464 | B32: 0 | C32: 20 | D32: 0 | E32: 0 | F32: 0 | G32: 0 | H32: 4034.63
A33: 43465 | B33: 0 | C33: 20 | D33: 0 | E33: 0 | F33: 0 | G33: 0 | H33: 4034.64
A34: Monthly Total | B34: =SUM(B3:B33) -> 0 | C34: =SUM(C3:C33) -> 549 | D34: =SUM(D3:D33) -> 0 | E34: =SUM(E3:E33) -> 1.69 | F34: =SUM(F3:F33) -> 0.37 | G34: =SUM(G3:G33) -> 0
A35: WY Total | B35: =SUM(B34+'Nov 2018'!B34) -> 1047 | C35: =SUM(C34+'Nov 2018'!C34) -> 1007 | D35: =SUM(D34+'Nov 2018'!D34) -> 780 | E35: =SUM(E34+'Nov 2018'!E34) -> 3.04 | F35: =SUM(F34+'Nov 2018'!F34) -> 0.37 | G35: =SUM(G34+'Nov 2018'!G34) -> 5180
A37: Acre Feet | B37: =SUM(B3:B33)*1.9835 -> 0 | C37: =SUM(C3:C33)*1.9835 -> 1088.9415 | D37: =SUM(D3:D33)*1.9835 -> 0
A39: WY AF Total | B39: =SUM('Nov 2018'!B38+B37) -> 2076.7245 | C39: =SUM('Nov 2018'!C38+C37) -> 1997.3845 | D39: =SUM('Nov 2018'!D38+D37) -> 6724.065
G41: * COMPUTATIONAL PURPOSES ONLY! Do Not Enter Data in the Red Columns
A43: *This is computation purposes only for Station 48
A44: Sta 48
F45: =SUM(24-D45) -> 24 | G45: =SUM(C45+E45) -> 0 | H45: =SUM(C45/24*D45+G45/24*F45) -> 0
F46: =SUM(24-D46) -> 24 | G46: =SUM(C46+E46) -> 0 | H46: =SUM(C46/24*D46+G46/24*F46) -> 0
F47: =SUM(24-D47) -> 24 | G47: =SUM(C47+E47) -> 0 | H47: =SUM(C47/24*D47+G47/24*F47) -> 0
F48: =SUM(24-D48) -> 24 | G48: =SUM(C48+E48) -> 0 | H48: =SUM(C48/24*D48+G48/24*F48) -> 0
F49: =SUM(24-D49) -> 24 | G49: =SUM(C49+E49) -> 0 | H49: =SUM(C49/24*D49+G49/24*F49) -> 0
A51: Use for more than 1 change in a day.
A52: **Station 48: | B52: Time | C52: Current CFS | D52: Hours Run | E52: +/- cfs | F52: Sub-total cfs
A58: Total Hours Run | D58: =SUM(D53:D57) -> 0 | E58: Total/Day cfs | F58: =SUM(F53:F57) -> 0

Sheet Nov 2018
A1: DATE | B1: STATION 48 | C1: ANDERSON-ROSE | D1: J CANAL | E1: TULE LAKE PRECIP | F1: TULE LAKE SNOW | G1: D PLANT | H1: TULE LAKE ELEV. | I1: CHANGES @ STATION 48
B2: (in CFS) | C2: (in CFS) | D2: (in CFS) | G2: (in AF)
A3: 43405 | B3: 50 | C3: 0 | D3: 66 | E3: 0 | F3: 0 | G3: 160 | H3: 4034.48
A4: 43406 | B4: 39 | C4: 0 | D4: 56 | E4: 0 | F4: 0 | G4: 60 | H4: 4034.46 | I4: * 13:30 50/25
A5: 43407 | B5: 25 | C5: 0 | D5: 41 | E5: 0 | F5: 0 | G5: 0 | H5: 4034.46
A6: 43408 | B6: 40 | C6: 0 | D6: 47 | E6: 0 | F6: 0 | G6: 0 | H6: 4034.46 | I6: * 9:30 25/50
A7: 43409 | B7: 43 | C7: 0 | D7: 61 | E7: 0 | F7: 0 | G7: 0 | H7: 4034.44 | I7: * 13:30 50/25
A8: 43410 | B8: 25 | C8: 0 | D8: 65 | E8: 0 | F8: 0 | G8: 0 | H8: 4034.44
A9: 43411 | B9: 25 | C9: 0 | D9: 63 | E9: 0 | F9: 0 | G9: 0 | H9: 4034.44
A10: 43412 | B10: 34 | C10: 0 | D10: 57 | E10: 0 | F10: 0 | G10: 0 | H10: 4034.44 | I10: * 0800 25/38
A11: 43413 | B11: 38 | C11: 0 | D11: 51 | E11: 0 | F11: 0 | G11: 0 | H11: 4034.44
A12: 43414 | B12: 38 | C12: 0 | D12: 50 | E12: 0 | F12: 0 | G12: 0 | H12: 4034.44
A13: 43415 | B13: 38 | C13: 0 | D13: 47 | E13: 0 | F13: 0 | G13: 0 | H13: 4034.42
A14: 43416 | B14: 38 | C14: 0 | D14: 42 | E14: 0 | F14: 0 | G14: 0 | H14: 4034.4
A15: 43417 | B15: 29 | C15: 0 | D15: 42 | E15: 0 | F15: 0 | G15: 0 | H15: 4034.4 | I15: * 0900 38/22
A16: 43418 | B16: 22 | C16: 0 | D16: 39 | E16: 0 | F16: 0 | G16: 0 | H16: 4034.4
A17: 43419 | B17: 11 | C17: 0 | D17: 38 | E17: 0 | F17: 0 | G17: 0 | H17: 4034.4 | I17: * 1200 22/0
A18: 43420 | B18: 0 | C18: 12 | D18: 15 | E18: 0 | F18: 0 | G18: 0 | H18: 4034.4
A19: 43421 | B19: 0 | C19: 20 | D19: 0 | E19: 0 | F19: 0 | G19: 0 | H19: 4034.4
A20: 43422 | B20: 0 | C20: 20 | D20: 0 | E20: 0 | F20: 0 | G20: 0 | H20: 4034.4
A21: 43423 | B21: 0 | C21: 20 | D21: 0 | E21: 0 | F21: 0 | G21: 0 | H21: 4034.4
A22: 43424 | B22: 0 | C22: 20 | D22: 0 | E22: 0 | F22: 0 | G22: 0 | H22: 4034.42
A23: 43425 | B23: 0 | C23: 20 | D23: 0 | E23: 0 | F23: 0 | G23: 0 | H23: 4034.42
A24: 43426 | B24: 0 | C24: 20 | D24: 0 | E24: 0.05 | F24: 0 | G24: 0 | H24: 4034.42
A25: 43427 | B25: 0 | C25: 20 | D25: 0 | E25: 0.27 | F25: 0 | G25: 0 | H25: 4034.44
A26: 43428 | B26: 0 | C26: 20 | D26: 0 | E26: 0 | F26: 0 | G26: 0 | H26: 4034.44
A27: 43429 | B27: 0 | C27: 20 | D27: 0 | E27: 0 | F27: 0 | G27: 0 | H27: 4034.44
A28: 43430 | B28: 0 | C28: 20 | D28: 0 | E28: 0 | F28: 0 | G28: 0 | H28: 4034.46
A29: 43431 | B29: 0 | C29: 20 | D29: 0 | E29: 0.17 | F29: 0 | G29: 0 | H29: 4034.48
... A32: 43434 | B32: 0 | C32: 20 | D32: 0 | E32: 0 | F32: 0 | G32: 0 | H32: 4034.52
A33: Monthly Total | B33: =SUM(B3:B32) -> 495 | C33: =SUM(C3:C32) -> 292 | D33: =SUM(D3:D32) -> 780 | E33: =SUM(E3:E32) -> 0.78 | F33: =SUM(F3:F32) -> 0 | G33: =SUM(G3:G32) -> 220
A34: WY Total | B34: =SUM(B33+'Oct 2018'!B35) -> 1047 | C34: =SUM(C33+'Oct 2018'!C35) -> 458 | D34: =SUM(D33+'Oct 2018'!D35) -> 780 | E34: =SUM(E33+'Oct 2018'!E35) -> 1.35 | F34: =SUM(F33+'Oct 2018'!F35) -> 0 | G34: =SUM(G33+'Oct 2018'!G35) -> 5180
A36: Acre Feet | B36: =SUM(B3:B32)*1.9835 -> 981.8325 | C36: =SUM(C3:C32)*1.9835 -> 579.182 | D36: =SUM(D3:D32)*1.9835 -> 1547.13
A38: WY AF Total | B38: =SUM('Oct 2018'!B39+B36) -> 2076.7245 | C38: =SUM('Oct 2018'!C39+C36) -> 908.443 | D38: =SUM('Oct 2018'!D39+D36) -> 6724.065
G40: * COMPUTATIONAL PURPOSES ONLY! Do Not Enter Data in the Red Columns
A42: *This is computation purposes only for Station 48
A43: Sta 48
F44: =SUM(24-D44) -> 24 | G44: =SUM(C44+E44) -> 0 | H44: =SUM(C44/24*D44+G44/24*F44) -> 0
F45: =SUM(24-D45) -> 24 | G45: =SUM(C45+E45) -> 0 | H45: =SUM(C45/24*D45+G45/24*F45) -> 0
F46: =SUM(24-D46) -> 24 | G46: =SUM(C46+E46) -> 0 | H46: =SUM(C46/24*D46+G46/24*F46) -> 0
...

Sheet Oct 2018
A1: DATE | B1: STATION 48 | C1: ANDERSON-ROSE | D1: J CANAL | E1: TULE LAKE PRECIP | F1: TULE LAKE SNOW | G1: D PLANT | H1: TULE LAKE ELEV. | I1: CHANGES @ STATION 48
B2: (in CFS) | C2: (in CFS) | D2: (in CFS)
A3: 43374 | B3: 13 | C3: 30 | D3: 138 | E3: 0.03 | F3: 0 | G3: 160 | H3: 4034.88 | I3: * 1200 25/0
A4: 43375 | B4: 0 | C4: 0 | D4: 131 | E4: 0.01 | F4: 0 | G4: 160 | H4: 4034.88
A5: 43376 | B5: 0 | C5: 0 | D5: 131 | E5: 0.5 | F5: 0 | G5: 160 | H5: 4034.88
A6: 43377 | B6: 0 | C6: 0 | D6: 126 | E6: 0.02 | F6: 0 | G6: 160 | H6: 4034.9
A7: 43378 | B7: 0 | C7: 0 | D7: 127 | E7: 0.01 | F7: 0 | G7: 160 | H7: 4034.9
A8: 43379 | B8: 0 | C8: 0 | D8: 128 | E8: 0 | F8: 0 | G8: 160 | H8: 4034.9
A9: 43380 | B9: 0 | C9: 0 | D9: 123 | E9: 0 | F9: 0 | G9: 160 | H9: 4034.9
A10: 43381 | B10: 31 | C10: 0 | D10: 118 | E10: 0 | F10: 0 | G10: 160 | H10: 4034.9 | I10: * 0900 0/50
A11: 43382 | B11: 27 | C11: 10 | D11: 107 | E11: 0 | F11: 0 | G11: 160 | H11: 4034.9 | I11: * 1300 50/0
A12: 43383 | B12: 0 | C12: 45 | D12: 96 | E12: 0 | F12: 0 | G12: 160 | H12: 4034.9
A13: 43384 | B13: 0 | C13: 34 | D13: 95 | E13: 0 | F13: 0 | G13: 160 | H13: 4034.9
A14: 43385 | B14: 0 | C14: 35 | D14: 63 | E14: 0 | F14: 0 | G14: 160 | H14: 4034.9
A15: 43386 | B15: 0 | C15: 12 | D15: 66 | E15: 0 | F15: 0 | G15: 160 | H15: 4034.9
A16: 43387 | B16: 0 | C16: 0 | D16: 71 | E16: 0 | F16: 0 | G16: 160 | H16: 4034.9
A17: 43388 | B17: 17 | C17: 0 | D17: 58 | E17: 0 | F17: 0 | G17: 160 | H17: 4034.9 | I17: * 0800 0/25
A18: 43389 | B18: 25 | C18: 0 | D18: 57 | E18: 0 | F18: 0 | G18: 160 | H18: 4034.89
A19: 43390 | B19: 25 | C19: 0 | D19: 92 | E19: 0 | F19: 0 | G19: 160 | H19: 4034.88
A20: 43391 | B20: 25 | C20: 0 | D20: 90 | E20: 0 | F20: 0 | G20: 160 | H20: 4034.87
A21: 43392 | B21: 12 | C21: 0 | D21: 57 | E21: 0 | F21: 0 | G21: 160 | H21: 4034.86 | I21: * 1130 25/0
A22: 43393 | B22: 0 | C22: 0 | D22: 63 | E22: 0 | F22: 0 | G22: 160 | H22: 4034.85
A23: 43394 | B23: 0 | C23: 0 | D23: 31 | E23: 0 | F23: 0 | G23: 160 | H23: 4034.84
A24: 43395 | B24: 0 | C24: 0 | D24: 47 | E24: 0 | F24: 0 | G24: 160 | H24: 4034.83
A25: 43396 | B25: 13 | C25: 0 | D25: 55 | E25: 0 | F25: 0 | G25: 160 | H25: 4034.8 | I25: * 1200 0/25
A26: 43397 | B26: 25 | C26: 0 | D26: 59 | E26: 0 | F26: 0 | G26: 160 | H26: 4034.77
A27: 43398 | B27: 39 | C27: 0 | D27: 68 | E27: 0 | F27: 0 | G27: 160 | H27: 4034.74 | I27: * 1100 25/50
A28: 43399 | B28: 50 | C28: 0 | D28: 70 | E28: 0 | F28: 0 | G28: 160 | H28: 4034.72
A29: 43400 | B29: 50 | C29: 0 | D29: 74 | E29: 0 | F29: 0 | G29: 160 | H29: 4034.66
A30: 43401 | B30: 50 | C30: 0 | D30: 72 | E30: 0 | F30: 0 | G30: 160 | H30: 4034.62
A31: 43402 | B31: 50 | C31: 0 | D31: 70 | E31: 0 | F31: 0 | G31: 160 | H31: 4034.58
A32: 43403 | B32: 50 | C32: 0 | D32: 63 | E32: 0 | F32: 0 | G32: 160 | H32: 4034.54
A33: 43404 | B33: 50 | C33: 0 | D33: 64 | E33: 0 | F33: 0 | G33: 160 | H33: 4034.51
A34: Monthly Total | B34: =SUM(B3:B33) -> 552 | C34: =SUM(C3:C33) -> 166 | D34: 0 | E34: =SUM(E3:E33) -> 0.57 | F34: =SUM(F3:F33) -> 0 | G34: =SUM(G3:G33) -> 4960
A35: WY Total | B35: =SUM(B34+'Oct 2018'!B36) -> 552 | C35: =SUM(C34+'Oct 2018'!C36) -> 166 | D35: =SUM(D34+'Oct 2018'!D36) -> 0 | E35: =SUM(E34+'Oct 2018'!E36) -> 0.57 | F35: =SUM(F34+'Oct 2018'!F36) -> 0 | G35: =SUM(G34+'Oct 2018'!G36) -> 4960
A37: Acre Feet | B37: =SUM(B3:B33)*1.9835 -> 1094.892 | C37: =SUM(C3:C33)*1.9835 -> 329.261 | D37: =SUM(D3:D33)*1.9835 -> 5176.935
A39: WY AF Total | B39: =SUM('Oct 2018'!B40+B37) -> 1094.892 | C39: =SUM('Oct 2018'!C40+C37) -> 329.261 | D39: =SUM('Oct 2018'!D40+D37) -> 5176.935
G41: * COMPUTATIONAL PURPOSES ONLY! Do Not Enter Data in the Red Columns
A43: *This is computation purposes only for Station 48
A44: Sta 48
...
