Workbook

Sheet Oct 2026
A1: DATE | B1: LRDC | C1: STATION 48 | D1: ANDERSON-ROSE | E1: J CANAL | F1: TULE LAKE PRECIP | G1: TULE LAKE SNOW | H1: D PLANT | I1: TULE LAKE ELEV. | J1: CHANGES @ STATION 48
B2: (in CFS) | C2: (in CFS) | D2: (in CFS) | E2: (in CFS) | H2: (in AF)
A3: 46296
A4: =A3+1 -> 46297
A5: =A4+1 -> 46298
A6: =A5+1 -> 46299
A7: =A6+1 -> 46300
A8: =A7+1 -> 46301
A9: =A8+1 -> 46302
A10: =A9+1 -> 46303
A11: =A10+1 -> 46304
A12: =A11+1 -> 46305
A13: =A12+1 -> 46306
A14: =A13+1 -> 46307
A15: =A14+1 -> 46308
... A31: =A30+1 -> 46324
A32: 45960
A33: 45961
A34: Monthly Total | B34: =SUM(B3:B33) -> 0 | C34: =SUM(C3:C33) -> 0 | D34: =SUM(D3:D33) -> 0 | E34: =SUM(E3:E33) -> 0 | F34: =SUM(F3:F33) -> 0 | G34: =SUM(G3:G33) -> 0 | H34: =SUM(H3:H33) -> 0
A35: WY Total | B35: =SUM(B34+'Aug 2026'!B35) -> 17333 | C35: =SUM(C34+'Aug 2026'!C35) -> 29689 | D35: =SUM(D34+'Aug 2026'!D35) -> 8715 | E35: =SUM(E34+'Aug 2026'!E35) -> 44430 | F35: =SUM(F34+'Aug 2026'!F35) -> 11.12 | G35: =SUM(G34+'Aug 2026'!G35) -> 2.5 | H35: =SUM(H34+'Aug 2026'!H35) -> 33365
A37: Acre Feet | B37: =SUM(B3:B33)*1.9835 -> 0 | C37: =SUM(C3:C33)*1.9835 -> 0 | D37: =SUM(D3:D33)*1.9835 -> 0 | E37: =SUM(E3:E33)*1.9835 -> 0
A39: WY AF Total | B39: =SUM(B37+'Aug 2026'!B39) -> 35425.31 | C39: =SUM(C37+'Aug 2026'!C39) -> 70203.999 | D39: =SUM(D37+'Aug 2026'!D39) -> 17294.136 | E39: =SUM(E37+'Aug 2026'!E39) -> 103370.1
H41: * COMPUTATIONAL PURPOSES ONLY! Do Not Enter Data in the Red Columns
A43: *This is computation purposes only for Station 48
A44: Sta 48
G45: =SUM(24-E45) -> 24 | H45: =SUM(D45+F45) -> 0 | I45: =SUM(D45/24*E45+H45/24*G45) -> 0
G46: =SUM(24-E46) -> 24 | H46: =SUM(D46+F46) -> 0 | I46: =SUM(D46/24*E46+H46/24*G46) -> 0
G47: =SUM(24-E47) -> 24 | H47: =SUM(D47+F47) -> 0 | I47: =SUM(D47/24*E47+H47/24*G47) -> 0
G48: =SUM(24-E48) -> 24 | H48: =SUM(D48+F48) -> 0 | I48: =SUM(D48/24*E48+H48/24*G48) -> 0
G49: =SUM(24-E49) -> 24 | H49: =SUM(D49+F49) -> 0 | I49: =SUM(D49/24*E49+H49/24*G49) -> 0
A51: Use for more than 1 change in a day.
A52: **Station 48: | C52: Time | D52: Current CFS | E52: Hours Run | F52: +/- cfs | G52: Sub-total cfs
G53: =SUM(D53/24*E53) -> 0
G54: =SUM(D54/24*E54) -> 0
G55: =SUM(D55/24*E55) -> 0
G56: =SUM(D56/24*E56) -> 0
G57: =SUM(D57/24*E57) -> 0
A58: Total Hours Run | E58: =SUM(E53:E57) -> 0 | F58: Total/Day cfs | G58: =SUM(G53:G57) -> 0

Sheet Sep 2026
A1: DATE | B1: LRDC | C1: STATION 48 | D1: ANDERSON-ROSE | E1: J CANAL | F1: TULE LAKE PRECIP | G1: TULE LAKE SNOW | H1: D PLANT | I1: TULE LAKE ELEV. | J1: CHANGES @ STATION 48
B2: (in CFS) | C2: (in CFS) | D2: (in CFS) | E2: (in CFS) | H2: (in AF)
A3: 46266
A4: =A3+1 -> 46267
A5: =A4+1 -> 46268
A6: =A5+1 -> 46269
A7: =A6+1 -> 46270
A8: =A7+1 -> 46271
A9: =A8+1 -> 46272
A10: =A9+1 -> 46273
A11: =A10+1 -> 46274
A12: =A11+1 -> 46275
A13: =A12+1 -> 46276
A14: =A13+1 -> 46277
A15: =A14+1 -> 46278
... A32: =A31+1 -> 46295
A33: Monthly Total | B33: =SUM(B3:B32) -> 0 | C33: =SUM(C3:C32) -> 0 | D33: =SUM(D3:D32) -> 0 | E33: =SUM(E3:E32) -> 0 | F33: =SUM(F3:F32) -> 0 | G33: =SUM(G3:G32) -> 0 | H33: =SUM(H3:H32) -> 0
A34: WY Total | B34: =SUM(B33+'Aug 2026'!B35) -> 17333 | C34: =SUM(C33+'Aug 2026'!C35) -> 29689 | D34: =SUM(D33+'Aug 2026'!D35) -> 8715 | E34: =SUM(E33+'Aug 2026'!E35) -> 44430 | F34: =SUM(F33+'Aug 2026'!F35) -> 11.12 | G34: =SUM(G33+'Aug 2026'!G35) -> 2.5 | H34: =SUM(H33+'Aug 2026'!H35) -> 33365
A36: Acre Feet | B36: =SUM(B3:B32)*1.9835 -> 0 | C36: =SUM(C3:C32)*1.9835 -> 0 | D36: =SUM(D3:D32)*1.9835 -> 0 | E36: =SUM(E3:E32)*1.9835 -> 0
A38: WY AF Total | B38: =SUM(B36+'Aug 2026'!B39) -> 35425.31 | C38: =SUM(C36+'Aug 2026'!C39) -> 70203.999 | D38: =SUM(D36+'Aug 2026'!D39) -> 17294.136 | E38: =SUM(E36+'Aug 2026'!E39) -> 103370.1
H40: * COMPUTATIONAL PURPOSES ONLY! Do Not Enter Data in the Red Columns
A42: *This is computation purposes only for Station 48
A43: Sta 48
G44: =SUM(24-E44) -> 24 | H44: =SUM(D44+F44) -> 0 | I44: =SUM(D44/24*E44+H44/24*G44) -> 0
G45: =SUM(24-E45) -> 24 | H45: =SUM(D45+F45) -> 0 | I45: =SUM(D45/24*E45+H45/24*G45) -> 0
G46: =SUM(24-E46) -> 24 | H46: =SUM(D46+F46) -> 0 | I46: =SUM(D46/24*E46+H46/24*G46) -> 0
G47: =SUM(24-E47) -> 24 | H47: =SUM(D47+F47) -> 0 | I47: =SUM(D47/24*E47+H47/24*G47) -> 0
G48: =SUM(24-E48) -> 24 | H48: =SUM(D48+F48) -> 0 | I48: =SUM(D48/24*E48+H48/24*G48) -> 0
A50: Use for more than 1 change in a day.
A51: **Station 48: | C51: Time | D51: Current CFS | E51: Hours Run | F51: +/- cfs | G51: Sub-total cfs
G52: =SUM(D52/24*E52) -> 0
G53: =SUM(D53/24*E53) -> 0
G54: =SUM(D54/24*E54) -> 0
G55: =SUM(D55/24*E55) -> 0
G56: =SUM(D56/24*E56) -> 0
A57: Total Hours Run | E57: =SUM(E52:E56) -> 0 | F57: Total/Day cfs | G57: =SUM(G52:G56) -> 0

Sheet Aug 2026
A1: DATE | B1: LRDC | C1: STATION 48 | D1: ANDERSON-ROSE | E1: J CANAL | F1: TULE LAKE PRECIP | G1: TULE LAKE SNOW | H1: D PLANT | I1: TULE LAKE ELEV. | J1: CHANGES @ STATION 48
B2: (in CFS) | C2: (in CFS) | D2: (in CFS) | E2: (in CFS) | H2: (in AF)
A3: 46235 | B3: 0 | C3: 300 | D3: 0 | E3: 259 | F3: 0 | G3: 0 | H3: 0
A4: =A3+1 -> 46236 | B4: 0 | C4: 300 | D4: 0 | E4: 282 | F4: 0 | G4: 0 | H4: 0
A5: =A4+1 -> 46237 | B5: 0 | C5: 300 | D5: 0 | E5: 274 | F5: 0 | G5: 0 | H5: 0
A6: =A5+1 -> 46238 | C6: 300 | D6: 0 | E6: 280 | F6: 0 | G6: 0 | H6: 0
A7: =A6+1 -> 46239 | C7: 300 | D7: 0 | E7: 298 | F7: 0 | G7: 0 | H7: 0
A8: =A7+1 -> 46240
A9: =A8+1 -> 46241
A10: =A9+1 -> 46242
A11: =A10+1 -> 46243
A12: =A11+1 -> 46244
A13: =A12+1 -> 46245
A14: =A13+1 -> 46246
A15: =A14+1 -> 46247
A16: =A15+1 -> 46248
A17: =A16+1 -> 46249
A18: =A17+1 -> 46250
A19: =A18+1 -> 46251
... A33: =A32+1 -> 46265
A34: Monthly Total | B34: =SUM(B3:B33) -> 0 | C34: =SUM(C3:C33) -> 1500 | D34: =SUM(D3:D33) -> 0 | E34: =SUM(E3:E33) -> 1393 | F34: =SUM(F3:F33) -> 0 | G34: =SUM(G3:G33) -> 0 | H34: =SUM(H3:H33) -> 0
A35: WY Total | B35: =SUM(B34+'Jul 2026'!B35) -> 17333 | C35: =SUM(C34+'Jul 2026'!C35) -> 29689 | D35: =SUM(D34+'Jul 2026'!D35) -> 8715 | E35: =SUM(E34+'Jul 2026'!E35) -> 44430 | F35: =SUM(F34+'Jul 2026'!F35) -> 11.12 | G35: =SUM(G34+'Jul 2026'!G35) -> 2.5 | H35: =SUM(H34+'Jul 2026'!H35) -> 33365
A37: Acre Feet | B37: =SUM(B3:B33)*1.9835 -> 0 | C37: =SUM(C3:C33)*1.9835 -> 2975.25 | D37: =SUM(D3:D33)*1.9835 -> 0 | E37: =SUM(E3:E33)*1.9835 -> 2763.0155
A39: WY AF Total | B39: =SUM(B37+'Jul 2026'!B39) -> 35425.31 | C39: =SUM(C37+'Jul 2026'!C39) -> 70203.999 | D39: =SUM(D37+'Jul 2026'!D39) -> 17294.136 | E39: =SUM(E37+'Jul 2026'!E39) -> 103370.1
H41: * COMPUTATIONAL PURPOSES ONLY! Do Not Enter Data in the Red Columns
A43: *This is computation purposes only for Station 48
A44: Sta 48
G45: =SUM(24-E45) -> 24 | H45: =SUM(D45+F45) -> 0 | I45: =SUM(D45/24*E45+H45/24*G45) -> 0
G46: =SUM(24-E46) -> 24 | H46: =SUM(D46+F46) -> 0 | I46: =SUM(D46/24*E46+H46/24*G46) -> 0
G47: =SUM(24-E47) -> 24 | H47: =SUM(D47+F47) -> 0 | I47: =SUM(D47/24*E47+H47/24*G47) -> 0
G48: =SUM(24-E48) -> 24 | H48: =SUM(D48+F48) -> 0 | I48: =SUM(D48/24*E48+H48/24*G48) -> 0
G49: =SUM(24-E49) -> 24 | H49: =SUM(D49+F49) -> 0 | I49: =SUM(D49/24*E49+H49/24*G49) -> 0
A51: Use for more than 1 change in a day.
A52: **Station 48: | C52: Time | D52: Current CFS | E52: Hours Run | F52: +/- cfs | G52: Sub-total cfs
G53: =SUM(D53/24*E53) -> 0
G54: =SUM(D54/24*E54) -> 0
G55: =SUM(D55/24*E55) -> 0
G56: =SUM(D56/24*E56) -> 0
G57: =SUM(D57/24*E57) -> 0
A58: Total Hours Run | E58: =SUM(E53:E57) -> 0 | F58: Total/Day cfs | G58: =SUM(G53:G57) -> 0

Sheet Jul 2026
A1: DATE | B1: LRDC | C1: STATION 48 | D1: ANDERSON-ROSE | E1: J CANAL | F1: TULE LAKE PRECIP | G1: TULE LAKE SNOW | H1: D PLANT | I1: TULE LAKE ELEV. | J1: CHANGES @ STATION 48
B2: (in CFS) | C2: (in CFS) | D2: (in CFS) | E2: (in CFS) | H2: (in AF)
A3: 46204 | B3: 0 | C3: 200 | D3: 0 | E3: 176 | F3: 0 | G3: 0 | H3: 0
A4: =A3+1 -> 46205 | B4: 0 | C4: 200 | D4: 0 | E4: 208 | F4: 0 | G4: 0 | H4: 0
A5: =A4+1 -> 46206 | B5: 0 | C5: 200 | D5: 0 | E5: 210 | F5: 0 | G5: 0 | H5: 0
A6: =A5+1 -> 46207 | B6: 0 | C6: 200 | D6: 0 | E6: 189 | F6: 0 | G6: 0 | H6: 0
A7: =A6+1 -> 46208 | B7: 0 | C7: 200 | D7: 0 | E7: 210 | F7: 0 | G7: 0 | H7: 0
A8: =A7+1 -> 46209 | B8: 0 | C8: 200 | D8: 0 | E8: 187 | F8: 0 | G8: 0 | H8: 0
A9: =A8+1 -> 46210 | B9: 0 | C9: 200 | D9: 0 | E9: 178 | F9: 0 | G9: 0 | H9: 0
A10: =A9+1 -> 46211 | B10: 0 | C10: 270 | D10: 0 | E10: 179 | F10: 0 | G10: 0 | H10: 0 | J10: *07:15 200/300
A11: =A10+1 -> 46212 | B11: 0 | C11: 231 | D11: 0 | E11: 180 | F11: 0 | G11: 0 | H11: 0 | J11: *07:30 300/200
A12: =A11+1 -> 46213 | B12: 0 | C12: 203 | D12: 0 | E12: 200 | F12: 0 | G12: 0 | H12: 0
A13: =A12+1 -> 46214 | B13: 0 | C13: 230 | D13: 0 | E13: 212 | F13: 0 | G13: 0 | H13: 0 | J13: *08:30 200/250
A14: =A13+1 -> 46215 | B14: 0 | C14: 250 | D14: 0 | E14: 226 | F14: 0 | G14: 0 | H14: 0
A15: =A14+1 -> 46216 | B15: 0 | C15: 281 | D15: 0 | E15: 230 | F15: 0 | G15: 0 | H15: 0 | J15: *09:00 250/300
A16: =A15+1 -> 46217 | B16: 0 | C16: 300 | D16: 0 | E16: 263 | F16: 0 | G16: 0 | H16: 0
A17: =A16+1 -> 46218 | B17: 0 | C17: 300 | D17: 0 | E17: 277 | F17: 0 | G17: 0 | H17: 0
A18: =A17+1 -> 46219 | B18: 0 | C18: 300 | D18: 0 | E18: 306 | F18: 0 | G18: 0 | H18: 0
A19: =A18+1 -> 46220 | B19: 0 | C19: 349 | D19: 0 | E19: 336 | F19: 0 | G19: 0 | H19: 0 | J19: 15:00 300/400 * 21:15 400/500
A20: =A19+1 -> 46221 | B20: 0 | C20: 431 | D20: 0 | E20: 329 | F20: 0 | G20: 0 | H20: 0 | J20: * 13:00 500/350
A21: =A20+1 -> 46222 | B21: 0 | C21: 333 | D21: 24 | E21: 340 | F21: 0 | G21: 0 | H21: 0 | J21: * 16:00 350/300
A22: =A21+1 -> 46223 | B22: 0 | C22: 300 | D22: 25 | E22: 303 | F22: 0.02 | G22: 0 | H22: 0
A23: =A22+1 -> 46224 | B23: 0 | C23: 300 | D23: 2 | E23: 294 | F23: 0 | G23: 0 | H23: 0
A24: =A23+1 -> 46225 | B24: 0 | C24: 300 | D24: 4 | E24: 293 | F24: 0 | G24: 0 | H24: 0
A25: =A24+1 -> 46226 | B25: 0 | C25: 300 | D25: 0 | E25: 297 | F25: 0 | G25: 0 | H25: 0
A26: =A25+1 -> 46227 | B26: 0 | C26: 300 | D26: 0 | E26: 299 | F26: 0 | G26: 0 | H26: 0
A27: =A26+1 -> 46228 | B27: 0 | C27: 280 | D27: 0 | E27: 289 | F27: 0 | G27: 0 | H27: 0 | J27: *300/250 14:30
A28: =A27+1 -> 46229 | B28: 0 | C28: 250 | D28: 0 | E28: 265 | F28: 0 | G28: 0 | H28: 0
A29: =A28+1 -> 46230 | B29: 0 | C29: 281 | D29: 0 | E29: 300 | F29: 0 | G29: 0 | H29: 0 | J29: * 09:15 250/300
A30: =A29+1 -> 46231 | B30: 0 | C30: 300 | D30: 0 | E30: 317 | F30: 0 | G30: 0 | H30: 0
A31: =A30+1 -> 46232 | B31: 0 | C31: 300 | D31: 0 | E31: 291 | F31: 0 | G31: 0 | H31: 0
A32: =A31+1 -> 46233 | B32: 0 | C32: 300 | D32: 0 | E32: 269 | F32: 0 | G32: 0 | H32: 0
A33: =A32+1 -> 46234 | B33: 0 | C33: 300 | D33: 0 | E33: 237 | F33: 0 | G33: 0 | H33: 0
A34: Monthly Total | B34: =SUM(B3:B33) -> 0 | C34: =SUM(C3:C33) -> 8389 | D34: =SUM(D3:D33) -> 55 | E34: =SUM(E3:E33) -> 7890 | F34: =SUM(F3:F33) -> 0.02 | G34: =SUM(G3:G33) -> 0 | H34: =SUM(H3:H33) -> 0
A35: WY Total | B35: =SUM(B34+'Jun 2026'!B34) -> 17333 | C35: =SUM(C34+'Jun 2026'!C34) -> 28189 | D35: =SUM(D34+'Jun 2026'!D34) -> 8715 | E35: =SUM(E34+'Jun 2026'!E34) -> 43037 | F35: =SUM(F34+'Jun 2026'!F34) -> 11.12 | G35: =SUM(G34+'Jun 2026'!G34) -> 2.5 | H35: =SUM(H34+'Jun 2026'!H34) -> 33365
A37: Acre Feet | B37: =SUM(B3:B33)*1.9835 -> 0 | C37: =SUM(C3:C33)*1.9835 -> 16639.582 | D37: =SUM(D3:D33)*1.9835 -> 109.0925 | E37: =SUM(E3:E33)*1.9835 -> 15649.815
A39: WY AF Total | B39: =SUM(B37+'Jun 2026'!B38) -> 35425.31 | C39: =SUM(C37+'Jun 2026'!C38) -> 67228.749 | D39: =SUM(D37+'Jun 2026'!D38) -> 17294.136 | E39: =SUM(E37+'Jun 2026'!E38) -> 100607.09
H41: * COMPUTATIONAL PURPOSES ONLY! Do Not Enter Data in the Red Columns
A43: *This is computation purposes only for Station 48
A44: Sta 48
...

Sheet Jun 2026
A1: DATE | B1: LRDC | C1: STATION 48 | D1: ANDERSON-ROSE | E1: J CANAL | F1: TULE LAKE PRECIP | G1: TULE LAKE SNOW | H1: D PLANT | I1: TULE LAKE ELEV. | J1: CHANGES @ STATION 48
B2: (in CFS) | C2: (in CFS) | D2: (in CFS) | E2: (in CFS) | H2: (in AF)
A3: 46174 | B3: 101 | C3: 0 | D3: 21 | E3: 172 | F3: 0 | G3: 0 | H3: 0
A4: =A3+1 -> 46175 | B4: 6 | C4: 0 | D4: 23 | E4: 145 | F4: 0 | G4: 0 | H4: 0
A5: =A4+1 -> 46176 | B5: 0 | C5: 0 | D5: 23 | E5: 183 | F5: 0 | G5: 0 | H5: 0
A6: =A5+1 -> 46177 | B6: 0 | C6: 0 | D6: 0 | E6: 188 | F6: 0 | G6: 0 | H6: 0
A7: =A6+1 -> 46178 | B7: 0 | C7: 2 | D7: 0 | E7: 191 | F7: 0 | G7: 0 | H7: 0 | J7: *23:00 0/50
A8: =A7+1 -> 46179 | B8: 0 | C8: 50 | D8: 0 | E8: 198 | F8: 0 | G8: 0 | H8: 0
A9: =A8+1 -> 46180 | B9: 0 | C9: 78 | D9: 0 | E9: 181 | F9: 0 | G9: 0 | H9: 0 | J9: *10:30 50/100
A10: =A9+1 -> 46181 | B10: 0 | C10: 117 | D10: 0 | E10: 193 | F10: 0 | G10: 0 | H10: 0 | J10: *14:30 100/150
A11: =A10+1 -> 46182 | B11: 0 | C11: 188 | D11: 0 | E11: 237 | F11: 0 | G11: 0 | H11: 0 | J11: *07:00 150/200 22:45 200/250
A12: =A11+1 -> 46183 | B12: 0 | C12: 244 | D12: 0 | E12: 270 | F12: 0 | G12: 0 | H12: 0 | J12: *14:30 250/300
A13: =A12+1 -> 46184 | B13: 0 | C13: 251 | D13: 0 | E13: 263 | F13: 0 | G13: 0 | H13: 0 | J13: *00:30 300/250
A14: =A13+1 -> 46185 | B14: 0 | C14: 328 | D14: 0 | E14: 317 | F14: 0 | G14: 0 | H14: 0 | J14: *10:30 300/350
A15: =A14+1 -> 46186 | B15: 0 | C15: 350 | D15: 0 | E15: 313 | F15: 0 | G15: 0 | H15: 0
A16: =A15+1 -> 46187 | B16: 0 | C16: 321 | D16: 0 | E16: 286 | F16: 0 | G16: 0 | H16: 0 | J16: *10:00 350/300
A17: =A16+1 -> 46188 | B17: 0 | C17: 300 | D17: 0 | E17: 320 | F17: 0 | G17: 0 | H17: 0
A18: =A17+1 -> 46189 | B18: 0 | C18: 300 | D18: 0 | E18: 348 | F18: 0 | G18: 0 | H18: 0
A19: =A18+1 -> 46190 | B19: 0 | C19: 367 | D19: 0 | E19: 313 | F19: 0 | G19: 0 | H19: 0 | J19: 08:00 300/400
A20: =A19+1 -> 46191 | B20: 0 | C20: 335 | D20: 0 | E20: 296 | F20: 0 | G20: 0 | H20: 0 | J20: 08:30 400/300
A21: =A20+1 -> 46192 | B21: 0 | C21: 267 | D21: 0 | E21: 275 | F21: 0.01 | G21: 0 | H21: 0 | J21: 08:00 300/250
A22: =A21+1 -> 46193 | B22: 0 | C22: 281 | D22: 0 | E22: 261 | F22: 0 | G22: 0 | H22: 0 | J22: 00:00 250/300 15:00 300/250
A23: =A22+1 -> 46194 | B23: 0 | C23: 250 | D23: 0 | E23: 235 | F23: 0 | G23: 0 | H23: 0
A24: =A23+1 -> 46195 | B24: 0 | C24: 255 | D24: 0 | E24: 231 | F24: 0 | G24: 0 | H24: 0 | J24: *21:30 250/300
A25: =A24+1 -> 46196 | B25: 0 | C25: 300 | D25: 0 | E25: 236 | F25: 0 | G25: 0 | H25: 0
A26: =A25+1 -> 46197 | B26: 0 | C26: 300 | D26: 0 | E26: 212 | F26: 0 | G26: 0 | H26: 0
A27: =A26+1 -> 46198 | B27: 0 | C27: 269 | D27: 0 | E27: 195 | F27: 0 | G27: 0 | H27: 0
A28: =A27+1 -> 46199 | B28: 0 | C28: 234 | D28: 0 | E28: 214 | F28: 0.12 | G28: 0 | H28: 0 | J28: *17:00 250/200
A29: =A28+1 -> 46200 | B29: 0 | C29: 200 | D29: 0 | E29: 213 | F29: 0 | G29: 0 | H29: 0
A30: =A29+1 -> 46201 | B30: 0 | C30: 200 | D30: 0 | E30: 221 | F30: 0 | G30: 0 | H30: 0
A31: =A30+1 -> 46202 | B31: 0 | C31: 200 | D31: 0 | E31: 216 | F31: 0 | G31: 0 | H31: 0
A32: =A31+1 -> 46203 | B32: 0 | C32: 200 | D32: 0 | E32: 179 | F32: 0 | G32: 0 | H32: 0
A33: Monthly Total | B33: =SUM(B3:B32) -> 107 | C33: =SUM(C3:C32) -> 6187 | D33: =SUM(D3:D32) -> 67 | E33: =SUM(E3:E32) -> 7102 | F33: =SUM(F3:F32) -> 0.13 | G33: =SUM(G3:G32) -> 0 | H33: =SUM(H3:H32) -> 0
A34: WY Total | B34: =SUM(B33+'May 2026'!B35) -> 17333 | C34: =SUM(C33+'May 2026'!C35) -> 19800 | D34: =SUM(D33+'May 2026'!D35) -> 8660 | E34: =SUM(E33+'May 2026'!E35) -> 35147 | F34: =SUM(F33+'May 2026'!F35) -> 11.1 | G34: =SUM(G33+'May 2026'!G35) -> 2.5 | H34: =SUM(H33+'May 2026'!H35) -> 33365
A36: Acre Feet | B36: =SUM(B3:B32)*1.9835 -> 212.2345 | C36: =SUM(C3:C32)*1.9835 -> 12271.915 | D36: =SUM(D3:D32)*1.9835 -> 132.8945 | E36: =SUM(E3:E32)*1.9835 -> 14086.817
A38: WY AF Total | B38: =SUM(B36+'May 2026'!B39) -> 35425.31 | C38: =SUM(C36+'May 2026'!C39) -> 50589.167 | D38: =SUM(D36+'May 2026'!D39) -> 17185.044 | E38: =SUM(E36+'May 2026'!E39) -> 84957.272
H40: * COMPUTATIONAL PURPOSES ONLY! Do Not Enter Data in the Red Columns
A42: *This is computation purposes only for Station 48
A43: Sta 48
G44: =SUM(24-E44) -> 24 | H44: =SUM(D44+F44) -> 0 | I44: =SUM(D44/24*E44+H44/24*G44) -> 0
...

Sheet May 2026
A1: DATE | B1: LRDC | C1: STATION 48 | D1: ANDERSON-ROSE | E1: J CANAL | F1: TULE LAKE PRECIP | G1: TULE LAKE SNOW | H1: D PLANT | I1: TULE LAKE ELEV. | J1: CHANGES @ STATION 48
B2: (in CFS) | C2: (in CFS) | D2: (in CFS) | E2: (in CFS) | H2: (in AF)
A3: 46143 | B3: 0 | C3: 368 | D3: 21 | E3: 503 | F3: 0 | G3: 0 | H3: 0 | J3: *8:30 400/350
A4: =A3+1 -> 46144 | B4: 0 | C4: 328 | D4: 18 | E4: 474 | F4: 0 | G4: 0 | H4: 0 | J4: *13:30 350/300
A5: =A4+1 -> 46145 | B5: 0 | C5: 222 | D5: 38 | E5: 420 | F5: 0.02 | G5: 0 | H5: 0 | J5: *00:30 300/250 10:00 250/200
A6: =A5+1 -> 46146 | B6: 5 | C6: 200 | D6: 2 | E6: 409 | F6: 0 | G6: 0 | H6: 0
A7: =A6+1 -> 46147 | B7: 10 | C7: 253 | D7: 0 | E7: 379 | F7: 0 | G7: 0 | H7: 0 | J7: *08:00 200/250 14:30 250/300
A8: =A7+1 -> 46148 | B8: 8 | C8: 300 | D8: 0 | E8: 391 | F8: 0 | G8: 0 | H8: 0
A9: =A8+1 -> 46149 | B9: 6 | C9: 300 | D9: 0 | E9: 386 | F9: 0 | G9: 0 | H9: 0
A10: =A9+1 -> 46150 | B10: 7 | C10: 284 | D10: 0 | E10: 370 | F10: 0 | G10: 0 | H10: 0 | J10: * 16:30 300/250
A11: =A10+1 -> 46151 | B11: 6 | C11: 250 | D11: 0 | E11: 347 | F11: 0 | G11: 0 | H11: 0
A12: =A11+1 -> 46152 | B12: 4 | C12: 213 | D12: 2 | E12: 311 | F12: 0 | G12: 0 | H12: 0 | J12: * 12:30 250/200 * 17:30 200/150
A13: =A12+1 -> 46153 | B13: 7 | C13: 163 | D13: 1 | E13: 306 | F13: 0 | G13: 0 | H13: 0 | J13: * 18:00 150/200
A14: =A13+1 -> 46154 | B14: 0 | C14: 231 | D14: 0 | E14: 334 | F14: 0 | G14: 0 | H14: 0 | J14: * 15:00 200/250 * 18:00 250/300
A15: =A14+1 -> 46155 | B15: 6 | C15: 300 | D15: 0 | E15: 360 | F15: 0 | G15: 0 | H15: 0
A16: =A15+1 -> 46156 | B16: 6 | C16: 280 | D16: 0 | E16: 375 | F16: 0 | G16: 0 | H16: 0 | J16: * 14:30 300/250
A17: =A16+1 -> 46157 | B17: 6 | C17: 250 | D17: 0 | E17: 360 | F17: 0 | G17: 0 | H17: 0
A18: =A17+1 -> 46158 | B18: 4 | C18: 279 | D18: 0 | E18: 353 | F18: 0 | G18: 0 | H18: 0 | J18: * 10:00 250/300
A19: =A18+1 -> 46159 | B19: 1 | C19: 242 | D19: 2 | E19: 325 | F19: 0 | G19: 0 | H19: 0 | J19: *08:00 300/250 12:00 250/200
A20: =A19+1 -> 46160 | B20: 2 | C20: 169 | D20: 14 | E20: 334 | F20: 0 | G20: 0 | H20: 0 | J20: *09:00 200/150
A21: =A20+1 -> 46161 | B21: 6 | C21: 169 | D21: 0 | E21: 354 | F21: 0 | G21: 0 | H21: 0 | J21: *15:00 150/200
A22: =A21+1 -> 46162 | B22: 0 | C22: 204 | D22: 0 | E22: 338 | F22: 0 | G22: 0 | H22: 0 | J22: * 22:00 200/250
A23: =A22+1 -> 46163 | B23: 0 | C23: 233 | D23: 0 | E23: 335 | F23: 0 | G23: 0 | H23: 0 | J23: *16:00 250/200
A24: =A23+1 -> 46164 | B24: 0 | C24: 200 | D24: 24 | E24: 353 | F24: 0 | G24: 0 | H24: 0 | J24: *23:15 200/175
A25: =A24+1 -> 46165 | B25: 0 | C25: 166 | D25: 27 | E25: 342 | F25: 0 | G25: 0 | H25: 0 | J25: *15:00 175/150
A26: =A25+1 -> 46166 | B26: 0 | C26: 142 | D26: 18 | E26: 340 | F26: 0.08 | G26: 0 | H26: 0 | J26: *16:00 150/125
A27: =A26+1 -> 46167 | B27: 0 | C27: 109 | D27: 10 | E27: 319 | F27: 0 | G27: 0 | H27: 0 | J27: *07:30 125/100 *23:30 100/150
A28: =A27+1 -> 46168 | B28: 0 | C28: 182 | D28: 0 | E28: 317 | F28: 0.04 | G28: 0 | H28: 0 | J28: *08:30 150/200
A29: =A28+1 -> 46169 | B29: 0 | C29: 218 | D29: 0 | E29: 305 | F29: 0.24 | G29: 0 | H29: 0 | J29: *07:00 200/250 15:30 250/200
... A31: =A30+1 -> 46171 | B31: 161 | C31: 20 | D31: 56 | E31: 253 | F31: 1.18 | G31: 0 | H31: 0 | J31: * 06:30 50/18 14:30 18/0
A32: =A31+1 -> 46172 | B32: 263 | C32: 0 | D32: 94 | E32: 246 | F32: 0 | G32: 0 | H32: 0
A33: =A32+1 -> 46173 | B33: 281 | C33: 0 | D33: 68 | E33: 209 | F33: 0 | G33: 0 | H33: 0
A34: Monthly Total | B34: =SUM(B3:B33) -> 789 | C34: =SUM(C3:C33) -> 6360 | D34: =SUM(D3:D33) -> 395 | E34: =SUM(E3:E33) -> 10732 | F34: =SUM(F3:F33) -> 3.11 | G34: =SUM(G3:G33) -> 0 | H34: =SUM(H3:H33) -> 0
A35: WY Total | B35: =SUM(B34+'Apr 2026'!B34) -> 17226 | C35: =SUM(C34+'Apr 2026'!C34) -> 13613 | D35: =SUM(D34+'Apr 2026'!D34) -> 8593 | E35: =SUM(E34+'Apr 2026'!E34) -> 28045 | F35: =SUM(F34+'Apr 2026'!F34) -> 10.97 | G35: =SUM(G34+'Apr 2026'!G34) -> 2.5 | H35: =SUM(H34+'Apr 2026'!H34) -> 33365
A37: Acre Feet | B37: =SUM(B3:B33)*1.9835 -> 1564.9815 | C37: =SUM(C3:C33)*1.9835 -> 12615.06 | D37: =SUM(D3:D33)*1.9835 -> 783.4825 | E37: =SUM(E3:E33)*1.9835 -> 21286.922
A39: WY AF Total | B39: =SUM(B37+'Apr 2026'!B38) -> 35213.075 | C39: =SUM(C37+'Apr 2026'!C38) -> 38317.253 | D39: =SUM(D37+'Apr 2026'!D38) -> 17052.149 | E39: =SUM(E37+'Apr 2026'!E38) -> 70870.455
H41: * COMPUTATIONAL PURPOSES ONLY! Do Not Enter Data in the Red Columns
A43: *This is computation purposes only for Station 48
A44: Sta 48
G45: =SUM(24-E45) -> 24 | H45: =SUM(D45+F45) -> 0 | I45: =SUM(D45/24*E45+H45/24*G45) -> 0
...

Sheet Apr 2026
A1: DATE | B1: LRDC | C1: STATION 48 | D1: ANDERSON-ROSE | E1: J CANAL | F1: TULE LAKE PRECIP | G1: TULE LAKE SNOW | H1: D PLANT | I1: TULE LAKE ELEV. | J1: CHANGES @ STATION 48
B2: (in CFS) | C2: (in CFS) | D2: (in CFS) | E2: (in CFS) | H2: (in AF)
A3: 46113 | B3: 31 | C3: 75 | D3: 0 | E3: 104 | F3: 0.02 | G3: 0 | H3: 0
A4: =A3+1 -> 46114 | B4: 32 | C4: 75 | D4: 0 | E4: 106 | F4: 0.15 | G4: 0 | H4: 0
A5: =A4+1 -> 46115 | B5: 31 | C5: 75 | D5: 0 | E5: 103 | F5: 0 | G5: 0 | H5: 0
A6: =A5+1 -> 46116 | B6: 31 | C6: 75 | D6: 0 | E6: 104 | F6: 0 | G6: 0 | H6: 0
A7: =A6+1 -> 46117 | B7: 30 | C7: 78 | D7: 0 | E7: 110 | F7: 0 | G7: 0 | H7: 0 | J7: *21:00 75/100
A8: =A7+1 -> 46118 | B8: 33 | C8: 106 | D8: 0 | E8: 110 | F8: 0 | G8: 0 | H8: 0 | J8: * 18:00 100/125
A9: =A8+1 -> 46119 | B9: 33 | C9: 125 | D9: 2 | E9: 183 | F9: 0 | G9: 0 | H9: 0
A10: =A9+1 -> 46120 | B10: 34 | C10: 170 | D10: 0 | E10: 235 | F10: 0 | G10: 0 | H10: 0 | J10: * 06:30 125/150 08:00 150/175 * 14:00 175/200
A11: =A10+1 -> 46121 | B11: 33 | C11: 224 | D11: 0 | E11: 268 | F11: 0 | G11: 0 | H11: 0 | J11: * 12:30 200/250
A12: =A11+1 -> 46122 | B12: 35 | C12: 250 | D12: 0 | E12: 240 | F12: 0.17 | G12: 0 | H12: 0
A13: =A12+1 -> 46123 | B13: 36 | C13: 229 | D13: 0 | E13: 239 | F13: 0.02 | G13: 0 | H13: 0 | J13: * 14:00 250/200
A14: =A13+1 -> 46124 | B14: 33 | C14: 200 | D14: 0 | E14: 226 | F14: 0.01 | G14: 0 | H14: 0
A15: =A14+1 -> 46125 | B15: 32 | C15: 200 | D15: 0 | E15: 227 | F15: 0 | G15: 0 | H15: 0
A16: =A15+1 -> 46126 | B16: 43 | C16: 200 | D16: 0 | E16: 241 | F16: 0 | G16: 0 | H16: 0
A17: =A16+1 -> 46127 | B17: 5 | C17: 178 | D17: 0 | E17: 225 | F17: 0.13 | G17: 0 | H17: 0 | J17: * 13:30 200/150
A18: =A17+1 -> 46128 | B18: 4 | C18: 127 | D18: 0 | E18: 212 | F18: 0.01 | G18: 0 | H18: 0 | J18: * 13:00 150/100
A19: =A18+1 -> 46129 | B19: 8 | C19: 100 | D19: 0 | E19: 226 | F19: 0 | G19: 0 | H19: 0
A20: =A19+1 -> 46130 | B20: 5 | C20: 100 | D20: 0 | E20: 243 | F20: 0 | G20: 0 | H20: 0
A21: =A20+1 -> 46131 | B21: 2 | C21: 145 | D21: 0 | E21: 262 | F21: 0 | G21: 0 | H21: 0 | J21: *11:00 100/150 *15:30 150/200
A22: =A21+1 -> 46132 | B22: 3 | C22: 219 | D22: 0 | E22: 283 | F22: 0.05 | G22: 0 | H22: 0 | J22: *15:00 200/250
A23: =A22+1 -> 46133 | B23: 2 | C23: 250 | D23: 0 | E23: 294 | F23: 0.02 | G23: 0 | H23: 0
A24: =A23+1 -> 46134 | B24: 3 | C24: 217 | D24: 0 | E24: 300 | F24: 0 | G24: 0 | H24: 0 | J24: * 08:00 250/200
A25: =A24+1 -> 46135 | B25: 7 | C25: 200 | D25: 0 | E25: 320 | F25: 0 | G25: 0 | H25: 0
A26: =A25+1 -> 46136 | B26: 3 | C26: 208 | D26: 0 | E26: 337 | F26: 0 | G26: 0 | H26: 0 | J26: *16:00 200/225
A27: =A26+1 -> 46137 | B27: 4 | C27: 225 | D27: 0 | E27: 343 | F27: 0 | G27: 0 | H27: 0
A28: =A27+1 -> 46138 | B28: 4 | C28: 234 | D28: 0 | E28: 325 | F28: 0 | G28: 0 | H28: 0 | J28: * 15:30 225/250
A29: =A28+1 -> 46139 | B29: 4 | C29: 267 | D29: 2 | E29: 364 | F29: 0 | G29: 0 | H29: 0 | J29: * 16:00 250/300
A30: =A29+1 -> 46140 | B30: 6 | C30: 353 | D30: 0 | E30: 445 | F30: 0 | G30: 0 | H30: 0 | J30: * 09:00 300/350 * 13:30 350/400
A31: =A30+1 -> 46141 | B31: 0 | C31: 400 | D31: 0 | E31: 498 | F31: 0 | G31: 0 | H31: 0
A32: =A31+1 -> 46142 | B32: 0 | C32: 400 | D32: 0 | E32: 512 | F32: 0 | G32: 0 | H32: 0
A33: Monthly Total | B33: =SUM(B3:B32) -> 527 | C33: =SUM(C3:C32) -> 5705 | D33: =SUM(D3:D32) -> 4 | E33: =SUM(E3:E32) -> 7685 | F33: =SUM(F3:F32) -> 0.58 | G33: =SUM(G3:G32) -> 0 | H33: =SUM(H3:H32) -> 0
A34: WY Total | B34: =SUM(B33+'Mar 2026'!B35) -> 16437 | C34: =SUM(C33+'Mar 2026'!C35) -> 7253 | D34: =SUM(D33+'Mar 2026'!D35) -> 8198 | E34: =SUM(E33+'Mar 2026'!E35) -> 17313 | F34: =SUM(F33+'Mar 2026'!F35) -> 7.86 | G34: =SUM(G33+'Mar 2026'!G35) -> 2.5 | H34: =SUM(H33+'Mar 2026'!H35) -> 33365
A36: Acre Feet | B36: =SUM(B3:B33)*1.9835 -> 2090.609 | C36: =SUM(C3:C33)*1.9835 -> 22631.735 | D36: =SUM(D3:D33)*1.9835 -> 15.868 | E36: =SUM(E3:E33)*1.9835 -> 30486.395
A38: WY AF Total | B38: =SUM(B36+'Mar 2026'!B39) -> 33648.094 | C38: =SUM(C36+'Mar 2026'!C39) -> 25702.193 | D38: =SUM(D36+'Mar 2026'!D39) -> 16268.667 | E38: =SUM(E36+'Mar 2026'!E39) -> 49583.533
H40: * COMPUTATIONAL PURPOSES ONLY! Do Not Enter Data in the Red Columns
A42: *This is computation purposes only for Station 48
A43: Sta 48
G44: =SUM(24-E44) -> 24 | H44: =SUM(D44+F44) -> 0 | I44: =SUM(D44/24*E44+H44/24*G44) -> 0
...

Sheet Mar 2026
A1: DATE | B1: LRDC | C1: STATION 48 | D1: ANDERSON-ROSE | E1: J CANAL | F1: TULE LAKE PRECIP | G1: TULE LAKE SNOW | H1: D PLANT | I1: TULE LAKE ELEV. | J1: CHANGES @ STATION 48
B2: (in CFS) | C2: (in CFS) | D2: (in CFS) | E2: (in CFS) | H2: (in AF)
A3: 46082 | B3: 256 | C3: 0 | D3: 0 | E3: 38 | F3: 0 | G3: 0 | H3: 0
A4: =A3+1 -> 46083 | B4: 220 | C4: 0 | D4: 0 | E4: 38 | F4: 0.1 | G4: 0 | H4: 0
A5: =A4+1 -> 46084 | B5: 178 | C5: 0 | D5: 0 | E5: 38 | F5: 0 | G5: 0 | H5: 0
A6: =A5+1 -> 46085 | B6: 148 | C6: 0 | D6: 0 | E6: 38 | F6: 0.08 | G6: 0 | H6: 0
A7: =A6+1 -> 46086 | B7: 160 | C7: 0 | D7: 0 | E7: 38 | F7: 0.07 | G7: 0 | H7: 0
A8: =A7+1 -> 46087 | B8: 158 | C8: 0 | D8: 0 | E8: 38 | F8: 0.01 | G8: 0 | H8: 0
A9: =A8+1 -> 46088 | B9: 148 | C9: 0 | D9: 0 | E9: 37 | F9: 0 | G9: 0 | H9: 0
A10: =A9+1 -> 46089 | B10: 137 | C10: 0 | D10: 0 | E10: 37 | F10: 0 | G10: 0 | H10: 0
A11: =A10+1 -> 46090 | B11: 128 | C11: 0 | D11: 0 | E11: 37 | F11: T | G11: 0 | H11: 0
A12: =A11+1 -> 46091 | B12: 123 | C12: 0 | D12: 0 | E12: 37 | F12: 0 | G12: 0 | H12: 0
A13: =A12+1 -> 46092 | B13: 113 | C13: 0 | D13: 0 | E13: 37 | F13: 0 | G13: 0 | H13: 0
A14: =A13+1 -> 46093 | B14: 109 | C14: 0 | D14: 0 | E14: 36 | F14: 0 | G14: 0 | H14: 0
A15: =A14+1 -> 46094 | B15: 110 | C15: 0 | D15: 0 | E15: 36 | F15: 0 | G15: 0 | H15: 0
A16: =A15+1 -> 46095 | B16: 68 | C16: 0 | D16: 0 | E16: 36 | F16: 0 | G16: 0 | H16: 0
A17: =A16+1 -> 46096 | B17: 94 | C17: 0 | D17: 0 | E17: 36 | F17: 0 | G17: 0 | H17: 0
A18: =A17+1 -> 46097 | B18: 99 | C18: 9 | D18: 0 | E18: 36 | F18: 0 | G18: 0 | H18: 0 | J18: * 15:30 0/25
A19: =A18+1 -> 46098 | B19: 100 | C19: 25 | D19: 0 | E19: 47 | F19: 0 | G19: 0 | H19: 0
A20: =A19+1 -> 46099 | B20: 101 | C20: 25 | D20: 0 | E20: 34 | F20: 0 | G20: 0 | H20: 0
A21: =A20+1 -> 46100 | B21: 103 | C21: 25 | D21: 0 | E21: 31 | F21: 0 | G21: 0 | H21: 0
A22: =A21+1 -> 46101 | B22: 99 | C22: 25 | D22: 0 | E22: 39 | F22: 0 | G22: 0 | H22: 0
A23: =A22+1 -> 46102 | B23: 97 | C23: 25 | D23: 0 | E23: 31 | F23: 0 | G23: 0 | H23: 0
A24: =A23+1 -> 46103 | B24: 97 | C24: 32 | D24: 0 | E24: 41 | F24: 0 | G24: 0 | H24: 0 | J24: *18:00 25/50
A25: =A24+1 -> 46104 | B25: 93 | C25: 50 | D25: 0 | E25: 62 | F25: 0 | G25: 0 | H25: 0
A26: =A25+1 -> 46105 | B26: 78 | C26: 66 | D26: 0 | E26: 85 | F26: 0 | G26: 0 | H26: 0 | J26: * 08:30 50/75
A27: =A26+1 -> 46106 | B27: 45 | C27: 75 | D27: 0 | E27: 107 | F27: 0 | G27: 0 | H27: 0
A28: =A27+1 -> 46107 | B28: 19 | C28: 75 | D28: 0 | E28: 104 | F28: 0 | G28: 0 | H28: 0
A29: =A28+1 -> 46108 | B29: 20 | C29: 75 | D29: 0 | E29: 106 | F29: 0 | G29: 0 | H29: 0
A30: =A29+1 -> 46109 | B30: 16 | C30: 75 | D30: 0 | E30: 106 | F30: 0 | G30: 0 | H30: 0
A31: =A30+1 -> 46110 | B31: 17 | C31: 75 | D31: 0 | E31: 107 | F31: 0 | G31: 0 | H31: 0
A32: =A31+1 -> 46111 | B32: 22 | C32: 75 | D32: 0 | E32: 109 | F32: T | G32: 0 | H32: 0
A33: =A32+1 -> 46112 | B33: 28 | C33: 75 | D33: 0 | E33: 108 | F33: 0.07 | G33: 0 | H33: 0
A34: Monthly Total | B34: =SUM(B3:B33) -> 3184 | C34: =SUM(C3:C33) -> 807 | D34: =SUM(D3:D33) -> 0 | E34: =SUM(E3:E33) -> 1710 | F34: =SUM(F3:F33) -> 0.33 | G34: =SUM(G3:G33) -> 0 | H34: =SUM(H3:H33) -> 0
A35: WY Total | B35: =SUM(B34+'Feb 2026'!B33) -> 15910 | C35: =SUM(C34+'Feb 2026'!C33) -> 1548 | D35: =SUM(D34+'Feb 2026'!D33) -> 8194 | E35: =SUM(E34+'Feb 2026'!E33) -> 9628 | F35: =SUM(F34+'Feb 2026'!F33) -> 7.28 | G35: =SUM(G34+'Feb 2026'!G33) -> 2.5 | H35: =SUM(H34+'Feb 2026'!H33) -> 33365
A37: Acre Feet | B37: =SUM(B3:B33)*1.9835 -> 6315.464 | C37: =SUM(C3:C33)*1.9835 -> 1600.6845 | D37: =SUM(D3:D33)*1.9835 -> 0 | E37: =SUM(E3:E33)*1.9835 -> 3391.785
A39: WY AF Total | B39: =SUM(B37+'Feb 2026'!B37) -> 31557.485 | C39: =SUM(C37+'Feb 2026'!C37) -> 3070.458 | D39: =SUM(D37+'Feb 2026'!D37) -> 16252.799 | E39: =SUM(E37+'Feb 2026'!E37) -> 19097.138
H41: * COMPUTATIONAL PURPOSES ONLY! Do Not Enter Data in the Red Columns
A43: *This is computation purposes only for Station 48
A44: Sta 48
...

Sheet Feb 2026
A1: DATE | B1: LRDC | C1: STATION 48 | D1: ANDERSON-ROSE | E1: J CANAL | F1: TULE LAKE PRECIP | G1: TULE LAKE SNOW | H1: D PLANT | I1: TULE LAKE ELEV. | J1: CHANGES @ STATION 48
B2: (in CFS) | C2: (in CFS) | D2: (in CFS) | E2: (in CFS) | H2: (in AF)
A3: 46054 | B3: 101 | C3: 0 | D3: 20 | E3: 0 | F3: 0 | G3: 0 | H3: 160
A4: =A3+1 -> 46055 | B4: 101 | C4: 0 | D4: 20 | E4: 0 | F4: 0 | G4: 0 | H4: 160
A5: =A4+1 -> 46056 | B5: 101 | C5: 0 | D5: 20 | E5: 0 | F5: 0 | G5: 0 | H5: 160
A6: =A5+1 -> 46057 | B6: 99 | C6: 0 | D6: 20 | E6: 0 | F6: 0 | G6: 0 | H6: 160
A7: =A6+1 -> 46058 | B7: 99 | C7: 0 | D7: 20 | E7: 0 | F7: 0 | G7: 0 | H7: 160
A8: =A7+1 -> 46059 | B8: 100 | C8: 0 | D8: 20 | E8: 0 | F8: 0 | G8: 0 | H8: 160
A9: =A8+1 -> 46060 | B9: 99 | C9: 0 | D9: 20 | E9: 0 | F9: 0 | G9: 0 | H9: 160
A10: =A9+1 -> 46061 | B10: 101 | C10: 0 | D10: 20 | E10: 0 | F10: 0 | G10: 0 | H10: 160
A11: =A10+1 -> 46062 | B11: 102 | C11: 0 | D11: 20 | E11: 0 | F11: 0.2 | G11: 0 | H11: 160
A12: =A11+1 -> 46063 | B12: 104 | C12: 0 | D12: 20 | E12: 0 | F12: T | G12: 0 | H12: 160
A13: =A12+1 -> 46064 | B13: 106 | C13: 0 | D13: 20 | E13: 0 | F13: 0.09 | G13: 0 | H13: 160
A14: =A13+1 -> 46065 | B14: 104 | C14: 0 | D14: 20 | E14: 0 | F14: 0 | G14: 0 | H14: 160
A15: =A14+1 -> 46066 | B15: 106 | C15: 0 | D15: 20 | E15: 0 | F15: 0 | G15: 0 | H15: 160
A16: =A15+1 -> 46067 | B16: 106 | C16: 0 | D16: 20 | E16: 0 | F16: 0 | G16: 0 | H16: 160
A17: =A16+1 -> 46068 | B17: 107 | C17: 0 | D17: 20 | E17: 0 | F17: 0 | G17: 0 | H17: 160
A18: =A17+1 -> 46069 | B18: 102 | C18: 0 | D18: 20 | E18: 0 | F18: 0 | G18: 0 | H18: 160
A19: =A18+1 -> 46070 | B19: 98 | C19: 0 | D19: 20 | E19: 0 | F19: 0.26 | G19: 2.5 | H19: 57 | J19: 08:33 D-Plant off
A20: =A19+1 -> 46071 | B20: 95 | C20: 0 | D20: 20 | E20: 0 | F20: 0.01 | G20: 0 | H20: 0
A21: =A20+1 -> 46072 | B21: 95 | C21: 0 | D21: 20 | E21: 0 | F21: 0.15 | G21: 0 | H21: 0
A22: =A21+1 -> 46073 | B22: 100 | C22: 0 | D22: 10 | E22: 9 | F22: 0 | G22: 0 | H22: 0
A23: =A22+1 -> 46074 | B23: 96 | C23: 0 | D23: 0 | E23: 18 | F23: 0 | G23: 0 | H23: 0
A24: =A23+1 -> 46075 | B24: 108 | C24: 0 | D24: 0 | E24: 18 | F24: 0 | G24: 0 | H24: 0
A25: =A24+1 -> 46076 | B25: 106 | C25: 0 | D25: 0 | E25: 18 | F25: 0 | G25: 0 | H25: 0
A26: =A25+1 -> 46077 | B26: 106 | C26: 0 | D26: 0 | E26: 18 | F26: 0.54 | G26: 0 | H26: 0
A27: =A26+1 -> 46078 | B27: 695 | C27: 0 | D27: 0 | E27: 18 | F27: 0.01 | G27: 0 | H27: 0
A28: =A27+1 -> 46079 | B28: 1005 | C28: 0 | D28: 1 | E28: 30 | F28: 0 | G28: 0 | H28: 0
A29: =A28+1 -> 46080 | B29: 477 | C29: 0 | D29: 2 | E29: 38 | F29: 0.05 | G29: 0 | H29: 0
A30: =A29+1 -> 46081 | B30: 287 | C30: 0 | D30: 0 | E30: 38 | F30: 0 | G30: 0 | H30: 0
A31: =A30+1 -> 46082
A32: Monthly Total | B32: =SUM(B3:B31) -> 4906 | C32: =SUM(C3:C31) -> 0 | D32: =SUM(D3:D31) -> 393 | E32: =SUM(E3:E31) -> 205 | F32: =SUM(F3:F31) -> 1.31 | G32: =SUM(G3:G31) -> 2.5 | H32: =SUM(H3:H31) -> 2617
A33: WY Total | B33: =SUM(B32+'Jan 2026'!B35) -> 12726 | C33: =SUM(C32+'Jan 2026'!C35) -> 741 | D33: =SUM(D32+'Jan 2026'!D35) -> 8194 | E33: =SUM(E32+'Jan 2026'!E35) -> 7918 | F33: =SUM(F32+'Jan 2026'!F35) -> 6.95 | G33: =SUM(G32+'Jan 2026'!G35) -> 2.5 | H33: =SUM(H32+'Jan 2026'!H35) -> 33365
A35: Acre Feet | B35: =SUM(B3:B31)*1.9835 -> 9731.051 | C35: =SUM(C3:C31)*1.9835 -> 0 | D35: =SUM(D3:D31)*1.9835 -> 779.5155 | E35: =SUM(E3:E31)*1.9835 -> 406.6175
A37: WY AF Total | B37: =SUM(B35+'Jan 2026'!B39) -> 25242.021 | C37: =SUM(C35+'Jan 2026'!C39) -> 1469.7735 | D37: =SUM(D35+'Jan 2026'!D39) -> 16252.799 | E37: =SUM(E35+'Jan 2026'!E39) -> 15705.353
H39: * COMPUTATIONAL PURPOSES ONLY! Do Not Enter Data in the Red Columns
A41: *This is computation purposes only for Station 48
A42: Sta 48
G43: =SUM(24-E43) -> 24 | H43: =SUM(D43+F43) -> 0 | I43: =SUM(D43/24*E43+H43/24*G43) -> 0
G44: =SUM(24-E44) -> 24 | H44: =SUM(D44+F44) -> 0 | I44: =SUM(D44/24*E44+H44/24*G44) -> 0
...

Sheet Jan 2026
A1: DATE | B1: LRDC | C1: STATION 48 | D1: ANDERSON-ROSE | E1: J CANAL | F1: TULE LAKE PRECIP | G1: TULE LAKE SNOW | H1: D PLANT | I1: TULE LAKE ELEV. | J1: CHANGES @ STATION 48
B2: (in CFS) | C2: (in CFS) | D2: (in CFS) | E2: (in CFS) | H2: (in AF)
A3: 46023 | B3: 172 | C3: 0 | D3: 40 | E3: 0 | F3: 0 | G3: 0 | H3: 450
A4: =A3+1 -> 46024 | B4: 184 | C4: 0 | D4: 40 | E4: 0 | F4: 0 | G4: 0 | H4: 450
A5: =A4+1 -> 46025 | B5: 217 | C5: 0 | D5: 40 | E5: 0 | F5: 0 | G5: 0 | H5: 450
A6: =A5+1 -> 46026 | B6: 236 | C6: 0 | D6: 43 | E6: 0 | F6: 0 | G6: 0 | H6: 450
A7: =A6+1 -> 46027 | B7: 323 | C7: 0 | D7: 57 | E7: 0 | F7: 1 | G7: 0 | H7: 449
A8: =A7+1 -> 46028 | B8: 401 | C8: 0 | D8: 63 | E8: 0 | F8: T | G8: 0 | H8: 449
A9: =A8+1 -> 46029 | B9: 353 | C9: 0 | D9: 56 | E9: 0 | F9: T | G9: 0 | H9: 449
A10: =A9+1 -> 46030 | B10: 318 | C10: 0 | D10: 50 | E10: 0 | F10: 0.05 | G10: 0 | H10: 449
A11: =A10+1 -> 46031 | B11: 317 | C11: 0 | D11: 51 | E11: 0 | F11: 0 | G11: 0 | H11: 449
A12: =A11+1 -> 46032 | B12: 387 | C12: 0 | D12: 42 | E12: 0 | F12: 0 | G12: 0 | H12: 449
A13: =A12+1 -> 46033 | B13: 173 | C13: 0 | D13: 40 | E13: 0 | F13: 0 | G13: 0 | H13: 449
A14: =A13+1 -> 46034 | B14: 126 | C14: 0 | D14: 40 | E14: 0 | F14: 0 | G14: 0 | H14: 449
A15: =A14+1 -> 46035 | B15: 129 | C15: 0 | D15: 40 | E15: 0 | F15: 0 | G15: 0 | H15: 449
A16: =A15+1 -> 46036 | B16: 129 | C16: 0 | D16: 40 | E16: 0 | F16: 0.02 | G16: 0 | H16: 449
A17: =A16+1 -> 46037 | B17: 129 | C17: 0 | D17: 40 | E17: 0 | F17: 0 | G17: 0 | H17: 449
A18: =A17+1 -> 46038 | B18: 120 | C18: 0 | D18: 42 | E18: 0 | F18: T | G18: 0 | H18: 449
A19: =A18+1 -> 46039 | B19: 119 | C19: 0 | D19: 41 | E19: 0 | F19: 0 | G19: 0 | H19: 449
A20: =A19+1 -> 46040 | B20: 119 | C20: 0 | D20: 40 | E20: 0 | F20: 0 | G20: 0 | H20: 449
A21: =A20+1 -> 46041 | B21: 114 | C21: 0 | D21: 40 | E21: 0 | F21: 0 | G21: 0 | H21: 449
A22: =A21+1 -> 46042 | B22: 114 | C22: 0 | D22: 40 | E22: 0 | F22: 0 | G22: 0 | H22: 388 | J22: D-Plant 1 unit off at 09:40
A23: =A22+1 -> 46043 | B23: 90 | C23: 0 | D23: 40 | E23: 0 | F23: 0.01 | G23: 0 | H23: 294
A24: =A23+1 -> 46044 | B24: 86 | C24: 0 | D24: 40 | E24: 0 | F24: 0 | G24: 0 | H24: 294
A25: =A24+1 -> 46045 | B25: 98 | C25: 0 | D25: 40 | E25: 0 | F25: 0 | G25: 0 | H25: 294
A26: =A25+1 -> 46046 | B26: 98 | C26: 0 | D26: 40 | E26: 0 | F26: 0 | G26: 0 | H26: 294
A27: =A26+1 -> 46047 | B27: 101 | C27: 0 | D27: 40 | E27: 0 | F27: 0 | G27: 0 | H27: 294
A28: =A27+1 -> 46048 | B28: 99 | C28: 0 | D28: 40 | E28: 0 | F28: 0 | G28: 0 | H28: 300
A29: =A28+1 -> 46049 | B29: 100 | C29: 0 | D29: 40 | E29: 0 | F29: T | G29: 0 | H29: 300
A30: =A29+1 -> 46050 | B30: 96 | C30: 0 | D30: 32 | E30: 0 | F30: 0 | G30: 0 | H30: 300
A31: =A30+1 -> 46051 | B31: 94 | C31: 0 | D31: 20 | E31: 0 | F31: 0 | G31: 0 | H31: 300
A32: =A31+1 -> 46052 | B32: 100 | C32: 0 | D32: 20 | E32: 0 | F32: 0 | G32: 0 | H32: 209 | J32: D-Plant 1 unti off at 08:30
A33: =A32+1 -> 46053 | B33: 101 | C33: 0 | D33: 20 | E33: 0 | F33: 0 | G33: 0 | H33: 160
A34: Monthly Total | B34: =SUM(B3:B33) -> 5243 | C34: =SUM(C3:C33) -> 0 | D34: =SUM(D3:D33) -> 1257 | E34: =SUM(E3:E33) -> 0 | F34: =SUM(F3:F33) -> 1.08 | G34: =SUM(G3:G33) -> 0 | H34: =SUM(H3:H33) -> 11962
A35: WY Total | B35: =SUM(B34+'Dec 2025'!B35) -> 7820 | C35: =SUM(C34+'Dec 2025'!C35) -> 741 | D35: =SUM(D34+'Dec 2025'!D35) -> 7801 | E35: =SUM(E34+'Dec 2025'!E35) -> 7713 | F35: =SUM(F34+'Dec 2025'!F35) -> 5.64 | G35: =SUM(G34+'Dec 2025'!G35) -> 0 | H35: =SUM(H34+'Dec 2025'!H35) -> 30748
A37: Acre Feet | B37: =SUM(B3:B33)*1.9835 -> 10399.49 | C37: =SUM(C3:C33)*1.9835 -> 0 | D37: =SUM(D3:D33)*1.9835 -> 2493.2595 | E37: =SUM(E3:E33)*1.9835 -> 0
A39: WY AF Total | B39: =SUM(B37+'Dec 2025'!B39) -> 15510.97 | C39: =SUM(C37+'Dec 2025'!C39) -> 1469.7735 | D39: =SUM(D37+'Dec 2025'!D39) -> 15473.284 | E39: =SUM(E37+'Dec 2025'!E39) -> 15298.735
H41: * COMPUTATIONAL PURPOSES ONLY! Do Not Enter Data in the Red Columns
A43: *This is computation purposes only for Station 48
A44: Sta 48
...

Sheet Dec 2025
A1: DATE | B1: LRDC | C1: STATION 48 | D1: ANDERSON-ROSE | E1: J CANAL | F1: TULE LAKE PRECIP | G1: TULE LAKE SNOW | H1: D PLANT | I1: TULE LAKE ELEV. | J1: CHANGES @ STATION 48
B2: (in CFS) | C2: (in CFS) | D2: (in CFS) | E2: (in CFS) | H2: (in AF)
A3: 45992 | B3: 0 | C3: 0 | D3: 30 | E3: 78 | F3: 0 | G3: 0 | H3: 248 | J3: 8:50 2nd D-plant started
A4: =A3+1 -> 45993 | B4: 0 | C4: 0 | D4: 29 | E4: 78 | F4: 0 | G4: 0 | H4: 297
A5: =A4+1 -> 45994 | B5: 0 | C5: 0 | D5: 58 | E5: 52 | F5: 0 | G5: 0 | H5: 300
A6: =A5+1 -> 45995 | B6: 0 | C6: 0 | D6: 92 | E6: 0 | F6: 0 | G6: 0 | H6: 300
A7: =A6+1 -> 45996 | B7: 0 | C7: 0 | D7: 91 | E7: 0 | F7: 0 | G7: 0 | H7: 300
A8: =A7+1 -> 45997 | B8: 0 | C8: 0 | D8: 84 | E8: 0 | F8: 0 | G8: 0 | H8: 300
A9: =A8+1 -> 45998 | B9: 0 | C9: 0 | D9: 81 | E9: 0 | F9: 0 | G9: 0 | H9: 300
A10: =A9+1 -> 45999 | B10: 0 | C10: 0 | D10: 80 | E10: 0 | F10: T | G10: 0 | H10: 300
A11: =A10+1 -> 46000 | B11: 0 | C11: 0 | D11: 80 | E11: 0 | F11: 0 | G11: 0 | H11: 300
A12: =A11+1 -> 46001 | B12: 0 | C12: 0 | D12: 80 | E12: 0 | F12: 0 | G12: 0 | H12: 300
A13: =A12+1 -> 46002 | B13: 0 | C13: 0 | D13: 80 | E13: 0 | F13: 0 | G13: 0 | H13: 300
A14: =A13+1 -> 46003 | B14: 0 | C14: 0 | D14: 55 | E14: 0 | F14: 0 | G14: 0 | H14: 300
A15: =A14+1 -> 46004 | B15: 0 | C15: 0 | D15: 40 | E15: 0 | F15: 0 | G15: 0 | H15: 300
A16: =A15+1 -> 46005 | B16: 0 | C16: 0 | D16: 40 | E16: 0 | F16: 0 | G16: 0 | H16: 300
A17: =A16+1 -> 46006 | B17: 0 | C17: 0 | D17: 58 | E17: 0 | F17: T | G17: 0 | H17: 198 | J17: 1 D-plant off at 08:45
A18: =A17+1 -> 46007 | B18: 0 | C18: 0 | D18: 86 | E18: 0 | F18: 0.18 | G18: 0 | H18: 141
A19: =A18+1 -> 46008 | B19: 0 | C19: 0 | D19: 90 | E19: 0 | F19: 0.44 | G19: 0 | H19: 141
A20: =A19+1 -> 46009 | B20: 0 | C20: 0 | D20: 116 | E20: 0 | F20: 0.01 | G20: 0 | H20: 141
A21: =A20+1 -> 46010 | B21: 0 | C21: 0 | D21: 143 | E21: 0 | F21: 0 | G21: 0 | H21: 141
A22: =A21+1 -> 46011 | B22: 0 | C22: 0 | D22: 150 | E22: 0 | F22: 0 | G22: 0 | H22: 141
A23: =A22+1 -> 46012 | B23: 0 | C23: 0 | D23: 184 | E23: 0 | F23: 0 | G23: 0 | H23: 141
A24: =A23+1 -> 46013 | B24: 0 | C24: 0 | D24: 385 | E24: 0 | F24: 1.02 | G24: 0 | H24: 141
A25: =A24+1 -> 46014 | B25: 69 | C25: 0 | D25: 584 | E25: 0 | F25: 0.1 | G25: 0 | H25: 141
A26: =A25+1 -> 46015 | B26: 156 | C26: 0 | D26: 421 | E26: 0 | F26: 0 | G26: 0 | H26: 141
A27: =A26+1 -> 46016 | B27: 403 | C27: 0 | D27: 184 | E27: 0 | F27: 0 | G27: 0 | H27: 141
A28: =A27+1 -> 46017 | B28: 423 | C28: 0 | D28: 316 | E28: 0 | F28: 0 | G28: 0 | H28: 231 | J28: 10:30 2nd D-plant started
A29: =A28+1 -> 46018 | B29: 405 | C29: 0 | D29: 140 | E29: 0 | F29: 0 | G29: 0 | H29: 300
A30: =A29+1 -> 46019 | B30: 479 | C30: 0 | D30: 86 | E30: 0 | F30: 0 | G30: 0 | H30: 300
A31: =A30+1 -> 46020 | B31: 252 | C31: 0 | D31: 55 | E31: 0 | F31: 1.28 | G31: 0 | H31: 300
A32: =A31+1 -> 46021 | B32: 163 | C32: 0 | D32: 40 | E32: 0 | F32: 0 | G32: 0 | H32: 392 | J32: 08:50 3rd D-plant started
A33: =A32+1 -> 46022 | B33: 156 | C33: 0 | D33: 40 | E33: 0 | F33: 0 | G33: 0 | H33: 450
A34: Monthly Total | B34: =SUM(B3:B33) -> 2506 | C34: =SUM(C3:C33) -> 0 | D34: =SUM(D3:D33) -> 3998 | E34: =SUM(E3:E33) -> 208 | F34: =SUM(F3:F33) -> 3.03 | G34: =SUM(G3:G33) -> 0 | H34: =SUM(H3:H33) -> 7726
A35: WY Total | B35: =SUM(B34+'Nov 2025'!B34) -> 2577 | C35: =SUM(C34+'Nov 2025'!C34) -> 741 | D35: =SUM(D34+'Nov 2025'!D34) -> 6544 | E35: =SUM(E34+'Nov 2025'!E34) -> 7713 | F35: =SUM(F34+'Nov 2025'!F34) -> 4.56 | G35: =SUM(G34+'Nov 2025'!G34) -> 0 | H35: =SUM(H34+'Nov 2025'!H34) -> 18786
A37: Acre Feet | B37: =SUM(B3:B33)*1.9835 -> 4970.651 | C37: =SUM(C3:C33)*1.9835 -> 0 | D37: =SUM(D3:D33)*1.9835 -> 7930.033 | E37: =SUM(E3:E33)*1.9835 -> 412.568
A39: WY AF Total | B39: =SUM('Nov 2025'!B38+B37) -> 5111.4795 | C39: =SUM('Nov 2025'!C38+C37) -> 1469.7735 | D39: =SUM('Nov 2025'!D38+D37) -> 12980.024 | E39: =SUM('Nov 2025'!E38+E37) -> 15298.735
H41: * COMPUTATIONAL PURPOSES ONLY! Do Not Enter Data in the Red Columns
A43: *This is computation purposes only for Station 48
A44: Sta 48
...

Sheet Nov 2025
A1: DATE | B1: LRDC | C1: STATION 48 | D1: ANDERSON-ROSE | E1: J CANAL | F1: TULE LAKE PRECIP | G1: TULE LAKE SNOW | H1: D PLANT | I1: TULE LAKE ELEV. | J1: CHANGES @ STATION 48
B2: (in CFS) | C2: (in CFS) | D2: (in CFS) | E2: (in CFS) | H2: (in AF)
A3: 45962 | B3: 0 | C3: 25 | D3: 0 | E3: 154 | F3: T | G3: 0 | H3: 40 | J3: D Plant off a 06:00
A4: =A3+1 -> 45963 | B4: 0 | C4: 25 | D4: 0 | E4: 146 | F4: 0 | G4: 0 | H4: 0
A5: =A4+1 -> 45964 | B5: 0 | C5: 25 | D5: 0 | E5: 111 | F5: T | G5: 0 | H5: 22 | J5: Started 1 D at 11:00 Dplant off at 14:15
A6: =A5+1 -> 45965 | B6: 0 | C6: 25 | D6: 0 | E6: 123 | F6: T | G6: 0 | H6: 0
A7: =A6+1 -> 45966 | B7: 0 | C7: 15 | D7: 15 | E7: 146 | F7: 0.35 | G7: 0 | H7: 0 | J7: 14:00 25/0
A8: =A7+1 -> 45967 | B8: 0 | C8: 0 | D8: 70 | E8: 152 | F8: 0.02 | G8: 0 | H8: 105 | J8: Started 1 D plant 08:30
A9: =A8+1 -> 45968 | B9: 0 | C9: 0 | D9: 56 | E9: 155 | F9: 0.12 | G9: 0 | H9: 160
A10: =A9+1 -> 45969 | B10: 0 | C10: 0 | D10: 54 | E10: 152 | F10: 0 | G10: 0 | H10: 160
A11: =A10+1 -> 45970 | B11: 0 | C11: 0 | D11: 33 | E11: 142 | F11: 0 | G11: 0 | H11: 160
A12: =A11+1 -> 45971 | B12: 0 | C12: 31 | D12: 23 | E12: 142 | F12: 0 | G12: 0 | H12: 160 | J12: *09:00 0/50
A13: =A12+1 -> 45972 | B13: 0 | C13: 48 | D13: 49 | E13: 140 | F13: 0.02 | G13: 0 | H13: 160
A14: =A13+1 -> 45973 | B14: 0 | C14: 48 | D14: 61 | E14: 143 | F14: 0 | G14: 0 | H14: 160
A15: =A14+1 -> 45974 | B15: 0 | C15: 60 | D15: 81 | E15: 120 | F15: 0.01 | G15: 0 | H15: 155 | J15: * 09:30 50/100 * 16:30 100/50
A16: =A15+1 -> 45975 | B16: 0 | C16: 44 | D16: 103 | E16: 93 | F16: 0 | G16: 0 | H16: 160
A17: =A16+1 -> 45976 | B17: 0 | C17: 42 | D17: 104 | E17: 99 | F17: 0 | G17: 0 | H17: 160
A18: =A17+1 -> 45977 | B18: 0 | C18: 40 | D18: 72 | E18: 101 | F18: 0 | G18: 0 | H18: 160
A19: =A18+1 -> 45978 | B19: 0 | C19: 51 | D19: 56 | E19: 79 | F19: 0.05 | G19: 0 | H19: 208 | J19: 2nd D plant at 15:30
A20: =A19+1 -> 45979 | B20: 0 | C20: 55 | D20: 74 | E20: 79 | F20: 0 | G20: 0 | H20: 243
A21: =A20+1 -> 45980 | B21: 0 | C21: 33 | D21: 63 | E21: 79 | F21: 0 | G21: 0 | H21: 300
A22: =A21+1 -> 45981 | B22: 0 | C22: 0 | D22: 48 | E22: 79 | F22: 0.08 | G22: 0 | H22: 248
A23: =A22+1 -> 45982 | B23: 0 | C23: 0 | D23: 43 | E23: 78 | F23: 0 | G23: 0 | H23: 300
A24: =A23+1 -> 45983 | B24: 0 | C24: 0 | D24: 32 | E24: 78 | F24: 0 | G24: 0 | H24: 300
A25: =A24+1 -> 45984 | B25: 0 | C25: 0 | D25: 25 | E25: 78 | F25: 0 | G25: 0 | H25: 300
A26: =A25+1 -> 45985 | B26: 0 | C26: 0 | D26: 22 | E26: 78 | F26: T | G26: 0 | H26: 300
A27: =A26+1 -> 45986 | B27: 0 | C27: 0 | D27: 21 | E27: 78 | F27: 0 | G27: 0 | H27: 300
A28: =A27+1 -> 45987 | B28: 0 | C28: 0 | D28: 21 | E28: 78 | F28: 0 | G28: 0 | H28: 242 | J28: 1 D plant off at 14:00
A29: =A28+1 -> 45988 | B29: 0 | C29: 0 | D29: 21 | E29: 78 | F29: 0 | G29: 0 | H29: 159
A30: =A29+1 -> 45989 | B30: 0 | C30: 0 | D30: 19 | E30: 78 | F30: 0 | G30: 0 | H30: 159
A31: =A30+1 -> 45990 | B31: 0 | C31: 0 | D31: 24 | E31: 78 | F31: 0 | G31: 0 | H31: 159
A32: =A31+1 -> 45991 | B32: 0 | C32: 0 | D32: 28 | E32: 78 | F32: 0 | G32: 0 | H32: 159
A33: Monthly Total | B33: =SUM(B3:B32) -> 0 | C33: =SUM(C3:C32) -> 567 | D33: =SUM(D3:D32) -> 1218 | E33: =SUM(E3:E32) -> 3215 | F33: =SUM(F3:F32) -> 0.65 | G33: =SUM(G3:G32) -> 0 | H33: =SUM(H3:H32) -> 5139
A34: WY Total | B34: =SUM(B33+'Oct 2025'!B35) -> 71 | C34: =SUM(C33+'Oct 2025'!C35) -> 741 | D34: =SUM(D33+'Oct 2025'!D35) -> 2546 | E34: =SUM(E33+'Oct 2025'!E35) -> 7505 | F34: =SUM(F33+'Oct 2025'!F35) -> 1.53 | G34: =SUM(G33+'Oct 2025'!G35) -> 0 | H34: =SUM(H33+'Oct 2025'!H35) -> 11060
A36: Acre Feet | B36: =SUM(B3:B32)*1.9835 -> 0 | C36: =SUM(C3:C32)*1.9835 -> 1124.6445 | D36: =SUM(D3:D32)*1.9835 -> 2415.903 | E36: =SUM(E3:E32)*1.9835 -> 6376.9525
A38: WY AF Total | B38: =SUM('Oct 2025'!B39+B36) -> 140.8285 | C38: =SUM('Oct 2025'!C39+C36) -> 1469.7735 | D38: =SUM('Oct 2025'!D39+D36) -> 5049.991 | E38: =SUM('Oct 2025'!E39+E36) -> 14886.167
H40: * COMPUTATIONAL PURPOSES ONLY! Do Not Enter Data in the Red Columns
A42: *This is computation purposes only for Station 48
A43: Sta 48
G44: =SUM(24-E44) -> 24 | H44: =SUM(D44+F44) -> 0 | I44: =SUM(D44/24*E44+H44/24*G44) -> 0
...

Sheet Oct 2025
A1: DATE | B1: LRDC | C1: STATION 48 | D1: ANDERSON-ROSE | E1: J CANAL | F1: TULE LAKE PRECIP | G1: TULE LAKE SNOW | H1: D PLANT | I1: TULE LAKE ELEV. | J1: CHANGES @ STATION 48
B2: (in CFS) | C2: (in CFS) | D2: (in CFS) | E2: (in CFS)
A3: 45931 | B3: 71 | C3: 15 | D3: 0 | E3: 143 | F3: 0.01 | G3: 0 | H3: 300
A4: =A3+1 -> 45932 | B4: 0 | C4: 0 | D4: 0 | E4: 152 | F4: 0.02 | G4: 0 | H4: 300
A5: =A4+1 -> 45933 | B5: 0 | C5: 0 | D5: 72 | E5: 145 | F5: 0.02 | G5: 0 | H5: 300
A6: =A5+1 -> 45934 | B6: 0 | C6: 0 | D6: 86 | E6: 159 | F6: 0.02 | G6: 0 | H6: 299
A7: =A6+1 -> 45935 | B7: 0 | C7: 0 | D7: 101 | E7: 160 | F7: 0 | G7: 0 | H7: 300
A8: =A7+1 -> 45936 | B8: 0 | C8: 0 | D8: 50 | E8: 178 | F8: 0 | G8: 0 | H8: 299
A9: =A8+1 -> 45937 | B9: 0 | C9: 0 | D9: 72 | E9: 152 | F9: 0 | G9: 0 | H9: 248 | J9: * 1 unit at D plant
A10: =A9+1 -> 45938 | B10: 0 | C10: 0 | D10: 79 | E10: 125 | F10: 0 | G10: 0 | H10: 141
A11: =A10+1 -> 45939 | B11: 0 | C11: 0 | D11: 76 | E11: 128 | F11: 0 | G11: 0 | H11: 141
A12: =A11+1 -> 45940 | B12: 0 | C12: 0 | D12: 114 | E12: 128 | F12: 0 | G12: 0 | H12: 153 | J12: *Switched to unit 1 at D plant from unit 3
A13: =A12+1 -> 45941 | B13: 0 | C13: 0 | D13: 159 | E13: 129 | F13: 0.12 | G13: 0 | H13: 159
A14: =A13+1 -> 45942 | B14: 0 | C14: 0 | D14: 129 | E14: 134 | F14: 0.01 | G14: 0 | H14: 159
A15: =A14+1 -> 45943 | B15: 0 | C15: 0 | D15: 131 | E15: 142 | F15: 0.07 | G15: 0 | H15: 252
A16: =A15+1 -> 45944 | B16: 0 | C16: 0 | D16: 149 | E16: 132 | F16: 0.01 | G16: 0 | H16: 160
A17: =A16+1 -> 45945 | B17: 0 | C17: 0 | D17: 98 | E17: 154 | F17: T | G17: 0 | H17: 159
A18: =A17+1 -> 45946 | B18: 0 | C18: 0 | D18: 12 | E18: 168 | F18: 0 | G18: 0 | H18: 159
A19: =A18+1 -> 45947 | B19: 0 | C19: 0 | D19: 0 | E19: 138 | F19: 0 | G19: 0 | H19: 159
A20: =A19+1 -> 45948 | B20: 0 | C20: 0 | D20: 0 | E20: 109 | F20: 0 | G20: 0 | H20: 159
A21: =A20+1 -> 45949 | B21: 0 | C21: 0 | D21: 0 | E21: 110 | F21: 0.04 | G21: 0 | H21: 159
A22: =A21+1 -> 45950 | B22: 0 | C22: 0 | D22: 0 | E22: 117 | F22: 0 | G22: 0 | H22: 160
A23: =A22+1 -> 45951 | B23: 0 | C23: 0 | D23: 0 | E23: 115 | F23: 0 | G23: 0 | H23: 160
A24: =A23+1 -> 45952 | B24: 0 | C24: 29 | D24: 0 | E24: 120 | F24: 0 | G24: 0 | H24: 160 | J24: * 09:00 0/20 *10:30 20/50
A25: =A24+1 -> 45953 | B25: 0 | C25: 50 | D25: 0 | E25: 137 | F25: 0 | G25: 0 | H25: 160
A26: =A25+1 -> 45954 | B26: 0 | C26: 50 | D26: 0 | E26: 150 | F26: 0 | G26: 0 | H26: 160 | J26: *11:00 50/0
A27: =A26+1 -> 45955 | B27: 0 | C27: 23 | D27: 0 | E27: 143 | F27: 0.3 | G27: 0 | H27: 160
A28: =A27+1 -> 45956 | B28: 0 | C28: 0 | D28: 0 | E28: 137 | F28: 0.19 | G28: 0 | H28: 160
A29: =A28+1 -> 45957 | B29: 0 | C29: 0 | D29: 0 | E29: 133 | F29: 0.05 | G29: 0 | H29: 159
A30: =A29+1 -> 45958 | B30: 0 | C30: 0 | D30: 0 | E30: 127 | F30: 0.01 | G30: 0 | H30: 159
A31: =A30+1 -> 45959 | B31: 0 | C31: 0 | D31: 0 | E31: 117 | F31: 0 | G31: 0 | H31: 159
A32: =A31+1 -> 45960 | B32: 0 | C32: 0 | D32: 0 | E32: 149 | F32: 0 | G32: 0 | H32: 159
A33: =A32+1 -> 45961 | B33: 0 | C33: 7 | D33: 0 | E33: 159 | F33: 0.01 | G33: 0 | H33: 159 | J33: * 17:00 0/25
A34: Monthly Total | B34: =SUM(B3:B33) -> 71 | C34: =SUM(C3:C33) -> 174 | D34: =SUM(D3:D33) -> 1328 | E34: =SUM(E3:E33) -> 4290 | F34: =SUM(F3:F33) -> 0.88 | G34: =SUM(G3:G33) -> 0 | H34: =SUM(H3:H33) -> 5921 | I34: -
A35: WY Total | B35: =SUM(B34+'Oct 2025'!B36) -> 71 | C35: =SUM(C34+'Oct 2025'!C36) -> 174 | D35: =SUM(D34+'Oct 2025'!D36) -> 1328 | E35: =SUM(E34+'Oct 2025'!E36) -> 4290 | F35: =SUM(F34+'Oct 2025'!F36) -> 0.88 | G35: =SUM(G34+'Oct 2025'!G36) -> 0 | H35: =SUM(H34+'Oct 2025'!H36) -> 5921
A37: Acre Feet | B37: =SUM(B3:B33)*1.9835 -> 140.8285 | C37: =SUM(C3:C33)*1.9835 -> 345.129 | D37: =SUM(D3:D33)*1.9835 -> 2634.088 | E37: =SUM(E3:E33)*1.9835 -> 8509.215
A39: WY AF Total | B39: =SUM('Oct 2025'!B40+B37) -> 140.8285 | C39: =SUM('Oct 2025'!C40+C37) -> 345.129 | D39: =SUM('Oct 2025'!D40+D37) -> 2634.088 | E39: =SUM('Oct 2025'!E40+E37) -> 8509.215
H41: * COMPUTATIONAL PURPOSES ONLY! Do Not Enter Data in the Red Columns
A43: *This is computation purposes only for Station 48
A44: Sta 48
...
