Workbook

Sheet Sep 2013
A1: DATE | B1: STATION 48 | C1: ANDERSON-ROSE | D1: J CANAL | E1: TULE LAKE PRECIP | F1: TULE LAKE SNOW | G1: D PLANT | H1: TULE LAKE ELEV. | I1: CHANGES @ STATION 48
B2: (in CFS) | C2: (in CFS) | D2: (in CFS) | G2: (in AF)
A3: 41518
A4: 41519
A5: 41520
A6: 41521
A7: 41522
A8: 41523
A9: 41524
A10: 41525
A11: 41526
A12: 41527
A13: 41528
A14: 41529
... A32: 41547
A33: Monthly Total | B33: =SUM(B3:B32) -> 0 | C33: =SUM(C3:C32) -> 0 | D33: =SUM(D3:D32) -> 0 | E33: =SUM(E3:E32) -> 0 | F33: =SUM(F3:F32) -> 0 | G33: =SUM(G3:G32) -> 0
A34: WY Total | B34: =SUM(B33+'Aug 2013'!B35) -> 23386 | C34: =SUM(C33+'Aug 2013'!C35) -> 4878 | D34: =SUM(D33+'Aug 2013'!D35) -> 46785 | E34: =SUM(E33+'Aug 2013'!E35) -> 8.13 | F34: =SUM(F33+'Aug 2013'!F35) -> 12.1 | G34: =SUM(G33+'Aug 2013'!G35) -> 20772
A36: Acre Feet | B36: =SUM(B3:B32)*1.9835 -> 0 | C36: =SUM(C3:C32)*1.9835 -> 0 | D36: =SUM(D3:D32)*1.9835 -> 0
A38: WY AF Total | B38: =SUM(B36+'Aug 2013'!B39) -> 46386.131 | C38: =SUM(C36+'Aug 2013'!C39) -> 9675.513 | D38: =SUM(D36+'Aug 2013'!D39) -> 92798.048
G40: * COMPUTATIONAL PURPOSES ONLY! Do Not Enter Data in the Red Columns
A42: *This is computation purposes only for Station 48
A43: Sta 48
F44: =SUM(24-D44) -> 24 | G44: =SUM(C44+E44) -> 0 | H44: =SUM(C44/24*D44+G44/24*F44) -> 0
F45: =SUM(24-D45) -> 24 | G45: =SUM(C45+E45) -> 0 | H45: =SUM(C45/24*D45+G45/24*F45) -> 0
F46: =SUM(24-D46) -> 24 | G46: =SUM(C46+E46) -> 0 | H46: =SUM(C46/24*D46+G46/24*F46) -> 0
F47: =SUM(24-D47) -> 24 | G47: =SUM(C47+E47) -> 0 | H47: =SUM(C47/24*D47+G47/24*F47) -> 0
F48: =SUM(24-D48) -> 24 | G48: =SUM(C48+E48) -> 0 | H48: =SUM(C48/24*D48+G48/24*F48) -> 0
A50: Use for more than 1 change in a day.
A51: **Station 48: | B51: Time | C51: Current CFS | D51: Hours Run | E51: +/- cfs | F51: Sub-total cfs
F52: =SUM(C52/24*D52) -> 0
F53: =SUM(C53/24*D53) -> 0
F54: =SUM(C54/24*D54) -> 0
F55: =SUM(C55/24*D55) -> 0
F56: =SUM(C56/24*D56) -> 0
A57: Total Hours Run | D57: =SUM(D52:D56) -> 0 | E57: Total/Day cfs | F57: =SUM(F52:F56) -> 0

Sheet Aug 2013
A1: DATE | B1: STATION 48 | C1: ANDERSON-ROSE | D1: J CANAL | E1: TULE LAKE PRECIP | F1: TULE LAKE SNOW | G1: D PLANT | H1: TULE LAKE ELEV. | I1: CHANGES @ STATION 48
B2: (in CFS) | C2: (in CFS) | D2: (in CFS) | G2: (in AF)
A3: 41487 | B3: 150 | C3: 0 | D3: 292 | E3: 0 | F3: 0 | G3: 0 | H3: 4034.7
A4: 41488 | B4: 173 | C4: 0 | D4: 272 | E4: 0 | F4: 0 | G4: 0 | H4: 4034.7 | I4: * 7 AM 150/200 * 6 PM 200/150
A5: 41489 | B5: 150 | C5: 14 | D5: 279 | E5: 0 | F5: 0 | G5: 0 | H5: 4034.7
A6: 41490 | B6: 92 | C6: 55 | D6: 247 | E6: 0 | F6: 0 | G6: 0 | H6: 4034.72 | I6: * 7 AM 150/100 * 1 PM 100/50
A7: 41491 | B7: 50 | C7: 15 | D7: 249 | E7: 0 | F7: 0 | G7: 0 | H7: 4034.74
A8: 41492 | B8: 77 | C8: 0 | D8: 269 | E8: 0 | F8: 0 | G8: 0 | H8: 4034.75 | I8: * 7 AM 50/100 *2 PM 100/50 * 6 PM 50/100
A9: 41493 | B9: 134 | C9: 0 | D9: 280 | E9: 0.1 | F9: 0 | G9: 0 | H9: 4034.76 | I9: * 8 AM 100/150
A10: 41494 | B10: 135 | C10: 0 | D10: 288 | E10: 0 | F10: 0 | G10: 0 | H10: 4034.77 | I10: * 5 PM 150/100
A11: 41495 | B11: 85 | C11: 40 | D11: 280 | E11: 0.01 | F11: 0 | G11: 0 | H11: 4034.78 | I11: * 5 PM 100/50
A12: 41496 | B12: 44 | C12: 20 | D12: 229 | E12: 0 | F12: 0 | G12: 0 | H12: 4034.78 | I12: * 6 PM 50/25
A13: 41497
A14: 41498
A15: 41499
A16: 41500
A17: 41501
A18: 41502
A19: 41503
A20: 41504
A21: 41505
A22: 41506
A23: 41507
A24: 41508
... A33: 41517
A34: Monthly Total | B34: =SUM(B3:B33) -> 1090 | C34: =SUM(C3:C33) -> 144 | D34: =SUM(D3:D33) -> 2685 | E34: =SUM(E3:E33) -> 0.11 | F34: =SUM(F3:F33) -> 0 | G34: =SUM(G3:G33) -> 0
A35: WY Total | B35: =SUM(B34+'Jul 2013'!B35) -> 23386 | C35: =SUM(C34+'Jul 2013'!C35) -> 4878 | D35: =SUM(D34+'Jul 2013'!D35) -> 46785 | E35: =SUM(E34+'Jul 2013'!E35) -> 8.13 | F35: =SUM(F34+'Jul 2013'!F35) -> 12.1 | G35: =SUM(G34+'Jul 2013'!G35) -> 20772
A37: Acre Feet | B37: =SUM(B3:B33)*1.9835 -> 2162.015 | C37: =SUM(C3:C33)*1.9835 -> 285.624 | D37: =SUM(D3:D33)*1.9835 -> 5325.6975
A39: WY AF Total | B39: =SUM(B37+'Jul 2013'!B39) -> 46386.131 | C39: =SUM(C37+'Jul 2013'!C39) -> 9675.513 | D39: =SUM(D37+'Jul 2013'!D39) -> 92798.048
G41: * COMPUTATIONAL PURPOSES ONLY! Do Not Enter Data in the Red Columns
A43: *This is computation purposes only for Station 48
A44: Sta 48
F45: =SUM(24-D45) -> 24 | G45: =SUM(C45+E45) -> 0 | H45: =SUM(C45/24*D45+G45/24*F45) -> 0
F46: =SUM(24-D46) -> 24 | G46: =SUM(C46+E46) -> 0 | H46: =SUM(C46/24*D46+G46/24*F46) -> 0
F47: =SUM(24-D47) -> 24 | G47: =SUM(C47+E47) -> 0 | H47: =SUM(C47/24*D47+G47/24*F47) -> 0
F48: =SUM(24-D48) -> 24 | G48: =SUM(C48+E48) -> 0 | H48: =SUM(C48/24*D48+G48/24*F48) -> 0
F49: =SUM(24-D49) -> 24 | G49: =SUM(C49+E49) -> 0 | H49: =SUM(C49/24*D49+G49/24*F49) -> 0
A51: Use for more than 1 change in a day.
A52: **Station 48: | B52: Time | C52: Current CFS | D52: Hours Run | E52: +/- cfs | F52: Sub-total cfs
F53: =SUM(C53/24*D53) -> 0
...

Sheet Jul 2013
A1: DATE | B1: STATION 48 | C1: ANDERSON-ROSE | D1: J CANAL | E1: TULE LAKE PRECIP | F1: TULE LAKE SNOW | G1: D PLANT | H1: TULE LAKE ELEV. | I1: CHANGES @ STATION 48
B2: (in CFS) | C2: (in CFS) | D2: (in CFS) | G2: (in AF)
A3: 41456 | B3: 235 | C3: 0 | D3: 364 | E3: 0 | F3: 0 | G3: 0 | H3: 4034.9 | I3: * 8 AM 250/200 * 3 PM 200/250
A4: 41457 | B4: 260 | C4: 0 | D4: 364 | E4: 0 | F4: 0 | G4: 0 | H4: 4034.9 | I4: * 7 PM 250/300
A5: 41458 | B5: 300 | C5: 0 | D5: 383 | E5: 0 | F5: 0 | G5: 0 | H5: 4034.88
A6: 41459 | B6: 250 | C6: 5 | D6: 352 | E6: 0 | F6: 0 | G6: 0 | H6: 4034.86 | I6: * 8 AM 300/250 * 4 PM 250/200
A7: 41460 | B7: 219 | C7: 34 | D7: 357 | E7: 0 | F7: 0 | G7: 0 | H7: 4034.86 | I7: * 3 PM 200/250
A8: 41461 | B8: 183 | C8: 51 | D8: 372 | E8: 0 | F8: 0 | G8: 0 | H8: 4034.84 | I8: * 8 AM 250/150
A9: 41462 | B9: 163 | C9: 2 | D9: 369 | E9: 0 | F9: 0 | G9: 0 | H9: 4034.84 | I9: * 9 AM 150/200 * 3 PM 200/150
A10: 41463 | B10: 150 | C10: 0 | D10: 303 | E10: 0 | F10: 0 | G10: 0 | H10: 4034.82
A11: 41464 | B11: 117 | C11: 25 | D11: 318 | E11: 0 | F11: 0 | G11: 0 | H11: 4034.83 | I11: * 8 AM 150/100
A12: 41465 | B12: 142 | C12: 0 | D12: 308 | E12: 0 | F12: 0 | G12: 0 | H12: 4034.84 | I12: * 10 AM 100/150 * 6 PM 150/200
A13: 41466 | B13: 156 | C13: 0 | D13: 323 | E13: 0 | F13: 0 | G13: 0 | H13: 4034.83 | I13: * 9 AM 200/150 * 6 PM 150/100
A14: 41467 | B14: 129 | C14: 0 | D14: 308 | E14: 0 | F14: 0 | G14: 0 | H14: 4034.83 | I14: * 10 AM 100/150
A15: 41468 | B15: 138 | C15: 0 | D15: 282 | E15: 0 | F15: 0 | G15: 0 | H15: 4034.83 | I15: * 6 PM 150/100
A16: 41469 | B16: 100 | C16: 0 | D16: 252 | E16: 0 | F16: 0 | G16: 0 | H16: 4034.82
A17: 41470 | B17: 88 | C17: 20 | D17: 248 | E17: 0 | F17: 0 | G17: 0 | H17: 4034.79 | I17: * 6 PM 100/50
A18: 41471 | B18: 85 | C18: 18 | D18: 260 | E18: 0 | F18: 0 | G18: 0 | H18: 4034.78 | I18: * 7 AM 50/100
A19: 41472 | B19: 117 | C19: 0 | D19: 283 | E19: 0 | F19: 0 | G19: 0 | H19: 4034.78 | I19: * 4 PM 100/150
A20: 41473 | B20: 150 | C20: 0 | D20: 291 | E20: 0 | F20: 0 | G20: 0 | H20: 4034.78
A21: 41474 | B21: 183 | C21: 0 | D21: 287 | E21: 0 | F21: 0 | G21: 0 | H21: 4034.78 | I21: * 8 AM 150/200
A22: 41475 | B22: 200 | C22: 0 | D22: 319 | E22: 0 | F22: 0 | G22: 0 | H22: 4034.76
A23: 41476 | B23: 219 | C23: 0 | D23: 332 | E23: 0 | F23: 0 | G23: 0 | H23: 4034.76 | I23: * 3 PM 200/250
A24: 41477 | B24: 221 | C24: 0 | D24: 346 | E24: 0 | F24: 0 | G24: 0 | H24: 4034.76 | I24: * 10 AM 250/200
A25: 41478 | B25: 213 | C25: 0 | D25: 334 | E25: 0 | F25: 0 | G25: 0 | H25: 4034.76 | I25: * 6 PM 200/250
A26: 41479 | B26: 215 | C26: 15 | D26: 367 | E26: 0 | F26: 0 | G26: 0 | H26: 4034.76 | I26: * 7 AM 250/200
A27: 41480 | B27: 165 | C27: 25 | D27: 334 | E27: 0 | F27: 0 | G27: 0 | H27: 4034.76 | I27: * 7 AM 200/150
A28: 41481 | B28: 150 | C28: 0 | D28: 364 | E28: 0 | F28: 0 | G28: 0 | H28: 4034.75 | I28: * 12 PM 150/50 * 4 PM 50/200
A29: 41482 | B29: 185 | C29: 0 | D29: 358 | E29: T | F29: 0 | G29: 0 | H29: 4034.74 | I29: * 5 PM 200/150
A30: 41483 | B30: 185 | C30: 0 | D30: 349 | E30: 0 | F30: 0 | G30: 0 | H30: 4034.74 | I30: * 7 AM 150/200
A31: 41484 | B31: 158 | D31: 342 | E31: 0 | F31: 0 | G31: 0 | H31: 4034.74 | I31: * 10 AM 200/150 * 6 PM 150/100
A32: 41485 | B32: 156 | D32: 311 | E32: 0 | F32: 0 | G32: 0 | H32: 4034.72 | I32: * 7 AM 100/200 * 5 PM 200/150
A33: 41486 | B33: 150 | D33: 294 | E33: 0 | F33: 0 | G33: 0 | H33: 4034.72
A34: Monthly Total | B34: =SUM(B3:B33) -> 5382 | C34: =SUM(C3:C33) -> 195 | D34: =SUM(D3:D33) -> 10074 | E34: =SUM(E3:E33) -> 0 | F34: =SUM(F3:F33) -> 0 | G34: =SUM(G3:G33) -> 0
A35: WY Total | B35: =SUM(B34+'Jun 2013'!B34) -> 22296 | C35: =SUM(C34+'Jun 2013'!C34) -> 4734 | D35: =SUM(D34+'Jun 2013'!D34) -> 44100 | E35: =SUM(E34+'Jun 2013'!E34) -> 8.02 | F35: =SUM(F34+'Jun 2013'!F34) -> 12.1 | G35: =SUM(G34+'Jun 2013'!G34) -> 20772
A37: Acre Feet | B37: =SUM(B3:B33)*1.9835 -> 10675.197 | C37: =SUM(C3:C33)*1.9835 -> 386.7825 | D37: =SUM(D3:D33)*1.9835 -> 19981.779
A39: WY AF Total | B39: =SUM(B37+'Jun 2013'!B38) -> 44224.116 | C39: =SUM(C37+'Jun 2013'!C38) -> 9389.889 | D39: =SUM(D37+'Jun 2013'!D38) -> 87472.35
G41: * COMPUTATIONAL PURPOSES ONLY! Do Not Enter Data in the Red Columns
A43: *This is computation purposes only for Station 48
A44: Sta 48
...

Sheet Jun 2013
A1: DATE | B1: STATION 48 | C1: ANDERSON-ROSE | D1: J CANAL | E1: TULE LAKE PRECIP | F1: TULE LAKE SNOW | G1: D PLANT | H1: TULE LAKE ELEV. | I1: CHANGES @ STATION 48
B2: (in CFS) | C2: (in CFS) | D2: (in CFS) | G2: (in AF)
A3: 41426 | B3: 275 | C3: 0 | D3: 394 | E3: 0 | F3: 0 | G3: 0 | H3: 4034.9 | I3: * Noon 250/300
A4: 41427 | B4: 277 | C4: 1 | D4: 409 | E4: 0 | F4: 0 | G4: 0 | H4: 4034.9 | I4: * 7 AM 300/250 * 6 PM 250/300
A5: 41428 | B5: 265 | C5: 45 | D5: 442 | E5: 0 | F5: 0 | G5: 0 | H5: 4034.9 | I5: * 7 AM 300/250
A6: 41429 | B6: 304 | C6: 0 | D6: 466 | E6: 0 | F6: 0 | G6: 0 | H6: 4034.9 | I6: * 11 AM 250/350 * No Change
A7: 41430 | B7: 377 | C7: 0 | D7: 507 | E7: 0 | F7: 0 | G7: 0 | H7: 4034.86 | I7: * 1 PM 350/400
A8: 41431 | B8: 360 | C8: 0 | D8: 499 | E8: 0 | F8: 0 | G8: 0 | H8: 4034.86 | I8: * 11 Am 400/350 * 6 PM 350/300
A9: 41432 | B9: 300 | C9: 0 | D9: 472 | E9: 0 | F9: 0 | G9: 0 | H9: 4034.85
A10: 41433 | B10: 281 | C10: 0 | D10: 472 | E10: 0 | F10: 0 | G10: 0 | H10: 4034.85 | I10: * 3 PM 300/250
A11: 41434 | B11: 250 | C11: 0 | D11: 451 | E11: 0 | F11: 0 | G11: 0 | H11: 4034.82
A12: 41435 | B12: 294 | C12: 0 | D12: 500 | E12: 0 | F12: 0 | G12: 0 | H12: 4034.8 | I12: * 9 AM 250/300 6 PM 300/350
A13: 41436 | B13: 315 | C13: 0 | D13: 490 | E13: 0 | F13: 0 | G13: 0 | H13: 4034.8 | I13: * 8 AM 350/300
A14: 41437 | B14: 300 | C14: 0 | D14: 473 | E14: 0 | F14: 0 | G14: 0 | H14: 4034.8
A15: 41438 | B15: 281 | C15: 35 | D15: 468 | E15: 0 | F15: 0 | G15: 0 | H15: 4034.78 | I15: * 3 PM 300/250
A16: 41439 | B16: 263 | C16: 6 | D16: 441 | E16: 0 | F16: 0 | G16: 0 | H16: 4034.78 | I16: * 6 PM 250/300
A17: 41440 | B17: 252 | C17: 0 | D17: 458 | E17: 0 | F17: 0 | G17: 0 | H17: 4034.78 | I17: * 7 AM 300/250 * 6 PM 250/200
A18: 41441 | B18: 233 | C18: 0 | D18: 373 | E18: 0 | F18: 0 | G18: 0 | H18: 4034.78 | I18: * 8 AM 200/250
A19: 41442 | B19: 275 | C19: 0 | D19: 405 | E19: 0 | F19: 0 | G19: 0 | H19: 4034.78 | I19: * Noon 250/300
A20: 41443 | B20: 277 | C20: 0 | D20: 452 | E20: 0 | F20: 0 | G20: 0 | H20: 4034.78 | I20: * 7 AM 300/250 * 6 PM 250/300
A21: 41444 | B21: 242 | C21: 17 | D21: 452 | E21: 0.03 | F21: 0 | G21: 0 | H21: 4034.76 | I21: * 7 AM 300/250 * 1 PM 250/200
A22: 41445 | B22: 219 | C22: 17 | D22: 456 | E22: 0 | F22: 0 | G22: 0 | H22: 4034.74 | I22: * 3 PM 200/250
A23: 41446 | B23: 250 | C23: 0 | D23: 454 | E23: 0 | F23: 0 | G23: 0 | H23: 4034.74
A24: 41447 | B24: 214 | C24: 24 | D24: 404 | E24: 0 | F24: 0 | G24: 0 | H24: 4034.74 | I24: * 7 AM 250/200
A25: 41448 | B25: 181 | C25: 40 | D25: 365 | E25: 0.2 | F25: 0 | G25: 0 | H25: 4034.75 | I25: * 3 PM 200/150
A26: 41449 | B26: 81 | C26: 66 | D26: 324 | E26: 0.65 | F26: 0 | G26: 0 | H26: 4034.78 | I26: * 7 AM 150/100 * 8 AM 100/50
A27: 41450 | B27: 40 | C27: 17 | D27: 297 | E27: 0.07 | F27: 0 | G27: 0 | H27: 4034.8 | I27: * 3 PM 50/25
A28: 41451 | B28: 25 | C28: 35 | D28: 278 | E28: 0.25 | F28: 0 | G28: 0 | H28: 4034.82
A29: 41452 | B29: 25 | C29: 33 | D29: 260 | E29: 0 | F29: 0 | G29: 0 | H29: 4034.85
A30: 41453 | B30: 45 | C30: 24 | D30: 268 | E30: 0 | F30: 0 | G30: 0 | H30: 4034.88 | I30: * 5 PM 25/50 *6 PM 50/100
A31: 41454 | B31: 100 | C31: 0 | D31: 284 | E31: 0 | F31: 0 | G31: 0 | H31: 4034.9
A32: 41455 | B32: 183 | C32: 0 | D32: 315 | E32: 0 | F32: 0 | G32: 0 | H32: 4034.9 | I32: * 7 AM 100/200 * 6 PM 200/250
A33: Monthly Total | B33: =SUM(B3:B32) -> 6784 | C33: =SUM(C3:C32) -> 360 | D33: =SUM(D3:D32) -> 12329 | E33: =SUM(E3:E32) -> 1.2 | F33: =SUM(F3:F32) -> 0 | G33: =SUM(G3:G32) -> 0
A34: WY Total | B34: =SUM(B33+'May 2013'!B35) -> 16914 | C34: =SUM(C33+'May 2013'!C35) -> 4539 | D34: =SUM(D33+'May 2013'!D35) -> 34026 | E34: =SUM(E33+'May 2013'!E35) -> 8.02 | F34: =SUM(F33+'May 2013'!F35) -> 12.1 | G34: =SUM(G33+'May 2013'!G35) -> 20772
A36: Acre Feet | B36: =SUM(B3:B32)*1.9835 -> 13456.064 | C36: =SUM(C3:C32)*1.9835 -> 714.06 | D36: =SUM(D3:D32)*1.9835 -> 24454.572
A38: WY AF Total | B38: =SUM(B36+'May 2013'!B39) -> 33548.919 | C38: =SUM(C36+'May 2013'!C39) -> 9003.1065 | D38: =SUM(D36+'May 2013'!D39) -> 67490.571
G40: * COMPUTATIONAL PURPOSES ONLY! Do Not Enter Data in the Red Columns
A42: *This is computation purposes only for Station 48
A43: Sta 48
F44: =SUM(24-D44) -> 24 | G44: =SUM(C44+E44) -> 0 | H44: =SUM(C44/24*D44+G44/24*F44) -> 0
...

Sheet May 2013
A1: DATE | B1: STATION 48 | C1: ANDERSON-ROSE | D1: J CANAL | E1: TULE LAKE PRECIP | F1: TULE LAKE SNOW | G1: D PLANT | H1: TULE LAKE ELEV. | I1: CHANGES @ STATION 48
B2: (in CFS) | C2: (in CFS) | D2: (in CFS) | G2: (in AF)
A3: 41395 | B3: 217 | C3: 0 | D3: 380 | E3: 0 | F3: 0 | G3: 0 | H3: 4034.62 | I3: * 8 AM 200/250 4 PM 250/200
A4: 41396 | B4: 233 | C4: 0 | D4: 413 | E4: 0 | F4: 0 | G4: 0 | H4: 4034.62 | I4: * 8 AM 200/250
A5: 41397 | B5: 267 | C5: 0 | D5: 454 | E5: 0 | F5: 0 | G5: 0 | H5: 4034.61 | I5: * 4 PM 250/300
A6: 41398 | B6: 265 | C6: 0 | D6: 463 | E6: 0 | F6: 0 | G6: 0 | H6: 4034.61 | I6: * 7 AM 300/250
A7: 41399 | B7: 229 | C7: 8 | D7: 446 | E7: 0 | F7: 0 | G7: 0 | H7: 4034.61 | I7: * 2 PM 250/200
A8: 41400 | B8: 200 | C8: 15 | D8: 414 | E8: 0.13 | F8: 0 | G8: 0 | H8: 4034.62
A9: 41401 | B9: 219 | C9: 0 | D9: 421 | E9: 0.18 | F9: 0 | G9: 0 | H9: 4034.63 | I9: * 3 PM 200/250
A10: 41402 | B10: 190 | C10: 22 | D10: 431 | E10: 0.2 | F10: 0 | G10: 0 | H10: 4034.64 | I10: * 7 AM 250/200 * Noon 200/150
A11: 41403 | B11: 129 | C11: 24 | D11: 381 | E11: 0.07 | F11: 0 | G11: 0 | H11: 4034.65 | I11: * 2 PM 150/100
A12: 41404 | B12: 131 | C12: 0 | D12: 349 | E12: 0 | F12: 0 | G12: 0 | H12: 4034.66 | I12: * 9 AM 100/150
A13: 41405 | B13: 150 | C13: 0 | D13: 332 | E13: 0 | F13: 0 | G13: 0 | H13: 4034.67
A14: 41406 | B14: 150 | C14: 0 | D14: 309 | E14: 0 | F14: 0 | G14: 0 | H14: 4034.68
A15: 41407 | B15: 150 | C15: 0 | D15: 334 | E15: 0 | F15: 0 | G15: 0 | H15: 4034.7
A16: 41408 | B16: 201 | C16: 0 | D16: 337 | E16: 0 | F16: 0 | G16: 0 | H16: 4034.71 | I16: * 8:30 AM 150/200 * 3 PM 200/250
A17: 41409 | B17: 267 | C17: 0 | D17: 351 | E17: 0 | F17: 0 | G17: 0 | H17: 4034.73 | I17: * 4 PM 250/300
A18: 41410 | B18: 197 | C18: 20 | D18: 364 | E18: 0.08 | F18: 0 | G18: 0 | H18: 4034.75 | I18: * 7:30 AM 300/150
A19: 41411 | B19: 94 | C19: 65 | D19: 318 | E19: 0.24 | F19: 0 | G19: 0 | H19: 4034.76 | I19: * 8 AM 150/100 *2 PM 100/50
A20: 41412 | B20: 50 | C20: 2 | D20: 298 | E20: 0.02 | F20: 0 | G20: 0 | H20: 4034.78
A21: 41413 | B21: 50 | C21: 0 | D21: 278 | E21: 0 | F21: 0 | G21: 0 | H21: 4034.79
A22: 41414 | B22: 50 | C22: 0 | D22: 284 | E22: 0 | F22: 0 | G22: 0 | H22: 4034.81
A23: 41415 | B23: 71 | C23: 0 | D23: 277 | E23: 0 | F23: 0 | G23: 0 | H23: 4034.8 | I23: * 2 PM 50/100
A24: 41416 | B24: 65 | C24: 0 | D24: 265 | E24: 0 | F24: 0 | G24: 0 | H24: 4034.8 | I24: * 7 AM 100/50
A25: 41417 | B25: 50 | C25: 0 | D25: 281 | E25: 0.03 | F25: 0 | G25: 0 | H25: 4034.82
A26: 41418 | B26: 50 | C26: 0 | D26: 293 | E26: 0 | F26: 0 | G26: 0 | H26: 4034.85
A27: 41419 | B27: 117 | C27: 0 | D27: 287 | E27: 0 | F27: 0 | G27: 0 | H27: 4034.85 | I27: * 7 AM 50/100 * 9 AM 100/150
A28: 41420 | B28: 164 | C28: 0 | D28: 298 | E28: 0 | F28: 0 | G28: 0 | H28: 4034.86 | I28: * 10 AM 150/200 * 4:30 PM 200/150
A29: 41421 | B29: 150 | C29: 0 | D29: 306 | E29: 0.13 | F29: 0 | G29: 0 | H29: 4034.87
A30: 41422 | B30: 115 | C30: 65 | D30: 350 | E30: 0.08 | F30: 0 | G30: 0 | H30: 4034.88 | I30: * 7 AM 150/100
A31: 41423 | B31: 123 | C31: 2 | D31: 357 | E31: 0.03 | F31: 0 | G31: 0 | H31: 4034.89 | I31: * 1 PM 100/150
A32: 41424 | B32: 183 | C32: 0 | D32: 375 | E32: 0 | F32: 0 | G32: 0 | H32: 4034.9 | I32: * 8 AM 150/200
A33: 41425 | B33: 156 | C33: 0 | D33: 390 | E33: 0 | F33: 0 | G33: 0 | H33: 4034.9 | I33: * 9 AM 200/250
A34: Monthly Total | B34: =SUM(B3:B33) -> 4683 | C34: =SUM(C3:C33) -> 223 | D34: =SUM(D3:D33) -> 10836 | E34: =SUM(E3:E33) -> 1.19 | F34: =SUM(F3:F33) -> 0 | G34: =SUM(G3:G33) -> 0
A35: WY Total | B35: =SUM(B34+'Apr 2013'!B34) -> 10130 | C35: =SUM(C34+'Apr 2013'!C34) -> 4179 | D35: =SUM(D34+'Apr 2013'!D34) -> 21697 | E35: =SUM(E34+'Apr 2013'!E34) -> 6.82 | F35: =SUM(F34+'Apr 2013'!F34) -> 12.1 | G35: =SUM(G34+'Apr 2013'!G34) -> 20772
A37: Acre Feet | B37: =SUM(B3:B33)*1.9835 -> 9288.7305 | C37: =SUM(C3:C33)*1.9835 -> 442.3205 | D37: =SUM(D3:D33)*1.9835 -> 21493.206
A39: WY AF Total | B39: =SUM(B37+'Apr 2013'!B38) -> 20092.855 | C39: =SUM(C37+'Apr 2013'!C38) -> 8289.0465 | D39: =SUM(D37+'Apr 2013'!D38) -> 43036
G41: * COMPUTATIONAL PURPOSES ONLY! Do Not Enter Data in the Red Columns
A43: *This is computation purposes only for Station 48
A44: Sta 48
...

Sheet Apr 2013
A1: DATE | B1: STATION 48 | C1: ANDERSON-ROSE | D1: J CANAL | E1: TULE LAKE PRECIP | F1: TULE LAKE SNOW | G1: D PLANT | H1: TULE LAKE ELEV. | I1: CHANGES @ STATION 48
B2: (in CFS) | C2: (in CFS) | D2: (in CFS) | G2: (in AF)
A3: 41365 | B3: 50 | C3: 0 | D3: 64 | E3: 0.62 | F3: 0 | G3: 0 | H3: 4034.6
A4: 41366 | B4: 50 | C4: 0 | D4: 76 | E4: 0.01 | F4: 0 | G4: 0 | H4: 4034.6
A5: 41367 | B5: 50 | C5: 0 | D5: 77 | E5: 0.01 | F5: 0 | G5: 0 | H5: 4034.6
A6: 41368 | B6: 50 | C6: 0 | D6: 67 | E6: 0 | F6: 0 | G6: 0 | H6: 4034.6
A7: 41369 | B7: 50 | C7: 0 | D7: 63 | E7: 0 | F7: 0 | G7: 0 | H7: 4034.61
A8: 41370 | B8: 50 | C8: 0 | D8: 66 | E8: 0 | F8: 0 | G8: 0 | H8: 4034.61
A9: 41371 | B9: 50 | C9: 0 | D9: 68 | E9: 0.03 | F9: 0 | G9: 0 | H9: 4034.6
A10: 41372 | B10: 50 | C10: 0 | D10: 69 | E10: 0.06 | F10: 0 | G10: 0 | H10: 4034.61
A11: 41373 | B11: 50 | C11: 0 | D11: 68 | E11: 0 | F11: 0 | G11: 0 | H11: 4034.61
A12: 41374 | B12: 58 | C12: 0 | D12: 74 | E12: 0 | F12: 0 | G12: 0 | H12: 4034.6 | I12: * 4 PM 50/75
A13: 41375 | B13: 75 | C13: 0 | D13: 86 | E13: 0 | F13: 0 | G13: 0 | H13: 4034.61
A14: 41376 | B14: 75 | C14: 0 | D14: 83 | E14: 0 | F14: 0 | G14: 0 | H14: 4034.61
A15: 41377 | B15: 92 | C15: 0 | D15: 90 | E15: 0 | F15: 0 | G15: 0 | H15: 4034.61 | I15: * 8 AM 75/100
A16: 41378 | B16: 83 | C16: 0 | D16: 94 | E16: 0 | F16: 0 | G16: 0 | H16: 4034.62 | I16: * 8 AM 100/75
A17: 41379 | B17: 75 | C17: 0 | D17: 115 | E17: 0 | F17: 0 | G17: 0 | H17: 4034.61
A18: 41380 | B18: 75 | C18: 0 | D18: 114 | E18: 0.01 | F18: T | G18: 0 | H18: 4034.61
A19: 41381 | B19: 75 | C19: 0 | D19: 114 | E19: 0 | F19: 0 | G19: 0 | H19: 4034.62
A20: 41382 | B20: 75 | C20: 0 | D20: 114 | E20: 0 | F20: 0 | G20: 0 | H20: 4034.62
A21: 41383 | B21: 65 | C21: 0 | D21: 118 | E21: 0 | F21: 0 | G21: 0 | H21: 4034.61 | I21: * 2 PM 75/50
A22: 41384 | B22: 50 | C22: 8 | D22: 121 | E22: 0 | F22: 0 | G22: 0 | H22: 4034.61
A23: 41385 | B23: 50 | C23: 10 | D23: 140 | E23: 0 | F23: 0 | G23: 0 | H23: 4034.61
A24: 41386 | B24: 50 | C24: 0 | D24: 185 | E24: 0 | F24: 0 | G24: 0 | H24: 4034.61
A25: 41387 | B25: 83 | C25: 0 | D25: 198 | E25: 0 | F25: 0 | G25: 3 | H25: 4034.61 | I25: * 8 AM 50/100 D PLANT TEST
A26: 41388 | B26: 134 | C26: 0 | D26: 213 | E26: 0 | F26: 0 | G26: 0 | H26: 4034.62 | I26: * 8 AM 100/150
A27: 41389 | B27: 150 | C27: 0 | D27: 227 | E27: 0 | F27: 0 | G27: 0 | H27: 4034.61
A28: 41390 | B28: 206 | C28: 0 | D28: 244 | E28: 0 | F28: 0 | G28: 0 | H28: 4034.61 | I28: * 8 AM 150/200//**12PM 200/250
A29: 41391 | B29: 183 | C29: 25 | D29: 252 | E29: 0 | F29: 0 | G29: 0 | H29: 4034.62 | I29: * 8 AM 250/150
A30: 41392 | B30: 150 | C30: 10 | D30: 278 | E30: 0 | F30: 0 | G30: 0 | H30: 4034.61
A31: 41393 | B31: 150 | C31: 29 | D31: 298 | E31: 0 | F31: 0 | G31: 0 | H31: 4034.61
A32: 41394 | B32: 167 | C32: 0 | D32: 346 | E32: 0 | F32: 0 | G32: 0 | H32: 4034.61 | I32: * 4 PM 150/200
A33: Monthly Total | B33: =SUM(B3:B32) -> 2571 | C33: =SUM(C3:C32) -> 82 | D33: =SUM(D3:D32) -> 4122 | E33: =SUM(E3:E32) -> 0.74 | F33: =SUM(F3:F32) -> 0 | G33: =SUM(G3:G32) -> 3
A34: WY Total | B34: =SUM(B33+'Mar 2013'!B35) -> 5447 | C34: =SUM(C33+'Mar 2013'!C35) -> 3956 | D34: =SUM(D33+'Mar 2013'!D35) -> 10861 | E34: =SUM(E33+'Mar 2013'!E35) -> 5.63 | F34: =SUM(F33+'Mar 2013'!F35) -> 12.1 | G34: =SUM(G33+'Mar 2013'!G35) -> 20772
A36: Acre Feet | B36: =SUM(B3:B32)*1.9835 -> 5099.5785 | C36: =SUM(C3:C32)*1.9835 -> 162.647 | D36: =SUM(D3:D32)*1.9835 -> 8175.987
A38: WY AF Total | B38: =SUM(B36+'Mar 2013'!B39) -> 10804.125 | C38: =SUM(C36+'Mar 2013'!C39) -> 7846.726 | D38: =SUM(D36+'Mar 2013'!D39) -> 21542.793
G40: * COMPUTATIONAL PURPOSES ONLY! Do Not Enter Data in the Red Columns
A42: *This is computation purposes only for Station 48
A43: Sta 48
F44: =SUM(24-D44) -> 24 | G44: =SUM(C44+E44) -> 0 | H44: =SUM(C44/24*D44+G44/24*F44) -> 0
...

Sheet Mar 2013
A1: DATE | B1: STATION 48 | C1: ANDERSON-ROSE | D1: J CANAL | E1: TULE LAKE PRECIP | F1: TULE LAKE SNOW | G1: D PLANT | H1: TULE LAKE ELEV. | I1: CHANGES @ STATION 48
B2: (in CFS) | C2: (in CFS) | D2: (in CFS) | G2: (in AF)
A3: 41334 | B3: 0 | C3: 20 | D3: 0 | E3: 0.01 | F3: 0 | G3: 0 | H3: 4034.49
A4: 41335 | B4: 0 | C4: 20 | D4: 0 | E4: 0 | F4: 0 | G4: 0 | H4: 4034.49
A5: 41336 | B5: 0 | C5: 20 | D5: 0 | E5: 0.04 | F5: 0 | G5: 0 | H5: 4034.5
A6: 41337 | B6: 0 | C6: 20 | D6: 0 | E6: 0 | F6: 0 | G6: 0 | H6: 4034.51
A7: 41338 | B7: 0 | C7: 20 | D7: 0 | E7: 0 | F7: 0 | G7: 0 | H7: 4034.52
A8: 41339 | B8: 0 | C8: 20 | D8: 0 | E8: 0.06 | F8: 0.5 | G8: 0 | H8: 4034.53
A9: 41340 | B9: 0 | C9: 20 | D9: 0 | E9: 0.05 | F9: 1 | G9: 0 | H9: 4034.54
A10: 41341 | B10: 0 | C10: 20 | D10: 0 | E10: 0.01 | F10: 0 | G10: 0 | H10: 4034.55
A11: 41342 | B11: 0 | C11: 20 | D11: 0 | E11: 0 | F11: 0 | G11: 0 | H11: 4034.56
A12: 41343 | B12: 0 | C12: 20 | D12: 0 | E12: 0 | F12: 0 | G12: 0 | H12: 4034.57
A13: 41344 | B13: 0 | C13: 8 | D13: 0 | E13: 0 | F13: 0 | G13: 0 | H13: 4034.58
A14: 41345 | B14: 0 | C14: 0 | D14: 0 | E14: 0 | F14: 0 | G14: 0 | H14: 4034.59
... A17: 41348 | B17: 0 | C17: 14 | D17: 6 | E17: 0 | F17: 0 | G17: 0 | H17: 4034.61
A18: 41349 | B18: *8 | C18: 3 | D18: 32 | E18: 0 | F18: 0 | G18: 0 | H18: 4034.61 | I18: * 4 PM 0/25
A19: 41350 | B19: 25 | C19: 0 | D19: 45 | E19: 0 | F19: 0 | G19: 0 | H19: 4034.62
A20: 41351 | B20: 25 | C20: 0 | D20: 36 | E20: 0 | F20: 0 | G20: 0 | H20: 4034.61
A21: 41352 | B21: 25 | C21: 0 | D21: 36 | E21: 0 | F21: 0 | G21: 0 | H21: 4034.6
A22: 41353 | B22: 25 | C22: 0 | D22: 39 | E22: 0.02 | F22: 0 | G22: 0 | H22: 4034.59
A23: 41354 | B23: 25 | C23: 0 | D23: 38 | E23: 0.01 | F23: 0 | G23: 0 | H23: 4034.58
A24: 41355 | B24: 25 | C24: 0 | D24: 39 | E24: 0 | F24: 0 | G24: 0 | H24: 4034.57
A25: 41356 | B25: 25 | C25: 0 | D25: 39 | E25: 0 | F25: 0 | G25: 0 | H25: 4034.57
A26: 41357 | B26: 25 | C26: 0 | D26: 41 | E26: 0 | F26: 0 | G26: 0 | H26: 4034.56
A27: 41358 | B27: 25 | C27: 0 | D27: 41 | E27: 0 | F27: 0 | G27: 0 | H27: 4034.55
A28: 41359 | B28: 25 | C28: 0 | D28: 41 | E28: 0.02 | F28: 0 | G28: 0 | H28: 4034.56
A29: 41360 | B29: 25 | C29: 0 | D29: 42 | E29: 0.02 | F29: 0 | G29: 0 | H29: 4034.56
A30: 41361 | B30: 42 | C30: 0 | D30: 53 | E30: 0.01 | F30: 0 | G30: 0 | H30: 4034.57 | I30: * 8 AM 25/50
A31: 41362 | B31: 50 | C31: 0 | D31: 62 | E31: 0 | F31: 0 | G31: 0 | H31: 4034.58
A32: 41363 | B32: 50 | C32: 0 | D32: 62 | E32: 0 | F32: 0 | G32: 0 | H32: 4034.59
A33: 41364 | B33: 50 | C33: 0 | D33: 62 | E33: 0.02 | F33: 0 | G33: 0 | H33: 4034.6
A34: Monthly Total | B34: =SUM(B3:B33) -> 467 | C34: =SUM(C3:C33) -> 238 | D34: =SUM(D3:D33) -> 714 | E34: =SUM(E3:E33) -> 0.27 | F34: =SUM(F3:F33) -> 1.5 | G34: =SUM(G3:G33) -> 0
A35: WY Total | B35: =SUM(B34+'Feb 2013'!B33) -> 2876 | C35: =SUM(C34+'Feb 2013'!C33) -> 3874 | D35: =SUM(D34+'Feb 2013'!D33) -> 6739 | E35: =SUM(E34+'Feb 2013'!E33) -> 4.89 | F35: =SUM(F34+'Feb 2013'!F33) -> 12.1 | G35: =SUM(G34+'Feb 2013'!G33) -> 20769
A37: Acre Feet | B37: =SUM(B3:B33)*1.9835 -> 926.2945 | C37: =SUM(C3:C33)*1.9835 -> 472.073 | D37: =SUM(D3:D33)*1.9835 -> 1416.219
A39: WY AF Total | B39: =SUM(B37+'Feb 2013'!B37) -> 5704.546 | C39: =SUM(C37+'Feb 2013'!C37) -> 7684.079 | D39: =SUM(D37+'Feb 2013'!D37) -> 13366.806
G41: * COMPUTATIONAL PURPOSES ONLY! Do Not Enter Data in the Red Columns
A43: *This is computation purposes only for Station 48
A44: Sta 48
F45: =SUM(24-D45) -> 24 | G45: =SUM(C45+E45) -> 0 | H45: =SUM(C45/24*D45+G45/24*F45) -> 0
F46: =SUM(24-D46) -> 24 | G46: =SUM(C46+E46) -> 0 | H46: =SUM(C46/24*D46+G46/24*F46) -> 0
...

Sheet Feb 2013
A1: DATE | B1: STATION 48 | C1: ANDERSON-ROSE | D1: J CANAL | E1: TULE LAKE PRECIP | F1: TULE LAKE SNOW | G1: D PLANT | H1: TULE LAKE ELEV. | I1: CHANGES @ STATION 48
B2: (in CFS) | C2: (in CFS) | D2: (in CFS) | G2: (in AF)
A3: 41306 | B3: 0 | C3: 30 | D3: 0 | E3: 0 | F3: 0 | G3: 0 | H3: 4034.39
A4: =A3+1 -> 41307 | B4: 0 | C4: 30 | D4: 0 | E4: 0 | F4: 0 | G4: 0 | H4: 4034.4
A5: =A4+1 -> 41308 | B5: 0 | C5: 30 | D5: 0 | E5: 0 | F5: 0 | G5: 0 | H5: 4034.4
A6: =A5+1 -> 41309 | B6: 0 | C6: 30 | D6: 0 | E6: 0 | F6: 0 | G6: 0 | H6: 4034.41
A7: =A6+1 -> 41310 | B7: 0 | C7: 30 | D7: 0 | E7: 0.01 | F7: 0 | G7: 0 | H7: 4034.42
A8: =A7+1 -> 41311 | B8: 0 | C8: 30 | D8: 0 | E8: 0 | F8: 0 | G8: 0 | H8: 4034.43
A9: =A8+1 -> 41312 | B9: 0 | C9: 30 | D9: 0 | E9: 0.13 | F9: 2 | G9: 0 | H9: 4034.45
A10: =A9+1 -> 41313 | B10: 0 | C10: 30 | D10: 0 | E10: 0 | F10: 0 | G10: 0 | H10: 4034.47
A11: =A10+1 -> 41314 | B11: 0 | C11: 30 | D11: 0 | E11: 0 | F11: 0 | G11: 0 | H11: 4034.49
A12: =A11+1 -> 41315 | B12: 0 | C12: 30 | D12: 0 | E12: 0 | F12: 0 | G12: 0 | H12: 4034.5
A13: =A12+1 -> 41316 | B13: 0 | C13: 25 | D13: 0 | E13: 0 | F13: 0 | G13: 0 | H13: 4034.5
A14: =A13+1 -> 41317 | B14: 0 | C14: 20 | D14: 0 | E14: 0 | F14: 0 | G14: 0 | H14: 4034.51
A15: =A14+1 -> 41318 | B15: 0 | C15: 20 | D15: 0 | E15: 0 | F15: 0 | G15: 0 | H15: 4034.52
... A25: =A24+1 -> 41328 | B25: 0 | C25: 30 | D25: 0 | E25: 0.07 | F25: 0 | G25: 319 | H25: 4034.55
A26: =A25+1 -> 41329 | B26: 0 | C26: 30 | D26: 0 | E26: T | F26: 0 | G26: 318 | H26: 4034.54
A27: =A26+1 -> 41330 | B27: 0 | C27: 30 | D27: 0 | E27: 0 | F27: 0 | G27: 318 | H27: 4034.52
A28: =A27+1 -> 41331 | B28: 0 | C28: 30 | D28: 0 | E28: 0 | F28: 0 | G28: 318 | H28: 4034.5
A29: =A28+1 -> 41332 | B29: 0 | C29: 30 | D29: 0 | E29: 0 | F29: 0 | G29: 318 | H29: 4034.48
A30: =A29+1 -> 41333 | B30: 0 | C30: 23 | D30: 0 | E30: 0.04 | F30: 0 | G30: 166 | H30: 4034.48
A32: Monthly Total | B32: =SUM(B3:B31) -> 0 | C32: =SUM(C3:C31) -> 762 | D32: =SUM(D3:D31) -> 0 | E32: =SUM(E3:E31) -> 0.6 | F32: =SUM(F3:F31) -> 6 | G32: =SUM(G3:G31) -> 2401
A33: WY Total | B33: =SUM(B32+'Jan 2013'!B35) -> 2409 | C33: =SUM(C32+'Jan 2013'!C35) -> 3636 | D33: =SUM(D32+'Jan 2013'!D35) -> 6025 | E33: =SUM(E32+'Jan 2013'!E35) -> 4.62 | F33: =SUM(F32+'Jan 2013'!F35) -> 10.6 | G33: =SUM(G32+'Jan 2013'!G35) -> 20769
A35: Acre Feet | B35: =SUM(B3:B31)*1.9835 -> 0 | C35: =SUM(C3:C31)*1.9835 -> 1511.427 | D35: =SUM(D3:D31)*1.9835 -> 0
A37: WY AF Total | B37: =SUM(B35+'Jan 2013'!B39) -> 4778.2515 | C37: =SUM(C35+'Jan 2013'!C39) -> 7212.006 | D37: =SUM(D35+'Jan 2013'!D39) -> 11950.587
G39: * COMPUTATIONAL PURPOSES ONLY! Do Not Enter Data in the Red Columns
A41: *This is computation purposes only for Station 48
A42: Sta 48
F43: =SUM(24-D43) -> 24 | G43: =SUM(C43+E43) -> 0 | H43: =SUM(C43/24*D43+G43/24*F43) -> 0
F44: =SUM(24-D44) -> 24 | G44: =SUM(C44+E44) -> 0 | H44: =SUM(C44/24*D44+G44/24*F44) -> 0
F45: =SUM(24-D45) -> 24 | G45: =SUM(C45+E45) -> 0 | H45: =SUM(C45/24*D45+G45/24*F45) -> 0
F46: =SUM(24-D46) -> 24 | G46: =SUM(C46+E46) -> 0 | H46: =SUM(C46/24*D46+G46/24*F46) -> 0
F47: =SUM(24-D47) -> 24 | G47: =SUM(C47+E47) -> 0 | H47: =SUM(C47/24*D47+G47/24*F47) -> 0
A49: Use for more than 1 change in a day.
A50: **Station 48: | B50: Time | C50: Current CFS | D50: Hours Run | E50: +/- cfs | F50: Sub-total cfs
F51: =SUM(C51/24*D51) -> 0
F52: =SUM(C52/24*D52) -> 0
F53: =SUM(C53/24*D53) -> 0
F54: =SUM(C54/24*D54) -> 0
F55: =SUM(C55/24*D55) -> 0
...

Sheet Jan 2013
A1: DATE | B1: STATION 48 | C1: ANDERSON-ROSE | D1: J CANAL | E1: TULE LAKE PRECIP | F1: TULE LAKE SNOW | G1: D PLANT | H1: TULE LAKE ELEV. | I1: CHANGES @ STATION 48
B2: (in CFS) | C2: (in CFS) | D2: (in CFS) | G2: (in AF)
A3: 41275 | B3: 0 | C3: 20 | D3: 0 | E3: 0 | F3: 0 | G3: 0 | H3: 4034.39
A4: 41276 | B4: 0 | C4: 20 | D4: 0 | E4: 0 | F4: 0 | G4: 0 | H4: 4034.4
A5: 41277 | B5: 0 | C5: 20 | D5: 0 | E5: 0 | F5: 0 | G5: 0 | H5: 4034.4
A6: 41278 | B6: 0 | C6: 20 | D6: 0 | E6: 0 | F6: 0 | G6: 0 | H6: 4034.4
A7: 41279 | B7: 0 | C7: 20 | D7: 0 | E7: 0 | F7: 0 | G7: 0 | H7: 4034.4
A8: 41280 | B8: 0 | C8: 20 | D8: 0 | E8: 0.04 | F8: 0.5 | G8: 0 | H8: 4034.4
A9: 41281 | B9: 0 | C9: 20 | D9: 0 | E9: T | F9: 0 | G9: 0 | H9: 4034.4
A10: 41282 | B10: 0 | C10: 20 | D10: 0 | E10: T | F10: T | G10: 0 | H10: 4034.4
A11: 41283 | B11: 0 | C11: 20 | D11: 0 | E11: 0.03 | F11: 1 | G11: 0 | H11: 4034.4
A12: 41284 | B12: 0 | C12: 20 | D12: 0 | E12: 0.12 | F12: 1 | G12: 0 | H12: 4034.41
A13: 41285 | B13: 0 | C13: 20 | D13: 0 | E13: 0.01 | F13: 0.25 | G13: 0 | H13: 4034.41
A14: 41286 | B14: 0 | C14: 20 | D14: 0 | E14: 0 | F14: 0 | G14: 0 | H14: 4034.41
A15: 41287 | B15: 0 | C15: 20 | D15: 0 | E15: 0 | F15: 0 | G15: 0 | H15: 4034.41
A16: 41288 | B16: 0 | C16: 20 | D16: 0 | E16: 0 | F16: 0 | G16: 0 | H16: 4034.41
A17: 41289 | B17: 0 | C17: 20 | D17: 0 | E17: 0 | F17: 0 | G17: 0 | H17: 4034.4
A18: 41290 | B18: 0 | C18: 20 | D18: 0 | E18: 0 | F18: 0 | G18: 0 | H18: 4034.4
A19: 41291 | B19: 0 | C19: 20 | D19: 0 | E19: 0 | F19: 0 | G19: 0 | H19: 4034.39
A20: 41292 | B20: 0 | C20: 20 | D20: 0 | E20: 0 | F20: 0 | G20: 0 | H20: 4034.38
A21: 41293 | B21: 0 | C21: 20 | D21: 0 | E21: 0 | F21: 0 | G21: 0 | H21: 4034.38
A22: 41294 | B22: 0 | C22: 20 | D22: 0 | E22: 0 | F22: 0 | G22: 0 | H22: 4034.37
... A33: 41305 | B33: 0 | C33: 30 | D33: 0 | E33: 0 | F33: 0 | G33: 0 | H33: 4034.38
A34: Monthly Total | B34: =SUM(B3:B33) -> 0 | C34: =SUM(C3:C33) -> 728 | D34: =SUM(D3:D33) -> 0 | E34: =SUM(E3:E33) -> 0.45 | F34: =SUM(F3:F33) -> 2.75 | G34: =SUM(G3:G33) -> 0
A35: WY Total | B35: =SUM(B34+'Dec 2012'!B35) -> 2409 | C35: =SUM(C34+'Dec 2012'!C35) -> 2874 | D35: =SUM(D34+'Dec 2012'!D35) -> 6025 | E35: =SUM(E34+'Dec 2012'!E35) -> 4.02 | F35: =SUM(F34+'Dec 2012'!F35) -> 4.6 | G35: =SUM(G34+'Dec 2012'!G35) -> 18368
A37: Acre Feet | B37: =SUM(B3:B33)*1.9835 -> 0 | C37: =SUM(C3:C33)*1.9835 -> 1443.988 | D37: =SUM(D3:D33)*1.9835 -> 0
A39: WY AF Total | B39: =SUM(B37+'Dec 2012'!B39) -> 4778.2515 | C39: =SUM(C37+'Dec 2012'!C39) -> 5700.579 | D39: =SUM(D37+'Dec 2012'!D39) -> 11950.587
G41: * COMPUTATIONAL PURPOSES ONLY! Do Not Enter Data in the Red Columns
A43: *This is computation purposes only for Station 48
A44: Sta 48
F45: =SUM(24-D45) -> 24 | G45: =SUM(C45+E45) -> 0 | H45: =SUM(C45/24*D45+G45/24*F45) -> 0
F46: =SUM(24-D46) -> 24 | G46: =SUM(C46+E46) -> 0 | H46: =SUM(C46/24*D46+G46/24*F46) -> 0
F47: =SUM(24-D47) -> 24 | G47: =SUM(C47+E47) -> 0 | H47: =SUM(C47/24*D47+G47/24*F47) -> 0
F48: =SUM(24-D48) -> 24 | G48: =SUM(C48+E48) -> 0 | H48: =SUM(C48/24*D48+G48/24*F48) -> 0
F49: =SUM(24-D49) -> 24 | G49: =SUM(C49+E49) -> 0 | H49: =SUM(C49/24*D49+G49/24*F49) -> 0
A51: Use for more than 1 change in a day.
A52: **Station 48: | B52: Time | C52: Current CFS | D52: Hours Run | E52: +/- cfs | F52: Sub-total cfs
E53: -100 | F53: =SUM(C53/24*D53) -> 0
E54: -50 | F54: =SUM(C54/24*D54) -> 0
F55: =SUM(C55/24*D55) -> 0
...

Sheet Dec 2012
A1: DATE | B1: STATION 48 | C1: ANDERSON-ROSE | D1: J CANAL | E1: TULE LAKE PRECIP | F1: TULE LAKE SNOW | G1: D PLANT | H1: TULE LAKE ELEV. | I1: CHANGES @ STATION 48
B2: (in CFS) | C2: (in CFS) | D2: (in CFS) | G2: (in AF)
A3: 41244 | B3: 0 | C3: 20 | D3: 0 | E3: 0.07 | F3: 0 | G3: 319 | H3: 4034.56
A4: 41245 | B4: 0 | C4: 20 | D4: 0 | E4: 0.52 | F4: 0 | G4: 319 | H4: 4034.56
A5: 41246 | B5: 0 | C5: 93 | D5: 0 | E5: 0.01 | F5: 0 | G5: 319 | H5: 4034.56
A6: 41247 | B6: 0 | C6: 80 | D6: 0 | E6: 0.02 | F6: 0 | G6: 114 | H6: 4034.55 | I6: *D Plant Off for Aprox. 24 Hrs
A7: 41248 | B7: 0 | C7: 53 | D7: 0 | E7: 0.07 | F7: 0 | G7: 192 | H7: 4034.54 | I7: *D Plant will be restarted at approx 9:00 AMOff for Aprox. 6 Hrs
A8: 41249 | B8: 0 | C8: 34 | D8: 0 | E8: 0.01 | F8: 0 | G8: 301 | H8: 4034.53
A9: 41250 | B9: 0 | C9: 30 | D9: 0 | E9: 0 | F9: 0 | G9: 301 | H9: 4034.52
A10: 41251 | B10: 0 | C10: 30 | D10: 0 | E10: 0 | F10: 0 | G10: 301 | H10: 4034.51
A11: 41252 | B11: 0 | C11: 30 | D11: 0 | E11: 0 | F11: 0 | G11: 301 | H11: 4034.5
A12: 41253 | B12: 0 | C12: 30 | D12: 0 | E12: 0 | F12: 0 | G12: 300 | H12: 4034.5
A13: 41254 | B13: 0 | C13: 30 | D13: 0 | E13: 0.01 | F13: 0 | G13: 300 | H13: 4034.48
A14: 41255 | B14: 0 | C14: 30 | D14: 0 | E14: 0.09 | F14: 0 | G14: 300 | H14: 4034.46
A15: 41256 | B15: 0 | C15: 27 | D15: 0 | E15: 0 | F15: 0 | G15: 300 | H15: 4034.45
A16: 41257 | B16: 0 | C16: 25 | D16: 0 | E16: 0.03 | F16: 0.1 | G16: 300 | H16: 4034.44
A17: 41258 | B17: 0 | C17: 25 | D17: 0 | E17: 0.03 | F17: 0 | G17: 300 | H17: 4034.42
A18: 41259 | B18: 0 | C18: 25 | D18: 0 | E18: 0.02 | F18: 0 | G18: 300 | H18: 4034.4
A19: 41260 | B19: 0 | C19: 25 | D19: 0 | E19: 0.13 | F19: 0 | G19: 300 | H19: 4034.39
... A22: 41263 | B22: 0 | C22: 20 | D22: 0 | E22: 0 | F22: 0 | G22: 300 | H22: 4034.36
A23: 41264 | B23: 0 | C23: 20 | D23: 0 | E23: T | F23: T | G23: 188 | H23: 4034.35 | I23: *D Plant Off at Approx. 3:00 PM
A24: 41265 | B24: 0 | C24: 20 | D24: 0 | E24: 0.13 | F24: 1" | G24: 0 | H24: 4034.34
A25: 41266 | B25: 0 | C25: 20 | D25: 0 | E25: T | F25: T | G25: 0 | H25: 4034.34
A26: 41267 | B26: 0 | C26: 20 | D26: 0 | E26: T | F26: 0 | G26: 0 | H26: 4034.34
A27: 41268 | B27: 0 | C27: 20 | D27: 0 | E27: T | F27: 0 | G27: 0 | H27: 4034.35
A28: 41269 | B28: 0 | C28: 20 | D28: 0 | E28: 0.09 | F28: 2" | G28: 0 | H28: 4034.35
A29: 41270 | B29: 0 | C29: 27 | D29: 0 | E29: T | F29: 0 | G29: 0 | H29: 4034.36
A30: 41271 | B30: 0 | C30: 30 | D30: 0 | E30: 0.02 | F30: .1" | G30: 0 | H30: 4034.37
A31: 41272 | B31: 0 | C31: 30 | D31: 0 | E31: 0.05 | F31: .7" | G31: 0 | H31: 4034.38
A32: 41273 | B32: 0 | C32: 30 | D32: 0 | E32: 0 | F32: 0 | G32: 0 | H32: 4034.39
A33: 41274 | B33: 0 | C33: 25 | D33: 0 | E33: 0 | F33: 0 | G33: 0 | H33: 4034.39
A34: Monthly Total | B34: =SUM(B3:B33) -> 0 | C34: =SUM(C3:C33) -> 936 | D34: =SUM(D3:D33) -> 0 | E34: =SUM(E3:E33) -> 1.3 | F34: =SUM(F3:F33) -> 0.1 | G34: =SUM(G3:G33) -> 5955
A35: WY Total | B35: =SUM(B34+'Nov 2012'!B34) -> 2409 | C35: =SUM(C34+'Nov 2012'!C34) -> 2146 | D35: =SUM(D34+'Nov 2012'!D34) -> 6025 | E35: =SUM(E34+'Nov 2012'!E34) -> 3.57 | F35: =SUM(F34+'Nov 2012'!F34) -> 1.85 | G35: =SUM(G34+'Nov 2012'!G34) -> 18368
A37: Acre Feet | B37: =SUM(B3:B33)*1.9835 -> 0 | C37: =SUM(C3:C33)*1.9835 -> 1856.556 | D37: =SUM(D3:D33)*1.9835 -> 0
A39: WY AF Total | B39: =SUM('Nov 2012'!B38+B37) -> 4778.2515 | C39: =SUM('Nov 2012'!C38+C37) -> 4256.591 | D39: =SUM('Nov 2012'!D38+D37) -> 11950.587
G41: * COMPUTATIONAL PURPOSES ONLY! Do Not Enter Data in the Red Columns
A43: *This is computation purposes only for Station 48
A44: Sta 48
F45: =SUM(24-D45) -> 24 | G45: =SUM(C45+E45) -> 0 | H45: =SUM(C45/24*D45+G45/24*F45) -> 0
F46: =SUM(24-D46) -> 24 | G46: =SUM(C46+E46) -> 0 | H46: =SUM(C46/24*D46+G46/24*F46) -> 0
...

Sheet Nov 2012
A1: DATE | B1: STATION 48 | C1: ANDERSON-ROSE | D1: J CANAL | E1: TULE LAKE PRECIP | F1: TULE LAKE SNOW | G1: D PLANT | H1: TULE LAKE ELEV. | I1: CHANGES @ STATION 48
B2: (in CFS) | C2: (in CFS) | D2: (in CFS) | G2: (in AF)
A3: 41214 | B3: 150 | C3: 0 | D3: 158 | E3: 0.05 | F3: 0 | G3: 300 | H3: 4034.52
A4: 41215 | B4: 150 | C4: 0 | D4: 192 | E4: 0.01 | F4: 0 | G4: 300 | H4: 4034.5
A5: 41216 | B5: 150 | C5: 0 | D5: 214 | E5: 0.02 | F5: 0 | G5: 300 | H5: 4034.48
A6: 41217 | B6: 150 | C6: 0 | D6: 194 | E6: 0 | F6: 0 | G6: 300 | H6: 4034.47
A7: 41218 | B7: 150 | C7: 0 | D7: 151 | E7: 0 | F7: 0 | G7: 300 | H7: 4034.46
A8: 41219 | B8: 150 | C8: 0 | D8: 139 | E8: 0.01 | F8: 0 | G8: 300 | H8: 4034.44
A9: 41220 | B9: 115 | C9: 0 | D9: 147 | E9: 0 | F9: 0 | G9: 300 | H9: 4034.42 | I9: *7:00 am 150/100
A10: 41221 | B10: 77 | C10: 0 | D10: 138 | E10: 0 | F10: 0 | G10: 300 | H10: 4034.4 | I10: *1PM 100/50
A11: 41222 | B11: 42 | C11: 0 | D11: 98 | E11: 0.12 | F11: 1 | G11: 300 | H11: 4034.38 | I11: *4PM 50/25
A12: 41223 | B12: 25 | C12: 0 | D12: 87 | E12: 0.04 | F12: 0 | G12: 300 | H12: 4034.36
A13: 41224 | B13: 25 | C13: 0 | D13: 71 | E13: 0 | F13: 0 | G13: 300 | H13: 4034.34
A14: 41225 | B14: 18 | C14: 0 | D14: 59 | E14: 0.06 | F14: 0 | G14: 300 | H14: 4034.32 | I14: *5PM 25/0
A15: 41226 | B15: 0 | C15: 0 | D15: 36 | E15: 0.01 | F15: 0 | G15: 114 | H15: 4034.3 | I15: * D Plant OFF approx. 9AM
A16: 41227 | B16: 0 | C16: 0 | D16: 13 | E16: 0.02 | F16: 0 | G16: 0 | H16: 4034.31 | I16: * J Canal OFF 9AM
A17: 41228 | B17: 0 | C17: 0 | D17: 0 | E17: 0.01 | F17: 0 | G17: 0 | H17: 4034.32
A18: 41229 | B18: 0 | C18: 0 | D18: 0 | E18: T | F18: 0 | G18: 0 | H18: 4034.33
A19: 41230 | B19: 0 | C19: 0 | D19: 0 | E19: 0.15 | F19: 0 | G19: 0 | H19: 4034.34
A20: 41231 | B20: 0 | C20: 0 | D20: 0 | E20: 0.23 | F20: 0 | G20: 0 | H20: 4034.35
A21: 41232 | B21: 0 | C21: 12 | D21: 0 | E21: 0 | F21: 0 | G21: 0 | H21: 4034.36
A22: 41233 | B22: 0 | C22: 20 | D22: 0 | E22: 0.02 | F22: 0 | G22: 0 | H22: 4034.38
A23: 41234 | B23: 0 | C23: 20 | D23: 0 | E23: 0.12 | F23: 0 | G23: 0 | H23: 4034..40
A24: 41235 | B24: 0 | C24: 20 | D24: 0 | E24: 0 | F24: 0 | G24: 0 | H24: 4034.42
A25: 41236 | B25: 0 | C25: 20 | D25: 0 | E25: 0 | F25: 0 | G25: 0 | H25: 4034.44
A26: 41237 | B26: 0 | C26: 20 | D26: 0 | E26: 0.02 | F26: 0 | G26: 0 | H26: 4034.46
A27: 41238 | B27: 0 | C27: 20 | D27: 0 | E27: 0 | F27: 0 | G27: 0 | H27: 4034.48
A28: 41239 | B28: 0 | C28: 20 | D28: 0 | E28: 0 | F28: 0 | G28: 0 | H28: 4034.5
A29: 41240 | B29: 0 | C29: 20 | D29: 0 | E29: 0 | F29: 0 | G29: 0 | H29: 4034.52
A30: 41241 | B30: 0 | C30: 20 | D30: 0 | E30: 0 | F30: 0 | G30: 194 | H30: 4034.54 | I30: *2 units on at approx 9AM
A31: 41242 | B31: 0 | C31: 20 | D31: 0 | E31: 0.02 | F31: 0 | G31: 319 | H31: 4034.54
A32: 41243 | B32: 0 | C32: 20 | D32: 0 | E32: 0.82 | F32: 0 | G32: 319 | H32: 4034.55
A33: Monthly Total | B33: =SUM(B3:B32) -> 1202 | C33: =SUM(C3:C32) -> 232 | D33: =SUM(D3:D32) -> 1697 | E33: =SUM(E3:E32) -> 1.73 | F33: =SUM(F3:F32) -> 1 | G33: =SUM(G3:G32) -> 4546
A34: WY Total | B34: =SUM(B33+'Oct 2012'!B35) -> 2409 | C34: =SUM(C33+'Oct 2012'!C35) -> 1210 | D34: =SUM(D33+'Oct 2012'!D35) -> 6025 | E34: =SUM(E33+'Oct 2012'!E35) -> 2.27 | F34: =SUM(F33+'Oct 2012'!F35) -> 1.75 | G34: =SUM(G33+'Oct 2012'!G35) -> 12413
A36: Acre Feet | B36: =SUM(B3:B32)*1.9835 -> 2384.167 | C36: =SUM(C3:C32)*1.9835 -> 460.172 | D36: =SUM(D3:D32)*1.9835 -> 3365.9995
A38: WY AF Total | B38: =SUM('Oct 2012'!B39+B36) -> 4778.2515 | C38: =SUM('Oct 2012'!C39+C36) -> 2400.035 | D38: =SUM('Oct 2012'!D39+D36) -> 11950.587
G40: * COMPUTATIONAL PURPOSES ONLY! Do Not Enter Data in the Red Columns
A42: *This is computation purposes only for Station 48
A43: Sta 48
F44: =SUM(24-D44) -> 24 | G44: =SUM(C44+E44) -> 0 | H44: =SUM(C44/24*D44+G44/24*F44) -> 0
...

Sheet Oct 2012
A1: DATE | B1: STATION 48 | C1: ANDERSON-ROSE | D1: J CANAL | E1: TULE LAKE PRECIP | F1: TULE LAKE SNOW | G1: D PLANT | H1: TULE LAKE ELEV. | I1: CHANGES @ STATION 48
B2: (in CFS) | C2: (in CFS) | D2: (in CFS)
A3: 41183 | B3: 9 | C3: 35 | D3: 182 | E3: 0 | F3: 0 | G3: 0 | H3: 4034.9 | I3: *11 AM 20/0
A4: 41184 | B4: 0 | C4: 0 | D4: 189 | E4: 0 | F4: 0 | G4: 0 | H4: 4034.9
A5: 41185 | B5: 0 | C5: 0 | D5: 171 | E5: 0 | F5: 0 | G5: 63 | H5: 4034.9
A6: 41186 | B6: 0 | C6: 29 | D6: 156 | E6: 0 | F6: 0 | G6: 160 | H6: 4034.9
A7: 41187 | B7: 0 | C7: 47 | D7: 157 | E7: 0 | F7: 0 | G7: 160 | H7: 4034.9
A8: 41188 | B8: 0 | C8: 54 | D8: 144 | E8: 0 | F8: 0 | G8: 160 | H8: 4034.9
A9: 41189 | B9: 0 | C9: 81 | D9: 128 | E9: 0 | F9: 0 | G9: 158 | H9: 4034.9
A10: 41190 | B10: 0 | C10: 102 | D10: 119 | E10: 0 | F10: 0 | G10: 243 | H10: 4034.9 | I10: * 2nd unit at D Started at 9:48 AM
A11: 41191 | B11: 0 | C11: 75 | D11: 119 | E11: 0 | F11: 0 | G11: 301 | H11: 4034.9
A12: 41192 | B12: 0 | C12: 70 | D12: 122 | E12: 0 | F12: 0 | G12: 301 | H12: 4034.88
A13: 41193 | B13: 0 | C13: 65 | D13: 127 | E13: 0 | F13: 0 | G13: 301 | H13: 4034.87
A14: 41194 | B14: 0 | C14: 63 | D14: 109 | E14: 0 | F14: 0 | G14: 301 | H14: 4034.85
A15: 41195 | B15: 0 | C15: 75 | D15: 96 | E15: 0.02 | F15: 0 | G15: 301 | H15: 4034.84
A16: 41196 | B16: 0 | C16: 95 | D16: 103 | E16: 0 | F16: 0 | G16: 301 | H16: 4034.83
A17: 41197 | B17: 0 | C17: 84 | D17: 111 | E17: 0 | F17: 0 | G17: 301 | H17: 4034.82
A18: 41198 | B18: 0 | C18: 55 | D18: 126 | E18: 0.06 | F18: 0 | G18: 301 | H18: 4034.81
A19: 41199 | B19: 0 | C19: 35 | D19: 136 | E19: 0 | F19: 0 | G19: 301 | H19: 4034.8
A20: 41200 | B20: 0 | C20: 13 | D20: 150 | E20: 0 | F20: 0 | G20: 301 | H20: 4034.79
A21: 41201 | B21: 17 | C21: 0 | D21: 162 | E21: 0 | F21: 0 | G21: 301 | H21: 4034.78 | I21: *4 PM 0/50
A22: 41202 | B22: 73 | C22: 0 | D22: 169 | E22: 0.02 | F22: 0 | G22: 301 | H22: 4034.77 | I22: *1 PM 50/100
A23: 41203 | B23: 131 | C23: 0 | D23: 152 | E23: 0 | F23: 0 | G23: 301 | H23: 4034.76 | I23: *9 AM 100/150
A24: 41204 | B24: 150 | C24: 0 | D24: 138 | E24: 0.02 | F24: 0 | G24: 301 | H24: 4034.72
A25: 41205 | B25: 150 | C25: 0 | D25: 139 | E25: 0.16 | F25: 0.25 | G25: 301 | H25: 4034.68
A26: 41206 | B26: 83 | C26: 0 | D26: 149 | E26: 0.16 | F26: 0.5 | G26: 301 | H26: 4034.65 | I26: *8 AM 150/50
A27: 41207 | B27: 50 | C27: 0 | D27: 116 | E27: 0.07 | F27: T | G27: 301 | H27: 4034.62
A28: 41208 | B28: 50 | C28: 0 | D28: 123 | E28: 0.01 | F28: 0 | G28: 301 | H28: 4034.6
A29: 41209 | B29: 67 | C29: 0 | D29: 129 | E29: 0 | F29: 0 | G29: 301 | H29: 4034.58 | I29: *8 AM 50/75
A30: 41210 | B30: 92 | C30: 0 | D30: 136 | E30: 0.01 | F30: 0 | G30: 301 | H30: 4034.56 | I30: *8 AM 75/100
A31: 41211 | B31: 100 | C31: 0 | D31: 150 | E31: 0.01 | F31: 0 | G31: 301 | H31: 4034.55
A32: 41212 | B32: 100 | C32: 0 | D32: 160 | E32: 0 | F32: 0 | G32: 301 | H32: 4034.54
A33: 41213 | B33: 135 | C33: 0 | D33: 160 | E33: T | F33: 0 | G33: 301 | H33: 4034.53 | I33: *7 AM 100/150
A34: Monthly Total | B34: =SUM(B3:B33) -> 1207 | C34: =SUM(C3:C33) -> 978 | D34: =SUM(D3:D33) -> 4328 | E34: =SUM(E3:E33) -> 0.54 | F34: =SUM(F3:F33) -> 0.75 | G34: =SUM(G3:G33) -> 7867
A35: WY Total | B35: =SUM(B34+'Oct 2012'!B36) -> 1207 | C35: =SUM(C34+'Oct 2012'!C36) -> 978 | D35: =SUM(D34+'Oct 2012'!D36) -> 4328 | E35: =SUM(E34+'Oct 2012'!E36) -> 0.54 | F35: =SUM(F34+'Oct 2012'!F36) -> 0.75 | G35: =SUM(G34+'Oct 2012'!G36) -> 7867
A37: Acre Feet | B37: =SUM(B3:B33)*1.9835 -> 2394.0845 | C37: =SUM(C3:C33)*1.9835 -> 1939.863 | D37: =SUM(D3:D33)*1.9835 -> 8584.588
A39: WY AF Total | B39: =SUM('Oct 2012'!B40+B37) -> 2394.0845 | C39: =SUM('Oct 2012'!C40+C37) -> 1939.863 | D39: =SUM('Oct 2012'!D40+D37) -> 8584.588
G41: * COMPUTATIONAL PURPOSES ONLY! Do Not Enter Data in the Red Columns
A43: *This is computation purposes only for Station 48
A44: Sta 48
...
