Workbook

Sheet Sep 2016
A1: DATE | B1: STATION 48 | C1: ANDERSON-ROSE | D1: J CANAL | E1: TULE LAKE PRECIP | F1: TULE LAKE SNOW | G1: D PLANT | H1: TULE LAKE ELEV. | I1: CHANGES @ STATION 48
B2: (in CFS) | C2: (in CFS) | D2: (in CFS) | G2: (in AF)
A3: 42614 | B3: 163 | C3: 0 | D3: 300 | E3: 0 | F3: 0 | G3: 0 | H3: 4034.62 | I3: *1800 150/200
A4: 42615 | B4: 235 | C4: 0 | D4: 337 | E4: 0 | F4: 0 | G4: 0 | H4: 4034.61 | I4: *0700 200/250
A5: 42616 | B5: 267 | C5: 0 | D5: 328 | E5: 0 | F5: 0 | G5: 0 | H5: 4034.61 | I5: *0600 250/300 *1400 300/250
A6: 42617 | B6: 196 | C6: 15 | D6: 330 | E6: 0 | F6: 0 | G6: 0 | H6: 4034.61 | I6: *0800 250/200 *1400 200/150
A7: 42618 | B7: 175 | C7: 4 | D7: 278 | E7: 0 | F7: 0 | G7: 0 | H7: 4034.61 | I7: *1000 150/250 * 1600 250/150
A8: 42619 | B8: 129 | C8: 0 | D8: 235 | E8: 0 | F8: 0 | G8: 0 | H8: 4034.62 | I8: *1400 150/100
A9: 42620 | B9: 100 | C9: 0 | D9: 214 | E9: 0 | F9: 0 | G9: 0 | H9: 4034.62
A10: 42621 | B10: 171 | C10: 0 | D10: 217 | E10: 0 | F10: 0 | G10: 0 | H10: 4034.62 | I10: *0700 100/200
A11: 42622 | B11: 151 | C11: 0 | D11: 216 | E11: 0 | F11: 0 | G11: 0 | H11: 4034.62 | I11: *10:30 200/150 *14:00 150/100
A12: 42623 | B12: 83 | C12: 11 | D12: 191 | E12: 0 | F12: 0 | G12: 0 | H12: 4034.61 | I12: *16:00 100/50
A13: 42624 | B13: 67 | C13: 1 | D13: 208 | E13: 0 | F13: 0 | G13: 0 | H13: 4034.61 | I13: *16:00 50/100
A14: 42625 | B14: 67 | C14: 3 | D14: 262 | E14: 0 | F14: 0 | G14: 0 | H14: 4034.63 | I14: 08:00 100/50
A15: 42626 | B15: 71 | C15: 0 | D15: 276 | E15: 0 | F15: 0 | G15: 0 | H15: 4034.64 | I15: *1400 50/100
A16: 42627 | B16: 100 | C16: 0 | D16: 253 | E16: 0 | F16: 0 | G16: 0 | H16: 4034.65
A17: 42628 | B17: 148 | C17: 0 | D17: 195 | E17: 0 | F17: 0 | G17: 0 | H17: 4034.66 | I17: * 08:30 100/200 *1600 200/150
A18: 42629 | B18: 116 | C18: 0 | D18: 183 | E18: 0 | F18: 0 | G18: 0 | H18: 4034.67 | I18: * 0730 150/100
A19: 42630 | B19: 70 | C19: 28 | D19: 197 | E19: 0 | F19: 0 | G19: 0 | H19: 4034.69 | I19: * 0930 100/50
A20: 42631 | B20: 30 | C20: 45 | D20: 188 | E20: 0 | F20: 0 | G20: 0 | H20: 4034.7 | I20: * 0800 50/20
A21: 42632 | B21: 11 | C21: 16 | D21: 168 | E21: 0 | F21: 0 | G21: 0 | H21: 4034.7 | I21: * 1330 20/0
A22: 42633 | B22: 0 | C22: 0 | D22: 167 | E22: 0 | F22: 0 | G22: 0 | H22: 4034.71
A23: 42634 | B23: 0 | C23: 0 | D23: 180 | E23: 0 | F23: 0 | G23: 0 | H23: 4034.72
A24: 42635 | B24: 0 | C24: 0 | D24: 166 | E24: 0.02 | F24: 0 | G24: 0 | H24: 4034.73
A25: 42636 | B25: 0 | C25: 0 | D25: 166 | E25: 0.01 | F25: 0 | G25: 0 | H25: 4034.74
A26: 42637 | B26: 0 | C26: 0 | D26: 148 | E26: 0.01 | F26: 0 | G26: 0 | H26: 4034.74
A27: 42638 | B27: 0 | C27: 8 | D27: 147 | E27: 0 | F27: 0 | G27: 0 | H27: 4034.75
A28: 42639 | B28: 0 | C28: 12 | D28: 161 | E28: 0 | F28: 0 | G28: 103 | H28: 4034.77 | I28: * Start 1 unit D-Plant Apprx. 0900
A29: 42640 | B29: 0 | C29: 0 | D29: 141 | E29: 0 | F29: 0 | G29: 160 | H29: 4034.75
A30: 42641 | B30: 17 | C30: 0 | D30: 151 | E30: 0 | F30: 0 | G30: 160 | H30: 4034.75 | I30: * 1600 0/50
A31: 42642 | B31: 29 | C31: 0 | D31: 160 | E31: 0 | F31: 0 | G31: 160 | H31: 4034.74 | I31: * 0700 50/20
A32: 42643 | B32: 8 | C32: 0 | D32: 153 | E32: 0 | F32: 0 | G32: 160 | H32: 4034.73 | I32: * 0930 20/0
A33: Monthly Total | B33: =SUM(B3:B32) -> 2404 | C33: =SUM(C3:C32) -> 143 | D33: =SUM(D3:D32) -> 6316 | E33: =SUM(E3:E32) -> 0.04 | F33: =SUM(F3:F32) -> 0 | G33: =SUM(G3:G32) -> 743
A34: WY Total | B34: =SUM(B33+'Aug 2016'!B35) -> 33664 | C34: =SUM(C33+'Aug 2016'!C35) -> 6346 | D34: =SUM(D33+'Aug 2016'!D35) -> 61560 | E34: =SUM(E33+'Aug 2016'!E35) -> 12.51 | F34: =SUM(F33+'Aug 2016'!F35) -> 22.69 | G34: =SUM(G33+'Aug 2016'!G35) -> 21925
A36: Acre Feet | B36: =SUM(B3:B32)*1.9835 -> 4768.334 | C36: =SUM(C3:C32)*1.9835 -> 283.6405 | D36: =SUM(D3:D32)*1.9835 -> 12527.786
A38: WY AF Total | B38: =SUM(B36+'Aug 2016'!B39) -> 69093.239 | C38: =SUM(C36+'Aug 2016'!C39) -> 13830.946 | D38: =SUM(D36+'Aug 2016'!D39) -> 129056.43
G40: * COMPUTATIONAL PURPOSES ONLY! Do Not Enter Data in the Red Columns
A42: *This is computation purposes only for Station 48
A43: Sta 48
F44: =SUM(24-D44) -> 24 | G44: =SUM(C44+E44) -> 0 | H44: =SUM(C44/24*D44+G44/24*F44) -> 0
...

Sheet Aug 2016
A1: DATE | B1: STATION 48 | C1: ANDERSON-ROSE | D1: J CANAL | E1: TULE LAKE PRECIP | F1: TULE LAKE SNOW | G1: D PLANT | H1: TULE LAKE ELEV. | I1: CHANGES @ STATION 48
B2: (in CFS) | C2: (in CFS) | D2: (in CFS) | G2: (in AF)
A3: 42583 | B3: 217 | C3: 0 | D3: 398 | E3: 0 | F3: 0 | G3: 0 | H3: 4034.64 | I3: * 16:00 200/250
A4: 42584 | B4: 250 | C4: 0 | D4: 408 | E4: 0 | F4: 0 | G4: 0 | H4: 4034.63
A5: 42585 | B5: 297 | C5: 0 | D5: 413 | E5: 0 | F5: 0 | G5: 0 | H5: 4034.62 | I5: * 09:30 250/350 * 17:30 350/300
A6: 42586 | B6: 277 | C6: 0 | D6: 421 | E6: 0 | F6: 0 | G6: 0 | H6: 4034.62 | I6: * 07:00 300/250 * 18:00 250/300
A7: 42587 | B7: 262 | C7: 0 | D7: 393 | E7: 0 | F7: 0 | G7: 0 | H7: 4034.62 | I7: * 15:00 300/200
A8: 42588 | B8: 188 | C8: 0 | D8: 346 | E8: T | F8: 0 | G8: 0 | H8: 4034.61 | I8: * 18:00 200/150
A9: 42589 | B9: 206 | C9: 0 | D9: 318 | E9: 0 | F9: 0 | G9: 0 | H9: 4034.61 | I9: * 0700 150/250 * 1700 250/200
A10: 42590 | B10: 200 | C10: 0 | D10: 321 | E10: 0 | F10: 0 | G10: 0 | H10: 4034.62
A11: 42591 | B11: 200 | C11: 0 | D11: 361 | E11: 0 | F11: 0 | G11: 0 | H11: 4034.62
A12: 42592 | B12: 200 | C12: 0 | D12: 370 | E12: 0 | F12: 0 | G12: 0 | H12: 4034.63
A13: 42593 | B13: 200 | C13: 0 | D13: 372 | E13: 0 | F13: 0 | G13: 0 | H13: 4034.62
A14: 42594 | B14: 219 | C14: 0 | D14: 372 | E14: 0 | F14: 0 | G14: 0 | H14: 4034.62 | I14: *0700 200/300 *1500 300/200 *1700 200/150
A15: 42595 | B15: 150 | C15: 0 | D15: 307 | E15: 0 | F15: 0 | G15: 0 | H15: 4034.63
A16: 42596 | B16: 198 | C16: 0 | D16: 308 | E16: 0 | F16: 0 | G16: 0 | H16: 4034.62 | I16: * 07:00 150/200 *18:00 200/250
A17: 42597 | B17: 223 | C17: 0 | D17: 357 | E17: 0 | F17: 0 | G17: 0 | H17: 4034.62 | I17: *11:00 250/200
A18: 42598 | B18: 200 | C18: 0 | D18: 401 | E18: 0 | F18: 0 | G18: 0 | H18: 4034.62
A19: 42599 | B19: 263 | C19: 0 | D19: 432 | E19: 0 | F19: 0 | G19: 0 | H19: 4034.63 | I19: *0900 200/300
A20: 42600 | B20: 288 | C20: 0 | D20: 434 | E20: 0 | F20: 0 | G20: 0 | H20: 4034.62 | I20: *1800 300/250
A21: 42601 | B21: 271 | C21: 0 | D21: 420 | E21: 0 | F21: 0 | G21: 0 | H21: 4034.63 | I21: *0700 250/300 *1700 300/250
A22: 42602 | B22: 252 | C22: 0 | D22: 427 | E22: 0 | F22: 0 | G22: 0 | H22: 4034.62 | I22: *0700 250/200 *1500 200/300
A23: 42603 | B23: 254 | C23: 0 | D23: 453 | E23: 0 | F23: 0 | G23: 0 | H23: 4034.62 | I23: *0700 300/200 *1800 200/300
A24: 42604 | B24: 233 | C24: 0 | D24: 464 | E24: 0 | F24: 0 | G24: 0 | H24: 4034.62 | I24: *0800 300/200
A25: 42605 | B25: 271 | C25: 0 | D25: 445 | E25: 0 | F25: 0 | G25: 0 | H25: 4034.62 | I25: *0700 200/300
A26: 42606 | B26: 300 | C26: 0 | D26: 439 | E26: 0 | F26: 0 | G26: 0 | H26: 4034.62
A27: 42607 | B27: 252 | C27: 0 | D27: 435 | E27: 0 | F27: 0 | G27: 0 | H27: 4034.63 | I27: *0700 300/250 *1800 250/200
A28: 42608 | B28: 235 | C28: 0 | D28: 428 | E28: 0 | F28: 0 | G28: 0 | H28: 4034.63 | I28: *0700 200/250
A29: 42609 | B29: 262 | C29: 0 | D29: 430 | E29: 0 | F29: 0 | G29: 0 | H29: 4034.62 | I29: *1800 250/300
A30: 42610 | B30: 281 | C30: 0 | D30: 404 | E30: 0 | F30: 0 | G30: 0 | H30: 4034.62 | I30: *1500 300/250
A31: 42611 | B31: 219 | C31: 0 | D31: 382 | E31: 0 | F31: 0 | G31: 0 | H31: 4034.61 | I31: *0900 250/200
A32: 42612 | B32: 219 | C32: 0 | D32: 383 | E32: T | F32: 0 | G32: 0 | H32: 4034.61 | I32: *0700 200/250 *1600 250/200
A33: 42613 | B33: 183 | C33: 5 | D33: 349 | E33: 0 | F33: 0 | G33: 0 | H33: 4034.62 | I33: *1600 200/150
A34: Monthly Total | B34: =SUM(B3:B33) -> 7270 | C34: =SUM(C3:C33) -> 5 | D34: =SUM(D3:D33) -> 12191 | E34: =SUM(E3:E33) -> 0 | F34: =SUM(F3:F33) -> 0 | G34: =SUM(G3:G33) -> 0
A35: WY Total | B35: =SUM(B34+'Jul 2016'!B35) -> 31260 | C35: =SUM(C34+'Jul 2016'!C35) -> 6203 | D35: =SUM(D34+'Jul 2016'!D35) -> 55244 | E35: =SUM(E34+'Jul 2016'!E35) -> 12.47 | F35: =SUM(F34+'Jul 2016'!F35) -> 22.69 | G35: =SUM(G34+'Jul 2016'!G35) -> 21182
A37: Acre Feet | B37: =SUM(B3:B33)*1.9835 -> 14420.045 | C37: =SUM(C3:C33)*1.9835 -> 9.9175 | D37: =SUM(D3:D33)*1.9835 -> 24180.849
A39: WY AF Total | B39: =SUM(B37+'Jul 2016'!B39) -> 64324.905 | C39: =SUM(C37+'Jul 2016'!C39) -> 13547.305 | D39: =SUM(D37+'Jul 2016'!D39) -> 116528.64
G41: * COMPUTATIONAL PURPOSES ONLY! Do Not Enter Data in the Red Columns
A43: *This is computation purposes only for Station 48
A44: Sta 48
...

Sheet Jul 2016
A1: DATE | B1: STATION 48 | C1: ANDERSON-ROSE | D1: J CANAL | E1: TULE LAKE PRECIP | F1: TULE LAKE SNOW | G1: D PLANT | H1: TULE LAKE ELEV. | I1: CHANGES @ STATION 48
B2: (in CFS) | C2: (in CFS) | D2: (in CFS) | G2: (in AF)
A3: 42552 | B3: 367 | C3: 0 | D3: 406 | E3: 0 | F3: 0 | G3: 0 | H3: 4034.94 | I3: * 08:00 400/350
A4: 42553 | B4: 317 | C4: 3 | D4: 400 | E4: 0 | F4: 0 | G4: 0 | H4: 4034.94 | I4: * 16:00 350/250
A5: 42554 | B5: 217 | C5: 6 | D5: 358 | E5: 0 | F5: 0 | G5: 0 | H5: 4034.94 | I5: * 15:00 250/200 *17:00 200/150
A6: 42555 | B6: 165 | C6: 0 | D6: 299 | E6: 0 | F6: 0 | G6: 0 | H6: 4034.94 | I6: * 17:00 150/200
A7: 42556 | B7: 218 | C7: 0 | D7: 337 | E7: 0 | F7: 0 | G7: 0 | H7: 4034.94 | I7: * 15:30 200/250
A8: 42557 | B8: 250 | C8: 0 | D8: 360 | E8: 0 | F8: 0 | G8: 0 | H8: 4034.94
A9: 42558 | B9: 295 | C9: 0 | D9: 383 | E9: 0 | F9: 0 | G9: 0 | H9: 4034.93 | I9: * 10:00 250/350 * 17:30 350/300
A10: 42559 | B10: 286 | C10: 0 | D10: 407 | E10: 0 | F10: 0 | G10: 0 | H10: 4034.92 | I10: * 17:30 300/250
A11: 42560 | B11: 238 | C11: 0 | D11: 397 | E11: 0.05 | F11: 0 | G11: 0 | H11: 4034.92 | I11: * 18:00 250/200
A12: 42561 | B12: 200 | C12: 0 | D12: 385 | E12: 0.02 | F12: 0 | G12: 0 | H12: 4034.91
A13: 42562 | B13: 271 | C13: 0 | D13: 420 | E13: 0 | F13: 0 | G13: 0 | H13: 4034.9 | I13: * 07:00 200/300
A14: 42563 | B14: 269 | C14: 0 | D14: 391 | E14: 0 | F14: 0 | G14: 0 | H14: 4034.9 | I14: * 09:00 300/250
A15: 42564 | B15: 263 | C15: 0 | D15: 395 | E15: 0 | F15: 0 | G15: 0 | H15: 4034.92 | I15: * 18:00 250/300
A16: 42565 | B16: 313 | C16: 0 | D16: 373 | E16: 0 | F16: 0 | G16: 0 | H16: 4034.92 | I16: * 07:30 300/400 *15:00 400/250
A17: 42566 | B17: 246 | C17: 0 | D17: 318 | E17: 0 | F17: 0 | G17: 0 | H17: 4034.9 | I17: *09:00 250/300 *15:30 300/200
A18: 42567 | B18: 193 | C18: 9 | D18: 319 | E18: 0 | F18: 0 | G18: 0 | H18: 4034.88 | I18: *20:30 200/150
A19: 42568 | B19: 161 | C19: 0 | D19: 321 | E19: 0 | F19: 0 | G19: 0 | H19: 4034.86 | I19: *18:30 150/200
A20: 42569 | B20: 217 | C20: 0 | D20: 402 | E20: 0 | F20: 0 | G20: 0 | H20: 4034.85 | I20: * 16:00 200/250
A21: 42570 | B21: 285 | C21: 0 | D21: 421 | E21: 0 | F21: 0 | G21: 0 | H21: 4034.84 | I21: * 15:30 250/350
A22: 42571 | B22: 375 | C22: 0 | D22: 431 | E22: 0 | F22: 0 | G22: 0 | H22: 4034.83 | I22: * 03:00 350/450 *09:00 450/350
A23: 42572 | B23: 350 | C23: 0 | D23: 441 | E23: 0 | F23: 0 | G23: 0 | H23: 4034.82
A24: 42573 | B24: 350 | C24: 0 | D24: 474 | E24: 0 | F24: 0 | G24: 0 | H24: 4034.81
A25: 42574 | B25: 350 | C25: 0 | D25: 489 | E25: 0 | F25: 0 | G25: 0 | H25: 4034.8
A26: 42575 | B26: 331 | C26: 0 | D26: 469 | E26: 0 | F26: 0 | G26: 0 | H26: 4034.79 | I26: * 15:00 350/300
A27: 42576 | B27: 300 | C27: 0 | D27: 462 | E27: 0 | F27: 0 | G27: 0 | H27: 4034.78
A28: 42577 | B28: 252 | C28: 24 | D28: 450 | E28: 0 | F28: 0 | G28: 0 | H28: 4034.75 | I28: * 10:00 300/250 *15:00 250/200
A29: 42578 | B29: 271 | C29: 2 | D29: 438 | E29: 0 | F29: 0 | G29: 0 | H29: 4034.72 | I29: * 07:00 200/300
A30: 42579 | B30: 300 | C30: 0 | D30: 416 | E30: 0 | F30: 0 | G30: 0 | H30: 4034.7
A31: 42580 | B31: 330 | C31: 0 | D31: 421 | E31: 0 | F31: 0 | G31: 0 | H31: 4034.68 | I31: * 07:30 300/350 *08:00 350/400 * 15:00 400/300
A32: 42581 | B32: 263 | C32: 0 | D32: 373 | E32: 0 | F32: 0 | G32: 0 | H32: 4034.66 | I32: * 15:00 300/200
A33: 42582 | B33: 200 | C33: 0 | D33: 363 | E33: 0 | F33: 0 | G33: 0 | H33: 4034.64
A34: Monthly Total | B34: =SUM(B3:B33) -> 8443 | C34: =SUM(C3:C33) -> 44 | D34: =SUM(D3:D33) -> 12319 | E34: =SUM(E3:E33) -> 0.07 | F34: =SUM(F3:F33) -> 0 | G34: =SUM(G3:G33) -> 0
A35: WY Total | B35: =SUM(B34+'Jun 2016'!B34) -> 23990 | C35: =SUM(C34+'Jun 2016'!C34) -> 6198 | D35: =SUM(D34+'Jun 2016'!D34) -> 43053 | E35: =SUM(E34+'Jun 2016'!E34) -> 12.47 | F35: =SUM(F34+'Jun 2016'!F34) -> 22.69 | G35: =SUM(G34+'Jun 2016'!G34) -> 21182
A37: Acre Feet | B37: =SUM(B3:B33)*1.9835 -> 16746.691 | C37: =SUM(C3:C33)*1.9835 -> 87.274 | D37: =SUM(D3:D33)*1.9835 -> 24434.736
A39: WY AF Total | B39: =SUM(B37+'Jun 2016'!B38) -> 49904.86 | C39: =SUM(C37+'Jun 2016'!C38) -> 13537.388 | D39: =SUM(D37+'Jun 2016'!D38) -> 92347.793
G41: * COMPUTATIONAL PURPOSES ONLY! Do Not Enter Data in the Red Columns
A43: *This is computation purposes only for Station 48
A44: Sta 48
...

Sheet Jun 2016
A1: DATE | B1: STATION 48 | C1: ANDERSON-ROSE SPILL | D1: J CANAL | E1: TULE LAKE PRECIP | F1: TULE LAKE SNOW | G1: D PLANT | H1: TULE LAKE ELEV. | I1: CHANGES @ STATION 48
B2: (in CFS) | C2: (in CFS) | D2: (in CFS) | G2: (in AF)
A3: 42522 | B3: 220 | C3: 0 | D3: 336 | E3: 0 | F3: 0 | G3: 301 | H3: 4035.15 | I3: *14:30 200/250
A4: 42523 | B4: 233 | C4: 0 | D4: 371 | E4: 0 | F4: 0 | G4: 301 | H4: 4035.14 | I4: * 16:00 250/200
A5: 42524 | B5: 200 | C5: 0 | D5: 368 | E5: 0 | F5: 0 | G5: 301 | H5: 4035.1
A6: 42525 | B6: 200 | C6: 0 | D6: 367 | E6: 0 | F6: 0 | G6: 301 | H6: 4035.06
A7: 42526 | B7: 186 | C7: 0 | D7: 331 | E7: 0 | F7: 0 | G7: 301 | H7: 4035 | I7: *17:30 200/150
A8: 42527 | B8: 150 | C8: 6 | D8: 344 | E8: 0 | F8: 0 | G8: 101 | H8: 4035 | I8: * 8:00 AM 2 Units Off
A9: 42528 | B9: 258 | C9: 0 | D9: 403 | E9: 0 | F9: 0 | G9: 0 | H9: 4035 | I9: *09:30 150/200 *11:30 200/300 *15:30 300/350 *20:00 350/400
A10: 42529 | B10: 427 | C10: 0 | D10: 496 | E10: 0 | F10: 0 | G10: 0 | H10: 4035 | I10: * 17:30 400/500
A11: 42530 | B11: 444 | C11: 0 | D11: 535 | E11: 0 | F11: 0 | G11: 0 | H11: 4035 | I11: * 07:00 500/400 * 17:00 400/450
A12: 42531 | B12: 450 | C12: 0 | D12: 608 | E12: 0 | F12: 0 | G12: 0 | H12: 4035
A13: 42532 | B13: 410 | C13: 3 | D13: 541 | E13: 0 | F13: 0 | G13: 0 | H13: 4034.98 | I13: * 14:30 450/350
A14: 42533 | B14: 394 | C14: 3 | D14: 514 | E14: 0 | F14: 0 | G14: 0 | H14: 4034.98 | I14: * 10:00 350/450 * 17:00 450/400
A15: 42534 | B15: 379 | C15: 6 | D15: 556 | E15: 0 | F15: 0 | G15: 0 | H15: 4034.98 | I15: * 07:00 400/350 * 17:00 350/400
A16: 42535 | B16: 423 | C16: 0 | D16: 549 | E16: 0 | F16: 0 | G16: 0 | H16: 4034.98 | I16: * 13:00 400/450
A17: 42536 | B17: 450 | C17: 0 | D17: 513 | E17: 0.23 | F17: 0 | G17: 0 | H17: 4034.97
A18: 42537 | B18: 435 | C18: 0 | D18: 484 | E18: 0.18 | F18: 0 | G18: 0 | H18: 4034.96 | I18: * 20:30 450/350
A19: 42538 | B19: 350 | C19: 0 | D19: 456 | E19: 0.2 | F19: 0 | G19: 0 | H19: 4034.96
A20: 42539 | B20: 250 | C20: 13 | D20: 370 | E20: 0.8 | F20: 0 | G20: 0 | H20: 4035 | I20: * 09:00 350/250 *15:00 250/150
A21: 42540 | B21: 150 | C21: 20 | D21: 270 | E21: 0.01 | F21: 0 | G21: 0 | H21: 4035.02
A22: 42541 | B22: 97 | C22: 18 | D22: 246 | E22: 0 | F22: 0 | G22: 0 | H22: 4035.05 | I22: * 08:30 150/100 * 14:00 100/50
A23: 42542 | B23: 81 | C23: 0 | D23: 236 | E23: 0 | F23: 0 | G23: 0 | H23: 40235.06 | I23: * 09:00 50/100
A24: 42543 | B24: 169 | C24: 0 | D24: 250 | E24: 0 | F24: 0 | G24: 0 | H24: 4035.07 | I24: * 08:00 100/150 *15:30 150/250
A25: 42544 | B25: 221 | C25: 0 | D25: 325 | E25: 0 | F25: 0 | G25: 0 | H25: 4035.06 | I25: * 09:00 250/150 *16:00 150/250
A26: 42545 | B26: 384 | C26: 0 | D26: 407 | E26: 0 | F26: 0 | G26: 0 | H26: 4035.04 | I26: * 08:30 250/400 *15:00 400/500
A27: 42546 | B27: 379 | C27: 0 | D27: 448 | E27: 0 | F27: 0 | G27: 0 | H27: 4035.02 | I27: * 07:00 500/350 * 17:00 350/300
A28: 42547 | B28: 300 | C28: 12 | D28: 395 | E28: 0 | F28: 0 | G28: 0 | H28: 4035
A29: 42548 | B29: 285 | C29: 6 | D29: 411 | E29: 0 | F29: 0 | G29: 0 | H29: 4035 | I29: * 17:00 300/250
A30: 42549 | B30: 363 | C30: 0 | D30: 456 | E30: 0 | F30: 0 | G30: 0 | H30: 4034.98 | I30: * 07:00 250/350 * 14:00 350/450
A31: 42550 | B31: 365 | C31: 0 | D31: 462 | E31: 0 | F31: 0 | G31: 0 | H31: 4034.96 | I31: * 07:00 450/350 * 17:00 350/300
A32: 42551 | B32: 352 | C32: 0 | D32: 437 | E32: 0 | F32: 0 | G32: 0 | H32: 4034.95 | I32: * 11:30 300/400
A33: Monthly Total | B33: =SUM(B3:B32) -> 9005 | C33: =SUM(C3:C32) -> 87 | D33: =SUM(D3:D32) -> 12485 | E33: =SUM(E3:E32) -> 1.42 | F33: =SUM(F3:F32) -> 0 | G33: =SUM(G3:G32) -> 1606
A34: WY Total | B34: =SUM(B33+'May 2016'!B35) -> 15547 | C34: =SUM(C33+'May 2016'!C35) -> 6154 | D34: =SUM(D33+'May 2016'!D35) -> 30734 | E34: =SUM(E33+'May 2016'!E35) -> 12.4 | F34: =SUM(F33+'May 2016'!F35) -> 22.69 | G34: =SUM(G33+'May 2016'!G35) -> 21182
A36: Acre Feet | B36: =SUM(B3:B32)*1.9835 -> 17861.417 | C36: =SUM(C3:C32)*1.9835 -> 172.5645 | D36: =SUM(D3:D32)*1.9835 -> 24763.998
A38: WY AF Total | B38: =SUM(B36+'May 2016'!B39) -> 33158.17 | C38: =SUM(C36+'May 2016'!C39) -> 13450.114 | D38: =SUM(D36+'May 2016'!D39) -> 67913.057
G40: * COMPUTATIONAL PURPOSES ONLY! Do Not Enter Data in the Red Columns
A42: *This is computation purposes only for Station 48
A43: Sta 48
F44: =SUM(24-D44) -> 24 | G44: =SUM(C44+E44) -> 0 | H44: =SUM(C44/24*D44+G44/24*F44) -> 0
...

Sheet May 2016
A1: DATE | B1: STATION 48 | C1: ANDERSON-ROSE SPILL | D1: J CANAL | E1: TULE LAKE PRECIP | F1: TULE LAKE SNOW | G1: D PLANT | H1: TULE LAKE ELEV. | I1: CHANGES @ STATION 48
B2: (in CFS) | C2: (in CFS) | D2: (in CFS) | G2: (in AF)
A3: 42491 | B3: 177 | C3: 0 | D3: 283 | E3: 0 | F3: 0 | G3: 0 | H3: 4035.06 | I3: *07:00 100/150 *14:00 150/250
A4: 42492 | B4: 235 | C4: 0 | D4: 347 | E4: 0 | F4: 0 | G4: 0 | H4: 4035.08 | I4: *07:00 250/200 *14:00 200/250
A5: 42493 | B5: 250 | C5: 0 | D5: 372 | E5: 0.01 | F5: 0 | G5: 0 | H5: 4035.1
A6: 42494 | B6: 250 | C6: 0 | D6: 388 | E6: 0.08 | F6: 0 | G6: 0 | H6: 4035.12
A7: 42495 | B7: 264 | C7: 0 | D7: 391 | E7: 0.11 | F7: 0 | G7: 0 | H7: 4035.14 | I7: *08:00 250/300 *14:30 300/250
A8: 42496 | B8: 198 | C8: 27 | D8: 351 | E8: 0.08 | F8: 0 | G8: 0 | H8: 4035.16 | I8: *09:30 250/200 *13:30 200/150
A9: 42497 | B9: 117 | C9: 22 | D9: 292 | E9: 0 | F9: 0 | G9: 0 | H9: 4035.18 | I9: *08:00 150/100
A10: 42498 | B10: 70 | C10: 49 | D10: 242 | E10: 0 | F10: 0 | G10: 0 | H10: 4035.19 | I10: *14:30 100/25
A11: 42499 | B11: 33 | C11: 7 | D11: 213 | E11: 0 | F11: 0 | G11: 0 | H11: 4035.2 | I11: *20:00 25/75
A12: 42500 | B12: 43 | C12: 0 | D12: 221 | E12: 0 | F12: 0 | G12: 0 | H12: 4035.2 | I12: *08:00 75/25 *23:30 25/75
A13: 42501 | B13: 92 | C13: 0 | D13: 227 | E13: 0 | F13: 0 | G13: 0 | H13: 4035.2 | I13: *16:00 75/125
A14: 42502 | B14: 74 | C14: 0 | D14: 207 | E14: 0 | F14: 0 | G14: 0 | H14: 4035.2 | I14: *07:00 125/75 *16:30 75/25
A15: 42503 | B15: 33 | C15: 0 | D15: 201 | E15: 0 | F15: 0 | G15: 0 | H15: 4035.2 | I15: *16:30 25/50
A16: 42504 | B16: 32 | C16: 0 | D16: 193 | E16: 0.08 | F16: 0 | G16: 0 | H16: 4035.2 | I16: *07:00 50/25
A17: 42505 | B17: 25 | C17: 15 | D17: 174 | E17: 0.05 | F17: 0 | G17: 0 | H17: 4035.2
A18: 42506 | B18: 9 | C18: 31 | D18: 205 | E18: 0 | F18: 0 | G18: 0 | H18: 4035.2 | I18: *09:00 25/0
A19: 42507 | B19: 71 | C19: 0 | D19: 248 | E19: 0 | F19: 0 | G19: 0 | H19: 4035.2 | I19: *07:00 0/100
A20: 42508 | B20: 143 | C20: 0 | D20: 278 | E20: 0 | F20: 0 | G20: 0 | H20: 4035.2 | I20: *12:30 100/150 *15:00 150/200
A21: 42509 | B21: 200 | C21: 19 | D21: 292 | E21: 0 | F21: 0 | G21: 0 | H21: 4035.2
A22: 42510 | B22: 85 | C22: 59 | D22: 248 | E22: 0.26 | F22: 0 | G22: 0 | H22: 4035.23 | I22: *08:00 200/100 *08:30 100/25
A23: 42511 | B23: 15 | C23: 49 | D23: 213 | E23: 0.1 | F23: 0 | G23: 0 | H23: 4035.27 | I23: *14:30 25/0
A24: 42512 | B24: 0 | C24: 59 | D24: 151 | E24: 0.06 | F24: 0 | G24: 0 | H24: 4035.3
A25: 42513 | B25: 0 | C25: 95 | D25: 113 | E25: 0.12 | F25: 0 | G25: *188 | H25: 4035.33 | I25: * 9 AM 2 Units ON | J25: * Corrected from 190
A26: 42514 | B26: 0 | C26: 109 | D26: 94 | E26: 0 | F26: 0 | G26: 301 | H26: 4035.32 | I26: *07:00 0/0
A27: 42515 | B27: 0 | C27: 54 | D27: 93 | E27: 0 | F27: 0 | G27: 301 | H27: 4035.31 | I27: *07:00* 0/0
A28: 42516 | B28: 0 | C28: 34 | D28: 117 | E28: 0 | F28: 0 | G28: 301 | H28: 4035.3
A29: 42517 | B29: 0 | C29: 3 | D29: 140 | E29: 0 | F29: 0 | G29: 301 | H29: 4035.28
A30: 42518 | B30: 0 | C30: 0 | D30: 150 | E30: 0 | F30: 0 | G30: 301 | H30: 4035.26
A31: 42519 | B31: 71 | C31: 0 | D31: 200 | E31: 0 | F31: 0 | G31: 301 | H31: 4035.24 | I31: *07:00 0/50 *14:00 50/100 *17:00 100/150
A32: 42520 | B32: 115 | C32: 0 | D32: 265 | E32: 0 | F32: 0 | G32: 301 | H32: 4035.22 | I32: *07:00 150/100
A33: 42521 | B33: 171 | C33: 0 | D33: 283 | E33: 0 | F33: 0 | G33: 301 | H33: 4035.2 | I33: *07:00 100/200
A34: Monthly Total | B34: =SUM(B3:B33) -> 2773 | C34: =SUM(C3:C33) -> 632 | D34: =SUM(D3:D33) -> 7192 | E34: =SUM(E3:E33) -> 0.95 | F34: =SUM(F3:F33) -> 0 | G34: =SUM(G3:G33) -> 2408
A35: WY Total | B35: =SUM(B34+'Apr 2016'!B34) -> 6542 | C35: =SUM(C34+'Apr 2016'!C34) -> 6067 | D35: =SUM(D34+'Apr 2016'!D34) -> 18249 | E35: =SUM(E34+'Apr 2016'!E34) -> 10.98 | F35: =SUM(F34+'Apr 2016'!F34) -> 22.69 | G35: =SUM(G34+'Apr 2016'!G34) -> 19576
A37: Acre Feet | B37: =SUM(B3:B33)*1.9835 -> 5500.2455 | C37: =SUM(C3:C33)*1.9835 -> 1253.572 | D37: =SUM(D3:D33)*1.9835 -> 14265.332
A39: WY AF Total | B39: =SUM(B37+'Apr 2016'!B38) -> 15296.752 | C39: =SUM(C37+'Apr 2016'!C38) -> 13277.549 | D39: =SUM(D37+'Apr 2016'!D38) -> 43149.059
G41: * COMPUTATIONAL PURPOSES ONLY! Do Not Enter Data in the Red Columns
A43: *This is computation purposes only for Station 48
A44: Sta 48
...

Sheet Apr 2016
A1: DATE | B1: STATION 48 | C1: ANDERSON-ROSE | D1: J CANAL | E1: TULE LAKE PRECIP | F1: TULE LAKE SNOW | G1: D PLANT | H1: TULE LAKE ELEV. | I1: CHANGES @ STATION 48
B2: (in CFS) | C2: (in CFS) | D2: (in CFS) | G2: (in AF)
A3: 42461 | B3: 50 | C3: 0 | D3: 64 | E3: 0 | F3: 0 | G3: 0 | H3: 4035
A4: 42462 | B4: 50 | C4: 0 | D4: 64 | E4: 0 | F4: 0 | G4: 0 | H4: 4035
A5: 42463 | B5: 36 | C5: 0 | D5: 68 | E5: 0 | F5: 0 | G5: 0 | H5: 4035 | I5: * 11 AM 50/25
A6: 42464 | B6: 25 | C6: 0 | D6: 54 | E6: 0 | F6: 0 | G6: 0 | H6: 4035
A7: 42465 | B7: 25 | C7: 0 | D7: 57 | E7: 0 | F7: 0 | G7: 0 | H7: 4035
A8: 42466 | B8: 25 | C8: 0 | D8: 57 | E8: 0 | F8: 0 | G8: 0 | H8: 4035
A9: 42467 | B9: 25 | C9: 0 | D9: 52 | E9: 0 | F9: 0 | G9: 0 | H9: 4035
A10: 42468 | B10: 25 | C10: 0 | D10: 56 | E10: 0 | F10: 0 | G10: 0 | H10: 4035.02
A11: 42469 | B11: 25 | C11: 0 | D11: 62 | E11: 0.49 | F11: 0 | G11: 0 | H11: 4035.04
A12: 42470 | B12: 8 | C12: 33 | D12: 69 | E12: 0.19 | F12: 0 | G12: 0 | H12: 4035.04 | I12: * 8 AM 25/0
A13: 42471 | B13: 0 | C13: 35 | D13: 84 | E13: 0.02 | F13: 0 | G13: 0 | H13: 4035.06
A14: 42472 | B14: 0 | C14: 49 | D14: 68 | E14: 0.31 | F14: 0 | G14: 0 | H14: 4035.08
A15: 42473 | B15: 0 | C15: 83 | D15: 61 | E15: 0.3 | F15: 0 | G15: 0 | H15: 4035.09
A16: 42474 | B16: 0 | C16: 106 | D16: 63 | E16: 0.13 | F16: 0 | G16: 0 | H16: 4035.1
A17: 42475 | B17: 0 | C17: 101 | D17: 63 | E17: 0.17 | F17: 0 | G17: 0 | H17: 4035.11
A18: 42476 | B18: 0 | C18: 79 | D18: 58 | E18: 0.01 | F18: 0 | G18: 0 | H18: 4035.12
A19: 42477 | B19: 0 | C19: 62 | D19: 58 | E19: 0 | F19: 0 | G19: 0 | H19: 4035.14
A20: 42478 | B20: 0 | C20: 47 | D20: 67 | E20: 0 | F20: 0 | G20: 0 | H20: 4035.16
A21: 42479 | B21: 0 | C21: 32 | D21: 102 | E21: 0 | F21: 0 | G21: 0 | H21: 4035.16
A22: 42480 | B22: 0 | C22: 0 | D22: 143 | E22: 0 | F22: 0 | G22: 0 | H22: 4035.16
A23: 42481 | B23: 18 | C23: 0 | D23: 150 | E23: 0 | F23: 0 | G23: 0 | H23: 4035.16 | I23: * 3:30 PM 0/50
A24: 42482 | B24: 68 | C24: 0 | D24: 187 | E24: 0.14 | F24: 0 | G24: 0 | H24: 4035.16 | I24: * 3.30 PM 50/100
A25: 42483 | B25: 78 | C25: 0 | D25: 181 | E25: 0 | F25: 0 | G25: 0 | H25: 4035.16 | I25: * 1:30 PM 100/50
A26: 42484 | B26: 42 | C26: 0 | D26: 172 | E26: T | F26: 0 | G26: 0 | H26: 4035.16 | I26: * 4 PM 50/25
A27: 42485 | B27: 25 | C27: 0 | D27: 200 | E27: 0 | F27: 0 | G27: 0 | H27: 4035.13
A28: 42486 | B28: 25 | C28: 0 | D28: 207 | E28: 0 | F28: 0 | G28: 0 | H28: 4035.1
A29: 42487 | B29: 83 | C29: 0 | D29: 231 | E29: 0 | F29: 0 | G29: 0 | H29: 4035.08 | I29: * 9AM 25/75 * 2 PM 75/100 * 4 PM 100/150
A30: 42488 | B30: 200 | C30: 0 | D30: 271 | E30: 0.46 | F30: 0 | G30: 0 | H30: 4035.06 | I30: *12pm 150/250
A31: 42489 | B31: 203 | C31: 0 | D31: 270 | E31: 0.01 | F31: 0 | G31: 0 | H31: 4035.06 | I31: * 9 AM 250/200 * 4:30 PM 200/150
A32: 42490 | B32: 134 | C32: 0 | D32: 266 | E32: 0 | F32: 0 | G32: 0 | H32: 4035.06 | I32: * 4:30 PM 150/100
A33: Monthly Total | B33: =SUM(B3:B32) -> 1170 | C33: =SUM(C3:C32) -> 627 | D33: =SUM(D3:D32) -> 3505 | E33: =SUM(E3:E32) -> 2.23 | F33: =SUM(F3:F32) -> 0 | G33: =SUM(G3:G32) -> 0
A34: WY Total | B34: =SUM(B33+'Mar 2016'!B35) -> 3769 | C34: =SUM(C33+'Mar 2016'!C35) -> 5435 | D34: =SUM(D33+'Mar 2016'!D35) -> 11057 | E34: =SUM(E33+'Mar 2016'!E35) -> 10.03 | F34: =SUM(F33+'Mar 2016'!F35) -> 22.69 | G34: =SUM(G33+'Mar 2016'!G35) -> 17168
A36: Acre Feet | B36: =SUM(B3:B33)*1.9835 -> 4641.39 | C36: =SUM(C3:C33)*1.9835 -> 2487.309 | D36: =SUM(D3:D33)*1.9835 -> 13904.335
A38: WY AF Total | B38: =SUM(B36+'Mar 2016'!B39) -> 9796.5065 | C38: =SUM(C36+'Mar 2016'!C39) -> 12023.977 | D38: =SUM(D36+'Mar 2016'!D39) -> 28883.727
G40: * COMPUTATIONAL PURPOSES ONLY! Do Not Enter Data in the Red Columns
A42: *This is computation purposes only for Station 48
A43: Sta 48
F44: =SUM(24-D44) -> 24 | G44: =SUM(C44+E44) -> 0 | H44: =SUM(C44/24*D44+G44/24*F44) -> 0
...

Sheet Mar 2016
A1: DATE | B1: STATION 48 | C1: ANDERSON-ROSE | D1: J CANAL | E1: TULE LAKE PRECIP | F1: TULE LAKE SNOW | G1: D PLANT | H1: TULE LAKE ELEV. | I1: CHANGES @ STATION 48
B2: (in CFS) | C2: (in CFS) | D2: (in CFS) | G2: (in AF)
A3: 42430 | B3: 0 | C3: 20 | D3: 0 | E3: 0.01 | F3: 0 | G3: 0 | H3: 4034.68
A4: 42431 | B4: 0 | C4: 20 | D4: 0 | E4: T | F4: 0 | G4: 0 | H4: 4034.7
A5: 42432 | B5: 0 | C5: 20 | D5: 0 | E5: 0.01 | F5: 0 | G5: 0 | H5: 4034.72
A6: 42433 | B6: 0 | C6: 20 | D6: 0 | E6: 0.04 | F6: 0 | G6: 0 | H6: 4034.74
A7: 42434 | B7: 0 | C7: 20 | D7: 0 | E7: 0.06 | F7: 0 | G7: 0 | H7: 4034.76
A8: 42435 | B8: 0 | C8: 20 | D8: 0 | E8: 0.75 | F8: 0 | G8: 0 | H8: 4034.8
A9: 42436 | B9: 0 | C9: 36 | D9: 0 | E9: 0.02 | F9: 0 | G9: 94 | H9: 4034.84 | I9: * Start 1 unit at D-Plant approx 10:00 AM
A10: 42437 | B10: 0 | C10: 38 | D10: 0 | E10: 0.03 | F10: 0 | G10: 160 | H10: 4034.86
A11: 42438 | B11: 0 | C11: 30 | D11: 0 | E11: 0.08 | F11: 0.5 | G11: 160 | H11: 4034.86
A12: 42439 | B12: 0 | C12: 30 | D12: 0 | E12: T | F12: 0 | G12: 160 | H12: 4034.86
A13: 42440 | B13: 0 | C13: 30 | D13: 0 | E13: 0 | F13: 0 | G13: 160 | H13: 4034.86
A14: 42441 | B14: 0 | C14: 30 | D14: 0 | E14: 0.01 | F14: 0 | G14: 160 | H14: 4034.86
A15: 42442 | B15: 0 | C15: 13 | D15: 0 | E15: 0.2 | F15: 0 | G15: 160 | H15: 4034.86
A16: 42443 | B16: 0 | C16: 17 | D16: 35 | E16: 0.16 | F16: 0.5 | G16: 65 | H16: 4034.88 | I16: * Shut 1 unit at D-Plant OFF apprx 10:00 AM
A17: 42444 | B17: 0 | C17: 0 | D17: 38 | E17: 0 | F17: 0 | G17: 0 | H17: 4034.88
A18: 42445 | B18: 0 | C18: 0 | D18: 35 | E18: 0 | F18: 0 | G18: 0 | H18: 4034.88
A19: 42446 | B19: 0 | C19: 0 | D19: 32 | E19: 0 | F19: 0 | G19: 0 | H19: 4034.88
A20: 42447 | B20: 0 | C20: 0 | D20: 31 | E20: 0 | F20: 0 | G20: 0 | H20: 4034.88
A21: 42448 | B21: 0 | C21: 0 | D21: 31 | E21: 0 | F21: 0 | G21: 0 | H21: 4034.88
A22: 42449 | B22: 0 | C22: 0 | D22: 29 | E22: 0 | F22: 0 | G22: 0 | H22: 4034.88
A23: 42450 | B23: 0 | C23: 0 | D23: 28 | E23: 0.14 | F23: 0 | G23: 0 | H23: 4034.9
A24: 42451 | B24: 0 | C24: 0 | D24: 28 | E24: 0.01 | F24: T | G24: 0 | H24: 4034.92
A25: 42452 | B25: 13 | C25: 0 | D25: 30 | E25: 0 | F25: 0 | G25: 0 | H25: 4034.94 | I25: * 11:30 AM 0/25
A26: 42453 | B26: 25 | C26: 0 | D26: 40 | E26: 0 | F26: 0 | G26: 0 | H26: 4034.96
A27: 42454 | B27: 25 | C27: 0 | D27: 44 | E27: 0 | F27: 0 | G27: 0 | H27: 4034.98
A28: 42455 | B28: 25 | C28: 0 | D28: 36 | E28: 0 | F28: 0 | G28: 0 | H28: 4034.98
A29: 42456 | B29: 25 | C29: 0 | D29: 38 | E29: 0.06 | F29: 0 | G29: 0 | H29: 4034.98
A30: 42457 | B30: 42 | C30: 0 | D30: 38 | E30: 0 | F30: 0 | G30: 0 | H30: 4034.98 | I30: * 8 AM 25/50
A31: 42458 | B31: 50 | C31: 0 | D31: 57 | E31: 0 | F31: 0 | G31: 0 | H31: 4035
A32: 42459 | B32: 50 | C32: 0 | D32: 66 | E32: 0 | F32: 0 | G32: 0 | H32: 4035
A33: 42460 | B33: 50 | C33: 0 | D33: 65 | E33: 0 | F33: 0 | G33: 0 | H33: 4035
A34: Monthly Total | B34: =SUM(B3:B33) -> 305 | C34: =SUM(C3:C33) -> 344 | D34: =SUM(D3:D33) -> 701 | E34: =SUM(E3:E33) -> 1.58 | F34: =SUM(F3:F33) -> 1 | G34: =SUM(G3:G33) -> 1119
A35: WY Total | B35: =SUM(B34+'Feb 2016'!B33) -> 2599 | C35: =SUM(C34+'Feb 2016'!C33) -> 4808 | D35: =SUM(D34+'Feb 2016'!D33) -> 7552 | E35: =SUM(E34+'Feb 2016'!E33) -> 7.8 | F35: =SUM(F34+'Feb 2016'!F33) -> 22.69 | G35: =SUM(G34+'Feb 2016'!G33) -> 17168
A37: Acre Feet | B37: =SUM(B3:B33)*1.9835 -> 604.9675 | C37: =SUM(C3:C33)*1.9835 -> 682.324 | D37: =SUM(D3:D33)*1.9835 -> 1390.4335
A39: WY AF Total | B39: =SUM(B37+'Feb 2016'!B37) -> 5155.1165 | C39: =SUM(C37+'Feb 2016'!C37) -> 9536.668 | D39: =SUM(D37+'Feb 2016'!D37) -> 14979.392
G41: * COMPUTATIONAL PURPOSES ONLY! Do Not Enter Data in the Red Columns
A43: *This is computation purposes only for Station 48
A44: Sta 48
...

Sheet Feb 2016
A1: DATE | B1: STATION 48 | C1: ANDERSON-ROSE | D1: J CANAL | E1: TULE LAKE PRECIP | F1: TULE LAKE SNOW | G1: D PLANT | H1: TULE LAKE ELEV. | I1: CHANGES @ STATION 48
B2: (in CFS) | C2: (in CFS) | D2: (in CFS) | G2: (in AF)
A3: 42401 | B3: 0 | C3: 70 | D3: 0 | E3: 0 | F3: 0 | G3: 318 | H3: 4034.8
A4: 42402 | B4: 0 | C4: 70 | D4: 0 | E4: 0.09 | F4: 1.5 | G4: 318 | H4: 4034.81
A5: 42403 | B5: 0 | C5: 70 | D5: 0 | E5: T | F5: 0 | G5: 318 | H5: 4034.82
A6: 42404 | B6: 0 | C6: 70 | D6: 0 | E6: 0 | F6: 0 | G6: 318 | H6: 4034.82
A7: 42405 | B7: 0 | C7: 70 | D7: 0 | E7: 0.02 | F7: 0 | G7: 318 | H7: 4034.82
A8: 42406 | B8: 0 | C8: 70 | D8: 0 | E8: 0.02 | F8: 0 | G8: 318 | H8: 4034.81
A9: 42407 | B9: 0 | C9: 70 | D9: 0 | E9: 0 | F9: 0 | G9: 318 | H9: 4034.8
A10: 42408 | B10: 0 | C10: 59 | D10: 0 | E10: 0.01 | F10: 0 | G10: 318 | H10: 4034.79
A11: 42409 | B11: 0 | C11: 50 | D11: 0 | E11: 0 | F11: 0 | G11: 318 | H11: 4034.78
A12: 42410 | B12: 0 | C12: 50 | D12: 0 | E12: 0 | F12: 0 | G12: 318 | H12: 4034.77
A13: 42411 | B13: 0 | C13: 50 | D13: 0 | E13: 0 | F13: 0 | G13: 318 | H13: 4034.76
A14: 42412 | B14: 0 | C14: 50 | D14: 0 | E14: 0 | F14: 0 | G14: 318 | H14: 4034.74
A15: 42413 | B15: 0 | C15: 50 | D15: 0 | E15: 0 | F15: 0 | G15: 318 | H15: 4034.72
A16: 42414 | B16: 0 | C16: 50 | D16: 0 | E16: 0.01 | F16: 0 | G16: 318 | H16: 4034.71
A17: 42415 | B17: 0 | C17: 50 | D17: 0 | E17: T | F17: 0 | G17: 318 | H17: 4034.7
A18: 42416 | B18: 0 | C18: 31 | D18: 0 | E18: 0.01 | F18: 0 | G18: 318 | H18: 4034.69
A19: 42417 | B19: 0 | C19: 30 | D19: 0 | E19: 0.01 | F19: 0 | G19: 318 | H19: 4034.68
A20: 42418 | B20: 0 | C20: 40 | D20: 0 | E20: 0.51 | F20: 3 | G20: 238 | H20: 4034.67
A21: 42419 | B21: 0 | C21: 40 | D21: 0 | E21: 0.07 | F21: T | G21: 206 | H21: 4034.66
A22: 42420 | B22: 0 | C22: 40 | D22: 0 | E22: 0.01 | F22: 0 | G22: 318 | H22: 4034.65
A23: 42421 | B23: 0 | C23: 40 | D23: 0 | E23: 0 | F23: 0 | G23: 318 | H23: 4034.64
A24: 42422 | B24: 0 | C24: 29 | D24: 0 | E24: 0.01 | F24: 0 | G24: 318 | H24: 4034.64
A25: 42423 | B25: 0 | C25: 20 | D25: 0 | E25: 0.01 | F25: 0 | G25: 318 | H25: 4034.62
A26: 42424 | B26: 0 | C26: 20 | D26: 0 | E26: 0 | F26: 0 | G26: 318 | H26: 4034.6
A27: 42425 | B27: 0 | C27: 20 | D27: 0 | E27: 0 | F27: 0 | G27: 318 | H27: 4034.6
A28: 42426 | B28: 0 | C28: 20 | D28: 0 | E28: 0 | F28: 0 | G28: 119 | H28: 4034.6 | I28: * D-Plant off at approx. 9:00 AM
A29: 42427 | B29: 0 | C29: 20 | D29: 0 | E29: 0.13 | F29: 0 | G29: 0 | H29: 4034.62
A30: 42428 | B30: 0 | C30: 20 | D30: 0 | E30: 0 | F30: 0 | G30: 0 | H30: 4034.64
A31: 42429 | B31: 0 | C31: 20 | D31: 0 | E31: T | F31: 0 | G31: 0 | H31: 4034.66
A32: Monthly Total | B32: =SUM(B3:B31) -> 0 | C32: =SUM(C3:C31) -> 1289 | D32: =SUM(D3:D31) -> 0 | E32: =SUM(E3:E31) -> 0.91 | F32: =SUM(F3:F31) -> 4.5 | G32: =SUM(G3:G31) -> 7877
A33: WY Total | B33: =SUM(B32+'Jan 2016'!B35) -> 2294 | C33: =SUM(C32+'Jan 2016'!C35) -> 4464 | D33: =SUM(D32+'Jan 2016'!D35) -> 6851 | E33: =SUM(E32+'Jan 2016'!E35) -> 6.22 | F33: =SUM(F32+'Jan 2016'!F35) -> 21.69 | G33: =SUM(G32+'Jan 2016'!G35) -> 16049
A35: Acre Feet | B35: =SUM(B3:B31)*1.9835 -> 0 | C35: =SUM(C3:C31)*1.9835 -> 2556.7315 | D35: =SUM(D3:D31)*1.9835 -> 0
A37: WY AF Total | B37: =SUM(B35+'Jan 2016'!B39) -> 4550.149 | C37: =SUM(C35+'Jan 2016'!C39) -> 8854.344 | D37: =SUM(D35+'Jan 2016'!D39) -> 13588.959
G39: * COMPUTATIONAL PURPOSES ONLY! Do Not Enter Data in the Red Columns
A41: *This is computation purposes only for Station 48
A42: Sta 48
F43: =SUM(24-D43) -> 24 | G43: =SUM(C43+E43) -> 0 | H43: =SUM(C43/24*D43+G43/24*F43) -> 0
F44: =SUM(24-D44) -> 24 | G44: =SUM(C44+E44) -> 0 | H44: =SUM(C44/24*D44+G44/24*F44) -> 0
...

Sheet Jan 2016
A1: DATE | B1: STATION 48 | C1: ANDERSON-ROSE | D1: J CANAL | E1: TULE LAKE PRECIP | F1: TULE LAKE SNOW | G1: D PLANT | H1: TULE LAKE ELEV. | I1: CHANGES @ STATION 48
B2: (in CFS) | C2: (in CFS) | D2: (in CFS) | G2: (in AF)
A3: 42370 | B3: 0 | C3: 50 | D3: 0 | E3: 0 | F3: 0 | G3: 0 | H3: 4034.86
A4: 42371 | B4: 0 | C4: 43 | D4: 0 | E4: 0 | F4: 0 | G4: 0 | H4: 4034.88
A5: 42372 | B5: 0 | C5: 36 | D5: 0 | E5: 0 | F5: 0 | G5: 0 | H5: 4034.9
A6: 42373 | B6: 0 | C6: 40 | D6: 0 | E6: 0 | F6: 0 | G6: 0 | H6: 4034.87
A7: 42374 | B7: 0 | C7: 40 | D7: 0 | E7: 0.01 | F7: 0 | G7: 0 | H7: 4034.85
A8: 42375 | B8: 0 | C8: 40 | D8: 0 | E8: 0 | F8: 0 | G8: 0 | H8: 4034.82
A9: 42376 | B9: 0 | C9: 40 | D9: 0 | E9: 0 | F9: 0 | G9: 0 | H9: 4034.8
A10: 42377 | B10: 0 | C10: 40 | D10: 0 | E10: 0 | F10: 0 | G10: 0 | H10: 4034.8
A11: 42378 | B11: 0 | C11: 36 | D11: 0 | E11: 0.18 | F11: 2 | G11: 0 | H11: 4034.8
A12: 42379 | B12: 0 | C12: 30 | D12: 0 | E12: 0.01 | F12: 0 | G12: 0 | H12: 4034.8
A13: 42380 | B13: 0 | C13: 21 | D13: 0 | E13: 0 | F13: 0 | G13: 0 | H13: 4034.8
A14: 42381 | B14: 0 | C14: 15 | D14: 0 | E14: 0 | F14: 0 | G14: 0 | H14: 4034.8
A15: 42382 | B15: 0 | C15: 15 | D15: 0 | E15: 0.15 | F15: 0 | G15: 0 | H15: 4034.8
A16: 42383 | B16: 0 | C16: 24 | D16: 0 | E16: 0.01 | F16: T | G16: 0 | H16: 4034.81
A17: 42384 | B17: 0 | C17: 42 | D17: 0 | E17: 0.02 | F17: 0.3 | G17: 0 | H17: 4034.8
A18: 42385 | B18: 0 | C18: 50 | D18: 0 | E18: 0.1 | F18: 1 | G18: 0 | H18: 4034.82
A19: 42386 | B19: 0 | C19: 50 | D19: 0 | E19: 0.08 | F19: 0.08 | G19: 0 | H19: 4034.84
A20: 42387 | B20: 0 | C20: 60 | D20: 0 | E20: 0.28 | F20: 0 | G20: 0 | H20: 4034.86
A21: 42388 | B21: 0 | C21: 114 | D21: 0 | E21: 0.06 | F21: 0 | G21: 102 | H21: 4034.87 | I21: * 8:45 AM 1 unit at D Plant Started
A22: 42389 | B22: 0 | C22: 137 | D22: 0 | E22: 0 | F22: 0 | G22: 224 | H22: 4034.89 | I22: * 2:00 PM 2nd unit at D Plant Started
A23: 42390 | B23: 0 | C23: 94 | D23: 0 | E23: 0 | F23: 0 | G23: 318 | H23: 4034.91
A24: 42391 | B24: 0 | C24: 80 | D24: 0 | E24: 0.19 | F24: 0 | G24: 318 | H24: 4034.9
A25: 42392 | B25: 0 | C25: 80 | D25: 0 | E25: 0.11 | F25: 0 | G25: 318 | H25: 4034.88
A26: 42393 | B26: 0 | C26: 93 | D26: 0 | E26: 0.02 | F26: 0 | G26: 318 | H26: 4034.86
A27: 42394 | B27: 0 | C27: 100 | D27: 0 | E27: 0.02 | F27: 0 | G27: 318 | H27: 4034.85
A28: 42395 | B28: 0 | C28: 100 | D28: 0 | E28: 0.01 | F28: 0 | G28: 318 | H28: 4034.84
A29: 42396 | B29: 0 | C29: 82 | D29: 0 | E29: 0 | F29: 0 | G29: 318 | H29: 4034.83
A30: 42397 | B30: 0 | C30: 58 | D30: 0 | E30: 0.1 | F30: 0 | G30: 318 | H30: 4034.82
A31: 42398 | B31: 0 | C31: 54 | D31: 0 | E31: 0.28 | F31: 0 | G31: 318 | H31: 4034.81
A32: 42399 | B32: 0 | C32: 64 | D32: 0 | E32: 0.06 | F32: 0 | G32: 318 | H32: 4034.81
A33: 42400 | B33: 0 | C33: 70 | D33: 0 | E33: 0 | F33: 0 | G33: 318 | H33: 4034.8
A34: Monthly Total | B34: =SUM(B3:B33) -> 0 | C34: =SUM(C3:C33) -> 1798 | D34: =SUM(D3:D33) -> 0 | E34: =SUM(E3:E33) -> 1.69 | F34: =SUM(F3:F33) -> 3.38 | G34: =SUM(G3:G33) -> 3824
A35: WY Total | B35: =SUM(B34+'Dec 2015'!B35) -> 2294 | C35: =SUM(C34+'Dec 2015'!C35) -> 3175 | D35: =SUM(D34+'Dec 2015'!D35) -> 6851 | E35: =SUM(E34+'Dec 2015'!E35) -> 5.31 | F35: =SUM(F34+'Dec 2015'!F35) -> 17.19 | G35: =SUM(G34+'Dec 2015'!G35) -> 8172
A37: Acre Feet | B37: =SUM(B3:B33)*1.9835 -> 0 | C37: =SUM(C3:C33)*1.9835 -> 3566.333 | D37: =SUM(D3:D33)*1.9835 -> 0
A39: WY AF Total | B39: =SUM(B37+'Dec 2015'!B39) -> 4550.149 | C39: =SUM(C37+'Dec 2015'!C39) -> 6297.6125 | D39: =SUM(D37+'Dec 2015'!D39) -> 13588.959
G41: * COMPUTATIONAL PURPOSES ONLY! Do Not Enter Data in the Red Columns
A43: *This is computation purposes only for Station 48
A44: Sta 48
...

Sheet Dec 2015
A1: DATE | B1: STATION 48 | C1: ANDERSON-ROSE | D1: J CANAL | E1: TULE LAKE PRECIP | F1: TULE LAKE SNOW | G1: D PLANT | H1: TULE LAKE ELEV. | I1: CHANGES @ STATION 48
B2: (in CFS) | C2: (in CFS) | D2: (in CFS) | G2: (in AF)
A3: 42339 | B3: 0 | C3: 15 | D3: 0 | E3: 0 | F3: 0 | G3: 0 | H3: 4034.38
A4: 42340 | B4: 0 | C4: 15 | D4: 0 | E4: 0.01 | F4: 0 | G4: 0 | H4: 4034.38
A5: 42341 | B5: 0 | C5: 17 | D5: 0 | E5: 0.03 | F5: 0 | G5: 0 | H5: 4034.38
A6: 42342 | B6: 0 | C6: 20 | D6: 0 | E6: 0.05 | F6: 0 | G6: 0 | H6: 4034.4
A7: 42343 | B7: 0 | C7: 20 | D7: 0 | E7: 0.01 | F7: 0 | G7: 0 | H7: 4034.4
A8: 42344 | B8: 0 | C8: 20 | D8: 0 | E8: 0.07 | F8: 0 | G8: 0 | H8: 4034.4
A9: 42345 | B9: 0 | C9: 20 | D9: 0 | E9: 0.01 | F9: 0 | G9: 0 | H9: 4034.4
A10: 42346 | B10: 0 | C10: 20 | D10: 0 | E10: 0 | F10: 0 | G10: 0 | H10: 4034.42
A11: 42347 | B11: 0 | C11: 20 | D11: 0 | E11: 0.25 | F11: 0 | G11: 0 | H11: 4034.44
A12: 42348 | B12: 0 | C12: 22 | D12: 0 | E12: 0.4 | F12: 0 | G12: 0 | H12: 4034.46
A13: 42349 | B13: 0 | C13: 25 | D13: 0 | E13: 0.01 | F13: 0 | G13: 0 | H13: 4034.48
A14: 42350 | B14: 0 | C14: 25 | D14: 0 | E14: 0.13 | F14: 3 | G14: 0 | H14: 4034.5
... A26: 42362 | B26: 0 | C26: 50 | D26: 0 | E26: 0.01 | F26: 0 | G26: 0 | H26: 4034.72
A27: 42363 | B27: 0 | C27: 50 | D27: 0 | E27: 0.03 | F27: T | G27: 0 | H27: 4034.74
A28: 42364 | B28: 0 | C28: 50 | D28: 0 | E28: 0 | F28: 0 | G28: 0 | H28: 4034.74
A29: 42365 | B29: 0 | C29: 50 | D29: 0 | E29: 0.02 | F29: T | G29: 0 | H29: 4034.75
A30: 42366 | B30: 0 | C30: 50 | D30: 0 | E30: 0.12 | F30: 0 | G30: 0 | H30: 4034.78
A31: 42367 | B31: 0 | C31: 50 | D31: 0 | E31: T | F31: 0 | G31: 0 | H31: 4034.8
A32: 42368 | B32: 0 | C32: 50 | D32: 0 | E32: 0.11 | F32: 1 | G32: 0 | H32: 4034.82
A33: 42369 | B33: 0 | C33: 50 | D33: 0 | E33: T | F33: 0 | G33: 0 | H33: 4034.84
A34: Monthly Total | B34: =SUM(B3:B33) -> 0 | C34: =SUM(C3:C33) -> 1009 | D34: =SUM(D3:D33) -> 0 | E34: =SUM(E3:E33) -> 2.21 | F34: =SUM(F3:F33) -> 8.81 | G34: =SUM(G3:G33) -> 0
A35: WY Total | B35: =SUM(B34+'Nov 2015'!B34) -> 2294 | C35: =SUM(C34+'Nov 2015'!C34) -> 1377 | D35: =SUM(D34+'Nov 2015'!D34) -> 6851 | E35: =SUM(E34+'Nov 2015'!E34) -> 3.62 | F35: =SUM(F34+'Nov 2015'!F34) -> 13.81 | G35: =SUM(G34+'Nov 2015'!G34) -> 4348
A37: Acre Feet | B37: =SUM(B3:B33)*1.9835 -> 0 | C37: =SUM(C3:C33)*1.9835 -> 2001.3515 | D37: =SUM(D3:D33)*1.9835 -> 0
A39: WY AF Total | B39: =SUM('Nov 2015'!B38+B37) -> 4550.149 | C39: =SUM('Nov 2015'!C38+C37) -> 2731.2795 | D39: =SUM('Nov 2015'!D38+D37) -> 13588.959
G41: * COMPUTATIONAL PURPOSES ONLY! Do Not Enter Data in the Red Columns
A43: *This is computation purposes only for Station 48
A44: Sta 48
F45: =SUM(24-D45) -> 24 | G45: =SUM(C45+E45) -> 0 | H45: =SUM(C45/24*D45+G45/24*F45) -> 0
F46: =SUM(24-D46) -> 24 | G46: =SUM(C46+E46) -> 0 | H46: =SUM(C46/24*D46+G46/24*F46) -> 0
F47: =SUM(24-D47) -> 24 | G47: =SUM(C47+E47) -> 0 | H47: =SUM(C47/24*D47+G47/24*F47) -> 0
F48: =SUM(24-D48) -> 24 | G48: =SUM(C48+E48) -> 0 | H48: =SUM(C48/24*D48+G48/24*F48) -> 0
F49: =SUM(24-D49) -> 24 | G49: =SUM(C49+E49) -> 0 | H49: =SUM(C49/24*D49+G49/24*F49) -> 0
A51: Use for more than 1 change in a day.
A52: **Station 48: | B52: Time | C52: Current CFS | D52: Hours Run | E52: +/- cfs | F52: Sub-total cfs
A58: Total Hours Run | D58: =SUM(D53:D57) -> 0 | E58: Total/Day cfs | F58: =SUM(F53:F57) -> 0

Sheet Nov 2015
A1: DATE | B1: STATION 48 | C1: ANDERSON-ROSE | D1: J CANAL | E1: TULE LAKE PRECIP | F1: TULE LAKE SNOW | G1: D PLANT | H1: TULE LAKE ELEV. | I1: CHANGES @ STATION 48
B2: (in CFS) | C2: (in CFS) | D2: (in CFS) | G2: (in AF)
A3: 42309 | B3: 125 | C3: 0 | D3: 139 | E3: 0.12 | F3: 0 | G3: 0 | H3: 4034.37
A4: 42310 | B4: 95 | C4: 0 | D4: 118 | E4: T | F4: 0 | G4: 0 | H4: 4034.38 | I4: * 9:30 AM 125/75
A5: 42311 | B5: 75 | C5: 0 | D5: 122 | E5: 0 | F5: 0 | G5: 0 | H5: 4034.38
A6: 42312 | B6: 75 | C6: 0 | D6: 121 | E6: 0 | F6: 0 | G6: 0 | H6: 4034.37
A7: 42313 | B7: 93 | C7: 0 | D7: 118 | E7: 0 | F7: 0 | G7: 0 | H7: 4034.36 | I7: * 10 AM 75/100 * 2PM 100/125
A8: 42314 | B8: 85 | C8: 0 | D8: 117 | E8: 0 | F8: 0 | G8: 0 | H8: 4034.35
A9: 42315 | B9: 63 | C9: 0 | D9: 107 | E9: 0 | F9: 0 | G9: 0 | H9: 4034.34
A10: 42316 | B10: 56 | C10: 0 | D10: 100 | E10: T | F10: 0 | G10: 0 | H10: 4034.32
A11: 42317 | B11: 37 | C11: 0 | D11: 88 | E11: 0.21 | F11: 0 | G11: 0 | H11: 4034.3
A12: 42318 | B12: 12 | C12: 0 | D12: 72 | E12: 0.01 | F12: 0 | G12: 0 | H12: 4034.3
A13: 42319 | B13: 5 | C13: 0 | D13: 71 | E13: T | F13: 0 | G13: 0 | H13: 4034.3
A14: 42320 | B14: 0 | C14: 0 | D14: 74 | E14: 0 | F14: 0 | G14: 0 | H14: 4034.3
A15: 42321 | B15: 0 | C15: 0 | D15: 64 | E15: T | F15: 0 | G15: 0 | H15: 4034.3
A16: 42322 | B16: 0 | C16: 0 | D16: 49 | E16: 0 | F16: 0 | G16: 0 | H16: 4034.3
A17: 42323 | B17: 0 | C17: 0 | D17: 45 | E17: 0.14 | F17: 0 | G17: 0 | H17: 4034.3
A18: 42324 | B18: 0 | C18: 0 | D18: 45 | E18: 0 | F18: 0 | G18: 0 | H18: 4034.3
A19: 42325 | B19: 0 | C19: 0 | D19: 31 | E19: 0.02 | F19: 0 | G19: 0 | H19: 4034.3
A20: 42326 | B20: 0 | C20: 0 | D20: 27 | E20: 0.01 | F20: 0 | G20: 0 | H20: 4034.3
A21: 42327 | B21: 0 | C21: 8 | D21: 32 | E21: 0.02 | F21: 0 | G21: 0 | H21: 4034.3
A22: 42328 | B22: 0 | C22: 20 | D22: 0 | E22: T | F22: 0 | G22: 0 | H22: 4034.3
A23: 42329 | B23: 0 | C23: 20 | D23: 0 | E23: 0 | F23: 0 | G23: 0 | H23: 4034.3
A24: 42330 | B24: 0 | C24: 20 | D24: 0 | E24: 0 | F24: 0 | G24: 0 | H24: 4034.3
A25: 42331 | B25: 0 | C25: 22 | D25: 0 | E25: 0.01 | F25: 0 | G25: 0 | H25: 4034.3
A26: 42332 | B26: 0 | C26: 25 | D26: 0 | E26: 0.16 | F26: 3 | G26: 0 | H26: 4034.32
A27: 42333 | B27: 0 | C27: 25 | D27: 0 | E27: 0.02 | F27: 2 | G27: 0 | H27: 4034.33
A28: 42334 | B28: 0 | C28: 25 | D28: 0 | E28: 0.01 | F28: 0 | G28: 0 | H28: 4034.34
A29: 42335 | B29: 0 | C29: 25 | D29: 0 | E29: 0 | F29: 0 | G29: 0 | H29: 4034.35
A30: 42336 | B30: 0 | C30: 25 | D30: 0 | E30: 0 | F30: 0 | G30: 0 | H30: 4034.36
A31: 42337 | B31: 0 | C31: 25 | D31: 0 | E31: 0 | F31: 0 | G31: 0 | H31: 4034.37
A32: 42338 | B32: 0 | C32: 20 | D32: 0 | E32: 0 | F32: 0 | G32: 0 | H32: 4034.38
A33: Monthly Total | B33: =SUM(B3:B32) -> 721 | C33: =SUM(C3:C32) -> 260 | D33: =SUM(D3:D32) -> 1540 | E33: =SUM(E3:E32) -> 0.73 | F33: =SUM(F3:F32) -> 5 | G33: =SUM(G3:G32) -> 0
A34: WY Total | B34: =SUM(B33+'Oct 2015'!B35) -> 2294 | C34: =SUM(C33+'Oct 2015'!C35) -> 368 | D34: =SUM(D33+'Oct 2015'!D35) -> 6851 | E34: =SUM(E33+'Oct 2015'!E35) -> 1.41 | F34: =SUM(F33+'Oct 2015'!F35) -> 5 | G34: =SUM(G33+'Oct 2015'!G35) -> 4348
A36: Acre Feet | B36: =SUM(B3:B32)*1.9835 -> 1430.1035 | C36: =SUM(C3:C32)*1.9835 -> 515.71 | D36: =SUM(D3:D32)*1.9835 -> 3054.59
A38: WY AF Total | B38: =SUM('Oct 2015'!B39+B36) -> 4550.149 | C38: =SUM('Oct 2015'!C39+C36) -> 729.928 | D38: =SUM('Oct 2015'!D39+D36) -> 13588.959
G40: * COMPUTATIONAL PURPOSES ONLY! Do Not Enter Data in the Red Columns
A42: *This is computation purposes only for Station 48
A43: Sta 48
F44: =SUM(24-D44) -> 24 | G44: =SUM(C44+E44) -> 0 | H44: =SUM(C44/24*D44+G44/24*F44) -> 0
...

Sheet Oct 2015
A1: DATE | B1: STATION 48 | C1: ANDERSON-ROSE | D1: J CANAL | E1: TULE LAKE PRECIP | F1: TULE LAKE SNOW | G1: D PLANT | H1: TULE LAKE ELEV. | I1: CHANGES @ STATION 48
B2: (in CFS) | C2: (in CFS) | D2: (in CFS)
A3: 42278 | B3: 0 | C3: 41 | D3: 119 | E3: 0 | F3: 0 | G3: 160 | H3: 4034.69
A4: 42279 | B4: 0 | C4: 25 | D4: 123 | E4: 0 | F4: 0 | G4: 160 | H4: 4034.69
A5: 42280 | B5: 0 | C5: 12 | D5: 135 | E5: 0 | F5: 0 | G5: 160 | H5: 4034.68
A6: 42281 | B6: 0 | C6: 12 | D6: 126 | E6: 0 | F6: 0 | G6: 160 | H6: 4034.68
A7: 42282 | B7: 0 | C7: 15 | D7: 121 | E7: 0 | F7: 0 | G7: 160 | H7: 4034.64
A8: 42283 | B8: 0 | C8: 3 | D8: 142 | E8: 0 | F8: 0 | G8: 160 | H8: 4034.62
A9: 42284 | B9: 8 | C9: 0 | D9: 175 | E9: 0 | F9: 0 | G9: 57 | H9: 4034.6 | I9: * 4:30 PM 0/25
A10: 42285 | B10: 25 | C10: 0 | D10: 165 | E10: 0 | F10: 0 | G10: 73 | H10: 4034.58
A11: 42286 | B11: 56 | C11: 0 | D11: 184 | E11: 0 | F11: 0 | G11: 160 | H11: 4034.58 | I11: * 9 AM 25/75
A12: 42287 | B12: 75 | C12: 0 | D12: 188 | E12: 0 | F12: 0 | G12: 160 | H12: 4034.56
A13: 42288 | B13: 44 | C13: 0 | D13: 188 | E13: 0 | F13: 0 | G13: 160 | H13: 4034.54 | I13: * 9 AM 75/25
A14: 42289 | B14: 25 | C14: 0 | D14: 191 | E14: 0 | F14: 0 | G14: 160 | H14: 4034.52
A15: 42290 | B15: 22 | C15: 0 | D15: 177 | E15: 0 | F15: 0 | G15: 160 | H15: 4034.51 | I15: * 1 PM 25/18
A16: 42291 | B16: 18 | C16: 0 | D16: 180 | E16: 0 | F16: 0 | G16: 160 | H16: 4034.5
A17: 42292 | B17: 18 | C17: 0 | D17: 174 | E17: 0 | F17: 0 | G17: 160 | H17: 4034.47
A18: 42293 | B18: 18 | C18: 0 | D18: 187 | E18: 0 | F18: 0 | G18: 160 | H18: 4034.46
A19: 42294 | B19: 18 | C19: 0 | D19: 200 | E19: 0.37 | F19: 0 | G19: 160 | H19: 4034.46
A20: 42295 | B20: 18 | C20: 0 | D20: 184 | E20: 0.01 | F20: 0 | G20: 160 | H20: 4034.46
A21: 42296 | B21: 18 | C21: 0 | D21: 173 | E21: 0 | F21: 0 | G21: 160 | H21: 4034.46
A22: 42297 | B22: 18 | C22: 0 | D22: 169 | E22: 0.01 | F22: 0 | G22: 160 | H22: 4034.44
A23: 42298 | B23: 18 | C23: 0 | D23: 133 | E23: 0 | F23: 0 | G23: 160 | H23: 4034.42
A24: 42299 | B24: 18 | C24: 0 | D24: 170 | E24: 0 | F24: 0 | G24: 160 | H24: 4034.4
A25: 42300 | B25: 18 | C25: 0 | D25: 159 | E25: 0 | F25: 0 | G25: 160 | H25: 4034.4
A26: 42301 | B26: 62 | C26: 0 | D26: 142 | E26: 0 | F26: 0 | G26: 160 | H26: 4034.4 | I26: * 8 AM 18/50 * 1 PM 50/100
A27: 42302 | B27: 151 | C27: 0 | D27: 173 | E27: 0 | F27: 0 | G27: 160 | H27: 4034.38 | I27: * 8:30 AM 100/150 *3 PM 150/200
A28: 42303 | B28: 184 | C28: 0 | D28: 209 | E28: 0 | F28: 0 | G28: 160 | H28: 4034.38 | I28: * 4:30 PM 200/150
A29: 42304 | B29: 150 | C29: 0 | D29: 216 | E29: 0 | F29: 0 | G29: 160 | H29: 4034.37
A30: 42305 | B30: 150 | C30: 0 | D30: 219 | E30: 0.29 | F30: 0 | G30: 160 | H30: 4034.36
A31: 42306 | B31: 150 | C31: 0 | D31: 213 | E31: 0 | F31: 0 | G31: 58 | H31: 4034.35 | I31: * 8:42 AM D Plant Off
A32: 42307 | B32: 150 | C32: 0 | D32: 200 | E32: 0 | F32: 0 | G32: 0 | H32: 4034.35
A33: 42308 | B33: 141 | C33: 0 | D33: 176 | E33: 0 | F33: 0 | G33: 0 | H33: 4034.36 | I33: * 3:30 PM 150/125
A34: Monthly Total | B34: =SUM(B3:B33) -> 1573 | C34: =SUM(C3:C33) -> 108 | D34: =SUM(D3:D33) -> 5311 | E34: =SUM(E3:E33) -> 0.68 | F34: =SUM(F3:F33) -> 0 | G34: =SUM(G3:G33) -> 4348
A35: WY Total | B35: =SUM(B34+'Oct 2015'!B36) -> 1573 | C35: =SUM(C34+'Oct 2015'!C36) -> 108 | D35: =SUM(D34+'Oct 2015'!D36) -> 5311 | E35: =SUM(E34+'Oct 2015'!E36) -> 0.68 | F35: =SUM(F34+'Oct 2015'!F36) -> 0 | G35: =SUM(G34+'Oct 2015'!G36) -> 4348
A37: Acre Feet | B37: =SUM(B3:B33)*1.9835 -> 3120.0455 | C37: =SUM(C3:C33)*1.9835 -> 214.218 | D37: =SUM(D3:D33)*1.9835 -> 10534.369
A39: WY AF Total | B39: =SUM('Oct 2015'!B40+B37) -> 3120.0455 | C39: =SUM('Oct 2015'!C40+C37) -> 214.218 | D39: =SUM('Oct 2015'!D40+D37) -> 10534.369
G41: * COMPUTATIONAL PURPOSES ONLY! Do Not Enter Data in the Red Columns
A43: *This is computation purposes only for Station 48
A44: Sta 48
...
