Workbook

Sheet Sep 2020
A1: DATE | B1: STATION 48 | C1: ANDERSON-ROSE | D1: J CANAL | E1: TULE LAKE PRECIP | F1: TULE LAKE SNOW | G1: D PLANT | H1: TULE LAKE ELEV. | I1: CHANGES @ STATION 48
B2: (in CFS) | C2: (in CFS) | D2: (in CFS) | G2: (in AF)
A3: 44075 | B3: 200 | C3: 75 | D3: 217 | E3: 0 | F3: 0 | G3: 0 | H3: 4034.28 | J3: Sump 1A - 50
A4: 44076 | B4: 219 | C4: 50 | D4: 200 | E4: 0 | F4: 0 | G4: 0 | H4: 4034.3 | I4: * 15:00 200/250 | J4: Sump 1A - 50
A5: 44077 | B5: 250 | C5: 50 | D5: 200 | E5: 0 | F5: 0 | G5: 0 | H5: 4034.32 | J5: Sump 1A - 50
A6: 44078 | B6: 242 | C6: 50 | D6: 181 | E6: 0 | F6: 0 | G6: 0 | H6: 4034.33 | I6: * 16:00 250/225 | J6: Sump 1A - 50
A7: 44079 | B7: 225 | C7: 50 | D7: 184 | E7: 0 | F7: 0 | G7: 0 | H7: 4034.34 | J7: Sump 1A - 50
A8: 44080 | B8: 225 | C8: 50 | D8: 168 | E8: 0 | F8: 0 | G8: 0 | H8: 4034.34 | J8: Sump 1A - 50
A9: 44081 | B9: 225 | C9: 50 | D9: 168 | E9: 0 | F9: 0 | G9: 0 | H9: 4034.35 | J9: Sump 1A - 50
A10: 44082 | B10: 225 | C10: 50 | D10: 186 | E10: 0 | F10: 0 | G10: 0 | H10: 4034.36 | J10: Sump 1A - 50
A11: 44083 | B11: 225 | C11: 50 | D11: 172 | E11: 0 | F11: 0 | G11: 0 | H11: 4034.36 | J11: Sump 1A - 50
A12: 44084 | B12: 225 | C12: 50 | D12: 154 | E12: 0 | F12: 0 | G12: 0 | H12: 4034.37 | J12: Sump 1A - 50
A13: 44085 | B13: 205 | C13: 50 | D13: 164 | E13: 0 | F13: 0 | G13: 0 | H13: 4034.37 | I13: * 13:00 225/200 * 16:00 200/175 Correction to J-canal | J13: Sump 1A - 50
A14: 44086 | B14: 161 | C14: 61 | D14: 158 | E14: 0 | F14: 0 | G14: 0 | H14: 4034.37 | I14: * 11:00 175/150 | J14: Sump 1A - 50
A15: 44087 | B15: 131 | C15: 55 | D15: 166 | E15: 0 | F15: 0 | G15: 0 | H15: 4034.38 | I15: * 10:00 150/100 * 14:00 100/125 | J15: Sump 1A - 50
A16: 44088 | B16: 138 | C16: 50 | D16: 183 | E16: 0 | F16: 0 | G16: 0 | H16: 4034.39 | I16: * 12:00 125/150 | J16: Sump 1A - 50
A17: 44089 | B17: 150 | C17: 50 | D17: 175 | E17: 0 | F17: 0 | G17: 0 | H17: 4034.4 | J17: Sump 1A - 50
A18: 44090 | B18: 165 | C18: 50 | D18: 172 | E18: 0 | F18: 0 | G18: 0 | H18: 4034.42 | I18: * 10:00 150/175 | J18: Sump 1A - 50
A19: 44091 | B19: 188 | C19: 50 | D19: 156 | E19: 0 | F19: 0 | G19: 0 | H19: 4034.44 | I19: * 12:00 175/200 | J19: Sump 1A - 50
A20: 44092 | B20: 194 | C20: 50 | D20: 140 | E20: 0 | F20: 0 | G20: 0 | H20: 4034.46 | I20: * 18:00 200/175 | J20: Sump 1A - 50
A21: 44093 | B21: 160 | C21: 50 | D21: 136 | E21: 0 | F21: 0 | G21: 0 | H21: 4034.48 | I21: * 09:00 175/150 | J21: Sump 1A - 50
A22: 44094 | B22: 133 | C22: 50 | D22: 120 | E22: 0 | F22: 0 | G22: 0 | H22: 4034.5 | I22: * 13:30 150/125 * 18:30 125/100 | J22: Sump 1A - 50
A23: 44095 | B23: 94 | C23: 67 | D23: 119 | E23: 0 | F23: 0 | G23: 0 | H23: 4034.52 | I23: *10:00 100/75 * 16:00 75/100 | J23: Sump 1A - 50
A24: 44096 | B24: 100 | C24: 50 | D24: 128 | E24: 0 | F24: 0 | G24: 0 | H24: 4034.54 | J24: Sump 1A - 50
A25: 44097 | B25: 95 | C25: 50 | D25: 114 | E25: 0 | F25: 0 | G25: 0 | H25: 4034.56 | I25: * 09:00 100/75 * 14:00 75/100 | J25: Sump 1A - 50
A26: 44098 | B26: 100 | C26: 50 | D26: 111 | E26: 0 | F26: 0 | G26: 0 | H26: 4034.58 | J26: Sump 1A - 50
A27: 44099 | B27: 100 | C27: 50 | D27: 96 | E27: 0 | F27: 0 | G27: 0 | H27: 4034.59 | J27: Sump 1A - 50
A28: 44100 | B28: 90 | C28: 50 | D28: 101 | E28: 0 | F28: 0 | G28: 0 | H28: 4034.56 | I28: * 14:00 100/75 | J28: Sump 1A - 50
A29: 44101 | B29: 75 | C29: 50 | D29: 93 | E29: 0 | F29: 0 | G29: 0 | H29: 4034.53 | J29: Sump 1A - 50
A30: 44102 | B30: 75 | C30: 50 | D30: 108 | E30: 0 | F30: 0 | G30: 0 | H30: 4034.51 | J30: Sump 1A - 50
A31: 44103 | B31: 94 | C31: 50 | D31: 127 | E31: 0 | F31: 0 | G31: 0 | H31: 4034.49 | I31: *12:00 75/100 * 18:00 100/125 | J31: Sump 1A - 50
A32: 44104 | B32: 125 | C32: 50 | D32: 131 | E32: 0 | F32: 0 | G32: 0 | H32: 4034.47 | J32: Sump 1A - 50
A33: Monthly Total | B33: =SUM(B3:B32) -> 4834 | C33: =SUM(C3:C32) -> 1558 | D33: =SUM(D3:D32) -> 4528 | E33: =SUM(E3:E32) -> 0 | F33: =SUM(F3:F32) -> 0 | G33: =SUM(G3:G32) -> 0
A34: WY Total | B34: =SUM(B33+'Aug 2020'!B35) -> 28283 | C34: =SUM(C33+'Aug 2020'!C35) -> 7395 | D34: =SUM(D33+'Aug 2020'!D35) -> 34365 | E34: =SUM(E33+'Aug 2020'!E35) -> 5.53 | F34: =SUM(F33+'Aug 2020'!F35) -> 14.6 | G34: =SUM(G33+'Aug 2020'!G35) -> 14754
A36: Acre Feet | B36: =SUM(B3:B32)*1.9835 -> 9588.239 | C36: =SUM(C3:C32)*1.9835 -> 3090.293 | D36: =SUM(D3:D32)*1.9835 -> 8981.288
A38: WY AF Total | B38: =SUM(B36+'Aug 2020'!B39) -> 60359.889 | C38: =SUM(C36+'Aug 2020'!C39) -> 16677.268 | D38: =SUM(D36+'Aug 2020'!D39) -> 75745.898
G40: * COMPUTATIONAL PURPOSES ONLY! Do Not Enter Data in the Red Columns
A42: *This is computation purposes only for Station 48
A43: Sta 48
F44: =SUM(24-D44) -> 24 | G44: =SUM(C44+E44) -> 0 | H44: =SUM(C44/24*D44+G44/24*F44) -> 0
...

Sheet Aug 2020
A1: DATE | B1: STATION 48 | C1: ANDERSON-ROSE | D1: J CANAL | E1: TULE LAKE PRECIP | F1: TULE LAKE SNOW | G1: D PLANT | H1: TULE LAKE ELEV. | I1: CHANGES @ STATION 48
B2: (in CFS) | C2: (in CFS) | D2: (in CFS) | G2: (in AF)
A3: 44044 | B3: 175 | C3: 0 | D3: 194 | E3: 0 | F3: 0 | G3: 0 | H3: 4034.18
A4: 44045 | B4: 167 | C4: 0 | D4: 159 | E4: 0 | F4: 0 | G4: 0 | H4: 4034.17 | I4: * 16:00 175/150
A5: 44046 | B5: 150 | C5: 0 | D5: 160 | E5: 0 | F5: 0 | G5: 0 | H5: 4034.17
A6: 44047 | B6: 150 | C6: 0 | D6: 153 | E6: 0 | F6: 0 | G6: 0 | H6: 4034.16
A7: 44048 | B7: 150 | C7: 0 | D7: 166 | E7: 0 | F7: 0 | G7: 0 | H7: 4034.15
A8: 44049 | B8: 150 | C8: 0 | D8: 181 | E8: 0 | F8: 0 | G8: 0 | H8: 4034.14
A9: 44050 | B9: 150 | C9: 0 | D9: 166 | E9: 0 | F9: 0 | G9: 0 | H9: 4034.13
A10: 44051 | B10: 150 | C10: 0 | D10: 164 | E10: 0 | F10: 0 | G10: 0 | H10: 4034.11
A11: 44052 | B11: 117 | C11: 0 | D11: 138 | E11: 0 | F11: 0 | G11: 0 | H11: 4034.09 | I11: * 08:00 150/100
A12: 44053 | B12: 109 | C12: 0 | D12: 134 | E12: 0 | F12: 0 | G12: 0 | H12: 4034.08 | I12: * 15:00 100/125
A13: 44054 | B13: 183 | C13: 0 | D13: 131 | E13: 0 | F13: 0 | G13: 0 | H13: 4034.06 | I13: * 10:00 125/225 | J13: * 10:00 Sta 48 for Sump 1A - 0/100
A14: 44055 | B14: 225 | C14: 58 | D14: 123 | E14: 0 | F14: 0 | G14: 0 | H14: 4034.04 | J14: Sump 1A - 100
A15: 44056 | B15: 225 | C15: 100 | D15: 107 | E15: 0 | F15: 0 | G15: 0 | H15: 4034.03 | J15: Sump 1A - 100
A16: 44057 | B16: 234 | C16: 100 | D16: 115 | E16: 0 | F16: 0 | G16: 0 | H16: 4034.02 | I16: * 15:00 225/250 | J16: Sump 1A - 100
A17: 44058 | B17: 238 | C17: 100 | D17: 123 | E17: 0 | F17: 0 | G17: 0 | H17: 4034.01 | I17: * 12:00 250/225 | J17: Sump 1A - 100
A18: 44059 | B18: 225 | C18: 100 | D18: 127 | E18: T | F18: 0 | G18: 0 | H18: 4034 | J18: Sump 1A - 100
A19: 44060 | B19: 225 | C19: 100 | D19: 173 | E19: 0 | F19: 0 | G19: 0 | H19: 4034 | J19: Sump 1A - 100
A20: 44061 | B20: 225 | C20: 100 | D20: 191 | E20: 0 | F20: 0 | G20: 0 | H20: 4034.01 | J20: Sump 1A - 100
A21: 44062 | B21: 225 | C21: 100 | D21: 217 | E21: 0 | F21: 0 | G21: 0 | H21: 4034.02 | J21: Sump 1A - 100
A22: 44063 | B22: 225 | C22: 100 | D22: 227 | E22: 0 | F22: 0 | G22: 0 | H22: 4034.04 | J22: Sump 1A - 100
A23: 44064 | B23: 225 | C23: 100 | D23: 243 | E23: 0 | F23: 0 | G23: 0 | H23: 4034.06 | J23: Sump 1A - 100
A24: 44065 | B24: 240 | C24: 100 | D24: 226 | E24: 0 | F24: 0 | G24: 0 | H24: 4034.08 | I24: * 10:00 225/250 | J24: Sump 1A - 100
A25: 44066 | B25: 250 | C25: 100 | D25: 195 | E25: 0 | F25: 0 | G25: 0 | H25: 4034.1 | J25: Sump 1A - 100
A26: 44067 | B26: 250 | C26: 100 | D26: 167 | E26: 0 | F26: 0 | G26: 0 | H26: 4034.12 | J26: Sump 1A - 100
A27: 44068 | B27: 250 | C27: 100 | D27: 182 | E27: 0 | F27: 0 | G27: 0 | H27: 4034.14 | J27: Sump 1A - 100
A28: 44069 | B28: 250 | C28: 100 | D28: 210 | E28: T | F28: 0 | G28: 0 | H28: 4034.16 | J28: Sump 1A - 100
A29: 44070 | B29: 250 | C29: 100 | D29: 214 | E29: 0 | F29: 0 | G29: 0 | H29: 4034.18 | J29: Sump 1A - 100
A30: 44071 | B30: 250 | C30: 100 | D30: 223 | E30: 0 | F30: 0 | G30: 0 | H30: 4034.2 | J30: Sump 1A - 100
A31: 44072 | B31: 250 | C31: 100 | D31: 213 | E31: 0 | F31: 0 | G31: 0 | H31: 4034.22 | J31: Sump 1A - 100
A32: 44073 | B32: 250 | C32: 100 | D32: 190 | E32: 0 | F32: 0 | G32: 0 | H32: 4034.24 | J32: Sump 1A - 100
A33: 44074 | B33: 225 | C33: 100 | D33: 206 | E33: 0 | F33: 0 | G33: 0 | H33: 4034.26 | I33: * 14:00 250/150 * 16:00 150/200 | J33: * 14:00 Sump 1A - 100/0 * 16:00 Sump 1A - 0/50
A34: Monthly Total | B34: =SUM(B3:B33) -> 6388 | C34: =SUM(C3:C33) -> 1958 | D34: =SUM(D3:D33) -> 5418 | E34: =SUM(E3:E33) -> 0 | F34: =SUM(F3:F33) -> 0 | G34: =SUM(G3:G33) -> 0
A35: WY Total | B35: =SUM(B34+'Jul 2020'!B35) -> 23449 | C35: =SUM(C34+'Jul 2020'!C35) -> 5837 | D35: =SUM(D34+'Jul 2020'!D35) -> 29837 | E35: =SUM(E34+'Jul 2020'!E35) -> 5.53 | F35: =SUM(F34+'Jul 2020'!F35) -> 14.6 | G35: =SUM(G34+'Jul 2020'!G35) -> 14754
A37: Acre Feet | B37: =SUM(B3:B33)*1.9835 -> 12670.598 | C37: =SUM(C3:C33)*1.9835 -> 3883.693 | D37: =SUM(D3:D33)*1.9835 -> 10746.603
A39: WY AF Total | B39: =SUM(B37+'Jul 2020'!B39) -> 50771.649 | C39: =SUM(C37+'Jul 2020'!C39) -> 13586.975 | D39: =SUM(D37+'Jul 2020'!D39) -> 66764.61
G41: * COMPUTATIONAL PURPOSES ONLY! Do Not Enter Data in the Red Columns
A43: *This is computation purposes only for Station 48
A44: Sta 48
...

Sheet Jul 2020
A1: DATE | B1: STATION 48 | C1: ANDERSON-ROSE | D1: J CANAL | E1: TULE LAKE PRECIP | F1: TULE LAKE SNOW | G1: D PLANT | H1: TULE LAKE ELEV. | I1: CHANGES @ STATION 48
B2: (in CFS) | C2: (in CFS) | D2: (in CFS) | G2: (in AF)
A3: 44013 | B3: 180 | C3: 0 | D3: 207 | E3: 0 | F3: 0 | G3: 0 | H3: 4034.44 | I3: * 15:30 200/150
A4: 44014 | B4: 185 | C4: 0 | D4: 157 | E4: 0 | F4: 0 | G4: 0 | H4: 4034.42 | I4: * 07:00 150/200
A5: 44015 | B5: 163 | C5: 0 | D5: 135 | E5: 0 | F5: 0 | G5: 0 | H5: 4034.42 | I5: * 15:00 200/100
A6: 44016 | B6: 90 | C6: 0 | D6: 99 | E6: 0 | F6: 0 | G6: 0 | H6: 4034.4 | I6: * 14:30 100/75
A7: 44017 | B7: 94 | C7: 0 | D7: 105 | E7: 0 | F7: 0 | G7: 0 | H7: 4034.4 | I7: * 15:00 75/125 STATION 48 CORRECTED
A8: 44018 | B8: 125 | C8: 0 | D8: 138 | E8: 0 | F8: 0 | G8: 0 | H8: 4034.39
A9: 44019 | B9: 116 | C9: 0 | D9: 126 | E9: 0 | F9: 0 | G9: 0 | H9: 4034.37 | I9: * 15:30 125/100
A10: 44020 | B10: 100 | C10: 0 | D10: 117 | E10: 0 | F10: 0 | G10: 0 | H10: 4034.34
A11: 44021 | B11: 125 | C11: 0 | D11: 106 | E11: 0 | F11: 0 | G11: 0 | H11: 4034.34 | I11: * 09:30 100/125 *14:30 125/150
A12: 44022 | B12: 150 | C12: 0 | D12: 146 | E12: 0 | F12: 0 | G12: 0 | H12: 4034.34
A13: 44023 | B13: 131 | C13: 0 | D13: 135 | E13: 0 | F13: 0 | G13: 0 | H13: 4034.34 | I13: * 15:00 150/100
A14: 44024 | B14: 100 | C14: 0 | D14: 106 | E14: 0 | F14: 0 | G14: 0 | H14: 4034.34
A15: 44025 | B15: 100 | C15: 0 | D15: 80 | E15: 0 | F15: 0 | G15: 0 | H15: 4034.32
A16: 44026 | B16: 100 | C16: 0 | D16: 119 | E16: 0 | F16: 0 | G16: 0 | H16: 4034.3
A17: 44027 | B17: 100 | C17: 0 | D17: 130 | E17: 0 | F17: 0 | G17: 0 | H17: 4034.28
A18: 44028 | B18: 100 | C18: 0 | D18: 133 | E18: 0 | F18: 0 | G18: 0 | H18: 4034.28
A19: 44029 | B19: 107 | C19: 0 | D19: 148 | E19: 0 | F19: 0 | G19: 0 | H19: 4034.3 | I19: * 17:00 100/125
A20: 44030 | B20: 125 | C20: 0 | D20: 140 | E20: 0 | F20: 0 | G20: 0 | H20: 4034.3
A21: 44031 | B21: 125 | C21: 0 | D21: 120 | E21: 0 | F21: 0 | G21: 0 | H21: 4034.28
A22: 44032 | B22: 113 | C22: 0 | D22: 145 | E22: 0 | F22: 0 | G22: 0 | H22: 4034.27 | I22: * 12:00 125/100
A23: 44033 | B23: 118 | C23: 0 | D23: 189 | E23: 0 | F23: 0 | G23: 0 | H23: 4034.26 | I23: * 15:30 100/150
A24: 44034 | B24: 169 | C24: 0 | D24: 222 | E24: 0 | F24: 0 | G24: 0 | H24: 4034.25 | I24: * 15:00 150/200
A25: 44035 | B25: 200 | C25: 0 | D25: 234 | E25: 0 | F25: 0 | G25: 0 | H25: 4034.25
A26: 44036 | B26: 200 | C26: 0 | D26: 217 | E26: 0 | F26: 0 | G26: 0 | H26: 4034.24
A27: 44037 | B27: 200 | C27: 0 | D27: 235 | E27: 0 | F27: 0 | G27: 0 | H27: 4034.24
A28: 44038 | B28: 191 | C28: 0 | D28: 248 | E28: 0 | F28: 0 | G28: 0 | H28: 4034.23 | I28: * 15:00 200/175
A29: 44039 | B29: 204 | C29: 0 | D29: 232 | E29: 0 | F29: 0 | G29: 0 | H29: 4034.23 | I29: * 06:00 175/200 * 19:00 200/250
A30: 44040 | B30: 250 | C30: 0 | D30: 212 | E30: 0 | F30: 0 | G30: 0 | H30: 4034.2
A31: 44041 | B31: 222 | C31: 0 | D31: 188 | E31: 0 | F31: 0 | G31: 0 | H31: 4034.2 | I31: * 15:00 250/175
A32: 44042 | B32: 175 | C32: 0 | D32: 178 | E32: 0 | F32: 0 | G32: 0 | H32: 4034.2
A33: 44043 | B33: 175 | C33: 0 | D33: 197 | E33: 0 | F33: 0 | G33: 0 | H33: 4034.2
A34: Monthly Total | B34: =SUM(B3:B33) -> 4533 | C34: =SUM(C3:C33) -> 0 | D34: =SUM(D3:D33) -> 4944 | E34: =SUM(E3:E33) -> 0 | F34: =SUM(F3:F33) -> 0 | G34: =SUM(G3:G33) -> 0
A35: WY Total | B35: =SUM(B34+'Jun 2020'!B34) -> 17061 | C35: =SUM(C34+'Jun 2020'!C34) -> 3879 | D35: =SUM(D34+'Jun 2020'!D34) -> 24419 | E35: =SUM(E34+'Jun 2020'!E34) -> 5.53 | F35: =SUM(F34+'Jun 2020'!F34) -> 14.6 | G35: =SUM(G34+'Jun 2020'!G34) -> 14754
A37: Acre Feet | B37: =SUM(B3:B33)*1.9835 -> 8991.2055 | C37: =SUM(C3:C33)*1.9835 -> 0 | D37: =SUM(D3:D33)*1.9835 -> 9806.424
A39: WY AF Total | B39: =SUM(B37+'Jun 2020'!B38) -> 38101.052 | C39: =SUM(C37+'Jun 2020'!C38) -> 9703.282 | D39: =SUM(D37+'Jun 2020'!D38) -> 56018.007
G41: * COMPUTATIONAL PURPOSES ONLY! Do Not Enter Data in the Red Columns
A43: *This is computation purposes only for Station 48
A44: Sta 48
...

Sheet Jun 2020
A1: DATE | B1: STATION 48 | C1: ANDERSON-ROSE | D1: J CANAL | E1: TULE LAKE PRECIP | F1: TULE LAKE SNOW | G1: D PLANT | H1: TULE LAKE ELEV. | I1: CHANGES @ STATION 48
B2: (in CFS) | C2: (in CFS) | D2: (in CFS) | G2: (in AF)
A3: 43983 | B3: 0 | C3: 0 | D3: 64 | E3: 0 | F3: 0 | G3: 0 | H3: 4034.86
A4: 43984 | B4: 0 | C4: 0 | D4: 110 | E4: 0 | F4: 0 | G4: 0 | H4: 4034.86
A5: 43985 | B5: 0 | C5: 0 | D5: 102 | E5: 0 | F5: 0 | G5: 0 | H5: 4034.84
A6: 43986 | B6: 38 | C6: 0 | D6: 110 | E6: 0 | F6: 0 | G6: 0 | H6: 4034.82 | I6: * 06:00 0/50
A7: 43987 | B7: 50 | C7: 0 | D7: 110 | E7: 0 | F7: 0 | G7: 0 | H7: 4034.81
A8: 43988 | B8: 50 | C8: 0 | D8: 98 | E8: 0 | F8: 0 | G8: 0 | H8: 4034.75
A9: 43989 | B9: 50 | C9: 0 | D9: 97 | E9: 0.08 | F9: 0 | G9: 0 | H9: 4034.7
A10: 43990 | B10: 50 | C10: 0 | D10: 99 | E10: 0.01 | F10: 0 | G10: 0 | H10: 4034.68
A11: 43991 | B11: 50 | C11: 0 | D11: 103 | E11: 0 | F11: 0 | G11: 0 | H11: 4034.68
A12: 43992 | B12: 50 | C12: 0 | D12: 121 | E12: 0 | F12: 0 | G12: 0 | H12: 4034.68
A13: 43993 | B13: 50 | C13: 0 | D13: 112 | E13: 0 | F13: 0 | G13: 0 | H13: 4034.66
A14: 43994 | B14: 50 | C14: 0 | D14: 117 | E14: 0 | F14: 0 | G14: 0 | H14: 4034.64
A15: 43995 | B15: 85 | C15: 0 | D15: 129 | E15: 0.08 | F15: 0 | G15: 0 | H15: 4034.64 | I15: *07:00 50/100
A16: 43996 | B16: 100 | C16: 0 | D16: 117 | E16: 0 | F16: 0 | G16: 0 | H16: 4034.64
A17: 43997 | B17: 100 | C17: 0 | D17: 121 | E17: 0 | F17: 0 | G17: 0 | H17: 4034.62
A18: 43998 | B18: 100 | C18: 0 | D18: 123 | E18: T | F18: 0 | G18: 0 | H18: 4034.62
A19: 43999 | B19: 100 | C19: 0 | D19: 114 | E19: 0 | F19: 0 | G19: 0 | H19: 4034.62
A20: 44000 | B20: 88 | C20: 0 | D20: 117 | E20: 0 | F20: 0 | G20: 0 | H20: 4034.6 | I20: * 12:00 100/75
A21: 44001 | B21: 113 | C21: 0 | D21: 145 | E21: 0 | F21: 0 | G21: 0 | H21: 4034.6 | I21: * 12:00 75/125
A22: 44002 | B22: 133 | C22: 0 | D22: 187 | E22: 0 | F22: 0 | G22: 0 | H22: 4034.6 | I22: * 16:00 125/150
A23: 44003 | B23: 150 | C23: 0 | D23: 180 | E23: 0 | F23: 0 | G23: 0 | H23: 4034.6
A24: 44004 | B24: 195 | C24: 0 | D24: 156 | E24: 0 | F24: 0 | G24: 0 | H24: 4034.6 | I24: * 02:30 150/200
A25: 44005 | B25: 200 | C25: 0 | D25: 193 | E25: 0 | F25: 0 | G25: 0 | H25: 4034.6
A26: 44006 | B26: 238 | C26: 0 | D26: 221 | E26: 0 | F26: 0 | G26: 0 | H26: 4034.58 | I26: * correction Station 48 15:00 200/300
A27: 44007 | B27: 313 | C27: 0 | D27: 230 | E27: 0 | F27: 0 | G27: 0 | H27: 4034.55 | I27: * 18:00 300/350
A28: 44008 | B28: 335 | C28: 0 | D28: 284 | E28: 0 | F28: 0 | G28: 0 | H28: 4034.54 | I28: * 17:00 350/300
A29: 44009 | B29: 340 | C29: 0 | D29: 287 | E29: 0 | F29: 0 | G29: 0 | H29: 4034.52 | I29: * 05:00 300/350
A30: 44010 | B30: 344 | C30: 0 | D30: 276 | E30: 0 | F30: 0 | G30: 0 | H30: 4034.46 | I30: * 21:00 350/300
A31: 44011 | B31: 267 | C31: 0 | D31: 260 | E31: 0 | F31: 0 | G31: 0 | H31: 4034.46 | I31: * 08:00 300/250
A32: 44012 | B32: 233 | C32: 0 | D32: 251 | E32: 0 | F32: 0 | G32: 0 | H32: 4034.44 | I32: * 15:00 250/225 * 16:30 225/200
A33: Monthly Total | B33: =SUM(B3:B32) -> 3872 | C33: =SUM(C3:C32) -> 0 | D33: =SUM(D3:D32) -> 4634 | E33: =SUM(E3:E32) -> 0.17 | F33: =SUM(F3:F32) -> 0 | G33: =SUM(G3:G32) -> 0
A34: WY Total | B34: =SUM(B33+'May 2020'!B35) -> 12528 | C34: =SUM(C33+'May 2020'!C35) -> 3879 | D34: =SUM(D33+'May 2020'!D35) -> 19475 | E34: =SUM(E33+'May 2020'!E35) -> 5.53 | F34: =SUM(F33+'May 2020'!F35) -> 14.6 | G34: =SUM(G33+'May 2020'!G35) -> 14754
A36: Acre Feet | B36: =SUM(B3:B32)*1.9835 -> 7680.112 | C36: =SUM(C3:C32)*1.9835 -> 0 | D36: =SUM(D3:D32)*1.9835 -> 9191.539
A38: WY AF Total | B38: =SUM(B36+'May 2020'!B39) -> 29109.846 | C38: =SUM(C36+'May 2020'!C39) -> 9703.282 | D38: =SUM(D36+'May 2020'!D39) -> 46211.583
G40: * COMPUTATIONAL PURPOSES ONLY! Do Not Enter Data in the Red Columns
A42: *This is computation purposes only for Station 48
A43: Sta 48
F44: =SUM(24-D44) -> 24 | G44: =SUM(C44+E44) -> 0 | H44: =SUM(C44/24*D44+G44/24*F44) -> 0
...

Sheet May 2020
A1: DATE | B1: STATION 48 | C1: ANDERSON-ROSE | D1: J CANAL | E1: TULE LAKE PRECIP | F1: TULE LAKE SNOW | G1: D PLANT | H1: TULE LAKE ELEV. | I1: CHANGES @ STATION 48
B2: (in CFS) | C2: (in CFS) | D2: (in CFS) | G2: (in AF)
A3: 43952 | B3: 125 | C3: 0 | D3: 227 | E3: 0 | F3: 0 | G3: 0 | H3: 4034.85
A4: 43953 | B4: 87 | C4: 0 | D4: 172 | E4: 0 | F4: 0 | G4: 0 | H4: 4034.85 | I4: *10:00 125/75 * 15:30 75/50
A5: 43954 | B5: 37 | C5: 0 | D5: 165 | E5: 0.07 | F5: 0 | G5: 0 | H5: 4034.85 | I5: *10:00 50/28
A6: 43955 | B6: 28 | C6: 0 | D6: 207 | E6: 0 | F6: 0 | G6: 0 | H6: 4034.86
A7: 43956 | B7: 36 | C7: 0 | D7: 132 | E7: T | F7: 0 | G7: 0 | H7: 4034.88 | I7: * 15:00 28/50
A8: 43957 | B8: 57 | C8: 0 | D8: 130 | E8: T | F8: 0 | G8: 0 | H8: 4034.88 | I8: * 17:00 50/75
A9: 43958 | B9: 75 | C9: 0 | D9: 126 | E9: 0 | F9: 0 | G9: 0 | H9: 4034.88
A10: 43959 | B10: 75 | C10: 0 | D10: 123 | E10: 0 | F10: 0 | G10: 0 | H10: 4034.88
A11: 43960 | B11: 75 | C11: 0 | D11: 125 | E11: 0 | F11: 0 | G11: 0 | H11: 4034.88
A12: 43961 | B12: 75 | C12: 0 | D12: 121 | E12: T | F12: 0 | G12: 0 | H12: 4034.88
A13: 43962 | B13: 93 | C13: 0 | D13: 117 | E13: 0 | F13: 0 | G13: 0 | H13: 4034.86 | I13: * 06:30 75/100
A14: 43963 | B14: 83 | C14: 0 | D14: 109 | E14: 0.07 | F14: 0 | G14: 0 | H14: 4034.86 | I14: * 08:00 100/75
A15: 43964 | B15: 58 | C15: 0 | D15: 117 | E15: 0.24 | F15: 0 | G15: 0 | H15: 4034.84 | I15: * 08:00 75/50
A16: 43965 | B16: 31 | C16: 0 | D16: 154 | E16: 0.05 | F16: 0 | G16: 0 | H16: 4034.84 | I16: * 06:00 50/25
A17: 43966 | B17: 25 | C17: 0 | D17: 152 | E17: 0.03 | F17: 0 | G17: 0 | H17: 4034.82
A18: 43967 | B18: 25 | C18: 0 | D18: 110 | E18: 0 | F18: 0 | G18: 0 | H18: 4034.82
A19: 43968 | B19: 11 | C19: 0 | D19: 143 | E19: 0.1 | F19: 0 | G19: 0 | H19: 4034.82 | I19: * 09:00 25/18 * 11:00 18/0
A20: 43969 | B20: 0 | C20: 0 | D20: 133 | E20: 0.45 | F20: 0 | G20: 0 | H20: 4034.84
A21: 43970 | B21: 0 | C21: 0 | D21: 109 | E21: 0 | F21: 0 | G21: 0 | H21: 4034.86
A22: 43971 | B22: 0 | C22: 0 | D22: 112 | E22: T | F22: 0 | G22: 0 | H22: 4034.88
A23: 43972 | B23: 0 | C23: 0 | D23: 113 | E23: T | F23: 0 | G23: 0 | H23: 4034.9
A24: 43973 | B24: 0 | C24: 0 | D24: 98 | E24: 0 | F24: 0 | G24: 0 | H24: 4034.9
A25: 43974 | B25: 0 | C25: 0 | D25: 91 | E25: 0 | F25: 0 | G25: 0 | H25: 4034.92
A26: 43975 | B26: 0 | C26: 0 | D26: 87 | E26: 0 | F26: 0 | G26: 0 | H26: 4034.92
A27: 43976 | B27: 25 | C27: 0 | D27: 91 | E27: 0 | F27: 0 | G27: 0 | H27: 4034.92 | I27: * 00:00 0/25
A28: 43977 | B28: 23 | C28: 0 | D28: 91 | E28: 0 | F28: 0 | G28: 0 | H28: 4034.92 | I28: * 15:30 25/18
A29: 43978 | B29: 18 | C29: 0 | D29: 80 | E29: 0 | F29: 0 | G29: 0 | H29: 4034.92
A30: 43979 | B30: 7 | C30: 0 | D30: 82 | E30: 0 | F30: 0 | G30: 0 | H30: 4034.9 | I30: * 08:30 18/0
A31: 43980 | B31: 0 | C31: 0 | D31: 93 | E31: 0 | F31: 0 | G31: 0 | H31: 4034.9
A32: 43981 | B32: 0 | C32: 0 | D32: 72 | E32: 0.06 | F32: 0 | G32: 0 | H32: 4034.88
A33: 43982 | B33: 0 | C33: 0 | D33: 72 | E33: 0.02 | F33: 0 | G33: 0 | H33: 4034.86 | I33: Correction D-Plant 0
A34: Monthly Total | B34: =SUM(B3:B33) -> 1069 | C34: =SUM(C3:C33) -> 0 | D34: =SUM(D3:D33) -> 3754 | E34: =SUM(E3:E33) -> 1.09 | F34: =SUM(F3:F33) -> 0 | G34: =SUM(G3:G33) -> 0
A35: WY Total | B35: =SUM(B34+'Apr 2020'!B34) -> 8656 | C35: =SUM(C34+'Apr 2020'!C34) -> 3879 | D35: =SUM(D34+'Apr 2020'!D34) -> 14841 | E35: =SUM(E34+'Apr 2020'!E34) -> 5.36 | F35: =SUM(F34+'Apr 2020'!F34) -> 14.6 | G35: =SUM(G34+'Apr 2020'!G34) -> 14754
A37: Acre Feet | B37: =SUM(B3:B33)*1.9835 -> 2120.3615 | C37: =SUM(C3:C33)*1.9835 -> 0 | D37: =SUM(D3:D33)*1.9835 -> 7446.059
A39: WY AF Total | B39: =SUM(B37+'Apr 2020'!B38) -> 21429.734 | C39: =SUM(C37+'Apr 2020'!C38) -> 9703.282 | D39: =SUM(D37+'Apr 2020'!D38) -> 37020.044
G41: * COMPUTATIONAL PURPOSES ONLY! Do Not Enter Data in the Red Columns
A43: *This is computation purposes only for Station 48
A44: Sta 48
...

Sheet Apr 2020
A1: DATE | B1: STATION 48 | C1: ANDERSON-ROSE | D1: J CANAL | E1: TULE LAKE PRECIP | F1: TULE LAKE SNOW | G1: D PLANT | H1: TULE LAKE ELEV. | I1: CHANGES @ STATION 48
B2: (in CFS) | C2: (in CFS) | D2: (in CFS) | G2: (in AF)
A3: 43922 | B3: 30 | C3: 0 | D3: 50 | E3: 0 | F3: 0 | G3: 0 | H3: 4034.94
A4: 43923 | B4: 30 | C4: 0 | D4: 50 | E4: 0 | F4: 0 | G4: 0 | H4: 4034.92
A5: 43924 | B5: 30 | C5: 0 | D5: 50 | E5: 0 | F5: 0 | G5: 0 | H5: 4034.92
A6: 43925 | B6: 30 | C6: 0 | D6: 50 | E6: 0.07 | F6: 0 | G6: 0 | H6: 4034.9
A7: 43926 | B7: 30 | C7: 0 | D7: 50 | E7: 0.01 | F7: 0 | G7: 0 | H7: 4034.9
A8: 43927 | B8: 36 | C8: 0 | D8: 50 | E8: T | F8: 0 | G8: 0 | H8: 4034.9 | I8: * 10:00 30/40 correction 50 to 40 cfs
A9: 43928 | B9: 35 | C9: 0 | D9: 50 | E9: T | F9: 0 | G9: 0 | H9: 4034.9 | I9: *13:00 40/30
A10: 43929 | B10: 30 | C10: 0 | D10: 56 | E10: 0 | F10: 0 | G10: 0 | H10: 4034.92
A11: 43930 | B11: 36 | C11: 0 | D11: 70 | E11: 0 | F11: 0 | G11: 0 | H11: 4034.92 | I11: * 08:30 30/40
A12: 43931 | B12: 46 | C12: 0 | D12: 85 | E12: 0 | F12: 0 | G12: 0 | H12: 4034.92 | I12: * 08:30 40/50
A13: 43932 | B13: 67 | C13: 0 | D13: 93 | E13: 0 | F13: 0 | G13: 0 | H13: 4034.9 | I13: * 08:00 50/75
A14: 43933 | B14: 86 | C14: 0 | D14: 100 | E14: 0 | F14: 0 | G14: 0 | H14: 4034.88 | I14: * 13:00 75/100
A15: 43934 | B15: 125 | C15: 0 | D15: 126 | E15: 0 | F15: 0 | G15: 0 | H15: 4034.84 | I15: * 00:00 100/150 * 12:00 150/100
A16: 43935 | B16: 100 | C16: 0 | D16: 138 | E16: 0 | F16: 0 | G16: 0 | H16: 4034.82
A17: 43936 | B17: 100 | C17: 0 | D17: 126 | E17: 0 | F17: 0 | G17: 0 | H17: 4034.8
A18: 43937 | B18: 78 | C18: 0 | D18: 155 | E18: 0 | F18: 0 | G18: 0 | H18: 4034.82 | I18: * 08:00 100/50 * 14:00 50/75
A19: 43938 | B19: 79 | C19: 0 | D19: 148 | E19: 0 | F19: 0 | G19: 0 | H19: 4034.81 | I19: * 18:00 75/100
A20: 43939 | B20: 100 | C20: 0 | D20: 124 | E20: 0 | F20: 0 | G20: 0 | H20: 4034.8
A21: 43940 | B21: 100 | C21: 0 | D21: 116 | E21: 0 | F21: 0 | G21: 0 | H21: 4034.8 | I21: correction moved to 4/20
A22: 43941 | B22: 84 | C22: 0 | D22: 129 | E22: 0 | F22: 0 | G22: 0 | H22: 4034.8 | I22: * 09:00 100/75
A23: 43942 | B23: 75 | C23: 8 | D23: 151 | E23: 0 | F23: 0 | G23: 0 | H23: 4034.8
A24: 43943 | B24: 81 | C24: 0 | D24: 176 | E24: 0.01 | F24: 0 | G24: 0 | H24: 4034.8 | I24: * 18:00 75/100
A25: 43944 | B25: 88 | C25: 0 | D25: 201 | E25: 0.01 | F25: 0 | G25: 0 | H25: 4034.8 | I25: * 12:00 100/75 00:00 75/100
A26: 43945 | B26: 100 | C26: 0 | D26: 208 | E26: 0 | F26: 0 | G26: 0 | H26: 4034.82
A27: 43946 | B27: 102 | C27: 0 | D27: 210 | E27: 0 | F27: 0 | G27: 0 | H27: 4034.83 | I27: * 22:30 100/125
A28: 43947 | B28: 117 | C28: 0 | D28: 206 | E28: 0 | F28: 0 | G28: 0 | H28: 4034.84 | I28: * 16:30 125/100
A29: 43948 | B29: 71 | C29: 6 | D29: 196 | E29: 0 | F29: 0 | G29: 0 | H29: 4034.85 | I29: * 03:30 100/75 * 16:30 75/50
A30: 43949 | B30: 52 | C30: 0 | D30: 209 | E30: 0 | F30: 0 | G30: 0 | H30: 4034.85 | I30: * 23:00 50/100
A31: 43950 | B31: 100 | C31: 0 | D31: 224 | E31: 0 | F31: 0 | G31: 0 | H31: 4034.85
A32: 43951 | B32: 110 | C32: 0 | D32: 226 | E32: 0 | F32: 0 | G32: 0 | H32: 4034.85 | I32: * 14:00 100/125
A33: Monthly Total | B33: =SUM(B3:B32) -> 2148 | C33: =SUM(C3:C32) -> 14 | D33: =SUM(D3:D32) -> 3823 | E33: =SUM(E3:E32) -> 0.1 | F33: =SUM(F3:F32) -> 0 | G33: =SUM(G3:G32) -> 0
A34: WY Total | B34: =SUM(B33+'Mar 2020'!B35) -> 7587 | C34: =SUM(C33+'Mar 2020'!C35) -> 3879 | D34: =SUM(D33+'Mar 2020'!D35) -> 11087 | E34: =SUM(E33+'Mar 2020'!E35) -> 4.27 | F34: =SUM(F33+'Mar 2020'!F35) -> 14.6 | G34: =SUM(G33+'Mar 2020'!G35) -> 14754
A36: Acre Feet | B36: =SUM(B3:B33)*1.9835 -> 8521.116 | C36: =SUM(C3:C33)*1.9835 -> 55.538 | D36: =SUM(D3:D33)*1.9835 -> 15165.841
A38: WY AF Total | B38: =SUM(B36+'Mar 2020'!B39) -> 19309.372 | C38: =SUM(C36+'Mar 2020'!C39) -> 9703.282 | D38: =SUM(D36+'Mar 2020'!D39) -> 29573.985
G40: * COMPUTATIONAL PURPOSES ONLY! Do Not Enter Data in the Red Columns
A42: *This is computation purposes only for Station 48
A43: Sta 48
F44: =SUM(24-D44) -> 24 | G44: =SUM(C44+E44) -> 0 | H44: =SUM(C44/24*D44+G44/24*F44) -> 0
...

Sheet Mar 2020
A1: DATE | B1: STATION 48 | C1: ANDERSON-ROSE | D1: J CANAL | E1: TULE LAKE PRECIP | F1: TULE LAKE SNOW | G1: D PLANT | H1: TULE LAKE ELEV. | I1: CHANGES @ STATION 48
B2: (in CFS) | C2: (in CFS) | D2: (in CFS) | G2: (in AF)
A3: 43891 | B3: 0 | C3: 0 | D3: 20 | E3: 0 | F3: 0 | G3: 0 | H3: 4034.82
A4: 43892 | B4: 13 | C4: 0 | D4: 20 | E4: 0 | F4: 0 | G4: 0 | H4: 4034.82 | I4: *09:00 0/20
A5: 43893 | B5: 20 | C5: 0 | D5: 25 | E5: 0 | F5: 0 | G5: 0 | H5: 4034.85
A6: 43894 | B6: 20 | C6: 0 | D6: 40 | E6: 0 | F6: 0 | G6: 0 | H6: 4034.88
A7: 43895 | B7: 20 | C7: 0 | D7: 40 | E7: 0 | F7: 0 | G7: 0 | H7: 4034.88
A8: 43896 | B8: 20 | C8: 0 | D8: 40 | E8: 0 | F8: 0 | G8: 0 | H8: 4034.88
A9: 43897 | B9: 20 | C9: 0 | D9: 40 | E9: 0.07 | F9: 0.4 | G9: 0 | H9: 4034.9
A10: 43898 | B10: 20 | C10: 0 | D10: 40 | E10: 0.01 | F10: 0 | G10: 0 | H10: 4034.9
A11: 43899 | B11: 20 | C11: 0 | D11: 40 | E11: T | F11: 0 | G11: 0 | H11: 4034.9
A12: 43900 | B12: 20 | C12: 0 | D12: 40 | E12: T | F12: 0 | G12: 0 | H12: 4034.92
A13: 43901 | B13: 20 | C13: 0 | D13: 40 | E13: 0 | F13: 0 | G13: 0 | H13: 4034.92
A14: 43902 | B14: 20 | C14: 0 | D14: 40 | E14: 0 | F14: 0 | G14: 0 | H14: 4034.92
A15: 43903 | B15: 20 | C15: 0 | D15: 40 | E15: 0 | F15: 0 | G15: 0 | H15: 4034.92
A16: 43904 | B16: 20 | C16: 0 | D16: 40 | E16: 0.03 | F16: 0 | G16: 0 | H16: 4034.92
A17: 43905 | B17: 20 | C17: 0 | D17: 40 | E17: 0.03 | F17: T | G17: 0 | H17: 4034.92
A18: 43906 | B18: 20 | C18: 0 | D18: 40 | E18: T | F18: 0 | G18: 0 | H18: 4034.92
A19: 43907 | B19: 20 | C19: 0 | D19: 40 | E19: 0 | F19: 0 | G19: 0 | H19: 4034.93
A20: 43908 | B20: 20 | C20: 0 | D20: 40 | E20: 0.33 | F20: 4 | G20: 0 | H20: 4034.94
A21: 43909 | B21: 20 | C21: 0 | D21: 40 | E21: 0 | F21: 0 | G21: 0 | H21: 4034.95
A22: 43910 | B22: 25 | C22: 0 | D22: 45 | E22: 0 | F22: 0 | G22: 0 | H22: 4034.96 | I22: *1200 20/30
A23: 43911 | B23: 30 | C23: 0 | D23: 50 | E23: 0.01 | F23: 0 | G23: 0 | H23: 4034.96
A24: 43912 | B24: 30 | C24: 0 | D24: 50 | E24: 0 | F24: 0 | G24: 0 | H24: 4034.96
A25: 43913 | B25: 30 | C25: 0 | D25: 50 | E25: T | F25: 0 | G25: 0 | H25: 4034.96
A26: 43914 | B26: 30 | C26: 0 | D26: 50 | E26: 0.04 | F26: 0 | G26: 0 | H26: 4034.96
A27: 43915 | B27: 30 | C27: 0 | D27: 50 | E27: 0.1 | F27: 0 | G27: 0 | H27: 4034.96
A28: 43916 | B28: 30 | C28: 0 | D28: 50 | E28: T | F28: 0 | G28: 0 | H28: 4034.96
A29: 43917 | B29: 30 | C29: 0 | D29: 50 | E29: 0 | F29: 0 | G29: 0 | H29: 4034.96
A30: 43918 | B30: 30 | C30: 0 | D30: 50 | E30: T | F30: 0 | G30: 0 | H30: 4034.96
A31: 43919 | B31: 30 | C31: 0 | D31: 50 | E31: 0.04 | F31: 0 | G31: 0 | H31: 4034.96
A32: 43920 | B32: 30 | C32: 0 | D32: 50 | E32: 0 | F32: 0 | G32: 0 | H32: 4034.94
A33: 43921 | B33: 30 | C33: 0 | D33: 50 | E33: T | F33: 0 | G33: 0 | H33: 4034.94
A34: Monthly Total | B34: =SUM(B3:B33) -> 708 | C34: =SUM(C3:C33) -> 0 | D34: =SUM(D3:D33) -> 1300 | E34: =SUM(E3:E33) -> 0.66 | F34: =SUM(F3:F33) -> 4.4 | G34: =SUM(G3:G33) -> 0
A35: WY Total | B35: =SUM(B34+'Feb 2020'!B33) -> 5439 | C35: =SUM(C34+'Feb 2020'!C33) -> 3865 | D35: =SUM(D34+'Feb 2020'!D33) -> 7264 | E35: =SUM(E34+'Feb 2020'!E33) -> 4.17 | F35: =SUM(F34+'Feb 2020'!F33) -> 14.6 | G35: =SUM(G34+'Feb 2020'!G33) -> 14754
A37: Acre Feet | B37: =SUM(B3:B33)*1.9835 -> 1404.318 | C37: =SUM(C3:C33)*1.9835 -> 0 | D37: =SUM(D3:D33)*1.9835 -> 2578.55
A39: WY AF Total | B39: =SUM(B37+'Feb 2020'!B37) -> 10788.256 | C39: =SUM(C37+'Feb 2020'!C37) -> 9647.744 | D39: =SUM(D37+'Feb 2020'!D37) -> 14408.144
G41: * COMPUTATIONAL PURPOSES ONLY! Do Not Enter Data in the Red Columns
A43: *This is computation purposes only for Station 48
A44: Sta 48
...

Sheet Feb 2020
A1: DATE | B1: STATION 48 | C1: ANDERSON-ROSE | D1: J CANAL | E1: TULE LAKE PRECIP | F1: TULE LAKE SNOW | G1: D PLANT | H1: TULE LAKE ELEV. | I1: CHANGES @ STATION 48
B2: (in CFS) | C2: (in CFS) | D2: (in CFS) | G2: (in AF)
A3: 43862 | B3: 0 | C3: 58 | D3: 0 | E3: 0 | F3: 0 | G3: 0 | H3: 4034.88
A4: 43863 | B4: 0 | C4: 30 | D4: 0 | E4: 0 | F4: 0 | G4: 0 | H4: 4034.88
A5: 43864 | B5: 0 | C5: 30 | D5: 0 | E5: 0 | F5: 0 | G5: 0 | H5: 4034.88
A6: 43865 | B6: 0 | C6: 30 | D6: 0 | E6: T | F6: 0 | G6: 102 | H6: 4034.9 | I6: 1 Unit D-Plant 08:40
A7: 43866 | B7: 0 | C7: 30 | D7: 0 | E7: 0.02 | F7: 0 | G7: 160 | H7: 4034.9
A8: 43867 | B8: 0 | C8: 30 | D8: 0 | E8: T | F8: 0 | G8: 160 | H8: 4034.9
A9: 43868 | B9: 0 | C9: 30 | D9: 0 | E9: T | F9: 0 | G9: 160 | H9: 4034.88
A10: 43869 | B10: 0 | C10: 30 | D10: 0 | E10: 0 | F10: 0 | G10: 160 | H10: 4034.86
A11: 43870 | B11: 0 | C11: 28 | D11: 0 | E11: 0 | F11: 0 | G11: 160 | H11: 4034.8
A12: 43871 | B12: 0 | C12: 25 | D12: 0 | E12: 0 | F12: 0 | G12: 160 | H12: 4034.8
A13: 43872 | B13: 0 | C13: 25 | D13: 0 | E13: 0 | F13: 0 | G13: 160 | H13: 4034.8
A14: 43873 | B14: 0 | C14: 25 | D14: 0 | E14: T | F14: 0 | G14: 160 | H14: 4034.78
A15: 43874 | B15: 0 | C15: 25 | D15: 0 | E15: 0 | F15: 0 | G15: 160 | H15: 4034.78
A16: 43875 | B16: 0 | C16: 25 | D16: 0 | E16: 0 | F16: 0 | G16: 160 | H16: 4034.76
A17: 43876 | B17: 0 | C17: 25 | D17: 0 | E17: 0 | F17: 0 | G17: 160 | H17: 4034.76
A18: 43877 | B18: 0 | C18: 25 | D18: 0 | E18: 0.22 | F18: T | G18: 160 | H18: 4034.76
A19: 43878 | B19: 0 | C19: 23 | D19: 0 | E19: 0 | F19: 0 | G19: 160 | H19: 4034.76
A20: 43879 | B20: 0 | C20: 20 | D20: 0 | E20: T | F20: 0 | G20: 160 | H20: 4034.76
A21: 43880 | B21: 0 | C21: 20 | D21: 0 | E21: 0 | F21: 0 | G21: 63 | H21: 4034.75 | I21: D-Plant off 09:25
A22: 43881 | B22: 0 | C22: 20 | D22: 0 | E22: 0 | F22: 0 | G22: 0 | H22: 4034.75
A23: 43882 | B23: 0 | C23: 20 | D23: 0 | E23: 0 | F23: 0 | G23: 0 | H23: 4034.74
A24: 43883 | B24: 0 | C24: 20 | D24: 0 | E24: 0 | F24: 0 | G24: 0 | H24: 4034.74
A25: 43884 | B25: 0 | C25: 20 | D25: 0 | E25: 0 | F25: 0 | G25: 0 | H25: 4034.76
A26: 43885 | B26: 0 | C26: 20 | D26: 0 | E26: 0 | F26: 0 | G26: 0 | H26: 4034.77
A27: 43886 | B27: 0 | C27: 20 | D27: 5 | E27: 0 | F27: 0 | G27: 0 | H27: 4034.77
A28: 43887 | B28: 0 | C28: 15 | D28: 10 | E28: 0 | F28: 0 | G28: 0 | H28: 4034.8
A29: 43888 | B29: 0 | C29: 0 | D29: 15 | E29: 0 | F29: 0 | G29: 0 | H29: 4034.8
A30: 43889 | B30: 0 | C30: 0 | D30: 20 | E30: 0 | F30: 0 | G30: 0 | H30: 4034.8
A31: 43890 | B31: 0 | C31: 0 | D31: 20 | E31: 0 | F31: 0 | G31: 0 | H31: 4034.82
A32: Monthly Total | B32: =SUM(B3:B31) -> 0 | C32: =SUM(C3:C31) -> 669 | D32: =SUM(D3:D31) -> 70 | E32: =SUM(E3:E31) -> 0.24 | F32: =SUM(F3:F31) -> 0 | G32: =SUM(G3:G31) -> 2405
A33: WY Total | B33: =SUM(B32+'Jan 2020'!B35) -> 4731 | C33: =SUM(C32+'Jan 2020'!C35) -> 3865 | D33: =SUM(D32+'Jan 2020'!D35) -> 5964 | E33: =SUM(E32+'Jan 2020'!E35) -> 3.51 | F33: =SUM(F32+'Jan 2020'!F35) -> 10.2 | G33: =SUM(G32+'Jan 2020'!G35) -> 14754
A35: Acre Feet | B35: =SUM(B3:B31)*1.9835 -> 0 | C35: =SUM(C3:C31)*1.9835 -> 1326.9615 | D35: =SUM(D3:D31)*1.9835 -> 138.845
A37: WY AF Total | B37: =SUM(B35+'Jan 2020'!B39) -> 9383.9385 | C37: =SUM(C35+'Jan 2020'!C39) -> 9647.744 | D37: =SUM(D35+'Jan 2020'!D39) -> 11829.594
G39: * COMPUTATIONAL PURPOSES ONLY! Do Not Enter Data in the Red Columns
A41: *This is computation purposes only for Station 48
A42: Sta 48
F43: =SUM(24-D43) -> 24 | G43: =SUM(C43+E43) -> 0 | H43: =SUM(C43/24*D43+G43/24*F43) -> 0
F44: =SUM(24-D44) -> 24 | G44: =SUM(C44+E44) -> 0 | H44: =SUM(C44/24*D44+G44/24*F44) -> 0
...

Sheet Jan 2020
A1: DATE | B1: STATION 48 | C1: ANDERSON-ROSE | D1: J CANAL | E1: TULE LAKE PRECIP | F1: TULE LAKE SNOW | G1: D PLANT | H1: TULE LAKE ELEV. | I1: CHANGES @ STATION 48
B2: (in CFS) | C2: (in CFS) | D2: (in CFS) | G2: (in AF)
A3: 43831 | B3: 0 | C3: 25 | D3: 0 | E3: 0.09 | F3: 0 | G3: 0 | H3: 4034.54
A4: 43832 | B4: 0 | C4: 25 | D4: 0 | E4: 0 | F4: 0 | G4: 0 | H4: 4034.53
A5: 43833 | B5: 0 | C5: 25 | D5: 0 | E5: 0 | F5: 0 | G5: 0 | H5: 4034.53
A6: 43834 | B6: 0 | C6: 25 | D6: 0 | E6: 0.05 | F6: 0 | G6: 0 | H6: 4034.53
A7: 43835 | B7: 0 | C7: 25 | D7: 0 | E7: 0 | F7: 0 | G7: 0 | H7: 4034.54
A8: 43836 | B8: 0 | C8: 25 | D8: 0 | E8: 0 | F8: 0 | G8: 0 | H8: 4034.54
A9: 43837 | B9: 0 | C9: 25 | D9: 0 | E9: 0 | F9: 0 | G9: 0 | H9: 4034.56
A10: 43838 | B10: 0 | C10: 25 | D10: 0 | E10: 0 | F10: 0 | G10: 0 | H10: 4034.56
A11: 43839 | B11: 0 | C11: 25 | D11: 0 | E11: 0.13 | F11: 0.5 | G11: 0 | H11: 4034.56
A12: 43840 | B12: 0 | C12: 25 | D12: 0 | E12: 0 | F12: 0 | G12: 0 | H12: 4034.56
A13: 43841 | B13: 0 | C13: 25 | D13: 0 | E13: 0.02 | F13: 0 | G13: 0 | H13: 4034.54
A14: 43842 | B14: 0 | C14: 25 | D14: 0 | E14: 0 | F14: 0 | G14: 0 | H14: 4034.52
A15: 43843 | B15: 0 | C15: 25 | D15: 0 | E15: 0.03 | F15: T | G15: 0 | H15: 4034.5
A16: 43844 | B16: 0 | C16: 25 | D16: 0 | E16: 0.1 | F16: 0.5 | G16: 0 | H16: 4034.54
A17: 43845 | B17: 0 | C17: 25 | D17: 0 | E17: 0.01 | F17: T | G17: 0 | H17: 4034.56
A18: 43846 | B18: 0 | C18: 25 | D18: 0 | E18: 0.17 | F18: 2 | G18: 0 | H18: 4034.58
A19: 43847 | B19: 0 | C19: 25 | D19: 0 | E19: 0.19 | F19: 3 | G19: 0 | H19: 4034.6
A20: 43848 | B20: 0 | C20: 25 | D20: 0 | E20: 0 | F20: 0 | G20: 0 | H20: 4034.62
A21: 43849 | B21: 0 | C21: 25 | D21: 0 | E21: 0 | F21: 0 | G21: 0 | H21: 4034.62
A22: 43850 | B22: 0 | C22: 25 | D22: 0 | E22: 0 | F22: 0 | G22: 0 | H22: 4034.64
A23: 43851 | B23: 0 | C23: 25 | D23: 0 | E23: 0.01 | F23: 0 | G23: 0 | H23: 4034.66
A24: 43852 | B24: 0 | C24: 25 | D24: 0 | E24: 0.01 | F24: 0 | G24: 0 | H24: 4034.66
A25: 43853 | B25: 0 | C25: 25 | D25: 0 | E25: T | F25: 0 | G25: 0 | H25: 4034.68
A26: 43854 | B26: 0 | C26: 25 | D26: 0 | E26: 0.15 | F26: 0 | G26: 0 | H26: 4034.7
A27: 43855 | B27: 0 | C27: 25 | D27: 0 | E27: 0.12 | F27: 0 | G27: 0 | H27: 4034.74
A28: 43856 | B28: 0 | C28: 39 | D28: 0 | E28: 0.25 | F28: 0 | G28: 0 | H28: 4034.76
A29: 43857 | B29: 0 | C29: 75 | D29: 0 | E29: 0.07 | F29: 0 | G29: 0 | H29: 4034.78
A30: 43858 | B30: 0 | C30: 75 | D30: 0 | E30: T | F30: 0 | G30: 0 | H30: 4034.78
A31: 43859 | B31: 0 | C31: 58 | D31: 0 | E31: 0 | F31: 0 | G31: 0 | H31: 4034.82
A32: 43860 | B32: 0 | C32: 52 | D32: 0 | E32: 0.04 | F32: 0 | G32: 0 | H32: 4034.86
A33: 43861 | B33: 0 | C33: 75 | D33: 0 | E33: 0.02 | F33: 0 | G33: 0 | H33: 4034.88
A34: Monthly Total | B34: =SUM(B3:B33) -> 0 | C34: =L31 -> 0 | D34: =SUM(D3:D33) -> 0 | E34: =SUM(E3:E33) -> 1.46 | F34: =SUM(F3:F33) -> 6 | G34: =SUM(G3:G33) -> 0
A35: WY Total | B35: =SUM(B34+'Dec 2019'!B35) -> 4731 | C35: =SUM(C34+'Dec 2019'!C35) -> 3196 | D35: =SUM(D34+'Dec 2019'!D35) -> 5894 | E35: =SUM(E34+'Dec 2019'!E35) -> 3.27 | F35: =SUM(F34+'Dec 2019'!F35) -> 10.2 | G35: =SUM(G34+'Dec 2019'!G35) -> 12349
A37: Acre Feet | B37: =SUM(B3:B33)*1.9835 -> 0 | C37: =SUM(C3:C33)*1.9835 -> 1981.5165 | D37: =SUM(D3:D33)*1.9835 -> 0
A39: WY AF Total | B39: =SUM(B37+'Dec 2019'!B39) -> 9383.9385 | C39: =SUM(C37+'Dec 2019'!C39) -> 8320.7825 | D39: =SUM(D37+'Dec 2019'!D39) -> 11690.749
G41: * COMPUTATIONAL PURPOSES ONLY! Do Not Enter Data in the Red Columns
A43: *This is computation purposes only for Station 48
A44: Sta 48
...

Sheet Dec 2019
A1: DATE | B1: STATION 48 | C1: ANDERSON-ROSE | D1: J CANAL | E1: TULE LAKE PRECIP | F1: TULE LAKE SNOW | G1: D PLANT | H1: TULE LAKE ELEV. | I1: CHANGES @ STATION 48
B2: (in CFS) | C2: (in CFS) | D2: (in CFS) | G2: (in AF)
A3: 43800 | B3: 0 | C3: 20 | D3: 0 | E3: 0.12 | F3: 1 | G3: 0 | H3: 4034.22
A4: 43801 | B4: 0 | C4: 20 | D4: 0 | E4: T | F4: 0 | G4: 0 | H4: 4034.24
A5: 43802 | B5: 0 | C5: 20 | D5: 0 | E5: 0.01 | F5: 0 | G5: 0 | H5: 4034.26
A6: 43803 | B6: 0 | C6: 20 | D6: 0 | E6: 0 | F6: 0 | G6: 0 | H6: 4034.3
A7: 43804 | B7: 0 | C7: 20 | D7: 0 | E7: 0.01 | F7: 0 | G7: 0 | H7: 4034.32
A8: 43805 | B8: 0 | C8: 20 | D8: 0 | E8: 0 | F8: 0 | G8: 0 | H8: 4034.34
A9: 43806 | B9: 0 | C9: 20 | D9: 0 | E9: 0.23 | F9: 0 | G9: 0 | H9: 4034.36
A10: 43807 | B10: 0 | C10: 20 | D10: 0 | E10: 0.01 | F10: 0 | G10: 0 | H10: 4034.38
A11: 43808 | B11: 0 | C11: 20 | D11: 0 | E11: 0.01 | F11: 0 | G11: 0 | H11: 4034.4
A12: 43809 | B12: 0 | C12: 20 | D12: 0 | E12: 0 | F12: 0 | G12: 0 | H12: 4034.42
A13: 43810 | B13: 0 | C13: 12 | D13: 0 | E13: 0.07 | F13: 0 | G13: 0 | H13: 4034.44
A14: 43811 | B14: 0 | C14: 2 | D14: 0 | E14: 0.16 | F14: 0 | G14: 0 | H14: 4034.44
A15: 43812 | B15: 0 | C15: 7 | D15: 0 | E15: 0.3 | F15: 0 | G15: 0 | H15: 4034.45
A16: 43813 | B16: 0 | C16: 23 | D16: 0 | E16: 0.27 | F16: 0 | G16: 0 | H16: 4034.48
... A29: 43826 | B29: 0 | C29: 30 | D29: 0 | E29: 0 | F29: 0 | G29: 0 | H29: 4034.54
A30: 43827 | B30: 0 | C30: 30 | D30: 0 | E30: T | F30: 0 | G30: 0 | H30: 4034.54
A31: 43828 | B31: 0 | C31: 30 | D31: 0 | E31: 0 | F31: 0 | G31: 0 | H31: 4034.54
A32: 43829 | B32: 0 | C32: 29 | D32: 0 | E32: 0 | F32: 0 | H32: 4034.54
A33: 43830 | B33: 0 | C33: 25 | D33: 0 | E33: 0 | F33: 0 | G33: 0 | H33: 4034.54
A34: Monthly Total | B34: =SUM(B3:B33) -> 0 | C34: =SUM(C3:C33) -> 965 | D34: =SUM(D3:D33) -> 0 | E34: =SUM(E3:E33) -> 1.34 | F34: =SUM(F3:F33) -> 1.2 | G34: =SUM(G3:G33) -> 0
A35: WY Total | B35: =SUM(B34+'Nov 2019'!B34) -> 4731 | C35: =SUM(C34+'Nov 2019'!C34) -> 3196 | D35: =SUM(D34+'Nov 2019'!D34) -> 5894 | E35: =SUM(E34+'Nov 2019'!E34) -> 1.81 | F35: =SUM(F34+'Nov 2019'!F34) -> 4.2 | G35: =SUM(G34+'Nov 2019'!G34) -> 12349
A37: Acre Feet | B37: =SUM(B3:B33)*1.9835 -> 0 | C37: =SUM(C3:C33)*1.9835 -> 1914.0775 | D37: =SUM(D3:D33)*1.9835 -> 0
A39: WY AF Total | B39: =SUM('Nov 2019'!B38+B37) -> 9383.9385 | C39: =SUM('Nov 2019'!C38+C37) -> 6339.266 | D39: =SUM('Nov 2019'!D38+D37) -> 11690.749
G41: * COMPUTATIONAL PURPOSES ONLY! Do Not Enter Data in the Red Columns
A43: *This is computation purposes only for Station 48
A44: Sta 48
F45: =SUM(24-D45) -> 24 | G45: =SUM(C45+E45) -> 0 | H45: =SUM(C45/24*D45+G45/24*F45) -> 0
F46: =SUM(24-D46) -> 24 | G46: =SUM(C46+E46) -> 0 | H46: =SUM(C46/24*D46+G46/24*F46) -> 0
F47: =SUM(24-D47) -> 24 | G47: =SUM(C47+E47) -> 0 | H47: =SUM(C47/24*D47+G47/24*F47) -> 0
F48: =SUM(24-D48) -> 24 | G48: =SUM(C48+E48) -> 0 | H48: =SUM(C48/24*D48+G48/24*F48) -> 0
F49: =SUM(24-D49) -> 24 | G49: =SUM(C49+E49) -> 0 | H49: =SUM(C49/24*D49+G49/24*F49) -> 0
A51: Use for more than 1 change in a day.
A52: **Station 48: | B52: Time | C52: Current CFS | D52: Hours Run | E52: +/- cfs | F52: Sub-total cfs
A58: Total Hours Run | D58: =SUM(D53:D57) -> 0 | E58: Total/Day cfs | F58: =SUM(F53:F57) -> 0

Sheet Nov 2019
A1: DATE | B1: STATION 48 | C1: ANDERSON-ROSE | D1: J CANAL | E1: TULE LAKE PRECIP | F1: TULE LAKE SNOW | G1: D PLANT | H1: TULE LAKE ELEV. | I1: CHANGES @ STATION 48
B2: (in CFS) | C2: (in CFS) | D2: (in CFS) | G2: (in AF)
A3: 43770 | B3: 75 | C3: 0 | D3: 125 | E3: 0 | F3: 0 | G3: 160 | H3: 4034.62
A4: 43771 | B4: 92 | C4: 0 | D4: 127 | E4: 0 | F4: 0 | G4: 160 | H4: 4034.62 | I4: * 10:00 75/100
A5: 43772 | B5: 117 | C5: 0 | D5: 137 | E5: 0 | F5: 0 | G5: 160 | H5: 4034.6 | I5: * 08:00 100/125
A6: 43773 | B6: 125 | C6: 0 | D6: 131 | E6: 0 | F6: 0 | G6: 160 | H6: 4034.58
A7: 43774 | B7: 125 | C7: 0 | D7: 140 | E7: 0 | F7: 0 | G7: 160 | H7: 4034.58
A8: 43775 | B8: 175 | C8: 1 | D8: 150 | E8: 0 | F8: 0 | G8: 241 | H8: 4034.54 | I8: * 08:00 125/175 * start 2nd unit D plant 09:40 *16:00 175/225
A9: 43776 | B9: 275 | C9: 111 | D9: 159 | E9: 0 | F9: 0 | G9: 318 | H9: 4034.54 | I9: *0800 225/300
A10: 43777 | B10: 300 | C10: 196 | D10: 153 | E10: 0 | F10: 0 | G10: 318 | H10: 4034.54
A11: 43778 | B11: 300 | C11: 207 | D11: 131 | E11: 0 | F11: 0 | G11: 318 | H11: 4034.56
A12: 43779 | B12: 278 | C12: 238 | D12: 114 | E12: 0 | F12: 0 | G12: 318 | H12: 4034.56 | I12: * 13.30 300/250
A13: 43780 | B13: 250 | C13: 205 | D13: 109 | E13: 0 | F13: 0 | G13: 318 | H13: 4034.56 | I13: station 48 corrected from 283
A14: 43781 | B14: 233 | C14: 181 | D14: 132 | E14: 0 | F14: 0 | G14: 318 | H14: 4034.56 | I14: * 16:00 250/200
A15: 43782 | B15: 175 | C15: 56 | D15: 166 | E15: 0 | F15: 0 | G15: 318 | H15: 4034.55 | I15: * 12:00 200/150
A16: 43783 | B16: 142 | C16: 11 | D16: 172 | E16: 0 | F16: 0 | G16: 318 | H16: 4034.54 | I16: * 16:00 150/125
A17: 43784 | B17: 117 | C17: 14 | D17: 158 | E17: 0 | F17: 0 | G17: 318 | H17: 4034.52 | I17: * 16:00 125/100
A18: 43785 | B18: 100 | C18: 0 | D18: 137 | E18: 0.02 | F18: 0 | G18: 318 | H18: 4034.48
A19: 43786 | B19: 94 | C19: 0 | D19: 119 | E19: 0.01 | F19: 0 | G19: 318 | H19: 4034.48 | I19: *18:00 100/75
A20: 43787 | B20: 116 | C20: 0 | D20: 120 | E20: 0 | F20: 0 | G20: 318 | H20: 4034.44 | I20: *9:00 75/100 * 16:00 100/175
A21: 43788 | B21: 175 | C21: 78 | D21: 115 | E21: 0.01 | F21: 0 | G21: 318 | H21: 4034.42
A22: 43789 | B22: 153 | C22: 69 | D22: 106 | E22: T | F22: 0 | G22: 318 | H22: 4034.38 | I22: *12:00 175/150 * 15:00 150/125
A23: 43790 | B23: 125 | C23: 51 | D23: 100 | E23: 0 | F23: 0 | G23: 318 | H23: 4034.35
A24: 43791 | B24: 125 | C24: 51 | D24: 90 | E24: 0 | F24: 0 | G24: 318 | H24: 4034.32
A25: 43792 | B25: 113 | C25: 56 | D25: 78 | E25: 0 | F25: 0 | G25: 318 | H25: 4034.32 | I25: *12:00 125/100
A26: 43793 | B26: 89 | C26: 49 | D26: 65 | E26: 0 | F26: 0 | G26: 318 | H26: 4034.31 | I26: *13:30 100/75
A27: 43794 | B27: 75 | C27: 14 | D27: 56 | E27: 0 | F27: 0 | G27: 318 | H27: 4034.28
A28: 43795 | B28: 56 | C28: 14 | D28: 25 | E28: 0.01 | F28: 2 | G28: 246 | H28: 4034.26 | I28: * 09:00 75/25 *12:00 25/50 (1 unit off D plant)
A29: 43796 | B29: 19 | C29: 0 | D29: 24 | E29: 0.02 | F29: 1 | G29: 60 | H29: 4034.25 | I29: * 09:00 50/0 * (D Plant OFF)
A30: 43797 | B30: 0 | C30: 0 | D30: 25 | E30: T | F30: T | G30: 0 | H30: 4034.23
A31: 43798 | B31: 0 | C31: 10 | D31: 15 | E31: T | F31: T | G31: 0 | H31: 4034.23
A32: 43799 | B32: 0 | C32: 20 | D32: 9 | E32: 0 | F32: 0 | G32: 0 | H32: 4034.22
A33: Monthly Total | B33: =SUM(B3:B32) -> 4019 | C33: =SUM(C3:C32) -> 1632 | D33: =SUM(D3:D32) -> 3188 | E33: =SUM(E3:E32) -> 0.07 | F33: =SUM(F3:F32) -> 3 | G33: =SUM(G3:G32) -> 7389
A34: WY Total | B34: =SUM(B33+'Oct 2019'!B35) -> 4731 | C34: =SUM(C33+'Oct 2019'!C35) -> 2231 | D34: =SUM(D33+'Oct 2019'!D35) -> 5894 | E34: =SUM(E33+'Oct 2019'!E35) -> 0.47 | F34: =SUM(F33+'Oct 2019'!F35) -> 3 | G34: =SUM(G33+'Oct 2019'!G35) -> 12349
A36: Acre Feet | B36: =SUM(B3:B32)*1.9835 -> 7971.6865 | C36: =SUM(C3:C32)*1.9835 -> 3237.072 | D36: =SUM(D3:D32)*1.9835 -> 6323.398
A38: WY AF Total | B38: =SUM('Oct 2019'!B39+B36) -> 9383.9385 | C38: =SUM('Oct 2019'!C39+C36) -> 4425.1885 | D38: =SUM('Oct 2019'!D39+D36) -> 11690.749
G40: * COMPUTATIONAL PURPOSES ONLY! Do Not Enter Data in the Red Columns
A42: *This is computation purposes only for Station 48
A43: Sta 48
F44: =SUM(24-D44) -> 24 | G44: =SUM(C44+E44) -> 0 | H44: =SUM(C44/24*D44+G44/24*F44) -> 0
...

Sheet Oct 2019
A1: DATE | B1: STATION 48 | C1: ANDERSON-ROSE | D1: J CANAL | E1: TULE LAKE PRECIP | F1: TULE LAKE SNOW | G1: D PLANT | H1: TULE LAKE ELEV. | I1: CHANGES @ STATION 48
B2: (in CFS) | C2: (in CFS) | D2: (in CFS)
A3: 43739 | B3: 0 | C3: 69 | D3: 44 | E3: 0 | F3: 0 | G3: 160 | H3: 4034.9
A4: 43740 | B4: 0 | C4: 72 | D4: 46 | E4: 0 | F4: 0 | G4: 160 | H4: 4034.9 | I4: Correction to Anderson Rose River Spill
A5: 43741 | B5: 0 | C5: 72 | D5: 46 | E5: 0 | F5: 0 | G5: 160 | H5: 4034.9
A6: 43742 | B6: 0 | C6: 69 | D6: 53 | E6: 0.01 | F6: 0 | G6: 160 | H6: 4034.9
A7: 43743 | B7: 0 | C7: 46 | D7: 62 | E7: 0 | F7: 0 | G7: 160 | H7: 4034.9
A8: 43744 | B8: 0 | C8: 19 | D8: 63 | E8: 0 | F8: 0 | G8: 160 | H8: 4034.89
A9: 43745 | B9: 0 | C9: 26 | D9: 63 | E9: 0 | F9: 0 | G9: 160 | H9: 4034.88
A10: 43746 | B10: 0 | C10: 49 | D10: 65 | E10: 0 | F10: 0 | G10: 160 | H10: 4034.86
A11: 43747 | B11: 0 | C11: 19 | D11: 93 | E11: 0 | F11: 0 | G11: 160 | H11: 4034.86
A12: 43748 | B12: 0 | C12: 13 | D12: 91 | E12: 0 | F12: 0 | G12: 160 | H12: 4034.86
A13: 43749 | B13: 0 | C13: 19 | D13: 93 | E13: 0 | F13: 0 | G13: 160 | H13: 4034.86
A14: 43750 | B14: 0 | C14: 12 | D14: 92 | E14: 0 | F14: 0 | G14: 160 | H14: 4034.86
A15: 43751 | B15: 0 | C15: 17 | D15: 86 | E15: 0 | F15: 0 | G15: 160 | H15: 4034.85
A16: 43752 | B16: 0 | C16: 23 | D16: 86 | E16: 0 | F16: 0 | G16: 160 | H16: 4034.84
... A23: 43759 | B23: 0 | C23: 0 | D23: 74 | E23: 0 | F23: 0 | G23: 160 | H23: 4034.8
A24: 43760 | B24: 23 | C24: 0 | D24: 82 | E24: 0 | F24: 0 | G24: 160 | H24: 4034.78 | I24: * 13:00 0/50
A25: 43761 | B25: 50 | C25: 0 | D25: 108 | E25: 0 | F25: 0 | G25: 160 | H25: 4034.78
A26: 43762 | B26: 50 | C26: 0 | D26: 115 | E26: 0 | F26: 0 | G26: 160 | H26: 4034.76
A27: 43763 | B27: 72 | C27: 0 | D27: 133 | E27: 0 | F27: 0 | G27: 160 | H27: 4034.74 | I27: * 0830 50/75 2100 75/125
A28: 43764 | B28: 125 | C28: 0 | D28: 129 | E28: 0 | F28: 0 | G28: 160 | H28: 4034.74
A29: 43765 | B29: 92 | C29: 0 | D29: 111 | E29: 0 | F29: 0 | G29: 160 | H29: 4034.74 | I29: * 0800 125/75
A30: 43766 | B30: 75 | C30: 0 | D30: 112 | E30: 0 | F30: 0 | G30: 160 | H30: 4034.7
A31: 43767 | B31: 75 | C31: 0 | D31: 131 | E31: 0 | F31: 0 | G31: 160 | H31: 4034.7
A32: 43768 | B32: 75 | C32: 0 | D32: 121 | E32: 0 | F32: 0 | G32: 160 | H32: 4034.66
A33: 43769 | B33: 75 | C33: 0 | D33: 109 | E33: 0 | F33: 0 | G33: 160 | H33: 4034.64
A34: Monthly Total | B34: =SUM(B3:B33) -> 712 | C34: =SUM(C3:C33) -> 599 | D34: =SUM(D3:D33) -> 2706 | E34: =SUM(E3:E33) -> 0.4 | F34: =SUM(F3:F33) -> 0 | G34: =SUM(G3:G33) -> 4960
A35: WY Total | B35: =SUM(B34+'Oct 2019'!B36) -> 712 | C35: =SUM(C34+'Oct 2019'!C36) -> 599 | D35: =SUM(D34+'Oct 2019'!D36) -> 2706 | E35: =SUM(E34+'Oct 2019'!E36) -> 0.4 | F35: =SUM(F34+'Oct 2019'!F36) -> 0 | G35: =SUM(G34+'Oct 2019'!G36) -> 4960
A37: Acre Feet | B37: =SUM(B3:B33)*1.9835 -> 1412.252 | C37: =SUM(C3:C33)*1.9835 -> 1188.1165 | D37: =SUM(D3:D33)*1.9835 -> 5367.351
A39: WY AF Total | B39: =SUM('Oct 2019'!B40+B37) -> 1412.252 | C39: =SUM('Oct 2019'!C40+C37) -> 1188.1165 | D39: =SUM('Oct 2019'!D40+D37) -> 5367.351
G41: * COMPUTATIONAL PURPOSES ONLY! Do Not Enter Data in the Red Columns
A43: *This is computation purposes only for Station 48
A44: Sta 48
F45: =SUM(24-D45) -> 24 | G45: =SUM(C45+E45) -> 0 | H45: =SUM(C45/24*D45+G45/24*F45) -> 0
F46: =SUM(24-D46) -> 24 | G46: =SUM(C46+E46) -> 0 | H46: =SUM(C46/24*D46+G46/24*F46) -> 0
F47: =SUM(24-D47) -> 24 | G47: =SUM(C47+E47) -> 0 | H47: =SUM(C47/24*D47+G47/24*F47) -> 0
F48: =SUM(24-D48) -> 24 | G48: =SUM(C48+E48) -> 0 | H48: =SUM(C48/24*D48+G48/24*F48) -> 0
F49: =SUM(24-D49) -> 24 | G49: =SUM(C49+E49) -> 0 | H49: =SUM(C49/24*D49+G49/24*F49) -> 0
A51: Use for more than 1 change in a day.
...
