Workbook

Sheet Sep 2012
A1: DATE | B1: STATION 48 | C1: ANDERSON-ROSE | D1: J CANAL | E1: TULE LAKE PRECIP | F1: TULE LAKE SNOW | G1: D PLANT | H1: TULE LAKE ELEV. | I1: CHANGES @ STATION 48
B2: (in CFS) | C2: (in CFS) | D2: (in CFS) | G2: (in AF)
A3: 41153 | B3: 77 | C3: 0 | D3: 307 | E3: 0 | F3: 0 | G3: 0 | H3: 4034.64 | I3: *1 PM 100/50
A4: 41154 | B4: 50 | C4: 0 | D4: 307 | E4: 0 | F4: 0 | G4: 0 | H4: 4034.64
A5: 41155 | B5: 34 | C5: 37 | D5: 297 | E5: 0 | F5: 0 | G5: 0 | H5: 4034.65 | I5: * 9 AM 50/25
A6: 41156 | B6: 56 | C6: 8 | D6: 319 | E6: 0 | F6: 0 | G6: 0 | H6: 4034.65 | I6: * 2 PM 25/100
A7: 41157 | B7: 100 | C7: 0 | D7: 326 | E7: 0 | F7: 0 | G7: 0 | H7: 4034.66
A8: 41158 | B8: 100 | C8: 0 | D8: 313 | E8: 0 | F8: 0 | G8: 0 | H8: 4034.67
A9: 41159 | B9: 67 | C9: 24 | D9: 289 | E9: 0 | F9: 0 | G9: 0 | H9: 4034.68 | I9: * 8 AM 100/50
A10: 41160 | B10: 28 | C10: 50 | D10: 256 | E10: 0 | F10: 0 | G10: 0 | H10: 4034.69 | I10: * 8 AM 50/25 4 PM 25/10
A11: 41161 | B11: 17 | C11: 42 | D11: 248 | E11: 0 | F11: 0 | G11: 0 | H11: 4034.69 | I11: * 8 AM 10/20
A12: 41162 | B12: 20 | C12: 62 | D12: 245 | E12: 0 | F12: 0 | G12: 0 | H12: 4034.7
A13: 41163 | B13: 20 | C13: 16 | D13: 287 | E13: 0 | F13: 0 | G13: 0 | H13: 4034.7
A14: 41164 | B14: 59 | C14: 0 | D14: 281 | E14: 0 | F14: 0 | G14: 0 | H14: 4034.7 | I14: * 7 AM 20/75
A15: 41165 | B15: 94 | C15: 0 | D15: 266 | E15: 0 | F15: 0 | G15: 0 | H15: 4034.7 | I15: * 3 PM 75/125
A16: 41166 | B16: 75 | C16: 0 | D16: 227 | E16: 0 | F16: 0 | G16: 0 | H16: 4034.71 | I16: * 8 AM 125/50
A17: 41167 | B17: 30 | C17: 60 | D17: 216 | E17: 0 | F17: 0 | G17: 0 | H17: 4034.72 | I17: * 8 am 50/20
A18: 41168 | B18: 20 | C18: 80 | D18: 213 | E18: 0 | F18: 0 | G18: 0 | H18: 4034.72
A19: 41169 | B19: 13 | C19: 61 | D19: 201 | E19: 0 | F19: 0 | G19: 0 | H19: 4034.73 | I19: 3 PM 20/0
A20: 41170 | B20: 0 | C20: 33 | D20: 197 | E20: 0 | F20: 0 | G20: 0 | H20: 4034.75
A21: 41171 | B21: 0 | C21: 6 | D21: 238 | E21: 0 | F21: 0 | G21: 0 | H21: 4034.77
A22: 41172 | B22: 0 | C22: 0 | D22: 236 | E22: 0 | F22: 0 | G22: 0 | H22: 4034.79
A23: 41173 | B23: 0 | C23: 0 | D23: 245 | E23: 0 | F23: 0 | G23: 0 | H23: 4034.8
A24: 41174 | B24: 0 | C24: 0 | D24: 238 | E24: 0 | F24: 0 | G24: 0 | H24: 4034.81
A25: 41175 | B25: 0 | C25: 0 | D25: 231 | E25: 0 | F25: 0 | G25: 0 | H25: 4034.82
A26: 41176 | B26: 0 | C26: 0 | D26: 223 | E26: 0 | F26: 0 | G26: 0 | H26: 4034.82
A27: 41177 | B27: 33 | C27: 0 | D27: 230 | E27: 0 | F27: 0 | G27: 0 | H27: 4034.82 | I27: * 8 AM 0/50
A28: 41178 | B28: 50 | C28: 0 | D28: 223 | E28: 0 | F28: 0 | G28: 0 | H28: 4034.84
A29: 41179 | B29: 50 | C29: 0 | D29: 247 | E29: 0 | F29: 0 | G29: 0 | H29: 4034.84
A30: 41180 | B30: 50 | C30: 0 | D30: 252 | E30: 0 | F30: 0 | G30: 0 | H30: 4034.86
A31: 41181 | B31: 50 | C31: 0 | D31: 216 | E31: 0 | F31: 0 | G31: 0 | H31: 4034.88
A32: 41182 | B32: 30 | C32: 0 | D32: 197 | E32: 0 | F32: 0 | G32: 0 | H32: 4034.88 | I32: * 8 AM 50/20
A33: Monthly Total | B33: =SUM(B1:B32) -> 1123 | C33: =SUM(C1:C32) -> 479 | D33: =SUM(D1:D32) -> 7571 | E33: =SUM(E1:E32) -> 0 | F33: =SUM(F1:F32) -> 0 | G33: =SUM(G1:G32) -> 0
A34: WY Total | B34: =SUM(B33+'Aug 2012'!B35) -> 29703 | C34: =SUM(C33+'Aug 2012'!C35) -> 6430 | D34: =SUM(D33+'Aug 2012'!D35) -> 66535 | E34: =SUM(E33+'Aug 2012'!E35) -> 6.97 | F34: =SUM(F33+'Aug 2012'!F35) -> 20 | G34: =SUM(G33+'Aug 2012'!G35) -> 14512
A36: Acre Feet | B36: =SUM(B3:B32)*1.9835 -> 2227.4705 | C36: =SUM(C3:C32)*1.9835 -> 950.0965 | D36: =SUM(D3:D32)*1.9835 -> 15017.078
A38: WY AF Total | B38: =SUM(B36+'Aug 2012'!B39) -> 58471.597 | C38: =SUM(C36+'Aug 2012'!C39) -> 11797.858 | D38: =SUM(D36+'Aug 2012'!D39) -> 129240.89
G40: * COMPUTATIONAL PURPOSES ONLY! Do Not Enter Data in the Red Columns
A42: *This is computation purposes only for Station 48
A43: Sta 48
F44: =SUM(24-D44) -> 24 | G44: =SUM(C44+E44) -> 0 | H44: =SUM(C44/24*D44+G44/24*F44) -> 0
...

Sheet Aug 2012
A1: DATE | B1: STATION 48 | C1: ANDERSON-ROSE | D1: J CANAL | E1: TULE LAKE PRECIP | F1: TULE LAKE SNOW | G1: D PLANT | H1: TULE LAKE ELEV. | I1: CHANGES @ STATION 48
B2: (in CFS) | C2: (in CFS) | D2: (in CFS) | G2: (in AF)
A3: 41122 | B3: 250 | C3: 0 | D3: 407 | E3: 0 | F3: 0 | G3: 0 | H3: 4034.64
A4: 41123 | B4: 292 | C4: 0 | D4: 387 | E4: 0 | F4: 0 | G4: 0 | H4: 4034.64 | I4: * 11 AM 250/350 6 PM 350/300
A5: 41124 | B5: 244 | C5: 0 | D5: 402 | E5: 0 | F5: 0 | G5: 0 | H5: 4034.63 | I5: * 7 AM 300/200 5 PM 200/250
A6: 41125 | B6: 250 | C6: 0 | D6: 428 | E6: 0 | F6: 0 | G6: 0 | H6: 4034.63
A7: 41126 | B7: 302 | C7: 0 | D7: 405 | E7: 0 | F7: 0 | G7: 0 | H7: 4034.63 | I7: * 8 AM 250/350 5 PM 350/300
A8: 41127 | B8: 265 | C8: 50 | D8: 430 | E8: T | F8: 0 | G8: 0 | H8: 4034.63 | I8: * 7 AM 300/250
A9: 41128 | B9: 217 | C9: 20 | D9: 432 | E9: 0 | F9: 0 | G9: 0 | H9: 4034.63 | I9: * 8 AM 250/200
A10: 41129 | B10: 200 | C10: 11 | D10: 406 | E10: 0 | F10: 0 | G10: 0 | H10: 4034.63
A11: 41130 | B11: 200 | C11: 0 | D11: 420 | E11: 0 | F11: 0 | G11: 0 | H11: 4034.62
A12: 41131 | B12: 213 | C12: 0 | D12: 409 | E12: 0 | F12: 0 | G12: 0 | H12: 4034.62 | I12: *7 AM 200/250 1 PM 250/200
A13: 41132 | B13: 181 | C13: 0 | D13: 372 | E13: 0 | F13: 0 | G13: 0 | H13: 4034.62 | I13: * 3 PM 200/150
A14: 41133 | B14: 150 | C14: 15 | D14: 339 | E14: 0 | F14: 0 | G14: 0 | H14: 4034.62
A15: 41134 | B15: 150 | C15: 32 | D15: 341 | E15: 0 | F15: 0 | G15: 0 | H15: 4034.62
A16: 41135 | B16: 150 | C16: 0 | D16: 367 | E16: 0 | F16: 0 | G16: 0 | H16: 4034.62
A17: 41136 | B17: 115 | C17: 41 | D17: 334 | E17: 0 | F17: 0 | G17: 0 | H17: 4034.63 | I17: * 1 PM 150/100 6 PM 100/50
A18: 41137 | B18: 73 | C18: 69 | D18: 326 | E18: 0 | F18: 0 | G18: 0 | H18: 4034.63 | I18: * 7 AM 50/100 6 PM 100/50
A19: 41138 | B19: 85 | C19: 16 | D19: 287 | E19: 0 | F19: 0 | G19: 0 | H19: 4034.63 | I19: * 7 AM 50/100
A20: 41139 | B20: 65 | C20: 40 | D20: 273 | E20: 0.02 | F20: 0 | G20: 0 | H20: 4034.63 | I20: * 7 AM 100/50
A21: 41140 | B21: 63 | C21: 45 | D21: 279 | E21: 0 | F21: 0 | G21: 0 | H21: 4034.63 | I21: * 6 PM 50/100
A22: 41141 | B22: 65 | C22: 50 | D22: 316 | E22: 0 | F22: 0 | G22: 0 | H22: 4034.63 | I22: * 7 AM 100/50
A23: 41142 | B23: 63 | C23: 12 | D23: 328 | E23: 0 | F23: 0 | G23: 0 | H23: 4034.63 | I23: * 6 PM 50/100
A24: 41143 | B24: 65 | C24: 39 | D24: 336 | E24: 0 | F24: 0 | G24: 0 | H24: 4034.63 | I24: * 7 AM 100/50
A25: 41144 | B25: 50 | C25: 0 | D25: 330 | E25: 0 | F25: 0 | G25: 0 | H25: 4034.63
A26: 41145 | B26: 71 | C26: 0 | D26: 312 | E26: 0 | F26: 0 | G26: 0 | H26: 4034.63 | I26: * 8 AM 50/100 6 PM 100/50
A27: 41146 | B27: 50 | C27: 19 | D27: 299 | E27: 0 | F27: 0 | G27: 0 | H27: 4034.63
A28: 41147 | B28: 50 | C28: 12 | D28: 317 | E28: 0 | F28: 0 | G28: 0 | H28: 4034.63
A29: 41148 | B29: 50 | C29: 0 | D29: 318 | E29: 0 | F29: 0 | G29: 0 | H29: 4034.63
A30: 41149 | B30: 65 | C30: 0 | D30: 311 | E30: 0 | F30: 0 | G30: 0 | H30: 4034.63 | I30: * 5 PM 50/100
A31: 41150 | B31: 100 | C31: 0 | D31: 320 | E31: 0 | F31: 0 | G31: 0 | H31: 4034.63
A32: 41151 | B32: 67 | C32: 0 | D32: 317 | E32: 0 | F32: 0 | G32: 0 | H32: 4034.64 | I32: * 8 AM 100/50
A33: 41152 | B33: 73 | C33: 0 | D33: 320 | E33: 0 | F33: 0 | G33: 0 | H33: 4034.64 | I33: * 1 PM 50/100
A34: Monthly Total | B34: =SUM(B3:B33) -> 4234 | C34: =SUM(C3:C33) -> 471 | D34: =SUM(D3:D33) -> 10868 | E34: =SUM(E3:E33) -> 0.02 | F34: =SUM(F3:F33) -> 0 | G34: =SUM(G3:G33) -> 0
A35: WY Total | B35: =SUM(B34+'Jul 2012'!B35) -> 28580 | C35: =SUM(C34+'Jul 2012'!C35) -> 5951 | D35: =SUM(D34+'Jul 2012'!D35) -> 58964 | E35: =SUM(E34+'Jul 2012'!E35) -> 6.97 | F35: =SUM(F34+'Jul 2012'!F35) -> 20 | G35: =SUM(G34+'Jul 2012'!G35) -> 14512
A37: Acre Feet | B37: =SUM(B4:B33)*1.9835 -> 7902.264 | C37: =SUM(C4:C33)*1.9835 -> 934.2285 | D37: =SUM(D4:D33)*1.9835 -> 20749.394
A39: WY AF Total | B39: =SUM(B37+'Jul 2012'!B39) -> 56244.126 | C39: =SUM(C37+'Jul 2012'!C39) -> 10847.762 | D39: =SUM(D37+'Jul 2012'!D39) -> 114223.81
G41: * COMPUTATIONAL PURPOSES ONLY! Do Not Enter Data in the Red Columns
A43: *This is computation purposes only for Station 48
A44: Sta 48
...

Sheet Jul 2012
A1: DATE | B1: STATION 48 | C1: ANDERSON-ROSE | D1: J CANAL | E1: TULE LAKE PRECIP | F1: TULE LAKE SNOW | G1: D PLANT | H1: TULE LAKE ELEV. | I1: CHANGES @ STATION 48
B2: (in CFS) | C2: (in CFS) | D2: (in CFS) | G2: (in AF)
A3: 41091 | B3: 250 | C3: 15 | D3: 447 | E3: 0.14 | F3: 0 | G3: 0 | H3: 4034.7
A4: 41092 | B4: 250 | C4: 19 | D4: 465 | E4: 0 | F4: 0 | G4: 0 | H4: 4034.72
A5: 41093 | B5: 292 | C5: 0 | D5: 477 | E5: 0 | F5: 0 | G5: 0 | H5: 4034.72 | I5: * 1 PM 250/300 3 PM 300/350
A6: 41094 | B6: 319 | C6: 0 | D6: 498 | E6: 0 | F6: 0 | G6: 0 | H6: 4034.72 | I6: * 9 AM 350/300
A7: 41095 | B7: 300 | C7: 0 | D7: 504 | E7: 0 | F7: 0 | G7: 0 | H7: 4034.72
A8: 41096 | B8: 331 | C8: 0 | D8: 499 | E8: 0 | F8: 0 | G8: 0 | H8: 4034.73 | I8: * 9 AM 300/350
A9: 41097 | B9: 317 | C9: 0 | D9: 478 | E9: 0 | F9: 0 | G9: 0 | H9: 4034.73 | I9: * 8 AM 350/300
A10: 41098 | B10: 313 | C10: 0 | D10: 451 | E10: 0 | F10: 0 | G10: 0 | H10: 4034.73 | I10: * 6 PM 300/350
A11: 41099 | B11: 327 | C11: 0 | D11: 486 | E11: 0 | F11: 0 | G11: 0 | H11: 4034.73 | I11: * 7 AM 350/300 6 PM 300/350
A12: 41100 | B12: 385 | C12: 0 | D12: 515 | E12: 0 | F12: 0 | G12: 0 | H12: 4034.73 | I12: * 7 AM 350/400
A13: 41101 | B13: 372 | C13: 0 | D13: 502 | E13: 0 | F13: 0 | G13: 0 | H13: 4034.72 | I13: * 4 PM 400/350 6:30 PM 350/300
A14: 41102 | B14: 281 | C14: 0 | D14: 432 | E14: 0 | F14: 0 | G14: 0 | H14: 4034.72 | I14: * 3 PM 300/250
A15: 41103 | B15: 250 | C15: 0 | D15: 407 | E15: 0 | F15: 0 | G15: 0 | H15: 4034.71
A16: 41104 | B16: 231 | C16: 0 | D16: 398 | E16: 0 | F16: 0 | G16: 0 | H16: 4034.71 | I16: * 3 PM 250/200
A17: 41105 | B17: 200 | C17: 0 | D17: 373 | E17: 0 | F17: 0 | G17: 0 | H17: 4034.7
A18: 41106 | B18: 200 | C18: 0 | D18: 375 | E18: 0 | F18: 0 | G18: 0 | H18: 4034.69
A19: 41107 | B19: 200 | C19: 0 | D19: 371 | E19: 0 | F19: 0 | G19: 0 | H19: 4034.69
A20: 41108 | B20: 183 | C20: 13 | D20: 356 | E20: 0 | F20: 0 | G20: 0 | H20: 4034.69 | I20: * 4PM 200/150
A21: 41109 | B21: 150 | C21: 28 | D21: 350 | E21: 0.02 | F21: 0 | G21: 0 | H21: 4034.69
A22: 41110 | B22: 150 | C22: 8 | D22: 346 | E22: 0 | F22: 0 | G22: 0 | H22: 4034.69
A23: 41111 | B23: 150 | C23: 0 | D23: 341 | E23: 0 | F23: 0 | G23: 0 | H23: 4034.69
A24: 41112 | B24: 150 | C24: 6 | D24: 310 | E24: 0 | F24: 0 | G24: 0 | H24: 4034.69
A25: 41113 | B25: 171 | C25: 13 | D25: 373 | E25: 0 | F25: 0 | G25: 0 | H25: 4034.68 | I25: * 2 PM 150/200
A26: 41114 | B26: 188 | C26: 0 | D26: 393 | E26: 0 | F26: 0 | G26: 0 | H26: 4034.68 | I26: * 8 AM 200/150 2PM 150/200
A27: 41115 | B27: 229 | C27: 0 | D27: 420 | E27: 0 | F27: 0 | G27: 0 | H27: 4034.68 | I27: * 4 PM 200/250 6 PM 250/300
A28: 41116 | B28: 277 | C28: 0 | D28: 428 | E28: 0 | F28: 0 | G28: 0 | H28: 4034.67 | I28: * 1 PM 300/250
A29: 41117 | B29: 171 | C29: 43 | D29: 401 | E29: 0 | F29: 0 | G29: 0 | H29: 4034.67 | I29: * 8 AM 250/200 10AM 200/150
A30: 41118 | B30: 117 | C30: 46 | D30: 382 | E30: 0 | F30: 0 | G30: 0 | H30: 4034.66 | I30: * 8 AM 150/100
A31: 41119 | B31: 100 | C31: 0 | D31: 404 | E31: 0 | F31: 0 | G31: 0 | H31: 4034.66
A32: 41120 | B32: 177 | C32: 0 | D32: 447 | E32: 0 | F32: 0 | G32: 0 | H32: 4034.66 | I32: *7 AM 100/150 1 PM 150/200 3 PM 200/250
A33: 41121 | B33: 288 | C33: 0 | D33: 453 | E33: 0 | F33: 0 | G33: 0 | H33: 4034.65 | I33: * 8 AM 250/350 5 PM 350/250
A34: Monthly Total | B34: =SUM(B3:B33) -> 7319 | C34: =SUM(C3:C33) -> 191 | D34: =SUM(D3:D33) -> 13082 | E34: =SUM(E3:E33) -> 0.16 | F34: =SUM(F3:F33) -> 0 | G34: =SUM(G3:G33) -> 0
A35: WY Total | B35: =SUM(B34+'Jun 2012'!B34) -> 24346 | C35: =SUM(C34+'Jun 2012'!C34) -> 5480 | D35: =SUM(D34+'Jun 2012'!D34) -> 48096 | E35: =SUM(E34+'Jun 2012'!E34) -> 6.95 | F35: =SUM(F34+'Jun 2012'!F34) -> 20 | G35: =SUM(G34+'Jun 2012'!G34) -> 14512
A37: Acre Feet | B37: =SUM(B3:B33)*1.9835 -> 14517.237 | C37: =SUM(C3:C33)*1.9835 -> 378.8485 | D37: =SUM(D3:D33)*1.9835 -> 25948.147
A39: WY AF Total | B39: =SUM(B37+'Jun 2012'!B38) -> 48341.862 | C39: =SUM(C37+'Jun 2012'!C38) -> 9913.533 | D39: =SUM(D37+'Jun 2012'!D38) -> 93474.421
G41: * COMPUTATIONAL PURPOSES ONLY! Do Not Enter Data in the Red Columns
A43: *This is computation purposes only for Station 48
A44: Sta 48
...

Sheet Jun 2012
A1: DATE | B1: STATION 48 | C1: ANDERSON-ROSE | D1: J CANAL | E1: TULE LAKE PRECIP | F1: TULE LAKE SNOW | G1: D PLANT | H1: TULE LAKE ELEV. | I1: CHANGES @ STATION 48
B2: (in CFS) | C2: (in CFS) | D2: (in CFS) | G2: (in AF)
A3: 41061 | B3: 300 | C3: 26 | D3: 534 | E3: 0 | F3: 0 | G3: 0 | H3: 4034.8
A4: 41062 | B4: 279 | C4: 0 | D4: 513 | E4: 0 | F4: 0 | G4: 0 | H4: 4034.8 | I4: * 2 PM 300/250
A5: 41063 | B5: 250 | C5: 0 | D5: 462 | E5: 0 | F5: 0 | G5: 0 | H5: 4034.78
A6: 41064 | B6: 196 | C6: 80 | D6: 453 | E6: 0.19 | F6: 0 | G6: 0 | H6: 4034.78 | I6: * 7 AM 250/200 3 PM 200/150
A7: 41065 | B7: 131 | C7: 75 | D7: 386 | E7: 0.08 | F7: 0 | G7: 0 | H7: 4034.78 | I7: * 3 PM 150/100
A8: 41066 | B8: 148 | C8: 0 | D8: 331 | E8: 0.01 | F8: 0 | G8: 0 | H8: 4034.78 | I8: * 8 AM 100/200 3 PM 200/150
A9: 41067 | B9: 127 | C9: 100 | D9: 328 | E9: 0.02 | F9: 0 | G9: 0 | H9: 4034.79 | I9: * 1 PM 150/100
A10: 41068 | B10: 100 | C10: 30 | D10: 339 | E10: 0 | F10: 0 | G10: 0 | H10: 4034.8
A11: 41069 | B11: 117 | C11: 0 | D11: 342 | E11: 0 | F11: 0 | G11: 0 | H11: 4034.8 | I11: * 8 AM 100/150 4 PM 150/100
A12: 41070 | B12: 133 | C12: 0 | D12: 320 | E12: 0 | F12: 0 | G12: 0 | H12: 4034.8 | I12: * 8 AM 100/150
A13: 41071 | B13: 150 | C13: 0 | D13: 382 | E13: 0 | F13: 0 | G13: 0 | H13: 4034.8
A14: 41072 | B14: 217 | C14: 0 | D14: 402 | E14: 0 | F14: 0 | G14: 0 | H14: 4034.8 | I14: * 7 AM 150/200 3 PM 200/250 6 PM 250/300
A15: 41073 | B15: 265 | C15: 0 | D15: 416 | E15: 0 | F15: 0 | G15: 0 | H15: 4034.8 | I15: * 7 AM 300/250
A16: 41074 | B16: 250 | C16: 0 | D16: 423 | E16: 0 | F16: 0 | G16: 0 | H16: 4034.8
A17: 41075 | B17: 288 | C17: 0 | D17: 476 | E17: 0 | F17: 0 | G17: 0 | H17: 4034.8 | I17: * 3 PM 250/350
A18: 41076 | B18: 298 | C18: 34 | D18: 505 | E18: 0 | F18: 0 | G18: 0 | H18: 4034.8 | I18: *8 AM 350/300 3 PM 300/250
A19: 41077 | B19: 250 | C19: 44 | D19: 449 | E19: 0 | F19: 0 | G19: 0 | H19: 4034.8
A20: 41078 | B20: 250 | C20: 33 | D20: 484 | E20: 0 | F20: 0 | G20: 0 | H20: 4034.76
A21: 41079 | B21: 319 | C21: 0 | D21: 525 | E21: 0 | F21: 0 | G21: 0 | H21: 4034.76 | I21: * 4 AM 250/300 3 PM 300/350
A22: 41080 | B22: 350 | C22: 0 | D22: 545 | E22: 0 | F22: 0 | G22: 0 | H22: 4034.76
A23: 41081 | B23: 315 | C23: 65 | D23: 580 | E23: 0 | F23: 0 | G23: 0 | H23: 4034.76 | I23: * 7 AM 350/300
A24: 41082 | B24: 300 | C24: 0 | D24: 540 | E24: 0 | F24: 0 | G24: 0 | H24: 4034.76
A25: 41083 | B25: 269 | C25: 14 | D25: 539 | E25: 0.08 | F25: 0 | G25: 0 | H25: 4034.75 | I25: * 9 AM 300/250
A26: 41084 | B26: 271 | C26: 0 | D26: 508 | E26: 0 | F26: 0 | G26: 0 | H26: 4034.74 | I26: * 2 PM 250/300
A27: 41085 | B27: 306 | C27: 0 | D27: 516 | E27: 0 | F27: 0 | G27: 0 | H27: 4034.73 | I27: * 3 PM 300/350 6 PM 350/300
A28: 41086 | B28: 331 | C28: 0 | D28: 534 | E28: 0.15 | F28: 0 | G28: 0 | H28: 4034.72 | I28: * 9 AM 300/350
A29: 41087 | B29: 321 | C29: 0 | D29: 523 | E29: 0 | F29: 0 | G29: 0 | H29: 4034.71 | I29: * 10 AM 350/300
A30: 41088 | B30: 300 | C30: 0 | D30: 496 | E30: 0 | F30: 0 | G30: 0 | H30: 4034.7
A31: 41089 | B31: 300 | C31: 0 | D31: 491 | E31: 0 | F31: 0 | G31: 0 | H31: 4034.7
A32: 41090 | B32: 281 | C32: 0 | D32: 469 | E32: 0 | F32: 0 | G32: 0 | H32: 4034.7 | I32: *3 PM 300/250
A33: Monthly Total | B33: =SUM(B3:B32) -> 7412 | C33: =SUM(C1:C32) -> 501 | D33: =SUM(D1:D32) -> 13811 | E33: =SUM(E1:E32) -> 0.53 | F33: =SUM(F1:F32) -> 0 | G33: =SUM(G1:G32) -> 0
A34: WY Total | B34: =SUM(B33+'May 2012'!B35) -> 17027 | C34: =SUM(C33+'May 2012'!C35) -> 5289 | D34: =SUM(D33+'May 2012'!D35) -> 35014 | E34: =SUM(E33+'May 2012'!E35) -> 6.79 | F34: =SUM(F33+'May 2012'!F35) -> 20 | G34: =SUM(G33+'May 2012'!G35) -> 14512
A36: Acre Feet | B36: =SUM(B3:B32)*1.9835 -> 14701.702 | C36: =SUM(C3:C32)*1.9835 -> 993.7335 | D36: =SUM(D3:D32)*1.9835 -> 27394.119
A38: WY AF Total | B38: =SUM(B36+'May 2012'!B39) -> 33824.626 | C38: =SUM(C36+'May 2012'!C39) -> 9534.6845 | D38: =SUM(D36+'May 2012'!D39) -> 67526.274
G40: * COMPUTATIONAL PURPOSES ONLY! Do Not Enter Data in the Red Columns
A42: *This is computation purposes only for Station 48
A43: Sta 48
F44: =SUM(24-D44) -> 24 | G44: =SUM(C44+E44) -> 0 | H44: =SUM(C44/24*D44+G44/24*F44) -> 0
...

Sheet May 2012
A1: DATE | B1: STATION 48 | C1: ANDERSON-ROSE | D1: J CANAL | E1: TULE LAKE PRECIP | F1: TULE LAKE SNOW | G1: D PLANT | H1: TULE LAKE ELEV. | I1: CHANGES @ STATION 48
B2: (in CFS) | C2: (in CFS) | D2: (in CFS) | G2: (in AF)
A3: 41030 | B3: 15 | C3: 0 | D3: 133 | E3: 0 | F3: 0 | G3: 0 | H3: 4034.91
A4: 41031 | B4: 59 | C4: 0 | D4: 157 | E4: 0 | F4: 0 | G4: 0 | H4: 4034.9 | I4: * 8 AM 15/50 2 PM 50/100
A5: 41032 | B5: 100 | C5: 0 | D5: 211 | E5: 0.01 | F5: 0 | G5: 0 | H5: 4034.9
A6: 41033 | B6: 100 | C6: 30 | D6: 215 | E6: 0.03 | F6: 0 | G6: 100 | H6: 4034.89 | I6: * 9 AM One D-Plant unit started
A7: 41034 | B7: 100 | C7: 51 | D7: 229 | E7: 0.01 | F7: 0 | G7: 160 | H7: 4034.88
A8: 41035 | B8: 100 | C8: 66 | D8: 255 | E8: 0 | F8: 0 | G8: 160 | H8: 4034.88
A9: 41036 | B9: 160 | C9: 20 | D9: 292 | E9: 0 | F9: 0 | G9: 249 | H9: 4034.87 | I9: * 10:39 AM Started 2nd unit D * (48) 1 PM 100/150 2 PM 150/200 4 PM 200/250
A10: 41037 | B10: 217 | C10: 150 | D10: 340 | E10: 0 | F10: 0 | G10: 319 | H10: 4034.85 | I10: * 8 AM 250/200
A11: 41038 | B11: 242 | C11: 75 | D11: 390 | E11: 0 | F11: 0 | G11: 319 | H11: 4034.83 | I11: * 2 PM 200/300
A12: 41039 | B12: 342 | C12: 70 | D12: 427 | E12: 0 | F12: 0 | G12: 319 | H12: 4034.81 | I12: * 2 PM 300/400
A13: 41040 | B13: 366 | C13: 100 | D13: 470 | E13: 0 | F13: 0 | G13: 319 | H13: 4034.8 | I13: * 8 AM 400/350
A14: 41041 | B14: 350 | C14: 130 | D14: 478 | E14: 0 | F14: 0 | G14: 319 | H14: 4034.79
A15: 41042 | B15: 350 | C15: 110 | D15: 468 | E15: 0 | F15: 0 | G15: 319 | H15: 4034.78
A16: 41043 | B16: 323 | C16: 77 | D16: 489 | E16: 0 | F16: 0 | G16: 319 | H16: 4034.78 | I16: * 11 AM 350/300
A17: 41044 | B17: 300 | C17: 23 | D17: 514 | E17: 0 | F17: 0 | G17: 112 | H17: 4034.76 | I17: * 8:25 Am D-Plant Shut Off
A18: 41045 | B18: 300 | C18: 0 | D18: 543 | E18: 0 | F18: 0 | G18: 0 | H18: 4034.74
A19: 41046 | B19: 325 | C19: 0 | D19: 548 | E19: 0.04 | F19: 0 | G19: 0 | H19: 4034.73 | I19: * noon 300/350
A20: 41047 | B20: 317 | C20: 12 | D20: 552 | E20: 0 | F20: 0 | G20: 0 | H20: 4034.72 | I20: * 8:00 am 350/300
A21: 41048 | B21: 260 | C21: 38 | D21: 539 | E21: 0 | F21: 0 | G21: 0 | H21: 4034.72 | I21: * 2 PM 300/250 3PM 250/200
A22: 41049 | B22: 214 | C22: 0 | D22: 471 | E22: 0 | F22: 0 | G22: 0 | H22: 4034.72 | I22: * 7:30 AM 200/250 2PM 250/200
A23: 41050 | B23: 235 | C23: 0 | D23: 444 | E23: 0 | F23: 0 | G23: 0 | H23: 4034.72 | I23: * 7 AM 200/250
A24: 41051 | B24: 250 | C24: 0 | D24: 481 | E24: 0 | F24: 0 | G24: 0 | H24: 4034.72
A25: 41052 | B25: 227 | C25: 0 | D25: 436 | E25: 0 | F25: 0 | G25: 0 | H25: 4034.73 | I25: * 1 PM 250/200
A26: 41053 | B26: 200 | C26: 0 | D26: 425 | E26: T | F26: 0 | G26: 0 | H26: 4034.74
A27: 41054 | B27: 156 | C27: 40 | D27: 396 | E27: 0.25 | F27: 1 | G27: 0 | H27: 4034.75 | I27: * 11 AM 200/150 4PM 150/100
A28: 41055 | B28: 100 | C28: 65 | D28: 346 | E28: 0.07 | F28: 0 | G28: 0 | H28: 4034.77
A29: 41056 | B29: 100 | C29: 35 | D29: 320 | E29: 0.01 | F29: 0 | G29: 0 | H29: 4034.79
A30: 41057 | B30: 123 | C30: 25 | D30: 344 | E30: 0 | F30: 0 | G30: 0 | H30: 4034.8 | I30: * 1 PM 100/150
A31: 41058 | B31: 225 | C31: 0 | D31: 392 | E31: 0 | F31: 0 | G31: 0 | H31: 4034.82 | I31: * 8 AM 150/200 * 2PM 200/300
A32: 41059 | B32: 271 | C32: 53 | D32: 466 | E32: 0 | F32: 0 | G32: 0 | H32: 4034.83 | I32: * 10 AM 300/250
A33: 41060 | B33: 294 | C33: 15 | D33: 496 | E33: 0 | F33: 0 | G33: 0 | H33: 4034.82 | I33: * 9 AM 250/350 3 PM 350/300
A34: Monthly Total | B34: =SUM(B3:B33) -> 6721 | C34: =SUM(C3:C33) -> 1185 | D34: =SUM(D3:D33) -> 12267 | E34: =SUM(E3:E33) -> 0.42 | F34: =SUM(F3:F33) -> 1 | G34: =SUM(G3:G33) -> 3014
A35: WY Total | B35: =SUM(B34+'Apr 2012'!B34) -> 9615 | C35: =SUM(C34+'Apr 2012'!C34) -> 4788 | D35: =SUM(D34+'Apr 2012'!D34) -> 21203 | E35: =SUM(E34+'Apr 2012'!E34) -> 6.26 | F35: =SUM(F34+'Apr 2012'!F34) -> 20 | G35: =SUM(G34+'Apr 2012'!G34) -> 14512
A37: Acre Feet | B37: =SUM(B3:B33)*1.9835 -> 13331.104 | C37: =SUM(C3:C33)*1.9835 -> 2350.4475 | D37: =SUM(D3:D33)*1.9835 -> 24331.594
A39: WY AF Total | B39: =SUM(B37+'Apr 2012'!B38) -> 19122.924 | C39: =SUM(C37+'Apr 2012'!C38) -> 8540.951 | D39: =SUM(D37+'Apr 2012'!D38) -> 40132.156
G41: * COMPUTATIONAL PURPOSES ONLY! Do Not Enter Data in the Red Columns
A43: *This is computation purposes only for Station 48
A44: Sta 48
...

Sheet Apr 2012
A1: DATE | B1: STATION 48 | C1: ANDERSON-ROSE | D1: J CANAL | E1: TULE LAKE PRECIP | F1: TULE LAKE SNOW | G1: D PLANT | H1: TULE LAKE ELEV. | I1: CHANGES @ STATION 48
B2: (in CFS) | C2: (in CFS) | D2: (in CFS) | G2: (in AF)
A3: 41000 | B3: 50 | C3: 0 | D3: 68 | E3: 0.02 | F3: 0 | G3: 0 | H3: 4034.92
A4: 41001 | B4: 50 | C4: 0 | D4: 75 | E4: 0.01 | F4: 0 | G4: 0 | H4: 4034.9
A5: 41002 | B5: 50 | C5: 0 | D5: 78 | E5: 0 | F5: 0 | G5: 0 | H5: 4034.88
A6: 41003 | B6: 50 | C6: 0 | D6: 75 | E6: 0.04 | F6: T | G6: 0 | H6: 4034.87
A7: 41004 | B7: 50 | C7: 0 | D7: 74 | E7: 0.03 | F7: T | G7: 0 | H7: 4034.86
A8: 41005 | B8: 50 | C8: 0 | D8: 75 | E8: 0.02 | F8: T | G8: 0 | H8: 4034.86
A9: 41006 | B9: 50 | C9: 0 | D9: 76 | E9: 0 | F9: 0 | G9: 0 | H9: 4034.86
A10: 41007 | B10: 50 | C10: 0 | D10: 79 | E10: 0 | F10: 0 | G10: 0 | H10: 4034.86
A11: 41008 | B11: 33 | C11: 0 | D11: 80 | E11: 0 | F11: 0 | G11: 0 | H11: 4034.87 | I11: 8 AM 50/25
A12: 41009 | B12: 25 | C12: 0 | D12: 79 | E12: 0 | F12: 0 | G12: 0 | H12: 4034.87
A13: 41010 | B13: 25 | C13: 0 | D13: 83 | E13: 0.15 | F13: 0 | G13: 0 | H13: 4034.87
A14: 41011 | B14: 9 | C14: 0 | D14: 82 | E14: 0.05 | F14: 0.5 | G14: 0 | H14: 4034.88 | I14: 8 AM 25/15 9:30 AM 15/0
A15: 41012 | B15: 0 | C15: 2 | D15: 80 | E15: 0.05 | F15: 0.5 | G15: 0 | H15: 4034.89
A16: 41013 | B16: 0 | C16: 23 | D16: 80 | E16: 0.01 | F16: 0 | G16: 0 | H16: 4034.9
A17: 41014 | B17: 0 | C17: 42 | D17: 81 | E17: 0 | F17: 0 | G17: 0 | H17: 4034.91
A18: 41015 | B18: 0 | C18: 35 | D18: 82 | E18: 0.01 | F18: 0 | G18: 0 | H18: 4034.9
A19: 41016 | B19: 0 | C19: 3 | D19: 82 | E19: 0.03 | F19: 0 | G19: 0 | H19: 4034.9
A20: 41017 | B20: 0 | C20: 0 | D20: 75 | E20: 0.04 | F20: 0 | G20: 0 | H20: 4034.9
A21: 41018 | B21: 0 | C21: 21 | D21: 72 | E21: 0.15 | F21: 0 | G21: 0 | H21: 4034.9
A22: 41019 | B22: 0 | C22: 38 | D22: 73 | E22: 0.01 | F22: 0 | G22: 0 | H22: 4034.9
A23: 41020 | B23: 0 | C23: 42 | D23: 73 | E23: 0 | F23: 0 | G23: 0 | H23: 4034.9
A24: 41021 | B24: 0 | C24: 42 | D24: 73 | E24: 0 | F24: 0 | G24: 0 | H24: 4034.9
A25: 41022 | B25: 0 | C25: 39 | D25: 74 | E25: 0 | F25: 0 | G25: 0 | H25: 4034.9
A26: 41023 | B26: 0 | C26: 30 | D26: 88 | E26: 0 | F26: 0 | G26: 0 | H26: 4034.9
A27: 41024 | B27: 12 | C27: 0 | D27: 115 | E27: 0 | F27: 0 | G27: 0 | H27: 4034.9 | I27: * 1 PM 0/25
A28: 41025 | B28: 19 | C28: 0 | D28: 130 | E28: 0.36 | F28: 0 | G28: 0 | H28: 4034.91 | I28: * 10 AM 25/15
A29: 41026 | B29: 15 | C29: 0 | D29: 127 | E29: 0 | F29: 0 | G29: 0 | H29: 4034.91
A30: 41027 | B30: 15 | C30: 0 | D30: 124 | E30: 0 | F30: 0 | G30: 0 | H30: 4034.92
A31: 41028 | B31: 15 | C31: 0 | D31: 127 | E31: 0 | F31: 0 | G31: 0 | H31: 4034.92
A32: 41029 | B32: 15 | C32: 0 | D32: 125 | E32: 0 | F32: 0 | G32: 0 | H32: 4034.91
A33: Monthly Total | B33: =SUM(B3:B32) -> 583 | C33: =SUM(C3:C32) -> 317 | D33: =SUM(D3:D32) -> 2605 | E33: =SUM(E3:E32) -> 0.98 | F33: =SUM(F3:F32) -> 1 | G33: =SUM(G3:G32) -> 0
A34: WY Total | B34: =SUM(B33+'Mar 2012'!B35) -> 2894 | C34: =SUM(C33+'Mar 2012'!C35) -> 3603 | D34: =SUM(D33+'Mar 2012'!D35) -> 8936 | E34: =SUM(E33+'Mar 2012'!E35) -> 5.84 | F34: =SUM(F33+'Mar 2012'!F35) -> 19 | G34: =SUM(G33+'Mar 2012'!G35) -> 11498
A36: Acre Feet | B36: =SUM(B3:B33)*1.9835 -> 2312.761 | C36: =SUM(C3:C33)*1.9835 -> 1257.539 | D36: =SUM(D3:D33)*1.9835 -> 10334.035
A38: WY AF Total | B38: =SUM(B36+'Mar 2012'!B39) -> 5791.82 | C38: =SUM(C36+'Mar 2012'!C39) -> 6190.5035 | D38: =SUM(D36+'Mar 2012'!D39) -> 15800.561
G40: * COMPUTATIONAL PURPOSES ONLY! Do Not Enter Data in the Red Columns
A42: *This is computation purposes only for Station 48
A43: Sta 48
F44: =SUM(24-D44) -> 24 | G44: =SUM(C44+E44) -> 0 | H44: =SUM(C44/24*D44+G44/24*F44) -> 0
...

Sheet Mar 2012
A1: DATE | B1: STATION 48 | C1: ANDERSON-ROSE | D1: J CANAL | E1: TULE LAKE PRECIP | F1: TULE LAKE SNOW | G1: D PLANT | H1: TULE LAKE ELEV. | I1: CHANGES @ STATION 48
B2: (in CFS) | C2: (in CFS) | D2: (in CFS) | G2: (in AF)
A3: 40969 | B3: 0 | C3: 20 | D3: 0 | E3: 0.04 | F3: 0.5 | G3: 0 | H3: 4034.4
A4: 40970 | B4: 0 | C4: 13 | D4: 0 | E4: 0 | F4: 0 | G4: 0 | H4: 4034.4
A5: 40971 | B5: 0 | C5: 0 | D5: 0 | E5: 0 | F5: 0 | G5: 0 | H5: 4034.4
A6: 40972 | B6: 0 | C6: 5 | D6: 0 | E6: 0 | F6: 0 | G6: 0 | H6: 4034.4
A7: 40973 | B7: 0 | C7: 28 | D7: 16 | E7: 0 | F7: 0 | G7: 0 | H7: 4034.41
A8: 40974 | B8: 0 | C8: 0 | D8: 30 | E8: 0.01 | F8: T | G8: 0 | H8: 4034.41
A9: 40975 | B9: 8 | C9: 0 | D9: 36 | E9: 0 | F9: 0 | G9: 0 | H9: 4034.42 | I9: * 4 PM 0/25
A10: 40976 | B10: 25 | C10: 0 | D10: 40 | E10: 0 | F10: 0 | G10: 0 | H10: 4034.42
A11: 40977 | B11: 25 | C11: 0 | D11: 40 | E11: 0 | F11: 0 | G11: 0 | H11: 4034.43
A12: 40978 | B12: 25 | C12: 0 | D12: 40 | E12: 0 | F12: 0 | G12: 0 | H12: 4034.43
A13: 40979 | B13: 25 | C13: 0 | D13: 40 | E13: 0.17 | F13: 1 | G13: 0 | H13: 4034.44
A14: 40980 | B14: 25 | C14: 0 | D14: 40 | E14: 0.03 | F14: 0 | G14: 0 | H14: 4034.47
A15: 40981 | B15: 20 | C15: 0 | D15: 40 | E15: 0.11 | F15: 1 | G15: 0 | H15: 4034.49 | I15: * 1 PM 25/15
A16: 40982 | B16: 5 | C16: 0 | D16: 40 | E16: 0.4 | F16: 4.5 | G16: 0 | H16: 4034.51 | I16: * 8 AM 15/0
A17: 40983 | B17: 0 | C17: 0 | D17: 35 | E17: 0.03 | F17: 0 | G17: 0 | H17: 4034.55
A18: 40984 | B18: 0 | C18: 0 | D18: 30 | E18: 0.5 | F18: T | G18: 0 | H18: 4034.57
A19: 40985 | B19: 0 | C19: 0 | D19: 30 | E19: 0.45 | F19: T | G19: 0 | H19: 4034.61
A20: 40986 | B20: 67 | C20: 15 | D20: 43 | E20: 0.02 | F20: T | G20: 0 | H20: 4034.65 | I20: * 8 AM 0/100
A21: 40987 | B21: 100 | C21: 47 | D21: 50 | E21: 0.01 | F21: 0 | G21: 0 | H21: 4034.68
A22: 40988 | B22: 100 | C22: 60 | D22: 50 | E22: 0.13 | F22: 2 | G22: 0 | H22: 4034.71
A23: 40989 | B23: 100 | C23: 60 | D23: 50 | E23: 0.01 | F23: 0 | G23: 0 | H23: 4034.74
A24: 40990 | B24: 43 | C24: 35 | D24: 50 | E24: 0.03 | F24: 0.5 | G24: 0 | H24: 4034.77 | I24: * 8 AM 100/15
A25: 40991 | B25: 15 | C25: 0 | D25: 46 | E25: 0.02 | F25: T | G25: 0 | H25: 4034.79
A26: 40992 | B26: 15 | C26: 0 | D26: 43 | E26: 0 | F26: 0 | G26: 0 | H26: 4034.81
A27: 40993 | B27: 15 | C27: 0 | D27: 42 | E27: 0 | F27: 0 | G27: 0 | H27: 4034.83
A28: 40994 | B28: 15 | C28: 0 | D28: 42 | E28: 0.01 | F28: 0 | G28: 0 | H28: 4034.85
A29: 40995 | B29: 15 | C29: 0 | D29: 40 | E29: T | F29: 0 | G29: 0 | H29: 4034.87
A30: 40996 | B30: 15 | C30: 0 | D30: 40 | E30: 0.27 | F30: 0.5 | G30: 0 | H30: 4034.88
A31: 40997 | B31: 30 | C31: 0 | D31: 49 | E31: T | F31: 0 | G31: 0 | H31: 4034.89 | I31: * 2 PM 15/50
A32: 40998 | B32: 50 | C32: 0 | D32: 65 | E32: T | F32: 0 | G32: 0 | H32: 4034.9
A33: 40999 | B33: 50 | C33: 0 | D33: 64 | E33: 0.16 | F33: 1 | G33: 0 | H33: 4034.91
A34: Monthly Total | B34: =SUM(B3:B33) -> 788 | C34: =SUM(C3:C33) -> 283 | D34: =SUM(D3:D33) -> 1131 | E34: =SUM(E3:E33) -> 2.4 | F34: =SUM(F3:F33) -> 11 | G34: =SUM(G3:G33) -> 0
A35: WY Total | B35: =SUM(B34+'Feb 2012'!B33) -> 2311 | C35: =SUM(C34+'Feb 2012'!C33) -> 3286 | D35: =SUM(D34+'Feb 2012'!D33) -> 6331 | E35: =SUM(E34+'Feb 2012'!E33) -> 4.86 | F35: =SUM(F34+'Feb 2012'!F33) -> 18 | G35: =SUM(G34+'Feb 2012'!G33) -> 11498
A37: Acre Feet | B37: =SUM(B3:B33)*1.9835 -> 1562.998 | C37: =SUM(C3:C33)*1.9835 -> 561.3305 | D37: =SUM(D3:D33)*1.9835 -> 2243.3385
A39: WY AF Total | B39: =SUM(B37+'Feb 2012'!B37) -> 3479.059 | C39: =SUM(C37+'Feb 2012'!C37) -> 4932.9645 | D39: =SUM(D37+'Feb 2012'!D37) -> 5466.526
G41: * COMPUTATIONAL PURPOSES ONLY! Do Not Enter Data in the Red Columns
A43: *This is computation purposes only for Station 48
A44: Sta 48
...

Sheet Feb 2012
A1: DATE | B1: STATION 48 | C1: ANDERSON-ROSE | D1: J CANAL | E1: TULE LAKE PRECIP | F1: TULE LAKE SNOW | G1: D PLANT | H1: TULE LAKE ELEV. | I1: CHANGES @ STATION 48
B2: (in CFS) | C2: (in CFS) | D2: (in CFS) | G2: (in AF)
A3: 40940 | B3: 0 | C3: 20 | D3: 0 | E3: 0.04 | F3: 0 | G3: 0 | H3: 4034.55
A4: 40941 | B4: 0 | C4: 20 | D4: 0 | E4: 0.01 | F4: 0 | G4: 0 | H4: 4034.54
A5: 40942 | B5: 0 | C5: 20 | D5: 0 | E5: 0 | F5: 0 | G5: 0 | H5: 4034.53
A6: 40943 | B6: 0 | C6: 20 | D6: 0 | E6: 0 | F6: 0 | G6: 0 | H6: 4034.51
A7: 40944 | B7: 0 | C7: 20 | D7: 0 | E7: 0 | F7: 0 | G7: 0 | H7: 4034.49
A8: 40945 | B8: 0 | C8: 20 | D8: 0 | E8: 0 | F8: 0 | G8: 0 | H8: 4034.48
A9: 40946 | B9: 0 | C9: 20 | D9: 0 | E9: 0 | F9: 0 | G9: 0 | H9: 4034.47
A10: 40947 | B10: 0 | C10: 20 | D10: 0 | E10: 0.06 | F10: 0 | G10: 0 | H10: 4034.46
A11: 40948 | B11: 0 | C11: 20 | D11: 0 | E11: 0.01 | F11: 0 | G11: 0 | H11: 4034.46
A12: 40949 | B12: 0 | C12: 20 | D12: 0 | E12: 0 | F12: 0 | G12: 0 | H12: 4034.45
A13: 40950 | B13: 0 | C13: 20 | D13: 0 | E13: 0.02 | F13: 0 | G13: 0 | H13: 4034.45
A14: 40951 | B14: 0 | C14: 20 | D14: 0 | E14: 0 | F14: 0 | G14: 0 | H14: 4034.44
A15: 40952 | B15: 0 | C15: 38 | D15: 0 | E15: 0.29 | F15: 3 | G15: 0 | H15: 4034.42
A16: 40953 | B16: 0 | C16: 44 | D16: 0 | E16: 0.01 | F16: Tr | G16: 0 | H16: 4034.42
A17: 40954 | B17: 0 | C17: 34 | D17: 0 | E17: 0.01 | F17: 0 | G17: 0 | H17: 4034.41
A18: 40955 | B18: 0 | C18: 30 | D18: 0 | E18: 0.01 | F18: 0 | G18: 0 | H18: 4034.4
A19: 40956 | B19: 0 | C19: 30 | D19: 0 | E19: 0 | F19: 0 | G19: 0 | H19: 4034.4
A20: 40957 | B20: 0 | C20: 30 | D20: 0 | E20: 0.01 | F20: 0 | G20: 0 | H20: 4034.4
A21: 40958 | B21: 0 | C21: 30 | D21: 0 | E21: 0 | F21: 0 | G21: 0 | H21: 4034.4
A22: 40959 | B22: 0 | C22: 30 | D22: 0 | E22: 0.08 | F22: 1 | G22: 0 | H22: 4034.4
A23: 40960 | B23: 0 | C23: 30 | D23: 0 | E23: 0.01 | F23: 0 | G23: 0 | H23: 4034.4
A24: 40961 | B24: 0 | C24: 30 | D24: 0 | E24: 0.01 | F24: 0 | G24: 0 | H24: 4034.4
A25: 40962 | B25: 0 | C25: 30 | D25: 0 | E25: 0 | F25: 0 | G25: 0 | H25: 4034.4
A26: 40963 | B26: 0 | C26: 30 | D26: 0 | E26: 0 | F26: 0 | G26: 0 | H26: 4034.4
A27: 40964 | B27: 0 | C27: 30 | D27: 0 | E27: 0.01 | F27: Tr | G27: 0 | H27: 4034.4
A28: 40965 | B28: 0 | C28: 30 | D28: 0 | E28: 0 | F28: 0 | G28: 0 | H28: 4034.4
A29: 40966 | B29: 0 | C29: 30 | D29: 0 | E29: 0 | F29: 0 | G29: 0 | H29: 4034.4
A30: 40967 | B30: 0 | C30: 30 | D30: 0 | E30: 0 | F30: 0 | G30: 0 | H30: 4034.4
A31: 40968 | B31: 0 | C31: 24 | D31: 0 | E31: 0.02 | F31: 1 | G31: 0 | H31: 4034.4
A32: Monthly Total | B32: =SUM(B3:B31) -> 0 | C32: =SUM(C3:C31) -> 770 | D32: =SUM(D3:D31) -> 0 | E32: =SUM(E3:E31) -> 0.6 | F32: =SUM(F3:F31) -> 5 | G32: =SUM(G3:G31) -> 0
A33: WY Total | B33: =SUM(B32+'Jan 2012'!B35) -> 1523 | C33: =SUM(C32+'Jan 2012'!C35) -> 3003 | D33: =SUM(D32+'Jan 2012'!D35) -> 5200 | E33: =SUM(E32+'Jan 2012'!E35) -> 2.46 | F33: =SUM(F32+'Jan 2012'!F35) -> 7 | G33: =SUM(G32+'Jan 2012'!G35) -> 11498
A35: Acre Feet | B35: =SUM(B3:B31)*1.9835 -> 0 | C35: =SUM(C3:C31)*1.9835 -> 1527.295 | D35: =SUM(D3:D31)*1.9835 -> 0
A37: WY AF Total | B37: =SUM(B35+'Jan 2012'!B39) -> 1916.061 | C37: =SUM(C35+'Jan 2012'!C39) -> 4371.634 | D37: =SUM(D35+'Jan 2012'!D39) -> 3223.1875
G39: * COMPUTATIONAL PURPOSES ONLY! Do Not Enter Data in the Red Columns
A41: *This is computation purposes only for Station 48
A42: Sta 48
F43: =SUM(24-D43) -> 24 | G43: =SUM(C43+E43) -> 0 | H43: =SUM(C43/24*D43+G43/24*F43) -> 0
F44: =SUM(24-D44) -> 24 | G44: =SUM(C44+E44) -> 0 | H44: =SUM(C44/24*D44+G44/24*F44) -> 0
...

Sheet Jan 2012
A1: DATE | B1: STATION 48 | C1: ANDERSON-ROSE | D1: J CANAL | E1: TULE LAKE PRECIP | F1: TULE LAKE SNOW | G1: D PLANT | H1: TULE LAKE ELEV. | I1: CHANGES @ STATION 48
B2: (in CFS) | C2: (in CFS) | D2: (in CFS) | G2: (in AF)
A3: 40909 | B3: 0 | C3: 15 | D3: 0 | E3: 0 | F3: 0 | G3: 0 | H3: 4034.5
A4: 40910 | B4: 0 | C4: 15 | D4: 0 | E4: 0 | F4: 0 | G4: 0 | H4: 4034.5
A5: 40911 | B5: 0 | C5: 15 | D5: 0 | E5: 0 | F5: 0 | G5: 0 | H5: 4034.5
A6: 40912 | B6: 0 | C6: 15 | D6: 0 | E6: 0 | F6: 0 | G6: 0 | H6: 4034.51
A7: 40913 | B7: 0 | C7: 15 | D7: 0 | E7: 0 | F7: 0 | G7: 0 | H7: 4034.5
A8: 40914 | B8: 0 | C8: 15 | D8: 0 | E8: T | F8: 0 | G8: 0 | H8: 4034.5
A9: 40915 | B9: 0 | C9: 15 | D9: 0 | E9: 0 | F9: 0 | G9: 0 | H9: 4034.5
A10: 40916 | B10: 0 | C10: 15 | D10: 0 | E10: 0 | F10: 0 | G10: 0 | H10: 4034.5
A11: 40917 | B11: 0 | C11: 15 | D11: 0 | E11: 0 | F11: 0 | G11: 0 | H11: 4034.5
A12: 40918 | B12: 0 | C12: 15 | D12: 0 | E12: 0 | F12: 0 | G12: 0 | H12: 4034.5
A13: 40919 | B13: 0 | C13: 15 | D13: 0 | E13: 0 | F13: 0 | G13: 0 | H13: 4034.5
A14: 40920 | B14: 0 | C14: 15 | D14: 0 | E14: 0 | F14: 0 | G14: 0 | H14: 4034.5
A15: 40921 | B15: 0 | C15: 15 | D15: 0 | E15: 0 | F15: 0 | G15: 0 | H15: 4034.5
A16: 40922 | B16: 0 | C16: 15 | D16: 0 | E16: 0 | F16: 0 | G16: 0 | H16: 4034.5
A17: 40923 | B17: 0 | C17: 15 | D17: 0 | E17: 0 | F17: 0 | G17: 0 | H17: 4034.5
A18: 40924 | B18: 0 | C18: 15 | D18: 0 | E18: T | F18: 0 | G18: 0 | H18: 4034.5
A19: 40925 | B19: 0 | C19: 15 | D19: 0 | E19: 0 | F19: 0 | G19: 0 | H19: 4034.5
A20: 40926 | B20: 0 | C20: 15 | D20: 0 | E20: 0 | F20: 0 | G20: 0 | H20: 4034.51
A21: 40927 | B21: 0 | C21: 15 | D21: 0 | E21: 0.01 | F21: 0 | G21: 0 | H21: 4034.51
A22: 40928 | B22: 0 | C22: 15 | D22: 0 | E22: 0.02 | F22: 0 | G22: 0 | H22: 4034.51
A23: 40929 | B23: 0 | C23: 20 | D23: 0 | E23: 0.28 | F23: 0 | G23: 0 | H23: 4034.52
A24: 40930 | B24: 0 | C24: 30 | D24: 0 | E24: 0.02 | F24: T | G24: 0 | H24: 4034.52
A25: 40931 | B25: 0 | C25: 30 | D25: 0 | E25: 0.08 | F25: 1 | G25: 0 | H25: 4034.53
A26: 40932 | B26: 0 | C26: 30 | D26: 0 | E26: 0.05 | F26: 0.5 | G26: 0 | H26: 4034.54
A27: 40933 | B27: 0 | C27: 30 | D27: 0 | E27: 0.06 | F27: 0 | G27: 0 | H27: 4034.55
A28: 40934 | B28: 0 | C28: 34 | D28: 0 | E28: 0.18 | F28: 0 | G28: 0 | H28: 4034.55
A29: 40935 | B29: 0 | C29: 40 | D29: 0 | E29: 0.01 | F29: 0 | G29: 0 | H29: 4034.55
A30: 40936 | B30: 0 | C30: 40 | D30: 0 | E30: 0.01 | F30: 0 | G30: 0 | H30: 4034.55
A31: 40937 | B31: 0 | C31: 34 | D31: 0 | E31: 0 | F31: 0 | G31: 0 | H31: 4034.56
A32: 40938 | B32: 0 | C32: 30 | D32: 0 | E32: 0 | F32: 0 | G32: 0 | H32: 4034.57
A33: 40939 | B33: 0 | C33: 26 | D33: 0 | E33: 0 | F33: 0 | G33: 0 | H33: 4034.56
A34: Monthly Total | B34: =SUM(B3:B33) -> 0 | C34: =SUM(C3:C33) -> 644 | D34: =SUM(D3:D33) -> 0 | E34: =SUM(E3:E33) -> 0.72 | F34: =SUM(F3:F33) -> 1.5 | G34: =SUM(G3:G33) -> 0
A35: WY Total | B35: =SUM(B34+'Dec 2011'!B35) -> 1523 | C35: =SUM(C34+'Dec 2011'!C35) -> 2233 | D35: =SUM(D34+'Dec 2011'!D35) -> 5200 | E35: =SUM(E34+'Dec 2011'!E35) -> 1.86 | F35: =SUM(F34+'Dec 2011'!F35) -> 2 | G35: =SUM(G34+'Dec 2011'!G35) -> 11498
A37: Acre Feet | B37: =SUM(B3:B33)*1.9835 -> 0 | C37: =SUM(C3:C33)*1.9835 -> 1277.374 | D37: =SUM(D3:D33)*1.9835 -> 0
A39: WY AF Total | B39: =SUM(B37+'Dec 2011'!B39) -> 1916.061 | C39: =SUM(C37+'Dec 2011'!C39) -> 2844.339 | D39: =SUM(D37+'Dec 2011'!D39) -> 3223.1875
G41: * COMPUTATIONAL PURPOSES ONLY! Do Not Enter Data in the Red Columns
A43: *This is computation purposes only for Station 48
A44: Sta 48
...

Sheet Dec 2011
A1: DATE | B1: STATION 48 | C1: ANDERSON-ROSE | D1: J CANAL | E1: TULE LAKE PRECIP | F1: TULE LAKE SNOW | G1: D PLANT | H1: TULE LAKE ELEV. | I1: CHANGES @ STATION 48
B2: (in CFS) | C2: (in CFS) | D2: (in CFS) | G2: (in AF)
A3: 40878 | B3: 0 | C3: 20 | D3: 0 | E3: 0 | F3: 0 | G3: 0 | H3: 4034.44
A4: 40879 | B4: 0 | C4: 20 | D4: 0 | E4: 0 | F4: 0 | G4: 0 | H4: 4034.45
A5: 40880 | B5: 0 | C5: 20 | D5: 0 | E5: 0 | F5: 0 | G5: 0 | H5: 4034.46
A6: 40881 | B6: 0 | C6: 20 | D6: 0 | E6: 0 | F6: 0 | G6: 0 | H6: 4034.47
A7: 40882 | B7: 0 | C7: 17 | D7: 0 | E7: 0 | F7: 0 | G7: 0 | H7: 4034.48
A8: 40883 | B8: 0 | C8: 15 | D8: 0 | E8: 0 | F8: 0 | G8: 0 | H8: 4034.48
A9: 40884 | B9: 0 | C9: 15 | D9: 0 | E9: 0 | F9: 0 | G9: 0 | H9: 4034.48
A10: 40885 | B10: 0 | C10: 15 | D10: 0 | E10: 0 | F10: 0 | G10: 0 | H10: 4034.48
A11: 40886 | B11: 0 | C11: 15 | D11: 0 | E11: 0 | F11: 0 | G11: 0 | H11: 4034.48
A12: 40887 | B12: 0 | C12: 15 | D12: 0 | E12: 0 | F12: 0 | G12: 0 | H12: 4034.48
A13: 40888 | B13: 0 | C13: 15 | D13: 0 | E13: 0 | F13: 0 | G13: 0 | H13: 4034.48
A14: 40889 | B14: 0 | C14: 15 | D14: 0 | E14: 0 | F14: 0 | G14: 0 | H14: 4034.48
... A16: 40891 | B16: 0 | C16: 15 | D16: 0 | E16: 0 | F16: 0 | G16: 0 | H16: 4034.48
A17: 40892 | B17: 0 | C17: 15 | D17: 0 | E17: 0 | F17: T | G17: 0 | H17: 4034.48
A18: 40893 | B18: 0 | C18: 15 | D18: 0 | E18: 0 | F18: 0 | G18: 0 | H18: 4034.48
A19: 40894 | B19: 0 | C19: 15 | D19: 0 | E19: 0 | F19: 0 | G19: 0 | H19: 4034.48
A20: 40895 | B20: 0 | C20: 15 | D20: 0 | E20: 0 | F20: 0 | G20: 0 | H20: 4034.48
A21: 40896 | B21: 0 | C21: 15 | D21: 0 | E21: 0 | F21: 0 | G21: 0 | H21: 4034.48
A22: 40897 | B22: 0 | C22: 15 | D22: 0 | E22: 0 | F22: 0 | G22: 0 | H22: 4034.48
A23: 40898 | B23: 0 | C23: 15 | D23: 0 | E23: 0 | F23: 0 | G23: 0 | H23: 4034.48
A24: 40899 | B24: 0 | C24: 15 | D24: 0 | E24: 0 | F24: 0 | G24: 0 | H24: 4034.48
A25: 40900 | B25: 0 | C25: 15 | D25: 0 | E25: 0 | F25: 0 | G25: 0 | H25: 4034.48
A26: 40901 | B26: 0 | C26: 15 | D26: 0 | E26: 0 | F26: 0 | G26: 0 | H26: 4034.48
A27: 40902 | B27: 0 | C27: 15 | D27: 0 | E27: 0 | F27: 0 | G27: 0 | H27: 4034.48
A28: 40903 | B28: 0 | C28: 15 | D28: 0 | E28: 0 | F28: 0 | G28: 0 | H28: 4034.48
A29: 40904 | B29: 0 | C29: 15 | D29: 0 | E29: T | F29: 0 | G29: 0 | H29: 4034.48
A30: 40905 | B30: 0 | C30: 15 | D30: 0 | E30: 0.06 | F30: 0 | G30: 0 | H30: 4034.48
A31: 40906 | B31: 0 | C31: 15 | D31: 0 | E31: 0 | F31: 0 | G31: 0 | H31: 4034.49
A32: 40907 | B32: 0 | C32: 15 | D32: 0 | E32: 0.16 | F32: 0 | G32: 0 | H32: 4034.5
A33: 40908 | B33: 0 | C33: 15 | D33: 0 | E33: T | F33: 0 | G33: 0 | H33: 4034.5
A34: Monthly Total | B34: =SUM(B3:B33) -> 0 | C34: =SUM(C3:C33) -> 487 | D34: =SUM(D3:D33) -> 0 | E34: =SUM(E3:E33) -> 0.22 | F34: =SUM(F3:F33) -> 0 | G34: =SUM(G3:G33) -> 0
A35: WY Total | B35: =SUM(B34+'Nov 2011'!B34) -> 1523 | C35: =SUM(C34+'Nov 2011'!C34) -> 1589 | D35: =SUM(D34+'Nov 2011'!D34) -> 5200 | E35: =SUM(E34+'Nov 2011'!E34) -> 1.14 | F35: =SUM(F34+'Nov 2011'!F34) -> 0.5 | G35: =SUM(G34+'Nov 2011'!G34) -> 11498
A37: Acre Feet | B37: =SUM(B3:B33)*1.9835 -> 0 | C37: =SUM(C3:C33)*1.9835 -> 965.9645 | D37: =SUM(D3:D33)*1.9835 -> 0
A39: WY AF Total | B39: =SUM('Nov 2011'!B38+B37) -> 1916.061 | C39: =SUM('Nov 2011'!C38+C37) -> 1566.965 | D39: =SUM('Nov 2011'!D38+D37) -> 3223.1875
G41: * COMPUTATIONAL PURPOSES ONLY! Do Not Enter Data in the Red Columns
A43: *This is computation purposes only for Station 48
A44: Sta 48
F45: =SUM(24-D45) -> 24 | G45: =SUM(C45+E45) -> 0 | H45: =SUM(C45/24*D45+G45/24*F45) -> 0
...

Sheet Nov 2011
A1: DATE | B1: STATION 48 | C1: ANDERSON-ROSE | D1: J CANAL | E1: TULE LAKE PRECIP | F1: TULE LAKE SNOW | G1: D PLANT | H1: TULE LAKE ELEV. | I1: CHANGES @ STATION 48
B2: (in CFS) | C2: (in CFS) | D2: (in CFS) | G2: (in AF)
A3: 40848 | B3: 71 | C3: 0 | D3: 159 | E3: 0 | F3: 0 | G3: 103 | H3: 4034.56 | I3: *2 PM 50/100
A4: 40849 | B4: 100 | C4: 0 | D4: 169 | E4: 0 | F4: 0 | G4: 89 | H4: 4034.54
A5: 40850 | B5: 100 | C5: 0 | D5: 166 | E5: 0 | F5: 0 | G5: 84 | H5: 4034.53
A6: 40851 | B6: 83 | C6: 0 | D6: 130 | E6: 0 | F6: 0 | G6: 174 | H6: 4034.52 | I6: *8 AM 100/75
A7: 40852 | B7: 75 | C7: 0 | D7: 126 | E7: 0.02 | F7: 0.25 | G7: 300 | H7: 4034.5
A8: 40853 | B8: 58 | C8: 0 | D8: 120 | E8: 0.03 | F8: 0.25 | G8: 300 | H8: 4034.48 | I8: *8 AM 75/50
A9: 40854 | B9: 50 | C9: 0 | D9: 116 | E9: 0.01 | F9: 0 | G9: 300 | H9: 4034.44
A10: 40855 | B10: 50 | C10: 0 | D10: 89 | E10: 0 | F10: 0 | G10: 300 | H10: 4034.42
A11: 40856 | B11: 50 | C11: 0 | D11: 84 | E11: 0 | F11: 0 | G11: 300 | H11: 4034.4
A12: 40857 | B12: 50 | C12: 0 | D12: 83 | E12: 0 | F12: 0 | G12: 300 | H12: 4034.38
A13: 40858 | B13: 56 | C13: 0 | D13: 86 | E13: 0 | F13: 0 | G13: 300 | H13: 4034.36 | I13: *10 AM 50/75 4 PM 75/50
A14: 40859 | B14: 50 | C14: 0 | D14: 78 | E14: 0 | F14: 0 | G14: 300 | H14: 4034.33
A15: 40860 | B15: 50 | C15: 0 | D15: 68 | E15: 0 | F15: 0 | G15: 300 | H15: 4034.3
A16: 40861 | B16: 50 | C16: 0 | D16: 60 | E16: 0 | F16: 0 | G16: 300 | H16: 4034.3
A17: 40862 | B17: 39 | C17: 0 | D17: 38 | E17: 0 | F17: 0 | G17: 300 | H17: 4034.28 | I17: *1 PM 50/25
A18: 40863 | B18: 25 | C18: 0 | D18: 23 | E18: 0 | F18: 0 | G18: 300 | H18: 4034.26
A19: 40864 | B19: 9 | C19: 0 | D19: 20 | E19: 0 | F19: 0 | G19: 175 | H19: 4034.24 | I19: *9 AM 25/0
A20: 40865 | B20: 0 | C20: 16 | D20: 10 | E20: 0.16 | F20: T | G20: 0 | H20: 4034.22
A21: 40866 | B21: 0 | C21: 25 | D21: 0 | E21: 0 | F21: T | G21: 0 | H21: 4034.24
A22: 40867 | B22: 0 | C22: 25 | D22: 0 | E22: 0.04 | F22: T | G22: 0 | H22: 4034.26
A23: 40868 | B23: 0 | C23: 25 | D23: 0 | E23: 0 | F23: 0 | G23: 0 | H23: 4034.28
A24: 40869 | B24: 0 | C24: 25 | D24: 0 | E24: 0 | F24: 0 | G24: 0 | H24: 4034.3
A25: 40870 | B25: 0 | C25: 25 | D25: 0 | E25: 0 | F25: 0 | G25: 0 | H25: 4034.32
A26: 40871 | B26: 0 | C26: 25 | D26: 0 | E26: 0.21 | F26: 0 | G26: 0 | H26: 4034.34
A27: 40872 | B27: 0 | C27: 25 | D27: 0 | E27: 0 | F27: 0 | G27: 0 | H27: 4034.36
A28: 40873 | B28: 0 | C28: 25 | D28: 0 | E28: 0 | F28: 0 | G28: 0 | H28: 4034.38
A29: 40874 | B29: 0 | C29: 25 | D29: 0 | E29: 0 | F29: 0 | G29: 0 | H29: 4034.4
A30: 40875 | B30: 0 | C30: 22 | D30: 0 | E30: 0.08 | F30: 0 | G30: 0 | H30: 4034.41
A31: 40876 | B31: 0 | C31: 20 | D31: 0 | E31: 0 | F31: 0 | G31: 0 | H31: 4034.42
A32: 40877 | B32: 0 | C32: 20 | D32: 0 | E32: 0.01 | F32: 0 | G32: 0 | H32: 4034.43
A33: Monthly Total | B33: =SUM(B3:B32) -> 966 | C33: =SUM(C3:C32) -> 303 | D33: =SUM(D3:D32) -> 1625 | E33: =SUM(E3:E32) -> 0.56 | F33: =SUM(F3:F32) -> 0.5 | G33: =SUM(G3:G32) -> 4225
A34: WY Total | B34: =SUM(B33+'Oct 2011'!B35) -> 1523 | C34: =SUM(C33+'Oct 2011'!C35) -> 1102 | D34: =SUM(D33+'Oct 2011'!D35) -> 5200 | E34: =SUM(E33+'Oct 2011'!E35) -> 0.92 | F34: =SUM(F33+'Oct 2011'!F35) -> 0.5 | G34: =SUM(G33+'Oct 2011'!G35) -> 11498
A36: Acre Feet | B36: =SUM(B3:B32)*1.9835 -> 1916.061 | C36: =SUM(C3:C32)*1.9835 -> 601.0005 | D36: =SUM(D3:D32)*1.9835 -> 3223.1875
A38: WY AF Total | B38: =SUM('Oct 2011'!B40+B36) -> 1916.061 | C38: =SUM('Oct 2011'!C40+C36) -> 601.0005 | D38: =SUM('Oct 2011'!D40+D36) -> 3223.1875
G40: * COMPUTATIONAL PURPOSES ONLY! Do Not Enter Data in the Red Columns
A42: *This is computation purposes only for Station 48
A43: Sta 48
F44: =SUM(24-D44) -> 24 | G44: =SUM(C44+E44) -> 0 | H44: =SUM(C44/24*D44+G44/24*F44) -> 0
...

Sheet Oct 2011
A1: DATE | B1: STATION 48 | C1: ANDERSON-ROSE | D1: J CANAL | E1: TULE LAKE PRECIP | F1: TULE LAKE SNOW | G1: D PLANT | H1: TULE LAKE ELEV. | I1: CHANGES @ STATION 48
B2: (in CFS) | C2: (in CFS) | D2: (in CFS) | G2: (in AF)
A3: 40817 | B3: 0 | C3: 0 | D3: 158 | E3: 0 | F3: 0 | G3: 160 | H3: 4034.77
A4: 40818 | B4: 0 | C4: 0 | D4: 137 | E4: 0 | F4: 0 | G4: 160 | H4: 4034.76
A5: 40819 | B5: 0 | C5: 0 | D5: 138 | E5: 0 | F5: 0 | G5: 160 | H5: 4034.76
A6: 40820 | B6: 0 | C6: 8 | D6: 145 | E6: 0 | F6: 0 | G6: 160 | H6: 4034.76
A7: 40821 | B7: 0 | C7: 22 | D7: 133 | E7: 0.08 | F7: 0 | G7: 160 | H7: 4034.76
A8: 40822 | B8: 0 | C8: 15 | D8: 134 | E8: 0.02 | F8: 0 | G8: 160 | H8: 4034.76
A9: 40823 | B9: 0 | C9: 125 | D9: 121 | E9: 0 | F9: 0 | G9: 160 | H9: 4034.76
A10: 40824 | B10: 0 | C10: 100 | D10: 117 | E10: 0 | F10: 0 | G10: 160 | H10: 4034.76
A11: 40825 | B11: 0 | C11: 99 | D11: 135 | E11: 0 | F11: 0 | G11: 160 | H11: 4034.77
A12: 40826 | B12: 0 | C12: 95 | D12: 144 | E12: 0.26 | F12: 0 | G12: 160 | H12: 4034.79
A13: 40827 | B13: 0 | C13: 100 | D13: 122 | E13: 0 | F13: 0 | G13: 160 | H13: 4034.82
A14: 40828 | B14: 0 | C14: 61 | D14: 122 | E14: 0 | F14: 0 | G14: 160 | H14: 4034.84
... A24: 40838 | B24: 0 | C24: 0 | D24: 111 | E24: 0 | F24: 0 | G24: 301 | H24: 4034.78
A25: 40839 | B25: 47 | C25: 0 | D25: 105 | E25: 0 | F25: 0 | G25: 301 | H25: 4034.77 | I25: 9AM 0/75
A26: 40840 | B26: 75 | C26: 0 | D26: 91 | E26: 0 | F26: 0 | G26: 301 | H26: 4034.74
A27: 40841 | B27: 75 | C27: 0 | D27: 102 | E27: 0 | F27: 0 | G27: 301 | H27: 4034.73
A28: 40842 | B28: 75 | C28: 0 | D28: 117 | E28: 0 | F28: 0 | G28: 301 | H28: 4034.7
A29: 40843 | B29: 75 | C29: 0 | D29: 117 | E29: 0 | F29: 0 | G29: 301 | H29: 4034.68
A30: 40844 | B30: 60 | C30: 0 | D30: 117 | E30: 0 | F30: 0 | G30: 301 | H30: 4034.65 | I30: 10:00 am Sta 48 75/50
A31: 40845 | B31: 50 | C31: 0 | D31: 113 | E31: 0 | F31: 0 | G31: 301 | H31: 4034.62
A32: 40846 | B32: 50 | C32: 0 | D32: 112 | E32: 0 | F32: 0 | G32: 301 | H32: 4034.6
A33: 40847 | B33: 50 | C33: 0 | D33: 136 | E33: 0 | F33: 0 | G33: 126 | H33: 4034.58 | I33: * 1 D-Plant unit off at 3:PM
A34: Monthly Total | B34: =SUM(B3:B33) -> 557 | C34: =SUM(C3:C33) -> 799 | D34: =SUM(D3:D33) -> 3575 | E34: =SUM(E3:E33) -> 0.36 | F34: =SUM(F3:F33) -> 0 | G34: =SUM(G3:G33) -> 7273 | H34: =SUM(H3:H32) -> 121043.18
A35: WY Total | B35: =SUM(B34+'Oct 2011'!B36) -> 557 | C35: =SUM(C34+'Oct 2011'!C36) -> 799 | D35: =SUM(D34+'Oct 2011'!D36) -> 3575 | E35: =SUM(E34+'Oct 2011'!E36) -> 0.36 | F35: =SUM(F34+'Oct 2011'!F36) -> 0 | G35: =SUM(G34+'Oct 2011'!G36) -> 7273
A37: Acre Feet | B37: =SUM(B3:B32)*1.9835 -> 1005.6345 | C37: =SUM(C3:C32)*1.9835 -> 1584.8165 | D37: =SUM(D3:D32)*1.9835 -> 6821.2565
A39: WY AF Total | B39: =SUM('Oct 2011'!B40+B37) -> 1005.6345 | C39: =SUM('Oct 2011'!C40+C37) -> 1584.8165 | D39: =SUM('Oct 2011'!D40+D37) -> 6821.2565
G41: * COMPUTATIONAL PURPOSES ONLY! Do Not Enter Data in the Red Columns
A43: *This is computation purposes only for Station 48
A44: Sta 48
F45: =SUM(24-D45) -> 24 | G45: =SUM(C45+E45) -> 0 | H45: =SUM(C45/24*D45+G45/24*F45) -> 0
F46: =SUM(24-D46) -> 24 | G46: =SUM(C46+E46) -> 0 | H46: =SUM(C46/24*D46+G46/24*F46) -> 0
F47: =SUM(24-D47) -> 24 | G47: =SUM(C47+E47) -> 0 | H47: =SUM(C47/24*D47+G47/24*F47) -> 0
F48: =SUM(24-D48) -> 24 | G48: =SUM(C48+E48) -> 0 | H48: =SUM(C48/24*D48+G48/24*F48) -> 0
F49: =SUM(24-D49) -> 24 | G49: =SUM(C49+E49) -> 0 | H49: =SUM(C49/24*D49+G49/24*F49) -> 0
A51: Use for more than 1 change in a day.
A52: **Station 48: | B52: Time | C52: Current CFS | D52: Hours Run | E52: +/- cfs | F52: Sub-total cfs
A58: Total Hours Run | D58: =SUM(D53:D57) -> 0 | E58: Total/Day cfs | F58: =SUM(F53:F57) -> 0
A59: Total Hours Run | D59: =SUM(D54:D58) -> 0 | E59: Total/Day cfs | F59: =SUM(F54:F58) -> 0
