Workbook

Sheet Sep 2018
A1: DATE | B1: STATION 48 | C1: ANDERSON-ROSE | D1: J CANAL | E1: TULE LAKE PRECIP | F1: TULE LAKE SNOW | G1: D PLANT | H1: TULE LAKE ELEV. | I1: CHANGES @ STATION 48
B2: (in CFS) | C2: (in CFS) | D2: (in CFS) | G2: (in AF)
A3: 42614 | B3: 300 | C3: 0 | D3: 431 | E3: 0 | F3: 0 | G3: 0 | H3: 4034.81
A4: 42615 | B4: 252 | C4: 11 | D4: 389 | E4: 0 | F4: 0 | G4: 0 | H4: 4034.83 | I4: * 0800 300/250 * 1700 250/200
A5: 43346 | B5: 219 | C5: 10 | D5: 367 | E5: 0 | F5: 0 | G5: 0 | H5: 4034.85 | I5: * 1500 200/250
A6: 43347 | B6: 179 | C6: 18 | D6: 328 | E6: 0 | F6: 0 | G6: 0 | H6: 4034.88 | I6: * 0700 250/150
A7: 43348 | B7: 150 | C7: 11 | D7: 328 | E7: 0 | F7: 0 | G7: 0 | H7: 4034.9
A8: 43349 | B8: 165 | C8: 0 | D8: 330 | E8: 0 | F8: 0 | G8: 0 | H8: 4034.9 | I8: *1500 150/200
A9: 43350 | B9: 148 | C9: 17 | D9: 329 | E9: 0 | F9: 0 | G9: 113 | H9: 4034.9 | I9: 0900 200/150 1400 150/100 Started one unit at D plant approx 0700
A10: 43351 | B10: 100 | C10: 25 | D10: 290 | E10: 0 | F10: 0 | G10: 160 | H10: 4034.88
A11: 43352 | B11: 77 | C11: 16 | D11: 229 | E11: 0 | F11: 0 | G11: 160 | H11: 4034.88 | I11: *1300 100/50
A12: 43353 | B12: 85 | C12: 0 | D12: 225 | E12: 0 | F12: 0 | G12: 160 | H12: 4034.88 | I12: * 0900 50/100
A13: 43354 | B13: 125 | C13: 0 | D13: 225 | E13: 0 | F13: 0 | G13: 160 | H13: 4034.88 | I13: * 1200 100/150
A14: 43355 | B14: 122 | C14: 0 | D14: 222 | E14: 0 | F14: 0 | G14: 160 | H14: 4034.88 | I14: * 1030 150/100
A15: 43356 | B15: 100 | C15: 19 | D15: 225 | E15: 0 | F15: 0 | G15: 160 | H15: 4034.88
A16: 43357 | B16: 77 | C16: 27 | D16: 216 | E16: 0 | F16: 0 | G16: 160 | H16: 4034.88 | I16: * 1300 100/50
A17: 43358 | B17: 50 | C17: 14 | D17: 212 | E17: 0 | F17: 0 | G17: 160 | H17: 4034.88
A18: 43359 | B18: 50 | C18: 0 | D18: 208 | E18: 0 | F18: 0 | G18: 160 | H18: 4034.88
A19: 43360 | B19: 50 | C19: 0 | D19: 206 | E19: 0 | F19: 0 | G19: 160 | H19: 4034.88
A20: 43361 | B20: 50 | C20: 0 | D20: 210 | E20: 0 | F20: 0 | G20: 160 | H20: 4034.88
A21: 43362 | B21: 50 | C21: 0 | D21: 193 | E21: 0 | F21: 0 | G21: 160 | H21: 4034.88
A22: 43363 | B22: 83 | C22: 0 | D22: 192 | E22: 0 | F22: 0 | G22: 160 | H22: 4034.88 | I22: *0800 50/100
A23: 43364 | B23: 123 | C23: 0 | D23: 194 | E23: 0 | F23: 0 | G23: 160 | H23: 4034.88 | I23: *1300 100/150
A24: 43365 | B24: 150 | C24: 0 | D24: 197 | E24: 0 | F24: 0 | G24: 160 | H24: 4034.88
A25: 43366 | B25: 83 | C25: 0 | D25: 193 | E25: 0 | F25: 0 | G25: 160 | H25: 4034.88 | I25: * 0800 150/50
A26: 43367 | B26: 65 | C26: 0 | D26: 194 | E26: 0 | F26: 0 | G26: 160 | H26: 4034.88 | I26: *1700 50/100
A27: 43368 | B27: 100 | C27: 0 | D27: 180 | E27: 0 | F27: 0 | G27: 160 | H27: 4034.88
A28: 43369 | B28: 77 | C28: 0 | D28: 184 | E28: 0 | F28: 0 | G28: 160 | H28: 4034.88 | I28: *1300 100/50
A29: 43370 | B29: 50 | C29: 75 | D29: 180 | E29: 0 | F29: 0 | G29: 160 | H29: 4034.88
A30: 43371 | B30: 50 | C30: 0 | D30: 163 | E30: 0 | F30: 0 | G30: 160 | H30: 4034.88
A31: 43372 | B31: 85 | C31: 0 | D31: 171 | E31: 0 | F31: 0 | G31: 160 | H31: 4034.88 | I31: * 0700 50/100
A32: 43373 | B32: 58 | C32: 0 | D32: 160 | E32: 0.26 | F32: 0 | G32: 123 | H32: 4034.88 | I32: * 0800 100/50 * 1600 50/25
A33: Monthly Total | B33: =SUM(B3:B32) -> 3273 | C33: =SUM(C3:C32) -> 243 | D33: =SUM(D3:D32) -> 7171 | E33: =SUM(E3:E32) -> 0.26 | F33: =SUM(F3:F32) -> 0 | G33: =SUM(G3:G32) -> 3756
A34: WY Total | B34: =SUM(B33+'Aug 2018'!B35) -> 32901 | C34: =SUM(C33+'Aug 2018'!C35) -> 3552 | D34: =SUM(D33+'Aug 2018'!D35) -> 51860 | E34: =SUM(E33+'Aug 2018'!E35) -> 11.93 | F34: =SUM(F33+'Aug 2018'!F35) -> 14 | G34: =SUM(G33+'Aug 2018'!G35) -> 16168
A36: Acre Feet | B36: =SUM(B3:B32)*1.9835 -> 6491.9955 | C36: =SUM(C3:C32)*1.9835 -> 481.9905 | D36: =SUM(D3:D32)*1.9835 -> 14223.678
A38: WY AF Total | B38: =SUM(B36+'Aug 2018'!B39) -> 65818.481 | C38: =SUM(C36+'Aug 2018'!C39) -> 7045.392 | D38: =SUM(D36+'Aug 2018'!D39) -> 104538.38
G40: * COMPUTATIONAL PURPOSES ONLY! Do Not Enter Data in the Red Columns
A42: *This is computation purposes only for Station 48
A43: Sta 48
F44: =SUM(24-D44) -> 24 | G44: =SUM(C44+E44) -> 0 | H44: =SUM(C44/24*D44+G44/24*F44) -> 0
...

Sheet Aug 2018
A1: DATE | B1: STATION 48 | C1: ANDERSON-ROSE | D1: J CANAL | E1: TULE LAKE PRECIP | F1: TULE LAKE SNOW | G1: D PLANT | H1: TULE LAKE ELEV. | I1: CHANGES @ STATION 48
B2: (in CFS) | C2: (in CFS) | D2: (in CFS) | G2: (in AF)
A3: 43313 | B3: 300 | C3: 0 | D3: 440 | E3: 0 | F3: 0 | G3: 0 | H3: 4034.8
A4: 43314 | B4: 267 | C4: 0 | D4: 413 | E4: 0 | F4: 0 | G4: 0 | H4: 4034.79 | I4: * 0800 300/250
A5: 43315 | B5: 250 | C5: 0 | D5: 400 | E5: 0 | F5: 0 | G5: 0 | H5: 4034.78
A6: 43316 | B6: 250 | C6: 0 | D6: 385 | E6: 0 | F6: 0 | G6: 0 | H6: 4034.78
A7: 43317 | B7: 215 | C7: 0 | D7: 384 | E7: 0 | F7: 0 | G7: 0 | H7: 4034.78 | I7: * 0700 250/200
A8: 43318 | B8: 235 | C8: 0 | D8: 406 | E8: 0 | F8: 0 | G8: 0 | H8: 4034.78 | I8: * 0700 200/250
A9: 43319 | B9: 215 | C9: 0 | D9: 376 | E9: 0 | F9: 0 | G9: 0 | H9: 4034.78 | I9: * 0700 250/200
A10: 43320 | B10: 200 | C10: 0 | D10: 380 | E10: 0 | F10: 0 | G10: 0 | H10: 4034.78
A11: 43321 | B11: 200 | C11: 0 | D11: 381 | E11: 0 | F11: 0 | G11: 0 | H11: 4034.78
A12: 43322 | B12: 181 | C12: 0 | D12: 381 | E12: 0 | F12: 0 | G12: 0 | H12: 4034.76 | I12: *1500 200/150
A13: 43323 | B13: 185 | C13: 0 | D13: 336 | E13: 0 | F13: 0 | G13: 0 | H13: 4034.76 | I13: * 0700 150/200
A14: 43324 | B14: 169 | C14: 0 | D14: 344 | E14: 0 | F14: 0 | G14: 0 | H14: 4034.76 | I14: * 0900 200/150
A15: 43325 | B15: 150 | C15: 0 | D15: 344 | E15: 0 | F15: 0 | G15: 0 | H15: 4034.76 | I15: * 0700 150/200
A16: 43326 | B16: 185 | C16: 0 | D16: 330 | E16: 0 | F16: 0 | G16: 0 | H16: 4034.76
A17: 43327 | B17: 213 | C17: 0 | D17: 339 | E17: 0.01 | F17: 0 | G17: 0 | H17: 4034.76 | I17: * 1800 200/250
A18: 43328 | B18: 250 | C18: 0 | D18: 334 | E18: 0 | F18: 0 | G18: 0 | H18: 4034.76
A19: 43329 | B19: 217 | C19: 0 | D19: 350 | E19: 0 | F19: 0 | G19: 0 | H19: 4034.76 | I19: * 0800 250/200
A20: 43330 | B20: 258 | C20: 0 | D20: 398 | E20: 0 | F20: 0 | G20: 0 | H20: 4034.76 | I20: * 0700 200/300 * 1800 300/250
A21: 43331 | B21: 250 | C21: 0 | D21: 395 | E21: 0 | F21: 0 | G21: 0 | H21: 4034.76
A22: 43332 | B22: 269 | C22: 0 | D22: 428 | E22: 0 | F22: 0 | G22: 0 | H22: 4034.77 | I22: * 1500 250/300
A23: 43333 | B23: 277 | C23: 0 | D23: 450 | E23: 0 | F23: 0 | G23: 0 | H23: 4034.78 | I23: * 1300 300/250
A24: 43334 | B24: 225 | C24: 0 | D24: 420 | E24: 0 | F24: 0 | G24: 0 | H24: 4034.78 | I24: * 1400 250/200
A25: 43335 | B25: 200 | C25: 0 | D25: 372 | E25: 0 | F25: 0 | G25: 0 | H25: 4034.78
A26: 43336 | B26: 175 | C26: 0 | D26: 357 | E26: 0 | F26: 0 | G26: 0 | H26: 4034.79 | I26: * 1700 200/150
A27: 43337 | B27: 177 | C27: 0 | D27: 319 | E27: 0 | F27: 0 | G27: 0 | H27: 4034.79 | I27: *1100 150/200
A28: 43338 | B28: 220 | C28: 0 | D28: 325 | E28: 0 | F28: 0 | G28: 0 | H28: 4034.79 | I28: *1430 200/250
A29: 43339 | B29: 221 | C29: 0 | D29: 371 | E29: 0 | F29: 0 | G29: 0 | H29: 4034.8 | I29: * 1000 250/200
A30: 43340 | B30: 233 | C30: 0 | D30: 388 | E30: 0 | F30: 0 | G30: 0 | H30: 4034.8 | I30: * 0800 200/250
A31: 43341 | B31: 250 | C31: 0 | D31: 384 | E31: 0 | F31: 0 | G31: 0 | H31: 4034.8
A32: 43342 | B32: 250 | C32: 0 | D32: 394 | E32: 0 | F32: 0 | G32: 0 | H32: 4034.8
A33: 43343 | B33: 267 | C33: 0 | D33: 427 | E33: 0 | F33: 0 | G33: 0 | H33: 4034.81 | I33: * 1600 250/300
A34: Monthly Total | B34: =SUM(B3:B33) -> 6954 | C34: =SUM(C3:C33) -> 0 | D34: =SUM(D3:D33) -> 11751 | E34: =SUM(E3:E33) -> 0.01 | F34: =SUM(F3:F33) -> 0 | G34: =SUM(G3:G33) -> 0
A35: WY Total | B35: =SUM(B34+'Jul 2018'!B35) -> 29628 | C35: =SUM(C34+'Jul 2018'!C35) -> 3309 | D35: =SUM(D34+'Jul 2018'!D35) -> 44689 | E35: =SUM(E34+'Jul 2018'!E35) -> 11.67 | F35: =SUM(F34+'Jul 2018'!F35) -> 14 | G35: =SUM(G34+'Jul 2018'!G35) -> 12412
A37: Acre Feet | B37: =SUM(B3:B33)*1.9835 -> 13793.259 | C37: =SUM(C3:C33)*1.9835 -> 0 | D37: =SUM(D3:D33)*1.9835 -> 23308.109
A39: WY AF Total | B39: =SUM(B37+'Jul 2018'!B39) -> 59326.485 | C39: =SUM(C37+'Jul 2018'!C39) -> 6563.4015 | D39: =SUM(D37+'Jul 2018'!D39) -> 90314.705
G41: * COMPUTATIONAL PURPOSES ONLY! Do Not Enter Data in the Red Columns
A43: *This is computation purposes only for Station 48
A44: Sta 48
...

Sheet Jul 2018
A1: DATE | B1: STATION 48 | C1: ANDERSON-ROSE | D1: J CANAL | E1: TULE LAKE PRECIP | F1: TULE LAKE SNOW | G1: D PLANT | H1: TULE LAKE ELEV. | I1: CHANGES @ STATION 48
B2: (in CFS) | C2: (in CFS) | D2: (in CFS) | G2: (in AF)
A3: 43282 | B3: 373 | C3: 0 | D3: 484 | E3: 0 | F3: 0 | G3: 0 | H3: 4035.08 | I3: * 1630 350/400
A4: 43283 | B4: 395 | C4: 0 | D4: 463 | E4: 0 | F4: 0 | G4: 0 | H4: 4035.08 | I4: * 1030 400/450 1500 450/400 1700 400/350
A5: 43284 | B5: 365 | C5: 0 | D5: 460 | E5: 0 | F5: 0 | G5: 0 | H5: 4035.05 | I5: * 1700 350/400
A6: 43285 | B6: 415 | C6: 0 | D6: 474 | E6: 0 | F6: 0 | G6: 0 | H6: 4035.02 | I6: * 0730 400/450 * 1430 450/400
A7: 43286 | B7: 365 | C7: 13 | D7: 464 | E7: 0 | F7: 0 | G7: 0 | H7: 4034.99 | I7: * 0700 400/350
A8: 43287 | B8: 350 | C8: 9 | D8: 458 | E8: 0 | F8: 0 | G8: 0 | H8: 4034.96
A9: 43288 | B9: 337 | C9: 0 | D9: 427 | E9: 0 | F9: 0 | G9: 0 | H9: 4034.93 | I9: * 1800 350/300
A10: 43289 | B10: 284 | C10: 0 | D10: 380 | E10: 0 | F10: 0 | G10: 0 | H10: 4034.9 | I10: * 1700 300/250
A11: 43290 | B11: 279 | C11: 0 | D11: 371 | E11: 0 | F11: 0 | G11: 0 | H11: 4034.9 | I11: * 1000 250/300
A12: 43291 | B12: 300 | C12: 0 | D12: 397 | E12: 0 | F12: 0 | G12: 0 | H12: 4034.9
A13: 43292 | B13: 329 | C13: 0 | D13: 418 | E13: 0 | F13: 0 | G13: 0 | H13: 4034.88 | I13: * 1000 300/350
A14: 43293 | B14: 331 | C14: 15 | D14: 433 | E14: 0 | F14: 0 | G14: 0 | H14: 4034.88 | I14: * 1500 350/300
A15: 43294 | B15: 300 | C15: 12 | D15: 356 | E15: 0 | F15: 0 | G15: 0 | H15: 4034.86
A16: 43295 | B16: 319 | C16: 0 | D16: 438 | E16: 0 | F16: 0 | G16: 0 | H16: 4034.86 | I16: * 1500 300/350
A17: 43296 | B17: 315 | C17: 0 | D17: 447 | E17: 0 | F17: 0 | G17: 0 | H17: 4034.85 | I17: * 0700 350/300
A18: 43297 | B18: 300 | C18: 0 | D18: 416 | E18: 0 | F18: 0 | G18: 0 | H18: 4035.85
A19: 43298 | B19: 329 | C19: 0 | D19: 410 | E19: 0 | F19: 0 | G19: 0 | H19: 4034.84 | I19: * 0800 300/400 1500 400/300
A20: 43299 | B20: 300 | C20: 0 | D20: 404 | E20: 0 | F20: 0 | G20: 0 | H20: 4034.84
A21: 43300 | B21: 335 | C21: 0 | D21: 397 | E21: 0 | F21: 0 | G21: 0 | H21: 4034.83 | I21: * 0700 300/350
A22: 43301 | B22: 302 | C22: 0 | D22: 390 | E22: 0 | F22: 0 | G22: 0 | H22: 4034.83 | I22: * 0700 350/300 * 1800 300/250
A23: 43302 | B23: 269 | C23: 0 | D23: 336 | E23: 0 | F23: 0 | G23: 0 | H23: 4034.82 | I23: * 0700 250/300 * 1600 300/250
A24: 43303 | B24: 238 | C24: 13 | D24: 325 | E24: 0 | F24: 0 | G24: 0 | H24: 4034.82 | I24: * 1800 250/200
A25: 43304 | B25: 229 | C25: 10 | D25: 360 | E25: 0 | F25: 0 | G25: 0 | H25: 4034.82 | I25: * 1000 200/250
A26: 43305 | B26: 288 | C26: 0 | D26: 432 | E26: 0 | F26: 0 | G26: 0 | H26: 4034.82 | I26: * 1500 250/350
A27: 43306 | B27: 335 | C27: 0 | D27: 472 | E27: 0 | F27: 0 | G27: 0 | H27: 4034.82 | I27: * 0900 350/300 1700 300/350
A28: 43307 | B28: 331 | C28: 0 | D28: 497 | E28: 0 | F28: 0 | G28: 0 | H28: 4034.82 | I28: * 1500 350/300
A29: 43308 | B29: 319 | C29: 0 | D29: 511 | E29: 0 | F29: 0 | G29: 0 | H29: 4034.8 | I29: * 1500 300/350
A30: 43309 | B30: 360 | C30: 0 | D30: 475 | E30: 0 | F30: 0 | G30: 0 | H30: 4034.8 | I30: * 0800 350/400 1300 400/350
A31: 43310 | B31: 300 | C31: 0 | D31: 457 | E31: 0 | F31: 0 | G31: 0 | H31: 4034.8 | I31: * 0800 350/300 1600 300/250
A32: 43311 | B32: 275 | C32: 0 | D32: 448 | E32: 0 | F32: 0 | G32: 0 | H32: 4034.8 | I32: * 1200 250/300
A33: 43312 | B33: 279 | C33: 0 | D33: 469 | E33: 0 | F33: 0 | G33: 0 | H33: 4034.8 | I33: * 0800 300/250 1800 250/300
A34: Monthly Total | B34: =SUM(B3:B33) -> 9846 | C34: =SUM(C3:C33) -> 72 | D34: =SUM(D3:D33) -> 13269 | E34: =SUM(E3:E33) -> 0 | F34: =SUM(F3:F33) -> 0 | G34: =SUM(G3:G33) -> 0
A35: WY Total | B35: =SUM(B34+'Jun 2018'!B34) -> 22674 | C35: =SUM(C34+'Jun 2018'!C34) -> 3309 | D35: =SUM(D34+'Jun 2018'!D34) -> 32938 | E35: =SUM(E34+'Jun 2018'!E34) -> 11.66 | F35: =SUM(F34+'Jun 2018'!F34) -> 14 | G35: =SUM(G34+'Jun 2018'!G34) -> 12412
A37: Acre Feet | B37: =SUM(B3:B33)*1.9835 -> 19529.541 | C37: =SUM(C3:C33)*1.9835 -> 142.812 | D37: =SUM(D3:D33)*1.9835 -> 26319.061
A39: WY AF Total | B39: =SUM(B37+'Jun 2018'!B38) -> 45533.226 | C39: =SUM(C37+'Jun 2018'!C38) -> 6563.4015 | D39: =SUM(D37+'Jun 2018'!D38) -> 67006.597
G41: * COMPUTATIONAL PURPOSES ONLY! Do Not Enter Data in the Red Columns
A43: *This is computation purposes only for Station 48
A44: Sta 48
...

Sheet Jun 2018
A1: DATE | B1: STATION 48 | C1: ANDERSON-ROSE | D1: J CANAL | E1: TULE LAKE PRECIP | F1: TULE LAKE SNOW | G1: D PLANT | H1: TULE LAKE ELEV. | I1: CHANGES @ STATION 48
B2: (in CFS) | C2: (in CFS) | D2: (in CFS) | G2: (in AF)
A3: 43252 | B3: 69 | C3: 0 | D3: 101 | E3: 0 | F3: 0 | G3: 0 | H3: 4035.23 | I3: * 0900 100/50
A4: 43253 | B4: 50 | C4: 0 | D4: 94 | E4: 0 | F4: 0 | G4: 0 | H4: 4035.24
A5: 43254 | B5: 65 | C5: 0 | D5: 110 | E5: 0.15 | F5: 0 | G5: 0 | H5: 4035.25 | I5: * 17:00 50/100
A6: 43255 | B6: 100 | C6: 0 | D6: 160 | E6: 0 | F6: 0 | G6: 0 | H6: 4035.26 | I6: * 11:00 100/150
A7: 43256 | B7: 127 | C7: 0 | D7: 162 | E7: 0 | F7: 0 | G7: 0 | H7: 4035.26
A8: 43257 | B8: 150 | C8: 0 | D8: 191 | E8: 0 | F8: 0 | G8: 0 | H8: 4035.25
A9: 43258 | B9: 150 | C9: 0 | D9: 171 | E9: 0 | F9: 0 | G9: 0 | H9: 4035.24
A10: 43259 | B10: 169 | C10: 0 | D10: 190 | E10: 0 | F10: 0 | G10: 0 | H10: 4035.23 | I10: * 1500 150/200
A11: 43260 | B11: 196 | C11: 0 | D11: 212 | E11: 0.14 | F11: 0 | G11: 0 | H11: 4035.22 | I11: * 0800 200/250 *1400 250/200 * 1600 200/150
A12: 43261 | B12: 133 | C12: 24 | D12: 198 | E12: 0.01 | F12: 0 | G12: 0 | H12: 4035.21 | I12: * 1600 150/100
A13: 43262 | B13: 116 | C13: 25 | D13: 200 | E13: 0 | F13: 0 | G13: 0 | H13: 4035.2 | I13: * 1630 100/150
A14: 43263 | B14: 149 | C14: 0 | D14: 225 | E14: 0 | F14: 0 | G14: 0 | H14: 4035.2 | I14: * 0800 150/100 * 1430 100/150 * 1800 150/200
A15: 43264 | B15: 240 | C15: 0 | D15: 281 | E15: 0 | F15: 0 | G15: 0 | H15: 4035.22 | I15: * 1200 200/250 * 1700 250/300
A16: 43265 | B16: 331 | C16: 0 | D16: 354 | E16: 0 | F16: 0 | G16: 0 | H16: 4035.22 | I16: * 0900 300/350
A17: 43266 | B17: 369 | C17: 0 | D17: 390 | E17: 0 | F17: 0 | G17: 0 | H17: 4035.22 | I17: * 1500 350/400
A18: 43267 | B18: 340 | C18: 0 | D18: 416 | E18: 0 | F18: 0 | G18: 0 | H18: 4035.2 | I18: * 1000 400/350 *1500 350/300
A19: 43268 | B19: 336 | C19: 0 | D19: 367 | E19: 0.05 | F19: 0 | G19: 0 | H19: 4035.22 | I19: * 0700 300/350
A20: 43269 | B20: 296 | C20: 0 | D20: 422 | E20: 0.01 | F20: 0 | G20: 0 | H20: 4035.2 | I20: * 0700 350/250 *1600 250/300
A21: 43270 | B21: 369 | C21: 0 | D21: 470 | E21: 0.01 | F21: 0 | G21: 0 | H21: 4035.19 | I21: * 1100 300/350 *1400 350/450
... A24: 43273 | B24: 410 | C24: 0 | D24: 479 | E24: 0 | F24: 0 | G24: 0 | H24: 4035.16 | I24: * 1200 450/400 * 1700 400/350
A25: 43274 | B25: 350 | C25: 0 | D25: 469 | E25: 0 | F25: 0 | G25: 0 | H25: 4035.15
A26: 43275 | B26: 350 | C26: 0 | D26: 437 | E26: 0 | F26: 0 | G26: 0 | H26: 4035.14
A27: 43276 | B27: 375 | C27: 0 | D27: 503 | E27: 0 | F27: 0 | G27: 0 | H27: 4035.12 | I27: * 1800 350/450
A28: 43277 | B28: 415 | C28: 0 | D28: 522 | E28: 0 | F28: 0 | G28: 0 | H28: 4035.12 | I28: * 0700 450/400
A29: 43278 | B29: 469 | C29: 0 | D29: 579 | E29: 0 | F29: 0 | G29: 0 | H29: 4035.12 | I29: * 0700 400/450 *0800 450/500
A30: 43279 | B30: 467 | C30: 15 | D30: 580 | E30: 0 | F30: 0 | G30: 0 | H30: 4035.1 | I30: * 0800 500/450
A31: 43280 | B31: 450 | C31: 8 | D31: 575 | E31: 0 | F31: 0 | G31: 0 | H31: 4035.1
A32: 43281 | B32: 409 | C32: 0 | D32: 535 | E32: 0 | F32: 0 | G32: 0 | H32: 4035.08 | I32: * 1030 450/400 * 1800 400/350
A33: Monthly Total | B33: =SUM(B3:B32) -> 8301 | C33: =SUM(C3:C32) -> 72 | D33: =SUM(D3:D32) -> 10361 | E33: =SUM(E3:E32) -> 0.37 | F33: =SUM(F3:F32) -> 0 | G33: =SUM(G3:G32) -> 0
A34: WY Total | B34: =SUM(B33+'May 2018'!B35) -> 12828 | C34: =SUM(C33+'May 2018'!C35) -> 3237 | D34: =SUM(D33+'May 2018'!D35) -> 19669 | E34: =SUM(E33+'May 2018'!E35) -> 11.66 | F34: =SUM(F33+'May 2018'!F35) -> 14 | G34: =SUM(G33+'May 2018'!G35) -> 12412
A36: Acre Feet | B36: =SUM(B3:B32)*1.9835 -> 16465.034 | C36: =SUM(C3:C32)*1.9835 -> 142.812 | D36: =SUM(D3:D32)*1.9835 -> 20551.043
A38: WY AF Total | B38: =SUM(B36+'May 2018'!B39) -> 26003.685 | C38: =SUM(C36+'May 2018'!C39) -> 6420.5895 | D38: =SUM(D36+'May 2018'!D39) -> 40687.535
G40: * COMPUTATIONAL PURPOSES ONLY! Do Not Enter Data in the Red Columns
A42: *This is computation purposes only for Station 48
A43: Sta 48
F44: =SUM(24-D44) -> 24 | G44: =SUM(C44+E44) -> 0 | H44: =SUM(C44/24*D44+G44/24*F44) -> 0
F45: =SUM(24-D45) -> 24 | G45: =SUM(C45+E45) -> 0 | H45: =SUM(C45/24*D45+G45/24*F45) -> 0
F46: =SUM(24-D46) -> 24 | G46: =SUM(C46+E46) -> 0 | H46: =SUM(C46/24*D46+G46/24*F46) -> 0
...

Sheet May 2018
A1: DATE | B1: STATION 48 | C1: ANDERSON-ROSE | D1: J CANAL | E1: TULE LAKE PRECIP | F1: TULE LAKE SNOW | G1: D PLANT | H1: TULE LAKE ELEV. | I1: CHANGES @ STATION 48
B2: (in CFS) | C2: (in CFS) | D2: (in CFS) | G2: (in AF)
A3: 43221 | B3: 50 | C3: 0 | D3: 106 | E3: 0 | F3: 0 | G3: 0 | H3: 4035.15
A4: 43222 | B4: 50 | C4: 0 | D4: 116 | E4: 0 | F4: 0 | G4: 0 | H4: 4035.14
A5: 43223 | B5: 50 | C5: 0 | D5: 110 | E5: 0 | F5: 0 | G5: 0 | H5: 4035.14
A6: 43224 | B6: 50 | C6: 0 | D6: 90 | E6: 0 | F6: 0 | G6: 0 | H6: 4035.14
A7: 43225 | B7: 63 | C7: 0 | D7: 87 | E7: 0 | F7: 0 | G7: 0 | H7: 4035.12 | I7: * 11:30 AM 50/75
A8: 43226 | B8: 75 | C8: 0 | D8: 99 | E8: 0 | F8: 0 | G8: 0 | H8: 4035.12
A9: 43227 | B9: 75 | C9: 0 | D9: 113 | E9: 0 | F9: 0 | G9: 0 | H9: 4035.11
A10: 43228 | B10: 75 | C10: 0 | D10: 114 | E10: T | F10: 0 | G10: 0 | H10: 4035.1
A11: 43229 | B11: 75 | C11: 0 | D11: 114 | E11: 0.06 | F11: 0 | G11: 0 | H11: 4035.09
A12: 43230 | B12: 75 | C12: 0 | D12: 114 | E12: 0 | F12: 0 | G12: 0 | H12: 4035.08
A13: 43231 | B13: 75 | C13: 0 | D13: 113 | E13: 0 | F13: 0 | G13: 0 | H13: 4035.07
A14: 43232 | B14: 75 | C14: 0 | D14: 111 | E14: 0 | F14: 0 | G14: 0 | H14: 4035.06
A15: 43233 | B15: 92 | C15: 0 | D15: 120 | E15: 0 | F15: 0 | G15: 0 | H15: 4035.05 | I15: * 8:00 AM 75/100
A16: 43234 | B16: 116 | C16: 0 | D16: 141 | E16: 0 | F16: 0 | G16: 0 | H16: 4035.05 | I16: * 8:30 AM 100/125
A17: 43235 | B17: 125 | C17: 0 | D17: 155 | E17: 0 | F17: 0 | G17: 0 | H17: 4035.05
A18: 43236 | B18: 125 | C18: 0 | D18: 133 | E18: 0 | F18: 0 | G18: 0 | H18: 4035.05
A19: 43237 | B19: 156 | C19: 0 | D19: 150 | E19: 0.17 | F19: 0 | G19: 0 | H19: 4035.05 | I19: * 9:00 AM 125/175
A20: 43238 | B20: 175 | C20: 0 | D20: 182 | E20: 0 | F20: 0 | G20: 0 | H20: 4035.05
A21: 43239 | B21: 175 | C21: 0 | D21: 186 | E21: 0 | F21: 0 | G21: 0 | H21: 4035.05
A22: 43240 | B22: 165 | C22: 0 | D22: 179 | E22: 0.03 | F22: 0 | G22: 0 | H22: 4035.05 | I22: * 14:00 PM 175/150
A23: 43241 | B23: 198 | C23: 0 | D23: 190 | E23: 0 | F23: 0 | G23: 0 | H23: 4035.05 | I23: * 08:30 150/175 * 17:00 175/200 * 18:00 200/300 * 00:00 300/150
A24: 43242 | B24: 150 | C24: 0 | D24: 201 | E24: 0 | F24: 0 | G24: 0 | H24: 4035.04
A25: 43243 | B25: 150 | C25: 0 | D25: 196 | E25: 0.05 | F25: 0 | G25: 0 | H25: 4035.04
A26: 43244 | B26: 150 | C26: 0 | D26: 169 | E26: 0.01 | F26: 0 | G26: 0 | H26: 4035.05
A27: 43245 | B27: 124 | C27: 0 | D27: 229 | E27: 0.62 | F27: 0 | G27: 0 | H27: 4035.08 | I27: * 1700 150/100 * 2000 100/30
A28: 43246 | B28: 36 | C28: 0 | D28: 167 | E28: 1.3 | F28: 0 | G28: 0 | H28: 4035.11 | I28: * 1700 30/50
A29: 43247 | B29: 104 | C29: 0 | D29: 131 | E29: 0.01 | F29: 0 | G29: 0 | H29: 4035.16 | I29: * 0700 50/150 * 1600 150/100
A30: 43248 | B30: 100 | C30: 0 | D30: 126 | E30: 0 | F30: 0 | G30: 0 | H30: 4035.18
A31: 43249 | B31: 117 | C31: 0 | D31: 108 | E31: 0 | F31: 0 | G31: 0 | H31: 4035.2 | I31: * 1600 100/150
A32: 43250 | B32: 120 | C32: 0 | D32: 110 | E32: 0 | F32: 0 | G32: 0 | H32: 4035.21 | I32: * 0930 150/100
A33: 43251 | B33: 100 | C33: 0 | D33: 107 | E33: 0.4 | F33: 0 | G33: 0 | H33: 4035.22
A34: Monthly Total | B34: =SUM(B3:B33) -> 3266 | C34: =SUM(C3:C33) -> 0 | D34: =SUM(D3:D33) -> 4267 | E34: =SUM(E3:E33) -> 2.65 | F34: =SUM(F3:F33) -> 0 | G34: =SUM(G3:G33) -> 0
A35: WY Total | B35: =SUM(B34+'Apr 2018'!B34) -> 4527 | C35: =SUM(C34+'Apr 2018'!C34) -> 3165 | D35: =SUM(D34+'Apr 2018'!D34) -> 9308 | E35: =SUM(E34+'Apr 2018'!E34) -> 11.29 | F35: =SUM(F34+'Apr 2018'!F34) -> 14 | G35: =SUM(G34+'Apr 2018'!G34) -> 12412
A37: Acre Feet | B37: =SUM(B3:B33)*1.9835 -> 6478.111 | C37: =SUM(C3:C33)*1.9835 -> 0 | D37: =SUM(D3:D33)*1.9835 -> 8463.5945
A39: WY AF Total | B39: =SUM(B37+'Apr 2018'!B38) -> 9538.6515 | C39: =SUM(C37+'Apr 2018'!C38) -> 6277.7775 | D39: =SUM(D37+'Apr 2018'!D38) -> 20136.492
G41: * COMPUTATIONAL PURPOSES ONLY! Do Not Enter Data in the Red Columns
A43: *This is computation purposes only for Station 48
A44: Sta 48
...

Sheet Apr 2018
A1: DATE | B1: STATION 48 | C1: ANDERSON-ROSE | D1: J CANAL | E1: TULE LAKE PRECIP | F1: TULE LAKE SNOW | G1: D PLANT | H1: TULE LAKE ELEV. | I1: CHANGES @ STATION 48
B2: (in CFS) | C2: (in CFS) | D2: (in CFS) | G2: (in AF)
A3: 43191 | B3: 0 | C3: 0 | D3: 14 | E3: 0 | F3: 0 | G3: 0 | H3: 4035.08
A4: 43192 | B4: 0 | C4: 0 | D4: 14 | E4: 0 | F4: 0 | G4: 0 | H4: 4035.06
A5: 43193 | B5: 0 | C5: 0 | D5: 14 | E5: 0 | F5: 0 | G5: 0 | H5: 4035.06
A6: 43194 | B6: 0 | C6: 0 | D6: 14 | E6: 0 | F6: 0 | G6: 0 | H6: 4035.08
A7: 43195 | B7: 0 | C7: 0 | D7: 14 | E7: 0.1 | F7: 0 | G7: 0 | H7: 4035.1
A8: 43196 | B8: 0 | C8: 0 | D8: 14 | E8: 0.8 | F8: 0 | G8: 0 | H8: 4035.1
A9: 43197 | B9: 0 | C9: 0 | D9: 19 | E9: 0.36 | F9: 0 | G9: 0 | H9: 4035.14
A10: 43198 | B10: 0 | C10: 0 | D10: 25 | E10: 0 | F10: 0 | G10: 0 | H10: 4035.16
A11: 43199 | B11: 0 | C11: 0 | D11: 35 | E11: 0 | F11: 0 | G11: 0 | H11: 4035.18
A12: 43200 | B12: 0 | C12: 0 | D12: 39 | E12: 0.01 | F12: 0 | G12: 0 | H12: 4035.18
A13: 43201 | B13: 0 | C13: 0 | D13: 26 | E13: 0 | F13: 0 | G13: 0 | H13: 4035.18
A14: 43202 | B14: 0 | C14: 0 | D14: 19 | E14: 0.23 | F14: 0.5 | G14: 0 | H14: 4035.5
... A19: 43207 | B19: 0 | C19: 0 | D19: 19 | E19: 0.01 | F19: 0 | G19: 0 | H19: 4035.2
A20: 43208 | B20: 0 | C20: 0 | D20: 19 | E20: T | F20: 0 | G20: 0 | H20: 4035.2
A21: 43209 | B21: 0 | C21: 0 | D21: 19 | E21: 0 | F21: 0 | G21: 0 | H21: 4035.2
A22: 43210 | B22: 0 | C22: 0 | D22: 18 | E22: 0 | F22: 0 | G22: 0 | H22: 4035.2
A23: 43211 | B23: 0 | C23: 0 | D23: 18 | E23: 0 | F23: 0 | G23: 0 | H23: 4035.2
A24: 43212 | B24: 0 | C24: 0 | D24: 14 | E24: 0 | F24: 0 | G24: 0 | H24: 4035.2
A25: 43213 | B25: 0 | C25: 0 | D25: 10 | E25: 0 | F25: 0 | G25: 0 | H25: 4035.2
A26: 43214 | B26: 0 | C26: 0 | D26: 11 | E26: 0 | F26: 0 | G26: 0 | H26: 4035.2
A27: 43215 | B27: 0 | C27: 0 | D27: 11 | E27: 0 | F27: 0 | G27: 0 | H27: 4035.19
A28: 43216 | B28: 29 | C28: 0 | D28: 23 | E28: 0 | F28: 0 | G28: 0 | H28: 4035.19 | I28: *10:00 AM 0/50
A29: 43217 | B29: 66 | C29: 0 | D29: 74 | E29: 0 | F29: 0 | G29: 0 | H29: 4035.18 | I29: *8:30 AM 50/75
A30: 43218 | B30: 75 | C30: 0 | D30: 94 | E30: 0.08 | F30: 0 | G30: 0 | H30: 4035.18
A31: 43219 | B31: 62 | C31: 0 | D31: 98 | E31: 0.2 | F31: 0 | G31: 0 | H31: 4035.17 | I31: *11:00 AM 75/50
A32: 43220 | B32: 50 | C32: 0 | D32: 94 | E32: 0.02 | F32: 0 | G32: 0 | H32: 4035.17
A33: Monthly Total | B33: =SUM(B3:B32) -> 282 | C33: =SUM(C3:C32) -> 0 | D33: =SUM(D3:D32) -> 844 | E33: =SUM(E3:E32) -> 1.95 | F33: =SUM(F3:F32) -> 0.5 | G33: =SUM(G3:G32) -> 0
A34: WY Total | B34: =SUM(B33+'Mar 2018'!B35) -> 1261 | C34: =SUM(C33+'Mar 2018'!C35) -> 3165 | D34: =SUM(D33+'Mar 2018'!D35) -> 5041 | E34: =SUM(E33+'Mar 2018'!E35) -> 8.64 | F34: =SUM(F33+'Mar 2018'!F35) -> 14 | G34: =SUM(G33+'Mar 2018'!G35) -> 12412
A36: Acre Feet | B36: =SUM(B3:B33)*1.9835 -> 1118.694 | C36: =SUM(C3:C33)*1.9835 -> 0 | D36: =SUM(D3:D33)*1.9835 -> 3348.148
A38: WY AF Total | B38: =SUM(B36+'Mar 2018'!B39) -> 3060.5405 | C38: =SUM(C36+'Mar 2018'!C39) -> 6277.7775 | D38: =SUM(D36+'Mar 2018'!D39) -> 11672.897
G40: * COMPUTATIONAL PURPOSES ONLY! Do Not Enter Data in the Red Columns
A42: *This is computation purposes only for Station 48
A43: Sta 48
F44: =SUM(24-D44) -> 24 | G44: =SUM(C44+E44) -> 0 | H44: =SUM(C44/24*D44+G44/24*F44) -> 0
F45: =SUM(24-D45) -> 24 | G45: =SUM(C45+E45) -> 0 | H45: =SUM(C45/24*D45+G45/24*F45) -> 0
F46: =SUM(24-D46) -> 24 | G46: =SUM(C46+E46) -> 0 | H46: =SUM(C46/24*D46+G46/24*F46) -> 0
F47: =SUM(24-D47) -> 24 | G47: =SUM(C47+E47) -> 0 | H47: =SUM(C47/24*D47+G47/24*F47) -> 0
F48: =SUM(24-D48) -> 24 | G48: =SUM(C48+E48) -> 0 | H48: =SUM(C48/24*D48+G48/24*F48) -> 0
...

Sheet Mar 2018
A1: DATE | B1: STATION 48 | C1: ANDERSON-ROSE | D1: J CANAL | E1: TULE LAKE PRECIP | F1: TULE LAKE SNOW | G1: D PLANT | H1: TULE LAKE ELEV. | I1: CHANGES @ STATION 48
B2: (in CFS) | C2: (in CFS) | D2: (in CFS) | G2: (in AF)
A3: 43160 | B3: 0 | C3: 0 | D3: 0 | E3: 0.01 | F3: T | G3: 0 | H3: 4034.58
A4: 43161 | B4: 0 | C4: 0 | D4: 0 | E4: 0.18 | F4: 3 | G4: 0 | H4: 4034.59
A5: 43162 | B5: 0 | C5: 0 | D5: 0 | E5: 0.02 | F5: T | G5: 0 | H5: 4034.59
A6: 43163 | B6: 0 | C6: 0 | D6: 0 | E6: 0 | F6: 0 | G6: 0 | H6: 4034.6
A7: 43164 | B7: 0 | C7: 0 | D7: 0 | E7: T | F7: 0 | G7: 0 | H7: 4034.61
A8: 43165 | B8: 0 | C8: 0 | D8: 0 | E8: 0 | F8: 0 | G8: 0 | H8: 4034.62
A9: 43166 | B9: 0 | C9: 0 | D9: 0 | E9: 0 | F9: 0 | G9: 0 | H9: 4034.63
A10: 43167 | B10: 0 | C10: 0 | D10: 0 | E10: 0 | F10: 0 | G10: 0 | H10: 4034.64
A11: 43168 | B11: 0 | C11: 0 | D11: 0 | E11: 0.35 | F11: 0 | G11: 0 | H11: 4034.66
A12: 43169 | B12: 0 | C12: 0 | D12: 0 | E12: 0.01 | F12: 0 | G12: 0 | H12: 4034.67
A13: 43170 | B13: 0 | C13: 0 | D13: 0 | E13: T | F13: 0 | G13: 0 | H13: 4034.69
A14: 43171 | B14: 0 | C14: 0 | D14: 0 | E14: 0 | F14: 0 | G14: 0 | H14: 4034.71
A15: 43172 | B15: 0 | C15: 0 | D15: 0 | E15: 0.15 | F15: 0 | G15: 0 | H15: 4034.73
A16: 43173 | B16: 0 | C16: 0 | D16: 0 | E16: 0.29 | F16: 0 | G16: 0 | H16: 4034.75
A17: 43174 | B17: 0 | C17: 0 | D17: 19 | E17: 0.03 | F17: T | G17: 0 | H17: 4034.77
A18: 43175 | B18: 0 | C18: 0 | D18: 32 | E18: 0.03 | F18: T | G18: 0 | H18: 4034.78
A19: 43176 | B19: 0 | C19: 0 | D19: 28 | E19: 0.02 | F19: T | G19: 0 | H19: 4034.79
A20: 43177 | B20: 0 | C20: 0 | D20: 22 | E20: 0.01 | F20: 0 | G20: 0 | H20: 4034.81
A21: 43178 | B21: 0 | C21: 0 | D21: 21 | E21: 0.01 | F21: 0 | G21: 0 | H21: 4034.82
A22: 43179 | B22: 0 | C22: 0 | D22: 18 | E22: 0 | F22: 0 | G22: 0 | H22: 4034.82
A23: 43180 | B23: 0 | C23: 0 | D23: 17 | E23: 0.02 | F23: 0 | G23: 0 | H23: 4034.84
A24: 43181 | B24: 0 | C24: 0 | D24: 17 | E24: 1.07 | F24: 1 | G24: 0 | H24: 4034.9
A25: 43182 | B25: 0 | C25: 0 | D25: 17 | E25: T | F25: 0 | G25: 0 | H25: 4034.91
A26: 43183 | B26: 0 | C26: 0 | D26: 18 | E26: 0.07 | F26: 1 | G26: 0 | H26: 4034.93
A27: 43184 | B27: 0 | C27: 0 | D27: 21 | E27: 0.05 | F27: 0 | G27: 0 | H27: 4034.97
A28: 43185 | B28: 0 | C28: 0 | D28: 22 | E28: T | F28: 0 | G28: 0 | H28: 4035
A29: 43186 | B29: 0 | C29: 0 | D29: 18 | E29: 0 | F29: 0 | G29: 0 | H29: 4035.02
A30: 43187 | B30: 0 | C30: 0 | D30: 18 | E30: 0 | F30: 0 | G30: 0 | H30: 4035.04
A31: 43188 | B31: 0 | C31: 0 | D31: 18 | E31: 0 | F31: 0 | G31: 0 | H31: 4035.04
A32: 43189 | B32: 0 | C32: 0 | D32: 16 | E32: 0 | F32: 0 | G32: 0 | H32: 4035.06
A33: 43190 | B33: 0 | C33: 0 | D33: 15 | E33: 0 | F33: 0 | G33: 0 | H33: 4035.06
A34: Monthly Total | B34: =SUM(B3:B33) -> 0 | C34: =SUM(C3:C33) -> 0 | D34: =SUM(D3:D33) -> 337 | E34: =SUM(E3:E33) -> 2.32 | F34: =SUM(F3:F33) -> 5 | G34: =SUM(G3:G33) -> 0
A35: WY Total | B35: =SUM(B34+'Feb 2018'!B33) -> 979 | C35: =SUM(C34+'Feb 2018'!C33) -> 3165 | D35: =SUM(D34+'Feb 2018'!D33) -> 4197 | E35: =SUM(E34+'Feb 2018'!E33) -> 6.69 | F35: =SUM(F34+'Feb 2018'!F33) -> 13.5 | G35: =SUM(G34+'Feb 2018'!G33) -> 12412
A37: Acre Feet | B37: =SUM(B3:B33)*1.9835 -> 0 | C37: =SUM(C3:C33)*1.9835 -> 0 | D37: =SUM(D3:D33)*1.9835 -> 668.4395
A39: WY AF Total | B39: =SUM(B37+'Feb 2018'!B37) -> 1941.8465 | C39: =SUM(C37+'Feb 2018'!C37) -> 6277.7775 | D39: =SUM(D37+'Feb 2018'!D37) -> 8324.7495
G41: * COMPUTATIONAL PURPOSES ONLY! Do Not Enter Data in the Red Columns
A43: *This is computation purposes only for Station 48
A44: Sta 48
...

Sheet Feb 2018
A1: DATE | B1: STATION 48 | C1: ANDERSON-ROSE | D1: J CANAL | E1: TULE LAKE PRECIP | F1: TULE LAKE SNOW | G1: D PLANT | H1: TULE LAKE ELEV. | I1: CHANGES @ STATION 48
B2: (in CFS) | C2: (in CFS) | D2: (in CFS) | G2: (in AF)
A3: 43132 | B3: 0 | C3: 20 | D3: 0 | E3: 0.02 | F3: 0 | G3: 0 | H3: 4034.56
A4: 43133 | B4: 0 | C4: 20 | D4: 0 | E4: 0 | F4: 0 | G4: 0 | H4: 4034.56
A5: 43134 | B5: 0 | C5: 20 | D5: 0 | E5: 0 | F5: 0 | G5: 0 | H5: 4034.56
A6: 43135 | B6: 0 | C6: 20 | D6: 0 | E6: 0.01 | F6: 0 | G6: 0 | H6: 4034.56
A7: 43136 | B7: 0 | C7: 20 | D7: 0 | E7: 0 | F7: 0 | G7: 0 | H7: 4034.56
A8: 43137 | B8: 0 | C8: 20 | D8: 0 | E8: 0 | F8: 0 | G8: 0 | H8: 4034.57
A9: 43138 | B9: 0 | C9: 20 | D9: 0 | E9: 0 | F9: 0 | G9: 0 | H9: 4034.57
A10: 43139 | B10: 0 | C10: 20 | D10: 0 | E10: 0 | F10: 0 | G10: 0 | H10: 4034.58
A11: 43140 | B11: 0 | C11: 20 | D11: 0 | E11: 0 | F11: 0 | G11: 0 | H11: 4034.58
A12: 43141 | B12: 0 | C12: 20 | D12: 0 | E12: 0 | F12: 0 | G12: 0 | H12: 4034.58
A13: 43142 | B13: 0 | C13: 20 | D13: 0 | E13: T | F13: T | G13: 0 | H13: 4034.58
A14: 43143 | B14: 0 | C14: 20 | D14: 0 | E14: T | F14: T | G14: 0 | H14: 4034.57
A15: 43144 | B15: 0 | C15: 20 | D15: 0 | E15: 0 | F15: 0 | G15: 0 | H15: 4034.57
A16: 43145 | B16: 0 | C16: 20 | D16: 0 | E16: 0 | F16: 0 | G16: 0 | H16: 4034.57
A17: 43146 | B17: 0 | C17: 20 | D17: 0 | E17: 0 | F17: 0 | G17: 0 | H17: 4034.56
A18: 43147 | B18: 0 | C18: 20 | D18: 0 | E18: 0 | F18: 0 | G18: 0 | H18: 4034.56
A19: 43148 | B19: 0 | C19: 20 | D19: 0 | E19: T | F19: 0 | G19: 0 | H19: 4034.56
A20: 43149 | B20: 0 | C20: 20 | D20: 0 | E20: 0.02 | F20: T | G20: 0 | H20: 4034.55
A21: 43150 | B21: 0 | C21: 20 | D21: 0 | E21: 0.02 | F21: 1 | G21: 0 | H21: 4034.55
A22: 43151 | B22: 0 | C22: 20 | D22: 0 | E22: 0.01 | F22: 0 | G22: 0 | H22: 4034.55
A23: 43152 | B23: 0 | C23: 20 | D23: 0 | E23: 0 | F23: 0 | G23: 0 | H23: 4034.56
A24: 43153 | B24: 0 | C24: 20 | D24: 0 | E24: 0.07 | F24: 1 | G24: 0 | H24: 4034.56
A25: 43154 | B25: 0 | C25: 20 | D25: 0 | E25: 0 | F25: 0 | G25: 0 | H25: 4034.56
A26: 43155 | B26: 0 | C26: 20 | D26: 0 | E26: 0.05 | F26: T | G26: 0 | H26: 4034.57
A27: 43156 | B27: 0 | C27: 20 | D27: 0 | E27: 0.01 | F27: 0 | G27: 0 | H27: 4034.57
A28: 43157 | B28: 0 | C28: 20 | D28: 0 | E28: 0.12 | F28: 3 | G28: 0 | H28: 4034.57
A29: 43158 | B29: 0 | C29: 13 | D29: 0 | E29: T | F29: 0 | G29: 0 | H29: 4034.58
A30: 43159 | B30: 0 | C30: 0 | D30: 0 | E30: T | F30: 0 | G30: 0 | H30: 4034.58
A31: 43160
A32: Monthly Total | B32: =SUM(B3:B31) -> 0 | C32: =SUM(C3:C31) -> 533 | D32: =SUM(D3:D31) -> 0 | E32: =SUM(E3:E31) -> 0.33 | F32: =SUM(F3:F31) -> 5 | G32: =SUM(G3:G31) -> 0
A33: WY Total | B33: =SUM(B32+'Jan 2018'!B35) -> 979 | C33: =SUM(C32+'Jan 2018'!C35) -> 3165 | D33: =SUM(D32+'Jan 2018'!D35) -> 3860 | E33: =SUM(E32+'Jan 2018'!E35) -> 4.37 | F33: =SUM(F32+'Jan 2018'!F35) -> 8.5 | G33: =SUM(G32+'Jan 2018'!G35) -> 12412
A35: Acre Feet | B35: =SUM(B3:B31)*1.9835 -> 0 | C35: =SUM(C3:C31)*1.9835 -> 1057.2055 | D35: =SUM(D3:D31)*1.9835 -> 0
A37: WY AF Total | B37: =SUM(B35+'Jan 2018'!B39) -> 1941.8465 | C37: =SUM(C35+'Jan 2018'!C39) -> 6277.7775 | D37: =SUM(D35+'Jan 2018'!D39) -> 7656.31
G39: * COMPUTATIONAL PURPOSES ONLY! Do Not Enter Data in the Red Columns
A41: *This is computation purposes only for Station 48
A42: Sta 48
F43: =SUM(24-D43) -> 24 | G43: =SUM(C43+E43) -> 0 | H43: =SUM(C43/24*D43+G43/24*F43) -> 0
F44: =SUM(24-D44) -> 24 | G44: =SUM(C44+E44) -> 0 | H44: =SUM(C44/24*D44+G44/24*F44) -> 0
...

Sheet Jan 2018
A1: DATE | B1: STATION 48 | C1: ANDERSON-ROSE | D1: J CANAL | E1: TULE LAKE PRECIP | F1: TULE LAKE SNOW | G1: D PLANT | H1: TULE LAKE ELEV. | I1: CHANGES @ STATION 48
B2: (in CFS) | C2: (in CFS) | D2: (in CFS) | G2: (in AF)
A3: 43101 | B3: 0 | C3: 20 | D3: 0 | E3: 0.01 | F3: 0 | G3: 0 | H3: 4034.38
A4: 43102 | B4: 0 | C4: 20 | D4: 0 | E4: 0 | F4: 0 | G4: 0 | H4: 4034.4
A5: 43103 | B5: 0 | C5: 20 | D5: 0 | E5: 0 | F5: 0 | G5: 0 | H5: 4034.4
A6: 43104 | B6: 0 | C6: 20 | D6: 0 | E6: 0.03 | F6: 0 | G6: 0 | H6: 4034.4
A7: 43105 | B7: 0 | C7: 20 | D7: 0 | E7: 0 | F7: 0 | G7: 0 | H7: 4034.42
A8: 43106 | B8: 0 | C8: 20 | D8: 0 | E8: T | F8: 0 | G8: 0 | H8: 4034.42
A9: 43107 | B9: 0 | C9: 20 | D9: 0 | E9: 0.01 | F9: 0 | G9: 0 | H9: 4034.42
A10: 43108 | B10: 0 | C10: 20 | D10: 0 | E10: 0.04 | F10: 0 | G10: 0 | H10: 4034.42
A11: 43109 | B11: 0 | C11: 20 | D11: 0 | E11: 0.02 | F11: 0 | G11: 0 | H11: 4034.43
A12: 43110 | B12: 0 | C12: 20 | D12: 0 | E12: 0.05 | F12: 0.5 | G12: 0 | H12: 4034.43
A13: 43111 | B13: 0 | C13: 20 | D13: 0 | E13: 0 | F13: 0 | G13: 0 | H13: 4034.43
A14: 43112 | B14: 0 | C14: 20 | D14: 0 | E14: 0.01 | F14: 0 | G14: 0 | H14: 4034.43
A15: 43113 | B15: 0 | C15: 20 | D15: 0 | E15: 0 | F15: 0 | G15: 0 | H15: 4034.44
A16: 43114 | B16: 0 | C16: 20 | D16: 0 | E16: 0 | F16: 0 | G16: 0 | H16: 4034.44
A17: 43115 | B17: 0 | C17: 20 | D17: 0 | E17: 0 | F17: 0 | G17: 0 | H17: 4034.44
A18: 43116 | B18: 0 | C18: 20 | D18: 0 | E18: 0.01 | F18: 0 | G18: 0 | H18: 4034.44
A19: 43117 | B19: 0 | C19: 20 | D19: 0 | E19: 0.02 | F19: 0 | G19: 0 | H19: 4034.46
A20: 43118 | B20: 0 | C20: 20 | D20: 0 | E20: 0.44 | F20: 0 | G20: 0 | H20: 4034.46
A21: 43119 | B21: 0 | C21: 20 | D21: 0 | E21: 0.15 | F21: 0 | G21: 0 | H21: 4034.5
A22: 43120 | B22: 0 | C22: 20 | D22: 0 | E22: T | F22: 0 | G22: 0 | H22: 4034.5
A23: 43121 | B23: 0 | C23: 20 | D23: 0 | E23: 0 | F23: 0 | G23: 0 | H23: 4034.52
A24: 43122 | B24: 0 | C24: 20 | D24: 0 | E24: 0 | F24: 0 | G24: 0 | H24: 4034.52
A25: 43123 | B25: 0 | C25: 20 | D25: 0 | E25: T | F25: 0 | G25: 0 | H25: 4034.53
A26: 43124 | B26: 0 | C26: 20 | D26: 0 | E26: 0 | F26: 0 | G26: 0 | H26: 4034.53
A27: 43125 | B27: 0 | C27: 20 | D27: 0 | E27: 0.01 | F27: 0 | G27: 0 | H27: 4034.53
A28: 43126 | B28: 0 | C28: 20 | D28: 0 | E28: T | F28: T | G28: 0 | H28: 4034.54
A29: 43127 | B29: 0 | C29: 20 | D29: 0 | E29: 0.04 | F29: 0.5 | G29: 0 | H29: 4034.54
A30: 43128 | B30: 0 | C30: 20 | D30: 0 | E30: 0 | F30: 0 | G30: 0 | H30: 4034.55
A31: 43129 | B31: 0 | C31: 20 | D31: 0 | E31: 0 | F31: 0 | G31: 0 | H31: 4034.56
A32: 43130 | B32: 0 | C32: 20 | D32: 0 | E32: 0 | F32: 0 | G32: 0 | H32: 4034.56
A33: 43131 | B33: 0 | C33: 20 | D33: 0 | E33: 0 | F33: 0 | G33: 0 | H33: 4034.56
A34: Monthly Total | B34: =SUM(B3:B33) -> 0 | C34: =SUM(C3:C33) -> 620 | D34: =SUM(D3:D33) -> 0 | E34: =SUM(E3:E33) -> 0.84 | F34: =SUM(F3:F33) -> 1 | G34: =SUM(G3:G33) -> 0
A35: WY Total | B35: =SUM(B34+'Dec 2017'!B35) -> 979 | C35: =SUM(C34+'Dec 2017'!C35) -> 2632 | D35: =SUM(D34+'Dec 2017'!D35) -> 3860 | E35: =SUM(E34+'Dec 2017'!E35) -> 4.04 | F35: =SUM(F34+'Dec 2017'!F35) -> 3.5 | G35: =SUM(G34+'Dec 2017'!G35) -> 12412
A37: Acre Feet | B37: =SUM(B3:B33)*1.9835 -> 0 | C37: =SUM(C3:C33)*1.9835 -> 1229.77 | D37: =SUM(D3:D33)*1.9835 -> 0
A39: WY AF Total | B39: =SUM(B37+'Dec 2017'!B39) -> 1941.8465 | C39: =SUM(C37+'Dec 2017'!C39) -> 5220.572 | D39: =SUM(D37+'Dec 2017'!D39) -> 7656.31
G41: * COMPUTATIONAL PURPOSES ONLY! Do Not Enter Data in the Red Columns
A43: *This is computation purposes only for Station 48
A44: Sta 48
...

Sheet Dec 2017
A1: DATE | B1: STATION 48 | C1: ANDERSON-ROSE | D1: J CANAL | E1: TULE LAKE PRECIP | F1: TULE LAKE SNOW | G1: D PLANT | H1: TULE LAKE ELEV. | I1: CHANGES @ STATION 48
B2: (in CFS) | C2: (in CFS) | D2: (in CFS) | G2: (in AF)
A3: 43070 | B3: 0 | C3: 20 | D3: 0 | E3: 0 | F3: 0 | G3: 0 | H3: 4034.37
A4: 43071 | B4: 0 | C4: 20 | D4: 0 | E4: 0.08 | F4: 0 | G4: 0 | H4: 4034.37
A5: 43072 | B5: 0 | C5: 20 | D5: 0 | E5: 0.09 | F5: 0.5 | G5: 0 | H5: 4034.37
A6: 43073 | B6: 0 | C6: 30 | D6: 0 | E6: 0 | F6: 0 | G6: 0 | H6: 4034.37
A7: 43074 | B7: 0 | C7: 40 | D7: 0 | E7: 0 | F7: 0 | G7: 0 | H7: 4034.38
A8: 43075 | B8: 0 | C8: 20 | D8: 0 | E8: 0.01 | F8: 0 | G8: 0 | H8: 4034.38
A9: 43076 | B9: 0 | C9: 20 | D9: 0 | E9: 0 | F9: 0 | G9: 0 | H9: 4034.38
A10: 43077 | B10: 0 | C10: 20 | D10: 0 | E10: 0 | F10: 0 | G10: 0 | H10: 4034.38
A11: 43078 | B11: 0 | C11: 20 | D11: 0 | E11: 0.01 | F11: 0 | G11: 0 | H11: 4034.38
A12: 43079 | B12: 0 | C12: 20 | D12: 0 | E12: 0 | F12: 0 | G12: 0 | H12: 4034.38
A13: 43080 | B13: 0 | C13: 20 | D13: 0 | E13: T | F13: 0 | G13: 0 | H13: 4034.38
A14: 43081 | B14: 0 | C14: 20 | D14: 0 | E14: 0 | F14: 0 | G14: 0 | H14: 4034.38
A15: 43082 | B15: 0 | C15: 20 | D15: 0 | E15: 0 | F15: 0 | G15: 0 | H15: 4034.38
A16: 43083 | B16: 0 | C16: 20 | D16: 0 | E16: 0 | F16: 0 | G16: 0 | H16: 4034.38
A17: 43084 | B17: 0 | C17: 20 | D17: 0 | E17: 0 | F17: 0 | G17: 0 | H17: 4034.38
A18: 43085 | B18: 0 | C18: 20 | D18: 0 | E18: T | F18: 0 | G18: 0 | H18: 4034.38
A19: 43086 | B19: 0 | C19: 20 | D19: 0 | E19: 0 | F19: 0 | G19: 0 | H19: 4034.38
A20: 43087 | B20: 0 | C20: 20 | D20: 0 | E20: 0 | F20: 0 | G20: 0 | H20: 4034.36
A21: 43088 | B21: 0 | C21: 20 | D21: 0 | E21: 0 | F21: 0 | G21: 0 | H21: 4034.36
A22: 43089 | B22: 0 | C22: 20 | D22: 0 | E22: 0.24 | F22: 1 | G22: 0 | H22: 4034.36
A23: 43090 | B23: 0 | C23: 20 | D23: 0 | E23: 0.01 | F23: 0 | G23: 0 | H23: 4034.36
A24: 43091 | B24: 0 | C24: 20 | D24: 0 | E24: 0 | F24: 0 | G24: 0 | H24: 4034.36
A25: 43092 | B25: 0 | C25: 20 | D25: 0 | E25: 0 | F25: 0 | G25: 0 | H25: 4034.36
A26: 43093 | B26: 0 | C26: 20 | D26: 0 | E26: 0 | F26: 0 | G26: 0 | H26: 4034.36
A27: 43094 | B27: 0 | C27: 20 | D27: 0 | E27: 0 | F27: 0 | G27: 0 | H27: 4034.36
A28: 43095 | B28: 0 | C28: 20 | D28: 0 | E28: 0.01 | F28: 0 | G28: 0 | H28: 4034.36
A29: 43096 | B29: 0 | C29: 20 | D29: 0 | E29: 0.01 | F29: 0 | G29: 0 | H29: 4034.36
A30: 43097 | B30: 0 | C30: 20 | D30: 0 | E30: 0.02 | F30: 0 | G30: 0 | H30: 4034.36
A31: 43098 | B31: 0 | C31: 20 | D31: 0 | E31: 0.01 | F31: 0 | G31: 0 | H31: 4034.36
A32: 43099 | B32: 0 | C32: 20 | D32: 0 | E32: T | F32: 0 | G32: 0 | H32: 4034.37
A33: 43100 | B33: 0 | C33: 20 | D33: 0 | E33: 0 | F33: 0 | G33: 0 | H33: 4034.38
A34: Monthly Total | B34: =SUM(B3:B33) -> 0 | C34: =SUM(C3:C33) -> 650 | D34: =SUM(D3:D33) -> 0 | E34: =SUM(E3:E33) -> 0.49 | F34: =SUM(F3:F33) -> 1.5 | G34: =SUM(G3:G33) -> 0
A35: WY Total | B35: =SUM(B34+'Nov 2017'!B34) -> 979 | C35: =SUM(C34+'Nov 2017'!C34) -> 2012 | D35: =SUM(D34+'Nov 2017'!D34) -> 3860 | E35: =SUM(E34+'Nov 2017'!E34) -> 3.2 | F35: =SUM(F34+'Nov 2017'!F34) -> 2.5 | G35: =SUM(G34+'Nov 2017'!G34) -> 12412
A37: Acre Feet | B37: =SUM(B3:B33)*1.9835 -> 0 | C37: =SUM(C3:C33)*1.9835 -> 1289.275 | D37: =SUM(D3:D33)*1.9835 -> 0
A39: WY AF Total | B39: =SUM('Nov 2017'!B38+B37) -> 1941.8465 | C39: =SUM('Nov 2017'!C38+C37) -> 3990.802 | D39: =SUM('Nov 2017'!D38+D37) -> 7656.31
G41: * COMPUTATIONAL PURPOSES ONLY! Do Not Enter Data in the Red Columns
A43: *This is computation purposes only for Station 48
A44: Sta 48
...

Sheet Nov 2017
A1: DATE | B1: STATION 48 | C1: ANDERSON-ROSE | D1: J CANAL | E1: TULE LAKE PRECIP | F1: TULE LAKE SNOW | G1: D PLANT | H1: TULE LAKE ELEV. | I1: CHANGES @ STATION 48
B2: (in CFS) | C2: (in CFS) | D2: (in CFS) | G2: (in AF)
A3: 43040 | B3: 66 | C3: 0 | D3: 78 | E3: 0 | F3: 0 | G3: 318 | H3: 4034.44 | I3: * 15:00 75/50
A4: 43041 | B4: 50 | C4: 0 | D4: 63 | E4: 0 | F4: 0 | G4: 217 | H4: 4034.44
A5: 43042 | B5: 27 | C5: 0 | D5: 62 | E5: 0.22 | F5: 0 | G5: 153 | H5: 4034.42 | I5: * 13:00 50/0
A6: 43043 | B6: 8 | C6: 0 | D6: 53 | E6: 0.34 | F6: 0.5 | G6: 100 | H6: 4034.42 | I6: * 16:30 0/25
A7: 43044 | B7: 28 | C7: 0 | D7: 53 | E7: 0.02 | F7: 0 | G7: 159 | H7: 4034.42 | I7: * 21:00 25/50
A8: 43045 | B8: 40 | C8: 0 | D8: 56 | E8: 0.1 | F8: 0 | G8: 159 | H8: 4034.42 | I8: * 14:00 50/25
A9: 43046 | B9: 25 | C9: 0 | D9: 53 | E9: T | F9: 0 | G9: 256 | H9: 4034.42 | I9: * 2nd unit D plant on 08:48
A10: 43047 | B10: 25 | C10: 0 | D10: 51 | E10: 0 | F10: 0 | G10: 222 | H10: 4034.4 | I10: D plant 1 unit off 13:15
A11: 43048 | B11: 25 | C11: 0 | D11: 48 | E11: 0.31 | F11: 0 | G11: 159 | H11: 4034.4
A12: 43049 | B12: 25 | C12: 0 | D12: 48 | E12: 0.07 | F12: 0 | G12: 159 | H12: 4034.4
A13: 43050 | B13: 25 | C13: 0 | D13: 48 | E13: 0.02 | F13: 0 | G13: 159 | H13: 4034.4
A14: 43051 | B14: 25 | C14: 0 | D14: 48 | E14: 0 | F14: 0 | G14: 159 | H14: 4034.38
A15: 43052 | B15: 9 | C15: 0 | D15: 25 | E15: 0 | F15: 0 | G15: 172 | H15: 4034.36 | I15: * 09:00 25/0 * 2nd unit on D plant 08:42 off at 10:56
A16: 43053 | B16: 0 | C16: 12 | D16: 10 | E16: 0 | F16: 0 | G16: 159 | H16: 4034.36
A17: 43054 | B17: 0 | C17: 20 | D17: 0 | E17: 0.01 | F17: 0 | G17: 159 | H17: 4034.36
A18: 43055 | B18: 0 | C18: 33 | D18: 0 | E18: 0.03 | F18: 0 | G18: 159 | H18: 4034.34
A19: 43056 | B19: 0 | C19: 40 | D19: 0 | E19: 0.02 | F19: 0 | G19: 159 | H19: 4034.32
A20: 43057 | B20: 0 | C20: 40 | D20: 0 | E20: 0 | F20: 0 | G20: 159 | H20: 4034.32
A21: 43058 | B21: 0 | C21: 40 | D21: 0 | E21: 0.01 | F21: 0 | G21: 159 | H21: 4034.3
A22: 43059 | B22: 0 | C22: 40 | D22: 0 | E22: 0.2 | F22: 0 | G22: 159 | H22: 4034.3
A23: 43060 | B23: 0 | C23: 40 | D23: 0 | E23: 0.06 | F23: 0 | G23: 159 | H23: 4034.3
A24: 43061 | B24: 0 | C24: 40 | D24: 0 | E24: 0.01 | F24: 0 | G24: 60 | H24: 4034.3
A25: 43062 | B25: 0 | C25: 40 | D25: 0 | E25: 0 | F25: 0 | G25: 0 | H25: 4034.32
A26: 43063 | B26: 0 | C26: 40 | D26: 0 | E26: 0.14 | F26: 0 | G26: 0 | H26: 4034.32
A27: 43064 | B27: 0 | C27: 40 | D27: 0 | E27: T | F27: 0 | G27: 0 | H27: 4034.34
A28: 43065 | B28: 0 | C28: 40 | D28: 0 | E28: 0.08 | F28: 0 | G28: 0 | H28: 4034.34
A29: 43066 | B29: 0 | C29: 20 | D29: 0 | E29: 0.14 | F29: 0 | G29: 0 | H29: 4034.36
A30: 43067 | B30: 0 | C30: 20 | D30: 0 | E30: 0.02 | F30: 0 | G30: 0 | H30: 4034.37
A31: 43068 | B31: 0 | C31: 20 | D31: 0 | E31: 0 | F31: 0 | G31: 0 | H31: 4034.37
A32: 43069 | B32: 0 | C32: 20 | D32: 0 | E32: 0 | F32: 0 | G32: 0 | H32: 4034.37
A33: Monthly Total | B33: =SUM(B3:B32) -> 378 | C33: =SUM(C3:C32) -> 545 | D33: =SUM(D3:D32) -> 696 | E33: =SUM(E3:E32) -> 1.8 | F33: =SUM(F3:F32) -> 0.5 | G33: =SUM(G3:G32) -> 3724
A34: WY Total | B34: =SUM(B33+'Oct 2017'!B35) -> 979 | C34: =SUM(C33+'Oct 2017'!C35) -> 1362 | D34: =SUM(D33+'Oct 2017'!D35) -> 3860 | E34: =SUM(E33+'Oct 2017'!E35) -> 2.71 | F34: =SUM(F33+'Oct 2017'!F35) -> 1 | G34: =SUM(G33+'Oct 2017'!G35) -> 12412
A36: Acre Feet | B36: =SUM(B3:B32)*1.9835 -> 749.763 | C36: =SUM(C3:C32)*1.9835 -> 1081.0075 | D36: =SUM(D3:D32)*1.9835 -> 1380.516
A38: WY AF Total | B38: =SUM('Oct 2017'!B39+B36) -> 1941.8465 | C38: =SUM('Oct 2017'!C39+C36) -> 2701.527 | D38: =SUM('Oct 2017'!D39+D36) -> 7656.31
G40: * COMPUTATIONAL PURPOSES ONLY! Do Not Enter Data in the Red Columns
A42: *This is computation purposes only for Station 48
A43: Sta 48
F44: =SUM(24-D44) -> 24 | G44: =SUM(C44+E44) -> 0 | H44: =SUM(C44/24*D44+G44/24*F44) -> 0
...

Sheet Oct 2017
A1: DATE | B1: STATION 48 | C1: ANDERSON-ROSE | D1: J CANAL | E1: TULE LAKE PRECIP | F1: TULE LAKE SNOW | G1: D PLANT | H1: TULE LAKE ELEV. | I1: CHANGES @ STATION 48
B2: (in CFS) | C2: (in CFS) | D2: (in CFS)
A3: 43009 | B3: 0 | C3: 83 | D3: 94 | E3: 0 | F3: 0 | G3: 318 | H3: 4034.8
A4: 43010 | B4: 0 | C4: 105 | D4: 104 | E4: 0 | F4: 0 | G4: 318 | H4: 4034.8
A5: 43011 | B5: 0 | C5: 78 | D5: 109 | E5: 0 | F5: 0 | G5: 318 | H5: 4034.8
A6: 43012 | B6: 0 | C6: 62 | D6: 130 | E6: 0 | F6: 0 | G6: 318 | H6: 4034.79
A7: 43013 | B7: 0 | C7: 68 | D7: 134 | E7: 0 | F7: 0 | G7: 318 | H7: 4034.79
A8: 43014 | B8: 0 | C8: 0 | D8: 141 | E8: 0 | F8: 0 | G8: 318 | H8: 4034.78
A9: 43015 | B9: 0 | C9: 0 | D9: 147 | E9: 0 | F9: 0 | G9: 318 | H9: 4034.77
A10: 43016 | B10: 0 | C10: 0 | D10: 151 | E10: 0 | F10: 0 | G10: 318 | H10: 4034.75
A11: 43017 | B11: 0 | C11: 21 | D11: 149 | E11: 0 | F11: 0 | G11: 318 | H11: 4034.73
A12: 43018 | B12: 0 | C12: 35 | D12: 133 | E12: 0 | F12: 0 | G12: 318 | H12: 4034.7
A13: 43019 | B13: 0 | C13: 63 | D13: 122 | E13: 0 | F13: 0 | G13: 318 | H13: 4034.68 | I13: * 1 unit D off 2:50 PM: Restart 10/12 am
A14: 43020 | B14: 0 | C14: 57 | D14: 114 | E14: 0 | F14: 0 | G14: 223 | H14: 4034.66
A15: 43021 | B15: 0 | C15: 62 | D15: 98 | E15: 0 | F15: 0 | G15: 160 | H15: 4034.66
A16: 43022 | B16: 0 | C16: 66 | D16: 85 | E16: 0 | F16: 0 | G16: 160 | H16: 4034.66
A17: 43023 | B17: 0 | C17: 56 | D17: 92 | E17: 0 | F17: 0 | G17: 160 | H17: 4034.66
A18: 43024 | B18: 0 | C18: 23 | D18: 108 | E18: 0 | F18: 0 | G18: 262 | H18: 4034.68 | I18: * 2nd Unit D ON 08:30
A19: 43025 | B19: 31 | C19: 0 | D19: 114 | E19: 0 | F19: 0 | G19: 318 | H19: 4034.68 | I19: * 09:00 0/50
A20: 43026 | B20: 66 | C20: 0 | D20: 116 | E20: 0 | F20: 0 | G20: 318 | H20: 4034.68 | I20: * 0900 50/75
A21: 43027 | B21: 75 | C21: 0 | D21: 105 | E21: 0 | F21: 0 | G21: 305 | H21: 4034.68
A22: 43028 | B22: 75 | C22: 0 | D22: 99 | E22: 0.74 | F22: 0.25 | G22: 160 | H22: 4034.68
A23: 43029 | B23: 45 | C23: 10 | D23: 75 | E23: 0.15 | F23: 0.25 | G23: 160 | H23: 4034.68 | I23: * 0900 75/50 * 1030 50/25
A24: 43030 | B24: 25 | C24: 20 | D24: 65 | E24: 0.01 | F24: 0 | G24: 160 | H24: 4034.68
A25: 43031 | B25: 25 | C25: 8 | D25: 100 | E25: 0.01 | F25: 0 | G25: 260 | H25: 4034.66
A26: 43032 | B26: 25 | C26: 0 | D26: 95 | E26: 0 | F26: 0 | G26: 318 | H26: 4034.64
A27: 43033 | B27: 25 | C27: 0 | D27: 85 | E27: 0 | F27: 0 | G27: 318 | H27: 4034.64
A28: 43034 | B28: 25 | C28: 0 | D28: 82 | E28: 0 | F28: 0 | G28: 318 | H28: 4034.62
A29: 43035 | B29: 25 | C29: 0 | D29: 79 | E29: 0 | F29: 0 | G29: 318 | H29: 4034.6
A30: 43036 | B30: 41 | C30: 0 | D30: 69 | E30: 0 | F30: 0 | G30: 318 | H30: 4034.56 | I30: * 08:30 25/50
A31: 43037 | B31: 38 | C31: 0 | D31: 50 | E31: 0 | F31: 0 | G31: 318 | H31: 4034.54 | I31: * 12:30 50/25
A32: 43038 | B32: 25 | C32: 0 | D32: 55 | E32: 0 | F32: 0 | G32: 318 | H32: 4034.5
A33: 43039 | B33: 55 | C33: 0 | D33: 64 | E33: 0 | F33: 0 | G33: 318 | H33: 4034.48 | I33: * 08:00 25/75
A34: Monthly Total | B34: =SUM(B3:B33) -> 601 | C34: =SUM(C3:C33) -> 817 | D34: =SUM(D3:D33) -> 3164 | E34: =SUM(E3:E33) -> 0.91 | F34: =SUM(F3:F33) -> 0.5 | G34: =SUM(G3:G33) -> 8688
A35: WY Total | B35: =SUM(B34+'Oct 2017'!B36) -> 601 | C35: =SUM(C34+'Oct 2017'!C36) -> 817 | D35: =SUM(D34+'Oct 2017'!D36) -> 3164 | E35: =SUM(E34+'Oct 2017'!E36) -> 0.91 | F35: =SUM(F34+'Oct 2017'!F36) -> 0.5 | G35: =SUM(G34+'Oct 2017'!G36) -> 8688
A37: Acre Feet | B37: =SUM(B3:B33)*1.9835 -> 1192.0835 | C37: =SUM(C3:C33)*1.9835 -> 1620.5195 | D37: =SUM(D3:D33)*1.9835 -> 6275.794
A39: WY AF Total | B39: =SUM('Oct 2017'!B40+B37) -> 1192.0835 | C39: =SUM('Oct 2017'!C40+C37) -> 1620.5195 | D39: =SUM('Oct 2017'!D40+D37) -> 6275.794
G41: * COMPUTATIONAL PURPOSES ONLY! Do Not Enter Data in the Red Columns
A43: *This is computation purposes only for Station 48
A44: Sta 48
...
