Workbook

Sheet Sep 2022
A1: DATE | B1: LRDC | C1: STATION 48 | D1: ANDERSON-ROSE | E1: J CANAL | F1: TULE LAKE PRECIP | G1: TULE LAKE SNOW | H1: D PLANT | I1: TULE LAKE ELEV. | J1: CHANGES @ STATION 48
B2: (in CFS) | C2: (in CFS) | D2: (in CFS) | E2: (in CFS) | H2: (in AF)
A3: 44805 | B3: 0 | C3: 16 | D3: 0 | E3: 3 | F3: 0 | G3: 0 | H3: 0 | I3: -
A4: =A3+1 -> 44806 | B4: 0 | C4: 18 | D4: 0 | E4: 8 | F4: 0 | G4: 0 | H4: 0 | I4: - | J4: * 10:00 15/20
A5: =A4+1 -> 44807 | B5: 0 | C5: 20 | D5: 0 | E5: 12 | F5: 0 | G5: 0 | H5: 0 | I5: - | J5: * 08:30 17/22
A6: =A5+1 -> 44808 | B6: 0 | C6: 21 | D6: 0 | E6: 0 | F6: 0 | G6: 0 | H6: 0 | I6: -
A7: =A6+1 -> 44809 | B7: 0 | C7: 20 | D7: 0 | E7: 12 | F7: 0 | G7: 0 | H7: 0 | I7: -
A8: =A7+1 -> 44810 | B8: 0 | C8: 19 | D8: 0 | E8: 25 | F8: 0 | G8: 0 | H8: 0 | I8: -
A9: =A8+1 -> 44811 | B9: 0 | C9: 17 | D9: 0 | E9: 15 | F9: 0 | G9: 0 | H9: 0 | I9: -
A10: =A9+1 -> 44812 | B10: 0 | C10: 16 | D10: 0 | E10: 25 | F10: 0 | G10: 0 | H10: 0 | I10: -
A11: =A10+1 -> 44813 | B11: 0 | C11: 14 | D11: 0 | E11: 28 | F11: 0 | G11: 0 | H11: 0 | I11: -
A12: =A11+1 -> 44814 | B12: 0 | C12: 12 | D12: 0 | E12: 41 | F12: 0 | G12: 0 | H12: 0 | I12: -
A13: =A12+1 -> 44815 | B13: 0 | C13: 10 | D13: 0 | E13: 30 | F13: 0 | G13: 0 | H13: 0 | I13: -
A14: =A13+1 -> 44816 | B14: 0 | C14: 7 | D14: 0 | E14: 19 | F14: 0.02 | G14: 0 | H14: 0 | I14: -
A15: =A14+1 -> 44817 | B15: 0 | C15: 0 | D15: 0 | E15: 17 | F15: 0.13 | G15: 0 | H15: 0 | I15: - | J15: LRDC Below Sill Sta 48 Closed
A16: =A15+1 -> 44818 | B16: 0 | C16: 0 | D16: 0 | E16: 13 | F16: 0 | G16: 0 | H16: 0 | I16: -
A17: =A16+1 -> 44819 | B17: 0 | C17: 0 | D17: 0 | E17: 1 | F17: 0 | G17: 0 | H17: 0 | I17: -
A18: =A17+1 -> 44820 | B18: 0 | C18: 0 | D18: 0 | E18: 0 | F18: 0 | G18: 0 | H18: 0 | I18: -
A19: =A18+1 -> 44821 | B19: 0 | C19: 0 | D19: 0 | E19: 1 | F19: 0 | G19: 0 | H19: 0 | I19: -
A20: =A19+1 -> 44822 | B20: 0 | C20: 0 | D20: 0 | E20: 35 | F20: 0 | G20: 0 | H20: 0 | I20: -
A21: =A20+1 -> 44823 | B21: 0 | C21: 0 | D21: 0 | E21: 18 | F21: 0 | G21: 0 | H21: 0 | I21: -
A22: =A21+1 -> 44824 | B22: 0 | C22: 0 | D22: 0 | E22: 16 | F22: 0.73 | G22: 0 | H22: 0 | I22: -
A23: =A22+1 -> 44825 | B23: 0 | C23: 0 | D23: 0 | E23: 15 | F23: 0.17 | G23: 0 | H23: 0 | I23: -
A24: =A23+1 -> 44826 | B24: 0 | C24: 0 | D24: 0 | E24: 11 | F24: 0 | G24: 0 | H24: 0 | I24: -
A25: =A24+1 -> 44827 | B25: 0 | C25: 0 | D25: 0 | E25: 8 | F25: 0 | G25: 0 | H25: 0 | I25: -
A26: =A25+1 -> 44828 | B26: 0 | C26: 0 | D26: 0 | E26: 10 | F26: 0 | G26: 0 | H26: 0 | I26: -
A27: =A26+1 -> 44829 | B27: 0 | C27: 0 | D27: 0 | E27: 15 | F27: 0 | G27: 0 | H27: 0 | I27: -
... A32: =A31+1 -> 44834 | B32: 0 | C32: 0 | D32: 0 | E32: 26 | F32: 0 | G32: 0 | H32: 0 | I32: -
A33: Monthly Total | B33: =SUM(B3:B32) -> 0 | C33: =SUM(C3:C32) -> 190 | D33: =SUM(D3:D32) -> 0 | E33: =SUM(E3:E32) -> 496 | F33: =SUM(F3:F32) -> 1.05 | G33: =SUM(G3:G32) -> 0 | H33: =SUM(H3:H32) -> 0
A34: WY Total | B34: =SUM(B33+'Aug 2022'!B35) -> 8698 | C34: =SUM(C33+'Aug 2022'!C35) -> 17367 | D34: =SUM(D33+'Aug 2022'!D35) -> 0 | E34: =SUM(E33+'Aug 2022'!E35) -> 17773 | F34: =SUM(F33+'Aug 2022'!F35) -> 8.21 | G34: =SUM(G33+'Aug 2022'!G35) -> 13.55 | H34: =SUM(H33+'Aug 2022'!H35) -> 0
A36: Acre Feet | B36: =SUM(B3:B32)*1.9835 -> 0 | C36: =SUM(C3:C32)*1.9835 -> 376.865 | D36: =SUM(D3:D32)*1.9835 -> 0 | E36: =SUM(E3:E32)*1.9835 -> 983.816
A38: WY AF Total | B38: =SUM(B36+'Aug 2022'!B39) -> 18908.705 | C38: =SUM(C36+'Aug 2022'!C39) -> 36417.06 | D38: =SUM(D36+'Aug 2022'!D39) -> 0 | E38: =SUM(E36+'Aug 2022'!E39) -> 37991.959
H40: * COMPUTATIONAL PURPOSES ONLY! Do Not Enter Data in the Red Columns
A42: *This is computation purposes only for Station 48
A43: Sta 48
G44: =SUM(24-E44) -> 24 | H44: =SUM(D44+F44) -> 0 | I44: =SUM(D44/24*E44+H44/24*G44) -> 0
G45: =SUM(24-E45) -> 24 | H45: =SUM(D45+F45) -> 0 | I45: =SUM(D45/24*E45+H45/24*G45) -> 0
G46: =SUM(24-E46) -> 24 | H46: =SUM(D46+F46) -> 0 | I46: =SUM(D46/24*E46+H46/24*G46) -> 0
G47: =SUM(24-E47) -> 24 | H47: =SUM(D47+F47) -> 0 | I47: =SUM(D47/24*E47+H47/24*G47) -> 0
G48: =SUM(24-E48) -> 24 | H48: =SUM(D48+F48) -> 0 | I48: =SUM(D48/24*E48+H48/24*G48) -> 0
...

Sheet Aug 2022
A1: DATE | B1: LRDC | C1: STATION 48 | D1: ANDERSON-ROSE | E1: J CANAL | F1: TULE LAKE PRECIP | G1: TULE LAKE SNOW | H1: D PLANT | I1: TULE LAKE ELEV. | J1: CHANGES @ STATION 48
B2: (in CFS) | C2: (in CFS) | D2: (in CFS) | E2: (in CFS) | H2: (in AF)
A3: 44774 | B3: 11 | C3: 200 | D3: 0 | E3: 184 | F3: 0 | G3: 0 | H3: 0 | I3: -
A4: =A3+1 -> 44775 | B4: 15 | C4: 200 | D4: 0 | E4: 201 | F4: 0.03 | G4: 0 | H4: 0 | I4: -
A5: =A4+1 -> 44776 | B5: 14 | C5: 200 | D5: 0 | E5: 197 | F5: 0.1 | G5: 0 | H5: 0 | I5: -
A6: =A5+1 -> 44777 | B6: 5 | C6: 175 | D6: 0 | E6: 154 | F6: 0 | G6: 0 | H6: 0 | I6: - | J6: *12:00 200/150
A7: =A6+1 -> 44778 | B7: 7 | C7: 150 | D7: 0 | E7: 118 | F7: 0.06 | G7: 0 | H7: 0 | I7: -
A8: =A7+1 -> 44779 | B8: 4 | C8: 150 | D8: 0 | E8: 118 | F8: 0 | G8: 0 | H8: 0 | I8: -
A9: =A8+1 -> 44780 | B9: 11 | C9: 150 | D9: 0 | E9: 113 | F9: 0 | G9: 0 | H9: 0 | I9: -
A10: =A9+1 -> 44781 | B10: 15 | C10: 150 | D10: 0 | E10: 100 | F10: 0 | G10: 0 | H10: 0 | I10: -
A11: =A10+1 -> 44782 | B11: 14 | C11: 150 | D11: 0 | E11: 108 | F11: 0.06 | G11: 0 | H11: 0 | I11: -
A12: =A11+1 -> 44783 | B12: 1 | C12: 150 | D12: 0 | E12: 110 | F12: 0 | G12: 0 | H12: 0 | I12: -
A13: =A12+1 -> 44784 | B13: 9 | C13: 150 | D13: 0 | E13: 109 | F13: 0 | G13: 0 | H13: 0 | I13: -
A14: =A13+1 -> 44785 | B14: 4 | C14: 179 | D14: 0 | E14: 122 | F14: 0 | G14: 0 | H14: 0 | I14: - | J14: * 18:30 150/250
A15: =A14+1 -> 44786 | B15: 3 | C15: 250 | D15: 0 | E15: 107 | F15: 0 | G15: 0 | H15: 0 | I15: -
A16: =A15+1 -> 44787 | B16: 12 | C16: 232 | D16: 0 | E16: 126 | F16: 0 | G16: 0 | H16: 0 | I16: - | J16: * 22:00 250/30
A17: =A16+1 -> 44788 | B17: 6 | C17: 32 | D17: 0 | E17: 138 | F17: 0 | G17: 0 | H17: 0 | I17: - | J17: * 07:30 30/0 * 18:30 0/100
A18: =A17+1 -> 44789 | B18: 8 | C18: 100 | D18: 0 | E18: 137 | F18: 0 | G18: 0 | H18: 0 | I18: -
A19: =A18+1 -> 44790 | B19: 9 | C19: 100 | D19: 0 | E19: 68 | F19: T | G19: 0 | H19: 0 | I19: -
A20: =A19+1 -> 44791 | B20: 7 | C20: 100 | D20: 0 | E20: 41 | F20: 0.05 | G20: 0 | H20: 0 | I20: -
A21: =A20+1 -> 44792 | B21: 3 | C21: 77 | D21: 0 | E21: 30 | F21: 0 | G21: 0 | H21: 0 | I21: - | J21: * 16:30 100/25
A22: =A21+1 -> 44793 | B22: 3 | C22: 25 | D22: 0 | E22: 31 | F22: 0 | G22: 0 | H22: 0 | I22: -
A23: =A22+1 -> 44794 | B23: 4 | C23: 25 | D23: 0 | E23: 16 | F23: 0 | G23: 0 | H23: 0 | I23: -
A24: =A23+1 -> 44795 | B24: 5 | C24: 25 | D24: 0 | E24: 9 | F24: 0 | G24: 0 | H24: 0 | I24: -
A25: =A24+1 -> 44796 | B25: 5 | C25: 25 | D25: 0 | E25: 8 | F25: 0 | G25: 0 | H25: 0 | I25: -
A26: =A25+1 -> 44797 | B26: 17 | C26: 24 | D26: 0 | E26: 7 | F26: 0 | G26: 0 | H26: 0 | I26: -
A27: =A26+1 -> 44798 | B27: 2 | C27: 23 | D27: 0 | E27: 7 | F27: 0 | G27: 0 | H27: 0 | I27: -
A28: =A27+1 -> 44799 | B28: 0 | C28: 22 | D28: 0 | E28: 2 | F28: 0 | G28: 0 | H28: 0 | I28: -
A29: =A28+1 -> 44800 | B29: 0 | C29: 21 | D29: 0 | E29: 13 | F29: 0 | G29: 0 | H29: 0 | I29: -
A30: =A29+1 -> 44801 | B30: 0 | C30: 20 | D30: 0 | E30: 11 | F30: 0 | G30: 0 | H30: 0 | I30: -
A31: =A30+1 -> 44802 | B31: 0 | C31: 19 | D31: 0 | E31: 21 | F31: 0 | G31: 0 | H31: 0 | I31: -
A32: =A31+1 -> 44803 | B32: 0 | C32: 18 | D32: 0 | E32: 22 | F32: 0 | G32: 0 | H32: 0 | I32: -
A33: =A32+1 -> 44804 | B33: 0 | C33: 17 | D33: 0 | E33: 9 | F33: 0 | G33: 0 | H33: 0 | I33: -
A34: Monthly Total | B34: =SUM(B3:B33) -> 194 | C34: =SUM(C3:C33) -> 3159 | D34: =SUM(D3:D33) -> 0 | E34: =SUM(E3:E33) -> 2437 | F34: =SUM(F3:F33) -> 0.3 | G34: =SUM(G3:G33) -> 0 | H34: =SUM(H3:H33) -> 0
A35: WY Total | B35: =SUM(B34+'Jul 2022'!B35) -> 8698 | C35: =SUM(C34+'Jul 2022'!C35) -> 17177 | D35: =SUM(D34+'Jul 2022'!D35) -> 0 | E35: =SUM(E34+'Jul 2022'!E35) -> 17277 | F35: =SUM(F34+'Jul 2022'!F35) -> 7.16 | G35: =SUM(G34+'Jul 2022'!G35) -> 13.55 | H35: =SUM(H34+'Jul 2022'!H35) -> 0
A37: Acre Feet | B37: =SUM(B3:B33)*1.9835 -> 384.799 | C37: =SUM(C3:C33)*1.9835 -> 6265.8765 | D37: =SUM(D3:D33)*1.9835 -> 0 | E37: =SUM(E3:E33)*1.9835 -> 4833.7895
A39: WY AF Total | B39: =SUM(B37+'Jul 2022'!B39) -> 18908.705 | C39: =SUM(C37+'Jul 2022'!C39) -> 36040.195 | D39: =SUM(D37+'Jul 2022'!D39) -> 0 | E39: =SUM(E37+'Jul 2022'!E39) -> 37008.143
H41: * COMPUTATIONAL PURPOSES ONLY! Do Not Enter Data in the Red Columns
A43: *This is computation purposes only for Station 48
A44: Sta 48
...

Sheet Jul 2022
A1: DATE | B1: LRDC | C1: STATION 48 | D1: ANDERSON-ROSE | E1: J CANAL | F1: TULE LAKE PRECIP | G1: TULE LAKE SNOW | H1: D PLANT | I1: TULE LAKE ELEV. | J1: CHANGES @ STATION 48
B2: (in CFS) | C2: (in CFS) | D2: (in CFS) | E2: (in CFS) | H2: (in AF)
A3: 44743 | B3: 3 | C3: 150 | D3: 0 | E3: 126 | F3: 0 | G3: 0 | H3: 0 | I3: -
A4: =A3+1 -> 44744 | B4: 4 | C4: 159 | D4: 0 | E4: 157 | F4: 0 | G4: 0 | H4: 0 | I4: - | J4: *15:30 150/175
A5: =A4+1 -> 44745 | B5: 8 | C5: 175 | D5: 0 | E5: 131 | F5: 0.09 | G5: 0 | H5: 0 | I5: -
A6: =A5+1 -> 44746 | B6: 10 | C6: 148 | D6: 0 | E6: 135 | F6: 0.07 | G6: 0 | H6: 0 | I6: - | J6: *11:00 175/125
A7: =A6+1 -> 44747 | B7: 11 | C7: 115 | D7: 0 | E7: 135 | F7: 0.02 | G7: 0 | H7: 0 | I7: - | J7: *14:30 125/100
A8: =A7+1 -> 44748 | B8: 8 | C8: 119 | D8: 0 | E8: 150 | F8: 0 | G8: 0 | H8: 0 | I8: - | J8: *15:00 100/150
A9: =A8+1 -> 44749 | B9: 6 | C9: 160 | D9: 0 | E9: 168 | F9: 0 | G9: 0 | H9: 0 | I9: - | J9: *19:00 150/200
A10: =A9+1 -> 44750 | B10: 10 | C10: 200 | D10: 0 | E10: 147 | F10: 0 | G10: 0 | H10: 0 | I10: -
A11: =A10+1 -> 44751 | B11: 4 | C11: 200 | D11: 0 | E11: 132 | F11: 0 | G11: 0 | H11: 0 | I11: -
A12: =A11+1 -> 44752 | B12: 3 | C12: 175 | D12: 0 | E12: 132 | F12: 0 | G12: 0 | H12: 0 | I12: - | J12: *12:00 200/150
A13: =A12+1 -> 44753 | B13: 6 | C13: 175 | D13: 0 | E13: 145 | F13: 0 | G13: 0 | H13: 0 | I13: - | J13: * 12:00 150/200
A14: =A13+1 -> 44754 | B14: 3 | C14: 200 | D14: 0 | E14: 147 | F14: 0 | G14: 0 | H14: 0 | I14: -
A15: =A14+1 -> 44755 | B15: 5 | C15: 223 | D15: 0 | E15: 146 | F15: 0 | G15: 0 | H15: 0 | I15: - | J15: * 13:00 200/250
A16: =A15+1 -> 44756 | B16: 61 | C16: 250 | D16: 0 | E16: 137 | F16: 0 | G16: 0 | H16: 0 | I16: -
A17: =A16+1 -> 44757 | B17: 4 | C17: 250 | D17: 0 | E17: 135 | F17: 0 | G17: 0 | H17: 0 | I17: -
A18: =A17+1 -> 44758 | B18: 1 | C18: 250 | D18: 0 | E18: 156 | F18: 0 | G18: 0 | H18: 0 | I18: -
A19: =A18+1 -> 44759 | B19: 6 | C19: 250 | D19: 0 | E19: 209 | F19: 0 | G19: 0 | H19: 0 | I19: -
A20: =A19+1 -> 44760 | B20: 4 | C20: 250 | D20: 0 | E20: 224 | F20: 0 | G20: 0 | H20: 0 | I20: -
A21: =A20+1 -> 44761 | B21: 5 | C21: 250 | D21: 0 | E21: 217 | F21: 0 | G21: 0 | H21: 0 | I21: -
A22: =A21+1 -> 44762 | B22: 8 | C22: 250 | D22: 0 | E22: 199 | F22: 0 | G22: 0 | H22: 0 | I22: -
A23: =A22+1 -> 44763 | B23: 4 | C23: 250 | D23: 0 | E23: 249 | F23: 0 | G23: 0 | H23: 0 | I23: -
A24: =A23+1 -> 44764 | B24: 4 | C24: 250 | D24: 0 | E24: 208 | F24: 0 | G24: 0 | H24: 0 | I24: -
A25: =A24+1 -> 44765 | B25: 4 | C25: 250 | D25: 0 | E25: 212 | F25: 0 | G25: 0 | H25: 0 | I25: -
A26: =A25+1 -> 44766 | B26: 4 | C26: 250 | D26: 0 | E26: 193 | F26: 0 | G26: 0 | H26: 0 | I26: -
A27: =A26+1 -> 44767 | B27: 2 | C27: 250 | D27: 0 | E27: 176 | F27: 0 | G27: 0 | H27: 0 | I27: -
... A29: =A28+1 -> 44769 | B29: 12 | C29: 250 | D29: 0 | E29: 168 | F29: 0 | G29: 0 | H29: 0 | I29: -
A30: =A29+1 -> 44770 | B30: 10 | C30: 231 | D30: 0 | E30: 188 | F30: 0 | G30: 0 | H30: 0 | I30: - | J30: * 15:00 250/200
A31: =A30+1 -> 44771 | B31: 19 | C31: 200 | D31: 0 | E31: 172 | F31: 0 | G31: 0 | H31: 0 | I31: -
A32: =A31+1 -> 44772 | B32: 13 | C32: 200 | D32: 0 | E32: 155 | F32: T | G32: 0 | H32: 0 | I32: -
A33: =A32+1 -> 44773 | B33: 19 | C33: 200 | D33: 0 | E33: 163 | F33: 0 | G33: 0 | H33: 0 | I33: -
A34: Monthly Total | B34: =SUM(B3:B33) -> 270 | C34: =SUM(C3:C33) -> 6530 | D34: =SUM(D3:D33) -> 0 | E34: =SUM(E3:E33) -> 5158 | F34: =SUM(F3:F33) -> 0.18 | G34: =SUM(G3:G33) -> 0 | H34: =SUM(H3:H33) -> 0
A35: WY Total | B35: =SUM(B34+'Jun 2022'!B34) -> 8504 | C35: =SUM(C34+'Jun 2022'!C34) -> 14018 | D35: =SUM(D34+'Jun 2022'!D34) -> 0 | E35: =SUM(E34+'Jun 2022'!E34) -> 14840 | F35: =SUM(F34+'Jun 2022'!F34) -> 6.86 | G35: =SUM(G34+'Jun 2022'!G34) -> 13.55 | H35: =SUM(H34+'Jun 2022'!H34) -> 0
A37: Acre Feet | B37: =SUM(B3:B33)*1.9835 -> 535.545 | C37: =SUM(C3:C33)*1.9835 -> 12952.255 | D37: =SUM(D3:D33)*1.9835 -> 0 | E37: =SUM(E3:E33)*1.9835 -> 10230.893
A39: WY AF Total | B39: =SUM(B37+'Jun 2022'!B38) -> 18523.906 | C39: =SUM(C37+'Jun 2022'!C38) -> 29774.319 | D39: =SUM(D37+'Jun 2022'!D38) -> 0 | E39: =SUM(E37+'Jun 2022'!E38) -> 32174.353
H41: * COMPUTATIONAL PURPOSES ONLY! Do Not Enter Data in the Red Columns
A43: *This is computation purposes only for Station 48
A44: Sta 48
G45: =SUM(24-E45) -> 24 | H45: =SUM(D45+F45) -> 0 | I45: =SUM(D45/24*E45+H45/24*G45) -> 0
...

Sheet Jun 2022
A1: DATE | B1: LRDC | C1: STATION 48 | D1: ANDERSON-ROSE | E1: J CANAL | F1: TULE LAKE PRECIP | G1: TULE LAKE SNOW | H1: D PLANT | I1: TULE LAKE ELEV. | J1: CHANGES @ STATION 48
B2: (in CFS) | C2: (in CFS) | D2: (in CFS) | E2: (in CFS) | H2: (in AF)
A3: 44713 | B3: 20 | C3: 40 | D3: 0 | E3: 46 | F3: 0 | G3: 0 | H3: 0 | I3: -
A4: =A3+1 -> 44714 | B4: 27 | C4: 40 | D4: 0 | E4: 50 | F4: 0 | G4: 0 | H4: 0 | I4: -
A5: =A4+1 -> 44715 | B5: 25 | C5: 40 | D5: 0 | E5: 45 | F5: 0 | G5: 0 | H5: 0 | I5: -
A6: =A5+1 -> 44716 | B6: 27 | C6: 40 | D6: 0 | E6: 45 | F6: 0.14 | G6: 0 | H6: 0 | I6: -
A7: =A6+1 -> 44717 | B7: 26 | C7: 40 | D7: 0 | E7: 45 | F7: 0.31 | G7: 0 | H7: 0 | I7: -
A8: =A7+1 -> 44718 | B8: 37 | C8: 36 | D8: 0 | E8: 40 | F8: 0 | G8: 0 | H8: 0 | I8: - | J8: *15:00 40/30 J canal corrected from 41 to 40 cfs
A9: =A8+1 -> 44719 | B9: 55 | C9: 30 | D9: 0 | E9: 28 | F9: 0 | G9: 0 | H9: 0 | I9: -
A10: =A9+1 -> 44720 | B10: 32 | C10: 30 | D10: 0 | E10: 29 | F10: 0.01 | G10: 0 | H10: 0 | I10: -
A11: =A10+1 -> 44721 | B11: 23 | C11: 30 | D11: 0 | E11: 27 | F11: 0 | G11: 0 | H11: 0 | I11: -
A12: =A11+1 -> 44722 | B12: 24 | C12: 32 | D12: 0 | E12: 30 | F12: 0 | G12: 0 | H12: 0 | I12: - | J12: * 21:30 30/50
A13: =A12+1 -> 44723 | B13: 11 | C13: 50 | D13: 0 | E13: 45 | F13: 0 | G13: 0 | H13: 0 | I13: -
A14: =A13+1 -> 44724 | B14: 3 | C14: 41 | D14: 0 | E14: 36 | F14: 0.13 | G14: 0 | H14: 0 | I14: - | J14: * 13:00 50/30
A15: =A14+1 -> 44725 | B15: 3 | C15: 30 | D15: 0 | E15: 42 | F15: T | G15: 0 | H15: 0 | I15: -
A16: =A15+1 -> 44726 | B16: 5 | C16: 30 | D16: 0 | E16: 58 | F16: T | G16: 0 | H16: 0 | I16: -
A17: =A16+1 -> 44727 | B17: 6 | C17: 30 | D17: 0 | E17: 62 | F17: 0 | G17: 0 | H17: 0 | I17: -
A18: =A17+1 -> 44728 | B18: 5 | C18: 30 | D18: 0 | E18: 68 | F18: 0 | G18: 0 | H18: 0 | I18: -
A19: =A18+1 -> 44729 | B19: 5 | C19: 30 | D19: 0 | E19: 70 | F19: 0 | G19: 0 | H19: 0 | I19: -
A20: =A19+1 -> 44730 | B20: 4 | C20: 30 | D20: 0 | E20: 48 | F20: 0.19 | G20: 0 | H20: 0 | I20: -
A21: =A20+1 -> 44731 | B21: 4 | C21: 30 | D21: 0 | E21: 48 | F21: 0 | G21: 0 | H21: 0 | I21: -
A22: =A21+1 -> 44732 | B22: 5 | C22: 30 | D22: 0 | E22: 51 | F22: 0 | G22: 0 | H22: 0 | I22: -
A23: =A22+1 -> 44733 | B23: 18 | C23: 30 | D23: 0 | E23: 52 | F23: 0 | G23: 0 | H23: 0 | I23: -
A24: =A23+1 -> 44734 | B24: 38 | C24: 30 | D24: 0 | E24: 63 | F24: 0 | G24: 0 | H24: 0 | I24: -
A25: =A24+1 -> 44735 | B25: 35 | C25: 38 | D25: 0 | E25: 55 | F25: 0 | G25: 0 | H25: 0 | I25: - | J25: * 14:00 30/50 * 18:00 corrected J canal corrected from 52 to 55
A26: =A25+1 -> 44736 | B26: 32 | C26: 79 | D26: 0 | E26: 71 | F26: 0 | G26: 0 | H26: 0 | I26: - | J26: * 07:30 50/75 * 13:00 75/100
A27: =A26+1 -> 44737 | B27: 30 | C27: 114 | D27: 0 | E27: 73 | F27: 0 | G27: 0 | H27: 0 | I27: - | J27: * 17:30 100/150
A28: =A27+1 -> 44738 | B28: 21 | C28: 150 | D28: 0 | E28: 73 | F28: 0 | G28: 0 | H28: 0 | I28: -
A29: =A28+1 -> 44739 | B29: 8 | C29: 150 | D29: 0 | E29: 93 | F29: 0 | G29: 0 | H29: 0 | I29: -
A30: =A29+1 -> 44740 | B30: 3 | C30: 171 | D30: 0 | E30: 123 | F30: 0 | G30: 0 | H30: 0 | I30: - | J30: * 14:00 150/200
A31: =A30+1 -> 44741 | B31: 3 | C31: 200 | D31: 0 | E31: 142 | F31: 0 | G31: 0 | H31: 0 | I31: -
A32: =A31+1 -> 44742 | B32: 3 | C32: 182 | D32: 0 | E32: 135 | F32: 0 | G32: 0 | H32: 0 | I32: - | J32: * 15:30 200/150
A33: Monthly Total | B33: =SUM(B3:B32) -> 538 | C33: =SUM(C3:C32) -> 1833 | D33: =SUM(D3:D32) -> 0 | E33: =SUM(E3:E32) -> 1793 | F33: =SUM(F3:F32) -> 0.78 | G33: =SUM(G3:G32) -> 0 | H33: =SUM(H3:H32) -> 0
A34: WY Total | B34: =SUM(B33+'May 2022'!B35) -> 8234 | C34: =SUM(C33+'May 2022'!C35) -> 7488 | D34: =SUM(D33+'May 2022'!D35) -> 0 | E34: =SUM(E33+'May 2022'!E35) -> 9682 | F34: =SUM(F33+'May 2022'!F35) -> 6.68 | G34: =SUM(G33+'May 2022'!G35) -> 13.55 | H34: =SUM(H33+'May 2022'!H35) -> 0
A36: Acre Feet | B36: =SUM(B3:B32)*1.9835 -> 1067.123 | C36: =SUM(C3:C32)*1.9835 -> 3635.7555 | D36: =SUM(D3:D32)*1.9835 -> 0 | E36: =SUM(E3:E32)*1.9835 -> 3556.4155
A38: WY AF Total | B38: =SUM(B36+'May 2022'!B39) -> 17988.361 | C38: =SUM(C36+'May 2022'!C39) -> 16822.064 | D38: =SUM(D36+'May 2022'!D39) -> 0 | E38: =SUM(E36+'May 2022'!E39) -> 21943.46
H40: * COMPUTATIONAL PURPOSES ONLY! Do Not Enter Data in the Red Columns
A42: *This is computation purposes only for Station 48
A43: Sta 48
G44: =SUM(24-E44) -> 24 | H44: =SUM(D44+F44) -> 0 | I44: =SUM(D44/24*E44+H44/24*G44) -> 0
...

Sheet May 2022
A1: DATE | B1: LRDC | C1: STATION 48 | D1: ANDERSON-ROSE | E1: J CANAL | F1: TULE LAKE PRECIP | G1: TULE LAKE SNOW | H1: D PLANT | I1: TULE LAKE ELEV. | J1: CHANGES @ STATION 48
B2: (in CFS) | C2: (in CFS) | D2: (in CFS) | E2: (in CFS) | H2: (in AF)
A3: 44682 | B3: 34 | C3: 30 | D3: 0 | E3: 42 | F3: 0 | G3: 0 | H3: 0 | I3: -
A4: =A3+1 -> 44683 | B4: 26 | C4: 30 | D4: 0 | E4: 37 | F4: 0.09 | G4: 0 | H4: 0 | I4: -
A5: =A4+1 -> 44684 | B5: 30 | C5: 30 | D5: 0 | E5: 32 | F5: T | G5: 0 | H5: 0 | I5: -
A6: =A5+1 -> 44685 | B6: 16 | C6: 36 | D6: 0 | E6: 30 | F6: 0 | G6: 0 | H6: 0 | I6: - | J6: * 09:00 30/40 due to AR dropping below 30 cfs
A7: =A6+1 -> 44686 | B7: 8 | C7: 40 | D7: 0 | E7: 30 | F7: 0 | G7: 0 | H7: 0 | I7: -
A8: =A7+1 -> 44687 | B8: 19 | C8: 40 | D8: 0 | E8: 30 | F8: 0 | G8: 0 | H8: 0 | I8: -
A9: =A8+1 -> 44688 | B9: 19 | C9: 40 | D9: 0 | E9: 30 | F9: 0.06 | G9: 0 | H9: 0 | I9: -
A10: =A9+1 -> 44689 | B10: 23 | C10: 40 | D10: 0 | E10: 30 | F10: 0.04 | G10: 0 | H10: 0 | I10: -
A11: =A10+1 -> 44690 | B11: 39 | C11: 40 | D11: 0 | E11: 30 | F11: 0.01 | G11: 0 | H11: 0 | I11: -
A12: =A11+1 -> 44691 | B12: 45 | C12: 40 | D12: 0 | E12: 38 | F12: 0.08 | G12: 0 | H12: 0 | I12: -
A13: =A12+1 -> 44692 | B13: 35 | C13: 34 | D13: 0 | E13: 41 | F13: T | G13: 0 | H13: 0 | I13: - | J13: * 09:00 40/30
A14: =A13+1 -> 44693 | B14: 40 | C14: 30 | D14: 0 | E14: 42 | F14: T | G14: 0 | H14: 0 | I14: -
A15: =A14+1 -> 44694 | B15: 48 | C15: 30 | D15: 0 | E15: 55 | F15: 0 | G15: 0 | H15: 0 | I15: -
A16: =A15+1 -> 44695 | B16: 35 | C16: 30 | D16: 0 | E16: 51 | F16: 0 | G16: 0 | H16: 0 | I16: -
A17: =A16+1 -> 44696 | B17: 39 | C17: 30 | D17: 0 | E17: 49 | F17: 0 | G17: 0 | H17: 0 | I17: -
A18: =A17+1 -> 44697 | B18: 31 | C18: 30 | D18: 0 | E18: 39 | F18: 0 | G18: 0 | H18: 0 | I18: -
A19: =A18+1 -> 44698 | B19: 20 | C19: 36 | D19: 0 | E19: 33 | F19: 0 | G19: 0 | H19: 0 | I19: - | J19: * 10:00 30/40
A20: =A19+1 -> 44699 | B20: 20 | C20: 46 | D20: 0 | E20: 28 | F20: 0 | G20: 0 | H20: 0 | I20: - | J20: * 09:00 40/50
A21: =A20+1 -> 44700 | B21: 17 | C21: 50 | D21: 0 | E21: 27 | F21: 0 | G21: 0 | H21: 0 | I21: -
A22: =A21+1 -> 44701 | B22: 21 | C22: 50 | D22: 0 | E22: 29 | F22: 0 | G22: 0 | H22: 0 | I22: -
A23: =A22+1 -> 44702 | B23: 23 | C23: 50 | D23: 0 | E23: 29 | F23: 0 | G23: 0 | H23: 0 | I23: -
A24: =A23+1 -> 44703 | B24: 25 | C24: 50 | D24: 0 | E24: 29 | F24: 0 | G24: 0 | H24: 0 | I24: -
A25: =A24+1 -> 44704 | B25: 19 | C25: 50 | D25: 0 | E25: 27 | F25: 0 | G25: 0 | H25: 0 | I25: -
A26: =A25+1 -> 44705 | B26: 12 | C26: 50 | D26: 0 | E26: 28 | F26: 0 | G26: 0 | H26: 0 | I26: -
A27: =A26+1 -> 44706 | B27: 20 | C27: 50 | D27: 0 | E27: 28 | F27: 0 | G27: 0 | H27: 0 | I27: -
A28: =A27+1 -> 44707 | B28: 8 | C28: 50 | D28: 0 | E28: 33 | F28: 0 | G28: 0 | H28: 0 | I28: -
A29: =A28+1 -> 44708 | B29: 5 | C29: 50 | D29: 0 | E29: 46 | F29: 0.01 | G29: 0 | H29: 0 | I29: -
A30: =A29+1 -> 44709 | B30: 6 | C30: 50 | D30: 0 | E30: 43 | F30: 0.08 | G30: 0 | H30: 0 | I30: -
A31: =A30+1 -> 44710 | B31: 8 | C31: 50 | D31: 0 | E31: 35 | F31: T | G31: 0 | H31: 0 | I31: -
A32: =A31+1 -> 44711 | B32: 6 | C32: 50 | D32: 0 | E32: 42 | F32: 0 | G32: 0 | H32: 0 | I32: -
A33: =A32+1 -> 44712 | B33: 8 | C33: 41 | D33: 0 | E33: 42 | F33: 0 | G33: 0 | H33: 0 | J33: * 03:00 50/40
A34: Monthly Total | B34: =SUM(B3:B33) -> 705 | C34: =SUM(C3:C33) -> 1273 | D34: =SUM(D3:D33) -> 0 | E34: =SUM(E3:E33) -> 1105 | F34: =SUM(F3:F33) -> 0.37 | G34: =SUM(G3:G33) -> 0 | H34: =SUM(H3:H33) -> 0
A35: WY Total | B35: =SUM(B34+'Apr 2022'!B34) -> 7696 | C35: =SUM(C34+'Apr 2022'!C34) -> 5655 | D35: =SUM(D34+'Apr 2022'!D34) -> 0 | E35: =SUM(E34+'Apr 2022'!E34) -> 7889 | F35: =SUM(F34+'Apr 2022'!F34) -> 5.9 | G35: =SUM(G34+'Apr 2022'!G34) -> 13.55 | H35: =SUM(H34+'Apr 2022'!H34) -> 0
A37: Acre Feet | B37: =SUM(B3:B33)*1.9835 -> 1398.3675 | C37: =SUM(C3:C33)*1.9835 -> 2524.9955 | D37: =SUM(D3:D33)*1.9835 -> 0 | E37: =SUM(E3:E33)*1.9835 -> 2191.7675
A39: WY AF Total | B39: =SUM(B37+'Apr 2022'!B38) -> 16921.238 | C39: =SUM(C37+'Apr 2022'!C38) -> 13186.308 | D39: =SUM(D37+'Apr 2022'!D38) -> 0 | E39: =SUM(E37+'Apr 2022'!E38) -> 18387.045
H41: * COMPUTATIONAL PURPOSES ONLY! Do Not Enter Data in the Red Columns
A43: *This is computation purposes only for Station 48
A44: Sta 48
...

Sheet Apr 2022
A1: DATE | B1: LRDC | C1: STATION 48 | D1: ANDERSON-ROSE | E1: J CANAL | F1: TULE LAKE PRECIP | G1: TULE LAKE SNOW | H1: D PLANT | I1: TULE LAKE ELEV. | J1: CHANGES @ STATION 48
B2: (in CFS) | C2: (in CFS) | D2: (in CFS) | E2: (in CFS) | H2: (in AF)
A3: 44652 | B3: 24 | C3: 33 | D3: 0 | E3: 49 | F3: 0 | G3: 0 | H3: 0 | I3: - | J3: * 08:00 40/30
A4: =A3+1 -> 44653 | B4: 23 | C4: 30 | D4: 0 | E4: 42 | F4: 0 | G4: 0 | H4: 0 | I4: -
A5: =A4+1 -> 44654 | B5: 16 | C5: 30 | D5: 0 | E5: 34 | F5: 0 | G5: 0 | H5: 0 | I5: -
A6: =A5+1 -> 44655 | B6: 18 | C6: 30 | D6: 0 | E6: 36 | F6: 0.1 | G6: 0 | H6: 0 | I6: -
A7: =A6+1 -> 44656 | B7: 24 | C7: 30 | D7: 0 | E7: 38 | F7: 0 | G7: 0 | H7: 0 | I7: -
A8: =A7+1 -> 44657 | B8: 16 | C8: 30 | D8: 0 | E8: 43 | F8: 0 | G8: 0 | H8: 0 | I8: -
A9: =A8+1 -> 44658 | B9: 26 | C9: 30 | D9: 0 | E9: 47 | F9: 0 | G9: 0 | H9: 0 | I9: -
A10: =A9+1 -> 44659 | B10: 8 | C10: 35 | D10: 0 | E10: 52 | F10: 0 | G10: 0 | H10: 0 | I10: - | J10: *13:00 30/40
A11: =A10+1 -> 44660 | B11: 14 | C11: 40 | D11: 0 | E11: 46 | F11: 0 | G11: 0 | H11: 0 | I11: -
A12: =A11+1 -> 44661 | B12: 15 | C12: 40 | D12: 0 | E12: 40 | F12: 0 | G12: 0 | H12: 0 | I12: -
A13: =A12+1 -> 44662 | B13: 9 | C13: 40 | D13: 0 | E13: 39 | F13: 0.02 | G13: 0 | H13: 0 | I13: -
A14: =A13+1 -> 44663 | B14: 23 | C14: 35 | D14: 0 | E14: 43 | F14: 0.02 | G14: 0 | H14: 0 | I14: - | J14: * 12:00 40/30
A15: =A14+1 -> 44664 | B15: 30 | C15: 30 | D15: 0 | E15: 56 | F15: 0.09 | G15: 0 | H15: 0 | I15: -
A16: =A15+1 -> 44665 | B16: 23 | C16: 30 | D16: 0 | E16: 49 | F16: 0.12 | G16: 0 | H16: 0 | I16: -
A17: =A16+1 -> 44666 | B17: 20 | C17: 30 | D17: 0 | E17: 46 | F17: 0 | G17: 0 | H17: 0 | I17: -
A18: =A17+1 -> 44667 | B18: 32 | C18: 30 | D18: 0 | E18: 43 | F18: 0.38 | G18: 0 | H18: 0 | I18: -
A19: =A18+1 -> 44668 | B19: 29 | C19: 30 | D19: 0 | E19: 43 | F19: T | G19: 0 | H19: 0 | I19: -
A20: =A19+1 -> 44669 | B20: 31 | C20: 30 | D20: 0 | E20: 50 | F20: 0 | G20: 0 | H20: 0 | I20: -
A21: =A20+1 -> 44670 | B21: 35 | C21: 30 | D21: 0 | E21: 50 | F21: 0.35 | G21: 0 | H21: 0 | I21: -
A22: =A21+1 -> 44671 | B22: 37 | C22: 30 | D22: 0 | E22: 54 | F22: 0.03 | G22: 0 | H22: 0 | I22: -
A23: =A22+1 -> 44672 | B23: 46 | C23: 30 | D23: 0 | E23: 57 | F23: 0.23 | G23: 0 | H23: 0 | I23: -
A24: =A23+1 -> 44673 | B24: 28 | C24: 30 | D24: 0 | E24: 57 | F24: 0.03 | G24: 0 | H24: 0 | I24: -
A25: =A24+1 -> 44674 | B25: 33 | C25: 30 | D25: 0 | E25: 55 | F25: 0 | G25: 0 | H25: 0 | I25: -
A26: =A25+1 -> 44675 | B26: 87 | C26: 42 | D26: 0 | E26: 50 | F26: 0 | G26: 0 | H26: 0 | I26: - | J26: * 08:30 30/48 increase due to 18 cfs adams pump going on
A27: =A26+1 -> 44676 | B27: 78 | C27: 64 | D27: 0 | E27: 50 | F27: T | G27: 0 | H27: 0 | I27: - | J27: *07:00 48/75 *13:00 75/100 * 18:00 100/40
A28: =A27+1 -> 44677 | B28: 25 | C28: 34 | D28: 0 | E28: 53 | F28: 0 | G28: 0 | H28: 0 | I28: - | J28: * 09:00 40/30
A29: =A28+1 -> 44678 | B29: 27 | C29: 30 | D29: 0 | E29: 43 | F29: 0 | G29: 0 | H29: 0 | I29: -
A30: =A29+1 -> 44679 | B30: 13 | C30: 30 | D30: 0 | E30: 40 | F30: 0.16 | G30: 0 | H30: 0 | I30: -
A31: =A30+1 -> 44680 | B31: 26 | C31: 30 | D31: 0 | E31: 38 | F31: 0 | G31: 0 | H31: 0 | I31: -
A32: =A31+1 -> 44681 | B32: 19 | C32: 30 | D32: 0 | E32: 38 | F32: 0.11 | G32: 0 | H32: 0 | I32: -
A33: Monthly Total | B33: =SUM(B3:B32) -> 835 | C33: =SUM(C3:C32) -> 993 | D33: =SUM(D3:D32) -> 0 | E33: =SUM(E3:E32) -> 1381 | F33: =SUM(F3:F32) -> 1.64 | G33: =SUM(G3:G32) -> 0 | H33: =SUM(H3:H32) -> 0
A34: WY Total | B34: =SUM(B33+'Mar 2022'!B35) -> 6991 | C34: =SUM(C33+'Mar 2022'!C35) -> 4382 | D34: =SUM(D33+'Mar 2022'!D35) -> 0 | E34: =SUM(E33+'Mar 2022'!E35) -> 6784 | F34: =SUM(F33+'Mar 2022'!F35) -> 5.53 | G34: =SUM(G33+'Mar 2022'!G35) -> 13.55 | H34: =SUM(H33+'Mar 2022'!H35) -> 0
A36: Acre Feet | B36: =SUM(B3:B33)*1.9835 -> 3312.445 | C36: =SUM(C3:C33)*1.9835 -> 3939.231 | D36: =SUM(D3:D33)*1.9835 -> 0 | E36: =SUM(E3:E33)*1.9835 -> 5478.427
A38: WY AF Total | B38: =SUM(B36+'Mar 2022'!B39) -> 15522.871 | C38: =SUM(C36+'Mar 2022'!C39) -> 10661.312 | D38: =SUM(D36+'Mar 2022'!D39) -> 0 | E38: =SUM(E36+'Mar 2022'!E39) -> 16195.278
H40: * COMPUTATIONAL PURPOSES ONLY! Do Not Enter Data in the Red Columns
A42: *This is computation purposes only for Station 48
A43: Sta 48
G44: =SUM(24-E44) -> 24 | H44: =SUM(D44+F44) -> 0 | I44: =SUM(D44/24*E44+H44/24*G44) -> 0
...

Sheet Mar 2022
A1: DATE | B1: LRDC | C1: STATION 48 | D1: ANDERSON-ROSE | E1: J CANAL | F1: TULE LAKE PRECIP | G1: TULE LAKE SNOW | H1: D PLANT | I1: TULE LAKE ELEV. | J1: CHANGES @ STATION 48
B2: (in CFS) | C2: (in CFS) | D2: (in CFS) | E2: (in CFS) | H2: (in AF)
A3: 44621 | B3: 33 | C3: 20 | D3: 0 | E3: 39 | F3: 0 | G3: 0 | H3: 0 | I3: -
A4: =A3+1 -> 44622 | B4: 30 | C4: 23 | D4: 0 | E4: 35 | F4: 0 | G4: 0 | H4: 0 | I4: - | J4: * 09:00 20/25
A5: =A4+1 -> 44623 | B5: 47 | C5: 25 | D5: 0 | E5: 41 | F5: 0 | G5: 0.05 | H5: 0 | I5: -
A6: =A5+1 -> 44624 | B6: 9 | C6: 25 | D6: 0 | E6: 49 | F6: 0 | G6: 0 | H6: 0 | I6: -
A7: =A6+1 -> 44625 | B7: 17 | C7: 25 | D7: 0 | E7: 46 | F7: 0 | G7: 0 | H7: 0 | I7: -
A8: =A7+1 -> 44626 | B8: 20 | C8: 25 | D8: 0 | E8: 44 | F8: 0 | G8: 0 | H8: 0 | I8: -
A9: 44262 | B9: 12 | C9: 25 | D9: 0 | E9: 42 | F9: 0.02 | G9: 0 | H9: 0 | I9: -
A10: 44263 | B10: 4 | C10: 25 | D10: 0 | E10: 40 | F10: 0 | G10: 0 | H10: 0 | I10: -
A11: 44264 | B11: 42 | C11: 25 | D11: 0 | E11: 43 | F11: 0 | G11: 0 | H11: 0 | I11: -
A12: 44265 | B12: 11 | C12: 25 | D12: 0 | E12: 32 | F12: 0 | G12: 0 | H12: 0 | I12: -
A13: 44266 | B13: 32 | C13: 25 | D13: 0 | E13: 28 | F13: 0 | G13: 0 | H13: 0 | I13: -
A14: 44267 | B14: 21 | C14: 25 | D14: 0 | E14: 29 | F14: 0 | G14: 0 | H14: 0 | I14: -
A15: 44268 | B15: 48 | C15: 25 | D15: 0 | E15: 30 | F15: 0 | G15: 0 | H15: 0 | I15: -
A16: 44269 | B16: 28 | C16: 25 | D16: 0 | E16: 31 | F16: 0 | G16: 0 | H16: 0 | I16: -
A17: =A16+1 -> 44270 | B17: 30 | C17: 25 | D17: 0 | E17: 32 | F17: 0 | G17: 0 | H17: 0 | I17: -
A18: =A17+1 -> 44271 | B18: 29 | C18: 25 | D18: 0 | E18: 32 | F18: 0 | G18: 0 | H18: 0 | I18: -
A19: =A18+1 -> 44272 | B19: 17 | C19: 25 | D19: 0 | E19: 33 | F19: 0 | G19: 0 | H19: 0 | I19: -
A20: =A19+1 -> 44273 | B20: 32 | C20: 25 | D20: 0 | E20: 33 | F20: 0 | G20: 0 | H20: 0 | I20: -
A21: =A20+1 -> 44274 | B21: 27 | C21: 25 | D21: 0 | E21: 33 | F21: 0.06 | G21: 0 | H21: 0 | I21: -
A22: =A21+1 -> 44275 | B22: 30 | C22: 25 | D22: 0 | E22: 33 | F22: 0 | G22: 0 | H22: 0 | I22: -
A23: =A22+1 -> 44276 | B23: 34 | C23: 25 | D23: 0 | E23: 33 | F23: 0 | G23: 0 | H23: 0 | I23: -
A24: =A23+1 -> 44277 | B24: 39 | C24: 25 | D24: 0 | E24: 33 | F24: 0 | G24: 0 | H24: 0 | I24: -
A25: =A24+1 -> 44278 | B25: 24 | C25: 52 | D25: 0 | E25: 34 | F25: 0 | G25: 0 | H25: 0 | I25: - | J25: *11:00 25/75
A26: =A25+1 -> 44279 | B26: 22 | C26: 75 | D26: 0 | E26: 68 | F26: 0 | G26: 0 | H26: 0 | I26: -
A27: =A26+1 -> 44280 | B27: 22 | C27: 75 | D27: 0 | E27: 80 | F27: 0 | G27: 0 | H27: 0 | I27: -
A28: =A27+1 -> 44281 | B28: 18 | C28: 66 | D28: 0 | E28: 79 | F28: 0 | G28: 0 | H28: 0 | I28: - | J28: * 15:00 75/50
A29: =A28+1 -> 44282 | B29: 18 | C29: 50 | D29: 0 | E29: 78 | F29: 0 | G29: 0 | H29: 0 | I29: -
A30: =A29+1 -> 44283 | B30: 27 | C30: 44 | D30: 0 | E30: 64 | F30: 0 | G30: 0 | H30: 0 | I30: - | J30: * 10:00 50/40
A31: =A30+1 -> 44284 | B31: 27 | C31: 40 | D31: 0 | E31: 58 | F31: 0 | G31: 0 | H31: 0 | I31: -
A32: =A31+1 -> 44285 | B32: 14 | C32: 40 | D32: 0 | E32: 60 | F32: T | G32: 0 | H32: 0 | I32: -
A33: =A32+1 -> 44286 | B33: 19 | C33: 40 | D33: 0 | E33: 52 | F33: 0 | G33: 0 | H33: 0 | I33: -
A34: Monthly Total | B34: =SUM(B3:B33) -> 783 | C34: =SUM(C3:C33) -> 1025 | D34: =SUM(D3:D33) -> 0 | E34: =SUM(E3:E33) -> 1364 | F34: =SUM(F3:F33) -> 0.08 | G34: =SUM(G3:G33) -> 0.05 | H34: =SUM(H3:H33) -> 0
A35: WY Total | B35: =SUM(B34+'Feb 2022'!B33) -> 6156 | C35: =SUM(C34+'Feb 2022'!C33) -> 3389 | D35: =SUM(D34+'Feb 2022'!D33) -> 0 | E35: =SUM(E34+'Feb 2022'!E33) -> 5403 | F35: =SUM(F34+'Feb 2022'!F33) -> 3.89 | G35: =SUM(G34+'Feb 2022'!G33) -> 13.55 | H35: =SUM(H34+'Feb 2022'!H33) -> 0
A37: Acre Feet | B37: =SUM(B3:B33)*1.9835 -> 1553.0805 | C37: =SUM(C3:C33)*1.9835 -> 2033.0875 | D37: =SUM(D3:D33)*1.9835 -> 0 | E37: =SUM(E3:E33)*1.9835 -> 2705.494
A39: WY AF Total | B39: =SUM(B37+'Feb 2022'!B37) -> 12210.426 | C39: =SUM(C37+'Feb 2022'!C37) -> 6722.0815 | D39: =SUM(D37+'Feb 2022'!D37) -> 0 | E39: =SUM(E37+'Feb 2022'!E37) -> 10716.851
H41: * COMPUTATIONAL PURPOSES ONLY! Do Not Enter Data in the Red Columns
A43: *This is computation purposes only for Station 48
A44: Sta 48
...

Sheet Feb 2022
A1: DATE | B1: LRDC | C1: STATION 48 | D1: ANDERSON-ROSE | E1: J CANAL | F1: TULE LAKE PRECIP | G1: TULE LAKE SNOW | H1: D PLANT | I1: TULE LAKE ELEV. | J1: CHANGES @ STATION 48
B2: (in CFS) | C2: (in CFS) | D2: (in CFS) | E2: (in CFS) | H2: (in AF)
A3: 44593 | B3: 33 | C3: 30 | D3: 0 | E3: 34 | F3: 0 | G3: 0 | H3: 0 | I3: - | J3: * 12:00 25/35
A4: =A3+1 -> 44594 | B4: 37 | C4: 35 | D4: 0 | E4: 29 | F4: 0 | G4: 0 | H4: 0 | I4: -
A5: =A4+1 -> 44595 | B5: 32 | C5: 35 | D5: 0 | E5: 28 | F5: 0 | G5: 0 | H5: 0 | I5: -
A6: =A5+1 -> 44596 | B6: 32 | C6: 35 | D6: 0 | E6: 26 | F6: 0 | G6: 0 | H6: 0 | I6: -
A7: =A6+1 -> 44597 | B7: 30 | C7: 35 | D7: 0 | E7: 26 | F7: 0 | G7: 0 | H7: 0 | I7: -
A8: =A7+1 -> 44598 | B8: 29 | C8: 35 | D8: 0 | E8: 27 | F8: 0 | G8: 0 | H8: 0 | I8: -
A9: =A8+1 -> 44599 | B9: 29 | C9: 32 | D9: 0 | E9: 27 | F9: 0 | G9: 0 | H9: 0 | I9: - | J9: * 12:00 35/28
A10: =A9+1 -> 44600 | B10: 28 | C10: 28 | D10: 0 | E10: 27 | F10: 0 | G10: 0 | H10: 0 | I10: -
A11: =A10+1 -> 44601 | B11: 27 | C11: 28 | D11: 0 | E11: 27 | F11: 0 | G11: 0 | H11: 0 | I11: -
A12: =A11+1 -> 44602 | B12: 31 | C12: 28 | D12: 0 | E12: 27 | F12: 0 | G12: 0 | H12: 0 | I12: -
A13: =A12+1 -> 44603 | B13: 32 | C13: 28 | D13: 0 | E13: 27 | F13: 0 | G13: 0 | H13: 0 | I13: -
A14: =A13+1 -> 44604 | B14: 38 | C14: 28 | D14: 0 | E14: 27 | F14: 0 | G14: 0 | H14: 0 | I14: -
A15: =A14+1 -> 44605 | B15: 31 | C15: 28 | D15: 0 | E15: 27 | F15: 0 | G15: 0 | H15: 0 | I15: -
A16: =A15+1 -> 44606 | B16: 36 | C16: 28 | D16: 0 | E16: 27 | F16: 0 | G16: 0 | H16: 0 | I16: -
A17: =A16+1 -> 44607 | B17: 41 | C17: 31 | D17: 0 | E17: 27 | F17: 0 | G17: 0 | H17: 0 | I17: - | J17: *12:00 28/33
A18: =A17+1 -> 44608 | B18: 35 | C18: 33 | D18: 0 | E18: 35 | F18: 0 | G18: 0 | H18: 0 | I18: -
A19: =A18+1 -> 44609 | B19: 37 | C19: 33 | D19: 0 | E19: 50 | F19: 0 | G19: 0 | H19: 0 | I19: -
A20: =A19+1 -> 44610 | B20: 36 | C20: 34 | D20: 0 | E20: 54 | F20: 0 | G20: 0 | H20: 0 | I20: - | J20: * 10:00 33/35
A21: =A20+1 -> 44611 | B21: 17 | C21: 35 | D21: 0 | E21: 52 | F21: 0 | G21: 0 | H21: 0 | I21: -
A22: =A21+1 -> 44612 | B22: 23 | C22: 35 | D22: 0 | E22: 50 | F22: 0 | G22: 0 | H22: 0 | I22: -
A23: =A22+1 -> 44613 | B23: 32 | C23: 35 | D23: 0 | E23: 48 | F23: 0 | G23: 0 | H23: 0 | I23: -
A24: =A23+1 -> 44614 | B24: 31 | C24: 35 | D24: 0 | E24: 48 | F24: 0.03 | G24: 0 | H24: 0 | I24: -
A25: =A24+1 -> 44615 | B25: 14 | C25: 35 | D25: 0 | E25: 49 | F25: 0 | G25: 0 | H25: 0 | I25: -
A26: =A25+1 -> 44616 | B26: 29 | C26: 30 | D26: 0 | E26: 49 | F26: 0 | G26: 0 | H26: 0 | I26: - | J26: * 12:00 35/25
A27: =A26+1 -> 44617 | B27: 32 | C27: 25 | D27: 0 | E27: 49 | F27: 0 | G27: 0 | H27: 0 | I27: -
A28: =A27+1 -> 44618 | B28: 25 | C28: 25 | D28: 0 | E28: 45 | F28: 0 | G28: 0 | H28: 0 | I28: -
A29: =A28+1 -> 44619 | B29: 31 | C29: 25 | D29: 0 | E29: 42 | F29: 0 | G29: 0 | H29: 0 | I29: -
A30: =A29+1 -> 44620 | B30: 31 | C30: 22 | D30: 0 | E30: 42 | F30: 0 | G30: 0 | H30: 0 | I30: - | J30: * 11:00 25/20
A32: Monthly Total | B32: =SUM(B3:B31) -> 859 | C32: =SUM(C3:C31) -> 866 | D32: =SUM(D3:D31) -> 0 | E32: =SUM(E3:E31) -> 1026 | F32: =SUM(F3:F31) -> 0.03 | G32: =SUM(G3:G31) -> 0 | H32: =SUM(H3:H31) -> 0
A33: WY Total | B33: =SUM(B32+'Jan 2022'!B35) -> 5373 | C33: =SUM(C32+'Jan 2022'!C35) -> 2364 | D33: =SUM(D32+'Jan 2022'!D35) -> 0 | E33: =SUM(E32+'Jan 2022'!E35) -> 4039 | F33: =SUM(F32+'Jan 2022'!F35) -> 3.81 | G33: =SUM(G32+'Jan 2022'!G35) -> 13.5 | H33: =SUM(H32+'Jan 2022'!H35) -> 0
A35: Acre Feet | B35: =SUM(B3:B31)*1.9835 -> 1703.8265 | C35: =SUM(C3:C31)*1.9835 -> 1717.711 | D35: =SUM(D3:D31)*1.9835 -> 0 | E35: =SUM(E3:E31)*1.9835 -> 2035.071
A37: WY AF Total | B37: =SUM(B35+'Jan 2022'!B39) -> 10657.345 | C37: =SUM(C35+'Jan 2022'!C39) -> 4688.994 | D37: =SUM(D35+'Jan 2022'!D39) -> 0 | E37: =SUM(E35+'Jan 2022'!E39) -> 8011.3565
H39: * COMPUTATIONAL PURPOSES ONLY! Do Not Enter Data in the Red Columns
A41: *This is computation purposes only for Station 48
A42: Sta 48
G43: =SUM(24-E43) -> 24 | H43: =SUM(D43+F43) -> 0 | I43: =SUM(D43/24*E43+H43/24*G43) -> 0
G44: =SUM(24-E44) -> 24 | H44: =SUM(D44+F44) -> 0 | I44: =SUM(D44/24*E44+H44/24*G44) -> 0
G45: =SUM(24-E45) -> 24 | H45: =SUM(D45+F45) -> 0 | I45: =SUM(D45/24*E45+H45/24*G45) -> 0
...

Sheet Jan 2022
A1: DATE | B1: LRDC | C1: STATION 48 | D1: ANDERSON-ROSE | E1: J CANAL | F1: TULE LAKE PRECIP | G1: TULE LAKE SNOW | H1: D PLANT | I1: TULE LAKE ELEV. | J1: CHANGES @ STATION 48
B2: (in CFS) | C2: (in CFS) | D2: (in CFS) | E2: (in CFS) | H2: (in AF)
A3: 44562 | B3: 32 | C3: 0 | D3: 0 | E3: 10 | F3: 0 | G3: 0 | H3: 0 | I3: -
A4: =A3+1 -> 44563 | B4: 30 | C4: 0 | D4: 0 | E4: 10 | F4: 0 | G4: 0 | H4: 0 | I4: -
A5: =A4+1 -> 44564 | B5: 11 | C5: 0 | D5: 0 | E5: 11 | F5: 0.04 | G5: 0 | H5: 0 | I5: -
A6: =A5+1 -> 44565 | B6: 13 | C6: 0 | D6: 0 | E6: 10 | F6: 0.06 | G6: 0 | H6: 0 | I6: -
A7: =A6+1 -> 44566 | B7: 66 | C7: 0 | D7: 0 | E7: 9 | F7: 0.03 | G7: 0 | H7: 0 | I7: -
A8: =A7+1 -> 44567 | B8: 76 | C8: 0 | D8: 0 | E8: 24 | F8: 0 | G8: 0 | H8: 0 | I8: -
A9: =A8+1 -> 44568 | B9: 128 | C9: 0 | D9: 0 | E9: 24 | F9: 0.09 | G9: 0 | H9: 0 | I9: -
A10: =A9+1 -> 44569 | B10: 277 | C10: 0 | D10: 0 | E10: 24 | F10: T | G10: 0 | H10: 0 | I10: -
A11: =A10+1 -> 44570 | B11: 290 | C11: 0 | D11: 0 | E11: 24 | F11: 0 | G11: 0 | H11: 0 | I11: -
A12: =A11+1 -> 44571 | B12: 200 | C12: 0 | D12: 0 | E12: 30 | F12: 0 | G12: 0 | H12: 0 | I12: -
A13: =A12+1 -> 44572 | B13: 145 | C13: 0 | D13: 0 | E13: 29 | F13: 0 | G13: 0 | H13: 0 | I13: -
A14: =A13+1 -> 44573 | B14: 132 | C14: 0 | D14: 0 | E14: 29 | F14: 0 | G14: 0 | H14: 0 | I14: -
A15: =A14+1 -> 44574 | B15: 113 | C15: 0 | D15: 0 | E15: 29 | F15: 0 | G15: 0 | H15: 0 | I15: -
A16: =A15+1 -> 44575 | B16: 83 | C16: 0 | D16: 0 | E16: 29 | F16: 0 | G16: 0 | H16: 0 | I16: -
A17: =A16+1 -> 44576 | B17: 67 | C17: 0 | D17: 0 | E17: 28 | F17: T | G17: 0 | H17: 0 | I17: -
A18: =A17+1 -> 44577 | B18: 64 | C18: 0 | D18: 0 | E18: 28 | F18: T | G18: 0 | H18: 0 | I18: -
A19: =A18+1 -> 44578 | B19: 61 | C19: 0 | D19: 0 | E19: 27 | F19: T | G19: 0 | H19: 0 | I19: -
A20: =A19+1 -> 44579 | B20: 54 | C20: 0 | D20: 0 | E20: 27 | F20: 0 | G20: 0 | H20: 0 | I20: -
A21: =A20+1 -> 44580 | B21: 50 | C21: 0 | D21: 0 | E21: 27 | F21: 0 | G21: 0 | H21: 0 | I21: -
A22: =A21+1 -> 44581 | B22: 43 | C22: 0 | D22: 0 | E22: 27 | F22: 0 | G22: 0 | H22: 0 | I22: -
A23: =A22+1 -> 44582 | B23: 50 | C23: 0 | D23: 0 | E23: 25 | F23: 0.01 | G23: 0 | H23: 0 | I23: -
A24: =A23+1 -> 44583 | B24: 40 | C24: 0 | D24: 0 | E24: 25 | F24: 0 | G24: 0 | H24: 0 | I24: -
A25: =A24+1 -> 44584 | B25: 42 | C25: 0 | D25: 0 | E25: 25 | F25: 0 | G25: 0 | H25: 0 | I25: -
A26: =A25+1 -> 44585 | B26: 44 | C26: 0 | D26: 0 | E26: 25 | F26: 0 | G26: 0 | H26: 0 | I26: -
A27: =A26+1 -> 44586 | B27: 42 | C27: 0 | D27: 0 | E27: 25 | F27: 0 | G27: 0 | H27: 0 | I27: -
A28: =A27+1 -> 44587 | B28: 34 | C28: 0 | D28: 0 | E28: 25 | F28: 0 | G28: 0 | H28: 0 | I28: -
A29: =A28+1 -> 44588 | B29: 37 | C29: 16 | D29: 0 | E29: 25 | F29: 0 | G29: 0 | H29: 0 | I29: - | J29: * 13:00 0/35
A30: =A29+1 -> 44589 | B30: 36 | C30: 35 | D30: 0 | E30: 25 | F30: 0 | G30: 0 | H30: 0 | I30: -
A31: =A30+1 -> 44590 | B31: 34 | C31: 35 | D31: 0 | E31: 30 | F31: 0 | G31: 0 | H31: 0 | I31: -
A32: =A31+1 -> 44591 | B32: 32 | C32: 35 | D32: 0 | E32: 33 | F32: 0 | G32: 0 | H32: 0 | I32: -
A33: =A32+1 -> 44592 | B33: 32 | C33: 32 | D33: 0 | E33: 41 | F33: 0 | G33: 0 | H33: 0 | I33: - | J33: * 16:00 35/25
A34: Monthly Total | B34: =SUM(B3:B33) -> 2358 | C34: =SUM(C3:C33) -> 153 | D34: =SUM(D3:D33) -> 0 | E34: =SUM(E3:E33) -> 760 | F34: =SUM(F3:F33) -> 0.23 | G34: =SUM(G3:G33) -> 0 | H34: =SUM(H3:H33) -> 0
A35: WY Total | B35: =SUM(B34+'Dec 2021'!B35) -> 4514 | C35: =SUM(C34+'Dec 2021'!C35) -> 1498 | D35: =SUM(D34+'Dec 2021'!D35) -> 0 | E35: =SUM(E34+'Dec 2021'!E35) -> 3013 | F35: =SUM(F34+'Dec 2021'!F35) -> 3.78 | G35: =SUM(G34+'Dec 2021'!G35) -> 13.5 | H35: =SUM(H34+'Dec 2021'!H35) -> 0
A37: Acre Feet | B37: =SUM(B3:B33)*1.9835 -> 4677.093 | C37: =SUM(C3:C33)*1.9835 -> 303.4755 | D37: =SUM(D3:D33)*1.9835 -> 0 | E37: =SUM(E3:E33)*1.9835 -> 1507.46
A39: WY AF Total | B39: =SUM(B37+'Dec 2021'!B39) -> 8953.519 | C39: =SUM(C37+'Dec 2021'!C39) -> 2971.283 | D39: =SUM(D37+'Dec 2021'!D39) -> 0 | E39: =SUM(E37+'Dec 2021'!E39) -> 5976.2855
H41: * COMPUTATIONAL PURPOSES ONLY! Do Not Enter Data in the Red Columns
A43: *This is computation purposes only for Station 48
A44: Sta 48
...

Sheet Dec 2021
A1: DATE | B1: LRDC | C1: STATION 48 | D1: ANDERSON-ROSE | E1: J CANAL | F1: TULE LAKE PRECIP | G1: TULE LAKE SNOW | H1: D PLANT | I1: TULE LAKE ELEV. | J1: CHANGES @ STATION 48
B2: (in CFS) | C2: (in CFS) | D2: (in CFS) | E2: (in CFS) | H2: (in AF)
A3: 44531 | B3: 10 | C3: 5 | D3: 0 | E3: 17 | F3: T | G3: 0 | H3: 0 | I3: -
A4: =A3+1 -> 44532 | B4: 23 | C4: 13 | D4: 0 | E4: 13 | F4: 0 | G4: 0 | H4: 0 | I4: - | J4: * 12:00 5/20
A5: =A4+1 -> 44533 | B5: 21 | C5: 20 | D5: 0 | E5: 13 | F5: 0 | G5: 0 | H5: 0 | I5: -
A6: =A5+1 -> 44534 | B6: 20 | C6: 20 | D6: 0 | E6: 26 | F6: 0 | G6: 0 | H6: 0 | I6: -
A7: =A6+1 -> 44535 | B7: 20 | C7: 20 | D7: 0 | E7: 26 | F7: 0 | G7: 0 | H7: 0 | I7: -
A8: =A7+1 -> 44536 | B8: 9 | C8: 20 | D8: 0 | E8: 13 | F8: 0.01 | G8: 0 | H8: 0 | I8: -
A9: =A8+1 -> 44537 | B9: 19 | C9: 0 | D9: 0 | E9: 13 | F9: 0 | G9: 0 | H9: 0 | I9: - | J9: * 00:00 20/0
A10: =A9+1 -> 44538 | B10: 20 | C10: 0 | D10: 0 | E10: 13 | F10: T | G10: 0 | H10: 0 | I10: -
A11: =A10+1 -> 44539 | B11: 25 | C11: 0 | D11: 0 | E11: 13 | F11: 0 | G11: 0 | H11: 0 | I11: -
A12: =A11+1 -> 44540 | B12: 22 | C12: 0 | D12: 0 | E12: 13 | F12: 0 | G12: 0 | H12: 0 | I12: -
A13: =A12+1 -> 44541 | B13: 20 | C13: 0 | D13: 0 | E13: 13 | F13: T | G13: T | H13: 0 | I13: -
A14: =A13+1 -> 44542 | B14: 28 | C14: 0 | D14: 0 | E14: 12 | F14: 0 | G14: 0 | H14: 0 | I14: -
A15: =A14+1 -> 44543 | B15: 28 | C15: 0 | D15: 0 | E15: 12 | F15: 0.12 | G15: 0.25 | H15: 0 | I15: -
A16: =A15+1 -> 44544 | B16: 31 | C16: 0 | D16: 0 | E16: 12 | F16: 0.16 | G16: 1.25 | H16: 0 | I16: -
A17: =A16+1 -> 44545 | B17: 33 | C17: 0 | D17: 0 | E17: 12 | F17: T | G17: 0 | H17: 0 | I17: -
A18: =A17+1 -> 44546 | B18: 74 | C18: 0 | D18: 0 | E18: 11 | F18: 0.25 | G18: 1 | H18: 0 | I18: -
A19: =A18+1 -> 44547 | B19: 40 | C19: 0 | D19: 0 | E19: 11 | F19: T | G19: 0 | H19: 0 | I19: -
A20: =A19+1 -> 44548 | B20: 21 | C20: 0 | D20: 0 | E20: 11 | F20: 0 | G20: 0 | H20: 0 | I20: -
A21: =A20+1 -> 44549 | B21: 26 | C21: 0 | D21: 0 | E21: 12 | F21: 0 | G21: 0 | H21: 0 | I21: -
A22: =A21+1 -> 44550 | B22: 27 | C22: 0 | D22: 0 | E22: 13 | F22: T | G22: 0 | H22: 0
A23: =A22+1 -> 44551 | B23: 16 | C23: 0 | D23: 0 | E23: 12 | F23: 0 | G23: 0 | H23: 0
A24: =A23+1 -> 44552 | B24: 24 | C24: 0 | D24: 0 | E24: 11 | F24: 0.04 | G24: 0 | H24: 0
A25: =A24+1 -> 44553 | B25: 34 | C25: 0 | D25: 0 | E25: 10 | F25: 0 | G25: 0 | H25: 0
A26: =A25+1 -> 44554 | B26: 28 | C26: 0 | D26: 0 | E26: 10 | F26: 0.25 | G26: 2 | H26: 0
A27: =A26+1 -> 44555 | B27: 27 | C27: 0 | D27: 0 | E27: 10 | F27: 0.12 | G27: 1 | H27: 0
A28: =A27+1 -> 44556 | B28: 31 | C28: 0 | D28: 0 | E28: 9 | F28: 0 | G28: 2 | H28: 0
A29: =A28+1 -> 44557 | B29: 28 | C29: 0 | D29: 0 | E29: 9 | F29: 0.21 | G29: 4 | H29: 0
A30: =A29+1 -> 44558 | B30: 45 | C30: 0 | D30: 0 | E30: 10 | F30: 0.02 | G30: 0 | H30: 0
A31: =A30+1 -> 44559 | B31: 36 | C31: 0 | D31: 0 | E31: 10 | F31: 0.05 | G31: T | H31: 0
A32: =A31+1 -> 44560 | B32: 38 | C32: 0 | D32: 0 | E32: 10 | F32: T | G32: T | H32: 0
A33: =A32+1 -> 44561 | B33: 36 | C33: 0 | D33: 0 | E33: 10 | F33: 0 | G33: 2 | H33: 0
A34: Monthly Total | B34: =SUM(B3:B33) -> 860 | C34: =SUM(C3:C33) -> 98 | D34: =SUM(D3:D33) -> 0 | E34: =SUM(E3:E33) -> 390 | F34: =SUM(F3:F33) -> 1.23 | G34: =SUM(G3:G33) -> 13.5 | H34: =SUM(H3:H33) -> 0
A35: WY Total | B35: =SUM(B34+'Nov 2021'!B34) -> 2156 | C35: =SUM(C34+'Nov 2021'!C34) -> 1345 | D35: =SUM(D34+'Nov 2021'!D34) -> 0 | E35: =SUM(E34+'Nov 2021'!E34) -> 2253 | F35: =SUM(F34+'Nov 2021'!F34) -> 3.55 | G35: =SUM(G34+'Nov 2021'!G34) -> 13.5 | H35: =SUM(H34+'Nov 2021'!H34) -> 0
A37: Acre Feet | B37: =SUM(B3:B33)*1.9835 -> 1705.81 | C37: =SUM(C3:C33)*1.9835 -> 194.383 | D37: =SUM(D3:D33)*1.9835 -> 0 | E37: =SUM(E3:E33)*1.9835 -> 773.565
A39: WY AF Total | B39: =SUM('Nov 2021'!B38+B37) -> 4276.426 | C39: =SUM('Nov 2021'!C38+C37) -> 2667.8075 | D39: =SUM('Nov 2021'!D38+D37) -> 0 | E39: =SUM('Nov 2021'!E38+E37) -> 4468.8255
H41: * COMPUTATIONAL PURPOSES ONLY! Do Not Enter Data in the Red Columns
A43: *This is computation purposes only for Station 48
A44: Sta 48
...

Sheet Nov 2021
A1: DATE | B1: LRDC | C1: STATION 48 | D1: ANDERSON-ROSE | E1: J CANAL | F1: TULE LAKE PRECIP | G1: TULE LAKE SNOW | H1: D PLANT | I1: TULE LAKE ELEV. | J1: CHANGES @ STATION 48
B2: (in CFS) | C2: (in CFS) | D2: (in CFS) | E2: (in CFS) | H2: (in AF)
A3: 44501 | B3: 27 | C3: 20 | D3: 0 | E3: 47 | F3: 0.16 | G3: 0 | H3: 0 | I3: -
A4: =A3+1 -> 44502 | B4: 25 | C4: 20 | D4: 0 | E4: 47 | F4: 0 | G4: 0 | H4: 0 | I4: -
A5: =A4+1 -> 44503 | B5: 24 | C5: 23 | D5: 0 | E5: 48 | F5: 0.01 | G5: 0 | H5: 0 | I5: - | J5: * 09:00 20/25
A6: =A5+1 -> 44504 | B6: 42 | C6: 25 | D6: 0 | E6: 47 | F6: 0.02 | G6: 0 | H6: 0 | I6: -
A7: =A6+1 -> 44505 | B7: 36 | C7: 25 | D7: 0 | E7: 34 | F7: 0.07 | G7: 0 | H7: 0 | I7: -
A8: =A7+1 -> 44506 | B8: 35 | C8: 25 | D8: 0 | E8: 32 | F8: 0.17 | G8: 0 | H8: 0 | I8: -
A9: =A8+1 -> 44507 | B9: 28 | C9: 25 | D9: 0 | E9: 33 | F9: 0 | G9: 0 | H9: 0 | I9: -
A10: =A9+1 -> 44508 | B10: 28 | C10: 25 | D10: 0 | E10: 26 | F10: 0 | G10: 0 | H10: 0 | I10: -
A11: =A10+1 -> 44509 | B11: 30 | C11: 25 | D11: 0 | E11: 26 | F11: 0.02 | G11: 0 | H11: 0 | I11: -
A12: =A11+1 -> 44510 | B12: 30 | C12: 25 | D12: 0 | E12: 26 | F12: 0.01 | G12: 0 | H12: 0 | I12: -
A13: =A12+1 -> 44511 | B13: 30 | C13: 25 | D13: 0 | E13: 26 | F13: 0.05 | G13: 0 | H13: 0 | I13: -
A14: =A13+1 -> 44512 | B14: 29 | C14: 25 | D14: 0 | E14: 26 | F14: 0 | G14: 0 | H14: 0 | I14: -
A15: =A14+1 -> 44513 | B15: 26 | C15: 25 | D15: 0 | E15: 26 | F15: 0 | G15: 0 | H15: 0 | I15: -
A16: =A15+1 -> 44514 | B16: 25 | C16: 25 | D16: 0 | E16: 26 | F16: 0 | G16: 0 | H16: 0 | I16: -
A17: =A16+1 -> 44515 | B17: 26 | C17: 25 | D17: 0 | E17: 27 | F17: 0.01 | G17: 0 | H17: 0 | I17: -
... A19: =A18+1 -> 44517 | B19: 32 | C19: 25 | D19: 0 | E19: 27 | F19: 0 | G19: 0 | H19: 0 | I19: -
A20: =A19+1 -> 44518 | B20: 38 | C20: 25 | D20: 0 | E20: 26 | F20: T | G20: 0 | H20: 0 | I20: -
A21: =A20+1 -> 44519 | B21: 37 | C21: 25 | D21: 0 | E21: 26 | F21: T | G21: 0 | H21: 0 | I21: -
A22: =A21+1 -> 44520 | B22: 37 | C22: 25 | D22: 0 | E22: 28 | F22: 0 | G22: 0 | H22: 0 | I22: -
A23: =A22+1 -> 44521 | B23: 36 | C23: 25 | D23: 0 | E23: 28 | F23: 0 | G23: 0 | H23: 0 | I23: -
A24: =A23+1 -> 44522 | B24: 34 | C24: 28 | D24: 0 | E24: 31 | F24: 0 | G24: 0 | H24: 0 | I24: - | J24: * 12:00 25/30
A25: =A24+1 -> 44523 | B25: 31 | C25: 30 | D25: 0 | E25: 38 | F25: 0 | G25: 0 | H25: 0 | I25: -
A26: =A25+1 -> 44524 | B26: 29 | C26: 27 | D26: 0 | E26: 38 | F26: 0 | G26: 0 | H26: 0 | I26: - | J26: * 08:00 30/25
A27: =A26+1 -> 44525 | B27: 29 | C27: 25 | D27: 0 | E27: 38 | F27: 0.02 | G27: 0 | H27: 0 | I27: -
A28: =A27+1 -> 44526 | B28: 29 | C28: 25 | D28: 0 | E28: 38 | F28: 0 | G28: 0 | H28: 0 | I28: -
A29: =A28+1 -> 44527 | B29: 28 | C29: 25 | D29: 0 | E29: 38 | F29: 0 | G29: 0 | H29: 0 | I29: -
A30: =A29+1 -> 44528 | B30: 26 | C30: 25 | D30: 0 | E30: 37 | F30: 0 | G30: 0 | H30: 0 | I30: -
A31: =A30+1 -> 44529 | B31: 11 | C31: 15 | D31: 0 | E31: 37 | F31: 0.01 | G31: 0 | H31: 0 | I31: - | J31: * 12:00 25/5
A32: =A31+1 -> 44530 | B32: 5 | C32: 5 | D32: 0 | E32: 29 | F32: 0 | G32: 0 | H32: 0 | I32: -
A33: Monthly Total | B33: =SUM(B3:B32) -> 867 | C33: =SUM(C3:C32) -> 718 | D33: =SUM(D3:D32) -> 0 | E33: =SUM(E3:E32) -> 983 | F33: =SUM(F3:F32) -> 0.56 | G33: =SUM(G3:G32) -> 0 | H33: =SUM(H3:H32) -> 0
A34: WY Total | B34: =SUM(B33+'Oct 2021'!B35) -> 1296 | C34: =SUM(C33+'Oct 2021'!C35) -> 1247 | D34: =SUM(D33+'Oct 2021'!D35) -> 0 | E34: =SUM(E33+'Oct 2021'!E35) -> 1863 | F34: =SUM(F33+'Oct 2021'!F35) -> 2.32 | G34: =SUM(G33+'Oct 2021'!G35) -> 0 | H34: =SUM(H33+'Oct 2021'!H35) -> 0
A36: Acre Feet | B36: =SUM(B3:B32)*1.9835 -> 1719.6945 | C36: =SUM(C3:C32)*1.9835 -> 1424.153 | D36: =SUM(D3:D32)*1.9835 -> 0 | E36: =SUM(E3:E32)*1.9835 -> 1949.7805
A38: WY AF Total | B38: =SUM('Oct 2021'!B39+B36) -> 2570.616 | C38: =SUM('Oct 2021'!C39+C36) -> 2473.4245 | D38: =SUM('Oct 2021'!D39+D36) -> 0 | E38: =SUM('Oct 2021'!E39+E36) -> 3695.2605
H40: * COMPUTATIONAL PURPOSES ONLY! Do Not Enter Data in the Red Columns
A42: *This is computation purposes only for Station 48
A43: Sta 48
G44: =SUM(24-E44) -> 24 | H44: =SUM(D44+F44) -> 0 | I44: =SUM(D44/24*E44+H44/24*G44) -> 0
G45: =SUM(24-E45) -> 24 | H45: =SUM(D45+F45) -> 0 | I45: =SUM(D45/24*E45+H45/24*G45) -> 0
...

Sheet Oct 2021
A1: DATE | B1: LRDC | C1: STATION 48 | D1: ANDERSON-ROSE | E1: J CANAL | F1: TULE LAKE PRECIP | G1: TULE LAKE SNOW | H1: D PLANT | I1: TULE LAKE ELEV. | J1: CHANGES @ STATION 48
B2: (in CFS) | C2: (in CFS) | D2: (in CFS) | E2: (in CFS)
A3: 44470 | B3: 11 | C3: 9 | D3: 0 | E3: 5 | F3: 0 | G3: 0 | H3: 0 | I3: - | J3: * 08:30 0/14
A4: =A3+1 -> 44471 | B4: 11 | C4: 14 | D4: 0 | E4: 5 | F4: 0 | G4: 0 | H4: 0 | I4: -
A5: =A4+1 -> 44472 | B5: 12 | C5: 14 | D5: 0 | E5: 9 | F5: 0 | G5: 0 | H5: 0 | I5: -
A6: =A5+1 -> 44473 | B6: 12 | C6: 14 | D6: 0 | E6: 15 | F6: 0 | G6: 0 | H6: 0 | I6: -
A7: =A6+1 -> 44474 | B7: 7 | C7: 14 | D7: 0 | E7: 18 | F7: 0 | G7: 0 | H7: 0 | I7: -
A8: =A7+1 -> 44475 | B8: 6 | C8: 14 | D8: 0 | E8: 21 | F8: T | G8: 0 | H8: 0 | I8: -
A9: =A8+1 -> 44476 | B9: 10 | C9: 14 | D9: 0 | E9: 20 | F9: 0 | G9: 0 | H9: 0 | I9: -
A10: =A9+1 -> 44477 | B10: 9 | C10: 14 | D10: 0 | E10: 21 | F10: 0 | G10: 0 | H10: 0 | I10: -
A11: =A10+1 -> 44478 | B11: 11 | C11: 14 | D11: 0 | E11: 21 | F11: 0 | G11: 0 | H11: 0 | I11: -
A12: =A11+1 -> 44479 | B12: 8 | C12: 14 | D12: 0 | E12: 22 | F12: 0 | G12: 0 | H12: 0 | I12: -
A13: =A12+1 -> 44480 | B13: 6 | C13: 14 | D13: 0 | E13: 23 | F13: 0 | G13: 0 | H13: 0 | I13: -
A14: =A13+1 -> 44481 | B14: 9 | C14: 14 | D14: 0 | E14: 22 | F14: 0 | G14: 0 | H14: 0 | I14: -
A15: =A14+1 -> 44482 | B15: 10 | C15: 14 | D15: 0 | E15: 23 | F15: 0.03 | G15: 0 | H15: 0 | I15: -
A16: =A15+1 -> 44483 | B16: 11 | C16: 14 | D16: 0 | E16: 22 | F16: 0 | G16: 0 | H16: 0 | I16: -
A17: =A16+1 -> 44484 | B17: 8 | C17: 14 | D17: 0 | E17: 22 | F17: 0 | G17: 0 | H17: 0 | I17: -
A18: =A17+1 -> 44485 | B18: 8 | C18: 14 | D18: 0 | E18: 23 | F18: 0 | G18: 0 | H18: 0 | I18: -
A19: =A18+1 -> 44486 | B19: 11 | C19: 14 | D19: 0 | E19: 24 | F19: 0 | G19: 0 | H19: 0 | I19: -
A20: =A19+1 -> 44487 | B20: 11 | C20: 14 | D20: 0 | E20: 25 | F20: 0.12 | G20: 0 | H20: 0 | I20: -
... A26: =A25+1 -> 44493 | B26: 10 | C26: 14 | D26: 0 | E26: 26 | F26: 0.2 | G26: 0 | H26: 0 | I26: -
A27: =A26+1 -> 44494 | B27: 23 | C27: 29 | D27: 0 | E27: 34 | F27: 0.12 | G27: 0 | H27: 0 | I27: - | J27: * 10:00 14/40
A28: =A27+1 -> 44495 | B28: 35 | C28: 40 | D28: 0 | E28: 46 | F28: 0.01 | G28: 0 | H28: 0 | I28: -
A29: =A28+1 -> 44496 | B29: 35 | C29: 40 | D29: 0 | E29: 59 | F29: 0 | G29: 0 | H29: 0 | I29: -
A30: =A29+1 -> 44497 | B30: 29 | C30: 29 | D30: 0 | E30: 73 | F30: 0.01 | G30: 0 | H30: 0 | I30: - | J30: * 08:00 40/30 * 13:30 30/20
A31: =A30+1 -> 44498 | B31: 29 | C31: 20 | D31: 0 | E31: 65 | F31: T | G31: 0 | H31: 0 | I31: -
A32: =A31+1 -> 44499 | B32: 28 | C32: 20 | D32: 0 | E32: 53 | F32: 0.03 | G32: 0 | H32: 0 | I32: -
A33: =A32+1 -> 44500 | B33: 29 | C33: 20 | D33: 0 | E33: 54 | F33: 0 | G33: 0 | H33: 0 | I33: -
A34: Monthly Total | B34: =SUM(B3:B33) -> 429 | C34: =SUM(C3:C33) -> 529 | D34: =SUM(D3:D33) -> 0 | E34: =SUM(E3:E33) -> 880 | F34: =SUM(F3:F33) -> 1.76 | G34: =SUM(G3:G33) -> 0 | H34: =SUM(H3:H33) -> 0
A35: WY Total | B35: =SUM(B34+'Oct 2021'!B36) -> 429 | C35: =SUM(C34+'Oct 2021'!C36) -> 529 | D35: =SUM(D34+'Oct 2021'!D36) -> 0 | E35: =SUM(E34+'Oct 2021'!E36) -> 880 | F35: =SUM(F34+'Oct 2021'!F36) -> 1.76 | G35: =SUM(G34+'Oct 2021'!G36) -> 0 | H35: =SUM(H34+'Oct 2021'!H36) -> 0
A37: Acre Feet | B37: =SUM(B3:B33)*1.9835 -> 850.9215 | C37: =SUM(C3:C33)*1.9835 -> 1049.2715 | D37: =SUM(D3:D33)*1.9835 -> 0 | E37: =SUM(E3:E33)*1.9835 -> 1745.48
A39: WY AF Total | B39: =SUM('Oct 2021'!B40+B37) -> 850.9215 | C39: =SUM('Oct 2021'!C40+C37) -> 1049.2715 | D39: =SUM('Oct 2021'!D40+D37) -> 0 | E39: =SUM('Oct 2021'!E40+E37) -> 1745.48
H41: * COMPUTATIONAL PURPOSES ONLY! Do Not Enter Data in the Red Columns
A43: *This is computation purposes only for Station 48
A44: Sta 48
G45: =SUM(24-E45) -> 24 | H45: =SUM(D45+F45) -> 0 | I45: =SUM(D45/24*E45+H45/24*G45) -> 0
G46: =SUM(24-E46) -> 24 | H46: =SUM(D46+F46) -> 0 | I46: =SUM(D46/24*E46+H46/24*G46) -> 0
G47: =SUM(24-E47) -> 24 | H47: =SUM(D47+F47) -> 0 | I47: =SUM(D47/24*E47+H47/24*G47) -> 0
G48: =SUM(24-E48) -> 24 | H48: =SUM(D48+F48) -> 0 | I48: =SUM(D48/24*E48+H48/24*G48) -> 0
G49: =SUM(24-E49) -> 24 | H49: =SUM(D49+F49) -> 0 | I49: =SUM(D49/24*E49+H49/24*G49) -> 0
...
