Workbook

Sheet Sep 2023
A1: DATE | B1: LRDC | C1: STATION 48 | D1: ANDERSON-ROSE | E1: J CANAL | F1: TULE LAKE PRECIP | G1: TULE LAKE SNOW | H1: D PLANT | I1: TULE LAKE ELEV. | J1: CHANGES @ STATION 48
B2: (in CFS) | C2: (in CFS) | D2: (in CFS) | E2: (in CFS) | H2: (in AF)
A3: 45170 | B3: 0 | C3: 83 | D3: 0 | E3: 273 | F3: 0.07 | G3: 0 | H3: 0 | I3: - | J3: * 08:00 50/100
A4: =A3+1 -> 45171 | B4: 0 | C4: 75 | D4: 0 | E4: 283 | F4: 0.15 | G4: 0 | H4: 0 | I4: - | J4: * 12:00 100/50
A5: =A4+1 -> 45172 | B5: 0 | C5: 31 | D5: 20 | E5: 276 | F5: 0.03 | G5: 0 | H5: 0 | I5: - | J5: * 12:30 50/18
A6: =A5+1 -> 45173 | B6: 0 | C6: 4 | D6: 19 | E6: 281 | F6: 0 | G6: 0 | H6: 0 | I6: - | J6: * 08:30 18/0
A7: =A6+1 -> 45174 | B7: 0 | C7: 23 | D7: 0 | E7: 268 | F7: 0 | G7: 0 | H7: 0 | I7: - | J7: * 13:00 0/50
A8: =A7+1 -> 45175 | B8: 0 | C8: 50 | D8: 0 | E8: 264 | F8: 0 | G8: 0 | H8: 0 | I8: -
A9: =A8+1 -> 45176 | B9: 0 | C9: 37 | D9: 0 | E9: 264 | F9: 0 | G9: 0 | H9: 0 | I9: - | J9: * 14:00 50/18
A10: =A9+1 -> 45177 | B10: 0 | C10: 10 | D10: 2 | E10: 269 | F10: 0 | G10: 0 | H10: 0 | I10: - | J10: * 14:00 18/0
A11: =A10+1 -> 45178 | B11: 0 | C11: 0 | D11: 10 | E11: 245 | F11: 0 | G11: 0 | H11: 0 | I11: -
A12: =A11+1 -> 45179 | B12: 0 | C12: 0 | D12: 19 | E12: 221 | F12: 0 | G12: 0 | H12: 0 | I12: -
A13: =A12+1 -> 45180 | B13: 0 | C13: 0 | D13: 12 | E13: 231 | F13: 0 | G13: 0 | H13: 0 | I13: -
A14: =A13+1 -> 45181 | B14: 0 | C14: 27 | D14: 0 | E14: 271 | F14: 0 | G14: 0 | H14: 0 | I14: - | J14: * 11:00 0/50
A15: =A14+1 -> 45182 | B15: 0 | C15: 85 | D15: 0 | E15: 326 | F15: 0 | G15: 0 | H15: 0 | I15: - | J15: * 10:00 50/75 * 14:00 75/125
A16: =A15+1 -> 45183 | B16: 0 | C16: 133 | D16: 0 | E16: 326 | F16: 0 | G16: 0 | H16: 0 | I16: - | J16: * 16:00 125/150
A17: =A16+1 -> 45184 | B17: 0 | C17: 150 | D17: 0 | E17: 306 | F17: 0 | G17: 0 | H17: 0 | I17: -
A18: =A17+1 -> 45185 | B18: 0 | C18: 150 | D18: 0 | E18: 304 | F18: 0 | G18: 0 | H18: 0 | I18: -
A19: =A18+1 -> 45186 | B19: 0 | C19: 120 | D19: 0 | E19: 301 | F19: 0 | G19: 0 | H19: 0 | I19: - | J19: * 09:30 150/100
A20: =A19+1 -> 45187 | B20: 0 | C20: 100 | D20: 0 | E20: 290 | F20: 0 | G20: 0 | H20: 0 | I20: -
A21: =A20+1 -> 45188 | B21: 0 | C21: 100 | D21: 73 | E21: 272 | F21: 0 | G21: 0 | H21: 0 | I21: -
A22: =A21+1 -> 45189 | B22: 0 | C22: 100 | D22: 0 | E22: 269 | F22: 0 | G22: 0 | H22: 0 | I22: -
A23: =A22+1 -> 45190 | B23: 0 | C23: 100 | D23: 0 | E23: 251 | F23: 0 | G23: 0 | H23: 0 | I23: -
A24: =A23+1 -> 45191 | B24: 0 | C24: 100 | D24: 0 | E24: 259 | F24: 0 | G24: 0 | H24: 0 | I24: -
A25: =A24+1 -> 45192 | B25: 0 | C25: 100 | D25: 0 | E25: 271 | F25: 0 | G25: 0 | H25: 0 | I25: -
A26: =A25+1 -> 45193 | B26: 0 | C26: 100 | D26: 0 | E26: 325 | F26: 0.05 | G26: 0 | H26: 0 | I26: -
A27: =A26+1 -> 45194 | B27: 0 | C27: 100 | D27: 0 | E27: 362 | F27: 0 | G27: 0 | H27: 0 | I27: -
A28: =A27+1 -> 45195 | B28: 0 | C28: 100 | D28: 0 | E28: 370 | F28: 0 | G28: 0 | H28: 0 | I28: -
A29: =A28+1 -> 45196 | B29: 0 | C29: 100 | D29: 0 | E29: 382 | F29: 0 | G29: 0 | H29: 0 | I29: -
A30: =A29+1 -> 45197 | B30: 0 | C30: 117 | D30: 0 | E30: 364 | F30: 0 | G30: 0 | H30: 0 | I30: - | J30: * 07:30 100/125
A31: =A30+1 -> 45198 | B31: 0 | C31: 136 | D31: 0 | E31: 367 | F31: 0 | G31: 0 | H31: 0 | I31: - | J31: * 13:00 125/150
A32: =A31+1 -> 45199 | B32: 0 | C32: 150 | D32: 0 | E32: 374 | F32: 0.28 | G32: 0 | H32: 0 | I32: -
A33: Monthly Total | B33: =SUM(B3:B32) -> 0 | C33: =SUM(C3:C32) -> 2381 | D33: =SUM(D3:D32) -> 155 | E33: =SUM(E3:E32) -> 8865 | F33: =SUM(F3:F32) -> 0.58 | G33: =SUM(G3:G32) -> 0 | H33: =SUM(H3:H32) -> 0
A34: WY Total | B34: =SUM(B33+'Aug 2023'!B35) -> 327 | C34: =SUM(C33+'Aug 2023'!C35) -> 33979 | D34: =SUM(D33+'Aug 2023'!D35) -> 1760.5 | E34: =SUM(E33+'Aug 2023'!E35) -> 73301 | F34: =SUM(F33+'Aug 2023'!F35) -> 12.62 | G34: =SUM(G33+'Aug 2023'!G35) -> 25.5 | H34: =SUM(H33+'Aug 2023'!H35) -> 0
A36: Acre Feet | B36: =SUM(B3:B32)*1.9835 -> 0 | C36: =SUM(C3:C32)*1.9835 -> 4722.7135 | D36: =SUM(D3:D32)*1.9835 -> 307.4425 | E36: =SUM(E3:E32)*1.9835 -> 17583.728
A38: WY AF Total | B38: =SUM(B36+'Aug 2023'!B39) -> 648.6045 | C38: =SUM(C36+'Aug 2023'!C39) -> 67397.346 | D38: =SUM(D36+'Aug 2023'!D39) -> 3491.9518 | E38: =SUM(E36+'Aug 2023'!E39) -> 151317.25
H40: * COMPUTATIONAL PURPOSES ONLY! Do Not Enter Data in the Red Columns
A42: *This is computation purposes only for Station 48
A43: Sta 48
G44: =SUM(24-E44) -> 24 | H44: =SUM(D44+F44) -> 0 | I44: =SUM(D44/24*E44+H44/24*G44) -> 0
...

Sheet Aug 2023
A1: DATE | B1: LRDC | C1: STATION 48 | D1: ANDERSON-ROSE | E1: J CANAL | F1: TULE LAKE PRECIP | G1: TULE LAKE SNOW | H1: D PLANT | I1: TULE LAKE ELEV. | J1: CHANGES @ STATION 48
B2: (in CFS) | C2: (in CFS) | D2: (in CFS) | E2: (in CFS) | H2: (in AF)
A3: 45139 | B3: 0 | C3: 470 | D3: 0 | E3: 536 | F3: 0 | G3: 0 | H3: 0 | I3: - | J3: * 14:30 450/500
A4: =A3+1 -> 45140 | B4: 0 | C4: 475 | D4: 0 | E4: 591 | F4: 0 | G4: 0 | H4: 0 | I4: - | J4: * 12:00 500/450
A5: =A4+1 -> 45141 | B5: 0 | C5: 435 | D5: 0 | E5: 591 | F5: 0 | G5: 0 | H5: 0 | I5: - | J5: * 16:45 450/400
A6: =A5+1 -> 45142 | B6: 0 | C6: 400 | D6: 4 | E6: 581 | F6: 0 | G6: 0 | H6: 0 | I6: -
A7: =A6+1 -> 45143 | B7: 0 | C7: 308 | D7: 20 | E7: 572 | F7: 0.29 | G7: 0 | H7: 0 | I7: - | J7: * 07:00 400/300 * 14:00 300/250
A8: =A7+1 -> 45144 | B8: 0 | C8: 265 | D8: 0 | E8: 479 | F8: 0 | G8: 0 | H8: 0 | I8: - | J8: * 07:00 250/300 * 14:00 300/250
A9: =A8+1 -> 45145 | B9: 0 | C9: 250 | D9: 0 | E9: 365 | F9: 0 | G9: 0 | H9: 0 | I9: -
A10: =A9+1 -> 45146 | B10: 0 | C10: 233 | D10: 0 | E10: 340 | F10: 0 | G10: 0 | H10: 0 | I10: - | J10: * 16:00 250/200
A11: =A10+1 -> 45147 | B11: 0 | C11: 179 | D11: 13 | E11: 347 | F11: 0 | G11: 0 | H11: 0 | I11: - | J11: * 14:00 200/150
A12: =A11+1 -> 45148 | B12: 0 | C12: 150 | D12: 5 | E12: 327 | F12: 0 | G12: 0 | H12: 0 | I12: -
A13: =A12+1 -> 45149 | B13: 0 | C13: 150 | D13: 0 | E13: 329 | F13: 0 | G13: 0 | H13: 0 | I13: -
A14: =A13+1 -> 45150 | B14: 0 | C14: 200 | D14: 0 | E14: 330 | F14: 0 | G14: 0 | H14: 0 | I14: - | J14: * 24:00 150/200
A15: =A14+1 -> 45151 | B15: 0 | C15: 178 | D15: 0 | E15: 320 | F15: 0 | G15: 0 | H15: 0 | I15: - | J15: * 13:30 200/150
A16: =A15+1 -> 45152 | B16: 0 | C16: 136 | D16: 0 | E16: 325 | F16: 0 | G16: 0 | H16: 0 | I16: - | J16: * 16:30 150/100 * 22:00 100/125
A17: =A16+1 -> 45153 | B17: 0 | C17: 151 | D17: 0 | E17: 328 | F17: 0 | G17: 0 | H17: 0 | I17: - | J17: * 11:00 125/150 * 13:30 150/175 23:00 175/200
A18: =A17+1 -> 45154 | B18: 0 | C18: 179 | D18: 0 | E18: 304 | F18: 0 | G18: 0 | H18: 0 | I18: - | J18: * 14:00 200/150
A19: =A18+1 -> 45155 | B19: 0 | C19: 171 | D19: 0 | E19: 305 | F19: 0.02 | G19: 0 | H19: 0 | I19: - | J19: * 14:00 150/200
A20: =A19+1 -> 45156 | B20: 0 | C20: 155 | D20: 0 | E20: 333 | F20: 0.09 | G20: 0 | H20: 0 | I20: - | J20: * 09:00 200/100 * 15:30 100/150
A21: =A20+1 -> 45157 | B21: 0 | C21: 92 | D21: 1 | E21: 282 | F21: 0 | G21: 0 | H21: 0 | I21: - | J21: * 10:00 150/50
A22: =A21+1 -> 45158 | B22: 0 | C22: 34 | D22: 7 | E22: 268 | F22: 0 | G22: 0 | H22: 0 | I22: - | J22: * 08:30 50/25
A23: =A22+1 -> 45159 | B23: 0 | C23: 56 | D23: 0 | E23: 258 | F23: 0.45 | G23: 0 | H23: 0 | I23: - | J23: * 07:00 25/150 13:00 150/100 * 14:00 100/18
A24: =A23+1 -> 45160 | B24: 0 | C24: 18 | D24: 11 | E24: 257 | F24: 1.04 | G24: 0 | H24: 0 | I24: -
A25: =A24+1 -> 45161 | B25: 0 | C25: 5 | D25: 36 | E25: 249 | F25: 0.01 | G25: 0 | H25: 0 | I25: - | J25: * 07:00 18/0
A26: =A25+1 -> 45162 | B26: 0 | C26: 0 | D26: 57 | E26: 228 | F26: 0 | G26: 0 | H26: 0 | I26: -
A27: =A26+1 -> 45163 | B27: 0 | C27: 0 | D27: 154 | E27: 224 | F27: 0 | G27: 0 | H27: 0 | I27: -
A28: =A27+1 -> 45164 | B28: 0 | C28: 0 | D28: 180 | E28: 229 | F28: 0 | G28: 0 | H28: 0 | I28: -
A29: =A28+1 -> 45165 | B29: 0 | C29: 0 | D29: 150 | E29: 245 | F29: 0 | G29: 0 | H29: 0 | I29: -
A30: =A29+1 -> 45166 | B30: 0 | C30: 0 | D30: 64 | E30: 295 | F30: 0 | G30: 0 | H30: 0 | I30: -
A31: =A30+1 -> 45167 | B31: 0 | C31: 0 | D31: 0 | E31: 312 | F31: 0 | G31: 0 | H31: 0 | I31: -
A32: =A31+1 -> 45168 | B32: 0 | C32: 0 | D32: 0 | E32: 251 | F32: 0 | G32: 0 | H32: 0 | I32: -
A33: =A32+1 -> 45169 | B33: 0 | C33: 35 | D33: 0 | E33: 262 | F33: 0 | G33: 0 | H33: 0 | I33: - | J33: * 07:00 0/50
A34: Monthly Total | B34: =SUM(B3:B33) -> 0 | C34: =SUM(C3:C33) -> 4725 | D34: =SUM(D3:D33) -> 702 | E34: =SUM(E3:E33) -> 10663 | F34: =SUM(F3:F33) -> 1.9 | G34: =SUM(G3:G33) -> 0 | H34: =SUM(H3:H33) -> 0
A35: WY Total | B35: =SUM(B34+'Jul 2023'!B35) -> 327 | C35: =SUM(C34+'Jul 2023'!C35) -> 31598 | D35: =SUM(D34+'Jul 2023'!D35) -> 1605.5 | E35: =SUM(E34+'Jul 2023'!E35) -> 64436 | F35: =SUM(F34+'Jul 2023'!F35) -> 12.04 | G35: =SUM(G34+'Jul 2023'!G35) -> 25.5 | H35: =SUM(H34+'Jul 2023'!H35) -> 0
A37: Acre Feet | B37: =SUM(B3:B33)*1.9835 -> 0 | C37: =SUM(C3:C33)*1.9835 -> 9372.0375 | D37: =SUM(D3:D33)*1.9835 -> 1392.417 | E37: =SUM(E3:E33)*1.9835 -> 21150.06
A39: WY AF Total | B39: =SUM(B37+'Jul 2023'!B39) -> 648.6045 | C39: =SUM(C37+'Jul 2023'!C39) -> 62674.633 | D39: =SUM(D37+'Jul 2023'!D39) -> 3184.5093 | E39: =SUM(E37+'Jul 2023'!E39) -> 133733.52
H41: * COMPUTATIONAL PURPOSES ONLY! Do Not Enter Data in the Red Columns
A43: *This is computation purposes only for Station 48
A44: Sta 48
...

Sheet Jul 2023
A1: DATE | B1: LRDC | C1: STATION 48 | D1: ANDERSON-ROSE | E1: J CANAL | F1: TULE LAKE PRECIP | G1: TULE LAKE SNOW | H1: D PLANT | I1: TULE LAKE ELEV. | J1: CHANGES @ STATION 48
B2: (in CFS) | C2: (in CFS) | D2: (in CFS) | E2: (in CFS) | H2: (in AF)
A3: 45108 | B3: 0 | C3: 447 | D3: 9 | E3: 627 | F3: 0 | G3: 0 | H3: 0 | I3: - | J3: * 09:00 500/450 * 13:30 450/400
A4: =A3+1 -> 45109 | B4: 0 | C4: 438 | D4: 0 | E4: 582 | F4: 0 | G4: 0 | H4: 0 | I4: - | J4: * 06:00 400/450
A5: =A4+1 -> 45110 | B5: 0 | C5: 450 | D5: 0 | E5: 555 | F5: 0 | G5: 0 | H5: 0 | I5: -
A6: =A5+1 -> 45111 | B6: 0 | C6: 450 | D6: 0 | E6: 530 | F6: 0 | G6: 0 | H6: 0 | I6: -
A7: =A6+1 -> 45112 | B7: 0 | C7: 371 | D7: 0 | E7: 555 | F7: 0 | G7: 0 | H7: 0 | I7: - | J7: * 06:00 450/350 * 14:00 350/400
A8: =A7+1 -> 45113 | B8: 0 | C8: 436 | D8: 0 | E8: 563 | F8: 0 | G8: 0 | H8: 0 | I8: - | J8: * 09:30 400/450 * 21:00 450/500
A9: =A8+1 -> 45114 | B9: 0 | C9: 486 | D9: 0 | E9: 572 | F9: 0 | G9: 0 | H9: 0 | I9: - | J9: * 17:50 500/450
A10: =A9+1 -> 45115 | B10: 0 | C10: 450 | D10: 3 | E10: 564 | F10: 0 | G10: 0 | H10: 0 | I10: -
A11: =A10+1 -> 45116 | B11: 0 | C11: 418 | D11: 3 | E11: 547 | F11: 0 | G11: 0 | H11: 0 | I11: - | J11: * 09:30 400/450
A12: =A11+1 -> 45117 | B12: 0 | C12: 406 | D12: 0 | E12: 546 | F12: 0 | G12: 0 | H12: 0 | I12: - | J12: * 10:00 450/400
A13: =A12+1 -> 45118 | B13: 0 | C13: 421 | D13: 0 | E13: 545 | F13: 0 | G13: 0 | H13: 0 | I13: -
A14: =A13+1 -> 45119 | B14: 0 | C14: 379 | D14: 0.5 | E14: 506 | F14: 0 | G14: 0 | H14: 0 | I14: - | J14: * 14:00 400/350
A15: =A14+1 -> 45120 | B15: 0 | C15: 320 | D15: 1 | E15: 454 | F15: 0 | G15: 0 | H15: 0 | I15: - | J15: * 09:30 350/300
A16: =A15+1 -> 45121 | B16: 0 | C16: 300 | D16: 0 | E16: 437 | F16: 0 | G16: 0 | H16: 0 | I16: -
A17: =A16+1 -> 45122 | B17: 0 | C17: 300 | D17: 0 | E17: 423 | F17: 0 | G17: 0 | H17: 0 | I17: -
A18: =A17+1 -> 45123 | B18: 0 | C18: 279 | D18: 0 | E18: 382 | F18: 0 | G18: 0 | H18: 0 | I18: - | J18: * 14:00 300/250
A19: =A18+1 -> 45124 | B19: 0 | C19: 221 | D19: 0 | E19: 383 | F19: 0 | G19: 0 | H19: 0 | I19: - | J19: * 10:00 250/200
A20: =A19+1 -> 45125 | B20: 0 | C20: 200 | D20: 0 | E20: 391 | F20: 0 | G20: 0 | H20: 0 | I20: -
A21: =A20+1 -> 45126 | B21: 0 | C21: 225 | D21: 0 | E21: 390 | F21: 0 | G21: 0 | H21: 0 | I21: - | J21: * 04:00 200/250 16:00 250/200
A22: =A21+1 -> 45127 | B22: 0 | C22: 230 | D22: 0 | E22: 367 | F22: 0 | G22: 0 | H22: 0 | I22: - | J22: * 09:30 200/250
A23: =A22+1 -> 45128 | B23: 0 | C23: 274 | D23: 0 | E23: 380 | F23: 0 | G23: 0 | H23: 0 | I23: - | J23: * 12:30 250/300
A24: =A23+1 -> 45129 | B24: 0 | C24: 291 | D24: 0 | E24: 438 | F24: 0 | G24: 0 | H24: 0 | I24: - | J24: * 11:30 300/250 * 16:00 250/300
A25: =A24+1 -> 45130 | B25: 0 | C25: 300 | D25: 0 | E25: 440 | F25: 0 | G25: 0 | H25: 0 | I25: -
A26: =A25+1 -> 45131 | B26: 0 | C26: 317 | D26: 0 | E26: 413 | F26: 0 | G26: 0 | H26: 0 | I26: - | J26: * 07:00 300/350 15:00 350/300
A27: =A26+1 -> 45132 | B27: 0 | C27: 320 | D27: 0 | E27: 449 | F27: 0 | G27: 0 | H27: 0 | I27: - | J27: * 14:30 300/350
A28: =A27+1 -> 45133 | B28: 0 | C28: 386 | D28: 0 | E28: 484 | F28: 0 | G28: 0 | H28: 0 | I28: - | J28: * 06:30 350/400
A29: =A28+1 -> 45134 | B29: 0 | C29: 400 | D29: 0 | E29: 483 | F29: 0 | G29: 0 | H29: 0 | I29: -
A30: =A29+1 -> 45135 | B30: 0 | C30: 383 | D30: 0 | E30: 481 | F30: 0 | G30: 0 | H30: 0 | I30: - | J30: * 16:00 400/350
A31: =A30+1 -> 45136 | B31: 0 | C31: 341 | D31: 0 | E31: 488 | F31: 0 | G31: 0 | H31: 0 | I31: - | J31: * 10:00 350/300 * 14:30 00/350
A32: =A31+1 -> 45137 | B32: 0 | C32: 370 | D32: 0 | E32: 512 | F32: 0 | G32: 0 | H32: 0 | I32: - | J32: * 14:30 350/400
A33: =A32+1 -> 45138 | B33: 0 | C33: 429 | D33: 0 | E33: 567 | F33: 0 | G33: 0 | H33: 0 | I33: - | J33: * 10:00 400/450
A34: Monthly Total | B34: =SUM(B3:B33) -> 0 | C34: =SUM(C3:C33) -> 11038 | D34: =SUM(D3:D33) -> 16.5 | E34: =SUM(E3:E33) -> 15054 | F34: =SUM(F3:F33) -> 0 | G34: =SUM(G3:G33) -> 0 | H34: =SUM(H3:H33) -> 0
A35: WY Total | B35: =SUM(B34+'Jun 2023'!B34) -> 327 | C35: =SUM(C34+'Jun 2023'!C34) -> 26873 | D35: =SUM(D34+'Jun 2023'!D34) -> 903.5 | E35: =SUM(E34+'Jun 2023'!E34) -> 53773 | F35: =SUM(F34+'Jun 2023'!F34) -> 10.14 | G35: =SUM(G34+'Jun 2023'!G34) -> 25.5 | H35: =SUM(H34+'Jun 2023'!H34) -> 0
A37: Acre Feet | B37: =SUM(B3:B33)*1.9835 -> 0 | C37: =SUM(C3:C33)*1.9835 -> 21893.873 | D37: =SUM(D3:D33)*1.9835 -> 32.72775 | E37: =SUM(E3:E33)*1.9835 -> 29859.609
A39: WY AF Total | B39: =SUM(B37+'Jun 2023'!B38) -> 648.6045 | C39: =SUM(C37+'Jun 2023'!C38) -> 53302.595 | D39: =SUM(D37+'Jun 2023'!D38) -> 1792.0923 | E39: =SUM(E37+'Jun 2023'!E38) -> 112583.46
H41: * COMPUTATIONAL PURPOSES ONLY! Do Not Enter Data in the Red Columns
A43: *This is computation purposes only for Station 48
A44: Sta 48
...

Sheet Jun 2023
A1: DATE | B1: LRDC | C1: STATION 48 | D1: ANDERSON-ROSE | E1: J CANAL | F1: TULE LAKE PRECIP | G1: TULE LAKE SNOW | H1: D PLANT | I1: TULE LAKE ELEV. | J1: CHANGES @ STATION 48
B2: (in CFS) | C2: (in CFS) | D2: (in CFS) | E2: (in CFS) | H2: (in AF)
A3: 45078 | B3: 0 | C3: 150 | D3: 0 | E3: 346 | F3: 0.03 | G3: 0 | H3: 0 | I3: -
A4: =A3+1 -> 45079 | B4: 0 | C4: 134 | D4: 0 | E4: 368 | F4: 0 | G4: 0 | H4: 0 | I4: - | J4: * 16:00 150/100
A5: =A4+1 -> 45080 | B5: 0 | C5: 135 | D5: 0 | E5: 364 | F5: 0 | G5: 0 | H5: 0 | I5: - | J5: * 07:00 100/150
A6: =A5+1 -> 45081 | B6: 0 | C6: 150 | D6: 0 | E6: 363 | F6: 0 | G6: 0 | H6: 0 | I6: -
A7: =A6+1 -> 45082 | B7: 0 | C7: 166 | D7: 0 | E7: 376 | F7: 0.02 | G7: 0 | H7: 0 | I7: - | J7: * 16:30 150/200
A8: =A7+1 -> 45083 | B8: 0 | C8: 200 | D8: 0 | E8: 401 | F8: 0 | G8: 0 | H8: 0 | I8: -
A9: =A8+1 -> 45084 | B9: 0 | C9: 167 | D9: 0 | E9: 388 | F9: 0.02 | G9: 0 | H9: 0 | I9: - | J9: * 08:00 200/150
A10: =A9+1 -> 45085 | B10: 0 | C10: 190 | D10: 0 | E10: 395 | F10: 0.24 | G10: 0 | H10: 0 | I10: - | J10: * 05:00 150/200
A11: =A10+1 -> 45086 | B11: 0 | C11: 200 | D11: 0 | E11: 367 | F11: 0.05 | G11: 0 | H11: 0 | I11: -
A12: =A11+1 -> 45087 | B12: 0 | C12: 188 | D12: 0 | E12: 327 | F12: 0.02 | G12: 0 | H12: 0 | I12: - | J12: * 18:00 200/150
A13: =A12+1 -> 45088 | B13: 0 | C13: 129 | D13: 0 | E13: 316 | F13: 0 | G13: 0 | H13: 0 | I13: - | J13: * 14:00 150/100
A14: =A13+1 -> 45089 | B14: 0 | C14: 129 | D14: 0 | E14: 334 | F14: 0.01 | G14: 0 | H14: 0 | I14: - | J14: * 10:00 100/150
A15: =A14+1 -> 45090 | B15: 0 | C15: 171 | D15: 0 | E15: 363 | F15: 0 | G15: 0 | H15: 0 | I15: - | J15: * 14:00 150/200
A16: =A15+1 -> 45091 | B16: 0 | C16: 248 | D16: 0 | E16: 380 | F16: 0 | G16: 0 | H16: 0 | I16: - | J16: * 08:00 200/250 * 17:00 250/300
A17: =A16+1 -> 45092 | B17: 0 | C17: 269 | D17: 0 | E17: 397 | F17: 0 | G17: 0 | H17: 0 | I17: - | J17: * 09:00 300/250
A18: =A17+1 -> 45093 | B18: 0 | C18: 250 | D18: 0 | E18: 434 | F18: 0 | G18: 0 | H18: 0 | I18: -
A19: =A18+1 -> 45094 | B19: 0 | C19: 260 | D19: 0 | E19: 468 | F19: 0 | G19: 0 | H19: 0 | I19: - | J19: *12:00 250/300 * 17:00 300/250
A20: =A19+1 -> 45095 | B20: 0 | C20: 269 | D20: 0 | E20: 447 | F20: 0 | G20: 0 | H20: 0 | I20: - | J20: * 08:00 250/300 *17:00 300/250
A21: =A20+1 -> 45096 | B21: 0 | C21: 229 | D21: 4 | E21: 448 | F21: 0 | G21: 0 | H21: 0 | I21: - | J21: * 14:00 250/200
A22: =A21+1 -> 45097 | B22: 0 | C22: 200 | D22: 0 | E22: 446 | F22: 0.01 | G22: 0 | H22: 0 | I22: -
A23: =A22+1 -> 45098 | B23: 0 | C23: 244 | D23: 0 | E23: 419 | F23: 0 | G23: 0 | H23: 0 | I23: - | J23: * 09:00 200/250 * 11:00 250/300 *17:00 300/250
A24: =A23+1 -> 45099 | B24: 0 | C24: 250 | D24: 0 | E24: 414 | F24: 0 | G24: 0 | H24: 0 | I24: -
A25: =A24+1 -> 45100 | B25: 0 | C25: 285 | D25: 0 | E25: 456 | F25: 0 | G25: 0 | H25: 0 | I25: - | J25: * 14:30 250/300 * 16:30 300/350
A26: =A25+1 -> 45101 | B26: 0 | C26: 391 | D26: 0 | E26: 496 | F26: 0 | G26: 0 | H26: 0 | I26: - | J26: * 14:15 350/450
A27: =A26+1 -> 45102 | B27: 0 | C27: 435 | D27: 0 | E27: 541 | F27: 0.04 | G27: 0 | H27: 0 | I27: - | J27: * 10:00 450/400 * 17:00 400/450
A28: =A27+1 -> 45103 | B28: 0 | C28: 475 | D28: 0 | E28: 617 | F28: 0 | G28: 0 | H28: 0 | I28: - | J28: * 12:00 450/500
A29: =A28+1 -> 45104 | B29: 0 | C29: 500 | D29: 0 | E29: 618 | F29: 0.01 | G29: 0 | H29: 0 | I29: -
A30: =A29+1 -> 45105 | B30: 0 | C30: 483 | D30: 0 | E30: 621 | F30: 0 | G30: 0 | H30: 0 | I30: - | J30: * 16:00 500/450
A31: =A30+1 -> 45106 | B31: 0 | C31: 471 | D31: 0 | E31: 630 | F31: 0 | G31: 0 | H31: 0 | I31: - | J31: * 14:00 450/500
A32: =A31+1 -> 45107 | B32: 0 | C32: 500 | D32: 4 | E32: 650 | F32: 0 | G32: 0 | H32: 0 | I32: -
A33: Monthly Total | B33: =SUM(B3:B32) -> 0 | C33: =SUM(C3:C32) -> 7868 | D33: =SUM(D3:D32) -> 8 | E33: =SUM(E3:E32) -> 13190 | F33: =SUM(F3:F32) -> 0.45 | G33: =SUM(G3:G32) -> 0 | H33: =SUM(H3:H32) -> 0
A34: WY Total | B34: =SUM(B33+'May 2023'!B35) -> 327 | C34: =SUM(C33+'May 2023'!C35) -> 15835 | D34: =SUM(D33+'May 2023'!D35) -> 887 | E34: =SUM(E33+'May 2023'!E35) -> 38719 | F34: =SUM(F33+'May 2023'!F35) -> 10.14 | G34: =SUM(G33+'May 2023'!G35) -> 25.5 | H34: =SUM(H33+'May 2023'!H35) -> 0
A36: Acre Feet | B36: =SUM(B3:B32)*1.9835 -> 0 | C36: =SUM(C3:C32)*1.9835 -> 15606.178 | D36: =SUM(D3:D32)*1.9835 -> 15.868 | E36: =SUM(E3:E32)*1.9835 -> 26162.365
A38: WY AF Total | B38: =SUM(B36+'May 2023'!B39) -> 648.6045 | C38: =SUM(C36+'May 2023'!C39) -> 31408.722 | D38: =SUM(D36+'May 2023'!D39) -> 1759.3645 | E38: =SUM(E36+'May 2023'!E39) -> 82723.851
H40: * COMPUTATIONAL PURPOSES ONLY! Do Not Enter Data in the Red Columns
A42: *This is computation purposes only for Station 48
A43: Sta 48
G44: =SUM(24-E44) -> 24 | H44: =SUM(D44+F44) -> 0 | I44: =SUM(D44/24*E44+H44/24*G44) -> 0
...

Sheet May 2023
A1: DATE | B1: LRDC | C1: STATION 48 | D1: ANDERSON-ROSE | E1: J CANAL | F1: TULE LAKE PRECIP | G1: TULE LAKE SNOW | H1: D PLANT | I1: TULE LAKE ELEV. | J1: CHANGES @ STATION 48
B2: (in CFS) | C2: (in CFS) | D2: (in CFS) | E2: (in CFS) | H2: (in AF)
A3: 45047 | B3: 0 | C3: 98 | D3: 0 | E3: 40 | F3: 0 | G3: 0 | H3: 0 | I3: - | J3: * 00:30 0/100
A4: =A3+1 -> 45048 | B4: 0 | C4: 108 | D4: 0 | E4: 76 | F4: 0.3 | G4: 0 | H4: 0 | I4: - | J4: * 16:30 100/125
A5: =A4+1 -> 45049 | B5: 0 | C5: 163 | D5: 0 | E5: 96 | F5: 0.01 | G5: 0 | H5: 0 | I5: - | J5: * 08:00 125/150 * 14:00 150/200
A6: =A5+1 -> 45050 | B6: 0 | C6: 200 | D6: 0 | E6: 201 | F6: 0 | G6: 0 | H6: 0 | I6: -
A7: =A6+1 -> 45051 | B7: 0 | C7: 221 | D7: 0 | E7: 274 | F7: 0.05 | G7: 0 | H7: 0 | I7: - | J7: * 14:00 200/250
A8: =A7+1 -> 45052 | B8: 0 | C8: 231 | D8: 0 | E8: 296 | F8: 0.21 | G8: 0 | H8: 0 | I8: - | J8: * 10:00 250/200 * 14:00 200/225
A9: =A8+1 -> 45053 | B9: 0 | C9: 209 | D9: 0 | E9: 304 | F9: 0.1 | G9: 0 | H9: 0 | I9: - | J9: * 09:00 225/200
A10: =A9+1 -> 45054 | B10: 0 | C10: 201 | D10: 0 | E10: 306 | F10: 0.15 | G10: 0 | H10: 0 | I10: - | J10: * 23:00 200/225
A11: =A10+1 -> 45055 | B11: 0 | C11: 248 | D11: 0 | E11: 307 | F11: 0.02 | G11: 0 | H11: 0 | I11: - | J11: * 09:00 225/275 * 16:00 275/250
A12: =A11+1 -> 45056 | B12: 0 | C12: 221 | D12: 0 | E12: 346 | F12: 0 | G12: 0 | H12: 0 | I12: - | J12: * 07:00 250/200 * 18:00 200/225
A13: =A12+1 -> 45057 | B13: 0 | C13: 256 | D13: 0 | E13: 362 | F13: 0 | G13: 0 | H13: 0 | I13: - | J13: * 04:30 225/250 * 14:00 250/275
A14: =A13+1 -> 45058 | B14: 0 | C14: 281 | D14: 0 | E14: 342 | F14: 0 | G14: 0 | H14: 0 | I14: - | J14: * 18:30 275/300
A15: =A14+1 -> 45059 | B15: 0 | C15: 300 | D15: 0 | E15: 348 | F15: 0 | G15: 0 | H15: 0 | I15: -
A16: =A15+1 -> 45060 | B16: 0 | C16: 300 | D16: 0 | E16: 338 | F16: 0 | G16: 0 | H16: 0 | I16: -
A17: =A16+1 -> 45061 | B17: 0 | C17: 308 | D17: 0 | E17: 355 | F17: 0 | G17: 0 | H17: 0 | I17: - | J17: * 16:00 300/325
A18: =A17+1 -> 45062 | B18: 0 | C18: 321 | D18: 0 | E18: 333 | F18: 0 | G18: 0 | H18: 0 | I18: - | J18: * 13:30 325/350 * 17:00 350/300
A19: =A18+1 -> 45063 | B19: 0 | C19: 320 | D19: 0 | E19: 384 | F19: 0 | G19: 0 | H19: 0 | I19: - | J19: * 11:00 300/325 * 17:00 325/350
A20: =A19+1 -> 45064 | B20: 0 | C20: 372 | D20: 0 | E20: 428 | F20: 0 | G20: 0 | H20: 0 | I20: - | J20: * 06:00 350/400 * 14:00 400/375 * 19:30 375/350
A21: =A20+1 -> 45065 | B21: 0 | C21: 333 | D21: 0 | E21: 437 | F21: 0 | G21: 0 | H21: 0 | I21: -
A22: =A21+1 -> 45066 | B22: 0 | C22: 335 | D22: 0 | E22: 429 | F22: 0 | G22: 0 | H22: 0 | I22: - | J22: * 14:00 325/350
A23: =A22+1 -> 45067 | B23: 0 | C23: 332 | D23: 0 | E23: 392 | F23: 0 | G23: 0 | H23: 0 | I23: - | J23: * 15:30 350/300
A24: =A23+1 -> 45068 | B24: 0 | C24: 300 | D24: 1 | E24: 426 | F24: 0 | G24: 0 | H24: 0 | I24: -
A25: =A24+1 -> 45069 | B25: 0 | C25: 284 | D25: 0 | E25: 461 | F25: 0 | G25: 0 | H25: 0 | I25: - | J25: * 10:00 300/250 * 17:00 250/300
A26: =A25+1 -> 45070 | B26: 0 | C26: 296 | D26: 0 | E26: 451 | F26: 0 | G26: 0 | H26: 0 | I26: - | J26: * 16:00 300/350
A27: =A26+1 -> 45071 | B27: 0 | C27: 322 | D27: 0 | E27: 456 | F27: 0 | G27: 0 | H27: 0 | I27: -
A28: =A27+1 -> 45072 | B28: 0 | C28: 333 | D28: 0 | E28: 464 | F28: 0 | G28: 0 | H28: 0 | I28: -
A29: =A28+1 -> 45073 | B29: 0 | C29: 338 | D29: 0 | E29: 447 | F29: 0 | G29: 0 | H29: 0 | I29: - | J29: * 07:30 325/375 * 14:30 375/350 * 20:00 350/300 * 22:00 300/250
A30: =A29+1 -> 45074 | B30: 0 | C30: 233 | D30: 13 | E30: 427 | F30: 0.67 | G30: 0 | H30: 0 | I30: - | J30: * 16:00 250/200
A31: =A30+1 -> 45075 | B31: 0 | C31: 195 | D31: 4 | E31: 398 | F31: 0.01 | G31: 0 | H31: 0 | I31: - | J31: * 19:30 200/175
A32: =A31+1 -> 45076 | B32: 0 | C32: 158 | D32: 12 | E32: 381 | F32: 0.08 | G32: 0 | H32: 0 | I32: - | J32: * 08:00 175/150
A33: =A32+1 -> 45077 | B33: 0 | C33: 150 | D33: 1 | E33: 356 | F33: 0.15 | G33: 0 | H33: 0 | I33: -
A34: Monthly Total | B34: =SUM(B3:B33) -> 0 | C34: =SUM(C3:C33) -> 7967 | D34: =SUM(D3:D33) -> 31 | E34: =SUM(E3:E33) -> 10661 | F34: =SUM(F3:F33) -> 1.75 | G34: =SUM(G3:G33) -> 0 | H34: =SUM(H3:H33) -> 0
A35: WY Total | B35: =SUM(B34+'Apr 2023'!B34) -> 327 | C35: =SUM(C34+'Apr 2023'!C34) -> 7967 | D35: =SUM(D34+'Apr 2023'!D34) -> 879 | E35: =SUM(E34+'Apr 2023'!E34) -> 25529 | F35: =SUM(F34+'Apr 2023'!F34) -> 9.69 | G35: =SUM(G34+'Apr 2023'!G34) -> 25.5 | H35: =SUM(H34+'Apr 2023'!H34) -> 0
A37: Acre Feet | B37: =SUM(B3:B33)*1.9835 -> 0 | C37: =SUM(C3:C33)*1.9835 -> 15802.544 | D37: =SUM(D3:D33)*1.9835 -> 61.4885 | E37: =SUM(E3:E33)*1.9835 -> 21146.093
A39: WY AF Total | B39: =SUM(B37+'Apr 2023'!B38) -> 648.6045 | C39: =SUM(C37+'Apr 2023'!C38) -> 15802.544 | D39: =SUM(D37+'Apr 2023'!D38) -> 1743.4965 | E39: =SUM(E37+'Apr 2023'!E38) -> 56561.486
H41: * COMPUTATIONAL PURPOSES ONLY! Do Not Enter Data in the Red Columns
A43: *This is computation purposes only for Station 48
A44: Sta 48
...

Sheet Apr 2023
A1: DATE | B1: LRDC | C1: STATION 48 | D1: ANDERSON-ROSE | E1: J CANAL | F1: TULE LAKE PRECIP | G1: TULE LAKE SNOW | H1: D PLANT | I1: TULE LAKE ELEV. | J1: CHANGES @ STATION 48
B2: (in CFS) | C2: (in CFS) | D2: (in CFS) | E2: (in CFS) | H2: (in AF)
A3: 45017 | B3: 0 | C3: 0 | D3: 0 | E3: 80 | F3: 0.04 | G3: 0 | H3: 0 | I3: -
A4: =A3+1 -> 45018 | B4: 0 | C4: 0 | D4: 0 | E4: 73 | F4: T | G4: 0 | H4: 0 | I4: -
A5: =A4+1 -> 45019 | B5: 0 | C5: 0 | D5: 0 | E5: 76 | F5: 0.02 | G5: 0 | H5: 0 | I5: -
A6: =A5+1 -> 45020 | B6: 0 | C6: 0 | D6: 0 | E6: 76 | F6: T | G6: 0 | H6: 0 | I6: -
A7: =A6+1 -> 45021 | B7: 0 | C7: 0 | D7: 0 | E7: 85 | F7: 0 | G7: 0 | H7: 0 | I7: -
A8: =A7+1 -> 45022 | B8: 0 | C8: 0 | D8: 0 | E8: 85 | F8: 0 | G8: 0 | H8: 0 | I8: -
A9: =A8+1 -> 45023 | B9: 0 | C9: 0 | D9: 0 | E9: 80 | F9: 0 | G9: 0 | H9: 0 | I9: -
A10: =A9+1 -> 45024 | B10: 0 | C10: 0 | D10: 0 | E10: 75 | F10: 0 | G10: 0 | H10: 0 | I10: -
A11: =A10+1 -> 45025 | B11: 0 | C11: 0 | D11: 0 | E11: 76 | F11: 0 | G11: 0 | H11: 0 | I11: -
A12: =A11+1 -> 45026 | B12: 0 | C12: 0 | D12: 0 | E12: 81 | F12: 0 | G12: 0 | H12: 0 | I12: -
A13: =A12+1 -> 45027 | B13: 0 | C13: 0 | D13: 0 | E13: 79 | F13: 0.23 | G13: 0 | H13: 0 | I13: -
A14: =A13+1 -> 45028 | B14: 0 | C14: 0 | D14: 0 | E14: 121 | F14: 0 | G14: 0 | H14: 0 | I14: -
A15: =A14+1 -> 45029 | B15: 0 | C15: 0 | D15: 0 | E15: 340 | F15: 0 | G15: 0 | H15: 0 | I15: -
A16: =A15+1 -> 45030 | B16: 0 | C16: 0 | D16: 0 | E16: 308 | F16: 0 | G16: 0 | H16: 0 | I16: -
A17: =A16+1 -> 45031 | B17: 0 | C17: 0 | D17: 0 | E17: 192 | F17: 0 | G17: 0 | H17: 0 | I17: -
A18: =A17+1 -> 45032 | B18: 0 | C18: 0 | D18: 0 | E18: 164 | F18: 0 | G18: 0 | H18: 0 | I18: -
... A32: =A31+1 -> 45046 | B32: 0 | C32: 0 | D32: 0 | E32: 28 | F32: 0 | G32: 0 | H32: 0 | I32: -
A33: Monthly Total | B33: =SUM(B3:B32) -> 0 | C33: =SUM(C3:C32) -> 0 | D33: =SUM(D3:D32) -> 0 | E33: =SUM(E3:E32) -> 2987 | F33: =SUM(F3:F32) -> 0.38 | G33: =SUM(G3:G32) -> 0 | H33: =SUM(H3:H32) -> 0
A34: WY Total | B34: =SUM(B33+'Mar 2023'!B35) -> 327 | C34: =SUM(C33+'Mar 2023'!C35) -> 0 | D34: =SUM(D33+'Mar 2023'!D35) -> 848 | E34: =SUM(E33+'Mar 2023'!E35) -> 14868 | F34: =SUM(F33+'Mar 2023'!F35) -> 7.94 | G34: =SUM(G33+'Mar 2023'!G35) -> 25.5 | H34: =SUM(H33+'Mar 2023'!H35) -> 0
A36: Acre Feet | B36: =SUM(B3:B33)*1.9835 -> 0 | C36: =SUM(C3:C33)*1.9835 -> 0 | D36: =SUM(D3:D33)*1.9835 -> 0 | E36: =SUM(E3:E33)*1.9835 -> 11849.429
A38: WY AF Total | B38: =SUM(B36+'Mar 2023'!B39) -> 648.6045 | C38: =SUM(C36+'Mar 2023'!C39) -> 0 | D38: =SUM(D36+'Mar 2023'!D39) -> 1682.008 | E38: =SUM(E36+'Mar 2023'!E39) -> 35415.393
H40: * COMPUTATIONAL PURPOSES ONLY! Do Not Enter Data in the Red Columns
A42: *This is computation purposes only for Station 48
A43: Sta 48
G44: =SUM(24-E44) -> 24 | H44: =SUM(D44+F44) -> 0 | I44: =SUM(D44/24*E44+H44/24*G44) -> 0
G45: =SUM(24-E45) -> 24 | H45: =SUM(D45+F45) -> 0 | I45: =SUM(D45/24*E45+H45/24*G45) -> 0
G46: =SUM(24-E46) -> 24 | H46: =SUM(D46+F46) -> 0 | I46: =SUM(D46/24*E46+H46/24*G46) -> 0
G47: =SUM(24-E47) -> 24 | H47: =SUM(D47+F47) -> 0 | I47: =SUM(D47/24*E47+H47/24*G47) -> 0
G48: =SUM(24-E48) -> 24 | H48: =SUM(D48+F48) -> 0 | I48: =SUM(D48/24*E48+H48/24*G48) -> 0
A50: Use for more than 1 change in a day.
A51: **Station 48: | C51: Time | D51: Current CFS | E51: Hours Run | F51: +/- cfs | G51: Sub-total cfs
G52: =SUM(D52/24*E52) -> 0
G53: =SUM(D53/24*E53) -> 0
G54: =SUM(D54/24*E54) -> 0
G55: =SUM(D55/24*E55) -> 0
G56: =SUM(D56/24*E56) -> 0
A57: Total Hours Run | E57: =SUM(E52:E56) -> 0 | F57: Total/Day cfs | G57: =SUM(G52:G56) -> 0

Sheet Mar 2023
A1: DATE | B1: LRDC | C1: STATION 48 | D1: ANDERSON-ROSE | E1: J CANAL | F1: TULE LAKE PRECIP | G1: TULE LAKE SNOW | H1: D PLANT | I1: TULE LAKE ELEV. | J1: CHANGES @ STATION 48
B2: (in CFS) | C2: (in CFS) | D2: (in CFS) | E2: (in CFS) | H2: (in AF)
A3: 44986 | B3: 0 | C3: 0 | D3: 0 | E3: 39 | F3: 0.02 | G3: 0 | H3: 0 | I3: -
A4: =A3+1 -> 44987 | B4: 0 | C4: 0 | D4: 0 | E4: 40 | F4: 0 | G4: 0 | H4: 0 | I4: -
A5: =A4+1 -> 44988 | B5: 0 | C5: 0 | D5: 0 | E5: 38 | F5: 0 | G5: 0 | H5: 0 | I5: -
A6: =A5+1 -> 44989 | B6: 0 | C6: 0 | D6: 0 | E6: 38 | F6: 0.04 | G6: 1 | H6: 0 | I6: -
A7: =A6+1 -> 44990 | B7: 0 | C7: 0 | D7: 0 | E7: 39 | F7: 0.03 | G7: 2 | H7: 0 | I7: -
A8: =A7+1 -> 44991 | B8: 0 | C8: 0 | D8: 0 | E8: 41 | F8: 0 | G8: 0 | H8: 0 | I8: -
A9: 44262 | B9: 0 | C9: 0 | D9: 0 | E9: 41 | F9: T | G9: 0 | H9: 0 | I9: -
A10: 44263 | B10: 0 | C10: 0 | D10: 0 | E10: 41 | F10: 0.3 | G10: 5 | H10: 0 | I10: -
A11: 44264 | B11: 0 | C11: 0 | D11: 0 | E11: 43 | F11: 0.01 | G11: 1 | H11: 0 | I11: -
A12: 44265 | B12: 0 | C12: 0 | D12: 0 | E12: 41 | F12: 0.02 | G12: 0 | H12: 0 | I12: -
A13: 44266 | B13: 0 | C13: 0 | D13: 0 | E13: 66 | F13: 0.02 | G13: 0 | H13: 0 | I13: -
A14: 44267 | B14: 0 | C14: 0 | D14: 0 | E14: 71 | F14: 0.06 | G14: 0 | H14: 0 | I14: -
A15: 44268 | B15: 0 | C15: 0 | D15: 0 | E15: 78 | F15: 0.02 | G15: 0 | H15: 0
A16: 44269 | B16: 0 | C16: 0 | D16: 0 | E16: 80 | F16: 0.25 | G16: 0 | H16: 0
A17: =A16+1 -> 44270 | B17: 0 | C17: 0 | D17: 0 | E17: 140 | F17: 0.33 | G17: 0 | H17: 0
A18: =A17+1 -> 44271 | B18: 0 | C18: 0 | D18: 126 | E18: 369 | F18: 0.01 | G18: 0 | H18: 0
A19: =A18+1 -> 44272 | B19: 0 | C19: 0 | D19: 160 | E19: 423 | F19: 0 | G19: 0 | H19: 0
A20: =A19+1 -> 44273 | B20: 0 | C20: 0 | D20: 13 | E20: 423 | F20: 0 | G20: 0 | H20: 0
A21: =A20+1 -> 44274 | B21: 0 | C21: 0 | D21: 0 | E21: 377 | F21: 0 | G21: 0 | H21: 0
A22: =A21+1 -> 44275 | B22: 0 | C22: 0 | D22: 0 | E22: 327 | F22: 0 | G22: 0 | H22: 0
A23: =A22+1 -> 44276 | B23: 0 | C23: 0 | D23: 0 | E23: 276 | F23: 0 | G23: 0 | H23: 0
A24: =A23+1 -> 44277 | B24: 0 | C24: 0 | D24: 0 | E24: 256 | F24: 0.17 | G24: 0 | H24: 0
A25: =A24+1 -> 44278 | B25: 0 | C25: 0 | D25: 0 | E25: 229 | F25: 0.15 | G25: 0 | H25: 0
A26: =A25+1 -> 44279 | B26: 0 | C26: 0 | D26: 0 | E26: 208 | F26: 0.04 | G26: 0 | H26: 0
A27: =A26+1 -> 44280 | B27: 0 | C27: 0 | D27: 0 | E27: 208 | F27: 0.05 | G27: 0 | H27: 0
A28: =A27+1 -> 44281 | B28: 0 | C28: 0 | D28: 0 | E28: 208 | F28: 0 | G28: 0 | H28: 0
... A33: =A32+1 -> 44286 | B33: 0 | C33: 0 | D33: 0 | E33: 92 | F33: 0 | G33: 0 | H33: 0
A34: Monthly Total | B34: =SUM(B3:B33) -> 0 | C34: =SUM(C3:C33) -> 0 | D34: =SUM(D3:D33) -> 299 | E34: =SUM(E3:E33) -> 4762 | F34: =SUM(F3:F33) -> 1.6 | G34: =SUM(G3:G33) -> 9 | H34: =SUM(H3:H33) -> 0
A35: WY Total | B35: =SUM(B34+'Feb 2023'!B33) -> 327 | C35: =SUM(C34+'Feb 2023'!C33) -> 0 | D35: =SUM(D34+'Feb 2023'!D33) -> 848 | E35: =SUM(E34+'Feb 2023'!E33) -> 11881 | F35: =SUM(F34+'Feb 2023'!F33) -> 7.56 | G35: =SUM(G34+'Feb 2023'!G33) -> 25.5 | H35: =SUM(H34+'Feb 2023'!H33) -> 0
A37: Acre Feet | B37: =SUM(B3:B33)*1.9835 -> 0 | C37: =SUM(C3:C33)*1.9835 -> 0 | D37: =SUM(D3:D33)*1.9835 -> 593.0665 | E37: =SUM(E3:E33)*1.9835 -> 9445.427
A39: WY AF Total | B39: =SUM(B37+'Feb 2023'!B37) -> 648.6045 | C39: =SUM(C37+'Feb 2023'!C37) -> 0 | D39: =SUM(D37+'Feb 2023'!D37) -> 1682.008 | E39: =SUM(E37+'Feb 2023'!E37) -> 23565.963
H41: * COMPUTATIONAL PURPOSES ONLY! Do Not Enter Data in the Red Columns
A43: *This is computation purposes only for Station 48
A44: Sta 48
G45: =SUM(24-E45) -> 24 | H45: =SUM(D45+F45) -> 0 | I45: =SUM(D45/24*E45+H45/24*G45) -> 0
G46: =SUM(24-E46) -> 24 | H46: =SUM(D46+F46) -> 0 | I46: =SUM(D46/24*E46+H46/24*G46) -> 0
G47: =SUM(24-E47) -> 24 | H47: =SUM(D47+F47) -> 0 | I47: =SUM(D47/24*E47+H47/24*G47) -> 0
G48: =SUM(24-E48) -> 24 | H48: =SUM(D48+F48) -> 0 | I48: =SUM(D48/24*E48+H48/24*G48) -> 0
...

Sheet Feb 2023
A1: DATE | B1: LRDC | C1: STATION 48 | D1: ANDERSON-ROSE | E1: J CANAL | F1: TULE LAKE PRECIP | G1: TULE LAKE SNOW | H1: D PLANT | I1: TULE LAKE ELEV. | J1: CHANGES @ STATION 48
B2: (in CFS) | C2: (in CFS) | D2: (in CFS) | E2: (in CFS) | H2: (in AF)
A3: 44958 | B3: 0 | C3: 0 | D3: 0 | E3: 41 | F3: 0 | G3: 0 | H3: 0 | I3: -
A4: =A3+1 -> 44959 | B4: 0 | C4: 0 | D4: 0 | E4: 37 | F4: 0 | G4: 0 | H4: 0 | I4: -
A5: =A4+1 -> 44960 | B5: 0 | C5: 0 | D5: 0 | E5: 38 | F5: 0 | G5: 0 | H5: 0 | I5: -
A6: =A5+1 -> 44961 | B6: 0 | C6: 0 | D6: 0 | E6: 39 | F6: 0.18 | G6: 0 | H6: 0 | I6: -
A7: =A6+1 -> 44962 | B7: 0 | C7: 0 | D7: 0 | E7: 39 | F7: 0 | G7: 0 | H7: 0 | I7: -
A8: =A7+1 -> 44963 | B8: 0 | C8: 0 | D8: 0 | E8: 39 | F8: 0 | G8: 0 | H8: 0 | I8: -
A9: =A8+1 -> 44964 | B9: 0 | C9: 0 | D9: 0 | E9: 39 | F9: 0 | G9: 0 | H9: 0 | I9: -
A10: =A9+1 -> 44965 | B10: 0 | C10: 0 | D10: 0 | E10: 34 | F10: T | G10: 0 | H10: 0 | I10: -
A11: =A10+1 -> 44966 | B11: 0 | C11: 0 | D11: 0 | E11: 34 | F11: 0 | G11: 0 | H11: 0 | I11: -
A12: =A11+1 -> 44967 | B12: 0 | C12: 0 | D12: 0 | E12: 34 | F12: T | G12: 0 | H12: 0 | I12: -
A13: =A12+1 -> 44968 | B13: 0 | C13: 0 | D13: 0 | E13: 44 | F13: 0 | G13: 0 | H13: 0 | I13: -
A14: =A13+1 -> 44969 | B14: 0 | C14: 0 | D14: 0 | E14: 42 | F14: 0 | G14: 0 | H14: 0 | I14: -
A15: =A14+1 -> 44970 | B15: 0 | C15: 0 | D15: 0 | E15: 42 | F15: 0 | G15: 0 | H15: 0 | I15: -
A16: =A15+1 -> 44971 | B16: 0 | C16: 0 | D16: 0 | E16: 42 | F16: 0.08 | G16: 0 | H16: 0 | I16: -
A17: =A16+1 -> 44972 | B17: 0 | C17: 0 | D17: 0 | E17: 44 | F17: 0 | G17: 0 | H17: 0 | I17: -
A18: =A17+1 -> 44973 | B18: 0 | C18: 0 | D18: 0 | E18: 41 | F18: 0 | G18: 0 | H18: 0 | I18: -
A19: =A18+1 -> 44974 | B19: 0 | C19: 0 | D19: 0 | E19: 40 | F19: 0 | G19: 0 | H19: 0 | I19: -
A20: =A19+1 -> 44975 | B20: 0 | C20: 0 | D20: 0 | E20: 39 | F20: 0 | G20: 0 | H20: 0 | I20: -
A21: =A20+1 -> 44976 | B21: 0 | C21: 0 | D21: 0 | E21: 40 | F21: 0 | G21: 0 | H21: 0 | I21: -
A22: =A21+1 -> 44977 | B22: 0 | C22: 0 | D22: 0 | E22: 38 | F22: 0 | G22: 0 | H22: 0 | I22: -
A23: =A22+1 -> 44978 | B23: 0 | C23: 0 | D23: 0 | E23: 36 | F23: T | G23: 0 | H23: 0 | I23: -
A24: =A23+1 -> 44979 | B24: 0 | C24: 0 | D24: 0 | E24: 36 | F24: 0.01 | G24: 0 | H24: 0 | I24: -
A25: =A24+1 -> 44980 | B25: 0 | C25: 0 | D25: 0 | E25: 36 | F25: T | G25: 0 | H25: 0 | I25: -
A26: =A25+1 -> 44981 | B26: 0 | C26: 0 | D26: 0 | E26: 36 | F26: 0 | G26: 0 | H26: 0 | I26: -
A27: =A26+1 -> 44982 | B27: 0 | C27: 0 | D27: 0 | E27: 36 | F27: 0 | G27: 0 | H27: 0 | I27: -
A28: =A27+1 -> 44983 | B28: 0 | C28: 0 | D28: 0 | E28: 36 | F28: 0.1 | G28: 1 | H28: 0 | I28: -
A29: =A28+1 -> 44984 | B29: 0 | C29: 0 | D29: 0 | E29: 38 | F29: 0 | G29: 0 | H29: 0 | I29: -
A30: =A29+1 -> 44985 | B30: 0 | C30: 0 | D30: 0 | E30: 38 | F30: 0.02 | G30: 1 | H30: 0 | I30: -
A32: Monthly Total | B32: =SUM(B3:B31) -> 0 | C32: =SUM(C3:C31) -> 0 | D32: =SUM(D3:D31) -> 0 | E32: =SUM(E3:E31) -> 1078 | F32: =SUM(F3:F31) -> 0.39 | G32: =SUM(G3:G31) -> 2 | H32: =SUM(H3:H31) -> 0
A33: WY Total | B33: =SUM(B32+'Jan 2023'!B35) -> 327 | C33: =SUM(C32+'Jan 2023'!C35) -> 0 | D33: =SUM(D32+'Jan 2023'!D35) -> 549 | E33: =SUM(E32+'Jan 2023'!E35) -> 7119 | F33: =SUM(F32+'Jan 2023'!F35) -> 5.96 | G33: =SUM(G32+'Jan 2023'!G35) -> 16.5 | H33: =SUM(H32+'Jan 2023'!H35) -> 0
A35: Acre Feet | B35: =SUM(B3:B31)*1.9835 -> 0 | C35: =SUM(C3:C31)*1.9835 -> 0 | D35: =SUM(D3:D31)*1.9835 -> 0 | E35: =SUM(E3:E31)*1.9835 -> 2138.213
A37: WY AF Total | B37: =SUM(B35+'Jan 2023'!B39) -> 648.6045 | C37: =SUM(C35+'Jan 2023'!C39) -> 0 | D37: =SUM(D35+'Jan 2023'!D39) -> 1088.9415 | E37: =SUM(E35+'Jan 2023'!E39) -> 14120.537
H39: * COMPUTATIONAL PURPOSES ONLY! Do Not Enter Data in the Red Columns
A41: *This is computation purposes only for Station 48
A42: Sta 48
G43: =SUM(24-E43) -> 24 | H43: =SUM(D43+F43) -> 0 | I43: =SUM(D43/24*E43+H43/24*G43) -> 0
G44: =SUM(24-E44) -> 24 | H44: =SUM(D44+F44) -> 0 | I44: =SUM(D44/24*E44+H44/24*G44) -> 0
G45: =SUM(24-E45) -> 24 | H45: =SUM(D45+F45) -> 0 | I45: =SUM(D45/24*E45+H45/24*G45) -> 0
...

Sheet Jan 2023
A1: DATE | B1: LRDC | C1: STATION 48 | D1: ANDERSON-ROSE | E1: J CANAL | F1: TULE LAKE PRECIP | G1: TULE LAKE SNOW | H1: D PLANT | I1: TULE LAKE ELEV. | J1: CHANGES @ STATION 48
B2: (in CFS) | C2: (in CFS) | D2: (in CFS) | E2: (in CFS) | H2: (in AF)
A3: 44927 | B3: 49 | C3: 0 | D3: 252 | E3: 127 | F3: 0.01 | G3: 0 | H3: 0 | I3: -
A4: =A3+1 -> 44928 | B4: 49 | C4: 0 | D4: 283 | E4: 154 | F4: 0 | G4: 0 | H4: 0 | I4: -
A5: =A4+1 -> 44929 | B5: 49 | C5: 0 | D5: 0 | E5: 165 | F5: 0.13 | G5: 1 | H5: 0 | I5: -
A6: =A5+1 -> 44930 | B6: 40 | C6: 0 | D6: 0 | E6: 183 | F6: 0.05 | G6: 0 | H6: 0 | I6: -
A7: =A6+1 -> 44931 | B7: 25 | C7: 0 | D7: 0 | E7: 186 | F7: 0.05 | G7: 0 | H7: 0 | I7: -
A8: =A7+1 -> 44932 | B8: 0 | C8: 0 | D8: 0 | E8: 168 | F8: 0 | G8: 0 | H8: 0 | I8: -
A9: =A8+1 -> 44933 | B9: 0 | C9: 0 | D9: 0 | E9: 136 | F9: 0.03 | G9: 0 | H9: 0 | I9: -
A10: =A9+1 -> 44934 | B10: 0 | C10: 0 | D10: 0 | E10: 153 | F10: 0 | G10: 0 | H10: 0 | I10: -
A11: =A10+1 -> 44935 | B11: 0 | C11: 0 | D11: 0 | E11: 169 | F11: 0.25 | G11: 0 | H11: 0 | I11: -
A12: =A11+1 -> 44936 | B12: 0 | C12: 0 | D12: 0 | E12: 160 | F12: 0.01 | G12: 0 | H12: 0 | I12: -
A13: =A12+1 -> 44937 | B13: 0 | C13: 0 | D13: 0 | E13: 148 | F13: 0.11 | G13: 0 | H13: 0 | I13: -
A14: =A13+1 -> 44938 | B14: 0 | C14: 0 | D14: 0 | E14: 169 | F14: T | G14: 0 | H14: 0 | I14: -
A15: =A14+1 -> 44939 | B15: 0 | C15: 0 | D15: 0 | E15: 157 | F15: 0.02 | G15: 0 | H15: 0 | I15: -
A16: =A15+1 -> 44940 | B16: 0 | C16: 0 | D16: 0 | E16: 136 | F16: 0.08 | G16: 0 | H16: 0 | I16: -
A17: =A16+1 -> 44941 | B17: 0 | C17: 0 | D17: 0 | E17: 133 | F17: T | G17: 0 | H17: 0 | I17: -
A18: =A17+1 -> 44942 | B18: 0 | C18: 0 | D18: 0 | E18: 153 | F18: 0.01 | G18: 0 | H18: 0 | I18: -
A19: =A18+1 -> 44943 | B19: 0 | C19: 0 | D19: 0 | E19: 155 | F19: T | G19: 0 | H19: 0 | I19: -
A20: =A19+1 -> 44944 | B20: 0 | C20: 0 | D20: 0 | E20: 161 | F20: 0 | G20: 0 | H20: 0 | I20: -
A21: =A20+1 -> 44945 | B21: 0 | C21: 0 | D21: 0 | E21: 149 | F21: 0.22 | G21: 3 | H21: 0 | I21: -
A22: =A21+1 -> 44946 | B22: 0 | C22: 0 | D22: 0 | E22: 96 | F22: 0.02 | G22: 0 | H22: 0 | I22: -
A23: =A22+1 -> 44947 | B23: 0 | C23: 0 | D23: 0 | E23: 86 | F23: T | G23: 0 | H23: 0 | I23: -
A24: =A23+1 -> 44948 | B24: 0 | C24: 0 | D24: 0 | E24: 70 | F24: T | G24: 0 | H24: 0 | I24: -
A25: =A24+1 -> 44949 | B25: 0 | C25: 0 | D25: 0 | E25: 61 | F25: 0 | G25: 0 | H25: 0 | I25: -
A26: =A25+1 -> 44950 | B26: 0 | C26: 0 | D26: 0 | E26: 61 | F26: 0 | G26: 0 | H26: 0 | I26: -
A27: =A26+1 -> 44951 | B27: 0 | C27: 0 | D27: 0 | E27: 61 | F27: 0 | G27: 0 | H27: 0 | I27: -
A28: =A27+1 -> 44952 | B28: 0 | C28: 0 | D28: 0 | E28: 61 | F28: 0.01 | G28: 0 | H28: 0 | I28: -
A29: =A28+1 -> 44953 | B29: 0 | C29: 0 | D29: 0 | E29: 61 | F29: 0 | G29: 0 | H29: 0 | I29: -
A30: =A29+1 -> 44954 | B30: 0 | C30: 0 | D30: 0 | E30: 61 | F30: 0.01 | G30: 0 | H30: 0 | I30: -
A31: =A30+1 -> 44955 | B31: 0 | C31: 0 | D31: 0 | E31: 61 | F31: 0 | G31: 0 | H31: 0 | I31: -
A32: =A31+1 -> 44956 | B32: 0 | C32: 0 | D32: 0 | E32: 41 | F32: 0 | G32: 0 | H32: 0 | I32: -
A33: =A32+1 -> 44957 | B33: 0 | C33: 0 | E33: 41 | F33: 0 | G33: 0 | H33: 0 | I33: -
A34: Monthly Total | B34: =SUM(B3:B33) -> 212 | C34: =SUM(C3:C33) -> 0 | D34: =SUM(D3:D33) -> 535 | E34: =SUM(E3:E33) -> 3723 | F34: =SUM(F3:F33) -> 1.01 | G34: =SUM(G3:G33) -> 4 | H34: =SUM(H3:H33) -> 0
A35: WY Total | B35: =SUM(B34+'Dec 2022'!B35) -> 327 | C35: =SUM(C34+'Dec 2022'!C35) -> 0 | D35: =SUM(D34+'Dec 2022'!D35) -> 549 | E35: =SUM(E34+'Dec 2022'!E35) -> 6041 | F35: =SUM(F34+'Dec 2022'!F35) -> 5.57 | G35: =SUM(G34+'Dec 2022'!G35) -> 14.5 | H35: =SUM(H34+'Dec 2022'!H35) -> 0
A37: Acre Feet | B37: =SUM(B3:B33)*1.9835 -> 420.502 | C37: =SUM(C3:C33)*1.9835 -> 0 | D37: =SUM(D3:D33)*1.9835 -> 1061.1725 | E37: =SUM(E3:E33)*1.9835 -> 7384.5705
A39: WY AF Total | B39: =SUM(B37+'Dec 2022'!B39) -> 648.6045 | C39: =SUM(C37+'Dec 2022'!C39) -> 0 | D39: =SUM(D37+'Dec 2022'!D39) -> 1088.9415 | E39: =SUM(E37+'Dec 2022'!E39) -> 11982.324
H41: * COMPUTATIONAL PURPOSES ONLY! Do Not Enter Data in the Red Columns
A43: *This is computation purposes only for Station 48
A44: Sta 48
...

Sheet Dec 2022
A1: DATE | B1: LRDC | C1: STATION 48 | D1: ANDERSON-ROSE | E1: J CANAL | F1: TULE LAKE PRECIP | G1: TULE LAKE SNOW | H1: D PLANT | I1: TULE LAKE ELEV. | J1: CHANGES @ STATION 48
B2: (in CFS) | C2: (in CFS) | D2: (in CFS) | E2: (in CFS) | H2: (in AF)
A3: 44896 | B3: 0 | C3: 0 | D3: 0 | E3: 24 | F3: 0.18 | G3: 4 | H3: 0 | I3: -
A4: =A3+1 -> 44897 | B4: 0 | C4: 0 | D4: 0 | E4: 22 | F4: 0.05 | G4: 0 | H4: 0 | I4: -
A5: =A4+1 -> 44898 | B5: 0 | C5: 0 | D5: 0 | E5: 26 | F5: 0.8 | G5: 0 | H5: 0 | I5: -
A6: =A5+1 -> 44899 | B6: 0 | C6: 0 | D6: 0 | E6: 28 | F6: 0.4 | G6: 0 | H6: 0 | I6: -
A7: =A6+1 -> 44900 | B7: 0 | C7: 0 | D7: 0 | E7: 27 | F7: 0.09 | G7: 0 | H7: 0 | I7: -
A8: =A7+1 -> 44901 | B8: 0 | C8: 0 | D8: 0 | E8: 27 | F8: 0 | G8: 0 | H8: 0 | I8: -
A9: =A8+1 -> 44902 | B9: 0 | C9: 0 | D9: 0 | E9: 28 | F9: 0 | G9: 0 | H9: 0 | I9: -
A10: =A9+1 -> 44903 | B10: 0 | C10: 0 | D10: 0 | E10: 27 | F10: 0 | G10: 0 | H10: 0 | I10: -
A11: =A10+1 -> 44904 | B11: 0 | C11: 0 | D11: 0 | E11: 27 | F11: 0.07 | G11: 0.5 | H11: 0 | I11: -
A12: =A11+1 -> 44905 | B12: 0 | C12: 0 | D12: 0 | E12: 27 | F12: 0.15 | G12: 2 | H12: 0 | I12: -
A13: =A12+1 -> 44906 | B13: 0 | C13: 0 | D13: 0 | E13: 27 | F13: 0.03 | G13: 0 | H13: 0 | I13: -
A14: =A13+1 -> 44907 | B14: 0 | C14: 0 | D14: 0 | E14: 27 | F14: T | G14: 0 | H14: 0 | I14: -
A15: =A14+1 -> 44908 | B15: 0 | C15: 0 | D15: 0 | E15: 24 | F15: 0 | G15: 0 | H15: 0 | I15: -
A16: =A15+1 -> 44909 | B16: 0 | C16: 0 | D16: 0 | E16: 23 | F16: T | G16: 0 | H16: 0 | I16: -
A17: =A16+1 -> 44910 | B17: 0 | C17: 0 | D17: 0 | E17: 23 | F17: 0 | G17: 0 | H17: 0 | I17: -
A18: =A17+1 -> 44911 | B18: 0 | C18: 0 | D18: 0 | E18: 22 | F18: 0.02 | G18: 0 | H18: 0 | I18: -
A19: =A18+1 -> 44912 | B19: 0 | C19: 0 | D19: 0 | E19: 20 | F19: T | G19: 0 | H19: 0 | I19: -
A20: =A19+1 -> 44913 | B20: 0 | C20: 0 | D20: 0 | E20: 19 | F20: T | G20: 0 | H20: 0 | I20: -
A21: =A20+1 -> 44914 | B21: 0 | C21: 0 | D21: 0 | E21: 18 | F21: 0 | G21: 0 | H21: 0 | I21: -
A22: =A21+1 -> 44915 | B22: 0 | C22: 0 | D22: 0 | E22: 16 | F22: T | G22: 0 | H22: 0 | I22: -
A23: =A22+1 -> 44916 | B23: 0 | C23: 0 | D23: 0 | E23: 17 | F23: 0.03 | G23: 0 | H23: 0 | I23: -
A24: =A23+1 -> 44917 | B24: 0 | C24: 0 | D24: 0 | E24: 17 | F24: 0.02 | G24: 0 | H24: 0 | I24: -
A25: =A24+1 -> 44918 | B25: 0 | C25: 0 | D25: 0 | E25: 17 | F25: 0 | G25: 0 | H25: 0 | I25: -
A26: =A25+1 -> 44919 | B26: 0 | C26: 0 | D26: 0 | E26: 18 | F26: 0.05 | G26: 0 | H26: 0 | I26: -
A27: =A26+1 -> 44920 | B27: 0 | C27: 0 | D27: 0 | E27: 18 | F27: 0.05 | G27: 0 | H27: 0 | I27: -
A28: =A27+1 -> 44921 | B28: 0 | C28: 0 | D28: 0 | E28: 20 | F28: 0.1 | G28: 0 | H28: 0 | I28: -
A29: =A28+1 -> 44922 | B29: 19 | C29: 0 | D29: 0 | E29: 22 | F29: 0.13 | G29: 0 | H29: 0 | I29: -
A30: =A29+1 -> 44923 | B30: 19 | C30: 0 | D30: 0 | E30: 31 | F30: T | G30: 0 | H30: 0 | I30: -
A31: =A30+1 -> 44924 | B31: 19 | C31: 0 | D31: 0 | E31: 38 | F31: 0.11 | G31: 0.5 | H31: 0 | I31: -
A32: =A31+1 -> 44925 | B32: 19 | C32: 0 | D32: 0 | E32: 95 | F32: 0.8 | G32: 0 | H32: 0 | I32: -
A33: =A32+1 -> 44926 | B33: 39 | C33: 0 | D33: 14 | E33: 121 | F33: 0.14 | G33: 0 | H33: 0 | I33: -
A34: Monthly Total | B34: =SUM(B3:B33) -> 115 | C34: =SUM(C3:C33) -> 0 | D34: =SUM(D3:D33) -> 14 | E34: =SUM(E3:E33) -> 896 | F34: =SUM(F3:F33) -> 3.22 | G34: =SUM(G3:G33) -> 7 | H34: =SUM(H3:H33) -> 0
A35: WY Total | B35: =SUM(B34+'Nov 2022'!B34) -> 115 | C35: =SUM(C34+'Nov 2022'!C34) -> 0 | D35: =SUM(D34+'Nov 2022'!D34) -> 14 | E35: =SUM(E34+'Nov 2022'!E34) -> 2318 | F35: =SUM(F34+'Nov 2022'!F34) -> 4.56 | G35: =SUM(G34+'Nov 2022'!G34) -> 10.5 | H35: =SUM(H34+'Nov 2022'!H34) -> 0
A37: Acre Feet | B37: =SUM(B3:B33)*1.9835 -> 228.1025 | C37: =SUM(C3:C33)*1.9835 -> 0 | D37: =SUM(D3:D33)*1.9835 -> 27.769 | E37: =SUM(E3:E33)*1.9835 -> 1777.216
A39: WY AF Total | B39: =SUM('Nov 2022'!B38+B37) -> 228.1025 | C39: =SUM('Nov 2022'!C38+C37) -> 0 | D39: =SUM('Nov 2022'!D38+D37) -> 27.769 | E39: =SUM('Nov 2022'!E38+E37) -> 4597.753
H41: * COMPUTATIONAL PURPOSES ONLY! Do Not Enter Data in the Red Columns
A43: *This is computation purposes only for Station 48
A44: Sta 48
...

Sheet Nov 2022
A1: DATE | B1: LRDC | C1: STATION 48 | D1: ANDERSON-ROSE | E1: J CANAL | F1: TULE LAKE PRECIP | G1: TULE LAKE SNOW | H1: D PLANT | I1: TULE LAKE ELEV. | J1: CHANGES @ STATION 48
B2: (in CFS) | C2: (in CFS) | D2: (in CFS) | E2: (in CFS) | H2: (in AF)
A3: 44866 | B3: 0 | C3: 0 | D3: 0 | E3: 20 | F3: 0.28 | G3: 1.5 | H3: 0 | I3: -
A4: =A3+1 -> 44867 | B4: 0 | C4: 0 | D4: 0 | E4: 20 | F4: T | G4: 0 | H4: 0 | I4: -
A5: =A4+1 -> 44868 | B5: 0 | C5: 0 | D5: 0 | E5: 20 | F5: T | G5: 0 | H5: 0 | I5: -
A6: =A5+1 -> 44869 | B6: 0 | C6: 0 | D6: 0 | E6: 20 | F6: 0.05 | G6: 0 | H6: 0 | I6: -
A7: =A6+1 -> 44870 | B7: 0 | C7: 0 | D7: 0 | E7: 20 | F7: 0 | G7: 0 | H7: 0 | I7: -
A8: =A7+1 -> 44871 | B8: 0 | C8: 0 | D8: 0 | E8: 20 | F8: 0 | G8: 0 | H8: 0 | I8: -
A9: =A8+1 -> 44872 | B9: 0 | C9: 0 | D9: 0 | E9: 20 | F9: 0.54 | G9: 2 | H9: 0 | I9: -
A10: =A9+1 -> 44873 | B10: 0 | C10: 0 | D10: 0 | E10: 20 | F10: 0.01 | G10: T | H10: 0 | I10: -
A11: =A10+1 -> 44874 | B11: 0 | C11: 0 | D11: 0 | E11: 20 | F11: 0.13 | G11: 0 | H11: 0 | I11: -
A12: =A11+1 -> 44875 | B12: 0 | C12: 0 | D12: 0 | E12: 20 | F12: 0 | G12: 0 | H12: 0 | I12: -
A13: =A12+1 -> 44876 | B13: 0 | C13: 0 | D13: 0 | E13: 20 | F13: 0 | G13: 0 | H13: 0 | I13: -
A14: =A13+1 -> 44877 | B14: 0 | C14: 0 | D14: 0 | E14: 20 | F14: 0.08 | G14: 0 | H14: 0 | I14: -
A15: =A14+1 -> 44878 | B15: 0 | C15: 0 | D15: 0 | E15: 20 | F15: 0 | G15: 0 | H15: 0 | I15: -
A16: =A15+1 -> 44879 | B16: 0 | C16: 0 | D16: 0 | E16: 20 | F16: 0 | G16: 0 | H16: 0 | I16: -
A17: =A16+1 -> 44880 | B17: 0 | C17: 0 | D17: 0 | E17: 20 | F17: 0 | G17: 0 | H17: 0 | I17: -
A18: =A17+1 -> 44881 | B18: 0 | C18: 0 | D18: 0 | E18: 20 | F18: 0 | G18: 0 | H18: 0 | I18: -
A19: =A18+1 -> 44882 | B19: 0 | C19: 0 | D19: 0 | E19: 20 | F19: 0 | G19: 0 | H19: 0 | I19: -
A20: =A19+1 -> 44883 | B20: 0 | C20: 0 | D20: 0 | E20: 20 | F20: 0 | G20: 0 | H20: 0 | I20: -
A21: =A20+1 -> 44884 | B21: 0 | C21: 0 | D21: 0 | E21: 20 | F21: 0 | G21: 0 | H21: 0 | I21: -
A22: =A21+1 -> 44885 | B22: 0 | C22: 0 | D22: 0 | E22: 20 | F22: 0 | G22: 0 | H22: 0 | I22: -
... A30: =A29+1 -> 44893 | B30: 0 | C30: 0 | D30: 0 | E30: 20 | F30: 0.03 | G30: 0 | H30: 0 | I30: -
A31: =A30+1 -> 44894 | B31: 0 | C31: 0 | D31: 0 | E31: 21 | F31: T | G31: 0 | H31: 0 | I31: -
A32: =A31+1 -> 44895 | B32: 0 | C32: 0 | D32: 0 | E32: 24 | F32: 0 | G32: 0 | H32: 0 | I32: -
A33: Monthly Total | B33: =SUM(B3:B32) -> 0 | C33: =SUM(C3:C32) -> 0 | D33: =SUM(D3:D32) -> 0 | E33: =SUM(E3:E32) -> 605 | F33: =SUM(F3:F32) -> 1.13 | G33: =SUM(G3:G32) -> 3.5 | H33: =SUM(H3:H32) -> 0
A34: WY Total | B34: =SUM(B33+'Oct 2022'!B35) -> 0 | C34: =SUM(C33+'Oct 2022'!C35) -> 0 | D34: =SUM(D33+'Oct 2022'!D35) -> 0 | E34: =SUM(E33+'Oct 2022'!E35) -> 1422 | F34: =SUM(F33+'Oct 2022'!F35) -> 1.34 | G34: =SUM(G33+'Oct 2022'!G35) -> 3.5 | H34: =SUM(H33+'Oct 2022'!H35) -> 0
A36: Acre Feet | B36: =SUM(B3:B32)*1.9835 -> 0 | C36: =SUM(C3:C32)*1.9835 -> 0 | D36: =SUM(D3:D32)*1.9835 -> 0 | E36: =SUM(E3:E32)*1.9835 -> 1200.0175
A38: WY AF Total | B38: =SUM('Oct 2022'!B39+B36) -> 0 | C38: =SUM('Oct 2022'!C39+C36) -> 0 | D38: =SUM('Oct 2022'!D39+D36) -> 0 | E38: =SUM('Oct 2022'!E39+E36) -> 2820.537
H40: * COMPUTATIONAL PURPOSES ONLY! Do Not Enter Data in the Red Columns
A42: *This is computation purposes only for Station 48
A43: Sta 48
G44: =SUM(24-E44) -> 24 | H44: =SUM(D44+F44) -> 0 | I44: =SUM(D44/24*E44+H44/24*G44) -> 0
G45: =SUM(24-E45) -> 24 | H45: =SUM(D45+F45) -> 0 | I45: =SUM(D45/24*E45+H45/24*G45) -> 0
G46: =SUM(24-E46) -> 24 | H46: =SUM(D46+F46) -> 0 | I46: =SUM(D46/24*E46+H46/24*G46) -> 0
G47: =SUM(24-E47) -> 24 | H47: =SUM(D47+F47) -> 0 | I47: =SUM(D47/24*E47+H47/24*G47) -> 0
G48: =SUM(24-E48) -> 24 | H48: =SUM(D48+F48) -> 0 | I48: =SUM(D48/24*E48+H48/24*G48) -> 0
A50: Use for more than 1 change in a day.
A51: **Station 48: | C51: Time | D51: Current CFS | E51: Hours Run | F51: +/- cfs | G51: Sub-total cfs
A57: Total Hours Run | E57: =SUM(E52:E56) -> 0 | F57: Total/Day cfs | G57: =SUM(G52:G56) -> 0

Sheet Oct 2022
A1: DATE | B1: LRDC | C1: STATION 48 | D1: ANDERSON-ROSE | E1: J CANAL | F1: TULE LAKE PRECIP | G1: TULE LAKE SNOW | H1: D PLANT | I1: TULE LAKE ELEV. | J1: CHANGES @ STATION 48
B2: (in CFS) | C2: (in CFS) | D2: (in CFS) | E2: (in CFS)
A3: 44835 | B3: 0 | C3: 0 | D3: 0 | E3: 28 | F3: 0 | G3: 0 | H3: 0 | I3: -
A4: =A3+1 -> 44836 | B4: 0 | C4: 0 | D4: 0 | E4: 19 | F4: 0 | G4: 0 | H4: 0 | I4: -
A5: =A4+1 -> 44837 | B5: 0 | C5: 0 | D5: 0 | E5: 19 | F5: 0 | G5: 0 | H5: 0 | I5: -
A6: =A5+1 -> 44838 | B6: 0 | C6: 0 | D6: 0 | E6: 27 | F6: 0 | G6: 0 | H6: 0 | I6: -
A7: =A6+1 -> 44839 | B7: 0 | C7: 0 | D7: 0 | E7: 31 | F7: 0 | G7: 0 | H7: 0 | I7: -
A8: =A7+1 -> 44840 | B8: 0 | C8: 0 | D8: 0 | E8: 33 | F8: 0 | G8: 0 | H8: 0 | I8: -
A9: =A8+1 -> 44841 | B9: 0 | C9: 0 | D9: 0 | E9: 38 | F9: 0 | G9: 0 | H9: 0 | I9: -
A10: =A9+1 -> 44842 | B10: 0 | C10: 0 | D10: 0 | E10: 54 | F10: 0 | G10: 0 | H10: 0 | I10: -
A11: =A10+1 -> 44843 | B11: 0 | C11: 0 | D11: 0 | E11: 54 | F11: 0 | G11: 0 | H11: 0 | I11: -
A12: =A11+1 -> 44844 | B12: 0 | C12: 0 | D12: 0 | E12: 50 | F12: 0 | G12: 0 | H12: 0 | I12: -
A13: =A12+1 -> 44845 | B13: 0 | C13: 0 | D13: 0 | E13: 34 | F13: 0 | G13: 0 | H13: 0 | I13: -
A14: =A13+1 -> 44846 | B14: 0 | C14: 0 | D14: 0 | E14: 39 | F14: 0 | G14: 0 | H14: 0 | I14: -
A15: =A14+1 -> 44847 | B15: 0 | C15: 0 | D15: 0 | E15: 31 | F15: 0 | G15: 0 | H15: 0 | I15: -
... A25: =A24+1 -> 44857 | B25: 0 | C25: 0 | D25: 0 | E25: 20 | F25: 0 | G25: 0 | H25: 0 | I25: -
A26: =A25+1 -> 44858 | B26: 0 | C26: 0 | D26: 0 | E26: 20 | F26: T | G26: 0 | H26: 0 | I26: -
A27: =A26+1 -> 44859 | B27: 0 | C27: 0 | D27: 0 | E27: 20 | F27: 0 | G27: 0 | H27: 0 | I27: -
A28: =A27+1 -> 44860 | B28: 0 | C28: 0 | D28: 0 | E28: 20 | F28: 0 | G28: 0 | H28: 0 | I28: -
A29: =A28+1 -> 44861 | B29: 0 | C29: 0 | D29: 0 | E29: 20 | F29: 0 | G29: 0 | H29: 0 | I29: -
A30: =A29+1 -> 44862 | B30: 0 | C30: 0 | D30: 0 | E30: 20 | F30: 0 | G30: 0 | H30: 0 | I30: -
A31: =A30+1 -> 44863 | B31: 0 | C31: 0 | D31: 0 | E31: 20 | F31: 0 | G31: 0 | H31: 0 | I31: -
A32: =A31+1 -> 44864 | B32: 0 | C32: 0 | D32: 0 | E32: 20 | F32: 0 | G32: 0 | H32: 0 | I32: -
A33: =A32+1 -> 44865 | B33: 0 | C33: 0 | D33: 0 | E33: 20 | F33: 0 | G33: 0 | H33: 0 | I33: -
A34: Monthly Total | B34: =SUM(B3:B33) -> 0 | C34: =SUM(C3:C33) -> 0 | D34: =SUM(D3:D33) -> 0 | E34: =SUM(E3:E33) -> 817 | F34: =SUM(F3:F33) -> 0.21 | G34: =SUM(G3:G33) -> 0 | H34: =SUM(H3:H33) -> 0 | I34: -
A35: WY Total | B35: =SUM(B34+'Oct 2022'!B36) -> 0 | C35: =SUM(C34+'Oct 2022'!C36) -> 0 | D35: =SUM(D34+'Oct 2022'!D36) -> 0 | E35: =SUM(E34+'Oct 2022'!E36) -> 817 | F35: =SUM(F34+'Oct 2022'!F36) -> 0.21 | G35: =SUM(G34+'Oct 2022'!G36) -> 0 | H35: =SUM(H34+'Oct 2022'!H36) -> 0
A37: Acre Feet | B37: =SUM(B3:B33)*1.9835 -> 0 | C37: =SUM(C3:C33)*1.9835 -> 0 | D37: =SUM(D3:D33)*1.9835 -> 0 | E37: =SUM(E3:E33)*1.9835 -> 1620.5195
A39: WY AF Total | B39: =SUM('Oct 2022'!B40+B37) -> 0 | C39: =SUM('Oct 2022'!C40+C37) -> 0 | D39: =SUM('Oct 2022'!D40+D37) -> 0 | E39: =SUM('Oct 2022'!E40+E37) -> 1620.5195
H41: * COMPUTATIONAL PURPOSES ONLY! Do Not Enter Data in the Red Columns
A43: *This is computation purposes only for Station 48
A44: Sta 48
G45: =SUM(24-E45) -> 24 | H45: =SUM(D45+F45) -> 0 | I45: =SUM(D45/24*E45+H45/24*G45) -> 0
G46: =SUM(24-E46) -> 24 | H46: =SUM(D46+F46) -> 0 | I46: =SUM(D46/24*E46+H46/24*G46) -> 0
G47: =SUM(24-E47) -> 24 | H47: =SUM(D47+F47) -> 0 | I47: =SUM(D47/24*E47+H47/24*G47) -> 0
G48: =SUM(24-E48) -> 24 | H48: =SUM(D48+F48) -> 0 | I48: =SUM(D48/24*E48+H48/24*G48) -> 0
G49: =SUM(24-E49) -> 24 | H49: =SUM(D49+F49) -> 0 | I49: =SUM(D49/24*E49+H49/24*G49) -> 0
A51: Use for more than 1 change in a day.
A52: **Station 48: | C52: Time | D52: Current CFS | E52: Hours Run | F52: +/- cfs | G52: Sub-total cfs
A58: Total Hours Run | E58: =SUM(E53:E57) -> 0 | F58: Total/Day cfs | G58: =SUM(G53:G57) -> 0
A59: Total Hours Run | E59: =SUM(E54:E58) -> 0 | F59: Total/Day cfs | G59: =SUM(G54:G58) -> 0
